File: book/some_content/DG_ExpDat_OPC9%DC14; 30-1-2025-2.csv
#FILE:                       ,OPC9%DC14; 30-1-2025.ngb-ds3
#FORMAT:                     ,NETZSCH5
#IDENTITY:                   ,GEOPOLYMER PASTE
#DECIMAL:                    ,POINT
#SEPARATOR:                  ,COMMA
#MTYPE:                      ,DSC
#INSTRUMENT:                 ,Microlab TU Delft
#PROJECT:                    ,
#DATE/TIME:                  ,31/01/2025 8:16:42 AM
#CORR. FILE:                 ,Blank with cover; 13-1-2025.ngb-bs3
#LABORATORY:                 ,TU Delft Micro Lab
#OPERATOR:                   ,Ahmed
#REMARK:                     ,under Argon atmosphere, 10K/min
#SAMPLE:                     ,OPC9%DC14
#SAMPLE MASS /mg:            ,38.4
#MATERIAL:                   ,Geopolymer paste
#REFERENCE:                  ,blank
#REFERENCE MASS /mg:         ,0
#TYPE OF CRUCIBLE:           ,DSC/TG pan Al2O3
#SAMPLE CRUCIBLE MASS /mg:   ,0
#REFERENCE CRUCIBLE MASS /mg:,0
#CORR. CODE:                 ,020
#EXO:                        ,-1
#RANGE:                      ,40/10.0(K/min)/1000
#SEGMENT:                    ,S2/2

##Temp./øC,Time/min,DSC/(mW/mg),Mass/%,Gas Flow(purge1)/(ml/min),Gas Flow(purge2)/(ml/min),Gas Flow(protective)/(ml/min),DTG/(%/min),Sensit./(uV/mW)
 40.54700, 15.04000, 3.0462e-002,97.85513,50.00000,0.0000e+000,20.00000,-8.7999e-002,1.22619
 40.58200, 15.22000, 3.0220e-002,97.84206,50.00000,0.0000e+000,20.00000,-7.4727e-002,1.22614
 40.61100, 15.40000, 3.0011e-002,97.82911,50.00000,0.0000e+000,20.00000,-7.9518e-002,1.22610
 40.68500, 15.58000, 2.9786e-002,97.81552,50.00000,0.0000e+000,20.00000,-7.7562e-002,1.22600
 40.82700, 15.76000, 3.0018e-002,97.79913,50.00000,0.0000e+000,20.00000,-7.5104e-002,1.22580
 40.96900, 15.94000, 3.0185e-002,97.78372,50.00000,0.0000e+000,20.00000,-7.5589e-002,1.22561
 41.20200, 16.12000, 3.1214e-002,97.77167,50.00000,0.0000e+000,20.00000,-7.5722e-002,1.22528
 41.52800, 16.30000, 3.2150e-002,97.76009,50.00000,0.0000e+000,20.00000,-7.5614e-002,1.22484
 41.90100, 16.48000, 3.3673e-002,97.74783,50.00000,0.0000e+000,20.00000,-7.6493e-002,1.22432
 42.38000, 16.66000, 3.5380e-002,97.73401,50.00000,0.0000e+000,20.00000,-7.7400e-002,1.22366
 42.94100, 16.84000, 3.7742e-002,97.71991,50.00000,0.0000e+000,20.00000,-7.9282e-002,1.22289
 43.57500, 17.02000, 4.0598e-002,97.70656,50.00000,0.0000e+000,20.00000,-8.1030e-002,1.22201
 44.27800, 17.20000, 4.3152e-002,97.69246,50.00000,0.0000e+000,20.00000,-8.3293e-002,1.22104
 45.07900, 17.38000, 4.6025e-002,97.67953,50.00000,0.0000e+000,20.00000,-8.6032e-002,1.21994
 45.94400, 17.56000, 4.9233e-002,97.66573,50.00000,0.0000e+000,20.00000,-8.8500e-002,1.21875
 46.92500, 17.74000, 5.2535e-002,97.65104,50.00000,0.0000e+000,20.00000,-9.2299e-002,1.21740
 47.96200, 17.92000, 5.6012e-002,97.63601,50.00000,0.0000e+000,20.00000,-9.7795e-002,1.21597
 49.10700, 18.10000, 5.9438e-002,97.62096,50.00000,0.0000e+000,20.00000,    -0.10331,1.21439
 50.30700, 18.28000, 6.3189e-002,97.60556,50.00000,0.0000e+000,20.00000,    -0.10956,1.21274
 51.61200, 18.46000, 6.6794e-002,97.58952,50.00000,0.0000e+000,20.00000,    -0.11657,1.21094
 52.96700, 18.64000, 7.0808e-002,97.57085,50.00000,0.0000e+000,20.00000,    -0.12393,1.20908
 54.42400, 18.82000, 7.4860e-002,97.55094,50.00000,0.0000e+000,20.00000,    -0.13210,1.20707
 55.94600, 19.00000, 7.8683e-002,97.53007,50.00000,0.0000e+000,20.00000,    -0.14126,1.20498
 57.55300, 19.18000, 8.3023e-002,97.50695,50.00000,0.0000e+000,20.00000,    -0.15295,1.20277
 59.22900, 19.36000, 8.7254e-002,97.48233,50.00000,0.0000e+000,20.00000,    -0.16748,1.20046
 60.97100, 19.54000, 9.1608e-002,97.45336,50.00000,0.0000e+000,20.00000,    -0.18341,1.19807
 62.77900, 19.72000, 9.6351e-002,97.42086,50.00000,0.0000e+000,20.00000,    -0.20014,1.19558
 64.65900, 19.90000,     0.10114,97.38923,50.00000,0.0000e+000,20.00000,    -0.21813,1.19300
 66.61200, 20.08000,     0.10614,97.35502,50.00000,0.0000e+000,20.00000,    -0.23809,1.19032
 68.58400, 20.26000,     0.11133,97.31632,50.00000,0.0000e+000,20.00000,    -0.25868,1.18762
 70.64200, 20.44000,     0.11723,97.27538,50.00000,0.0000e+000,20.00000,    -0.27973,1.18479
 72.75300, 20.62000,     0.12298,97.23265,50.00000,0.0000e+000,20.00000,    -0.30179,1.18190
 74.88900, 20.80000,     0.12936,97.18593,50.00000,0.0000e+000,20.00000,    -0.32472,1.17898
 77.09000, 20.98000,     0.13616,97.13173,50.00000,0.0000e+000,20.00000,    -0.34847,1.17597
 79.31600, 21.16000,     0.14347,97.06651,50.00000,0.0000e+000,20.00000,    -0.37247,1.17292
 81.59000, 21.34000,     0.15097,96.99431,50.00000,0.0000e+000,20.00000,    -0.39583,1.16982
 83.88900, 21.52000,     0.15896,96.91866,50.00000,0.0000e+000,20.00000,    -0.41914,1.16668
 86.26200, 21.70000,     0.16700,96.83888,50.00000,0.0000e+000,20.00000,    -0.44390,1.16344
 88.63000, 21.88000,     0.17573,96.75152,50.00000,0.0000e+000,20.00000,    -0.46875,1.16022
 91.03000, 22.06000,     0.18411,96.66067,50.00000,0.0000e+000,20.00000,    -0.49180,1.15695
 93.45400, 22.24000,     0.19252,96.56644,50.00000,0.0000e+000,20.00000,    -0.51396,1.15365
 95.88700, 22.42000,     0.20109,96.46649,50.00000,0.0000e+000,20.00000,    -0.53558,1.15035
 98.35400, 22.60000,     0.20928,96.36288,50.00000,0.0000e+000,20.00000,    -0.55584,1.14700
100.83700, 22.78000,     0.21671,96.25391,50.00000,0.0000e+000,20.00000,    -0.57400,1.14364
103.32800, 22.96000,     0.22394,96.14210,50.00000,0.0000e+000,20.00000,    -0.58882,1.14027
105.79600, 23.14000,     0.23022,96.02888,50.00000,0.0000e+000,20.00000,    -0.60089,1.13693
108.28200, 23.32000,     0.23588,95.91220,50.00000,0.0000e+000,20.00000,    -0.61174,1.13358
110.77000, 23.50000,     0.24016,95.79050,50.00000,0.0000e+000,20.00000,    -0.62068,1.13022
113.24200, 23.68000,     0.24352,95.66621,50.00000,0.0000e+000,20.00000,    -0.62670,1.12690
115.71500, 23.86000,     0.24562,95.54346,50.00000,0.0000e+000,20.00000,    -0.63102,1.12357
118.19900, 24.04000,     0.24630,95.42179,50.00000,0.0000e+000,20.00000,    -0.63469,1.12024
120.66200, 24.22000,     0.24553,95.30028,50.00000,0.0000e+000,20.00000,    -0.63528,1.11693
123.12700, 24.40000,     0.24401,95.18004,50.00000,0.0000e+000,20.00000,    -0.63425,1.11364
125.59200, 24.58000,     0.24121,95.06092,50.00000,0.0000e+000,20.00000,    -0.63136,1.11034
128.04201, 24.76000,     0.23681,94.94270,50.00000,0.0000e+000,20.00000,    -0.62699,1.10707
130.47301, 24.94000,     0.23172,94.82700,50.00000,0.0000e+000,20.00000,    -0.62157,1.10384
132.92000, 25.12000,     0.22540,94.71186,50.00000,0.0000e+000,20.00000,    -0.61408,1.10058
135.34599, 25.30000,     0.21819,94.59977,50.00000,0.0000e+000,20.00000,    -0.60448,1.09736
137.73599, 25.48000,     0.21020,94.49094,50.00000,0.0000e+000,20.00000,    -0.59368,1.09419
140.15300, 25.66000,     0.20145,94.38463,50.00000,0.0000e+000,20.00000,    -0.58158,1.09099
142.53400, 25.84000,     0.19230,94.27749,50.00000,0.0000e+000,20.00000,    -0.56839,1.08785
144.88000, 26.02000,     0.18279,94.17525,50.00000,0.0000e+000,20.00000,    -0.55482,1.08476
147.22000, 26.20000,     0.17319,94.07596,50.00000,0.0000e+000,20.00000,    -0.54090,1.08168
149.53999, 26.38000,     0.16386,93.97799,50.00000,0.0000e+000,20.00000,    -0.52652,1.07863
151.83501, 26.56000,     0.15405,93.88206,50.00000,0.0000e+000,20.00000,    -0.51214,1.07562
154.11800, 26.74000,     0.14324,93.78846,50.00000,0.0000e+000,20.00000,    -0.49817,1.07263
156.37900, 26.92000,     0.13186,93.69911,50.00000,0.0000e+000,20.00000,    -0.48334,1.06968
158.60699, 27.10000,     0.11983,93.61312,50.00000,0.0000e+000,20.00000,    -0.46865,1.06677
160.81200, 27.28000,     0.10727,93.52791,50.00000,0.0000e+000,20.00000,    -0.45392,1.06390
163.00200, 27.46000, 9.4355e-002,93.44800,50.00000,0.0000e+000,20.00000,    -0.43876,1.06106
165.15900, 27.64000, 8.1350e-002,93.37396,50.00000,0.0000e+000,20.00000,    -0.42269,1.05826
167.30499, 27.82000, 6.8274e-002,93.30185,50.00000,0.0000e+000,20.00000,    -0.40776,1.05548
169.42599, 28.00000, 5.5184e-002,93.23170,50.00000,0.0000e+000,20.00000,    -0.39389,1.05274
171.52901, 28.18000, 4.2063e-002,93.16478,50.00000,0.0000e+000,20.00000,    -0.37977,1.05003
173.61000, 28.36000, 2.9460e-002,93.09877,50.00000,0.0000e+000,20.00000,    -0.36558,1.04735
175.66499, 28.54000, 1.7268e-002,93.03355,50.00000,0.0000e+000,20.00000,    -0.35155,1.04471
177.70900, 28.72000, 5.0143e-003,92.97184,50.00000,0.0000e+000,20.00000,    -0.33852,1.04209
179.73599, 28.90000,-6.8617e-003,92.91262,50.00000,0.0000e+000,20.00000,    -0.32646,1.03950
181.74300, 29.08000,-1.8490e-002,92.85641,50.00000,0.0000e+000,20.00000,    -0.31381,1.03693
183.72900, 29.26000,-2.9695e-002,92.80481,50.00000,0.0000e+000,20.00000,    -0.30170,1.03440
185.71500, 29.44000,-4.0762e-002,92.75610,50.00000,0.0000e+000,20.00000,    -0.29137,1.03188
187.67900, 29.62000,-5.1669e-002,92.70769,50.00000,0.0000e+000,20.00000,    -0.28138,1.02938
189.62000, 29.80000,-6.2376e-002,92.65876,50.00000,0.0000e+000,20.00000,    -0.27121,1.02692
191.54601, 29.98000,-7.2880e-002,92.61171,50.00000,0.0000e+000,20.00000,    -0.26157,1.02449
193.47301, 30.16000,-8.3551e-002,92.56707,50.00000,0.0000e+000,20.00000,    -0.25201,1.02206
195.37700, 30.34000,-9.3217e-002,92.52410,50.00000,0.0000e+000,20.00000,    -0.24260,1.01966
197.27200, 30.52000,    -0.10287,92.48164,50.00000,0.0000e+000,20.00000,    -0.23392,1.01727
199.13699, 30.70000,    -0.11199,92.43939,50.00000,0.0000e+000,20.00000,    -0.22542,1.01493
201.02499, 30.88000,    -0.12132,92.39943,50.00000,0.0000e+000,20.00000,    -0.21746,1.01257
202.85201, 31.06000,    -0.12995,92.36268,50.00000,0.0000e+000,20.00000,    -0.21052,1.01029
204.69200, 31.24000,    -0.13864,92.32571,50.00000,0.0000e+000,20.00000,    -0.20417,1.00799
206.53799, 31.42000,    -0.14708,92.28970,50.00000,0.0000e+000,20.00000,    -0.19783,1.00570
208.34000, 31.60000,    -0.15545,92.25585,50.00000,0.0000e+000,20.00000,    -0.19136,1.00346
210.15900, 31.78000,    -0.16354,92.22370,50.00000,0.0000e+000,20.00000,    -0.18534,1.00120
211.94299, 31.96000,    -0.17156,92.19246,50.00000,0.0000e+000,20.00000,    -0.18058,0.99900
213.73700, 32.14000,    -0.17945,92.16142,50.00000,0.0000e+000,20.00000,    -0.17595,0.99678
215.54900, 32.32000,    -0.18707,92.13057,50.00000,0.0000e+000,20.00000,    -0.17059,0.99455
217.31300, 32.50000,    -0.19418,92.10190,50.00000,0.0000e+000,20.00000,    -0.16500,0.99238
219.07401, 32.68000,    -0.20175,92.07411,50.00000,0.0000e+000,20.00000,    -0.16019,0.99022
220.84500, 32.86000,    -0.20883,92.04701,50.00000,0.0000e+000,20.00000,    -0.15677,0.98805
222.60699, 33.04000,    -0.21575,92.02114,50.00000,0.0000e+000,20.00000,    -0.15326,0.98590
224.36600, 33.22000,    -0.22220,91.99590,50.00000,0.0000e+000,20.00000,    -0.15010,0.98375
226.10001, 33.40000,    -0.22901,91.97065,50.00000,0.0000e+000,20.00000,    -0.14700,0.98164
227.84700, 33.58000,    -0.23594,91.94529,50.00000,0.0000e+000,20.00000,    -0.14393,0.97952
229.58501, 33.76000,    -0.24281,91.91805,50.00000,0.0000e+000,20.00000,    -0.14073,0.97742
231.33900, 33.94000,    -0.24925,91.89124,50.00000,0.0000e+000,20.00000,    -0.13752,0.97530
233.05499, 34.12000,    -0.25606,91.86798,50.00000,0.0000e+000,20.00000,    -0.13465,0.97323
234.78200, 34.30000,    -0.26244,91.84612,50.00000,0.0000e+000,20.00000,    -0.13213,0.97115
236.49899, 34.48000,    -0.26929,91.82337,50.00000,0.0000e+000,20.00000,    -0.12985,0.96909
238.23500, 34.66000,    -0.27622,91.79902,50.00000,0.0000e+000,20.00000,    -0.12758,0.96700
239.95000, 34.84000,    -0.28344,91.77488,50.00000,0.0000e+000,20.00000,    -0.12594,0.96495
241.66100, 35.02000,    -0.29052,91.75020,50.00000,0.0000e+000,20.00000,    -0.12434,0.96291
243.39999, 35.20000,    -0.29751,91.72693,50.00000,0.0000e+000,20.00000,    -0.12248,0.96084
245.11600, 35.38000,    -0.30476,91.70562,50.00000,0.0000e+000,20.00000,    -0.12045,0.95880
246.83200, 35.56000,    -0.31182,91.68574,50.00000,0.0000e+000,20.00000,    -0.11804,0.95677
248.55000, 35.74000,    -0.31869,91.66661,50.00000,0.0000e+000,20.00000,    -0.11563,0.95474
250.26401, 35.92000,    -0.32547,91.64615,50.00000,0.0000e+000,20.00000,    -0.11409,0.95272
252.00301, 36.10000,    -0.33257,91.62623,50.00000,0.0000e+000,20.00000,    -0.11331,0.95067
253.71600, 36.28000,    -0.33970,91.60669,50.00000,0.0000e+000,20.00000,    -0.11199,0.94866
255.43700, 36.46000,    -0.34674,91.58770,50.00000,0.0000e+000,20.00000,    -0.10979,0.94664
257.14899, 36.64000,    -0.35415,91.56782,50.00000,0.0000e+000,20.00000,    -0.10761,0.94464
258.88000, 36.82000,    -0.36171,91.54814,50.00000,0.0000e+000,20.00000,    -0.10542,0.94262
260.61301, 37.00000,    -0.36908,91.52964,50.00000,0.0000e+000,20.00000,    -0.10383,0.94061
262.33600, 37.18000,    -0.37621,91.51168,50.00000,0.0000e+000,20.00000,    -0.10300,0.93861
264.07401, 37.36000,    -0.38305,91.49371,50.00000,0.0000e+000,20.00000,    -0.10232,0.93660
265.80099, 37.54000,    -0.39067,91.47527,50.00000,0.0000e+000,20.00000,    -0.10180,0.93460
267.53601, 37.72000,    -0.39800,91.45718,50.00000,0.0000e+000,20.00000,    -0.10103,0.93261
269.25900, 37.90000,    -0.40508,91.43826,50.00000,0.0000e+000,20.00000,    -0.10036,0.93063
271.00400, 38.08000,    -0.41216,91.42018,50.00000,0.0000e+000,20.00000,-9.9955e-002,0.92863
272.72900, 38.26000,    -0.41915,91.40394,50.00000,0.0000e+000,20.00000,-9.9689e-002,0.92665
274.47299, 38.44000,    -0.42531,91.38774,50.00000,0.0000e+000,20.00000,-9.9253e-002,0.92467
276.19199, 38.62000,    -0.43175,91.37128,50.00000,0.0000e+000,20.00000,-9.9019e-002,0.92271
277.93100, 38.80000,    -0.43792,91.35365,50.00000,0.0000e+000,20.00000,-9.9415e-002,0.92074
279.67599, 38.98000,    -0.44452,91.33514,50.00000,0.0000e+000,20.00000,-9.9910e-002,0.91876
281.41000, 39.16000,    -0.45165,91.31731,50.00000,0.0000e+000,20.00000,    -0.10039,0.91681
283.14801, 39.34000,    -0.45915,91.30016,50.00000,0.0000e+000,20.00000,    -0.10114,0.91485
284.89200, 39.52000,    -0.46629,91.28273,50.00000,0.0000e+000,20.00000,    -0.10197,0.91289
286.66901, 39.70000,    -0.47322,91.26512,50.00000,0.0000e+000,20.00000,    -0.10250,0.91090
288.41199, 39.88000,    -0.47931,91.24709,50.00000,0.0000e+000,20.00000,    -0.10334,0.90896
290.16800, 40.06000,    -0.48551,91.22900,50.00000,0.0000e+000,20.00000,    -0.10472,0.90700
291.93600, 40.24000,    -0.49166,91.21095,50.00000,0.0000e+000,20.00000,    -0.10618,0.90504
293.70099, 40.42000,    -0.49710,91.19212,50.00000,0.0000e+000,20.00000,    -0.10735,0.90308
295.44501, 40.60000,    -0.50193,91.17217,50.00000,0.0000e+000,20.00000,    -0.10805,0.90116
297.19699, 40.78000,    -0.50659,91.15219,50.00000,0.0000e+000,20.00000,    -0.10883,0.89923
298.97198, 40.96000,    -0.51179,91.13267,50.00000,0.0000e+000,20.00000,    -0.11004,0.89728
300.72601, 41.14000,    -0.51710,91.11170,50.00000,0.0000e+000,20.00000,    -0.11139,0.89536
302.49100, 41.32000,    -0.52249,91.09041,50.00000,0.0000e+000,20.00000,    -0.11307,0.89343
304.23901, 41.50000,    -0.52777,91.06974,50.00000,0.0000e+000,20.00000,    -0.11499,0.89152
305.99701, 41.68000,    -0.53214,91.04841,50.00000,0.0000e+000,20.00000,    -0.11686,0.88961
307.76300, 41.86000,    -0.53745,91.02690,50.00000,0.0000e+000,20.00000,    -0.11885,0.88770
309.54199, 42.04000,    -0.54229,91.00540,50.00000,0.0000e+000,20.00000,    -0.12082,0.88578
311.29999, 42.22000,    -0.54703,90.98456,50.00000,0.0000e+000,20.00000,    -0.12268,0.88389
313.06299, 42.40000,    -0.55170,90.96458,50.00000,0.0000e+000,20.00000,    -0.12441,0.88200
314.83200, 42.58000,    -0.55656,90.94357,50.00000,0.0000e+000,20.00000,    -0.12612,0.88010
316.60800, 42.76000,    -0.56122,90.92114,50.00000,0.0000e+000,20.00000,    -0.12796,0.87821
318.36301, 42.94000,    -0.56548,90.89910,50.00000,0.0000e+000,20.00000,    -0.12968,0.87634
320.12701, 43.12000,    -0.56946,90.87583,50.00000,0.0000e+000,20.00000,    -0.13153,0.87447
321.90399, 43.30000,    -0.57411,90.85130,50.00000,0.0000e+000,20.00000,    -0.13422,0.87259
323.66101, 43.48000,    -0.57820,90.82656,50.00000,0.0000e+000,20.00000,    -0.13721,0.87074
325.44000, 43.66000,    -0.58242,90.80126,50.00000,0.0000e+000,20.00000,    -0.14014,0.86886
327.20599, 43.84000,    -0.58749,90.77598,50.00000,0.0000e+000,20.00000,    -0.14321,0.86701
329.00101, 44.02000,    -0.59269,90.75062,50.00000,0.0000e+000,20.00000,    -0.14678,0.86514
330.76901, 44.20000,    -0.59704,90.72459,50.00000,0.0000e+000,20.00000,    -0.15106,0.86330
332.54901, 44.38000,    -0.60049,90.69823,50.00000,0.0000e+000,20.00000,    -0.15562,0.86145
334.31500, 44.56000,    -0.60308,90.67206,50.00000,0.0000e+000,20.00000,    -0.16010,0.85962
336.08301, 44.74000,    -0.60566,90.64518,50.00000,0.0000e+000,20.00000,    -0.16529,0.85780
337.84000, 44.92000,    -0.60817,90.61728,50.00000,0.0000e+000,20.00000,    -0.17027,0.85599
339.61301, 45.10000,    -0.61116,90.58719,50.00000,0.0000e+000,20.00000,    -0.17521,0.85417
341.39401, 45.28000,    -0.61391,90.55514,50.00000,0.0000e+000,20.00000,    -0.18077,0.85235
343.14999, 45.46000,    -0.61696,90.52290,50.00000,0.0000e+000,20.00000,    -0.18672,0.85056
344.93701, 45.64000,    -0.61950,90.49033,50.00000,0.0000e+000,20.00000,    -0.19259,0.84874
346.69800, 45.82000,    -0.62148,90.45646,50.00000,0.0000e+000,20.00000,    -0.19843,0.84696
348.46201, 46.00000,    -0.62326,90.42109,50.00000,0.0000e+000,20.00000,    -0.20416,0.84518
350.24701, 46.18000,    -0.62499,90.38390,50.00000,0.0000e+000,20.00000,    -0.21056,0.84338
352.01801, 46.36000,    -0.62609,90.34545,50.00000,0.0000e+000,20.00000,    -0.21694,0.84161
353.79700, 46.54000,    -0.62706,90.30468,50.00000,0.0000e+000,20.00000,    -0.22277,0.83983
355.54501, 46.72000,    -0.62917,90.26350,50.00000,0.0000e+000,20.00000,    -0.22809,0.83809
357.32300, 46.90000,    -0.63162,90.22127,50.00000,0.0000e+000,20.00000,    -0.23294,0.83632
359.09100, 47.08000,    -0.63456,90.17673,50.00000,0.0000e+000,20.00000,    -0.23752,0.83457
360.87299, 47.26000,    -0.63883,90.12989,50.00000,0.0000e+000,20.00000,    -0.24170,0.83282
362.64801, 47.44000,    -0.64288,90.08303,50.00000,0.0000e+000,20.00000,    -0.24511,0.83107
364.43201, 47.62000,    -0.64763,90.03640,50.00000,0.0000e+000,20.00000,    -0.24809,0.82932
366.21201, 47.80000,    -0.65255,89.98969,50.00000,0.0000e+000,20.00000,    -0.25085,0.82758
368.01801, 47.98000,    -0.65706,89.94036,50.00000,0.0000e+000,20.00000,    -0.25312,0.82583
369.79999, 48.16000,    -0.66223,89.89059,50.00000,0.0000e+000,20.00000,    -0.25502,0.82410
371.60599, 48.34000,    -0.66660,89.84239,50.00000,0.0000e+000,20.00000,    -0.25608,0.82235
373.37500, 48.52000,    -0.67114,89.79515,50.00000,0.0000e+000,20.00000,    -0.25668,0.82065
375.16299, 48.70000,    -0.67645,89.74787,50.00000,0.0000e+000,20.00000,    -0.25684,0.81893
376.94501, 48.88000,    -0.68155,89.69941,50.00000,0.0000e+000,20.00000,    -0.25607,0.81723
378.73199, 49.06000,    -0.68756,89.65144,50.00000,0.0000e+000,20.00000,    -0.25454,0.81552
380.53000, 49.24000,    -0.69357,89.60628,50.00000,0.0000e+000,20.00000,    -0.25304,0.81382
382.31299, 49.42000,    -0.70019,89.56179,50.00000,0.0000e+000,20.00000,    -0.25132,0.81213
384.09100, 49.60000,    -0.70696,89.51672,50.00000,0.0000e+000,20.00000,    -0.24970,0.81045
385.86301, 49.78000,    -0.71441,89.47137,50.00000,0.0000e+000,20.00000,    -0.24803,0.80879
387.65601, 49.96000,    -0.72195,89.42624,50.00000,0.0000e+000,20.00000,    -0.24530,0.80711
389.46301, 50.14000,    -0.73013,89.38174,50.00000,0.0000e+000,20.00000,    -0.24190,0.80542
391.24399, 50.32000,    -0.73959,89.33823,50.00000,0.0000e+000,20.00000,    -0.23839,0.80377
393.02301, 50.50000,    -0.74787,89.29550,50.00000,0.0000e+000,20.00000,    -0.23546,0.80212
394.82401, 50.68000,    -0.75576,89.25404,50.00000,0.0000e+000,20.00000,    -0.23309,0.80045
396.61499, 50.86000,    -0.76473,89.21305,50.00000,0.0000e+000,20.00000,    -0.23133,0.79881
398.41199, 51.04000,    -0.77318,89.17161,50.00000,0.0000e+000,20.00000,    -0.23052,0.79716
400.20200, 51.22000,    -0.77964,89.13102,50.00000,0.0000e+000,20.00000,    -0.22980,0.79553
401.98499, 51.40000,    -0.78697,89.09064,50.00000,0.0000e+000,20.00000,    -0.22904,0.79390
403.75699, 51.58000,    -0.79350,89.04800,50.00000,0.0000e+000,20.00000,    -0.22789,0.79230
405.52600, 51.76000,    -0.79933,89.00729,50.00000,0.0000e+000,20.00000,    -0.22655,0.79070
407.32300, 51.94000,    -0.80542,88.97088,50.00000,0.0000e+000,20.00000,    -0.22553,0.78908
409.11200, 52.12000,    -0.81221,88.93633,50.00000,0.0000e+000,20.00000,    -0.22490,0.78748
410.90399, 52.30000,    -0.82006,88.90033,50.00000,0.0000e+000,20.00000,    -0.22576,0.78588
412.67001, 52.48000,    -0.82715,88.86118,50.00000,0.0000e+000,20.00000,    -0.22714,0.78431
414.47000, 52.66000,    -0.83292,88.81953,50.00000,0.0000e+000,20.00000,    -0.22759,0.78271
416.26401, 52.84000,    -0.83891,88.77702,50.00000,0.0000e+000,20.00000,    -0.22785,0.78113
418.06500, 53.02000,    -0.84558,88.73505,50.00000,0.0000e+000,20.00000,    -0.22878,0.77954
419.86099, 53.20000,    -0.85279,88.69298,50.00000,0.0000e+000,20.00000,    -0.23039,0.77797
421.67801, 53.38000,    -0.86064,88.65143,50.00000,0.0000e+000,20.00000,    -0.23146,0.77638
423.48999, 53.56000,    -0.86724,88.61136,50.00000,0.0000e+000,20.00000,    -0.23300,0.77480
425.29401, 53.74000,    -0.87213,88.57037,50.00000,0.0000e+000,20.00000,    -0.23601,0.77324
427.09399, 53.92000,    -0.87558,88.52933,50.00000,0.0000e+000,20.00000,    -0.23984,0.77169
428.89301, 54.10000,    -0.87742,88.48413,50.00000,0.0000e+000,20.00000,    -0.24332,0.77014
430.66699, 54.28000,    -0.87882,88.43694,50.00000,0.0000e+000,20.00000,    -0.24628,0.76862
432.43500, 54.46000,    -0.88104,88.39388,50.00000,0.0000e+000,20.00000,    -0.24901,0.76711
434.20200, 54.64000,    -0.88383,88.35172,50.00000,0.0000e+000,20.00000,    -0.25135,0.76561
435.96201, 54.82000,    -0.88738,88.30785,50.00000,0.0000e+000,20.00000,    -0.25349,0.76412
437.73801, 55.00000,    -0.89138,88.26195,50.00000,0.0000e+000,20.00000,    -0.25637,0.76262
439.49701, 55.18000,    -0.89570,88.21566,50.00000,0.0000e+000,20.00000,    -0.25921,0.76115
441.26099, 55.36000,    -0.90060,88.16881,50.00000,0.0000e+000,20.00000,    -0.26201,0.75967
443.02301, 55.54000,    -0.90644,88.12107,50.00000,0.0000e+000,20.00000,    -0.26531,0.75820
444.81100, 55.72000,    -0.91255,88.07240,50.00000,0.0000e+000,20.00000,    -0.26914,0.75672
446.59799, 55.90000,    -0.91912,88.02411,50.00000,0.0000e+000,20.00000,    -0.27182,0.75524
448.42700, 56.08000,    -0.92594,87.97489,50.00000,0.0000e+000,20.00000,    -0.27372,0.75373
450.20999, 56.26000,    -0.93104,87.92373,50.00000,0.0000e+000,20.00000,    -0.27713,0.75227
451.99301, 56.44000,    -0.93457,87.87253,50.00000,0.0000e+000,20.00000,    -0.28111,0.75081
453.78799, 56.62000,    -0.93756,87.82260,50.00000,0.0000e+000,20.00000,    -0.28475,0.74935
455.57300, 56.80000,    -0.94065,87.77066,50.00000,0.0000e+000,20.00000,    -0.28771,0.74790
457.37100, 56.98000,    -0.94535,87.71790,50.00000,0.0000e+000,20.00000,    -0.29062,0.74645
459.15601, 57.16000,    -0.95064,87.66771,50.00000,0.0000e+000,20.00000,    -0.29368,0.74502
460.94501, 57.34000,    -0.95453,87.61519,50.00000,0.0000e+000,20.00000,    -0.29691,0.74358
462.75400, 57.52000,    -0.95831,87.56041,50.00000,0.0000e+000,20.00000,    -0.30005,0.74214
464.52701, 57.70000,    -0.96134,87.50608,50.00000,0.0000e+000,20.00000,    -0.30376,0.74073
466.30801, 57.88000,    -0.96431,87.45192,50.00000,0.0000e+000,20.00000,    -0.30698,0.73932
468.08801, 58.06000,    -0.96818,87.39597,50.00000,0.0000e+000,20.00000,    -0.31014,0.73792
469.88699, 58.24000,    -0.97223,87.33949,50.00000,0.0000e+000,20.00000,    -0.31325,0.73651
471.66699, 58.42000,    -0.97680,87.28259,50.00000,0.0000e+000,20.00000,    -0.31651,0.73512
473.47699, 58.60000,    -0.98138,87.22606,50.00000,0.0000e+000,20.00000,    -0.31942,0.73371
475.26999, 58.78000,    -0.98571,87.16929,50.00000,0.0000e+000,20.00000,    -0.32234,0.73232
477.05600, 58.96000,    -0.98942,87.11158,50.00000,0.0000e+000,20.00000,    -0.32625,0.73094
478.86200, 59.14000,    -0.99318,87.05231,50.00000,0.0000e+000,20.00000,    -0.32971,0.72955
480.66800, 59.32000,    -0.99823,86.99250,50.00000,0.0000e+000,20.00000,    -0.33289,0.72817
482.46301, 59.50000,    -1.00309,86.93066,50.00000,0.0000e+000,20.00000,    -0.33682,0.72680
484.28201, 59.68000,    -1.00760,86.86981,50.00000,0.0000e+000,20.00000,    -0.34070,0.72542
486.07101, 59.86000,    -1.01072,86.80774,50.00000,0.0000e+000,20.00000,    -0.34299,0.72406
487.86600, 60.04000,    -1.01344,86.74483,50.00000,0.0000e+000,20.00000,    -0.34611,0.72271
489.64899, 60.22000,    -1.01520,86.68279,50.00000,0.0000e+000,20.00000,    -0.35017,0.72137
491.44400, 60.40000,    -1.01676,86.62093,50.00000,0.0000e+000,20.00000,    -0.35334,0.72003
493.23001, 60.58000,    -1.01991,86.55745,50.00000,0.0000e+000,20.00000,    -0.35521,0.71871
495.01901, 60.76000,    -1.02343,86.49280,50.00000,0.0000e+000,20.00000,    -0.35730,0.71738
496.80099, 60.94000,    -1.02695,86.42833,50.00000,0.0000e+000,20.00000,    -0.35959,0.71607
498.57999, 61.12000,    -1.02993,86.36232,50.00000,0.0000e+000,20.00000,    -0.36251,0.71476
500.36600, 61.30000,    -1.03405,86.29394,50.00000,0.0000e+000,20.00000,    -0.36560,0.71346
502.14600, 61.48000,    -1.03827,86.22509,50.00000,0.0000e+000,20.00000,    -0.36834,0.71216
503.94699, 61.66000,    -1.04272,86.16081,50.00000,0.0000e+000,20.00000,    -0.37085,0.71085
505.72101, 61.84000,    -1.04676,86.09390,50.00000,0.0000e+000,20.00000,    -0.37262,0.70957
507.51501, 62.02000,    -1.05170,86.02229,50.00000,0.0000e+000,20.00000,    -0.37433,0.70828
509.30600, 62.20000,    -1.05579,85.95324,50.00000,0.0000e+000,20.00000,    -0.37710,0.70700
511.12000, 62.38000,    -1.06187,85.88938,50.00000,0.0000e+000,20.00000,    -0.37995,0.70571
512.93500, 62.56000,    -1.06781,85.82477,50.00000,0.0000e+000,20.00000,    -0.38213,0.70442
514.75201, 62.74000,    -1.07270,85.75749,50.00000,0.0000e+000,20.00000,    -0.38440,0.70314
516.56702, 62.92000,    -1.07638,85.68783,50.00000,0.0000e+000,20.00000,    -0.38700,0.70186
518.37000, 63.10000,    -1.08045,85.61489,50.00000,0.0000e+000,20.00000,    -0.38903,0.70060
520.17902, 63.28000,    -1.08237,85.54357,50.00000,0.0000e+000,20.00000,    -0.39087,0.69934
521.98798, 63.46000,    -1.08551,85.47276,50.00000,0.0000e+000,20.00000,    -0.39421,0.69808
523.76898, 63.64000,    -1.08640,85.40288,50.00000,0.0000e+000,20.00000,    -0.39621,0.69685
525.57202, 63.82000,    -1.08871,85.33468,50.00000,0.0000e+000,20.00000,    -0.39618,0.69561
527.35602, 64.00000,    -1.09175,85.26333,50.00000,0.0000e+000,20.00000,    -0.39777,0.69438
529.15198, 64.18000,    -1.09557,85.18979,50.00000,0.0000e+000,20.00000,    -0.40181,0.69316
530.93799, 64.36000,    -1.09873,85.11694,50.00000,0.0000e+000,20.00000,    -0.40534,0.69194
532.73401, 64.54000,    -1.10293,85.04454,50.00000,0.0000e+000,20.00000,    -0.40737,0.69073
534.53900, 64.72000,    -1.10816,84.96961,50.00000,0.0000e+000,20.00000,    -0.40923,0.68951
536.36401, 64.90000,    -1.11336,84.89416,50.00000,0.0000e+000,20.00000,    -0.41101,0.68829
538.16803, 65.08000,    -1.11737,84.81843,50.00000,0.0000e+000,20.00000,    -0.41252,0.68709
539.97601, 65.26000,    -1.12052,84.74136,50.00000,0.0000e+000,20.00000,    -0.41391,0.68588
541.77100, 65.44000,    -1.12313,84.66726,50.00000,0.0000e+000,20.00000,    -0.41631,0.68470
543.57202, 65.62000,    -1.12528,84.59631,50.00000,0.0000e+000,20.00000,    -0.41912,0.68351
545.37402, 65.80000,    -1.12735,84.52146,50.00000,0.0000e+000,20.00000,    -0.42115,0.68233
547.14697, 65.98000,    -1.13011,84.44244,50.00000,0.0000e+000,20.00000,    -0.42268,0.68117
548.93903, 66.16000,    -1.13286,84.36488,50.00000,0.0000e+000,20.00000,    -0.42351,0.68000
550.72302, 66.34000,    -1.13620,84.29025,50.00000,0.0000e+000,20.00000,    -0.42536,0.67885
552.51599, 66.52000,    -1.13937,84.21491,50.00000,0.0000e+000,20.00000,    -0.42698,0.67769
554.31403, 66.70000,    -1.14301,84.13591,50.00000,0.0000e+000,20.00000,    -0.42822,0.67654
556.09601, 66.88000,    -1.14612,84.05813,50.00000,0.0000e+000,20.00000,    -0.42923,0.67540
557.90698, 67.06000,    -1.14973,83.98257,50.00000,0.0000e+000,20.00000,    -0.42963,0.67425
559.71002, 67.24000,    -1.15345,83.90391,50.00000,0.0000e+000,20.00000,    -0.43057,0.67310
561.50800, 67.42000,    -1.15690,83.82510,50.00000,0.0000e+000,20.00000,    -0.43301,0.67197
563.31299, 67.60000,    -1.16185,83.74730,50.00000,0.0000e+000,20.00000,    -0.43438,0.67084
565.12500, 67.78000,    -1.16604,83.66798,50.00000,0.0000e+000,20.00000,    -0.43404,0.66970
566.92200, 67.96000,    -1.16841,83.59171,50.00000,0.0000e+000,20.00000,    -0.43451,0.66858
568.70898, 68.14000,    -1.17044,83.51329,50.00000,0.0000e+000,20.00000,    -0.43617,0.66748
570.49799, 68.32000,    -1.17002,83.43289,50.00000,0.0000e+000,20.00000,    -0.43699,0.66637
572.28302, 68.50000,    -1.17016,83.35260,50.00000,0.0000e+000,20.00000,    -0.43642,0.66528
574.07098, 68.68000,    -1.17307,83.27343,50.00000,0.0000e+000,20.00000,    -0.43733,0.66418
575.87201, 68.86000,    -1.17914,83.19463,50.00000,0.0000e+000,20.00000,    -0.43888,0.66309
577.66803, 69.04000,    -1.18495,83.11666,50.00000,0.0000e+000,20.00000,    -0.43904,0.66200
579.46899, 69.22000,    -1.19030,83.03677,50.00000,0.0000e+000,20.00000,    -0.43956,0.66091
581.28101, 69.40000,    -1.19570,82.95756,50.00000,0.0000e+000,20.00000,    -0.44110,0.65982
583.08801, 69.58000,    -1.20092,82.88001,50.00000,0.0000e+000,20.00000,    -0.44162,0.65874
584.90198, 69.76000,    -1.20576,82.80076,50.00000,0.0000e+000,20.00000,    -0.44315,0.65766
586.71301, 69.94000,    -1.20918,82.71966,50.00000,0.0000e+000,20.00000,    -0.44437,0.65659
588.49500, 70.12000,    -1.20915,82.64105,50.00000,0.0000e+000,20.00000,    -0.44478,0.65553
590.26300, 70.30000,    -1.20943,82.56502,50.00000,0.0000e+000,20.00000,    -0.44562,0.65450
592.05298, 70.48000,    -1.21225,82.48387,50.00000,0.0000e+000,20.00000,    -0.44717,0.65345
593.84399, 70.66000,    -1.21764,82.40238,50.00000,0.0000e+000,20.00000,    -0.44903,0.65240
595.64801, 70.84000,    -1.22295,82.32335,50.00000,0.0000e+000,20.00000,    -0.45140,0.65136
597.43903, 71.02000,    -1.22605,82.24311,50.00000,0.0000e+000,20.00000,    -0.45324,0.65032
599.22601, 71.20000,    -1.22931,82.15969,50.00000,0.0000e+000,20.00000,    -0.45488,0.64930
601.02502, 71.38000,    -1.23371,82.07826,50.00000,0.0000e+000,20.00000,    -0.45692,0.64827
602.84198, 71.56000,    -1.23906,81.99621,50.00000,0.0000e+000,20.00000,    -0.45890,0.64723
604.65399, 71.74000,    -1.24506,81.91385,50.00000,0.0000e+000,20.00000,    -0.46085,0.64620
606.45398, 71.92000,    -1.25118,81.83208,50.00000,0.0000e+000,20.00000,    -0.46357,0.64519
608.27301, 72.10000,    -1.25514,81.74892,50.00000,0.0000e+000,20.00000,    -0.46782,0.64416
610.09198, 72.28000,    -1.25889,81.66412,50.00000,0.0000e+000,20.00000,    -0.47107,0.64314
611.90802, 72.46000,    -1.26270,81.57854,50.00000,0.0000e+000,20.00000,    -0.47381,0.64213
613.72998, 72.64000,    -1.26538,81.49206,50.00000,0.0000e+000,20.00000,    -0.47755,0.64112
615.54498, 72.82000,    -1.26770,81.40556,50.00000,0.0000e+000,20.00000,    -0.48193,0.64012
617.34900, 73.00000,    -1.26880,81.31999,50.00000,0.0000e+000,20.00000,    -0.48582,0.63912
619.14600, 73.18000,    -1.27256,81.23480,50.00000,0.0000e+000,20.00000,    -0.48997,0.63814
620.94800, 73.36000,    -1.27362,81.14910,50.00000,0.0000e+000,20.00000,    -0.49393,0.63716
622.74200, 73.54000,    -1.27482,81.06116,50.00000,0.0000e+000,20.00000,    -0.49779,0.63618
624.53302, 73.72000,    -1.27698,80.97217,50.00000,0.0000e+000,20.00000,    -0.50166,0.63522
626.33801, 73.90000,    -1.27997,80.88109,50.00000,0.0000e+000,20.00000,    -0.50544,0.63424
628.14398, 74.08000,    -1.28221,80.78874,50.00000,0.0000e+000,20.00000,    -0.50958,0.63328
629.92700, 74.26000,    -1.28443,80.69698,50.00000,0.0000e+000,20.00000,    -0.51416,0.63232
631.73199, 74.44000,    -1.28597,80.60422,50.00000,0.0000e+000,20.00000,    -0.51847,0.63136
633.53601, 74.62000,    -1.28883,80.50903,50.00000,0.0000e+000,20.00000,    -0.52292,0.63041
635.31403, 74.80000,    -1.28892,80.41161,50.00000,0.0000e+000,20.00000,    -0.52735,0.62947
637.09698, 74.98000,    -1.28790,80.31451,50.00000,0.0000e+000,20.00000,    -0.53108,0.62854
638.89502, 75.16000,    -1.28906,80.21830,50.00000,0.0000e+000,20.00000,    -0.53530,0.62760
640.69598, 75.34000,    -1.29381,80.12165,50.00000,0.0000e+000,20.00000,    -0.53877,0.62666
642.50403, 75.52000,    -1.29775,80.02570,50.00000,0.0000e+000,20.00000,    -0.54119,0.62573
644.31000, 75.70000,    -1.30245,79.92932,50.00000,0.0000e+000,20.00000,    -0.54327,0.62479
646.12402, 75.88000,    -1.30573,79.83007,50.00000,0.0000e+000,20.00000,    -0.54478,0.62386
647.92798, 76.06000,    -1.30588,79.72811,50.00000,0.0000e+000,20.00000,    -0.54595,0.62294
649.72998, 76.24000,    -1.30678,79.62587,50.00000,0.0000e+000,20.00000,    -0.54620,0.62202
651.57300, 76.42000,    -1.31358,79.52323,50.00000,0.0000e+000,20.00000,    -0.54572,0.62109
653.44299, 76.60000,    -1.32401,79.42084,50.00000,0.0000e+000,20.00000,    -0.54478,0.62014
655.24500, 76.78000,    -1.32588,79.32185,50.00000,0.0000e+000,20.00000,    -0.54311,0.61924
657.03802, 76.96000,    -1.31939,79.22133,50.00000,0.0000e+000,20.00000,    -0.54087,0.61834
658.80402, 77.14000,    -1.31586,79.12062,50.00000,0.0000e+000,20.00000,    -0.53855,0.61746
660.57599, 77.32000,    -1.31687,79.02269,50.00000,0.0000e+000,20.00000,    -0.53583,0.61658
662.37000, 77.50000,    -1.32131,78.92456,50.00000,0.0000e+000,20.00000,    -0.53208,0.61569
664.17401, 77.68000,    -1.32565,78.82651,50.00000,0.0000e+000,20.00000,    -0.52712,0.61480
665.97198, 77.86000,    -1.32988,78.73003,50.00000,0.0000e+000,20.00000,    -0.52138,0.61392
667.77899, 78.04000,    -1.33474,78.63634,50.00000,0.0000e+000,20.00000,    -0.51541,0.61304
669.59399, 78.22000,    -1.34079,78.54344,50.00000,0.0000e+000,20.00000,    -0.50846,0.61216
671.41998, 78.40000,    -1.34800,78.44962,50.00000,0.0000e+000,20.00000,    -0.50020,0.61127
673.25598, 78.58000,    -1.35496,78.35785,50.00000,0.0000e+000,20.00000,    -0.49305,0.61039
675.08801, 78.76000,    -1.36073,78.26959,50.00000,0.0000e+000,20.00000,    -0.48566,0.60951
676.90503, 78.94000,    -1.36555,78.18144,50.00000,0.0000e+000,20.00000,    -0.47809,0.60864
678.72400, 79.12000,    -1.36710,78.09476,50.00000,0.0000e+000,20.00000,    -0.47063,0.60777
680.49597, 79.30000,    -1.36638,78.01187,50.00000,0.0000e+000,20.00000,    -0.46175,0.60693
682.29498, 79.48000,    -1.36682,77.93107,50.00000,0.0000e+000,20.00000,    -0.45160,0.60608
684.14099, 79.66000,    -1.37492,77.85052,50.00000,0.0000e+000,20.00000,    -0.44213,0.60521
685.94501, 79.84000,    -1.38118,77.76978,50.00000,0.0000e+000,20.00000,    -0.43368,0.60437
687.75800, 80.02000,    -1.38250,77.69197,50.00000,0.0000e+000,20.00000,    -0.42462,0.60352
689.53998, 80.20000,    -1.38189,77.61904,50.00000,0.0000e+000,20.00000,    -0.41460,0.60269
691.31799, 80.38000,    -1.38187,77.54609,50.00000,0.0000e+000,20.00000,    -0.40505,0.60187
693.10699, 80.56000,    -1.38363,77.47290,50.00000,0.0000e+000,20.00000,    -0.39609,0.60104
694.87201, 80.74000,    -1.38550,77.39960,50.00000,0.0000e+000,20.00000,    -0.38691,0.60023
696.66602, 80.92000,    -1.38763,77.32792,50.00000,0.0000e+000,20.00000,    -0.37745,0.59941
698.47699, 81.10000,    -1.39512,77.26152,50.00000,0.0000e+000,20.00000,    -0.36904,0.59859
700.29102, 81.28000,    -1.40270,77.20012,50.00000,0.0000e+000,20.00000,    -0.36202,0.59776
702.11298, 81.46000,    -1.40940,77.13825,50.00000,0.0000e+000,20.00000,    -0.35539,0.59694
703.91901, 81.64000,    -1.41039,77.07499,50.00000,0.0000e+000,20.00000,    -0.34833,0.59612
705.71503, 81.82000,    -1.41190,77.01452,50.00000,0.0000e+000,20.00000,    -0.34214,0.59532
707.51898, 82.00000,    -1.41542,76.95729,50.00000,0.0000e+000,20.00000,    -0.33718,0.59451
709.32800, 82.18000,    -1.41898,76.89989,50.00000,0.0000e+000,20.00000,    -0.33262,0.59370
711.13202, 82.36000,    -1.42247,76.84371,50.00000,0.0000e+000,20.00000,    -0.32800,0.59290
712.93500, 82.54000,    -1.42405,76.78897,50.00000,0.0000e+000,20.00000,    -0.32335,0.59210
714.75299, 82.72000,    -1.42619,76.73614,50.00000,0.0000e+000,20.00000,    -0.31798,0.59130
716.56702, 82.90000,    -1.42915,76.68367,50.00000,0.0000e+000,20.00000,    -0.31318,0.59051
718.38000, 83.08000,    -1.42841,76.62881,50.00000,0.0000e+000,20.00000,    -0.30948,0.58971
720.16699, 83.26000,    -1.42770,76.57239,50.00000,0.0000e+000,20.00000,    -0.30382,0.58893
721.96399, 83.44000,    -1.42555,76.51738,50.00000,0.0000e+000,20.00000,    -0.29595,0.58815
723.73999, 83.62000,    -1.42450,76.46148,50.00000,0.0000e+000,20.00000,    -0.28743,0.58738
725.51099, 83.80000,    -1.42263,76.40613,50.00000,0.0000e+000,20.00000,    -0.27880,0.58662
727.28900, 83.98000,    -1.42242,76.35021,50.00000,0.0000e+000,20.00000,    -0.26936,0.58586
729.09302, 84.16000,    -1.42324,76.29379,50.00000,0.0000e+000,20.00000,    -0.26035,0.58508
730.90302, 84.34000,    -1.42897,76.23747,50.00000,0.0000e+000,20.00000,    -0.25132,0.58431
732.76202, 84.52000,    -1.44071,76.18405,50.00000,0.0000e+000,20.00000,    -0.24246,0.58352
734.60199, 84.70000,    -1.45150,76.13424,50.00000,0.0000e+000,20.00000,    -0.23315,0.58274
736.44800, 84.88000,    -1.46044,76.08525,50.00000,0.0000e+000,20.00000,    -0.22311,0.58196
738.25299, 85.06000,    -1.46850,76.04308,50.00000,0.0000e+000,20.00000,    -0.21288,0.58120
740.05798, 85.24000,    -1.48007,76.00790,50.00000,0.0000e+000,20.00000,    -0.20300,0.58045
741.87500, 85.42000,    -1.49308,75.97722,50.00000,0.0000e+000,20.00000,    -0.19268,0.57969
743.66302, 85.60000,    -1.49860,75.95064,50.00000,0.0000e+000,20.00000,    -0.18239,0.57894
745.44000, 85.78000,    -1.50261,75.92765,50.00000,0.0000e+000,20.00000,    -0.17132,0.57821
747.22498, 85.96000,    -1.50536,75.90414,50.00000,0.0000e+000,20.00000,    -0.15998,0.57747
749.01599, 86.14000,    -1.50915,75.88191,50.00000,0.0000e+000,20.00000,    -0.14908,0.57673
750.80701, 86.32000,    -1.51025,75.86099,50.00000,0.0000e+000,20.00000,    -0.13874,0.57599
752.59302, 86.50000,    -1.51085,75.84223,50.00000,0.0000e+000,20.00000,    -0.12894,0.57526
754.38898, 86.68000,    -1.51448,75.82473,50.00000,0.0000e+000,20.00000,    -0.11879,0.57453
756.21002, 86.86000,    -1.51917,75.80580,50.00000,0.0000e+000,20.00000,    -0.11080,0.57379
758.01599, 87.04000,    -1.52243,75.78667,50.00000,0.0000e+000,20.00000,    -0.10473,0.57305
759.81500, 87.22000,    -1.52558,75.76852,50.00000,0.0000e+000,20.00000,-9.9705e-002,0.57233
761.62097, 87.40000,    -1.52791,75.75056,50.00000,0.0000e+000,20.00000,-9.6512e-002,0.57160
763.42798, 87.58000,    -1.52905,75.73482,50.00000,0.0000e+000,20.00000,-9.4624e-002,0.57087
765.25201, 87.76000,    -1.53038,75.72010,50.00000,0.0000e+000,20.00000,-9.2081e-002,0.57014
767.07800, 87.94000,    -1.53524,75.70368,50.00000,0.0000e+000,20.00000,-8.9185e-002,0.56941
768.88098, 88.12000,    -1.53693,75.68719,50.00000,0.0000e+000,20.00000,-8.6297e-002,0.56869
770.70898, 88.30000,    -1.53963,75.67253,50.00000,0.0000e+000,20.00000,-8.4345e-002,0.56797
772.53198, 88.48000,    -1.54121,75.66027,50.00000,0.0000e+000,20.00000,-8.3427e-002,0.56725
774.33899, 88.66000,    -1.54251,75.64626,50.00000,0.0000e+000,20.00000,-8.1739e-002,0.56653
776.13702, 88.84000,    -1.54297,75.63212,50.00000,0.0000e+000,20.00000,-7.9729e-002,0.56582
777.93597, 89.02000,    -1.54237,75.61938,50.00000,0.0000e+000,20.00000,-7.8161e-002,0.56512
779.73401, 89.20000,    -1.54263,75.60417,50.00000,0.0000e+000,20.00000,-7.6336e-002,0.56441
781.53302, 89.38000,    -1.54378,75.58769,50.00000,0.0000e+000,20.00000,-7.4685e-002,0.56371
783.32800, 89.56000,    -1.54386,75.57317,50.00000,0.0000e+000,20.00000,-7.3586e-002,0.56301
785.10400, 89.74000,    -1.54427,75.56089,50.00000,0.0000e+000,20.00000,-7.2040e-002,0.56232
786.90302, 89.92000,    -1.54555,75.55035,50.00000,0.0000e+000,20.00000,-7.0465e-002,0.56163
788.70300, 90.10000,    -1.54952,75.53864,50.00000,0.0000e+000,20.00000,-6.9794e-002,0.56093
790.51398, 90.28000,    -1.55265,75.52469,50.00000,0.0000e+000,20.00000,-7.0075e-002,0.56024
792.31000, 90.46000,    -1.55513,75.51182,50.00000,0.0000e+000,20.00000,-6.9880e-002,0.55955
794.10797, 90.64000,    -1.55658,75.49997,50.00000,0.0000e+000,20.00000,-6.9257e-002,0.55886
795.91498, 90.82000,    -1.56047,75.48750,50.00000,0.0000e+000,20.00000,-6.9103e-002,0.55817
797.71002, 91.00000,    -1.56587,75.47584,50.00000,0.0000e+000,20.00000,-6.8785e-002,0.55748
799.53699, 91.18000,    -1.57143,75.46561,50.00000,0.0000e+000,20.00000,-6.8081e-002,0.55679
801.36401, 91.36000,    -1.57628,75.45518,50.00000,0.0000e+000,20.00000,-6.7229e-002,0.55610
803.19800, 91.54000,    -1.58129,75.44449,50.00000,0.0000e+000,20.00000,-6.7090e-002,0.55540
805.02197, 91.72000,    -1.58665,75.43390,50.00000,0.0000e+000,20.00000,-6.7829e-002,0.55472
806.85999, 91.90000,    -1.59104,75.42144,50.00000,0.0000e+000,20.00000,-6.8643e-002,0.55402
808.76898, 92.08000,    -1.60505,75.40815,50.00000,0.0000e+000,20.00000,-6.8983e-002,0.55331
810.61700, 92.26000,    -1.61106,75.39496,50.00000,0.0000e+000,20.00000,-6.9994e-002,0.55262
812.38202, 92.44000,    -1.60470,75.38286,50.00000,0.0000e+000,20.00000,-7.1076e-002,0.55196
814.09802, 92.62000,    -1.59020,75.37076,50.00000,0.0000e+000,20.00000,-7.2052e-002,0.55132
815.84003, 92.80000,    -1.58525,75.35741,50.00000,0.0000e+000,20.00000,-7.3541e-002,0.55067
817.61700, 92.98000,    -1.58484,75.34332,50.00000,0.0000e+000,20.00000,-7.5827e-002,0.55001
819.38098, 93.16000,    -1.58806,75.33122,50.00000,0.0000e+000,20.00000,-7.7966e-002,0.54936
821.16498, 93.34000,    -1.59019,75.31939,50.00000,0.0000e+000,20.00000,-8.0067e-002,0.54870
822.96002, 93.52000,    -1.59189,75.30611,50.00000,0.0000e+000,20.00000,-8.2305e-002,0.54804
824.83301, 93.70000,    -1.60178,75.29196,50.00000,0.0000e+000,20.00000,-8.4224e-002,0.54735
826.71002, 93.88000,    -1.61397,75.27710,50.00000,0.0000e+000,20.00000,-8.6244e-002,0.54666
828.52899, 94.06000,    -1.61631,75.26044,50.00000,0.0000e+000,20.00000,-8.7895e-002,0.54599
830.29797, 94.24000,    -1.60835,75.24434,50.00000,0.0000e+000,20.00000,-8.9628e-002,0.54534
832.07001, 94.42000,    -1.60187,75.22860,50.00000,0.0000e+000,20.00000,-9.2183e-002,0.54470
833.87201, 94.60000,    -1.59858,75.21150,50.00000,0.0000e+000,20.00000,-9.5094e-002,0.54404
835.68103, 94.78000,    -1.60037,75.19282,50.00000,0.0000e+000,20.00000,-9.8095e-002,0.54338
837.49902, 94.96000,    -1.60400,75.17464,50.00000,0.0000e+000,20.00000,    -0.10157,0.54272
839.29797, 95.14000,    -1.60549,75.15627,50.00000,0.0000e+000,20.00000,    -0.10534,0.54207
841.10901, 95.32000,    -1.60413,75.13764,50.00000,0.0000e+000,20.00000,    -0.10898,0.54142
842.89697, 95.50000,    -1.60127,75.11862,50.00000,0.0000e+000,20.00000,    -0.11283,0.54077
844.68402, 95.68000,    -1.60097,75.09817,50.00000,0.0000e+000,20.00000,    -0.11675,0.54013
846.47601, 95.86000,    -1.60133,75.07840,50.00000,0.0000e+000,20.00000,    -0.11997,0.53948
848.26801, 96.04000,    -1.60081,75.06012,50.00000,0.0000e+000,20.00000,    -0.12276,0.53884
850.08197, 96.22000,    -1.60186,75.03914,50.00000,0.0000e+000,20.00000,    -0.12633,0.53819
851.88702, 96.40000,    -1.60405,75.01575,50.00000,0.0000e+000,20.00000,    -0.12988,0.53754
853.68799, 96.58000,    -1.60571,74.99073,50.00000,0.0000e+000,20.00000,    -0.13293,0.53690
855.54700, 96.76000,    -1.60985,74.96554,50.00000,0.0000e+000,20.00000,    -0.13600,0.53623
857.46399, 96.94000,    -1.62589,74.94023,50.00000,0.0000e+000,20.00000,    -0.13954,0.53555
859.33502, 97.12000,    -1.63096,74.91399,50.00000,0.0000e+000,20.00000,    -0.14292,0.53489
861.14697, 97.30000,    -1.62496,74.88620,50.00000,0.0000e+000,20.00000,    -0.14597,0.53424
862.94299, 97.48000,    -1.61666,74.85714,50.00000,0.0000e+000,20.00000,    -0.14913,0.53360
864.70099, 97.66000,    -1.60830,74.82874,50.00000,0.0000e+000,20.00000,    -0.15272,0.53298
866.48199, 97.84000,    -1.60393,74.80214,50.00000,0.0000e+000,20.00000,    -0.15643,0.53235
868.26099, 98.02000,    -1.60101,74.77387,50.00000,0.0000e+000,20.00000,    -0.15956,0.53172
870.04401, 98.20000,    -1.60223,74.74410,50.00000,0.0000e+000,20.00000,    -0.16269,0.53109
871.85400, 98.38000,    -1.60641,74.71430,50.00000,0.0000e+000,20.00000,    -0.16475,0.53046
873.65302, 98.56000,    -1.60915,74.68492,50.00000,0.0000e+000,20.00000,    -0.16644,0.52982
875.42999, 98.74000,    -1.60674,74.65393,50.00000,0.0000e+000,20.00000,    -0.16835,0.52920
877.22498, 98.92000,    -1.60835,74.62272,50.00000,0.0000e+000,20.00000,    -0.17011,0.52857
879.01099, 99.10000,    -1.60966,74.59278,50.00000,0.0000e+000,20.00000,    -0.17219,0.52794
880.79901, 99.28000,    -1.61048,74.56125,50.00000,0.0000e+000,20.00000,    -0.17427,0.52731
882.58899, 99.46000,    -1.61243,74.52812,50.00000,0.0000e+000,20.00000,    -0.17598,0.52669
884.40900, 99.64000,    -1.61665,74.49596,50.00000,0.0000e+000,20.00000,    -0.17801,0.52605
886.22198, 99.82000,    -1.61951,74.46450,50.00000,0.0000e+000,20.00000,    -0.17975,0.52542
888.04602,100.00000,    -1.62185,74.43002,50.00000,0.0000e+000,20.00000,    -0.18161,0.52478
889.84302,100.18000,    -1.62061,74.39721,50.00000,0.0000e+000,20.00000,    -0.18364,0.52415
891.63702,100.36000,    -1.61928,74.36592,50.00000,0.0000e+000,20.00000,    -0.18545,0.52353
893.43500,100.54000,    -1.62122,74.33373,50.00000,0.0000e+000,20.00000,    -0.18734,0.52290
895.25201,100.72000,    -1.62379,74.30141,50.00000,0.0000e+000,20.00000,    -0.18947,0.52227
897.03400,100.90000,    -1.62099,74.26678,50.00000,0.0000e+000,20.00000,    -0.19173,0.52165
898.83502,101.08000,    -1.62115,74.23012,50.00000,0.0000e+000,20.00000,    -0.19355,0.52102
900.65802,101.26000,    -1.62629,74.19506,50.00000,0.0000e+000,20.00000,    -0.19526,0.52039
902.46802,101.44000,    -1.62867,74.16071,50.00000,0.0000e+000,20.00000,    -0.19681,0.51976
904.26501,101.62000,    -1.62894,74.12675,50.00000,0.0000e+000,20.00000,    -0.19847,0.51914
906.07202,101.80000,    -1.62803,74.09059,50.00000,0.0000e+000,20.00000,    -0.19999,0.51852
907.88000,101.98000,    -1.63000,74.05322,50.00000,0.0000e+000,20.00000,    -0.20206,0.51789
909.69299,102.16000,    -1.63202,74.01716,50.00000,0.0000e+000,20.00000,    -0.20372,0.51726
911.48798,102.34000,    -1.63017,73.97995,50.00000,0.0000e+000,20.00000,    -0.20502,0.51664
913.30798,102.52000,    -1.63035,73.94081,50.00000,0.0000e+000,20.00000,    -0.20694,0.51601
915.17297,102.70000,    -1.63894,73.90240,50.00000,0.0000e+000,20.00000,    -0.20881,0.51537
917.02600,102.88000,    -1.64569,73.86462,50.00000,0.0000e+000,20.00000,    -0.20966,0.51473
918.83600,103.06000,    -1.64309,73.82556,50.00000,0.0000e+000,20.00000,    -0.21051,0.51410
920.61102,103.24000,    -1.63592,73.78702,50.00000,0.0000e+000,20.00000,    -0.21209,0.51349
922.40002,103.42000,    -1.63254,73.74996,50.00000,0.0000e+000,20.00000,    -0.21373,0.51287
924.20697,103.60000,    -1.63258,73.71059,50.00000,0.0000e+000,20.00000,    -0.21458,0.51225
925.99103,103.78000,    -1.63299,73.66959,50.00000,0.0000e+000,20.00000,    -0.21497,0.51164
927.78497,103.96000,    -1.63124,73.63165,50.00000,0.0000e+000,20.00000,    -0.21600,0.51102
929.61499,104.14000,    -1.63372,73.59510,50.00000,0.0000e+000,20.00000,    -0.21715,0.51039
931.44598,104.32000,    -1.63551,73.55617,50.00000,0.0000e+000,20.00000,    -0.21797,0.50976
933.22400,104.50000,    -1.63123,73.51538,50.00000,0.0000e+000,20.00000,    -0.21849,0.50914
934.99402,104.68000,    -1.62787,73.47522,50.00000,0.0000e+000,20.00000,    -0.21844,0.50853
936.83099,104.86000,    -1.62814,73.43696,50.00000,0.0000e+000,20.00000,    -0.21912,0.50790
938.66101,105.04000,    -1.62934,73.39685,50.00000,0.0000e+000,20.00000,    -0.22071,0.50727
940.45001,105.22000,    -1.62508,73.35695,50.00000,0.0000e+000,20.00000,    -0.22257,0.50666
942.25702,105.40000,    -1.61880,73.31778,50.00000,0.0000e+000,20.00000,    -0.22267,0.50603
944.06000,105.58000,    -1.61300,73.27923,50.00000,0.0000e+000,20.00000,    -0.22207,0.50541
945.85400,105.76000,    -1.60683,73.23931,50.00000,0.0000e+000,20.00000,    -0.22185,0.50480
947.64801,105.94000,    -1.59985,73.19850,50.00000,0.0000e+000,20.00000,    -0.22188,0.50418
949.46100,106.12000,    -1.59363,73.15653,50.00000,0.0000e+000,20.00000,    -0.22178,0.50355
951.28497,106.30000,    -1.59159,73.11555,50.00000,0.0000e+000,20.00000,    -0.22100,0.50293
953.11401,106.48000,    -1.59058,73.07789,50.00000,0.0000e+000,20.00000,    -0.21960,0.50230
954.92297,106.66000,    -1.58673,73.03736,50.00000,0.0000e+000,20.00000,    -0.21811,0.50167
956.73700,106.84000,    -1.58240,72.99294,50.00000,0.0000e+000,20.00000,    -0.21593,0.50105
958.55103,107.02000,    -1.57910,72.94866,50.00000,0.0000e+000,20.00000,    -0.21316,0.50042
960.36401,107.20000,    -1.57571,72.90874,50.00000,0.0000e+000,20.00000,    -0.21026,0.49980
962.15997,107.38000,    -1.57348,72.87011,50.00000,0.0000e+000,20.00000,    -0.20723,0.49918
963.95697,107.56000,    -1.57045,72.83190,50.00000,0.0000e+000,20.00000,    -0.20267,0.49856
965.75000,107.74000,    -1.56826,72.79555,50.00000,0.0000e+000,20.00000,    -0.19658,0.49794
967.55103,107.92000,    -1.56714,72.75751,50.00000,0.0000e+000,20.00000,    -0.18980,0.49732
969.35400,108.10000,    -1.56622,72.71960,50.00000,0.0000e+000,20.00000,    -0.18258,0.49670
971.19000,108.28000,    -1.57091,72.68365,50.00000,0.0000e+000,20.00000,    -0.17609,0.49606
972.98798,108.46000,    -1.57272,72.65069,50.00000,0.0000e+000,20.00000,    -0.16911,0.49544
974.80603,108.64000,    -1.57439,72.61852,50.00000,0.0000e+000,20.00000,    -0.16082,0.49482
976.58002,108.82000,    -1.57011,72.58841,50.00000,0.0000e+000,20.00000,    -0.15177,0.49420
978.34998,109.00000,    -1.56711,72.55943,50.00000,0.0000e+000,20.00000,    -0.14334,0.49359
980.12097,109.18000,    -1.56869,72.53182,50.00000,0.0000e+000,20.00000,    -0.13664,0.49298
981.91803,109.36000,    -1.57269,72.50780,50.00000,0.0000e+000,20.00000,    -0.12882,0.49236
983.71399,109.54000,    -1.57477,72.48904,50.00000,0.0000e+000,20.00000,    -0.11876,0.49173
985.52502,109.72000,    -1.57827,72.47171,50.00000,0.0000e+000,20.00000,    -0.10830,0.49111
987.39203,109.90000,    -1.59085,72.45643,50.00000,0.0000e+000,20.00000,-9.7541e-002,0.49046
989.22101,110.08000,    -1.59612,72.44222,50.00000,0.0000e+000,20.00000,-8.5706e-002,0.48982
991.05298,110.26000,    -1.59803,72.42794,50.00000,0.0000e+000,20.00000,-7.6764e-002,0.48919
992.85901,110.44000,    -1.59732,72.41403,50.00000,0.0000e+000,20.00000,-7.1895e-002,0.48856
994.66998,110.62000,    -1.59506,72.40206,50.00000,0.0000e+000,20.00000,-6.8468e-002,0.48793
996.42902,110.80000,    -1.59242,72.39226,50.00000,0.0000e+000,20.00000,-6.4192e-002,0.48732
998.20398,110.98000,    -1.58958,72.38012,50.00000,0.0000e+000,20.00000,    -0.10205,0.48670
998.41302,111.00000,    -1.58994,72.37760,50.00000,0.0000e+000,20.00000,    -0.13860,0.48663