File: book/some_content/DG_ExpDat_A8%D28; 16-1-2025-2.csv
#FILE:                       ,A8%D28; 16-1-2025.ngb-ds3
#FORMAT:                     ,NETZSCH5
#IDENTITY:                   ,geopolymer paste
#DECIMAL:                    ,POINT
#SEPARATOR:                  ,COMMA
#MTYPE:                      ,DSC
#INSTRUMENT:                 ,Microlab TU Delft
#PROJECT:                    ,
#DATE/TIME:                  ,16/01/2025 7:55:55 AM
#CORR. FILE:                 ,Blank with cover; 13-1-2025.ngb-bs3
#LABORATORY:                 ,TU Delft Micro Lab
#OPERATOR:                   ,Ahmed
#REMARK:                     ,under Argon atmosphere, 10K/min
#SAMPLE:                     ,A8%D28;16-1-2025
#SAMPLE MASS /mg:            ,57
#MATERIAL:                   ,Geopolymer paste
#REFERENCE:                  ,blank
#REFERENCE MASS /mg:         ,0
#TYPE OF CRUCIBLE:           ,DSC/TG pan Al2O3
#SAMPLE CRUCIBLE MASS /mg:   ,0
#REFERENCE CRUCIBLE MASS /mg:,0
#CORR. CODE:                 ,020
#EXO:                        ,-1
#RANGE:                      ,40/10.0(K/min)/1000
#SEGMENT:                    ,S2/2

##Temp./øC,Time/min,DSC/(mW/mg),Mass/%,Gas Flow(purge1)/(ml/min),Gas Flow(purge2)/(ml/min),Gas Flow(protective)/(ml/min),DTG/(%/min),Sensit./(uV/mW)
 40.50700, 15.06000, 4.8617e-002,98.06658,50.00000,0.0000e+000,20.00000,    -0.11944,1.22624
 40.54500, 15.24000, 4.8619e-002,98.04458,50.00000,0.0000e+000,20.00000,    -0.12235,1.22619
 40.58100, 15.42000, 4.8457e-002,98.02220,50.00000,0.0000e+000,20.00000,    -0.12311,1.22614
 40.65300, 15.60000, 4.8843e-002,97.99989,50.00000,0.0000e+000,20.00000,    -0.12488,1.22604
 40.77300, 15.78000, 4.9909e-002,97.97757,50.00000,0.0000e+000,20.00000,    -0.12718,1.22588
 40.94000, 15.96000, 5.1382e-002,97.95463,50.00000,0.0000e+000,20.00000,    -0.13048,1.22565
 41.20000, 16.14000, 5.3724e-002,97.93140,50.00000,0.0000e+000,20.00000,    -0.13629,1.22529
 41.49400, 16.32000, 5.6736e-002,97.90770,50.00000,0.0000e+000,20.00000,    -0.14575,1.22488
 41.89000, 16.50000, 6.0631e-002,97.88327,50.00000,0.0000e+000,20.00000,    -0.15959,1.22434
 42.35700, 16.68000, 6.5169e-002,97.85816,50.00000,0.0000e+000,20.00000,    -0.17958,1.22369
 42.89200, 16.86000, 7.0473e-002,97.83194,50.00000,0.0000e+000,20.00000,    -0.20507,1.22295
 43.53100, 17.04000, 7.6657e-002,97.80377,50.00000,0.0000e+000,20.00000,    -0.22095,1.22207
 44.24000, 17.22000, 8.3372e-002,97.77329,50.00000,0.0000e+000,20.00000,    -0.23516,1.22110
 45.03400, 17.40000, 9.0655e-002,97.73948,50.00000,0.0000e+000,20.00000,    -0.25108,1.22000
 45.92400, 17.58000, 9.8412e-002,97.70181,50.00000,0.0000e+000,20.00000,    -0.26895,1.21878
 46.89000, 17.76000,     0.10684,97.65936,50.00000,0.0000e+000,20.00000,    -0.28864,1.21744
 47.91500, 17.94000,     0.11567,97.61158,50.00000,0.0000e+000,20.00000,    -0.31049,1.21603
 49.02900, 18.12000,     0.12490,97.55594,50.00000,0.0000e+000,20.00000,    -0.33462,1.21450
 50.25800, 18.30000,     0.13457,97.49214,50.00000,0.0000e+000,20.00000,    -0.36114,1.21281
 51.53800, 18.48000,     0.14471,97.41890,50.00000,0.0000e+000,20.00000,    -0.39021,1.21104
 52.90300, 18.66000,     0.15544,97.33458,50.00000,0.0000e+000,20.00000,    -0.42191,1.20916
 54.35100, 18.84000,     0.16647,97.25137,50.00000,0.0000e+000,20.00000,    -0.45618,1.20717
 55.87500, 19.02000,     0.17789,97.17792,50.00000,0.0000e+000,20.00000,    -0.49306,1.20507
 57.48600, 19.20000,     0.18989,97.09830,50.00000,0.0000e+000,20.00000,    -0.53249,1.20286
 59.13900, 19.38000,     0.20224,97.01190,50.00000,0.0000e+000,20.00000,    -0.57448,1.20058
 60.89100, 19.56000,     0.21512,96.91818,50.00000,0.0000e+000,20.00000,    -0.61895,1.19818
 62.69300, 19.74000,     0.22838,96.81645,50.00000,0.0000e+000,20.00000,    -0.66597,1.19570
 64.56100, 19.92000,     0.24255,96.70603,50.00000,0.0000e+000,20.00000,    -0.71502,1.19314
 66.49300, 20.10000,     0.25732,96.58626,50.00000,0.0000e+000,20.00000,    -0.76612,1.19048
 68.48100, 20.28000,     0.27277,96.45658,50.00000,0.0000e+000,20.00000,    -0.81910,1.18776
 70.51700, 20.46000,     0.28879,96.31636,50.00000,0.0000e+000,20.00000,    -0.87356,1.18497
 72.61100, 20.64000,     0.30578,96.16502,50.00000,0.0000e+000,20.00000,    -0.93143,1.18210
 74.73900, 20.82000,     0.32388,96.00197,50.00000,0.0000e+000,20.00000,    -0.99739,1.17918
 76.93100, 21.00000,     0.34323,95.82656,50.00000,0.0000e+000,20.00000,    -1.06593,1.17618
 79.15500, 21.18000,     0.36350,95.63815,50.00000,0.0000e+000,20.00000,    -1.13672,1.17314
 81.40700, 21.36000,     0.38491,95.43606,50.00000,0.0000e+000,20.00000,    -1.20939,1.17007
 83.69800, 21.54000,     0.40780,95.21961,50.00000,0.0000e+000,20.00000,    -1.28343,1.16694
 86.03000, 21.72000,     0.43233,94.98825,50.00000,0.0000e+000,20.00000,    -1.35836,1.16376
 88.39000, 21.90000,     0.45833,94.74140,50.00000,0.0000e+000,20.00000,    -1.43366,1.16054
 90.78300, 22.08000,     0.48582,94.47855,50.00000,0.0000e+000,20.00000,    -1.50880,1.15729
 93.16300, 22.26000,     0.51527,94.19948,50.00000,0.0000e+000,20.00000,    -1.58331,1.15405
 95.59300, 22.44000,     0.54616,93.90423,50.00000,0.0000e+000,20.00000,    -1.65670,1.15075
 98.02800, 22.62000,     0.57912,93.59302,50.00000,0.0000e+000,20.00000,    -1.72853,1.14745
100.47300, 22.80000,     0.61374,93.26620,50.00000,0.0000e+000,20.00000,    -1.79831,1.14413
102.90700, 22.98000,     0.65046,92.92435,50.00000,0.0000e+000,20.00000,    -1.86552,1.14084
105.36200, 23.16000,     0.68894,92.56829,50.00000,0.0000e+000,20.00000,    -1.92983,1.13752
107.79000, 23.34000,     0.72975,92.19910,50.00000,0.0000e+000,20.00000,    -1.99084,1.13424
110.24400, 23.52000,     0.77191,91.81789,50.00000,0.0000e+000,20.00000,    -2.04819,1.13093
112.66600, 23.70000,     0.81589,91.42591,50.00000,0.0000e+000,20.00000,    -2.10151,1.12767
115.09600, 23.88000,     0.86136,91.02445,50.00000,0.0000e+000,20.00000,    -2.15048,1.12440
117.51000, 24.06000,     0.90847,90.61472,50.00000,0.0000e+000,20.00000,    -2.19483,1.12116
119.94100, 24.24000,     0.95742,90.19787,50.00000,0.0000e+000,20.00000,    -2.23437,1.11790
122.36200, 24.42000,     1.00737,89.77495,50.00000,0.0000e+000,20.00000,    -2.26895,1.11466
124.78000, 24.60000,     1.05712,89.34704,50.00000,0.0000e+000,20.00000,    -2.29846,1.11143
127.16600, 24.78000,     1.10702,88.91551,50.00000,0.0000e+000,20.00000,    -2.32285,1.10824
129.53999, 24.96000,     1.15641,88.48089,50.00000,0.0000e+000,20.00000,    -2.34212,1.10508
131.91499, 25.14000,     1.20508,88.04399,50.00000,0.0000e+000,20.00000,    -2.35635,1.10192
134.26100, 25.32000,     1.25248,87.60551,50.00000,0.0000e+000,20.00000,    -2.36567,1.09880
136.59200, 25.50000,     1.29861,87.16622,50.00000,0.0000e+000,20.00000,    -2.37015,1.09571
138.89400, 25.68000,     1.34213,86.72682,50.00000,0.0000e+000,20.00000,    -2.36993,1.09266
141.22000, 25.86000,     1.38249,86.28799,50.00000,0.0000e+000,20.00000,    -2.36514,1.08959
143.49600, 26.04000,     1.41761,85.85041,50.00000,0.0000e+000,20.00000,    -2.35593,1.08658
145.77299, 26.22000,     1.44647,85.41487,50.00000,0.0000e+000,20.00000,    -2.34240,1.08358
148.01500, 26.40000,     1.46671,84.98207,50.00000,0.0000e+000,20.00000,    -2.32463,1.08063
150.27299, 26.58000,     1.47672,84.55274,50.00000,0.0000e+000,20.00000,    -2.30285,1.07767
152.52200, 26.76000,     1.47496,84.12764,50.00000,0.0000e+000,20.00000,    -2.27699,1.07472
154.77499, 26.94000,     1.45999,83.70752,50.00000,0.0000e+000,20.00000,    -2.24708,1.07177
156.99400, 27.12000,     1.43107,83.29309,50.00000,0.0000e+000,20.00000,    -2.21308,1.06888
159.24699, 27.30000,     1.38902,82.88520,50.00000,0.0000e+000,20.00000,    -2.17498,1.06594
161.49001, 27.48000,     1.33546,82.48471,50.00000,0.0000e+000,20.00000,    -2.13280,1.06302
163.71201, 27.66000,     1.27196,82.09239,50.00000,0.0000e+000,20.00000,    -2.08658,1.06014
165.96201, 27.84000,     1.20194,81.70880,50.00000,0.0000e+000,20.00000,    -2.03637,1.05722
168.18500, 28.02000,     1.12732,81.33471,50.00000,0.0000e+000,20.00000,    -1.98233,1.05434
170.42200, 28.20000,     1.05108,80.97078,50.00000,0.0000e+000,20.00000,    -1.92465,1.05146
172.64900, 28.38000,     0.97492,80.61767,50.00000,0.0000e+000,20.00000,    -1.86359,1.04859
174.85001, 28.56000,     0.90081,80.27615,50.00000,0.0000e+000,20.00000,    -1.79943,1.04576
177.07600, 28.74000,     0.82948,79.94691,50.00000,0.0000e+000,20.00000,    -1.73253,1.04290
179.25999, 28.92000,     0.76178,79.63082,50.00000,0.0000e+000,20.00000,    -1.66332,1.04011
181.43800, 29.10000,     0.69826,79.32868,50.00000,0.0000e+000,20.00000,    -1.59229,1.03732
183.60001, 29.28000,     0.63902,79.04114,50.00000,0.0000e+000,20.00000,    -1.51996,1.03457
185.73100, 29.46000,     0.58380,78.76874,50.00000,0.0000e+000,20.00000,    -1.44686,1.03186
187.85100, 29.64000,     0.53289,78.51200,50.00000,0.0000e+000,20.00000,    -1.37344,1.02916
189.92500, 29.82000,     0.48570,78.27121,50.00000,0.0000e+000,20.00000,    -1.30016,1.02654
191.99899, 30.00000,     0.44199,78.04635,50.00000,0.0000e+000,20.00000,    -1.22751,1.02392
194.05000, 30.18000,     0.40182,77.83724,50.00000,0.0000e+000,20.00000,    -1.15587,1.02133
196.05400, 30.36000,     0.36498,77.64361,50.00000,0.0000e+000,20.00000,    -1.08569,1.01881
198.04700, 30.54000,     0.33048,77.46496,50.00000,0.0000e+000,20.00000,    -1.01732,1.01630
200.00700, 30.72000,     0.29863,77.30050,50.00000,0.0000e+000,20.00000,    -0.95114,1.01384
201.95000, 30.90000,     0.26896,77.14925,50.00000,0.0000e+000,20.00000,    -0.88752,1.01141
203.86900, 31.08000,     0.24141,77.01019,50.00000,0.0000e+000,20.00000,    -0.82676,1.00902
205.75700, 31.26000,     0.21561,76.88217,50.00000,0.0000e+000,20.00000,    -0.76912,1.00667
207.65199, 31.44000,     0.19144,76.76412,50.00000,0.0000e+000,20.00000,    -0.71483,1.00431
209.51401, 31.62000,     0.16867,76.65507,50.00000,0.0000e+000,20.00000,    -0.66405,1.00200
211.35300, 31.80000,     0.14742,76.55397,50.00000,0.0000e+000,20.00000,    -0.61686,0.99972
213.16901, 31.98000,     0.12744,76.45997,50.00000,0.0000e+000,20.00000,    -0.57329,0.99748
214.98500, 32.16000,     0.10803,76.37224,50.00000,0.0000e+000,20.00000,    -0.53333,0.99524
216.78799, 32.34000, 8.9635e-002,76.29016,50.00000,0.0000e+000,20.00000,    -0.49691,0.99302
218.57899, 32.52000, 7.2678e-002,76.21318,50.00000,0.0000e+000,20.00000,    -0.46388,0.99083
220.35600, 32.70000, 5.6185e-002,76.14073,50.00000,0.0000e+000,20.00000,    -0.43400,0.98865
222.10500, 32.88000, 4.0839e-002,76.07240,50.00000,0.0000e+000,20.00000,    -0.40701,0.98651
223.86800, 33.06000, 2.6271e-002,76.00780,50.00000,0.0000e+000,20.00000,    -0.38268,0.98436
225.61400, 33.24000, 1.3055e-002,75.94659,50.00000,0.0000e+000,20.00000,    -0.36075,0.98223
227.35899, 33.42000, 2.3216e-004,75.88849,50.00000,0.0000e+000,20.00000,    -0.34096,0.98011
229.09399, 33.60000,-1.0935e-002,75.83327,50.00000,0.0000e+000,20.00000,    -0.32302,0.97801
230.81400, 33.78000,-2.1094e-002,75.78064,50.00000,0.0000e+000,20.00000,    -0.30675,0.97593
232.53000, 33.96000,-3.0320e-002,75.73037,50.00000,0.0000e+000,20.00000,    -0.29195,0.97386
234.23900, 34.14000,-3.8854e-002,75.68229,50.00000,0.0000e+000,20.00000,    -0.27841,0.97180
235.93700, 34.32000,-4.6804e-002,75.63617,50.00000,0.0000e+000,20.00000,    -0.26603,0.96976
237.64101, 34.50000,-5.4454e-002,75.59190,50.00000,0.0000e+000,20.00000,    -0.25467,0.96772
239.33900, 34.68000,-6.1929e-002,75.54944,50.00000,0.0000e+000,20.00000,    -0.24425,0.96568
241.03500, 34.86000,-6.8934e-002,75.50851,50.00000,0.0000e+000,20.00000,    -0.23470,0.96366
242.72400, 35.04000,-7.5899e-002,75.46896,50.00000,0.0000e+000,20.00000,    -0.22595,0.96165
244.41600, 35.22000,-8.2530e-002,75.43073,50.00000,0.0000e+000,20.00000,    -0.21790,0.95964
246.09000, 35.40000,-8.8809e-002,75.39383,50.00000,0.0000e+000,20.00000,    -0.21051,0.95765
247.77800, 35.58000,-9.5269e-002,75.35809,50.00000,0.0000e+000,20.00000,    -0.20371,0.95565
249.45399, 35.76000,    -0.10125,75.32340,50.00000,0.0000e+000,20.00000,    -0.19745,0.95367
251.13699, 35.94000,    -0.10737,75.28981,50.00000,0.0000e+000,20.00000,    -0.19169,0.95169
252.82401, 36.12000,    -0.11353,75.25719,50.00000,0.0000e+000,20.00000,    -0.18640,0.94971
254.51199, 36.30000,    -0.11926,75.22548,50.00000,0.0000e+000,20.00000,    -0.18155,0.94773
256.19901, 36.48000,    -0.12485,75.19454,50.00000,0.0000e+000,20.00000,    -0.17714,0.94575
257.89700, 36.66000,    -0.13034,75.16419,50.00000,0.0000e+000,20.00000,    -0.17307,0.94377
259.59100, 36.84000,    -0.13560,75.13442,50.00000,0.0000e+000,20.00000,    -0.16933,0.94180
261.28000, 37.02000,    -0.14109,75.10517,50.00000,0.0000e+000,20.00000,    -0.16589,0.93983
262.97198, 37.20000,    -0.14596,75.07648,50.00000,0.0000e+000,20.00000,    -0.16278,0.93787
264.67700, 37.38000,    -0.15071,75.04824,50.00000,0.0000e+000,20.00000,    -0.15996,0.93590
266.38800, 37.56000,    -0.15570,75.02044,50.00000,0.0000e+000,20.00000,    -0.15739,0.93393
268.09601, 37.74000,    -0.16032,74.99303,50.00000,0.0000e+000,20.00000,    -0.15512,0.93196
269.80099, 37.92000,    -0.16518,74.96593,50.00000,0.0000e+000,20.00000,    -0.15309,0.93000
271.50299, 38.10000,    -0.16948,74.93906,50.00000,0.0000e+000,20.00000,    -0.15132,0.92806
273.20401, 38.28000,    -0.17392,74.91244,50.00000,0.0000e+000,20.00000,    -0.14976,0.92611
274.92801, 38.46000,    -0.17828,74.88610,50.00000,0.0000e+000,20.00000,    -0.14839,0.92415
276.65500, 38.64000,    -0.18272,74.86001,50.00000,0.0000e+000,20.00000,    -0.14720,0.92218
278.37399, 38.82000,    -0.18749,74.83410,50.00000,0.0000e+000,20.00000,    -0.14620,0.92024
280.09201, 39.00000,    -0.19195,74.80837,50.00000,0.0000e+000,20.00000,    -0.14540,0.91829
281.81799, 39.18000,    -0.19564,74.78275,50.00000,0.0000e+000,20.00000,    -0.14479,0.91635
283.55399, 39.36000,    -0.19953,74.75726,50.00000,0.0000e+000,20.00000,    -0.14436,0.91439
285.27600, 39.54000,    -0.20325,74.73181,50.00000,0.0000e+000,20.00000,    -0.14409,0.91246
286.98300, 39.72000,    -0.20694,74.70642,50.00000,0.0000e+000,20.00000,    -0.14399,0.91055
288.70700, 39.90000,    -0.21065,74.68108,50.00000,0.0000e+000,20.00000,    -0.14403,0.90863
290.43399, 40.08000,    -0.21492,74.65574,50.00000,0.0000e+000,20.00000,    -0.14424,0.90670
292.17700, 40.26000,    -0.21904,74.63033,50.00000,0.0000e+000,20.00000,    -0.14462,0.90477
293.91901, 40.44000,    -0.22324,74.60482,50.00000,0.0000e+000,20.00000,    -0.14519,0.90284
295.64899, 40.62000,    -0.22766,74.57918,50.00000,0.0000e+000,20.00000,    -0.14595,0.90093
297.39200, 40.80000,    -0.23166,74.55335,50.00000,0.0000e+000,20.00000,    -0.14690,0.89901
299.15399, 40.98000,    -0.23518,74.52730,50.00000,0.0000e+000,20.00000,    -0.14802,0.89708
300.91299, 41.16000,    -0.23894,74.50104,50.00000,0.0000e+000,20.00000,    -0.14935,0.89515
302.64801, 41.34000,    -0.24228,74.47460,50.00000,0.0000e+000,20.00000,    -0.15084,0.89326
304.41199, 41.52000,    -0.24590,74.44790,50.00000,0.0000e+000,20.00000,    -0.15250,0.89134
306.17200, 41.70000,    -0.24947,74.42086,50.00000,0.0000e+000,20.00000,    -0.15437,0.88942
307.93701, 41.88000,    -0.25305,74.39350,50.00000,0.0000e+000,20.00000,    -0.15643,0.88751
309.70700, 42.06000,    -0.25651,74.36580,50.00000,0.0000e+000,20.00000,    -0.15863,0.88560
311.46399, 42.24000,    -0.25965,74.33765,50.00000,0.0000e+000,20.00000,    -0.16097,0.88371
313.25400, 42.42000,    -0.26277,74.30902,50.00000,0.0000e+000,20.00000,    -0.16345,0.88179
315.00800, 42.60000,    -0.26576,74.27988,50.00000,0.0000e+000,20.00000,    -0.16602,0.87991
316.77499, 42.78000,    -0.26842,74.25023,50.00000,0.0000e+000,20.00000,    -0.16867,0.87803
318.54300, 42.96000,    -0.27117,74.21996,50.00000,0.0000e+000,20.00000,    -0.17143,0.87615
320.29700, 43.14000,    -0.27366,74.18913,50.00000,0.0000e+000,20.00000,    -0.17427,0.87429
322.07001, 43.32000,    -0.27630,74.15776,50.00000,0.0000e+000,20.00000,    -0.17717,0.87241
323.83600, 43.50000,    -0.27891,74.12571,50.00000,0.0000e+000,20.00000,    -0.18013,0.87055
325.60001, 43.68000,    -0.28163,74.09291,50.00000,0.0000e+000,20.00000,    -0.18312,0.86870
327.36600, 43.86000,    -0.28393,74.05958,50.00000,0.0000e+000,20.00000,    -0.18612,0.86685
329.14801, 44.04000,    -0.28615,74.02563,50.00000,0.0000e+000,20.00000,    -0.18910,0.86498
330.92700, 44.22000,    -0.28769,73.99103,50.00000,0.0000e+000,20.00000,    -0.19205,0.86313
332.68600, 44.40000,    -0.28927,73.95592,50.00000,0.0000e+000,20.00000,    -0.19495,0.86131
334.46701, 44.58000,    -0.29084,73.92029,50.00000,0.0000e+000,20.00000,    -0.19780,0.85946
336.26001, 44.76000,    -0.29217,73.88406,50.00000,0.0000e+000,20.00000,    -0.20059,0.85761
338.02100, 44.94000,    -0.29335,73.84736,50.00000,0.0000e+000,20.00000,    -0.20329,0.85580
339.80200, 45.12000,    -0.29448,73.81016,50.00000,0.0000e+000,20.00000,    -0.20589,0.85398
341.57599, 45.30000,    -0.29513,73.77244,50.00000,0.0000e+000,20.00000,    -0.20834,0.85216
343.35800, 45.48000,    -0.29617,73.73425,50.00000,0.0000e+000,20.00000,    -0.21061,0.85035
345.12201, 45.66000,    -0.29713,73.69569,50.00000,0.0000e+000,20.00000,    -0.21276,0.84856
346.89499, 45.84000,    -0.29842,73.65678,50.00000,0.0000e+000,20.00000,    -0.21475,0.84676
348.67200, 46.02000,    -0.29983,73.61752,50.00000,0.0000e+000,20.00000,    -0.21657,0.84497
350.44101, 46.20000,    -0.30120,73.57790,50.00000,0.0000e+000,20.00000,    -0.21822,0.84319
352.21500, 46.38000,    -0.30322,73.53795,50.00000,0.0000e+000,20.00000,    -0.21970,0.84141
353.98999, 46.56000,    -0.30518,73.49765,50.00000,0.0000e+000,20.00000,    -0.22095,0.83964
355.77100, 46.74000,    -0.30749,73.45707,50.00000,0.0000e+000,20.00000,    -0.22202,0.83786
357.57599, 46.92000,    -0.31005,73.41632,50.00000,0.0000e+000,20.00000,    -0.22290,0.83607
359.35901, 47.10000,    -0.31233,73.37545,50.00000,0.0000e+000,20.00000,    -0.22359,0.83431
361.15100, 47.28000,    -0.31506,73.33446,50.00000,0.0000e+000,20.00000,    -0.22405,0.83254
362.94199, 47.46000,    -0.31725,73.29335,50.00000,0.0000e+000,20.00000,    -0.22433,0.83078
364.72601, 47.64000,    -0.31998,73.25221,50.00000,0.0000e+000,20.00000,    -0.22443,0.82903
366.52301, 47.82000,    -0.32297,73.21108,50.00000,0.0000e+000,20.00000,    -0.22433,0.82728
368.30399, 48.00000,    -0.32571,73.16998,50.00000,0.0000e+000,20.00000,    -0.22399,0.82555
370.06201, 48.18000,    -0.32858,73.12903,50.00000,0.0000e+000,20.00000,    -0.22345,0.82384
371.84799, 48.36000,    -0.33186,73.08825,50.00000,0.0000e+000,20.00000,    -0.22266,0.82212
373.62399, 48.54000,    -0.33565,73.04770,50.00000,0.0000e+000,20.00000,    -0.22164,0.82041
375.41400, 48.72000,    -0.34006,73.00733,50.00000,0.0000e+000,20.00000,    -0.22040,0.81869
377.19101, 48.90000,    -0.34477,72.96715,50.00000,0.0000e+000,20.00000,    -0.21896,0.81699
378.97299, 49.08000,    -0.34941,72.92727,50.00000,0.0000e+000,20.00000,    -0.21730,0.81530
380.75601, 49.26000,    -0.35426,72.88768,50.00000,0.0000e+000,20.00000,    -0.21540,0.81360
382.54901, 49.44000,    -0.35886,72.84842,50.00000,0.0000e+000,20.00000,    -0.21330,0.81191
384.32700, 49.62000,    -0.36403,72.80953,50.00000,0.0000e+000,20.00000,    -0.21103,0.81023
386.12900, 49.80000,    -0.36910,72.77112,50.00000,0.0000e+000,20.00000,    -0.20856,0.80854
387.89700, 49.98000,    -0.37443,72.73313,50.00000,0.0000e+000,20.00000,    -0.20595,0.80688
389.67401, 50.16000,    -0.37918,72.69568,50.00000,0.0000e+000,20.00000,    -0.20322,0.80522
391.43900, 50.34000,    -0.38462,72.65879,50.00000,0.0000e+000,20.00000,    -0.20036,0.80358
393.21600, 50.52000,    -0.39028,72.62249,50.00000,0.0000e+000,20.00000,    -0.19739,0.80194
394.99399, 50.70000,    -0.39698,72.58681,50.00000,0.0000e+000,20.00000,    -0.19431,0.80030
396.79501, 50.88000,    -0.40327,72.55178,50.00000,0.0000e+000,20.00000,    -0.19113,0.79864
398.56601, 51.06000,    -0.40973,72.51751,50.00000,0.0000e+000,20.00000,    -0.18788,0.79702
400.35400, 51.24000,    -0.41532,72.48397,50.00000,0.0000e+000,20.00000,    -0.18455,0.79539
402.15900, 51.42000,    -0.42050,72.45104,50.00000,0.0000e+000,20.00000,    -0.18119,0.79375
403.93900, 51.60000,    -0.42588,72.41882,50.00000,0.0000e+000,20.00000,    -0.17781,0.79213
405.73300, 51.78000,    -0.43063,72.38728,50.00000,0.0000e+000,20.00000,    -0.17442,0.79051
407.51300, 51.96000,    -0.43554,72.35636,50.00000,0.0000e+000,20.00000,    -0.17103,0.78891
409.30399, 52.14000,    -0.44078,72.32613,50.00000,0.0000e+000,20.00000,    -0.16765,0.78731
411.09500, 52.32000,    -0.44582,72.29650,50.00000,0.0000e+000,20.00000,    -0.16430,0.78571
412.89001, 52.50000,    -0.45075,72.26745,50.00000,0.0000e+000,20.00000,    -0.16099,0.78411
414.67099, 52.68000,    -0.45512,72.23903,50.00000,0.0000e+000,20.00000,    -0.15775,0.78253
416.47198, 52.86000,    -0.45958,72.21122,50.00000,0.0000e+000,20.00000,    -0.15460,0.78094
418.25400, 53.04000,    -0.46378,72.18399,50.00000,0.0000e+000,20.00000,    -0.15156,0.77938
420.02499, 53.22000,    -0.46806,72.15724,50.00000,0.0000e+000,20.00000,    -0.14858,0.77782
421.81100, 53.40000,    -0.47250,72.13100,50.00000,0.0000e+000,20.00000,    -0.14568,0.77626
423.59799, 53.58000,    -0.47697,72.10529,50.00000,0.0000e+000,20.00000,    -0.14287,0.77471
425.39200, 53.76000,    -0.48148,72.08007,50.00000,0.0000e+000,20.00000,    -0.14013,0.77316
427.17300, 53.94000,    -0.48603,72.05534,50.00000,0.0000e+000,20.00000,    -0.13751,0.77162
428.94800, 54.12000,    -0.49103,72.03114,50.00000,0.0000e+000,20.00000,    -0.13499,0.77009
430.75201, 54.30000,    -0.49691,72.00740,50.00000,0.0000e+000,20.00000,    -0.13254,0.76855
432.57999, 54.48000,    -0.50251,71.98406,50.00000,0.0000e+000,20.00000,    -0.13020,0.76699
434.38400, 54.66000,    -0.50766,71.96109,50.00000,0.0000e+000,20.00000,    -0.12794,0.76546
436.19299, 54.84000,    -0.51221,71.93851,50.00000,0.0000e+000,20.00000,    -0.12576,0.76393
437.99100, 55.02000,    -0.51590,71.91633,50.00000,0.0000e+000,20.00000,    -0.12363,0.76241
439.78500, 55.20000,    -0.51923,71.89454,50.00000,0.0000e+000,20.00000,    -0.12156,0.76090
441.57800, 55.38000,    -0.52200,71.87312,50.00000,0.0000e+000,20.00000,    -0.11957,0.75941
443.35999, 55.56000,    -0.52494,71.85204,50.00000,0.0000e+000,20.00000,    -0.11764,0.75792
445.14099, 55.74000,    -0.52841,71.83125,50.00000,0.0000e+000,20.00000,    -0.11577,0.75644
446.92401, 55.92000,    -0.53173,71.81073,50.00000,0.0000e+000,20.00000,    -0.11399,0.75497
448.69601, 56.10000,    -0.53452,71.79048,50.00000,0.0000e+000,20.00000,    -0.11228,0.75351
450.46399, 56.28000,    -0.53768,71.77048,50.00000,0.0000e+000,20.00000,    -0.11058,0.75206
452.25201, 56.46000,    -0.54142,71.75078,50.00000,0.0000e+000,20.00000,    -0.10893,0.75060
454.01999, 56.64000,    -0.54513,71.73139,50.00000,0.0000e+000,20.00000,    -0.10733,0.74916
455.81299, 56.82000,    -0.54985,71.71233,50.00000,0.0000e+000,20.00000,    -0.10578,0.74771
457.58600, 57.00000,    -0.55428,71.69353,50.00000,0.0000e+000,20.00000,    -0.10427,0.74628
459.36899, 57.18000,    -0.55898,71.67497,50.00000,0.0000e+000,20.00000,    -0.10281,0.74484
461.15799, 57.36000,    -0.56456,71.65666,50.00000,0.0000e+000,20.00000,    -0.10138,0.74341
462.94101, 57.54000,    -0.56924,71.63867,50.00000,0.0000e+000,20.00000,-9.9975e-002,0.74199
464.73499, 57.72000,    -0.57361,71.62087,50.00000,0.0000e+000,20.00000,-9.8598e-002,0.74057
466.53000, 57.90000,    -0.57855,71.60329,50.00000,0.0000e+000,20.00000,-9.7232e-002,0.73915
468.32501, 58.08000,    -0.58360,71.58604,50.00000,0.0000e+000,20.00000,-9.5878e-002,0.73773
470.12799, 58.26000,    -0.58834,71.56902,50.00000,0.0000e+000,20.00000,-9.4541e-002,0.73632
471.93500, 58.44000,    -0.59315,71.55220,50.00000,0.0000e+000,20.00000,-9.3217e-002,0.73491
473.74301, 58.62000,    -0.59819,71.53559,50.00000,0.0000e+000,20.00000,-9.1936e-002,0.73350
475.54700, 58.80000,    -0.60280,71.51921,50.00000,0.0000e+000,20.00000,-9.0682e-002,0.73210
477.33600, 58.98000,    -0.60709,71.50305,50.00000,0.0000e+000,20.00000,-8.9447e-002,0.73072
479.14099, 59.16000,    -0.61047,71.48712,50.00000,0.0000e+000,20.00000,-8.8238e-002,0.72933
480.92899, 59.34000,    -0.61320,71.47138,50.00000,0.0000e+000,20.00000,-8.7070e-002,0.72797
482.69501, 59.52000,    -0.61564,71.45584,50.00000,0.0000e+000,20.00000,-8.5915e-002,0.72662
484.46899, 59.70000,    -0.61891,71.44049,50.00000,0.0000e+000,20.00000,-8.4776e-002,0.72527
486.25101, 59.88000,    -0.62279,71.42538,50.00000,0.0000e+000,20.00000,-8.3690e-002,0.72393
488.04999, 60.06000,    -0.62759,71.41048,50.00000,0.0000e+000,20.00000,-8.2631e-002,0.72257
489.84900, 60.24000,    -0.63238,71.39584,50.00000,0.0000e+000,20.00000,-8.1598e-002,0.72123
491.63400, 60.42000,    -0.63709,71.38139,50.00000,0.0000e+000,20.00000,-8.0592e-002,0.71989
493.44601, 60.60000,    -0.64126,71.36711,50.00000,0.0000e+000,20.00000,-7.9631e-002,0.71855
495.24500, 60.78000,    -0.64600,71.35300,50.00000,0.0000e+000,20.00000,-7.8707e-002,0.71721
497.02899, 60.96000,    -0.64926,71.33904,50.00000,0.0000e+000,20.00000,-7.7826e-002,0.71590
498.83801, 61.14000,    -0.65176,71.32525,50.00000,0.0000e+000,20.00000,-7.6973e-002,0.71457
500.61200, 61.32000,    -0.65444,71.31162,50.00000,0.0000e+000,20.00000,-7.6164e-002,0.71328
502.41199, 61.50000,    -0.65770,71.29814,50.00000,0.0000e+000,20.00000,-7.5382e-002,0.71197
504.20700, 61.68000,    -0.66112,71.28480,50.00000,0.0000e+000,20.00000,-7.4643e-002,0.71067
506.00000, 61.86000,    -0.66499,71.27160,50.00000,0.0000e+000,20.00000,-7.3934e-002,0.70937
507.79199, 62.04000,    -0.66843,71.25850,50.00000,0.0000e+000,20.00000,-7.3268e-002,0.70809
509.59201, 62.22000,    -0.67169,71.24553,50.00000,0.0000e+000,20.00000,-7.2629e-002,0.70680
511.40302, 62.40000,    -0.67546,71.23262,50.00000,0.0000e+000,20.00000,-7.2020e-002,0.70551
513.21802, 62.58000,    -0.67884,71.21978,50.00000,0.0000e+000,20.00000,-7.1447e-002,0.70422
514.99597, 62.76000,    -0.68072,71.20703,50.00000,0.0000e+000,20.00000,-7.0901e-002,0.70297
516.78302, 62.94000,    -0.68207,71.19437,50.00000,0.0000e+000,20.00000,-7.0378e-002,0.70171
518.56702, 63.12000,    -0.68392,71.18173,50.00000,0.0000e+000,20.00000,-6.9885e-002,0.70046
520.36603, 63.30000,    -0.68685,71.16921,50.00000,0.0000e+000,20.00000,-6.9402e-002,0.69921
522.20697, 63.48000,    -0.69306,71.15675,50.00000,0.0000e+000,20.00000,-6.8918e-002,0.69793
524.04999, 63.66000,    -0.69928,71.14438,50.00000,0.0000e+000,20.00000,-6.8454e-002,0.69665
525.87500, 63.84000,    -0.70312,71.13214,50.00000,0.0000e+000,20.00000,-6.8019e-002,0.69540
527.70001, 64.02000,    -0.70483,71.11999,50.00000,0.0000e+000,20.00000,-6.7603e-002,0.69415
529.48901, 64.20000,    -0.70511,71.10789,50.00000,0.0000e+000,20.00000,-6.7172e-002,0.69293
531.29102, 64.38000,    -0.70556,71.09584,50.00000,0.0000e+000,20.00000,-6.6746e-002,0.69171
533.07202, 64.56000,    -0.70621,71.08385,50.00000,0.0000e+000,20.00000,-6.6332e-002,0.69050
534.85602, 64.74000,    -0.70748,71.07193,50.00000,0.0000e+000,20.00000,-6.5912e-002,0.68930
536.64301, 64.92000,    -0.70879,71.06008,50.00000,0.0000e+000,20.00000,-6.5461e-002,0.68810
538.41699, 65.10000,    -0.71069,71.04830,50.00000,0.0000e+000,20.00000,-6.5023e-002,0.68692
540.19299, 65.28000,    -0.71213,71.03671,50.00000,0.0000e+000,20.00000,-6.4585e-002,0.68574
541.95898, 65.46000,    -0.71424,71.02517,50.00000,0.0000e+000,20.00000,-6.4151e-002,0.68457
543.73297, 65.64000,    -0.71642,71.01364,50.00000,0.0000e+000,20.00000,-6.3730e-002,0.68340
545.52399, 65.82000,    -0.72013,71.00215,50.00000,0.0000e+000,20.00000,-6.3351e-002,0.68223
547.33197, 66.00000,    -0.72423,70.99080,50.00000,0.0000e+000,20.00000,-6.2986e-002,0.68105
549.13300, 66.18000,    -0.72735,70.97951,50.00000,0.0000e+000,20.00000,-6.2620e-002,0.67988
550.92297, 66.36000,    -0.72914,70.96824,50.00000,0.0000e+000,20.00000,-6.2247e-002,0.67872
552.71600, 66.54000,    -0.73056,70.95707,50.00000,0.0000e+000,20.00000,-6.1869e-002,0.67756
554.49200, 66.72000,    -0.73148,70.94607,50.00000,0.0000e+000,20.00000,-6.1503e-002,0.67642
556.27100, 66.90000,    -0.73279,70.93513,50.00000,0.0000e+000,20.00000,-6.1138e-002,0.67529
558.06097, 67.08000,    -0.73462,70.92425,50.00000,0.0000e+000,20.00000,-6.0794e-002,0.67415
559.86200, 67.26000,    -0.73730,70.91343,50.00000,0.0000e+000,20.00000,-6.0468e-002,0.67301
561.65900, 67.44000,    -0.73997,70.90271,50.00000,0.0000e+000,20.00000,-6.0143e-002,0.67187
563.46802, 67.62000,    -0.74204,70.89194,50.00000,0.0000e+000,20.00000,-5.9810e-002,0.67074
565.25098, 67.80000,    -0.74422,70.88116,50.00000,0.0000e+000,20.00000,-5.9504e-002,0.66962
567.06702, 67.98000,    -0.74562,70.87044,50.00000,0.0000e+000,20.00000,-5.9202e-002,0.66849
568.84998, 68.16000,    -0.74655,70.85979,50.00000,0.0000e+000,20.00000,-5.8897e-002,0.66739
570.63800, 68.34000,    -0.74773,70.84922,50.00000,0.0000e+000,20.00000,-5.8607e-002,0.66629
572.44897, 68.52000,    -0.74948,70.83869,50.00000,0.0000e+000,20.00000,-5.8355e-002,0.66517
574.24103, 68.70000,    -0.75192,70.82823,50.00000,0.0000e+000,20.00000,-5.8126e-002,0.66408
576.05402, 68.88000,    -0.75475,70.81785,50.00000,0.0000e+000,20.00000,-5.7910e-002,0.66298
577.84802, 69.06000,    -0.75674,70.80750,50.00000,0.0000e+000,20.00000,-5.7708e-002,0.66189
579.65503, 69.24000,    -0.75876,70.79716,50.00000,0.0000e+000,20.00000,-5.7544e-002,0.66080
581.43103, 69.42000,    -0.75895,70.78686,50.00000,0.0000e+000,20.00000,-5.7376e-002,0.65973
583.22302, 69.60000,    -0.75866,70.77661,50.00000,0.0000e+000,20.00000,-5.7217e-002,0.65866
585.03601, 69.78000,    -0.76072,70.76641,50.00000,0.0000e+000,20.00000,-5.7087e-002,0.65758
586.85797, 69.96000,    -0.76531,70.75625,50.00000,0.0000e+000,20.00000,-5.6961e-002,0.65650
588.68701, 70.14000,    -0.76806,70.74611,50.00000,0.0000e+000,20.00000,-5.6858e-002,0.65542
590.46698, 70.32000,    -0.76833,70.73600,50.00000,0.0000e+000,20.00000,-5.6781e-002,0.65438
592.27197, 70.50000,    -0.76777,70.72589,50.00000,0.0000e+000,20.00000,-5.6751e-002,0.65332
594.07001, 70.68000,    -0.76865,70.71579,50.00000,0.0000e+000,20.00000,-5.6767e-002,0.65227
595.87500, 70.86000,    -0.77127,70.70570,50.00000,0.0000e+000,20.00000,-5.6832e-002,0.65123
597.69000, 71.04000,    -0.77317,70.69557,50.00000,0.0000e+000,20.00000,-5.6935e-002,0.65018
599.49200, 71.22000,    -0.77496,70.68544,50.00000,0.0000e+000,20.00000,-5.7074e-002,0.64914
601.30103, 71.40000,    -0.77615,70.67525,50.00000,0.0000e+000,20.00000,-5.7260e-002,0.64811
603.13800, 71.58000,    -0.77915,70.66498,50.00000,0.0000e+000,20.00000,-5.7512e-002,0.64706
604.98798, 71.76000,    -0.78362,70.65479,50.00000,0.0000e+000,20.00000,-5.7825e-002,0.64601
606.80798, 71.94000,    -0.78616,70.64458,50.00000,0.0000e+000,20.00000,-5.8183e-002,0.64499
608.63501, 72.12000,    -0.78569,70.63433,50.00000,0.0000e+000,20.00000,-5.8580e-002,0.64396
610.44000, 72.30000,    -0.78378,70.62398,50.00000,0.0000e+000,20.00000,-5.9053e-002,0.64295
612.20502, 72.48000,    -0.78168,70.61355,50.00000,0.0000e+000,20.00000,-5.9599e-002,0.64197
613.97900, 72.66000,    -0.77937,70.60299,50.00000,0.0000e+000,20.00000,-6.0196e-002,0.64098
615.75897, 72.84000,    -0.77984,70.59229,50.00000,0.0000e+000,20.00000,-6.0830e-002,0.64000
617.58899, 73.02000,    -0.78306,70.58148,50.00000,0.0000e+000,20.00000,-6.1543e-002,0.63899
619.39001, 73.20000,    -0.78613,70.57057,50.00000,0.0000e+000,20.00000,-6.2298e-002,0.63801
621.19800, 73.38000,    -0.78798,70.55948,50.00000,0.0000e+000,20.00000,-6.3075e-002,0.63702
623.00500, 73.56000,    -0.78854,70.54819,50.00000,0.0000e+000,20.00000,-6.3922e-002,0.63604
624.80798, 73.74000,    -0.79057,70.53676,50.00000,0.0000e+000,20.00000,-6.4834e-002,0.63507
626.62903, 73.92000,    -0.79283,70.52520,50.00000,0.0000e+000,20.00000,-6.5795e-002,0.63409
628.43500, 74.10000,    -0.79392,70.51343,50.00000,0.0000e+000,20.00000,-6.6787e-002,0.63312
630.24200, 74.28000,    -0.79396,70.50136,50.00000,0.0000e+000,20.00000,-6.7820e-002,0.63216
632.03101, 74.46000,    -0.79259,70.48911,50.00000,0.0000e+000,20.00000,-6.8872e-002,0.63121
633.80603, 74.64000,    -0.79150,70.47670,50.00000,0.0000e+000,20.00000,-6.9942e-002,0.63027
635.58698, 74.82000,    -0.79059,70.46401,50.00000,0.0000e+000,20.00000,-7.1022e-002,0.62933
637.35699, 75.00000,    -0.78987,70.45110,50.00000,0.0000e+000,20.00000,-7.2126e-002,0.62840
639.13800, 75.18000,    -0.79172,70.43803,50.00000,0.0000e+000,20.00000,-7.3249e-002,0.62747
640.94098, 75.36000,    -0.79512,70.42476,50.00000,0.0000e+000,20.00000,-7.4357e-002,0.62653
642.73297, 75.54000,    -0.79639,70.41126,50.00000,0.0000e+000,20.00000,-7.5468e-002,0.62561
644.56702, 75.72000,    -0.80021,70.39754,50.00000,0.0000e+000,20.00000,-7.6579e-002,0.62466
646.40198, 75.90000,    -0.80335,70.38361,50.00000,0.0000e+000,20.00000,-7.7673e-002,0.62372
648.21899, 76.08000,    -0.80401,70.36946,50.00000,0.0000e+000,20.00000,-7.8705e-002,0.62279
650.03198, 76.26000,    -0.80350,70.35509,50.00000,0.0000e+000,20.00000,-7.9704e-002,0.62187
651.83197, 76.44000,    -0.80257,70.34053,50.00000,0.0000e+000,20.00000,-8.0671e-002,0.62096
653.60101, 76.62000,    -0.80195,70.32581,50.00000,0.0000e+000,20.00000,-8.1590e-002,0.62006
655.37701, 76.80000,    -0.80067,70.31091,50.00000,0.0000e+000,20.00000,-8.2458e-002,0.61917
657.15503, 76.98000,    -0.80052,70.29580,50.00000,0.0000e+000,20.00000,-8.3290e-002,0.61828
658.95697, 77.16000,    -0.80210,70.28049,50.00000,0.0000e+000,20.00000,-8.4079e-002,0.61738
660.80298, 77.34000,    -0.80783,70.26505,50.00000,0.0000e+000,20.00000,-8.4831e-002,0.61647
662.66901, 77.52000,    -0.81321,70.24948,50.00000,0.0000e+000,20.00000,-8.5539e-002,0.61555
664.50897, 77.70000,    -0.81487,70.23377,50.00000,0.0000e+000,20.00000,-8.6205e-002,0.61464
666.31299, 77.88000,    -0.81360,70.21797,50.00000,0.0000e+000,20.00000,-8.6804e-002,0.61376
668.13501, 78.06000,    -0.81397,70.20211,50.00000,0.0000e+000,20.00000,-8.7323e-002,0.61287
669.93701, 78.24000,    -0.81336,70.18619,50.00000,0.0000e+000,20.00000,-8.7773e-002,0.61199
671.69098, 78.42000,    -0.81002,70.17020,50.00000,0.0000e+000,20.00000,-8.8162e-002,0.61114
673.46198, 78.60000,    -0.80644,70.15415,50.00000,0.0000e+000,20.00000,-8.8479e-002,0.61029
675.21100, 78.78000,    -0.80459,70.13807,50.00000,0.0000e+000,20.00000,-8.8728e-002,0.60945
676.99902, 78.96000,    -0.80737,70.12196,50.00000,0.0000e+000,20.00000,-8.8891e-002,0.60859
678.81403, 79.14000,    -0.81167,70.10577,50.00000,0.0000e+000,20.00000,-8.8952e-002,0.60773
680.63202, 79.32000,    -0.81443,70.08950,50.00000,0.0000e+000,20.00000,-8.8946e-002,0.60687
682.42603, 79.50000,    -0.81563,70.07316,50.00000,0.0000e+000,20.00000,-8.8872e-002,0.60602
684.21997, 79.68000,    -0.81684,70.05685,50.00000,0.0000e+000,20.00000,-8.8738e-002,0.60518
686.00000, 79.86000,    -0.81721,70.04061,50.00000,0.0000e+000,20.00000,-8.8530e-002,0.60434
687.80402, 80.04000,    -0.81755,70.02442,50.00000,0.0000e+000,20.00000,-8.8256e-002,0.60350
689.62799, 80.22000,    -0.81979,70.00830,50.00000,0.0000e+000,20.00000,-8.7898e-002,0.60265
691.46100, 80.40000,    -0.82224,69.99225,50.00000,0.0000e+000,20.00000,-8.7464e-002,0.60180
693.27301, 80.58000,    -0.82323,69.97625,50.00000,0.0000e+000,20.00000,-8.6965e-002,0.60097
695.08600, 80.76000,    -0.82388,69.96036,50.00000,0.0000e+000,20.00000,-8.6394e-002,0.60013
696.89203, 80.94000,    -0.82287,69.94467,50.00000,0.0000e+000,20.00000,-8.5730e-002,0.59931
698.68903, 81.12000,    -0.82064,69.92913,50.00000,0.0000e+000,20.00000,-8.4946e-002,0.59849
700.49402, 81.30000,    -0.82031,69.91370,50.00000,0.0000e+000,20.00000,-8.4060e-002,0.59767
702.28101, 81.48000,    -0.82010,69.89838,50.00000,0.0000e+000,20.00000,-8.3107e-002,0.59686
704.09900, 81.66000,    -0.82013,69.88324,50.00000,0.0000e+000,20.00000,-8.2105e-002,0.59604
705.92200, 81.84000,    -0.82186,69.86832,50.00000,0.0000e+000,20.00000,-8.1044e-002,0.59522
707.74200, 82.02000,    -0.82362,69.85361,50.00000,0.0000e+000,20.00000,-7.9934e-002,0.59441
709.53601, 82.20000,    -0.82220,69.83912,50.00000,0.0000e+000,20.00000,-7.8753e-002,0.59361
711.30499, 82.38000,    -0.81943,69.82483,50.00000,0.0000e+000,20.00000,-7.7507e-002,0.59282
713.07202, 82.56000,    -0.81581,69.81077,50.00000,0.0000e+000,20.00000,-7.6205e-002,0.59204
714.84900, 82.74000,    -0.81476,69.79699,50.00000,0.0000e+000,20.00000,-7.4882e-002,0.59126
716.65997, 82.92000,    -0.81600,69.78354,50.00000,0.0000e+000,20.00000,-7.3523e-002,0.59046
718.45599, 83.10000,    -0.81636,69.77040,50.00000,0.0000e+000,20.00000,-7.2117e-002,0.58968
720.26398, 83.28000,    -0.81718,69.75753,50.00000,0.0000e+000,20.00000,-7.0674e-002,0.58889
722.05200, 83.46000,    -0.82008,69.74490,50.00000,0.0000e+000,20.00000,-6.9194e-002,0.58811
723.90399, 83.64000,    -0.82293,69.73254,50.00000,0.0000e+000,20.00000,-6.7713e-002,0.58731
725.68701, 83.82000,    -0.82332,69.72043,50.00000,0.0000e+000,20.00000,-6.6247e-002,0.58654
727.50598, 84.00000,    -0.82270,69.70864,50.00000,0.0000e+000,20.00000,-6.4796e-002,0.58576
729.29401, 84.18000,    -0.82209,69.69713,50.00000,0.0000e+000,20.00000,-6.3335e-002,0.58500
731.12201, 84.36000,    -0.82369,69.68594,50.00000,0.0000e+000,20.00000,-6.1884e-002,0.58422
732.94299, 84.54000,    -0.82448,69.67501,50.00000,0.0000e+000,20.00000,-6.0458e-002,0.58344
734.75000, 84.72000,    -0.82375,69.66437,50.00000,0.0000e+000,20.00000,-5.9053e-002,0.58268
736.56897, 84.90000,    -0.82403,69.65404,50.00000,0.0000e+000,20.00000,-5.7695e-002,0.58191
738.38098, 85.08000,    -0.82484,69.64392,50.00000,0.0000e+000,20.00000,-5.6370e-002,0.58115
740.19702, 85.26000,    -0.82617,69.63412,50.00000,0.0000e+000,20.00000,-5.5068e-002,0.58039
742.01001, 85.44000,    -0.82670,69.62455,50.00000,0.0000e+000,20.00000,-5.3808e-002,0.57963
743.80798, 85.62000,    -0.82552,69.61514,50.00000,0.0000e+000,20.00000,-5.2580e-002,0.57888
745.58197, 85.80000,    -0.82308,69.60589,50.00000,0.0000e+000,20.00000,-5.1399e-002,0.57815
747.37598, 85.98000,    -0.82328,69.59687,50.00000,0.0000e+000,20.00000,-5.0260e-002,0.57740
749.17700, 86.16000,    -0.82325,69.58805,50.00000,0.0000e+000,20.00000,-4.9177e-002,0.57666
750.99103, 86.34000,    -0.82362,69.57940,50.00000,0.0000e+000,20.00000,-4.8139e-002,0.57592
752.79999, 86.52000,    -0.82468,69.57100,50.00000,0.0000e+000,20.00000,-4.7166e-002,0.57518
754.60797, 86.70000,    -0.82261,69.56276,50.00000,0.0000e+000,20.00000,-4.6275e-002,0.57444
756.40601, 86.88000,    -0.82217,69.55468,50.00000,0.0000e+000,20.00000,-4.5417e-002,0.57371
758.20697, 87.06000,    -0.82210,69.54673,50.00000,0.0000e+000,20.00000,-4.4627e-002,0.57298
760.02002, 87.24000,    -0.82170,69.53893,50.00000,0.0000e+000,20.00000,-4.3893e-002,0.57224
761.79999, 87.42000,    -0.82102,69.53124,50.00000,0.0000e+000,20.00000,-4.3211e-002,0.57153
763.62097, 87.60000,    -0.82003,69.52370,50.00000,0.0000e+000,20.00000,-4.2564e-002,0.57079
765.42603, 87.78000,    -0.81915,69.51629,50.00000,0.0000e+000,20.00000,-4.1985e-002,0.57007
767.26398, 87.96000,    -0.81990,69.50899,50.00000,0.0000e+000,20.00000,-4.1445e-002,0.56934
769.06500, 88.14000,    -0.81976,69.50181,50.00000,0.0000e+000,20.00000,-4.0933e-002,0.56862
770.85199, 88.32000,    -0.81654,69.49467,50.00000,0.0000e+000,20.00000,-4.0493e-002,0.56791
772.63599, 88.50000,    -0.81411,69.48756,50.00000,0.0000e+000,20.00000,-4.0113e-002,0.56720
774.47198, 88.68000,    -0.81534,69.48052,50.00000,0.0000e+000,20.00000,-3.9798e-002,0.56648
776.32202, 88.86000,    -0.81868,69.47355,50.00000,0.0000e+000,20.00000,-3.9533e-002,0.56575
778.16400, 89.04000,    -0.81874,69.46662,50.00000,0.0000e+000,20.00000,-3.9326e-002,0.56503
779.96100, 89.22000,    -0.81591,69.45969,50.00000,0.0000e+000,20.00000,-3.9166e-002,0.56433
781.75403, 89.40000,    -0.81301,69.45278,50.00000,0.0000e+000,20.00000,-3.9063e-002,0.56363
783.54999, 89.58000,    -0.81140,69.44583,50.00000,0.0000e+000,20.00000,-3.9008e-002,0.56293
785.34497, 89.76000,    -0.81057,69.43895,50.00000,0.0000e+000,20.00000,-3.9013e-002,0.56223
787.19397, 89.94000,    -0.81206,69.43214,50.00000,0.0000e+000,20.00000,-3.9068e-002,0.56152
789.00500, 90.12000,    -0.81221,69.42532,50.00000,0.0000e+000,20.00000,-3.9182e-002,0.56082
790.78998, 90.30000,    -0.80993,69.41846,50.00000,0.0000e+000,20.00000,-3.9321e-002,0.56013
792.58698, 90.48000,    -0.80806,69.41150,50.00000,0.0000e+000,20.00000,-3.9518e-002,0.55944
794.36298, 90.66000,    -0.80531,69.40451,50.00000,0.0000e+000,20.00000,-3.9763e-002,0.55876
796.12097, 90.84000,    -0.80364,69.39747,50.00000,0.0000e+000,20.00000,-4.0062e-002,0.55809
797.92700, 91.02000,    -0.80501,69.39035,50.00000,0.0000e+000,20.00000,-4.0427e-002,0.55740
799.75000, 91.20000,    -0.80784,69.38317,50.00000,0.0000e+000,20.00000,-4.0834e-002,0.55671
801.55798, 91.38000,    -0.80901,69.37595,50.00000,0.0000e+000,20.00000,-4.1268e-002,0.55602
803.35498, 91.56000,    -0.80662,69.36862,50.00000,0.0000e+000,20.00000,-4.1747e-002,0.55534
805.14001, 91.74000,    -0.80565,69.36125,50.00000,0.0000e+000,20.00000,-4.2294e-002,0.55467
806.95801, 91.92000,    -0.80611,69.35371,50.00000,0.0000e+000,20.00000,-4.2880e-002,0.55399
808.76001, 92.10000,    -0.80673,69.34609,50.00000,0.0000e+000,20.00000,-4.3514e-002,0.55331
810.56097, 92.28000,    -0.80716,69.33835,50.00000,0.0000e+000,20.00000,-4.4153e-002,0.55264
812.34900, 92.46000,    -0.80590,69.33049,50.00000,0.0000e+000,20.00000,-4.4811e-002,0.55197
814.14001, 92.64000,    -0.80484,69.32249,50.00000,0.0000e+000,20.00000,-4.5500e-002,0.55130
815.94098, 92.82000,    -0.80385,69.31426,50.00000,0.0000e+000,20.00000,-4.6215e-002,0.55063
817.74402, 93.00000,    -0.80242,69.30587,50.00000,0.0000e+000,20.00000,-4.6939e-002,0.54996
819.53101, 93.18000,    -0.80163,69.29737,50.00000,0.0000e+000,20.00000,-4.7681e-002,0.54930
821.31702, 93.36000,    -0.80113,69.28874,50.00000,0.0000e+000,20.00000,-4.8443e-002,0.54864
823.13501, 93.54000,    -0.80233,69.27995,50.00000,0.0000e+000,20.00000,-4.9215e-002,0.54797
824.94800, 93.72000,    -0.80292,69.27101,50.00000,0.0000e+000,20.00000,-4.9984e-002,0.54730
826.76501, 93.90000,    -0.80360,69.26189,50.00000,0.0000e+000,20.00000,-5.0756e-002,0.54664
828.56799, 94.08000,    -0.80271,69.25262,50.00000,0.0000e+000,20.00000,-5.1541e-002,0.54598
830.41602, 94.26000,    -0.80462,69.24324,50.00000,0.0000e+000,20.00000,-5.2318e-002,0.54530
832.27698, 94.44000,    -0.80712,69.23371,50.00000,0.0000e+000,20.00000,-5.3094e-002,0.54462
834.07898, 94.62000,    -0.80548,69.22401,50.00000,0.0000e+000,20.00000,-5.3853e-002,0.54396
835.88000, 94.80000,    -0.80185,69.21421,50.00000,0.0000e+000,20.00000,-5.4585e-002,0.54331
837.66101, 94.98000,    -0.79974,69.20432,50.00000,0.0000e+000,20.00000,-5.5302e-002,0.54266
839.46002, 95.16000,    -0.79789,69.19425,50.00000,0.0000e+000,20.00000,-5.6013e-002,0.54201
841.24799, 95.34000,    -0.79578,69.18406,50.00000,0.0000e+000,20.00000,-5.6718e-002,0.54137
843.10101, 95.52000,    -0.79624,69.17376,50.00000,0.0000e+000,20.00000,-5.7430e-002,0.54070
845.01001, 95.70000,    -0.80442,69.16334,50.00000,0.0000e+000,20.00000,-5.8134e-002,0.54001
846.88898, 95.88000,    -0.80895,69.15278,50.00000,0.0000e+000,20.00000,-5.8834e-002,0.53933
848.71399, 96.06000,    -0.80497,69.14211,50.00000,0.0000e+000,20.00000,-5.9547e-002,0.53868
850.50500, 96.24000,    -0.79941,69.13132,50.00000,0.0000e+000,20.00000,-6.0264e-002,0.53804
852.26703, 96.42000,    -0.79372,69.12038,50.00000,0.0000e+000,20.00000,-6.0969e-002,0.53741
854.04602, 96.60000,    -0.78987,69.10934,50.00000,0.0000e+000,20.00000,-6.1677e-002,0.53677
855.80603, 96.78000,    -0.78705,69.09825,50.00000,0.0000e+000,20.00000,-6.2407e-002,0.53614
857.56702, 96.96000,    -0.78385,69.08705,50.00000,0.0000e+000,20.00000,-6.3130e-002,0.53551
859.34900, 97.14000,    -0.78160,69.07575,50.00000,0.0000e+000,20.00000,-6.3892e-002,0.53488
861.09900, 97.32000,    -0.77886,69.06425,50.00000,0.0000e+000,20.00000,-6.4683e-002,0.53426
862.87598, 97.50000,    -0.77714,69.05260,50.00000,0.0000e+000,20.00000,-6.5482e-002,0.53363
864.66498, 97.68000,    -0.77771,69.04081,50.00000,0.0000e+000,20.00000,-6.6286e-002,0.53299
866.47198, 97.86000,    -0.77799,69.02888,50.00000,0.0000e+000,20.00000,-6.7092e-002,0.53235
868.25201, 98.04000,    -0.77791,69.01677,50.00000,0.0000e+000,20.00000,-6.7926e-002,0.53173
870.04199, 98.22000,    -0.77649,69.00454,50.00000,0.0000e+000,20.00000,-6.8755e-002,0.53109
871.81201, 98.40000,    -0.77377,68.99218,50.00000,0.0000e+000,20.00000,-6.9578e-002,0.53047
873.58002, 98.58000,    -0.77086,68.97968,50.00000,0.0000e+000,20.00000,-7.0418e-002,0.52985
875.38501, 98.76000,    -0.76976,68.96700,50.00000,0.0000e+000,20.00000,-7.1268e-002,0.52921
877.20001, 98.94000,    -0.77125,68.95409,50.00000,0.0000e+000,20.00000,-7.2127e-002,0.52858
879.03998, 99.12000,    -0.77377,68.94096,50.00000,0.0000e+000,20.00000,-7.2963e-002,0.52793
880.91101, 99.30000,    -0.77709,68.92765,50.00000,0.0000e+000,20.00000,-7.3771e-002,0.52727
882.83099, 99.48000,    -0.78174,68.91420,50.00000,0.0000e+000,20.00000,-7.4563e-002,0.52660
884.70898, 99.66000,    -0.78320,68.90061,50.00000,0.0000e+000,20.00000,-7.5335e-002,0.52595
886.57001, 99.84000,    -0.78149,68.88683,50.00000,0.0000e+000,20.00000,-7.6078e-002,0.52530
888.38898,100.02000,    -0.77675,68.87291,50.00000,0.0000e+000,20.00000,-7.6773e-002,0.52466
890.18298,100.20000,    -0.77083,68.85887,50.00000,0.0000e+000,20.00000,-7.7420e-002,0.52403
891.96997,100.38000,    -0.76569,68.84475,50.00000,0.0000e+000,20.00000,-7.8034e-002,0.52341
893.76202,100.56000,    -0.76322,68.83048,50.00000,0.0000e+000,20.00000,-7.8631e-002,0.52279
895.54999,100.74000,    -0.76077,68.81607,50.00000,0.0000e+000,20.00000,-7.9170e-002,0.52217
897.33099,100.92000,    -0.75819,68.80157,50.00000,0.0000e+000,20.00000,-7.9639e-002,0.52155
899.11401,101.10000,    -0.75523,68.78699,50.00000,0.0000e+000,20.00000,-8.0062e-002,0.52093
900.88898,101.28000,    -0.75374,68.77235,50.00000,0.0000e+000,20.00000,-8.0440e-002,0.52031
902.68201,101.46000,    -0.75250,68.75761,50.00000,0.0000e+000,20.00000,-8.0754e-002,0.51969
904.46997,101.64000,    -0.75170,68.74283,50.00000,0.0000e+000,20.00000,-8.0997e-002,0.51907
906.28003,101.82000,    -0.75170,68.72807,50.00000,0.0000e+000,20.00000,-8.1179e-002,0.51844
908.07397,102.00000,    -0.75030,68.71336,50.00000,0.0000e+000,20.00000,-8.1302e-002,0.51782
909.86798,102.18000,    -0.74960,68.69864,50.00000,0.0000e+000,20.00000,-8.1353e-002,0.51720
911.68298,102.36000,    -0.74986,68.68382,50.00000,0.0000e+000,20.00000,-8.1357e-002,0.51657
913.49103,102.54000,    -0.74921,68.66898,50.00000,0.0000e+000,20.00000,-8.1301e-002,0.51595
915.27002,102.72000,    -0.74647,68.65416,50.00000,0.0000e+000,20.00000,-8.1194e-002,0.51533
917.10699,102.90000,    -0.74645,68.63933,50.00000,0.0000e+000,20.00000,-8.1012e-002,0.51470
918.94000,103.08000,    -0.74743,68.62452,50.00000,0.0000e+000,20.00000,-8.0769e-002,0.51407
920.74298,103.26000,    -0.74638,68.60978,50.00000,0.0000e+000,20.00000,-8.0453e-002,0.51345
922.53998,103.44000,    -0.74589,68.59513,50.00000,0.0000e+000,20.00000,-8.0079e-002,0.51283
924.36102,103.62000,    -0.74592,68.58056,50.00000,0.0000e+000,20.00000,-7.9661e-002,0.51220
926.17499,103.80000,    -0.74539,68.56606,50.00000,0.0000e+000,20.00000,-7.9200e-002,0.51157
928.01703,103.98000,    -0.74569,68.55175,50.00000,0.0000e+000,20.00000,-7.8670e-002,0.51094
929.85303,104.16000,    -0.74630,68.53748,50.00000,0.0000e+000,20.00000,-7.8047e-002,0.51031
931.65198,104.34000,    -0.74513,68.52328,50.00000,0.0000e+000,20.00000,-7.7334e-002,0.50969
933.45697,104.52000,    -0.74315,68.50917,50.00000,0.0000e+000,20.00000,-7.6543e-002,0.50906
935.22498,104.70000,    -0.74099,68.49524,50.00000,0.0000e+000,20.00000,-7.5654e-002,0.50846
937.07898,104.88000,    -0.74239,68.48147,50.00000,0.0000e+000,20.00000,-7.4675e-002,0.50782
938.93701,105.06000,    -0.74789,68.46787,50.00000,0.0000e+000,20.00000,-7.3634e-002,0.50718
940.74902,105.24000,    -0.74741,68.45444,50.00000,0.0000e+000,20.00000,-7.2528e-002,0.50655
942.50098,105.42000,    -0.74373,68.44117,50.00000,0.0000e+000,20.00000,-7.1372e-002,0.50595
944.27002,105.60000,    -0.74105,68.42811,50.00000,0.0000e+000,20.00000,-7.0760e-002,0.50534
946.08099,105.78000,    -0.74183,68.41528,50.00000,0.0000e+000,20.00000,-7.0153e-002,0.50472
947.88599,105.96000,    -0.74322,68.40273,50.00000,0.0000e+000,20.00000,-6.9398e-002,0.50410
949.64301,106.14000,    -0.74151,68.39045,50.00000,0.0000e+000,20.00000,-6.8510e-002,0.50349
951.45398,106.32000,    -0.74129,68.37845,50.00000,0.0000e+000,20.00000,-6.7488e-002,0.50287
953.27002,106.50000,    -0.74384,68.36682,50.00000,0.0000e+000,20.00000,-6.6417e-002,0.50224
955.04401,106.68000,    -0.74487,68.35554,50.00000,0.0000e+000,20.00000,-6.5261e-002,0.50163
956.82800,106.86000,    -0.74373,68.34454,50.00000,0.0000e+000,20.00000,-6.3975e-002,0.50102
958.64398,107.04000,    -0.74691,68.33386,50.00000,0.0000e+000,20.00000,-6.2578e-002,0.50039
960.42102,107.22000,    -0.74756,68.32347,50.00000,0.0000e+000,20.00000,-6.1060e-002,0.49978
962.20898,107.40000,    -0.74738,68.31153,50.00000,0.0000e+000,20.00000,-5.9504e-002,0.49916
964.03400,107.58000,    -0.75034,68.29934,50.00000,0.0000e+000,20.00000,-5.7914e-002,0.49853
965.84601,107.76000,    -0.75182,68.28773,50.00000,0.0000e+000,20.00000,-5.6239e-002,0.49791
967.63098,107.94000,    -0.75135,68.27669,50.00000,0.0000e+000,20.00000,-5.4523e-002,0.49729
969.40399,108.12000,    -0.75141,68.26621,50.00000,0.0000e+000,20.00000,-5.2799e-002,0.49668
971.19598,108.30000,    -0.75167,68.25612,50.00000,0.0000e+000,20.00000,-5.0939e-002,0.49606
972.98401,108.48000,    -0.75369,68.24645,50.00000,0.0000e+000,20.00000,-4.9017e-002,0.49544
974.79602,108.66000,    -0.75597,68.23743,50.00000,0.0000e+000,20.00000,-4.7069e-002,0.49482
976.62299,108.84000,    -0.75883,68.22899,50.00000,0.0000e+000,20.00000,-4.5189e-002,0.49419
978.50201,109.02000,    -0.76520,68.22116,50.00000,0.0000e+000,20.00000,-4.3482e-002,0.49354
980.39398,109.20000,    -0.77303,68.21370,50.00000,0.0000e+000,20.00000,-4.1726e-002,0.49288
982.19800,109.38000,    -0.77467,68.20658,50.00000,0.0000e+000,20.00000,-3.9010e-002,0.49226
983.93201,109.56000,    -0.76826,68.20002,50.00000,0.0000e+000,20.00000,-3.6408e-002,0.49166
985.68201,109.74000,    -0.76466,68.19392,50.00000,0.0000e+000,20.00000,-3.3764e-002,0.49105
987.51300,109.92000,    -0.76710,68.18812,50.00000,0.0000e+000,20.00000,-3.1291e-002,0.49042
989.32703,110.10000,    -0.77049,68.18307,50.00000,0.0000e+000,20.00000,-2.9049e-002,0.48979
991.12299,110.28000,    -0.77202,68.17876,50.00000,0.0000e+000,20.00000,-2.6790e-002,0.48916
992.90997,110.46000,    -0.77272,68.17472,50.00000,0.0000e+000,20.00000,-2.4688e-002,0.48854
994.71997,110.64000,    -0.77331,68.17103,50.00000,0.0000e+000,20.00000,-2.3976e-002,0.48791
996.51703,110.82000,    -0.77449,68.16664,50.00000,0.0000e+000,20.00000,-2.6302e-002,0.48729
998.30798,111.00000,    -0.77491,68.16272,50.00000,0.0000e+000,20.00000,-7.5907e-002,0.48666
998.35101,111.00500,    -0.77521,68.16140,50.00000,0.0000e+000,20.00000,    -0.11168,0.48665