File: book/some_content/DG_ExpDat_B50S50DC7; 23-1-2025-2.csv
#FILE:                       ,B50S50DC7; 23-1-2025.ngb-ds3
#FORMAT:                     ,NETZSCH5
#IDENTITY:                   ,geopolymer paste
#DECIMAL:                    ,POINT
#SEPARATOR:                  ,COMMA
#MTYPE:                      ,DSC
#INSTRUMENT:                 ,Microlab TU Delft
#PROJECT:                    ,
#DATE/TIME:                  ,23/01/2025 5:17:44 PM
#CORR. FILE:                 ,Blank with cover; 13-1-2025.ngb-bs3
#LABORATORY:                 ,TU Delft Micro Lab
#OPERATOR:                   ,Ahmed
#REMARK:                     ,under Argon atmosphere, 10K/min
#SAMPLE:                     ,B50S50DC7
#SAMPLE MASS /mg:            ,43.4
#MATERIAL:                   ,Geopolymer paste
#REFERENCE:                  ,blank
#REFERENCE MASS /mg:         ,0
#TYPE OF CRUCIBLE:           ,DSC/TG pan Al2O3
#SAMPLE CRUCIBLE MASS /mg:   ,0
#REFERENCE CRUCIBLE MASS /mg:,0
#CORR. CODE:                 ,020
#EXO:                        ,-1
#RANGE:                      ,40/10.0(K/min)/1000
#SEGMENT:                    ,S2/2

##Temp./øC,Time/min,DSC/(mW/mg),Mass/%,Gas Flow(purge1)/(ml/min),Gas Flow(purge2)/(ml/min),Gas Flow(protective)/(ml/min),DTG/(%/min),Sensit./(uV/mW)
 38.24000, 15.64917, 1.3842e-002,97.99954,50.00000,0.0000e+000,20.00000,-6.9406e-002,1.22937
 38.28200, 15.82917, 1.4400e-002,97.98255,50.00000,0.0000e+000,20.00000,-6.7700e-002,1.22931
 38.35100, 16.00917, 1.4888e-002,97.96810,50.00000,0.0000e+000,20.00000,-6.4844e-002,1.22922
 38.48200, 16.18917, 1.5920e-002,97.95904,50.00000,0.0000e+000,20.00000,-6.1791e-002,1.22904
 38.68800, 16.36917, 1.7168e-002,97.94929,50.00000,0.0000e+000,20.00000,-5.9788e-002,1.22875
 38.97700, 16.54917, 1.8676e-002,97.93797,50.00000,0.0000e+000,20.00000,-5.9466e-002,1.22835
 39.34300, 16.72917, 2.1103e-002,97.92727,50.00000,0.0000e+000,20.00000,-5.9451e-002,1.22785
 39.79200, 16.90917, 2.3248e-002,97.91804,50.00000,0.0000e+000,20.00000,-5.9563e-002,1.22723
 40.31300, 17.08917, 2.5971e-002,97.90929,50.00000,0.0000e+000,20.00000,-6.0790e-002,1.22651
 40.93500, 17.26917, 2.8958e-002,97.90123,50.00000,0.0000e+000,20.00000,-6.2238e-002,1.22565
 41.62600, 17.44917, 3.2110e-002,97.89370,50.00000,0.0000e+000,20.00000,-6.3684e-002,1.22470
 42.42600, 17.62917, 3.5486e-002,97.88587,50.00000,0.0000e+000,20.00000,-6.4592e-002,1.22360
 43.29800, 17.80917, 3.8843e-002,97.87550,50.00000,0.0000e+000,20.00000,-6.5863e-002,1.22240
 44.24400, 17.98917, 4.2887e-002,97.86512,50.00000,0.0000e+000,20.00000,-6.8885e-002,1.22109
 45.32300, 18.16917, 4.6643e-002,97.85537,50.00000,0.0000e+000,20.00000,-7.3794e-002,1.21960
 46.46400, 18.34917, 5.0629e-002,97.84425,50.00000,0.0000e+000,20.00000,-7.9418e-002,1.21803
 47.68300, 18.52917, 5.5035e-002,97.83416,50.00000,0.0000e+000,20.00000,-8.5200e-002,1.21635
 49.02100, 18.70917, 5.9200e-002,97.82238,50.00000,0.0000e+000,20.00000,-9.2367e-002,1.21451
 50.42800, 18.88917, 6.3920e-002,97.80775,50.00000,0.0000e+000,20.00000,    -0.10109,1.21257
 51.91000, 19.06917, 6.8471e-002,97.79164,50.00000,0.0000e+000,20.00000,    -0.11159,1.21053
 53.51300, 19.24917, 7.3062e-002,97.77232,50.00000,0.0000e+000,20.00000,    -0.12604,1.20832
 55.15300, 19.42917, 7.8111e-002,97.75213,50.00000,0.0000e+000,20.00000,    -0.14398,1.20607
 56.90700, 19.60917, 8.3014e-002,97.73220,50.00000,0.0000e+000,20.00000,    -0.16116,1.20365
 58.73900, 19.78917, 8.8194e-002,97.71199,50.00000,0.0000e+000,20.00000,    -0.17954,1.20113
 60.65500, 19.96917, 9.3873e-002,97.68590,50.00000,0.0000e+000,20.00000,    -0.20047,1.19850
 62.60700, 20.14917, 9.9788e-002,97.65428,50.00000,0.0000e+000,20.00000,    -0.22234,1.19582
 64.67400, 20.32917,     0.10626,97.62245,50.00000,0.0000e+000,20.00000,    -0.24663,1.19298
 66.75900, 20.50917,     0.11263,97.58754,50.00000,0.0000e+000,20.00000,    -0.27206,1.19012
 68.93300, 20.68917,     0.11955,97.54770,50.00000,0.0000e+000,20.00000,    -0.30076,1.18714
 71.17400, 20.86917,     0.12767,97.50227,50.00000,0.0000e+000,20.00000,    -0.33212,1.18407
 73.42300, 21.04917,     0.13598,97.44457,50.00000,0.0000e+000,20.00000,    -0.35905,1.18098
 75.72600, 21.22917,     0.14518,97.37229,50.00000,0.0000e+000,20.00000,    -0.38797,1.17783
 78.09600, 21.40917,     0.15487,97.29931,50.00000,0.0000e+000,20.00000,    -0.41779,1.17459
 80.48300, 21.58917,     0.16545,97.22289,50.00000,0.0000e+000,20.00000,    -0.44847,1.17133
 82.93200, 21.76917,     0.17673,97.13777,50.00000,0.0000e+000,20.00000,    -0.47684,1.16798
 85.39300, 21.94917,     0.18856,97.04759,50.00000,0.0000e+000,20.00000,    -0.50562,1.16463
 87.90000, 22.12917,     0.20101,96.94993,50.00000,0.0000e+000,20.00000,    -0.53196,1.16121
 90.43400, 22.30917,     0.21397,96.84621,50.00000,0.0000e+000,20.00000,    -0.55977,1.15776
 92.98200, 22.48917,     0.22649,96.73094,50.00000,0.0000e+000,20.00000,    -0.58321,1.15430
 95.54300, 22.66917,     0.23888,96.59879,50.00000,0.0000e+000,20.00000,    -0.60336,1.15082
 98.13400, 22.84917,     0.24988,96.48184,50.00000,0.0000e+000,20.00000,    -0.62220,1.14730
100.73600, 23.02917,     0.26010,96.35617,50.00000,0.0000e+000,20.00000,    -0.63407,1.14378
103.35200, 23.20917,     0.26909,96.22881,50.00000,0.0000e+000,20.00000,    -0.64671,1.14024
105.95200, 23.38917,     0.27656,96.09540,50.00000,0.0000e+000,20.00000,    -0.65552,1.13672
108.54000, 23.56917,     0.28225,95.96825,50.00000,0.0000e+000,20.00000,    -0.66075,1.13323
111.14300, 23.74917,     0.28638,95.83117,50.00000,0.0000e+000,20.00000,    -0.66475,1.12972
113.74300, 23.92917,     0.28886,95.70316,50.00000,0.0000e+000,20.00000,    -0.66663,1.12622
116.33500, 24.10917,     0.28926,95.56784,50.00000,0.0000e+000,20.00000,    -0.66455,1.12274
118.92100, 24.28917,     0.28806,95.44031,50.00000,0.0000e+000,20.00000,    -0.65819,1.11927
121.50300, 24.46917,     0.28516,95.32333,50.00000,0.0000e+000,20.00000,    -0.64872,1.11581
124.09000, 24.64917,     0.28093,95.19850,50.00000,0.0000e+000,20.00000,    -0.64327,1.11235
126.64500, 24.82917,     0.27517,95.08393,50.00000,0.0000e+000,20.00000,    -0.63545,1.10894
129.19800, 25.00917,     0.26793,94.96451,50.00000,0.0000e+000,20.00000,    -0.62005,1.10553
131.76199, 25.18917,     0.26007,94.85483,50.00000,0.0000e+000,20.00000,    -0.60428,1.10212
134.29201, 25.36917,     0.25104,94.75215,50.00000,0.0000e+000,20.00000,    -0.59442,1.09876
136.82800, 25.54917,     0.24103,94.64776,50.00000,0.0000e+000,20.00000,    -0.57661,1.09540
139.29900, 25.72917,     0.23058,94.54463,50.00000,0.0000e+000,20.00000,    -0.55994,1.09212
141.80901, 25.90917,     0.21993,94.44687,50.00000,0.0000e+000,20.00000,    -0.54246,1.08881
144.28200, 26.08917,     0.20822,94.35874,50.00000,0.0000e+000,20.00000,    -0.52369,1.08555
146.70399, 26.26917,     0.19691,94.26217,50.00000,0.0000e+000,20.00000,    -0.50711,1.08236
149.14301, 26.44917,     0.18540,94.16384,50.00000,0.0000e+000,20.00000,    -0.49117,1.07915
151.53300, 26.62917,     0.17463,94.06636,50.00000,0.0000e+000,20.00000,    -0.47645,1.07602
153.90700, 26.80917,     0.16424,93.99212,50.00000,0.0000e+000,20.00000,    -0.45697,1.07291
156.23300, 26.98917,     0.15332,93.92036,50.00000,0.0000e+000,20.00000,    -0.44151,1.06987
158.56900, 27.16917,     0.14209,93.82841,50.00000,0.0000e+000,20.00000,    -0.43083,1.06682
160.85400, 27.34917,     0.13057,93.75438,50.00000,0.0000e+000,20.00000,    -0.41311,1.06385
163.11600, 27.52917,     0.11804,93.68687,50.00000,0.0000e+000,20.00000,    -0.39304,1.06091
165.34000, 27.70917,     0.10529,93.61661,50.00000,0.0000e+000,20.00000,    -0.37696,1.05803
167.56700, 27.88917, 9.2466e-002,93.55288,50.00000,0.0000e+000,20.00000,    -0.36574,1.05514
169.76100, 28.06917, 7.9618e-002,93.49753,50.00000,0.0000e+000,20.00000,    -0.35115,1.05231
171.91000, 28.24917, 6.6830e-002,93.43242,50.00000,0.0000e+000,20.00000,    -0.33221,1.04954
174.05800, 28.42917, 5.4361e-002,93.36813,50.00000,0.0000e+000,20.00000,    -0.31391,1.04678
176.18300, 28.60917, 4.2128e-002,93.31976,50.00000,0.0000e+000,20.00000,    -0.30427,1.04405
178.27000, 28.78917, 3.0234e-002,93.26656,50.00000,0.0000e+000,20.00000,    -0.29543,1.04137
180.33501, 28.96917, 1.8836e-002,93.20206,50.00000,0.0000e+000,20.00000,    -0.27803,1.03873
182.39200, 29.14917, 7.9574e-003,93.15812,50.00000,0.0000e+000,20.00000,    -0.26558,1.03611
184.44000, 29.32917,-2.8746e-003,93.12904,50.00000,0.0000e+000,20.00000,    -0.25559,1.03350
186.45300, 29.50917,-1.3198e-002,93.08993,50.00000,0.0000e+000,20.00000,    -0.24450,1.03094
188.44501, 29.68917,-2.2957e-002,93.04294,50.00000,0.0000e+000,20.00000,    -0.23421,1.02841
190.42200, 29.86917,-3.2968e-002,92.99945,50.00000,0.0000e+000,20.00000,    -0.22692,1.02591
192.38100, 30.04917,-4.2495e-002,92.96849,50.00000,0.0000e+000,20.00000,    -0.21683,1.02343
194.31900, 30.22917,-5.1654e-002,92.93918,50.00000,0.0000e+000,20.00000,    -0.20487,1.02099
196.22800, 30.40917,-6.0646e-002,92.89621,50.00000,0.0000e+000,20.00000,    -0.19686,1.01859
198.13400, 30.58917,-6.9110e-002,92.85820,50.00000,0.0000e+000,20.00000,    -0.18899,1.01619
200.01199, 30.76917,-7.6744e-002,92.83001,50.00000,0.0000e+000,20.00000,    -0.17679,1.01384
201.87500, 30.94917,-8.3977e-002,92.79890,50.00000,0.0000e+000,20.00000,    -0.16980,1.01151
203.70900, 31.12917,-9.0926e-002,92.76783,50.00000,0.0000e+000,20.00000,    -0.16871,1.00922
205.51801, 31.30917,-9.8514e-002,92.73806,50.00000,0.0000e+000,20.00000,    -0.16464,1.00696
207.30901, 31.48917,    -0.10589,92.70995,50.00000,0.0000e+000,20.00000,    -0.15790,1.00474
209.12100, 31.66917,    -0.11424,92.68131,50.00000,0.0000e+000,20.00000,    -0.15094,1.00249
210.92000, 31.84917,    -0.12288,92.65423,50.00000,0.0000e+000,20.00000,    -0.14787,1.00026
212.68800, 32.02917,    -0.13106,92.63130,50.00000,0.0000e+000,20.00000,    -0.14673,0.99807
214.47099, 32.20917,    -0.13920,92.61052,50.00000,0.0000e+000,20.00000,    -0.14020,0.99588
216.25600, 32.38917,    -0.14650,92.58833,50.00000,0.0000e+000,20.00000,    -0.13387,0.99368
218.03200, 32.56917,    -0.15402,92.56830,50.00000,0.0000e+000,20.00000,    -0.13142,0.99150
219.79800, 32.74917,    -0.16120,92.54620,50.00000,0.0000e+000,20.00000,    -0.12835,0.98933
221.56300, 32.92916,    -0.16825,92.52097,50.00000,0.0000e+000,20.00000,    -0.12617,0.98717
223.33501, 33.10917,    -0.17468,92.49810,50.00000,0.0000e+000,20.00000,    -0.12425,0.98501
225.10100, 33.28917,    -0.18070,92.47639,50.00000,0.0000e+000,20.00000,    -0.12219,0.98286
226.81700, 33.46917,    -0.18696,92.45652,50.00000,0.0000e+000,20.00000,    -0.11828,0.98077
228.57300, 33.64917,    -0.19348,92.43587,50.00000,0.0000e+000,20.00000,    -0.11545,0.97864
230.31799, 33.82917,    -0.19946,92.41144,50.00000,0.0000e+000,20.00000,    -0.11391,0.97653
232.04300, 34.00917,    -0.20600,92.39309,50.00000,0.0000e+000,20.00000,    -0.11253,0.97445
233.76601, 34.18917,    -0.21262,92.37667,50.00000,0.0000e+000,20.00000,    -0.11106,0.97237
235.48399, 34.36917,    -0.21944,92.35690,50.00000,0.0000e+000,20.00000,    -0.10977,0.97030
237.23000, 34.54917,    -0.22623,92.33796,50.00000,0.0000e+000,20.00000,    -0.10817,0.96821
238.94600, 34.72917,    -0.23268,92.31494,50.00000,0.0000e+000,20.00000,    -0.10650,0.96615
240.66901, 34.90917,    -0.23970,92.29182,50.00000,0.0000e+000,20.00000,    -0.10416,0.96410
242.39799, 35.08917,    -0.24610,92.27038,50.00000,0.0000e+000,20.00000,    -0.10220,0.96203
244.11800, 35.26917,    -0.25281,92.25544,50.00000,0.0000e+000,20.00000,    -0.10147,0.95999
245.82600, 35.44917,    -0.25939,92.23909,50.00000,0.0000e+000,20.00000,-9.9419e-002,0.95796
247.55600, 35.62917,    -0.26535,92.22075,50.00000,0.0000e+000,20.00000,-9.6139e-002,0.95591
249.28400, 35.80917,    -0.27146,92.20485,50.00000,0.0000e+000,20.00000,-9.4568e-002,0.95387
250.99001, 35.98917,    -0.27810,92.18838,50.00000,0.0000e+000,20.00000,-9.4798e-002,0.95186
252.71201, 36.16917,    -0.28481,92.17230,50.00000,0.0000e+000,20.00000,-9.4608e-002,0.94984
254.43201, 36.34917,    -0.29145,92.15720,50.00000,0.0000e+000,20.00000,-9.3351e-002,0.94782
256.14301, 36.52917,    -0.29786,92.13839,50.00000,0.0000e+000,20.00000,-9.0333e-002,0.94582
257.86899, 36.70917,    -0.30491,92.12259,50.00000,0.0000e+000,20.00000,-8.7496e-002,0.94380
259.59601, 36.88917,    -0.31159,92.10878,50.00000,0.0000e+000,20.00000,-8.4254e-002,0.94179
261.29901, 37.06917,    -0.31774,92.09098,50.00000,0.0000e+000,20.00000,-8.2900e-002,0.93981
263.02701, 37.24917,    -0.32408,92.07770,50.00000,0.0000e+000,20.00000,-8.3043e-002,0.93781
264.75000, 37.42916,    -0.33041,92.06565,50.00000,0.0000e+000,20.00000,-8.2223e-002,0.93582
266.47501, 37.60917,    -0.33663,92.05204,50.00000,0.0000e+000,20.00000,-8.1035e-002,0.93383
268.21600, 37.78917,    -0.34292,92.03585,50.00000,0.0000e+000,20.00000,-8.0409e-002,0.93182
269.94000, 37.96917,    -0.34877,92.01676,50.00000,0.0000e+000,20.00000,-8.0960e-002,0.92985
271.67099, 38.14917,    -0.35429,92.00165,50.00000,0.0000e+000,20.00000,-8.0195e-002,0.92786
273.40500, 38.32917,    -0.36027,91.99028,50.00000,0.0000e+000,20.00000,-7.8817e-002,0.92588
275.15500, 38.50917,    -0.36567,91.97741,50.00000,0.0000e+000,20.00000,-7.8504e-002,0.92389
276.89099, 38.68917,    -0.37088,91.96667,50.00000,0.0000e+000,20.00000,-7.8598e-002,0.92192
278.60699, 38.86917,    -0.37636,91.95663,50.00000,0.0000e+000,20.00000,-7.7923e-002,0.91997
280.35599, 39.04917,    -0.38192,91.94087,50.00000,0.0000e+000,20.00000,-7.9122e-002,0.91800
282.09698, 39.22917,    -0.38692,91.92514,50.00000,0.0000e+000,20.00000,-8.0870e-002,0.91603
283.82901, 39.40917,    -0.39209,91.91257,50.00000,0.0000e+000,20.00000,-8.2176e-002,0.91408
285.56000, 39.58917,    -0.39721,91.89988,50.00000,0.0000e+000,20.00000,-8.1942e-002,0.91214
287.33099, 39.76917,    -0.40234,91.88107,50.00000,0.0000e+000,20.00000,-8.0839e-002,0.91016
289.07999, 39.94917,    -0.40752,91.86828,50.00000,0.0000e+000,20.00000,-8.1306e-002,0.90821
290.81500, 40.12917,    -0.41223,91.85561,50.00000,0.0000e+000,20.00000,-8.2884e-002,0.90628
292.58499, 40.30917,    -0.41668,91.83993,50.00000,0.0000e+000,20.00000,-8.4472e-002,0.90432
294.32999, 40.48917,    -0.42133,91.82600,50.00000,0.0000e+000,20.00000,-8.5950e-002,0.90239
296.06799, 40.66917,    -0.42537,91.81134,50.00000,0.0000e+000,20.00000,-8.7963e-002,0.90047
297.82800, 40.84917,    -0.43040,91.79321,50.00000,0.0000e+000,20.00000,-8.9404e-002,0.89853
299.59100, 41.02917,    -0.43521,91.77474,50.00000,0.0000e+000,20.00000,-9.0681e-002,0.89660
301.34900, 41.20917,    -0.43998,91.75654,50.00000,0.0000e+000,20.00000,-9.3185e-002,0.89467
303.11899, 41.38917,    -0.44451,91.74113,50.00000,0.0000e+000,20.00000,-9.5597e-002,0.89274
304.88400, 41.56917,    -0.44859,91.72668,50.00000,0.0000e+000,20.00000,-9.5927e-002,0.89082
306.64999, 41.74917,    -0.45240,91.70915,50.00000,0.0000e+000,20.00000,-9.7449e-002,0.88891
308.42001, 41.92916,    -0.45584,91.69174,50.00000,0.0000e+000,20.00000,-9.9242e-002,0.88699
310.18201, 42.10917,    -0.45928,91.67355,50.00000,0.0000e+000,20.00000,    -0.10014,0.88509
311.94400, 42.28917,    -0.46319,91.65621,50.00000,0.0000e+000,20.00000,    -0.10187,0.88320
313.71301, 42.46917,    -0.46728,91.63999,50.00000,0.0000e+000,20.00000,    -0.10483,0.88130
315.48901, 42.64917,    -0.47151,91.61965,50.00000,0.0000e+000,20.00000,    -0.10706,0.87940
317.27100, 42.82917,    -0.47553,91.59943,50.00000,0.0000e+000,20.00000,    -0.10821,0.87750
319.04501, 43.00917,    -0.47923,91.57686,50.00000,0.0000e+000,20.00000,    -0.10994,0.87561
320.82101, 43.18917,    -0.48273,91.55607,50.00000,0.0000e+000,20.00000,    -0.11251,0.87373
322.59100, 43.36917,    -0.48635,91.53612,50.00000,0.0000e+000,20.00000,    -0.11584,0.87186
324.37000, 43.54917,    -0.48928,91.51669,50.00000,0.0000e+000,20.00000,    -0.11778,0.86999
326.12500, 43.72917,    -0.49252,91.49792,50.00000,0.0000e+000,20.00000,    -0.12030,0.86815
327.88699, 43.90917,    -0.49554,91.47924,50.00000,0.0000e+000,20.00000,    -0.12423,0.86630
329.64401, 44.08917,    -0.49891,91.45904,50.00000,0.0000e+000,20.00000,    -0.12768,0.86447
331.42001, 44.26917,    -0.50201,91.43475,50.00000,0.0000e+000,20.00000,    -0.13176,0.86262
333.17499, 44.44917,    -0.50542,91.40857,50.00000,0.0000e+000,20.00000,    -0.13651,0.86080
334.93900, 44.62917,    -0.50850,91.38537,50.00000,0.0000e+000,20.00000,    -0.14090,0.85898
336.70801, 44.80917,    -0.51164,91.36139,50.00000,0.0000e+000,20.00000,    -0.14373,0.85715
338.48599, 44.98917,    -0.51444,91.33596,50.00000,0.0000e+000,20.00000,    -0.14717,0.85532
340.25101, 45.16917,    -0.51754,91.30957,50.00000,0.0000e+000,20.00000,    -0.15576,0.85352
342.01999, 45.34917,    -0.52040,91.28516,50.00000,0.0000e+000,20.00000,    -0.16702,0.85171
343.80701, 45.52917,    -0.52300,91.25910,50.00000,0.0000e+000,20.00000,    -0.17085,0.84989
345.58701, 45.70917,    -0.52529,91.22747,50.00000,0.0000e+000,20.00000,    -0.17227,0.84808
347.36801, 45.88917,    -0.52672,91.19630,50.00000,0.0000e+000,20.00000,    -0.17716,0.84628
349.15100, 46.06917,    -0.52872,91.16640,50.00000,0.0000e+000,20.00000,    -0.18355,0.84449
350.94199, 46.24917,    -0.53093,91.12965,50.00000,0.0000e+000,20.00000,    -0.18932,0.84269
352.73901, 46.42916,    -0.53311,91.09298,50.00000,0.0000e+000,20.00000,    -0.19465,0.84089
354.52600, 46.60917,    -0.53469,91.05974,50.00000,0.0000e+000,20.00000,    -0.19748,0.83910
356.31400, 46.78917,    -0.53622,91.02711,50.00000,0.0000e+000,20.00000,    -0.20062,0.83732
358.07700, 46.96917,    -0.53783,90.97920,50.00000,0.0000e+000,20.00000,    -0.20543,0.83558
359.86099, 47.14917,    -0.53964,90.91718,50.00000,0.0000e+000,20.00000,    -0.21104,0.83381
361.64200, 47.32917,    -0.54230,90.87956,50.00000,0.0000e+000,20.00000,    -0.21822,0.83206
363.41800, 47.50917,    -0.54564,90.85709,50.00000,0.0000e+000,20.00000,    -0.22077,0.83032
365.20499, 47.68917,    -0.54989,90.82126,50.00000,0.0000e+000,20.00000,    -0.21989,0.82857
366.98199, 47.86917,    -0.55404,90.77537,50.00000,0.0000e+000,20.00000,    -0.22352,0.82683
368.78299, 48.04917,    -0.55849,90.72747,50.00000,0.0000e+000,20.00000,    -0.22501,0.82508
370.55600, 48.22917,    -0.56267,90.68339,50.00000,0.0000e+000,20.00000,    -0.22393,0.82337
372.33701, 48.40917,    -0.56656,90.64834,50.00000,0.0000e+000,20.00000,    -0.22414,0.82165
374.11600, 48.58917,    -0.57135,90.61296,50.00000,0.0000e+000,20.00000,    -0.22577,0.81994
375.90302, 48.76917,    -0.57618,90.56946,50.00000,0.0000e+000,20.00000,    -0.22486,0.81822
377.68201, 48.94917,    -0.58207,90.52474,50.00000,0.0000e+000,20.00000,    -0.21843,0.81652
379.46899, 49.12917,    -0.58816,90.47377,50.00000,0.0000e+000,20.00000,    -0.21771,0.81482
381.25201, 49.30917,    -0.59414,90.43016,50.00000,0.0000e+000,20.00000,    -0.22276,0.81313
383.02600, 49.48917,    -0.60067,90.40221,50.00000,0.0000e+000,20.00000,    -0.22365,0.81146
384.81201, 49.66917,    -0.60665,90.36144,50.00000,0.0000e+000,20.00000,    -0.22190,0.80977
386.59201, 49.84917,    -0.61330,90.31864,50.00000,0.0000e+000,20.00000,    -0.21817,0.80810
388.37799, 50.02917,    -0.62113,90.28491,50.00000,0.0000e+000,20.00000,    -0.21438,0.80643
390.17099, 50.20917,    -0.62906,90.25084,50.00000,0.0000e+000,20.00000,    -0.21188,0.80476
391.95499, 50.38917,    -0.63656,90.21348,50.00000,0.0000e+000,20.00000,    -0.21129,0.80311
393.76501, 50.56917,    -0.64388,90.17241,50.00000,0.0000e+000,20.00000,    -0.21081,0.80143
395.54401, 50.74917,    -0.65043,90.13338,50.00000,0.0000e+000,20.00000,    -0.20808,0.79979
397.33301, 50.92916,    -0.65710,90.09402,50.00000,0.0000e+000,20.00000,    -0.20340,0.79815
399.12299, 51.10917,    -0.66359,90.05276,50.00000,0.0000e+000,20.00000,    -0.20278,0.79651
400.91199, 51.28917,    -0.67006,90.01591,50.00000,0.0000e+000,20.00000,    -0.20693,0.79488
402.70401, 51.46917,    -0.67631,89.97737,50.00000,0.0000e+000,20.00000,    -0.20372,0.79325
404.48401, 51.64917,    -0.68286,89.94223,50.00000,0.0000e+000,20.00000,    -0.20014,0.79164
406.28101, 51.82917,    -0.68889,89.91059,50.00000,0.0000e+000,20.00000,    -0.20125,0.79002
408.06400, 52.00917,    -0.69433,89.88293,50.00000,0.0000e+000,20.00000,    -0.20421,0.78842
409.84799, 52.18917,    -0.69958,89.85245,50.00000,0.0000e+000,20.00000,    -0.20700,0.78682
411.62201, 52.36917,    -0.70459,89.81197,50.00000,0.0000e+000,20.00000,    -0.20630,0.78524
413.40601, 52.54917,    -0.70945,89.77593,50.00000,0.0000e+000,20.00000,    -0.20432,0.78365
415.18301, 52.72917,    -0.71465,89.74407,50.00000,0.0000e+000,20.00000,    -0.20463,0.78208
416.96701, 52.90917,    -0.71963,89.70156,50.00000,0.0000e+000,20.00000,    -0.20429,0.78051
418.74200, 53.08917,    -0.72432,89.65596,50.00000,0.0000e+000,20.00000,    -0.20414,0.77895
420.54300, 53.26917,    -0.73027,89.62756,50.00000,0.0000e+000,20.00000,    -0.20418,0.77737
422.37000, 53.44917,    -0.74137,89.59847,50.00000,0.0000e+000,20.00000,    -0.20654,0.77578
424.22299, 53.62917,    -0.75172,89.56045,50.00000,0.0000e+000,20.00000,    -0.20926,0.77417
426.07199, 53.80917,    -0.75967,89.51714,50.00000,0.0000e+000,20.00000,    -0.21134,0.77257
427.90500, 53.98917,    -0.76353,89.46960,50.00000,0.0000e+000,20.00000,    -0.21297,0.77099
429.71399, 54.16917,    -0.76434,89.42990,50.00000,0.0000e+000,20.00000,    -0.21296,0.76944
431.50500, 54.34917,    -0.76438,89.39752,50.00000,0.0000e+000,20.00000,    -0.21513,0.76791
433.27399, 54.52917,    -0.76462,89.35900,50.00000,0.0000e+000,20.00000,    -0.21980,0.76640
435.04901, 54.70917,    -0.76658,89.31782,50.00000,0.0000e+000,20.00000,    -0.22167,0.76489
436.83099, 54.88917,    -0.77005,89.28106,50.00000,0.0000e+000,20.00000,    -0.22038,0.76339
438.59698, 55.06917,    -0.77373,89.24313,50.00000,0.0000e+000,20.00000,    -0.22364,0.76190
440.37201, 55.24917,    -0.77755,89.19945,50.00000,0.0000e+000,20.00000,    -0.22788,0.76041
442.12701, 55.42916,    -0.78121,89.15619,50.00000,0.0000e+000,20.00000,    -0.22888,0.75895
443.91000, 55.60917,    -0.78622,89.11987,50.00000,0.0000e+000,20.00000,    -0.22953,0.75746
445.68799, 55.78917,    -0.79198,89.08496,50.00000,0.0000e+000,20.00000,    -0.22935,0.75599
447.47699, 55.96917,    -0.79789,89.04640,50.00000,0.0000e+000,20.00000,    -0.23020,0.75451
449.26501, 56.14917,    -0.80465,89.00172,50.00000,0.0000e+000,20.00000,    -0.23432,0.75304
451.06900, 56.32917,    -0.80996,88.95345,50.00000,0.0000e+000,20.00000,    -0.23625,0.75157
452.85101, 56.50917,    -0.81394,88.90559,50.00000,0.0000e+000,20.00000,    -0.23590,0.75011
454.64499, 56.68917,    -0.81754,88.86272,50.00000,0.0000e+000,20.00000,    -0.23861,0.74865
456.43100, 56.86917,    -0.82169,88.82056,50.00000,0.0000e+000,20.00000,    -0.24195,0.74721
458.21799, 57.04917,    -0.82653,88.77709,50.00000,0.0000e+000,20.00000,    -0.24140,0.74577
460.00000, 57.22917,    -0.83104,88.73635,50.00000,0.0000e+000,20.00000,    -0.24210,0.74434
461.80200, 57.40917,    -0.83524,88.69246,50.00000,0.0000e+000,20.00000,    -0.24790,0.74290
463.59500, 57.58917,    -0.84033,88.64532,50.00000,0.0000e+000,20.00000,    -0.25222,0.74147
465.38101, 57.76917,    -0.84510,88.60080,50.00000,0.0000e+000,20.00000,    -0.25404,0.74005
467.19000, 57.94917,    -0.84909,88.55348,50.00000,0.0000e+000,20.00000,    -0.25508,0.73863
468.97800, 58.12917,    -0.85276,88.50820,50.00000,0.0000e+000,20.00000,    -0.25251,0.73722
470.75699, 58.30917,    -0.85645,88.46794,50.00000,0.0000e+000,20.00000,    -0.25146,0.73583
472.54901, 58.48917,    -0.86009,88.42228,50.00000,0.0000e+000,20.00000,    -0.25431,0.73443
474.32700, 58.66917,    -0.86342,88.37180,50.00000,0.0000e+000,20.00000,    -0.25795,0.73305
476.10101, 58.84917,    -0.86667,88.33028,50.00000,0.0000e+000,20.00000,    -0.25836,0.73167
477.88501, 59.02917,    -0.87025,88.28550,50.00000,0.0000e+000,20.00000,    -0.25853,0.73030
479.67700, 59.20917,    -0.87474,88.22811,50.00000,0.0000e+000,20.00000,    -0.26204,0.72892
481.44800, 59.38917,    -0.87883,88.17527,50.00000,0.0000e+000,20.00000,    -0.26409,0.72757
483.22299, 59.56917,    -0.88332,88.13141,50.00000,0.0000e+000,20.00000,    -0.26430,0.72622
485.01001, 59.74917,    -0.88776,88.08329,50.00000,0.0000e+000,20.00000,    -0.26420,0.72486
486.79599, 59.92916,    -0.89282,88.04370,50.00000,0.0000e+000,20.00000,    -0.26612,0.72352
488.56900, 60.10917,    -0.89753,88.00132,50.00000,0.0000e+000,20.00000,    -0.26926,0.72218
490.35800, 60.28917,    -0.90237,87.94795,50.00000,0.0000e+000,20.00000,    -0.27069,0.72084
492.14301, 60.46917,    -0.90785,87.89254,50.00000,0.0000e+000,20.00000,    -0.26912,0.71951
493.95499, 60.64917,    -0.91425,87.84528,50.00000,0.0000e+000,20.00000,    -0.26980,0.71817
495.76300, 60.82917,    -0.92074,87.80484,50.00000,0.0000e+000,20.00000,    -0.27279,0.71683
497.57901, 61.00917,    -0.92589,87.75089,50.00000,0.0000e+000,20.00000,    -0.27290,0.71550
499.39099, 61.18917,    -0.93062,87.69467,50.00000,0.0000e+000,20.00000,    -0.27267,0.71417
501.17899, 61.36917,    -0.93481,87.64835,50.00000,0.0000e+000,20.00000,    -0.27363,0.71286
502.97000, 61.54917,    -0.93786,87.60284,50.00000,0.0000e+000,20.00000,    -0.27233,0.71156
504.78000, 61.72917,    -0.94179,87.55020,50.00000,0.0000e+000,20.00000,    -0.27773,0.71025
506.58301, 61.90917,    -0.94763,87.49779,50.00000,0.0000e+000,20.00000,    -0.28159,0.70895
508.38800, 62.08917,    -0.95282,87.44781,50.00000,0.0000e+000,20.00000,    -0.27725,0.70766
510.19601, 62.26917,    -0.95690,87.40214,50.00000,0.0000e+000,20.00000,    -0.27470,0.70637
511.99301, 62.44917,    -0.96113,87.35747,50.00000,0.0000e+000,20.00000,    -0.27730,0.70509
513.78497, 62.62917,    -0.96441,87.30504,50.00000,0.0000e+000,20.00000,    -0.28291,0.70382
515.58801, 62.80917,    -0.96653,87.24806,50.00000,0.0000e+000,20.00000,    -0.28270,0.70255
517.36603, 62.98917,    -0.96938,87.19389,50.00000,0.0000e+000,20.00000,    -0.27908,0.70130
519.15601, 63.16917,    -0.97309,87.14480,50.00000,0.0000e+000,20.00000,    -0.28025,0.70005
520.95801, 63.34917,    -0.97849,87.10242,50.00000,0.0000e+000,20.00000,    -0.28432,0.69879
522.77100, 63.52917,    -0.98486,87.04436,50.00000,0.0000e+000,20.00000,    -0.28631,0.69754
524.57898, 63.70917,    -0.99082,86.98595,50.00000,0.0000e+000,20.00000,    -0.28477,0.69629
526.38202, 63.88917,    -0.99570,86.94882,50.00000,0.0000e+000,20.00000,    -0.28278,0.69505
528.17499, 64.06917,    -0.99964,86.90480,50.00000,0.0000e+000,20.00000,    -0.28358,0.69382
529.99298, 64.24917,    -1.00325,86.84768,50.00000,0.0000e+000,20.00000,    -0.28713,0.69259
531.78101, 64.42917,    -1.00570,86.78613,50.00000,0.0000e+000,20.00000,    -0.28941,0.69137
533.56097, 64.60917,    -1.00765,86.73388,50.00000,0.0000e+000,20.00000,    -0.28973,0.69017
535.34302, 64.78917,    -1.01030,86.68932,50.00000,0.0000e+000,20.00000,    -0.29111,0.68897
537.13800, 64.96917,    -1.01354,86.63955,50.00000,0.0000e+000,20.00000,    -0.29318,0.68777
538.91901, 65.14917,    -1.01758,86.58027,50.00000,0.0000e+000,20.00000,    -0.29510,0.68659
540.70801, 65.32917,    -1.02108,86.52041,50.00000,0.0000e+000,20.00000,    -0.29174,0.68540
542.49103, 65.50916,    -1.02518,86.47135,50.00000,0.0000e+000,20.00000,    -0.28938,0.68422
544.27301, 65.68916,    -1.03003,86.42849,50.00000,0.0000e+000,20.00000,    -0.29643,0.68305
546.07501, 65.86916,    -1.03485,86.38053,50.00000,0.0000e+000,20.00000,    -0.30150,0.68187
547.88397, 66.04916,    -1.04124,86.32413,50.00000,0.0000e+000,20.00000,    -0.30049,0.68069
549.69098, 66.22916,    -1.04762,86.26487,50.00000,0.0000e+000,20.00000,    -0.29763,0.67951
551.50800, 66.40916,    -1.05290,86.20652,50.00000,0.0000e+000,20.00000,    -0.29763,0.67834
553.31299, 66.58916,    -1.05632,86.14719,50.00000,0.0000e+000,20.00000,    -0.30131,0.67718
555.11902, 66.76917,    -1.05844,86.08851,50.00000,0.0000e+000,20.00000,    -0.30214,0.67602
556.90503, 66.94917,    -1.06002,86.03745,50.00000,0.0000e+000,20.00000,    -0.29874,0.67488
558.68402, 67.12917,    -1.06083,85.99492,50.00000,0.0000e+000,20.00000,    -0.29790,0.67375
560.45099, 67.30917,    -1.06317,85.94457,50.00000,0.0000e+000,20.00000,    -0.30231,0.67264
562.24902, 67.48917,    -1.06705,85.88088,50.00000,0.0000e+000,20.00000,    -0.30757,0.67150
564.03802, 67.66917,    -1.07130,85.81896,50.00000,0.0000e+000,20.00000,    -0.30985,0.67038
565.83698, 67.84917,    -1.07646,85.76652,50.00000,0.0000e+000,20.00000,    -0.30739,0.66926
567.64600, 68.02917,    -1.08225,85.71520,50.00000,0.0000e+000,20.00000,    -0.30624,0.66813
569.44397, 68.20917,    -1.08692,85.66202,50.00000,0.0000e+000,20.00000,    -0.30875,0.66702
571.26501, 68.38917,    -1.09068,85.60361,50.00000,0.0000e+000,20.00000,    -0.30818,0.66590
573.08099, 68.56917,    -1.09465,85.55062,50.00000,0.0000e+000,20.00000,    -0.30511,0.66479
574.88300, 68.74917,    -1.09917,85.50515,50.00000,0.0000e+000,20.00000,    -0.30741,0.66369
576.69299, 68.92917,    -1.10346,85.45011,50.00000,0.0000e+000,20.00000,    -0.31180,0.66259
578.48700, 69.10917,    -1.10639,85.38324,50.00000,0.0000e+000,20.00000,    -0.31293,0.66150
580.25598, 69.28917,    -1.10969,85.32015,50.00000,0.0000e+000,20.00000,    -0.31385,0.66044
582.06403, 69.46917,    -1.11418,85.26349,50.00000,0.0000e+000,20.00000,    -0.31308,0.65935
583.86401, 69.64917,    -1.12067,85.21685,50.00000,0.0000e+000,20.00000,    -0.31601,0.65828
585.69800, 69.82917,    -1.12681,85.16401,50.00000,0.0000e+000,20.00000,    -0.31956,0.65719
587.49701, 70.00916,    -1.13180,85.09737,50.00000,0.0000e+000,20.00000,    -0.32295,0.65612
589.28802, 70.18916,    -1.13419,85.03723,50.00000,0.0000e+000,20.00000,    -0.32376,0.65507
591.09003, 70.36916,    -1.13704,84.99010,50.00000,0.0000e+000,20.00000,    -0.32352,0.65401
592.87701, 70.54916,    -1.14061,84.93080,50.00000,0.0000e+000,20.00000,    -0.32913,0.65297
594.67499, 70.72916,    -1.14419,84.86983,50.00000,0.0000e+000,20.00000,    -0.33445,0.65192
596.47498, 70.90916,    -1.14753,84.81843,50.00000,0.0000e+000,20.00000,    -0.33388,0.65088
598.28802, 71.08916,    -1.15249,84.75376,50.00000,0.0000e+000,20.00000,    -0.33374,0.64984
600.09302, 71.26917,    -1.15701,84.69275,50.00000,0.0000e+000,20.00000,    -0.33531,0.64880
601.88397, 71.44917,    -1.16101,84.62904,50.00000,0.0000e+000,20.00000,    -0.34087,0.64778
603.69501, 71.62917,    -1.16484,84.56505,50.00000,0.0000e+000,20.00000,    -0.34641,0.64675
605.48297, 71.80917,    -1.16754,84.49990,50.00000,0.0000e+000,20.00000,    -0.34739,0.64573
607.28400, 71.98917,    -1.17132,84.43793,50.00000,0.0000e+000,20.00000,    -0.35028,0.64472
609.08301, 72.16917,    -1.17550,84.38398,50.00000,0.0000e+000,20.00000,    -0.35512,0.64371
610.88202, 72.34917,    -1.17863,84.32049,50.00000,0.0000e+000,20.00000,    -0.35923,0.64270
612.66998, 72.52917,    -1.18073,84.24757,50.00000,0.0000e+000,20.00000,    -0.36208,0.64171
614.46802, 72.70917,    -1.18396,84.18264,50.00000,0.0000e+000,20.00000,    -0.36401,0.64071
616.27502, 72.88917,    -1.18757,84.11954,50.00000,0.0000e+000,20.00000,    -0.36599,0.63972
618.06702, 73.06917,    -1.19242,84.05547,50.00000,0.0000e+000,20.00000,    -0.37311,0.63873
619.87598, 73.24917,    -1.19673,83.98908,50.00000,0.0000e+000,20.00000,    -0.37701,0.63774
621.67200, 73.42917,    -1.19970,83.91721,50.00000,0.0000e+000,20.00000,    -0.37746,0.63676
623.47400, 73.60917,    -1.20314,83.84932,50.00000,0.0000e+000,20.00000,    -0.37838,0.63579
625.28900, 73.78917,    -1.20877,83.77548,50.00000,0.0000e+000,20.00000,    -0.37973,0.63481
627.14203, 73.96917,    -1.21738,83.70965,50.00000,0.0000e+000,20.00000,    -0.38369,0.63381
628.98199, 74.14917,    -1.22480,83.63941,50.00000,0.0000e+000,20.00000,    -0.38693,0.63283
630.79901, 74.32917,    -1.22720,83.56482,50.00000,0.0000e+000,20.00000,    -0.38781,0.63186
632.58099, 74.50916,    -1.22425,83.50536,50.00000,0.0000e+000,20.00000,    -0.38993,0.63091
634.34802, 74.68916,    -1.22124,83.43841,50.00000,0.0000e+000,20.00000,    -0.39330,0.62998
636.11798, 74.86916,    -1.22123,83.35187,50.00000,0.0000e+000,20.00000,    -0.39622,0.62905
637.90002, 75.04916,    -1.22324,83.27124,50.00000,0.0000e+000,20.00000,    -0.39856,0.62812
639.69000, 75.22916,    -1.22892,83.20561,50.00000,0.0000e+000,20.00000,    -0.39998,0.62718
641.48901, 75.40916,    -1.23486,83.13726,50.00000,0.0000e+000,20.00000,    -0.40105,0.62625
643.29303, 75.58916,    -1.23973,83.06936,50.00000,0.0000e+000,20.00000,    -0.39670,0.62532
645.09698, 75.76917,    -1.24532,83.00052,50.00000,0.0000e+000,20.00000,    -0.39580,0.62439
646.90002, 75.94917,    -1.25024,82.92865,50.00000,0.0000e+000,20.00000,    -0.39786,0.62346
648.69202, 76.12917,    -1.25112,82.85241,50.00000,0.0000e+000,20.00000,    -0.39810,0.62255
650.50000, 76.30917,    -1.25274,82.77817,50.00000,0.0000e+000,20.00000,    -0.39967,0.62163
652.28802, 76.48917,    -1.25528,82.70361,50.00000,0.0000e+000,20.00000,    -0.39994,0.62073
654.08398, 76.66917,    -1.25867,82.62798,50.00000,0.0000e+000,20.00000,    -0.39486,0.61982
655.89801, 76.84917,    -1.26348,82.55482,50.00000,0.0000e+000,20.00000,    -0.39120,0.61891
657.71100, 77.02917,    -1.26701,82.47762,50.00000,0.0000e+000,20.00000,    -0.39384,0.61800
659.51202, 77.20917,    -1.26990,82.40417,50.00000,0.0000e+000,20.00000,    -0.39441,0.61711
661.29700, 77.38917,    -1.27235,82.34523,50.00000,0.0000e+000,20.00000,    -0.39375,0.61622
663.09900, 77.56917,    -1.27359,82.28350,50.00000,0.0000e+000,20.00000,    -0.38939,0.61533
664.92297, 77.74917,    -1.27834,82.20877,50.00000,0.0000e+000,20.00000,    -0.38590,0.61444
666.74902, 77.92917,    -1.28370,82.13143,50.00000,0.0000e+000,20.00000,    -0.38456,0.61354
668.56799, 78.10917,    -1.28739,82.06319,50.00000,0.0000e+000,20.00000,    -0.38152,0.61266
670.39398, 78.28917,    -1.29081,81.99818,50.00000,0.0000e+000,20.00000,    -0.37792,0.61177
672.19897, 78.46917,    -1.29150,81.93269,50.00000,0.0000e+000,20.00000,    -0.37472,0.61090
674.00299, 78.64917,    -1.29144,81.86351,50.00000,0.0000e+000,20.00000,    -0.36870,0.61003
675.79700, 78.82917,    -1.29162,81.78763,50.00000,0.0000e+000,20.00000,    -0.36355,0.60917
677.60199, 79.00916,    -1.29243,81.71658,50.00000,0.0000e+000,20.00000,    -0.35889,0.60831
679.39099, 79.18916,    -1.29326,81.64986,50.00000,0.0000e+000,20.00000,    -0.35381,0.60746
681.18201, 79.36916,    -1.29510,81.59556,50.00000,0.0000e+000,20.00000,    -0.35043,0.60661
682.98199, 79.54916,    -1.29718,81.53970,50.00000,0.0000e+000,20.00000,    -0.34773,0.60576
684.77197, 79.72916,    -1.29875,81.46924,50.00000,0.0000e+000,20.00000,    -0.34127,0.60492
686.57300, 79.90916,    -1.30065,81.40388,50.00000,0.0000e+000,20.00000,    -0.33194,0.60407
688.36700, 80.08916,    -1.30190,81.34390,50.00000,0.0000e+000,20.00000,    -0.32311,0.60324
690.14398, 80.26917,    -1.30333,81.27865,50.00000,0.0000e+000,20.00000,    -0.31753,0.60241
691.95599, 80.44917,    -1.30491,81.22619,50.00000,0.0000e+000,20.00000,    -0.31284,0.60157
693.73798, 80.62917,    -1.30743,81.17044,50.00000,0.0000e+000,20.00000,    -0.30418,0.60075
695.56097, 80.80917,    -1.31186,81.11040,50.00000,0.0000e+000,20.00000,    -0.29420,0.59992
697.35199, 80.98917,    -1.31418,81.06670,50.00000,0.0000e+000,20.00000,    -0.28728,0.59910
699.17401, 81.16917,    -1.31682,81.02155,50.00000,0.0000e+000,20.00000,    -0.28311,0.59827
701.02698, 81.34917,    -1.32418,80.95961,50.00000,0.0000e+000,20.00000,    -0.27798,0.59743
702.84698, 81.52917,    -1.32898,80.90230,50.00000,0.0000e+000,20.00000,    -0.26890,0.59661
704.65802, 81.70917,    -1.32983,80.86463,50.00000,0.0000e+000,20.00000,    -0.26281,0.59579
706.46198, 81.88917,    -1.32900,80.83285,50.00000,0.0000e+000,20.00000,    -0.25770,0.59498
708.26099, 82.06917,    -1.32882,80.78977,50.00000,0.0000e+000,20.00000,    -0.24808,0.59418
710.05103, 82.24917,    -1.32942,80.73885,50.00000,0.0000e+000,20.00000,    -0.24105,0.59338
711.85199, 82.42917,    -1.32958,80.69317,50.00000,0.0000e+000,20.00000,    -0.23551,0.59258
713.64301, 82.60917,    -1.32951,80.65748,50.00000,0.0000e+000,20.00000,    -0.22701,0.59179
715.43103, 82.78917,    -1.33021,80.61630,50.00000,0.0000e+000,20.00000,    -0.22067,0.59100
717.23798, 82.96917,    -1.33108,80.57422,50.00000,0.0000e+000,20.00000,    -0.21536,0.59021
719.04401, 83.14917,    -1.33256,80.53846,50.00000,0.0000e+000,20.00000,    -0.20576,0.58942
720.83502, 83.32917,    -1.33432,80.50353,50.00000,0.0000e+000,20.00000,    -0.19535,0.58864
722.64099, 83.50916,    -1.33604,80.45951,50.00000,0.0000e+000,20.00000,    -0.19021,0.58786
724.42902, 83.68916,    -1.33861,80.41712,50.00000,0.0000e+000,20.00000,    -0.18806,0.58709
726.23602, 83.86916,    -1.34012,80.38563,50.00000,0.0000e+000,20.00000,    -0.18278,0.58631
728.00800, 84.04916,    -1.34216,80.35733,50.00000,0.0000e+000,20.00000,    -0.17421,0.58555
729.79602, 84.22916,    -1.34656,80.32431,50.00000,0.0000e+000,20.00000,    -0.16646,0.58478
731.59698, 84.40916,    -1.35272,80.29293,50.00000,0.0000e+000,20.00000,    -0.16164,0.58402
733.40002, 84.58916,    -1.35691,80.26948,50.00000,0.0000e+000,20.00000,    -0.15521,0.58325
735.19702, 84.76917,    -1.35992,80.24627,50.00000,0.0000e+000,20.00000,    -0.14809,0.58249
737.00897, 84.94917,    -1.36388,80.22113,50.00000,0.0000e+000,20.00000,    -0.14413,0.58173
738.83398, 85.12917,    -1.36913,80.19896,50.00000,0.0000e+000,20.00000,    -0.13984,0.58096
740.64697, 85.30917,    -1.37113,80.17771,50.00000,0.0000e+000,20.00000,    -0.13249,0.58020
742.45502, 85.48917,    -1.37353,80.15443,50.00000,0.0000e+000,20.00000,    -0.12498,0.57945
744.28497, 85.66917,    -1.37551,80.13213,50.00000,0.0000e+000,20.00000,    -0.11977,0.57868
746.12299, 85.84917,    -1.37882,80.11283,50.00000,0.0000e+000,20.00000,    -0.11645,0.57792
747.94299, 86.02917,    -1.38040,80.09383,50.00000,0.0000e+000,20.00000,    -0.11195,0.57717
749.74597, 86.20917,    -1.37876,80.07492,50.00000,0.0000e+000,20.00000,    -0.10592,0.57643
751.55103, 86.38917,    -1.37535,80.05808,50.00000,0.0000e+000,20.00000,    -0.10180,0.57569
753.33899, 86.56917,    -1.37266,80.04196,50.00000,0.0000e+000,20.00000,-9.9370e-002,0.57496
755.14099, 86.74917,    -1.37215,80.02023,50.00000,0.0000e+000,20.00000,-9.7699e-002,0.57422
756.93597, 86.92917,    -1.37301,80.00067,50.00000,0.0000e+000,20.00000,-9.6177e-002,0.57349
758.74103, 87.10917,    -1.37430,79.98486,50.00000,0.0000e+000,20.00000,-9.3065e-002,0.57276
760.55902, 87.28917,    -1.37610,79.96847,50.00000,0.0000e+000,20.00000,-8.9110e-002,0.57203
762.37299, 87.46917,    -1.37700,79.95420,50.00000,0.0000e+000,20.00000,-8.5038e-002,0.57129
764.18298, 87.64917,    -1.37795,79.93904,50.00000,0.0000e+000,20.00000,-8.3901e-002,0.57057
766.01599, 87.82917,    -1.37963,79.92229,50.00000,0.0000e+000,20.00000,-8.3754e-002,0.56983
767.81799, 88.00916,    -1.37937,79.91151,50.00000,0.0000e+000,20.00000,-8.2556e-002,0.56912
769.59802, 88.18916,    -1.37765,79.90226,50.00000,0.0000e+000,20.00000,-8.0438e-002,0.56841
771.40900, 88.36916,    -1.37813,79.88941,50.00000,0.0000e+000,20.00000,-7.8056e-002,0.56769
773.20599, 88.54916,    -1.37917,79.87083,50.00000,0.0000e+000,20.00000,-7.5261e-002,0.56698
774.99902, 88.72916,    -1.38095,79.85270,50.00000,0.0000e+000,20.00000,-7.3169e-002,0.56627
776.81201, 88.90916,    -1.38304,79.84219,50.00000,0.0000e+000,20.00000,-7.3711e-002,0.56556
778.60101, 89.08916,    -1.38351,79.83363,50.00000,0.0000e+000,20.00000,-7.2751e-002,0.56486
780.38898, 89.26917,    -1.38553,79.82588,50.00000,0.0000e+000,20.00000,-7.0933e-002,0.56416
782.19702, 89.44917,    -1.39076,79.81204,50.00000,0.0000e+000,20.00000,-6.9048e-002,0.56345
784.03198, 89.62917,    -1.39668,79.79314,50.00000,0.0000e+000,20.00000,-6.7870e-002,0.56274
785.85101, 89.80917,    -1.40334,79.77800,50.00000,0.0000e+000,20.00000,-6.7748e-002,0.56204
787.65601, 89.98917,    -1.40659,79.76751,50.00000,0.0000e+000,20.00000,-6.8650e-002,0.56134
789.46802, 90.16917,    -1.41019,79.76077,50.00000,0.0000e+000,20.00000,-6.8499e-002,0.56064
791.29797, 90.34917,    -1.41642,79.75036,50.00000,0.0000e+000,20.00000,-6.7779e-002,0.55994
793.09900, 90.52917,    -1.42031,79.73812,50.00000,0.0000e+000,20.00000,-6.6736e-002,0.55924
794.88202, 90.70917,    -1.42286,79.72065,50.00000,0.0000e+000,20.00000,-6.5632e-002,0.55856
796.68103, 90.88917,    -1.42650,79.70646,50.00000,0.0000e+000,20.00000,-6.5541e-002,0.55788
798.47601, 91.06917,    -1.43267,79.69805,50.00000,0.0000e+000,20.00000,-6.6375e-002,0.55719
800.28400, 91.24917,    -1.43899,79.69081,50.00000,0.0000e+000,20.00000,-6.7830e-002,0.55651
802.10101, 91.42917,    -1.44444,79.67845,50.00000,0.0000e+000,20.00000,-6.7236e-002,0.55582
803.90997, 91.60917,    -1.44865,79.66693,50.00000,0.0000e+000,20.00000,-6.6321e-002,0.55514
805.70801, 91.78917,    -1.45080,79.65486,50.00000,0.0000e+000,20.00000,-6.9321e-002,0.55446
807.50299, 91.96917,    -1.45340,79.64305,50.00000,0.0000e+000,20.00000,-7.4087e-002,0.55378
809.30701, 92.14917,    -1.45737,79.62900,50.00000,0.0000e+000,20.00000,-7.5010e-002,0.55311
811.13000, 92.32917,    -1.45980,79.61269,50.00000,0.0000e+000,20.00000,-7.4281e-002,0.55242
812.92798, 92.50916,    -1.46241,79.60470,50.00000,0.0000e+000,20.00000,-7.3963e-002,0.55175
814.73798, 92.68916,    -1.46394,79.59672,50.00000,0.0000e+000,20.00000,-7.4240e-002,0.55108
816.56299, 92.86916,    -1.46801,79.58659,50.00000,0.0000e+000,20.00000,-7.6704e-002,0.55040
818.37402, 93.04916,    -1.46971,79.56993,50.00000,0.0000e+000,20.00000,-8.1256e-002,0.54973
820.17499, 93.22916,    -1.46970,79.55206,50.00000,0.0000e+000,20.00000,-8.3609e-002,0.54906
821.96100, 93.40916,    -1.46810,79.54000,50.00000,0.0000e+000,20.00000,-8.4815e-002,0.54840
823.74298, 93.58916,    -1.46726,79.51941,50.00000,0.0000e+000,20.00000,-8.4783e-002,0.54775
825.54401, 93.76917,    -1.46663,79.49417,50.00000,0.0000e+000,20.00000,-8.7417e-002,0.54708
827.33899, 93.94917,    -1.46914,79.47941,50.00000,0.0000e+000,20.00000,-9.3170e-002,0.54643
829.12903, 94.12917,    -1.47103,79.47035,50.00000,0.0000e+000,20.00000,-9.5636e-002,0.54577
830.92603, 94.30917,    -1.47212,79.45601,50.00000,0.0000e+000,20.00000,-9.7255e-002,0.54511
832.72601, 94.48917,    -1.47425,79.43891,50.00000,0.0000e+000,20.00000,    -0.10034,0.54446
834.54303, 94.66917,    -1.47724,79.42220,50.00000,0.0000e+000,20.00000,    -0.10361,0.54380
836.34698, 94.84917,    -1.47916,79.39861,50.00000,0.0000e+000,20.00000,    -0.10686,0.54314
838.18903, 95.02917,    -1.48389,79.37784,50.00000,0.0000e+000,20.00000,    -0.11093,0.54247
840.01703, 95.20917,    -1.48649,79.36054,50.00000,0.0000e+000,20.00000,    -0.11519,0.54181
841.84003, 95.38917,    -1.48456,79.34903,50.00000,0.0000e+000,20.00000,    -0.11613,0.54115
843.65100, 95.56917,    -1.48587,79.32961,50.00000,0.0000e+000,20.00000,    -0.11588,0.54050
845.47198, 95.74917,    -1.48712,79.29641,50.00000,0.0000e+000,20.00000,    -0.11822,0.53984
847.27399, 95.92917,    -1.48727,79.26788,50.00000,0.0000e+000,20.00000,    -0.12426,0.53919
849.07397, 96.10917,    -1.48674,79.25261,50.00000,0.0000e+000,20.00000,    -0.12779,0.53855
850.86499, 96.28917,    -1.48446,79.23450,50.00000,0.0000e+000,20.00000,    -0.13029,0.53791
852.66400, 96.46917,    -1.48532,79.21320,50.00000,0.0000e+000,20.00000,    -0.13488,0.53726
854.44397, 96.64917,    -1.48548,79.18704,50.00000,0.0000e+000,20.00000,    -0.13608,0.53663
856.23401, 96.82917,    -1.48456,79.15404,50.00000,0.0000e+000,20.00000,    -0.13707,0.53599
858.01599, 97.00916,    -1.48491,79.12438,50.00000,0.0000e+000,20.00000,    -0.13936,0.53535
859.81500, 97.18916,    -1.48790,79.10259,50.00000,0.0000e+000,20.00000,    -0.14457,0.53471
861.64398, 97.36916,    -1.49195,79.07762,50.00000,0.0000e+000,20.00000,    -0.15030,0.53407
863.46698, 97.54916,    -1.49633,79.05322,50.00000,0.0000e+000,20.00000,    -0.15242,0.53342
865.29102, 97.72916,    -1.49979,79.02232,50.00000,0.0000e+000,20.00000,    -0.15001,0.53277
867.10901, 97.90916,    -1.50253,78.99534,50.00000,0.0000e+000,20.00000,    -0.15111,0.53213
868.92603, 98.08916,    -1.50408,78.96957,50.00000,0.0000e+000,20.00000,    -0.15678,0.53149
870.72101, 98.26917,    -1.50372,78.93723,50.00000,0.0000e+000,20.00000,    -0.16081,0.53085
872.55298, 98.44917,    -1.50588,78.90855,50.00000,0.0000e+000,20.00000,    -0.16180,0.53021
874.35498, 98.62917,    -1.50579,78.88381,50.00000,0.0000e+000,20.00000,    -0.16322,0.52958
876.16199, 98.80917,    -1.50620,78.85753,50.00000,0.0000e+000,20.00000,    -0.16645,0.52894
877.96802, 98.98917,    -1.50745,78.82772,50.00000,0.0000e+000,20.00000,    -0.16750,0.52831
879.74402, 99.16917,    -1.50779,78.79046,50.00000,0.0000e+000,20.00000,    -0.16681,0.52768
881.54797, 99.34917,    -1.50780,78.75000,50.00000,0.0000e+000,20.00000,    -0.16855,0.52705
883.34601, 99.52917,    -1.50843,78.72516,50.00000,0.0000e+000,20.00000,    -0.17032,0.52642
885.12903, 99.70917,    -1.51069,78.70688,50.00000,0.0000e+000,20.00000,    -0.17134,0.52580
886.94202, 99.88917,    -1.51345,78.67079,50.00000,0.0000e+000,20.00000,    -0.17222,0.52517
888.72101,100.06917,    -1.51588,78.63365,50.00000,0.0000e+000,20.00000,    -0.17127,0.52454
890.53802,100.24917,    -1.51670,78.60451,50.00000,0.0000e+000,20.00000,    -0.17144,0.52391
892.33197,100.42917,    -1.51865,78.56968,50.00000,0.0000e+000,20.00000,    -0.17547,0.52329
894.13898,100.60917,    -1.52145,78.52518,50.00000,0.0000e+000,20.00000,    -0.18006,0.52266
895.90997,100.78917,    -1.52234,78.49708,50.00000,0.0000e+000,20.00000,    -0.18397,0.52204
897.71399,100.96917,    -1.52383,78.47557,50.00000,0.0000e+000,20.00000,    -0.18410,0.52141
899.51001,101.14917,    -1.52380,78.44641,50.00000,0.0000e+000,20.00000,    -0.18060,0.52079
901.32300,101.32917,    -1.52612,78.41021,50.00000,0.0000e+000,20.00000,    -0.18168,0.52016
903.12000,101.50916,    -1.52744,78.37717,50.00000,0.0000e+000,20.00000,    -0.18634,0.51954
904.92603,101.68916,    -1.52898,78.34880,50.00000,0.0000e+000,20.00000,    -0.18842,0.51891
906.76801,101.86916,    -1.53052,78.32059,50.00000,0.0000e+000,20.00000,    -0.18940,0.51827
908.62097,102.04916,    -1.53635,78.29093,50.00000,0.0000e+000,20.00000,    -0.19273,0.51763
910.46002,102.22916,    -1.54056,78.25294,50.00000,0.0000e+000,20.00000,    -0.19309,0.51700
912.26398,102.40916,    -1.53704,78.20994,50.00000,0.0000e+000,20.00000,    -0.18729,0.51637
914.07501,102.58916,    -1.53338,78.16691,50.00000,0.0000e+000,20.00000,    -0.18641,0.51575
915.87402,102.76917,    -1.53018,78.12838,50.00000,0.0000e+000,20.00000,    -0.18972,0.51513
917.67603,102.94917,    -1.52759,78.10006,50.00000,0.0000e+000,20.00000,    -0.19173,0.51450
919.47803,103.12917,    -1.52571,78.06871,50.00000,0.0000e+000,20.00000,    -0.19205,0.51388
921.27399,103.30917,    -1.52574,78.03506,50.00000,0.0000e+000,20.00000,    -0.19314,0.51326
923.07397,103.48917,    -1.52501,77.99510,50.00000,0.0000e+000,20.00000,    -0.19936,0.51264
924.88000,103.66917,    -1.52450,77.95265,50.00000,0.0000e+000,20.00000,    -0.20123,0.51202
926.67798,103.84917,    -1.52339,77.91073,50.00000,0.0000e+000,20.00000,    -0.20285,0.51140
928.48602,104.02917,    -1.52119,77.87451,50.00000,0.0000e+000,20.00000,    -0.20536,0.51078
930.32001,104.20917,    -1.52362,77.85047,50.00000,0.0000e+000,20.00000,    -0.20478,0.51014
932.10797,104.38917,    -1.51911,77.82367,50.00000,0.0000e+000,20.00000,    -0.20446,0.50953
933.90198,104.56917,    -1.51284,77.79114,50.00000,0.0000e+000,20.00000,    -0.20399,0.50891
935.68799,104.74917,    -1.50845,77.75609,50.00000,0.0000e+000,20.00000,    -0.20489,0.50830
937.45398,104.92917,    -1.49886,77.71948,50.00000,0.0000e+000,20.00000,    -0.20712,0.50769
939.22998,105.10917,    -1.49210,77.68241,50.00000,0.0000e+000,20.00000,    -0.21098,0.50708
941.04797,105.28917,    -1.48923,77.63218,50.00000,0.0000e+000,20.00000,    -0.21399,0.50645
942.83600,105.46917,    -1.48492,77.59352,50.00000,0.0000e+000,20.00000,    -0.21361,0.50584
944.66498,105.64917,    -1.47964,77.56102,50.00000,0.0000e+000,20.00000,    -0.21385,0.50521
946.46002,105.82917,    -1.47288,77.51547,50.00000,0.0000e+000,20.00000,    -0.21695,0.50459
948.28802,106.00916,    -1.46844,77.47412,50.00000,0.0000e+000,20.00000,    -0.22700,0.50396
950.13098,106.18916,    -1.46746,77.43266,50.00000,0.0000e+000,20.00000,    -0.23447,0.50332
951.96503,106.36916,    -1.46616,77.39315,50.00000,0.0000e+000,20.00000,    -0.23941,0.50269
953.78699,106.54916,    -1.46246,77.36052,50.00000,0.0000e+000,20.00000,    -0.24136,0.50207
955.60303,106.72916,    -1.45818,77.32328,50.00000,0.0000e+000,20.00000,    -0.24268,0.50144
957.40100,106.90916,    -1.45511,77.27703,50.00000,0.0000e+000,20.00000,    -0.24816,0.50082
959.22998,107.08916,    -1.45515,77.22662,50.00000,0.0000e+000,20.00000,    -0.24876,0.50019
961.09601,107.26917,    -1.46030,77.18431,50.00000,0.0000e+000,20.00000,    -0.24934,0.49955
962.88898,107.44917,    -1.45626,77.14239,50.00000,0.0000e+000,20.00000,    -0.25458,0.49893
964.66400,107.62917,    -1.44838,77.09462,50.00000,0.0000e+000,20.00000,    -0.25492,0.49832
966.47198,107.80917,    -1.44687,77.03370,50.00000,0.0000e+000,20.00000,    -0.25672,0.49769
968.26703,107.98917,    -1.44518,76.97865,50.00000,0.0000e+000,20.00000,    -0.26091,0.49707
970.07501,108.16917,    -1.44611,76.92896,50.00000,0.0000e+000,20.00000,    -0.25880,0.49645
971.90802,108.34917,    -1.45256,76.88487,50.00000,0.0000e+000,20.00000,    -0.25813,0.49582
973.75598,108.52917,    -1.45980,76.84562,50.00000,0.0000e+000,20.00000,    -0.26035,0.49518
975.58899,108.70917,    -1.46234,76.79030,50.00000,0.0000e+000,20.00000,    -0.25655,0.49454
977.40802,108.88917,    -1.46285,76.73799,50.00000,0.0000e+000,20.00000,    -0.24811,0.49392
979.21100,109.06917,    -1.46242,76.69356,50.00000,0.0000e+000,20.00000,    -0.24205,0.49329
980.98700,109.24917,    -1.46189,76.64445,50.00000,0.0000e+000,20.00000,    -0.23995,0.49268
982.76898,109.42917,    -1.46183,76.59716,50.00000,0.0000e+000,20.00000,    -0.23166,0.49206
984.52899,109.60917,    -1.46307,76.55046,50.00000,0.0000e+000,20.00000,    -0.22496,0.49145
986.26801,109.78917,    -1.45899,76.49303,50.00000,0.0000e+000,20.00000,    -0.22391,0.49085
987.99500,109.96917,    -1.45827,76.45652,50.00000,0.0000e+000,20.00000,    -0.21143,0.49025
989.79102,110.14917,    -1.47057,76.42791,50.00000,0.0000e+000,20.00000,    -0.20044,0.48963
991.56403,110.32917,    -1.48091,76.38448,50.00000,0.0000e+000,20.00000,    -0.18318,0.48901
993.36401,110.50916,    -1.49353,76.35045,50.00000,0.0000e+000,20.00000,    -0.16251,0.48838
995.16998,110.68916,    -1.50482,76.33010,50.00000,0.0000e+000,20.00000,    -0.13456,0.48776
996.99298,110.86916,    -1.51519,76.30922,50.00000,0.0000e+000,20.00000,    -0.13172,0.48712
998.32001,110.99917,    -1.52154,76.29032,50.00000,0.0000e+000,20.00000,    -0.23395,0.48666