File: book/some_content/DG_ExpDat_A8%DC28; 14-2-2025-2.csv
#FILE:                       ,A8%DC28; 14-2-2025.ngb-ds3
#FORMAT:                     ,NETZSCH5
#IDENTITY:                   ,GEOPOLYMER PASTE
#DECIMAL:                    ,POINT
#SEPARATOR:                  ,COMMA
#MTYPE:                      ,DSC
#INSTRUMENT:                 ,Microlab TU Delft
#PROJECT:                    ,
#DATE/TIME:                  ,14/02/2025 11:10:13 AM
#CORR. FILE:                 ,Blank with cover; 13-1-2025.ngb-bs3
#LABORATORY:                 ,TU Delft Micro Lab
#OPERATOR:                   ,Ahmed
#REMARK:                     ,under Argon atmosphere, 10K/min
#SAMPLE:                     ,A8%DC28
#SAMPLE MASS /mg:            ,32.6
#MATERIAL:                   ,Geopolymer paste
#REFERENCE:                  ,blank
#REFERENCE MASS /mg:         ,0
#TYPE OF CRUCIBLE:           ,DSC/TG pan Al2O3
#SAMPLE CRUCIBLE MASS /mg:   ,0
#REFERENCE CRUCIBLE MASS /mg:,0
#CORR. CODE:                 ,720
#EXO:                        ,-1
#RANGE:                      ,40/10.0(K/min)/1000
#SEGMENT:                    ,S2/2

##Temp./øC,Time/min,DSC/(mW/mg),Mass/%,Gas Flow(purge1)/(ml/min),Gas Flow(purge2)/(ml/min),Gas Flow(protective)/(ml/min),DTG/(%/min),Sensit./(uV/mW)
 57.14000, 18.66750,-9.3443e-002,91.87196,50.00000,0.0000e+000,20.00000,-4.0761e-002,1.20333
 57.19000, 18.84250,-9.4467e-002,91.86997,50.00000,0.0000e+000,20.00000,-2.4926e-002,1.20326
 57.27000, 19.01750,-9.4800e-002,91.87268,50.00000,0.0000e+000,20.00000,-9.2004e-003,1.20315
 57.46500, 19.19250,-9.4570e-002,91.87801,50.00000,0.0000e+000,20.00000, 5.3189e-003,1.20289
 57.78700, 19.36750,-9.3615e-002,91.88624,50.00000,0.0000e+000,20.00000, 1.8094e-002,1.20244
 58.21000, 19.54250,-9.2054e-002,91.89666,50.00000,0.0000e+000,20.00000, 3.0909e-002,1.20186
 58.72600, 19.71750,-9.0011e-002,91.91074,50.00000,0.0000e+000,20.00000, 4.3820e-002,1.20115
 59.35900, 19.89250,-8.7426e-002,91.92903,50.00000,0.0000e+000,20.00000, 5.4632e-002,1.20028
 60.09400, 20.06750,-8.4296e-002,91.94816,50.00000,0.0000e+000,20.00000, 6.3224e-002,1.19927
 60.99100, 20.24250,-8.0796e-002,91.96661,50.00000,0.0000e+000,20.00000, 7.0160e-002,1.19804
 61.96500, 20.41750,-7.7108e-002,91.98616,50.00000,0.0000e+000,20.00000, 7.5163e-002,1.19670
 63.06500, 20.59250,-7.3316e-002,92.00672,50.00000,0.0000e+000,20.00000, 7.7705e-002,1.19519
 64.29000, 20.76750,-6.9372e-002,92.02716,50.00000,0.0000e+000,20.00000, 7.8208e-002,1.19351
 65.61600, 20.94250,-6.5320e-002,92.04592,50.00000,0.0000e+000,20.00000, 7.7459e-002,1.19169
 67.03800, 21.11750,-6.1230e-002,92.06074,50.00000,0.0000e+000,20.00000, 7.5952e-002,1.18974
 68.57900, 21.29250,-5.7313e-002,92.07378,50.00000,0.0000e+000,20.00000, 7.3245e-002,1.18762
 70.22000, 21.46750,-5.3477e-002,92.08985,50.00000,0.0000e+000,20.00000, 6.9253e-002,1.18537
 71.95700, 21.64250,-4.9648e-002,92.10590,50.00000,0.0000e+000,20.00000, 6.3320e-002,1.18299
 73.77500, 21.81750,-4.5916e-002,92.12063,50.00000,0.0000e+000,20.00000, 5.5340e-002,1.18050
 75.69100, 21.99250,-4.2233e-002,92.13482,50.00000,0.0000e+000,20.00000, 4.5901e-002,1.17788
 77.66200, 22.16750,-3.8592e-002,92.14623,50.00000,0.0000e+000,20.00000, 3.4996e-002,1.17518
 79.74200, 22.34250,-3.4970e-002,92.15237,50.00000,0.0000e+000,20.00000, 2.2597e-002,1.17234
 81.89500, 22.51750,-3.1209e-002,92.15598,50.00000,0.0000e+000,20.00000, 7.9436e-003,1.16940
 84.12200, 22.69250,-2.7364e-002,92.15774,50.00000,0.0000e+000,20.00000,-8.9700e-003,1.16636
 86.41100, 22.86750,-2.3394e-002,92.15941,50.00000,0.0000e+000,20.00000,-2.7564e-002,1.16324
 88.76500, 23.04250,-1.9138e-002,92.15987,50.00000,0.0000e+000,20.00000,-4.8046e-002,1.16003
 91.15500, 23.21750,-1.4566e-002,92.15846,50.00000,0.0000e+000,20.00000,-7.2893e-002,1.15678
 93.63300, 23.39250,-9.6117e-003,92.15455,50.00000,0.0000e+000,20.00000,    -0.10219,1.15341
 96.13400, 23.56750,-4.1989e-003,92.14739,50.00000,0.0000e+000,20.00000,    -0.13250,1.15002
 98.68500, 23.74250, 1.8849e-003,92.13382,50.00000,0.0000e+000,20.00000,    -0.16233,1.14656
101.22500, 23.91750, 8.7090e-003,92.11503,50.00000,0.0000e+000,20.00000,    -0.19296,1.14311
103.83900, 24.09250, 1.6290e-002,92.09201,50.00000,0.0000e+000,20.00000,    -0.22467,1.13958
106.46300, 24.26750, 2.5132e-002,92.06292,50.00000,0.0000e+000,20.00000,    -0.25616,1.13603
109.09800, 24.44250, 3.5107e-002,92.02499,50.00000,0.0000e+000,20.00000,    -0.28778,1.13248
111.75800, 24.61750, 4.6163e-002,91.97774,50.00000,0.0000e+000,20.00000,    -0.31955,1.12889
114.40600, 24.79250, 5.8398e-002,91.92114,50.00000,0.0000e+000,20.00000,    -0.35210,1.12533
117.07000, 24.96750, 7.1595e-002,91.85177,50.00000,0.0000e+000,20.00000,    -0.38473,1.12175
119.73100, 25.14250, 8.5325e-002,91.76688,50.00000,0.0000e+000,20.00000,    -0.41728,1.11818
122.41500, 25.31750, 9.9127e-002,91.67224,50.00000,0.0000e+000,20.00000,    -0.44966,1.11459
125.07100, 25.49250,     0.11265,91.57719,50.00000,0.0000e+000,20.00000,    -0.48073,1.11104
127.75600, 25.66750,     0.12552,91.48142,50.00000,0.0000e+000,20.00000,    -0.50994,1.10745
130.43600, 25.84250,     0.13753,91.37728,50.00000,0.0000e+000,20.00000,    -0.53746,1.10388
133.10201, 26.01750,     0.14850,91.26768,50.00000,0.0000e+000,20.00000,    -0.56311,1.10034
135.75200, 26.19250,     0.15826,91.15550,50.00000,0.0000e+000,20.00000,    -0.58610,1.09682
138.39500, 26.36750,     0.16673,91.04173,50.00000,0.0000e+000,20.00000,    -0.60596,1.09332
141.04700, 26.54250,     0.17370,90.92552,50.00000,0.0000e+000,20.00000,    -0.62263,1.08981
143.67200, 26.71750,     0.17908,90.80641,50.00000,0.0000e+000,20.00000,    -0.63644,1.08635
146.26401, 26.89250,     0.18277,90.68558,50.00000,0.0000e+000,20.00000,    -0.64528,1.08294
148.84599, 27.06750,     0.18474,90.56272,50.00000,0.0000e+000,20.00000,    -0.64873,1.07954
151.38300, 27.24250,     0.18500,90.43838,50.00000,0.0000e+000,20.00000,    -0.65033,1.07621
153.92999, 27.41750,     0.18365,90.31466,50.00000,0.0000e+000,20.00000,    -0.65184,1.07288
156.45000, 27.59250,     0.18068,90.19195,50.00000,0.0000e+000,20.00000,    -0.65149,1.06959
158.91400, 27.76750,     0.17620,90.07130,50.00000,0.0000e+000,20.00000,    -0.64839,1.06637
161.37100, 27.94250,     0.17029,89.95280,50.00000,0.0000e+000,20.00000,    -0.64345,1.06318
163.78400, 28.11750,     0.16311,89.83584,50.00000,0.0000e+000,20.00000,    -0.63689,1.06004
166.17900, 28.29250,     0.15486,89.72179,50.00000,0.0000e+000,20.00000,    -0.62861,1.05694
168.56599, 28.46750,     0.14562,89.60849,50.00000,0.0000e+000,20.00000,    -0.61905,1.05385
170.90401, 28.64250,     0.13561,89.49581,50.00000,0.0000e+000,20.00000,    -0.60910,1.05084
173.21700, 28.81750,     0.12502,89.38906,50.00000,0.0000e+000,20.00000,    -0.59837,1.04786
175.51199, 28.99250,     0.11410,89.28691,50.00000,0.0000e+000,20.00000,    -0.58598,1.04491
177.78799, 29.16750,     0.10282,89.18605,50.00000,0.0000e+000,20.00000,    -0.57184,1.04199
180.02400, 29.34250, 9.1294e-002,89.08689,50.00000,0.0000e+000,20.00000,    -0.55759,1.03913
182.24100, 29.51750, 7.9622e-002,88.98909,50.00000,0.0000e+000,20.00000,    -0.54392,1.03630
184.44901, 29.69250, 6.7931e-002,88.89436,50.00000,0.0000e+000,20.00000,    -0.53046,1.03349
186.61200, 29.86750, 5.6134e-002,88.80344,50.00000,0.0000e+000,20.00000,    -0.51634,1.03074
188.74699, 30.04250, 4.4209e-002,88.71679,50.00000,0.0000e+000,20.00000,    -0.50219,1.02803
190.87801, 30.21750, 3.2340e-002,88.63368,50.00000,0.0000e+000,20.00000,    -0.48866,1.02533
192.98399, 30.39250, 2.0591e-002,88.55015,50.00000,0.0000e+000,20.00000,    -0.47418,1.02267
195.05600, 30.56750, 8.8238e-003,88.46669,50.00000,0.0000e+000,20.00000,    -0.45966,1.02006
197.09700, 30.74250,-2.9293e-003,88.38576,50.00000,0.0000e+000,20.00000,    -0.44615,1.01749
199.13200, 30.91750,-1.4660e-002,88.31081,50.00000,0.0000e+000,20.00000,    -0.43328,1.01494
201.12801, 31.09250,-2.6155e-002,88.23975,50.00000,0.0000e+000,20.00000,    -0.42066,1.01244
203.12500, 31.26750,-3.7502e-002,88.16813,50.00000,0.0000e+000,20.00000,    -0.40740,1.00995
205.08200, 31.44250,-4.8711e-002,88.09697,50.00000,0.0000e+000,20.00000,    -0.39360,1.00751
207.01401, 31.61750,-5.9803e-002,88.02881,50.00000,0.0000e+000,20.00000,    -0.38009,1.00510
208.92300, 31.79250,-7.0771e-002,87.96473,50.00000,0.0000e+000,20.00000,    -0.36790,1.00273
210.83000, 31.96750,-8.1578e-002,87.90077,50.00000,0.0000e+000,20.00000,    -0.35726,1.00037
212.71899, 32.14250,-9.2437e-002,87.83847,50.00000,0.0000e+000,20.00000,    -0.34611,0.99804
214.58099, 32.31750,    -0.10349,87.78005,50.00000,0.0000e+000,20.00000,    -0.33430,0.99574
216.42999, 32.49250,    -0.11489,87.72522,50.00000,0.0000e+000,20.00000,    -0.32233,0.99346
218.27000, 32.66750,    -0.12678,87.67100,50.00000,0.0000e+000,20.00000,    -0.31125,0.99120
220.09100, 32.84250,    -0.13902,87.61664,50.00000,0.0000e+000,20.00000,    -0.30199,0.98897
221.89400, 33.01750,    -0.15139,87.56475,50.00000,0.0000e+000,20.00000,    -0.29251,0.98677
223.68401, 33.19250,    -0.16379,87.51699,50.00000,0.0000e+000,20.00000,    -0.28281,0.98458
225.48000, 33.36750,    -0.17598,87.47312,50.00000,0.0000e+000,20.00000,    -0.27288,0.98240
227.24699, 33.54250,    -0.18777,87.42968,50.00000,0.0000e+000,20.00000,    -0.26405,0.98025
229.02000, 33.71750,    -0.19899,87.38449,50.00000,0.0000e+000,20.00000,    -0.25589,0.97810
230.76199, 33.89250,    -0.20977,87.34059,50.00000,0.0000e+000,20.00000,    -0.24718,0.97599
232.52499, 34.06750,    -0.22010,87.29939,50.00000,0.0000e+000,20.00000,    -0.23939,0.97387
234.26401, 34.24250,    -0.22998,87.25988,50.00000,0.0000e+000,20.00000,    -0.23255,0.97177
235.99699, 34.41750,    -0.23961,87.22212,50.00000,0.0000e+000,20.00000,    -0.22636,0.96969
237.73700, 34.59250,    -0.24910,87.18431,50.00000,0.0000e+000,20.00000,    -0.21993,0.96760
239.44299, 34.76750,    -0.25849,87.14684,50.00000,0.0000e+000,20.00000,    -0.21374,0.96556
241.14200, 34.94250,    -0.26789,87.11052,50.00000,0.0000e+000,20.00000,    -0.20895,0.96353
242.87199, 35.11750,    -0.27714,87.07558,50.00000,0.0000e+000,20.00000,    -0.20504,0.96147
244.56000, 35.29250,    -0.28625,87.04273,50.00000,0.0000e+000,20.00000,    -0.20153,0.95946
246.27600, 35.46750,    -0.29539,87.00867,50.00000,0.0000e+000,20.00000,    -0.19751,0.95743
247.97900, 35.64250,    -0.30451,86.97604,50.00000,0.0000e+000,20.00000,    -0.19333,0.95541
249.65700, 35.81750,    -0.31351,86.94459,50.00000,0.0000e+000,20.00000,    -0.19031,0.95343
251.35001, 35.99250,    -0.32243,86.91292,50.00000,0.0000e+000,20.00000,    -0.18778,0.95144
253.02400, 36.16750,    -0.33128,86.88181,50.00000,0.0000e+000,20.00000,    -0.18563,0.94947
254.70500, 36.34250,    -0.34022,86.85024,50.00000,0.0000e+000,20.00000,    -0.18348,0.94750
256.38300, 36.51750,    -0.34923,86.81990,50.00000,0.0000e+000,20.00000,    -0.18151,0.94554
258.07300, 36.69250,    -0.35815,86.78808,50.00000,0.0000e+000,20.00000,    -0.18056,0.94356
259.75400, 36.86750,    -0.36685,86.75646,50.00000,0.0000e+000,20.00000,    -0.17961,0.94161
261.42300, 37.04250,    -0.37517,86.72588,50.00000,0.0000e+000,20.00000,    -0.17931,0.93967
263.10101, 37.21750,    -0.38308,86.69582,50.00000,0.0000e+000,20.00000,    -0.17928,0.93772
264.76501, 37.39250,    -0.39076,86.66633,50.00000,0.0000e+000,20.00000,    -0.17959,0.93580
266.44299, 37.56750,    -0.39831,86.63570,50.00000,0.0000e+000,20.00000,    -0.18034,0.93386
268.11099, 37.74250,    -0.40563,86.60455,50.00000,0.0000e+000,20.00000,    -0.18123,0.93194
269.78000, 37.91750,    -0.41280,86.57363,50.00000,0.0000e+000,20.00000,    -0.18267,0.93003
271.46701, 38.09250,    -0.41975,86.54362,50.00000,0.0000e+000,20.00000,    -0.18383,0.92810
273.14600, 38.26750,    -0.42657,86.51384,50.00000,0.0000e+000,20.00000,    -0.18505,0.92618
274.82300, 38.44250,    -0.43326,86.48135,50.00000,0.0000e+000,20.00000,    -0.18646,0.92427
276.50299, 38.61750,    -0.43977,86.44849,50.00000,0.0000e+000,20.00000,    -0.18797,0.92236
278.18301, 38.79250,    -0.44615,86.41620,50.00000,0.0000e+000,20.00000,    -0.19007,0.92045
279.85400, 38.96750,    -0.45230,86.38365,50.00000,0.0000e+000,20.00000,    -0.19224,0.91856
281.55200, 39.14250,    -0.45816,86.34918,50.00000,0.0000e+000,20.00000,    -0.19461,0.91665
283.23999, 39.31750,    -0.46369,86.31459,50.00000,0.0000e+000,20.00000,    -0.19738,0.91475
284.92401, 39.49250,    -0.46895,86.28020,50.00000,0.0000e+000,20.00000,    -0.20074,0.91286
286.59601, 39.66750,    -0.47401,86.24418,50.00000,0.0000e+000,20.00000,    -0.20401,0.91098
288.28799, 39.84250,    -0.47898,86.20795,50.00000,0.0000e+000,20.00000,    -0.20739,0.90909
289.97900, 40.01750,    -0.48383,86.17253,50.00000,0.0000e+000,20.00000,    -0.21085,0.90721
291.67300, 40.19250,    -0.48854,86.13709,50.00000,0.0000e+000,20.00000,    -0.21395,0.90533
293.35999, 40.36750,    -0.49313,86.10006,50.00000,0.0000e+000,20.00000,    -0.21684,0.90346
295.05301, 40.54250,    -0.49759,86.06180,50.00000,0.0000e+000,20.00000,    -0.22002,0.90159
296.75000, 40.71750,    -0.50186,86.02327,50.00000,0.0000e+000,20.00000,    -0.22318,0.89972
298.44699, 40.89250,    -0.50605,85.98514,50.00000,0.0000e+000,20.00000,    -0.22614,0.89785
300.14801, 41.06750,    -0.51015,85.94625,50.00000,0.0000e+000,20.00000,    -0.22874,0.89599
301.84900, 41.24250,    -0.51438,85.90399,50.00000,0.0000e+000,20.00000,    -0.23197,0.89413
303.53900, 41.41750,    -0.51856,85.86056,50.00000,0.0000e+000,20.00000,    -0.23532,0.89229
305.25699, 41.59250,    -0.52248,85.81775,50.00000,0.0000e+000,20.00000,    -0.23855,0.89042
306.95499, 41.76750,    -0.52645,85.77511,50.00000,0.0000e+000,20.00000,    -0.24226,0.88858
308.66101, 41.94250,    -0.53045,85.73305,50.00000,0.0000e+000,20.00000,    -0.24628,0.88673
310.37399, 42.11750,    -0.53435,85.68979,50.00000,0.0000e+000,20.00000,    -0.25014,0.88488
312.09100, 42.29250,    -0.53833,85.64579,50.00000,0.0000e+000,20.00000,    -0.25375,0.88304
313.79599, 42.46750,    -0.54252,85.60193,50.00000,0.0000e+000,20.00000,    -0.25732,0.88121
315.49600, 42.64250,    -0.54671,85.55782,50.00000,0.0000e+000,20.00000,    -0.26077,0.87939
317.21600, 42.81750,    -0.55068,85.51341,50.00000,0.0000e+000,20.00000,    -0.26392,0.87756
318.92099, 42.99250,    -0.55446,85.46843,50.00000,0.0000e+000,20.00000,    -0.26653,0.87575
320.63699, 43.16750,    -0.55835,85.42125,50.00000,0.0000e+000,20.00000,    -0.26856,0.87393
322.35901, 43.34250,    -0.56247,85.37355,50.00000,0.0000e+000,20.00000,    -0.27104,0.87211
324.06900, 43.51750,    -0.56666,85.32454,50.00000,0.0000e+000,20.00000,    -0.27357,0.87031
325.78400, 43.69250,    -0.57077,85.27496,50.00000,0.0000e+000,20.00000,    -0.27645,0.86850
327.50500, 43.86750,    -0.57510,85.22474,50.00000,0.0000e+000,20.00000,    -0.27925,0.86670
329.22299, 44.04250,    -0.57989,85.17409,50.00000,0.0000e+000,20.00000,    -0.28184,0.86491
330.94901, 44.21750,    -0.58504,85.12264,50.00000,0.0000e+000,20.00000,    -0.28497,0.86311
332.68500, 44.39250,    -0.59015,85.07129,50.00000,0.0000e+000,20.00000,    -0.28884,0.86131
334.41599, 44.56750,    -0.59517,85.02109,50.00000,0.0000e+000,20.00000,    -0.29227,0.85952
336.14600, 44.74250,    -0.60041,84.97126,50.00000,0.0000e+000,20.00000,    -0.29606,0.85773
337.88901, 44.91750,    -0.60525,84.92079,50.00000,0.0000e+000,20.00000,    -0.29949,0.85594
339.64001, 45.09250,    -0.60918,84.86914,50.00000,0.0000e+000,20.00000,    -0.30235,0.85414
341.37299, 45.26750,    -0.61192,84.81704,50.00000,0.0000e+000,20.00000,    -0.30563,0.85237
343.08701, 45.44250,    -0.61392,84.76473,50.00000,0.0000e+000,20.00000,    -0.30993,0.85062
344.80899, 45.61750,    -0.61604,84.71186,50.00000,0.0000e+000,20.00000,    -0.31489,0.84887
346.52600, 45.79250,    -0.61884,84.65886,50.00000,0.0000e+000,20.00000,    -0.31887,0.84713
348.23700, 45.96750,    -0.62201,84.60474,50.00000,0.0000e+000,20.00000,    -0.32167,0.84541
349.94901, 46.14250,    -0.62545,84.54747,50.00000,0.0000e+000,20.00000,    -0.32474,0.84368
351.65799, 46.31750,    -0.62914,84.48988,50.00000,0.0000e+000,20.00000,    -0.32850,0.84197
353.38199, 46.49250,    -0.63309,84.43268,50.00000,0.0000e+000,20.00000,    -0.33291,0.84024
355.09299, 46.66750,    -0.63740,84.37346,50.00000,0.0000e+000,20.00000,    -0.33691,0.83854
356.82300, 46.84250,    -0.64172,84.31550,50.00000,0.0000e+000,20.00000,    -0.34036,0.83682
358.54401, 47.01750,    -0.64601,84.25644,50.00000,0.0000e+000,20.00000,    -0.34388,0.83511
360.27200, 47.19250,    -0.65033,84.19377,50.00000,0.0000e+000,20.00000,    -0.34733,0.83341
361.98499, 47.36750,    -0.65461,84.12610,50.00000,0.0000e+000,20.00000,    -0.35013,0.83172
363.72198, 47.54250,    -0.65892,84.05938,50.00000,0.0000e+000,20.00000,    -0.35235,0.83002
365.45200, 47.71750,    -0.66347,83.99675,50.00000,0.0000e+000,20.00000,    -0.35572,0.82833
367.19299, 47.89250,    -0.66785,83.93520,50.00000,0.0000e+000,20.00000,    -0.35898,0.82663
368.93301, 48.06750,    -0.67209,83.87120,50.00000,0.0000e+000,20.00000,    -0.35993,0.82494
370.65799, 48.24250,    -0.67641,83.80588,50.00000,0.0000e+000,20.00000,    -0.35988,0.82327
372.38599, 48.41750,    -0.68089,83.74029,50.00000,0.0000e+000,20.00000,    -0.36020,0.82160
374.13300, 48.59250,    -0.68562,83.67636,50.00000,0.0000e+000,20.00000,    -0.36127,0.81992
375.87000, 48.76750,    -0.69080,83.61216,50.00000,0.0000e+000,20.00000,    -0.36213,0.81826
377.59500, 48.94250,    -0.69639,83.54697,50.00000,0.0000e+000,20.00000,    -0.36201,0.81661
379.33499, 49.11750,    -0.70224,83.48316,50.00000,0.0000e+000,20.00000,    -0.36074,0.81495
381.08301, 49.29250,    -0.70817,83.42160,50.00000,0.0000e+000,20.00000,    -0.35910,0.81329
382.81400, 49.46750,    -0.71403,83.35877,50.00000,0.0000e+000,20.00000,    -0.35800,0.81166
384.55301, 49.64250,    -0.72000,83.29072,50.00000,0.0000e+000,20.00000,    -0.35789,0.81002
386.28601, 49.81750,    -0.72657,83.22580,50.00000,0.0000e+000,20.00000,    -0.35747,0.80839
388.00500, 49.99250,    -0.73371,83.16805,50.00000,0.0000e+000,20.00000,    -0.35647,0.80678
389.75101, 50.16750,    -0.74110,83.11023,50.00000,0.0000e+000,20.00000,    -0.35445,0.80515
391.48099, 50.34250,    -0.74868,83.04831,50.00000,0.0000e+000,20.00000,    -0.35240,0.80355
393.23199, 50.51750,    -0.75634,82.98626,50.00000,0.0000e+000,20.00000,    -0.35087,0.80192
394.94699, 50.69250,    -0.76391,82.92568,50.00000,0.0000e+000,20.00000,    -0.34897,0.80034
396.70200, 50.86750,    -0.77165,82.86521,50.00000,0.0000e+000,20.00000,    -0.34824,0.79873
398.45200, 51.04250,    -0.77963,82.80328,50.00000,0.0000e+000,20.00000,    -0.34898,0.79712
400.18900, 51.21750,    -0.78754,82.74212,50.00000,0.0000e+000,20.00000,    -0.34937,0.79554
401.94699, 51.39250,    -0.79487,82.68179,50.00000,0.0000e+000,20.00000,    -0.34787,0.79394
403.68500, 51.56750,    -0.80154,82.62040,50.00000,0.0000e+000,20.00000,    -0.34621,0.79236
405.44000, 51.74250,    -0.80775,82.55898,50.00000,0.0000e+000,20.00000,    -0.34728,0.79078
407.18399, 51.91750,    -0.81347,82.49915,50.00000,0.0000e+000,20.00000,    -0.34978,0.78921
408.92499, 52.09250,    -0.81898,82.44191,50.00000,0.0000e+000,20.00000,    -0.35126,0.78765
410.65302, 52.26750,    -0.82442,82.38410,50.00000,0.0000e+000,20.00000,    -0.35264,0.78610
412.37900, 52.44250,    -0.82980,82.32621,50.00000,0.0000e+000,20.00000,    -0.35383,0.78456
414.11401, 52.61750,    -0.83515,82.26645,50.00000,0.0000e+000,20.00000,    -0.35491,0.78303
415.84399, 52.79250,    -0.84076,82.20202,50.00000,0.0000e+000,20.00000,    -0.35638,0.78150
417.59000, 52.96750,    -0.84696,82.13764,50.00000,0.0000e+000,20.00000,    -0.35760,0.77996
419.33401, 53.14250,    -0.85323,82.07654,50.00000,0.0000e+000,20.00000,    -0.35934,0.77843
421.06699, 53.31750,    -0.85925,82.01552,50.00000,0.0000e+000,20.00000,    -0.36069,0.77691
422.79501, 53.49250,    -0.86497,81.95294,50.00000,0.0000e+000,20.00000,    -0.36218,0.77541
424.53799, 53.66750,    -0.87022,81.88685,50.00000,0.0000e+000,20.00000,    -0.36404,0.77390
426.27301, 53.84250,    -0.87517,81.82152,50.00000,0.0000e+000,20.00000,    -0.36680,0.77240
428.00900, 54.01750,    -0.88047,81.75464,50.00000,0.0000e+000,20.00000,    -0.37090,0.77090
429.73901, 54.19250,    -0.88607,81.68765,50.00000,0.0000e+000,20.00000,    -0.37328,0.76942
431.46399, 54.36750,    -0.89134,81.62362,50.00000,0.0000e+000,20.00000,    -0.37550,0.76794
433.21799, 54.54250,    -0.89649,81.55791,50.00000,0.0000e+000,20.00000,    -0.37749,0.76645
434.94501, 54.71750,    -0.90179,81.49124,50.00000,0.0000e+000,20.00000,    -0.37931,0.76498
436.67401, 54.89250,    -0.90722,81.42478,50.00000,0.0000e+000,20.00000,    -0.38244,0.76352
438.41101, 55.06750,    -0.91270,81.35844,50.00000,0.0000e+000,20.00000,    -0.38541,0.76206
440.13599, 55.24250,    -0.91810,81.29234,50.00000,0.0000e+000,20.00000,    -0.38793,0.76061
441.87701, 55.41750,    -0.92334,81.22441,50.00000,0.0000e+000,20.00000,    -0.38977,0.75916
443.62601, 55.59250,    -0.92832,81.15737,50.00000,0.0000e+000,20.00000,    -0.39154,0.75770
445.34900, 55.76750,    -0.93347,81.08594,50.00000,0.0000e+000,20.00000,    -0.39333,0.75627
447.08801, 55.94250,    -0.93884,81.01640,50.00000,0.0000e+000,20.00000,    -0.39451,0.75483
448.84000, 56.11750,    -0.94445,80.95090,50.00000,0.0000e+000,20.00000,    -0.39752,0.75339
450.56900, 56.29250,    -0.94984,80.88244,50.00000,0.0000e+000,20.00000,    -0.40143,0.75197
452.31299, 56.46750,    -0.95483,80.81148,50.00000,0.0000e+000,20.00000,    -0.40444,0.75055
454.05499, 56.64250,    -0.95995,80.73820,50.00000,0.0000e+000,20.00000,    -0.40769,0.74913
455.78201, 56.81750,    -0.96525,80.66536,50.00000,0.0000e+000,20.00000,    -0.41097,0.74773
457.52200, 56.99250,    -0.97050,80.59463,50.00000,0.0000e+000,20.00000,    -0.41421,0.74633
459.25500, 57.16750,    -0.97581,80.52342,50.00000,0.0000e+000,20.00000,    -0.41758,0.74494
461.00601, 57.34250,    -0.98106,80.45144,50.00000,0.0000e+000,20.00000,    -0.42021,0.74353
462.74500, 57.51750,    -0.98635,80.37891,50.00000,0.0000e+000,20.00000,    -0.42243,0.74215
464.47400, 57.69250,    -0.99155,80.30705,50.00000,0.0000e+000,20.00000,    -0.42520,0.74077
466.21500, 57.86750,    -0.99662,80.23331,50.00000,0.0000e+000,20.00000,    -0.42902,0.73939
467.95300, 58.04250,    -1.00142,80.15501,50.00000,0.0000e+000,20.00000,    -0.43370,0.73802
469.69800, 58.21750,    -1.00609,80.07671,50.00000,0.0000e+000,20.00000,    -0.43774,0.73665
471.42899, 58.39250,    -1.01075,79.99909,50.00000,0.0000e+000,20.00000,    -0.44047,0.73530
473.19199, 58.56750,    -1.01556,79.92023,50.00000,0.0000e+000,20.00000,    -0.44370,0.73393
474.93100, 58.74250,    -1.02041,79.84233,50.00000,0.0000e+000,20.00000,    -0.44824,0.73258
476.66901, 58.91750,    -1.02511,79.76369,50.00000,0.0000e+000,20.00000,    -0.45227,0.73124
478.42401, 59.09250,    -1.02952,79.68474,50.00000,0.0000e+000,20.00000,    -0.45685,0.72988
480.14401, 59.26750,    -1.03364,79.60915,50.00000,0.0000e+000,20.00000,    -0.46074,0.72857
481.87701, 59.44250,    -1.03770,79.52858,50.00000,0.0000e+000,20.00000,    -0.46471,0.72724
483.60999, 59.61750,    -1.04199,79.44737,50.00000,0.0000e+000,20.00000,    -0.46954,0.72593
485.36200, 59.79250,    -1.04667,79.36589,50.00000,0.0000e+000,20.00000,    -0.47195,0.72460
487.09399, 59.96750,    -1.05196,79.28032,50.00000,0.0000e+000,20.00000,    -0.47418,0.72329
488.83200, 60.14250,    -1.05758,79.19736,50.00000,0.0000e+000,20.00000,    -0.47838,0.72199
490.57800, 60.31750,    -1.06341,79.11415,50.00000,0.0000e+000,20.00000,    -0.48210,0.72068
492.31900, 60.49250,    -1.06931,79.02620,50.00000,0.0000e+000,20.00000,    -0.48405,0.71938
494.06799, 60.66750,    -1.07494,78.94004,50.00000,0.0000e+000,20.00000,    -0.48675,0.71809
495.81400, 60.84250,    -1.07994,78.85303,50.00000,0.0000e+000,20.00000,    -0.49002,0.71680
497.55801, 61.01750,    -1.08442,78.76485,50.00000,0.0000e+000,20.00000,    -0.49401,0.71551
499.31100, 61.19250,    -1.08930,78.67944,50.00000,0.0000e+000,20.00000,    -0.49710,0.71423
501.04199, 61.36750,    -1.09418,78.58980,50.00000,0.0000e+000,20.00000,    -0.49954,0.71296
502.78201, 61.54250,    -1.09897,78.50254,50.00000,0.0000e+000,20.00000,    -0.50283,0.71170
504.54001, 61.71750,    -1.10427,78.41721,50.00000,0.0000e+000,20.00000,    -0.50496,0.71043
506.27600, 61.89250,    -1.10985,78.32690,50.00000,0.0000e+000,20.00000,    -0.50677,0.70917
508.01501, 62.06750,    -1.11561,78.23294,50.00000,0.0000e+000,20.00000,    -0.50842,0.70793
509.78000, 62.24250,    -1.12164,78.14507,50.00000,0.0000e+000,20.00000,    -0.50979,0.70666
511.53101, 62.41750,    -1.12761,78.05937,50.00000,0.0000e+000,20.00000,    -0.51118,0.70542
513.27899, 62.59250,    -1.13331,77.96888,50.00000,0.0000e+000,20.00000,    -0.51259,0.70418
515.04303, 62.76750,    -1.13938,77.87729,50.00000,0.0000e+000,20.00000,    -0.51270,0.70293
516.80701, 62.94250,    -1.14593,77.78733,50.00000,0.0000e+000,20.00000,    -0.51422,0.70169
518.57202, 63.11750,    -1.15142,77.69783,50.00000,0.0000e+000,20.00000,    -0.51600,0.70046
520.33197, 63.29250,    -1.15579,77.60562,50.00000,0.0000e+000,20.00000,    -0.51769,0.69923
522.08600, 63.46750,    -1.15945,77.51348,50.00000,0.0000e+000,20.00000,    -0.51957,0.69801
523.82397, 63.64250,    -1.16305,77.42135,50.00000,0.0000e+000,20.00000,    -0.51827,0.69681
525.57098, 63.81750,    -1.16836,77.33239,50.00000,0.0000e+000,20.00000,    -0.51589,0.69561
527.33899, 63.99250,    -1.17604,77.24291,50.00000,0.0000e+000,20.00000,    -0.51545,0.69440
529.11298, 64.16750,    -1.18354,77.15050,50.00000,0.0000e+000,20.00000,    -0.51614,0.69319
530.86102, 64.34250,    -1.18926,77.05833,50.00000,0.0000e+000,20.00000,    -0.51517,0.69200
532.61700, 64.51750,    -1.19342,76.96917,50.00000,0.0000e+000,20.00000,    -0.51395,0.69081
534.35101, 64.69250,    -1.19647,76.87884,50.00000,0.0000e+000,20.00000,    -0.51189,0.68964
536.08502, 64.86750,    -1.19903,76.78580,50.00000,0.0000e+000,20.00000,    -0.50882,0.68848
537.79999, 65.04250,    -1.20228,76.69077,50.00000,0.0000e+000,20.00000,    -0.50542,0.68733
539.51898, 65.21750,    -1.20722,76.59589,50.00000,0.0000e+000,20.00000,    -0.50160,0.68619
541.24298, 65.39250,    -1.21372,76.50943,50.00000,0.0000e+000,20.00000,    -0.49737,0.68504
542.97803, 65.56750,    -1.22096,76.42718,50.00000,0.0000e+000,20.00000,    -0.49380,0.68390
544.70599, 65.74250,    -1.23020,76.33896,50.00000,0.0000e+000,20.00000,    -0.49109,0.68276
546.47601, 65.91750,    -1.24145,76.24963,50.00000,0.0000e+000,20.00000,    -0.48699,0.68161
548.22699, 66.09250,    -1.25153,76.16398,50.00000,0.0000e+000,20.00000,    -0.48044,0.68046
549.98700, 66.26750,    -1.25884,76.07821,50.00000,0.0000e+000,20.00000,    -0.47495,0.67932
551.71399, 66.44250,    -1.26413,75.99168,50.00000,0.0000e+000,20.00000,    -0.47021,0.67821
553.45203, 66.61750,    -1.26891,75.91238,50.00000,0.0000e+000,20.00000,    -0.46436,0.67709
555.18201, 66.79250,    -1.27442,75.83450,50.00000,0.0000e+000,20.00000,    -0.45776,0.67598
556.90100, 66.96750,    -1.28163,75.75515,50.00000,0.0000e+000,20.00000,    -0.45049,0.67488
558.64301, 67.14250,    -1.29035,75.67829,50.00000,0.0000e+000,20.00000,    -0.44429,0.67378
560.38300, 67.31750,    -1.29980,75.60090,50.00000,0.0000e+000,20.00000,    -0.43967,0.67268
562.12500, 67.49250,    -1.30956,75.52301,50.00000,0.0000e+000,20.00000,    -0.43354,0.67158
563.88098, 67.66750,    -1.31920,75.44460,50.00000,0.0000e+000,20.00000,    -0.42590,0.67048
565.64099, 67.84250,    -1.32869,75.37275,50.00000,0.0000e+000,20.00000,    -0.41815,0.66938
567.38702, 68.01750,    -1.33781,75.30433,50.00000,0.0000e+000,20.00000,    -0.41204,0.66830
569.15399, 68.19250,    -1.34643,75.23212,50.00000,0.0000e+000,20.00000,    -0.40527,0.66720
570.93103, 68.36750,    -1.35358,75.16135,50.00000,0.0000e+000,20.00000,    -0.39902,0.66611
572.66901, 68.54250,    -1.35976,75.09077,50.00000,0.0000e+000,20.00000,    -0.39317,0.66504
574.42297, 68.71750,    -1.36635,75.02150,50.00000,0.0000e+000,20.00000,    -0.38754,0.66397
576.17798, 68.89250,    -1.37344,74.95253,50.00000,0.0000e+000,20.00000,    -0.38185,0.66290
577.93903, 69.06750,    -1.38067,74.88563,50.00000,0.0000e+000,20.00000,    -0.37448,0.66183
579.69897, 69.24250,    -1.38853,74.82193,50.00000,0.0000e+000,20.00000,    -0.36594,0.66077
581.46802, 69.41750,    -1.39748,74.75910,50.00000,0.0000e+000,20.00000,    -0.35741,0.65971
583.24902, 69.59250,    -1.40679,74.69945,50.00000,0.0000e+000,20.00000,    -0.34904,0.65864
585.01898, 69.76750,    -1.41470,74.63870,50.00000,0.0000e+000,20.00000,    -0.34229,0.65759
586.78101, 69.94250,    -1.42094,74.57563,50.00000,0.0000e+000,20.00000,    -0.33491,0.65655
588.53198, 70.11750,    -1.42571,74.51412,50.00000,0.0000e+000,20.00000,    -0.32713,0.65551
590.26398, 70.29250,    -1.43012,74.45720,50.00000,0.0000e+000,20.00000,    -0.31935,0.65450
592.00897, 70.46750,    -1.43558,74.39986,50.00000,0.0000e+000,20.00000,    -0.31159,0.65347
593.74701, 70.64250,    -1.44293,74.34118,50.00000,0.0000e+000,20.00000,    -0.30365,0.65246
595.48499, 70.81750,    -1.45140,74.28773,50.00000,0.0000e+000,20.00000,    -0.29540,0.65145
597.22498, 70.99250,    -1.46003,74.24083,50.00000,0.0000e+000,20.00000,    -0.28781,0.65045
598.96997, 71.16750,    -1.46841,74.19360,50.00000,0.0000e+000,20.00000,    -0.28082,0.64944
600.72198, 71.34250,    -1.47659,74.14731,50.00000,0.0000e+000,20.00000,    -0.27435,0.64844
602.46600, 71.51750,    -1.48462,74.10338,50.00000,0.0000e+000,20.00000,    -0.26812,0.64744
604.19897, 71.69250,    -1.49274,74.05952,50.00000,0.0000e+000,20.00000,    -0.26050,0.64646
605.96698, 71.86750,    -1.50179,74.01583,50.00000,0.0000e+000,20.00000,    -0.25296,0.64546
607.72498, 72.04250,    -1.51274,73.97338,50.00000,0.0000e+000,20.00000,    -0.24670,0.64447
609.51703, 72.21750,    -1.52230,73.93141,50.00000,0.0000e+000,20.00000,    -0.24104,0.64347
611.27197, 72.39250,    -1.52834,73.89072,50.00000,0.0000e+000,20.00000,    -0.23423,0.64249
613.01898, 72.56750,    -1.53346,73.85173,50.00000,0.0000e+000,20.00000,    -0.22793,0.64151
614.79199, 72.74250,    -1.53953,73.81444,50.00000,0.0000e+000,20.00000,    -0.22325,0.64053
616.53998, 72.91750,    -1.54576,73.77708,50.00000,0.0000e+000,20.00000,    -0.21938,0.63957
618.30603, 73.09250,    -1.55105,73.73935,50.00000,0.0000e+000,20.00000,    -0.21546,0.63860
620.03497, 73.26750,    -1.55514,73.70215,50.00000,0.0000e+000,20.00000,    -0.21212,0.63766
621.78003, 73.44250,    -1.55821,73.66668,50.00000,0.0000e+000,20.00000,    -0.20843,0.63671
623.50403, 73.61750,    -1.56160,73.63196,50.00000,0.0000e+000,20.00000,    -0.20432,0.63577
625.26202, 73.79250,    -1.56614,73.59642,50.00000,0.0000e+000,20.00000,    -0.20101,0.63482
626.99402, 73.96750,    -1.57135,73.56015,50.00000,0.0000e+000,20.00000,    -0.19838,0.63389
628.74402, 74.14250,    -1.57660,73.52573,50.00000,0.0000e+000,20.00000,    -0.19587,0.63295
630.49103, 74.31750,    -1.58170,73.49206,50.00000,0.0000e+000,20.00000,    -0.19393,0.63202
632.22601, 74.49250,    -1.58673,73.45934,50.00000,0.0000e+000,20.00000,    -0.19265,0.63110
633.97101, 74.66750,    -1.59176,73.42733,50.00000,0.0000e+000,20.00000,    -0.19158,0.63018
635.71399, 74.84250,    -1.59651,73.39456,50.00000,0.0000e+000,20.00000,    -0.19024,0.62926
637.48102, 75.01750,    -1.60182,73.36165,50.00000,0.0000e+000,20.00000,    -0.18842,0.62834
639.24597, 75.19250,    -1.60959,73.33020,50.00000,0.0000e+000,20.00000,    -0.18676,0.62742
641.01898, 75.36750,    -1.61710,73.30120,50.00000,0.0000e+000,20.00000,    -0.18564,0.62649
642.77600, 75.54250,    -1.62167,73.27134,50.00000,0.0000e+000,20.00000,    -0.18434,0.62558
644.53198, 75.71750,    -1.62424,73.23929,50.00000,0.0000e+000,20.00000,    -0.18292,0.62468
646.28699, 75.89250,    -1.62619,73.20689,50.00000,0.0000e+000,20.00000,    -0.18209,0.62378
648.03998, 76.06750,    -1.62806,73.17454,50.00000,0.0000e+000,20.00000,    -0.18174,0.62288
649.79602, 76.24250,    -1.63053,73.14142,50.00000,0.0000e+000,20.00000,    -0.18168,0.62199
651.56000, 76.41750,    -1.63405,73.10823,50.00000,0.0000e+000,20.00000,    -0.18215,0.62109
653.31500, 76.59250,    -1.63864,73.07508,50.00000,0.0000e+000,20.00000,    -0.18229,0.62021
655.07098, 76.76750,    -1.64357,73.04329,50.00000,0.0000e+000,20.00000,    -0.18239,0.61933
656.84198, 76.94250,    -1.64748,73.01301,50.00000,0.0000e+000,20.00000,    -0.18294,0.61844
658.59003, 77.11750,    -1.65004,72.98242,50.00000,0.0000e+000,20.00000,    -0.18398,0.61757
660.35101, 77.29250,    -1.65104,72.95204,50.00000,0.0000e+000,20.00000,    -0.18488,0.61669
662.10400, 77.46750,    -1.65134,72.92139,50.00000,0.0000e+000,20.00000,    -0.18452,0.61582
663.83899, 77.64250,    -1.65273,72.88965,50.00000,0.0000e+000,20.00000,    -0.18306,0.61497
665.60400, 77.81750,    -1.65510,72.85708,50.00000,0.0000e+000,20.00000,    -0.18215,0.61410
667.34698, 77.99250,    -1.65716,72.82437,50.00000,0.0000e+000,20.00000,    -0.18149,0.61325
669.09100, 78.16750,    -1.65800,72.79077,50.00000,0.0000e+000,20.00000,    -0.18048,0.61240
670.82202, 78.34250,    -1.65901,72.75738,50.00000,0.0000e+000,20.00000,    -0.17952,0.61156
672.57300, 78.51750,    -1.66012,72.72447,50.00000,0.0000e+000,20.00000,    -0.17851,0.61072
674.30200, 78.69250,    -1.66167,72.69047,50.00000,0.0000e+000,20.00000,    -0.17722,0.60989
676.04602, 78.86750,    -1.66445,72.65616,50.00000,0.0000e+000,20.00000,    -0.17614,0.60905
677.79401, 79.04250,    -1.66813,72.62329,50.00000,0.0000e+000,20.00000,    -0.17502,0.60822
679.52502, 79.21750,    -1.67199,72.59203,50.00000,0.0000e+000,20.00000,    -0.17359,0.60739
681.28699, 79.39250,    -1.67566,72.56403,50.00000,0.0000e+000,20.00000,    -0.17154,0.60656
683.02100, 79.56750,    -1.67925,72.53637,50.00000,0.0000e+000,20.00000,    -0.16878,0.60574
684.78497, 79.74250,    -1.68327,72.50623,50.00000,0.0000e+000,20.00000,    -0.16534,0.60491
686.54199, 79.91750,    -1.68790,72.47620,50.00000,0.0000e+000,20.00000,    -0.16175,0.60409
688.31299, 80.09250,    -1.69291,72.44686,50.00000,0.0000e+000,20.00000,    -0.15829,0.60326
690.09198, 80.26750,    -1.69939,72.41701,50.00000,0.0000e+000,20.00000,    -0.15559,0.60244
691.87903, 80.44250,    -1.70564,72.39000,50.00000,0.0000e+000,20.00000,    -0.15203,0.60161
693.64099, 80.61750,    -1.70877,72.36408,50.00000,0.0000e+000,20.00000,    -0.14764,0.60080
695.40399, 80.79250,    -1.70862,72.33732,50.00000,0.0000e+000,20.00000,    -0.14360,0.59999
697.14697, 80.96750,    -1.70688,72.31154,50.00000,0.0000e+000,20.00000,    -0.13969,0.59919
698.87299, 81.14250,    -1.70626,72.28723,50.00000,0.0000e+000,20.00000,    -0.13602,0.59840
700.61298, 81.31750,    -1.70778,72.26420,50.00000,0.0000e+000,20.00000,    -0.13309,0.59762
702.37402, 81.49250,    -1.71234,72.24335,50.00000,0.0000e+000,20.00000,    -0.12983,0.59682
704.14099, 81.66750,    -1.71806,72.22344,50.00000,0.0000e+000,20.00000,    -0.12594,0.59602
705.90100, 81.84250,    -1.72126,72.20312,50.00000,0.0000e+000,20.00000,    -0.12253,0.59523
707.64001, 82.01750,    -1.72210,72.18065,50.00000,0.0000e+000,20.00000,    -0.11920,0.59445
709.41302, 82.19250,    -1.72508,72.15850,50.00000,0.0000e+000,20.00000,    -0.11602,0.59366
711.15503, 82.36750,    -1.72831,72.13985,50.00000,0.0000e+000,20.00000,    -0.11318,0.59289
712.90802, 82.54250,    -1.72973,72.12105,50.00000,0.0000e+000,20.00000,    -0.10982,0.59212
714.65698, 82.71750,    -1.73109,72.10276,50.00000,0.0000e+000,20.00000,    -0.10603,0.59134
716.40100, 82.89250,    -1.73334,72.08586,50.00000,0.0000e+000,20.00000,    -0.10241,0.59058
718.15698, 83.06750,    -1.73663,72.07000,50.00000,0.0000e+000,20.00000,-9.9946e-002,0.58981
719.90399, 83.24250,    -1.74046,72.05276,50.00000,0.0000e+000,20.00000,-9.8000e-002,0.58905
721.66101, 83.41750,    -1.74419,72.03620,50.00000,0.0000e+000,20.00000,-9.6498e-002,0.58828
723.40198, 83.59250,    -1.74783,72.01973,50.00000,0.0000e+000,20.00000,-9.4899e-002,0.58753
725.13300, 83.76750,    -1.75138,72.00219,50.00000,0.0000e+000,20.00000,-9.2740e-002,0.58678
726.91602, 83.94250,    -1.75790,71.98489,50.00000,0.0000e+000,20.00000,-8.9265e-002,0.58602
728.69702, 84.11750,    -1.76655,71.96859,50.00000,0.0000e+000,20.00000,-8.6863e-002,0.58525
730.47900, 84.29250,    -1.77203,71.95406,50.00000,0.0000e+000,20.00000,-8.5191e-002,0.58449
732.24103, 84.46750,    -1.77331,71.94035,50.00000,0.0000e+000,20.00000,-8.3687e-002,0.58374
733.99902, 84.64250,    -1.77224,71.92905,50.00000,0.0000e+000,20.00000,-8.1554e-002,0.58300
735.73798, 84.81750,    -1.77220,71.91563,50.00000,0.0000e+000,20.00000,-7.9884e-002,0.58226
737.49597, 84.99250,    -1.77521,71.90055,50.00000,0.0000e+000,20.00000,-7.8244e-002,0.58152
739.24298, 85.16750,    -1.77919,71.88599,50.00000,0.0000e+000,20.00000,-7.6425e-002,0.58079
741.02100, 85.34250,    -1.78257,71.87172,50.00000,0.0000e+000,20.00000,-7.5048e-002,0.58004
742.77399, 85.51750,    -1.78544,71.85749,50.00000,0.0000e+000,20.00000,-7.2960e-002,0.57931
744.52197, 85.69250,    -1.78748,71.84609,50.00000,0.0000e+000,20.00000,-7.0459e-002,0.57859
746.25500, 85.86750,    -1.78952,71.83549,50.00000,0.0000e+000,20.00000,-6.7941e-002,0.57787
747.99701, 86.04250,    -1.79257,71.82381,50.00000,0.0000e+000,20.00000,-6.5925e-002,0.57715
749.74402, 86.21750,    -1.79519,71.81049,50.00000,0.0000e+000,20.00000,-6.4345e-002,0.57643
751.48401, 86.39250,    -1.79704,71.79894,50.00000,0.0000e+000,20.00000,-6.3309e-002,0.57571
753.23999, 86.56750,    -1.80035,71.78989,50.00000,0.0000e+000,20.00000,-6.1577e-002,0.57500
754.99902, 86.74250,    -1.80714,71.77903,50.00000,0.0000e+000,20.00000,-5.9165e-002,0.57428
756.78400, 86.91750,    -1.81548,71.76887,50.00000,0.0000e+000,20.00000,-5.7538e-002,0.57355
758.55298, 87.09250,    -1.82226,71.75767,50.00000,0.0000e+000,20.00000,-5.5471e-002,0.57284
760.32098, 87.26750,    -1.82676,71.74737,50.00000,0.0000e+000,20.00000,-5.3408e-002,0.57212
762.08002, 87.44250,    -1.82863,71.73859,50.00000,0.0000e+000,20.00000,-5.2337e-002,0.57141
763.82202, 87.61750,    -1.82850,71.73058,50.00000,0.0000e+000,20.00000,-5.1779e-002,0.57071
765.55902, 87.79250,    -1.82878,71.72300,50.00000,0.0000e+000,20.00000,-5.1139e-002,0.57002
767.28900, 87.96750,    -1.83051,71.71481,50.00000,0.0000e+000,20.00000,-5.0375e-002,0.56933
769.03601, 88.14250,    -1.83325,71.70613,50.00000,0.0000e+000,20.00000,-4.9243e-002,0.56863
770.78198, 88.31750,    -1.83767,71.69901,50.00000,0.0000e+000,20.00000,-4.8823e-002,0.56794
772.53900, 88.49250,    -1.84387,71.69410,50.00000,0.0000e+000,20.00000,-4.8440e-002,0.56724
774.30200, 88.66750,    -1.85022,71.68609,50.00000,0.0000e+000,20.00000,-4.7685e-002,0.56655
776.07001, 88.84250,    -1.85581,71.67781,50.00000,0.0000e+000,20.00000,-4.6980e-002,0.56585
777.82202, 89.01750,    -1.86048,71.67204,50.00000,0.0000e+000,20.00000,-4.6538e-002,0.56516
779.59601, 89.19250,    -1.86497,71.66331,50.00000,0.0000e+000,20.00000,-4.6996e-002,0.56447
781.37701, 89.36750,    -1.86908,71.65479,50.00000,0.0000e+000,20.00000,-4.7316e-002,0.56377
783.11798, 89.54250,    -1.87248,71.64628,50.00000,0.0000e+000,20.00000,-4.7513e-002,0.56310
784.85303, 89.71750,    -1.87421,71.63677,50.00000,0.0000e+000,20.00000,-4.7704e-002,0.56242
786.59399, 89.89250,    -1.87505,71.62724,50.00000,0.0000e+000,20.00000,-4.7752e-002,0.56175
788.33301, 90.06750,    -1.87702,71.61917,50.00000,0.0000e+000,20.00000,-4.8309e-002,0.56108
790.07300, 90.24250,    -1.88043,71.61069,50.00000,0.0000e+000,20.00000,-4.9758e-002,0.56041
791.82800, 90.41750,    -1.88463,71.60238,50.00000,0.0000e+000,20.00000,-5.0307e-002,0.55973
793.57501, 90.59250,    -1.88866,71.59477,50.00000,0.0000e+000,20.00000,-5.0028e-002,0.55906
795.32703, 90.76750,    -1.89331,71.58594,50.00000,0.0000e+000,20.00000,-5.0330e-002,0.55839
797.08600, 90.94250,    -1.89889,71.57559,50.00000,0.0000e+000,20.00000,-5.0651e-002,0.55772
798.83698, 91.11750,    -1.90418,71.56487,50.00000,0.0000e+000,20.00000,-5.1276e-002,0.55706
800.61603, 91.29250,    -1.90867,71.55658,50.00000,0.0000e+000,20.00000,-5.1699e-002,0.55638
802.37598, 91.46750,    -1.91254,71.54784,50.00000,0.0000e+000,20.00000,-5.1358e-002,0.55571
804.13898, 91.64250,    -1.91664,71.53949,50.00000,0.0000e+000,20.00000,-5.0859e-002,0.55505
805.90503, 91.81750,    -1.92045,71.52991,50.00000,0.0000e+000,20.00000,-5.0711e-002,0.55438
807.64697, 91.99250,    -1.92255,71.51909,50.00000,0.0000e+000,20.00000,-5.0625e-002,0.55373
809.40900, 92.16750,    -1.92783,71.50957,50.00000,0.0000e+000,20.00000,-5.0576e-002,0.55307
811.23102, 92.34250,    -1.93874,71.50187,50.00000,0.0000e+000,20.00000,-5.1499e-002,0.55239
813.01599, 92.51750,    -1.94651,71.49388,50.00000,0.0000e+000,20.00000,-5.2298e-002,0.55172
814.78003, 92.69250,    -1.94680,71.48649,50.00000,0.0000e+000,20.00000,-5.2879e-002,0.55106
816.51398, 92.86750,    -1.94294,71.47612,50.00000,0.0000e+000,20.00000,-5.3122e-002,0.55042
818.24402, 93.04250,    -1.93819,71.46517,50.00000,0.0000e+000,20.00000,-5.3805e-002,0.54978
819.97198, 93.21750,    -1.93489,71.45676,50.00000,0.0000e+000,20.00000,-5.4360e-002,0.54914
821.69897, 93.39250,    -1.93416,71.44906,50.00000,0.0000e+000,20.00000,-5.4936e-002,0.54850
823.42798, 93.56750,    -1.93682,71.44084,50.00000,0.0000e+000,20.00000,-5.5527e-002,0.54786
825.18500, 93.74250,    -1.93998,71.43291,50.00000,0.0000e+000,20.00000,-5.5899e-002,0.54722
826.90601, 93.91750,    -1.94188,71.42517,50.00000,0.0000e+000,20.00000,-5.6629e-002,0.54658
828.64203, 94.09250,    -1.94420,71.41499,50.00000,0.0000e+000,20.00000,-5.7785e-002,0.54595
830.41400, 94.26750,    -1.95056,71.40381,50.00000,0.0000e+000,20.00000,-5.8602e-002,0.54530
832.21399, 94.44250,    -1.95887,71.39240,50.00000,0.0000e+000,20.00000,-5.9952e-002,0.54464
833.98602, 94.61750,    -1.96285,71.38046,50.00000,0.0000e+000,20.00000,-6.1068e-002,0.54400
835.75299, 94.79250,    -1.96369,71.36860,50.00000,0.0000e+000,20.00000,-6.1683e-002,0.54336
837.51099, 94.96750,    -1.96305,71.35750,50.00000,0.0000e+000,20.00000,-6.2952e-002,0.54272
839.26001, 95.14250,    -1.96171,71.34732,50.00000,0.0000e+000,20.00000,-6.5215e-002,0.54208
841.01099, 95.31750,    -1.95969,71.33619,50.00000,0.0000e+000,20.00000,-6.7758e-002,0.54145
842.74500, 95.49250,    -1.95613,71.32511,50.00000,0.0000e+000,20.00000,-7.0092e-002,0.54082
844.46899, 95.66750,    -1.95492,71.31232,50.00000,0.0000e+000,20.00000,-7.2503e-002,0.54020
846.21399, 95.84250,    -1.95815,71.29928,50.00000,0.0000e+000,20.00000,-7.4472e-002,0.53958
847.98102, 96.01750,    -1.96320,71.28808,50.00000,0.0000e+000,20.00000,-7.5141e-002,0.53894
849.78900, 96.19250,    -1.97433,71.27638,50.00000,0.0000e+000,20.00000,-7.6529e-002,0.53829
851.63397, 96.36750,    -1.98665,71.26368,50.00000,0.0000e+000,20.00000,-7.8020e-002,0.53763
853.42798, 96.54250,    -1.98940,71.25041,50.00000,0.0000e+000,20.00000,-7.9548e-002,0.53699
855.19897, 96.71750,    -1.98531,71.23651,50.00000,0.0000e+000,20.00000,-8.0796e-002,0.53636
856.96002, 96.89250,    -1.97976,71.22159,50.00000,0.0000e+000,20.00000,-8.2467e-002,0.53573
858.68903, 97.06750,    -1.97379,71.20442,50.00000,0.0000e+000,20.00000,-8.4199e-002,0.53511
860.43799, 97.24250,    -1.96758,71.18751,50.00000,0.0000e+000,20.00000,-8.5570e-002,0.53449
862.16199, 97.41750,    -1.96281,71.17102,50.00000,0.0000e+000,20.00000,-8.7355e-002,0.53388
863.88702, 97.59250,    -1.96168,71.15450,50.00000,0.0000e+000,20.00000,-8.8945e-002,0.53327
865.63397, 97.76750,    -1.96313,71.14003,50.00000,0.0000e+000,20.00000,-9.0523e-002,0.53265
867.37201, 97.94250,    -1.96414,71.12547,50.00000,0.0000e+000,20.00000,-9.2136e-002,0.53204
869.10400, 98.11750,    -1.96519,71.10816,50.00000,0.0000e+000,20.00000,-9.4185e-002,0.53143
870.84698, 98.29250,    -1.96580,71.09091,50.00000,0.0000e+000,20.00000,-9.6549e-002,0.53081
872.58801, 98.46750,    -1.96563,71.07380,50.00000,0.0000e+000,20.00000,-9.7804e-002,0.53020
874.31403, 98.64250,    -1.96449,71.05802,50.00000,0.0000e+000,20.00000,-9.8650e-002,0.52959
876.05603, 98.81750,    -1.96597,71.04081,50.00000,0.0000e+000,20.00000,-9.9453e-002,0.52898
877.82098, 98.99250,    -1.97069,71.02456,50.00000,0.0000e+000,20.00000,    -0.10041,0.52836
879.59698, 99.16750,    -1.97553,71.00739,50.00000,0.0000e+000,20.00000,    -0.10197,0.52773
881.35699, 99.34250,    -1.97833,70.98815,50.00000,0.0000e+000,20.00000,    -0.10359,0.52712
883.11798, 99.51750,    -1.97901,70.96973,50.00000,0.0000e+000,20.00000,    -0.10524,0.52650
884.84802, 99.69250,    -1.97735,70.95263,50.00000,0.0000e+000,20.00000,    -0.10705,0.52590
886.59198, 99.86750,    -1.97517,70.93441,50.00000,0.0000e+000,20.00000,    -0.10838,0.52529
888.33301,100.04250,    -1.97406,70.91289,50.00000,0.0000e+000,20.00000,    -0.10966,0.52468
890.08197,100.21750,    -1.97309,70.89288,50.00000,0.0000e+000,20.00000,    -0.11104,0.52407
891.83502,100.39250,    -1.97282,70.87575,50.00000,0.0000e+000,20.00000,    -0.11320,0.52346
893.59399,100.56750,    -1.97395,70.85743,50.00000,0.0000e+000,20.00000,    -0.11543,0.52285
895.34900,100.74250,    -1.97623,70.83730,50.00000,0.0000e+000,20.00000,    -0.11758,0.52224
897.12097,100.91750,    -1.98593,70.81554,50.00000,0.0000e+000,20.00000,    -0.12001,0.52162
899.10797,101.09250,    -2.01318,70.79311,50.00000,0.0000e+000,20.00000,    -0.12139,0.52093
901.02698,101.26750,    -2.03276,70.77083,50.00000,0.0000e+000,20.00000,    -0.12313,0.52026
902.85901,101.44250,    -2.02709,70.75002,50.00000,0.0000e+000,20.00000,    -0.12544,0.51963
904.58899,101.61750,    -2.00798,70.72942,50.00000,0.0000e+000,20.00000,    -0.12775,0.51903
906.30798,101.79250,    -1.98815,70.70751,50.00000,0.0000e+000,20.00000,    -0.12951,0.51843
907.99200,101.96750,    -1.97244,70.68539,50.00000,0.0000e+000,20.00000,    -0.13113,0.51785
909.68500,102.14250,    -1.96204,70.66214,50.00000,0.0000e+000,20.00000,    -0.13320,0.51727
911.37402,102.31750,    -1.95482,70.63758,50.00000,0.0000e+000,20.00000,    -0.13552,0.51668
913.06000,102.49250,    -1.94960,70.61283,50.00000,0.0000e+000,20.00000,    -0.13786,0.51610
914.75000,102.66750,    -1.94779,70.58773,50.00000,0.0000e+000,20.00000,    -0.13970,0.51551
916.46698,102.84250,    -1.94903,70.56354,50.00000,0.0000e+000,20.00000,    -0.14080,0.51492
918.18597,103.01750,    -1.95021,70.53918,50.00000,0.0000e+000,20.00000,    -0.14189,0.51433
919.90900,103.19250,    -1.95220,70.51304,50.00000,0.0000e+000,20.00000,    -0.14361,0.51373
921.65002,103.36750,    -1.95705,70.48737,50.00000,0.0000e+000,20.00000,    -0.14549,0.51313
923.39600,103.54250,    -1.96140,70.46132,50.00000,0.0000e+000,20.00000,    -0.14637,0.51253
925.14502,103.71750,    -1.96452,70.43387,50.00000,0.0000e+000,20.00000,    -0.14722,0.51193
926.90198,103.89250,    -1.96761,70.40759,50.00000,0.0000e+000,20.00000,    -0.14902,0.51132
928.68298,104.06750,    -1.97160,70.38227,50.00000,0.0000e+000,20.00000,    -0.15015,0.51071
930.44897,104.24250,    -1.97503,70.35501,50.00000,0.0000e+000,20.00000,    -0.15055,0.51010
932.21503,104.41750,    -1.97569,70.32688,50.00000,0.0000e+000,20.00000,    -0.15075,0.50949
933.98499,104.59250,    -1.97810,70.29996,50.00000,0.0000e+000,20.00000,    -0.15044,0.50888
935.80298,104.76750,    -1.98535,70.27389,50.00000,0.0000e+000,20.00000,    -0.14990,0.50826
937.61298,104.94250,    -1.98896,70.24653,50.00000,0.0000e+000,20.00000,    -0.14884,0.50763
939.37598,105.11750,    -1.98673,70.21874,50.00000,0.0000e+000,20.00000,    -0.14719,0.50703
941.13300,105.29250,    -1.98243,70.19290,50.00000,0.0000e+000,20.00000,    -0.14475,0.50642
942.87598,105.46750,    -1.97817,70.16886,50.00000,0.0000e+000,20.00000,    -0.14095,0.50582
944.60101,105.64250,    -1.97468,70.14111,50.00000,0.0000e+000,20.00000,    -0.13699,0.50523
946.34302,105.81750,    -1.97288,70.11193,50.00000,0.0000e+000,20.00000,    -0.13282,0.50463
948.09497,105.99250,    -1.97265,70.08504,50.00000,0.0000e+000,20.00000,    -0.12898,0.50402
949.83398,106.16750,    -1.97316,70.05916,50.00000,0.0000e+000,20.00000,    -0.12464,0.50343
951.57300,106.34250,    -1.97454,70.03429,50.00000,0.0000e+000,20.00000,    -0.11942,0.50283
953.30798,106.51750,    -1.97815,70.01204,50.00000,0.0000e+000,20.00000,    -0.11378,0.50223
955.09497,106.69250,    -1.98475,69.99012,50.00000,0.0000e+000,20.00000,    -0.10843,0.50161
956.84497,106.86750,    -1.98926,69.96927,50.00000,0.0000e+000,20.00000,    -0.10333,0.50101
958.57501,107.04250,    -1.99045,69.95070,50.00000,0.0000e+000,20.00000,-9.8061e-002,0.50042
960.32098,107.21750,    -1.99427,69.93665,50.00000,0.0000e+000,20.00000,-9.3322e-002,0.49981
962.10199,107.39250,    -1.99962,69.92363,50.00000,0.0000e+000,20.00000,-8.8414e-002,0.49920
963.84802,107.56750,    -2.00230,69.91244,50.00000,0.0000e+000,20.00000,-8.1991e-002,0.49860
965.58600,107.74250,    -2.00329,69.90178,50.00000,0.0000e+000,20.00000,-7.4948e-002,0.49800
967.35498,107.91750,    -2.00444,69.88869,50.00000,0.0000e+000,20.00000,-6.8363e-002,0.49739
969.09802,108.09250,    -2.00466,69.87854,50.00000,0.0000e+000,20.00000,-6.2343e-002,0.49679
970.84601,108.26750,    -2.00644,69.87186,50.00000,0.0000e+000,20.00000,-5.7514e-002,0.49618
972.59198,108.44250,    -2.01012,69.86622,50.00000,0.0000e+000,20.00000,-5.3253e-002,0.49558
974.36200,108.61750,    -2.01371,69.85725,50.00000,0.0000e+000,20.00000,-4.8643e-002,0.49497
976.12701,108.79250,    -2.01597,69.84881,50.00000,0.0000e+000,20.00000,-4.4154e-002,0.49436
977.88397,108.96750,    -2.01723,69.84167,50.00000,0.0000e+000,20.00000,-4.0842e-002,0.49375
979.64203,109.14250,    -2.02001,69.83424,50.00000,0.0000e+000,20.00000,-3.9692e-002,0.49314
981.40503,109.31750,    -2.02197,69.82709,50.00000,0.0000e+000,20.00000,-3.7633e-002,0.49253
983.14697,109.49250,    -2.02207,69.82344,50.00000,0.0000e+000,20.00000,-3.3968e-002,0.49193
984.91498,109.66750,    -2.02415,69.82183,50.00000,0.0000e+000,20.00000,-3.2853e-002,0.49132
986.67798,109.84250,    -2.02649,69.81890,50.00000,0.0000e+000,20.00000,-3.0977e-002,0.49071
988.41998,110.01750,    -2.02515,69.81433,50.00000,0.0000e+000,20.00000,-2.8905e-002,0.49010
990.16498,110.19250,    -2.02321,69.80777,50.00000,0.0000e+000,20.00000,-2.6565e-002,0.48950
991.90698,110.36750,    -2.02357,69.80239,50.00000,0.0000e+000,20.00000,-3.0360e-002,0.48889
993.66602,110.54250,    -2.02493,69.79844,50.00000,0.0000e+000,20.00000,-3.2432e-002,0.48828
995.41199,110.71750,    -2.02525,69.79541,50.00000,0.0000e+000,20.00000,-3.2409e-002,0.48767
997.17499,110.89250,    -2.02505,69.78875,50.00000,0.0000e+000,20.00000,-5.0060e-002,0.48706
998.32001,111.00750,    -2.02552,69.78221,50.00000,0.0000e+000,20.00000,-6.0427e-002,0.48666