File: book/some_content/DG_ExpDat_OPC7%DC14; 30-1-2025-2.csv
#FILE:                       ,OPC7%DC14; 30-1-2025.ngb-ds3
#FORMAT:                     ,NETZSCH5
#IDENTITY:                   ,GEOPOLYMER PASTE
#DECIMAL:                    ,POINT
#SEPARATOR:                  ,COMMA
#MTYPE:                      ,DSC
#INSTRUMENT:                 ,Microlab TU Delft
#PROJECT:                    ,
#DATE/TIME:                  ,30/01/2025 8:58:29 PM
#CORR. FILE:                 ,Blank with cover; 13-1-2025.ngb-bs3
#LABORATORY:                 ,TU Delft Micro Lab
#OPERATOR:                   ,Ahmed
#REMARK:                     ,under Argon atmosphere, 10K/min
#SAMPLE:                     ,OPC7%DC14
#SAMPLE MASS /mg:            ,32.6
#MATERIAL:                   ,Geopolymer paste
#REFERENCE:                  ,blank
#REFERENCE MASS /mg:         ,0
#TYPE OF CRUCIBLE:           ,DSC/TG pan Al2O3
#SAMPLE CRUCIBLE MASS /mg:   ,0
#REFERENCE CRUCIBLE MASS /mg:,0
#CORR. CODE:                 ,020
#EXO:                        ,-1
#RANGE:                      ,40/10.0(K/min)/1000
#SEGMENT:                    ,S2/2

##Temp./øC,Time/min,DSC/(mW/mg),Mass/%,Gas Flow(purge1)/(ml/min),Gas Flow(purge2)/(ml/min),Gas Flow(protective)/(ml/min),DTG/(%/min),Sensit./(uV/mW)
 50.70000, 18.36500,-7.0912e-002,95.64622,50.00000,0.0000e+000,20.00000,-5.5590e-002,1.21220
 50.75300, 18.54000,-7.2500e-002,95.64174,50.00000,0.0000e+000,20.00000,-3.9771e-002,1.21212
 50.89000, 18.71500,-7.4230e-002,95.63962,50.00000,0.0000e+000,20.00000,-2.4139e-002,1.21193
 51.11600, 18.89000,-7.4789e-002,95.64115,50.00000,0.0000e+000,20.00000,-8.8586e-003,1.21162
 51.44200, 19.06500,-7.4392e-002,95.64694,50.00000,0.0000e+000,20.00000, 5.7272e-003,1.21117
 51.86500, 19.24000,-7.3925e-002,95.65588,50.00000,0.0000e+000,20.00000, 1.8529e-002,1.21059
 52.39200, 19.41500,-7.2828e-002,95.66820,50.00000,0.0000e+000,20.00000, 3.0626e-002,1.20987
 53.03200, 19.59000,-7.0713e-002,95.68252,50.00000,0.0000e+000,20.00000, 4.3010e-002,1.20899
 53.80000, 19.76500,-6.8702e-002,95.70017,50.00000,0.0000e+000,20.00000, 5.3382e-002,1.20793
 54.67700, 19.94000,-6.5920e-002,95.71905,50.00000,0.0000e+000,20.00000, 5.9907e-002,1.20672
 55.66200, 20.11500,-6.3023e-002,95.73533,50.00000,0.0000e+000,20.00000, 6.5082e-002,1.20537
 56.76700, 20.29000,-5.9623e-002,95.75302,50.00000,0.0000e+000,20.00000, 6.8931e-002,1.20385
 58.01700, 20.46500,-5.6010e-002,95.77312,50.00000,0.0000e+000,20.00000, 7.0268e-002,1.20213
 59.38100, 20.64000,-5.2626e-002,95.79309,50.00000,0.0000e+000,20.00000, 6.9991e-002,1.20025
 60.81600, 20.81500,-4.9432e-002,95.81229,50.00000,0.0000e+000,20.00000, 6.7915e-002,1.19828
 62.39500, 20.99000,-4.5823e-002,95.82836,50.00000,0.0000e+000,20.00000, 6.4147e-002,1.19611
 64.05100, 21.16500,-4.2559e-002,95.84000,50.00000,0.0000e+000,20.00000, 5.8969e-002,1.19384
 65.85100, 21.34000,-3.9327e-002,95.85232,50.00000,0.0000e+000,20.00000, 5.2493e-002,1.19137
 67.71300, 21.51500,-3.6400e-002,95.86640,50.00000,0.0000e+000,20.00000, 4.4065e-002,1.18881
 69.65200, 21.69000,-3.3167e-002,95.87551,50.00000,0.0000e+000,20.00000, 3.3318e-002,1.18615
 71.69900, 21.86500,-3.0397e-002,95.88296,50.00000,0.0000e+000,20.00000, 2.1694e-002,1.18335
 73.82200, 22.04000,-2.7478e-002,95.89233,50.00000,0.0000e+000,20.00000, 9.5511e-003,1.18044
 76.03200, 22.21500,-2.4826e-002,95.89706,50.00000,0.0000e+000,20.00000,-4.8944e-003,1.17741
 78.29400, 22.39000,-2.1364e-002,95.89643,50.00000,0.0000e+000,20.00000,-2.1696e-002,1.17432
 80.62300, 22.56500,-1.8145e-002,95.89416,50.00000,0.0000e+000,20.00000,-4.0500e-002,1.17114
 83.04100, 22.74000,-1.4489e-002,95.88901,50.00000,0.0000e+000,20.00000,-6.0718e-002,1.16784
 85.50000, 22.91500,-1.0772e-002,95.88166,50.00000,0.0000e+000,20.00000,-8.0972e-002,1.16448
 88.01400, 23.09000,-6.7727e-003,95.87270,50.00000,0.0000e+000,20.00000,    -0.10242,1.16106
 90.58300, 23.26500,-2.3048e-003,95.86024,50.00000,0.0000e+000,20.00000,    -0.12757,1.15756
 93.20000, 23.44000, 2.7175e-003,95.84229,50.00000,0.0000e+000,20.00000,    -0.15318,1.15400
 95.84700, 23.61500, 8.0356e-003,95.81922,50.00000,0.0000e+000,20.00000,    -0.17690,1.15040
 98.52300, 23.79000, 1.4449e-002,95.79239,50.00000,0.0000e+000,20.00000,    -0.20190,1.14677
101.21500, 23.96500, 2.0985e-002,95.76200,50.00000,0.0000e+000,20.00000,    -0.22928,1.14313
103.94300, 24.14000, 2.7666e-002,95.72426,50.00000,0.0000e+000,20.00000,    -0.25508,1.13944
106.65900, 24.31500, 3.5483e-002,95.67866,50.00000,0.0000e+000,20.00000,    -0.27915,1.13577
109.39900, 24.49000, 4.2855e-002,95.62543,50.00000,0.0000e+000,20.00000,    -0.30338,1.13207
112.15700, 24.66500, 5.0815e-002,95.56663,50.00000,0.0000e+000,20.00000,    -0.32609,1.12836
114.91200, 24.84000, 5.8557e-002,95.50297,50.00000,0.0000e+000,20.00000,    -0.34746,1.12465
117.64600, 25.01500, 6.6056e-002,95.42994,50.00000,0.0000e+000,20.00000,    -0.36892,1.12098
120.39500, 25.19000, 7.3354e-002,95.34828,50.00000,0.0000e+000,20.00000,    -0.38956,1.11729
123.15100, 25.36500, 7.9859e-002,95.26787,50.00000,0.0000e+000,20.00000,    -0.40883,1.11360
125.90300, 25.54000, 8.5395e-002,95.18788,50.00000,0.0000e+000,20.00000,    -0.42566,1.10993
128.64700, 25.71500, 8.9761e-002,95.09991,50.00000,0.0000e+000,20.00000,    -0.44107,1.10627
131.39301, 25.89000, 9.2839e-002,95.00511,50.00000,0.0000e+000,20.00000,    -0.45416,1.10261
134.10899, 26.06500, 9.5124e-002,94.91498,50.00000,0.0000e+000,20.00000,    -0.46450,1.09900
136.82201, 26.24000, 9.5586e-002,94.82393,50.00000,0.0000e+000,20.00000,    -0.47155,1.09540
139.52499, 26.41500, 9.5513e-002,94.73202,50.00000,0.0000e+000,20.00000,    -0.47569,1.09183
142.20000, 26.59000, 9.3824e-002,94.64539,50.00000,0.0000e+000,20.00000,    -0.47898,1.08829
144.86000, 26.76500, 9.1560e-002,94.55771,50.00000,0.0000e+000,20.00000,    -0.48036,1.08478
147.50400, 26.94000, 8.8132e-002,94.46755,50.00000,0.0000e+000,20.00000,    -0.47684,1.08130
150.11600, 27.11500, 8.2984e-002,94.37583,50.00000,0.0000e+000,20.00000,    -0.47082,1.07787
152.70300, 27.29000, 7.6777e-002,94.28690,50.00000,0.0000e+000,20.00000,    -0.46514,1.07448
155.26300, 27.46500, 6.9807e-002,94.20124,50.00000,0.0000e+000,20.00000,    -0.45814,1.07114
157.77299, 27.64000, 6.1496e-002,94.11810,50.00000,0.0000e+000,20.00000,    -0.44808,1.06786
160.27100, 27.81500, 5.2297e-002,94.03713,50.00000,0.0000e+000,20.00000,    -0.43799,1.06461
162.71500, 27.99000, 4.2311e-002,93.95914,50.00000,0.0000e+000,20.00000,    -0.42818,1.06143
165.14799, 28.16500, 3.1491e-002,93.88631,50.00000,0.0000e+000,20.00000,    -0.41677,1.05827
167.53600, 28.34000, 2.0294e-002,93.81397,50.00000,0.0000e+000,20.00000,    -0.40547,1.05518
169.89700, 28.51500, 8.1189e-003,93.74004,50.00000,0.0000e+000,20.00000,    -0.39425,1.05213
172.22501, 28.69000,-3.9707e-003,93.67002,50.00000,0.0000e+000,20.00000,    -0.38207,1.04913
174.53000, 28.86500,-1.6733e-002,93.60830,50.00000,0.0000e+000,20.00000,    -0.36942,1.04617
176.80200, 29.04000,-2.9634e-002,93.54962,50.00000,0.0000e+000,20.00000,    -0.35735,1.04325
179.07201, 29.21500,-4.2179e-002,93.49114,50.00000,0.0000e+000,20.00000,    -0.34522,1.04035
181.28000, 29.39000,-5.4993e-002,93.43423,50.00000,0.0000e+000,20.00000,    -0.33290,1.03753
183.49899, 29.56500,-6.7403e-002,93.37797,50.00000,0.0000e+000,20.00000,    -0.32093,1.03470
185.66600, 29.74000,-7.9058e-002,93.32334,50.00000,0.0000e+000,20.00000,    -0.30870,1.03194
187.83900, 29.91500,-9.0276e-002,93.27097,50.00000,0.0000e+000,20.00000,    -0.29657,1.02918
189.96700, 30.09000,    -0.10096,93.22209,50.00000,0.0000e+000,20.00000,    -0.28526,1.02648
192.06900, 30.26500,    -0.11219,93.17594,50.00000,0.0000e+000,20.00000,    -0.27362,1.02383
194.13400, 30.44000,    -0.12249,93.13091,50.00000,0.0000e+000,20.00000,    -0.26201,1.02122
196.17799, 30.61500,    -0.13316,93.08651,50.00000,0.0000e+000,20.00000,    -0.25217,1.01865
198.19501, 30.79000,    -0.14319,93.04000,50.00000,0.0000e+000,20.00000,    -0.24354,1.01612
200.20000, 30.96500,    -0.15354,92.99530,50.00000,0.0000e+000,20.00000,    -0.23498,1.01360
202.17599, 31.14000,    -0.16327,92.95509,50.00000,0.0000e+000,20.00000,    -0.22649,1.01113
204.11600, 31.31500,    -0.17361,92.91642,50.00000,0.0000e+000,20.00000,    -0.21806,1.00871
206.05499, 31.49000,    -0.18303,92.87966,50.00000,0.0000e+000,20.00000,    -0.20975,1.00630
207.96201, 31.66500,    -0.19276,92.84744,50.00000,0.0000e+000,20.00000,    -0.20235,1.00393
209.85500, 31.84000,    -0.20202,92.81726,50.00000,0.0000e+000,20.00000,    -0.19612,1.00158
211.73100, 32.01500,    -0.21104,92.78637,50.00000,0.0000e+000,20.00000,    -0.19064,0.99926
213.57899, 32.19000,    -0.22047,92.75569,50.00000,0.0000e+000,20.00000,    -0.18466,0.99698
215.42101, 32.36500,    -0.22902,92.72594,50.00000,0.0000e+000,20.00000,    -0.17840,0.99471
217.24400, 32.54000,    -0.23807,92.69759,50.00000,0.0000e+000,20.00000,    -0.17181,0.99246
219.03900, 32.71500,    -0.24645,92.67019,50.00000,0.0000e+000,20.00000,    -0.16490,0.99026
220.83400, 32.89000,    -0.25462,92.64307,50.00000,0.0000e+000,20.00000,    -0.15944,0.98806
222.60800, 33.06500,    -0.26325,92.61708,50.00000,0.0000e+000,20.00000,    -0.15420,0.98590
224.38200, 33.24000,    -0.27135,92.59179,50.00000,0.0000e+000,20.00000,    -0.14994,0.98373
226.13699, 33.41500,    -0.28005,92.56614,50.00000,0.0000e+000,20.00000,    -0.14619,0.98160
227.88200, 33.59000,    -0.28858,92.53889,50.00000,0.0000e+000,20.00000,    -0.14293,0.97948
229.61900, 33.76500,    -0.29708,92.51099,50.00000,0.0000e+000,20.00000,    -0.13964,0.97738
231.34399, 33.94000,    -0.30533,92.48592,50.00000,0.0000e+000,20.00000,    -0.13608,0.97529
233.05299, 34.11500,    -0.31379,92.46360,50.00000,0.0000e+000,20.00000,    -0.13286,0.97323
234.77699, 34.29000,    -0.32227,92.44231,50.00000,0.0000e+000,20.00000,    -0.12963,0.97115
236.48100, 34.46500,    -0.33002,92.42123,50.00000,0.0000e+000,20.00000,    -0.12682,0.96911
238.16200, 34.64000,    -0.33773,92.39930,50.00000,0.0000e+000,20.00000,    -0.12401,0.96709
239.86800, 34.81500,    -0.34555,92.37876,50.00000,0.0000e+000,20.00000,    -0.12159,0.96505
241.55000, 34.99000,    -0.35353,92.35755,50.00000,0.0000e+000,20.00000,    -0.11923,0.96305
243.24001, 35.16500,    -0.36158,92.33554,50.00000,0.0000e+000,20.00000,    -0.11676,0.96103
244.91800, 35.34000,    -0.36921,92.31648,50.00000,0.0000e+000,20.00000,    -0.11374,0.95904
246.58200, 35.51500,    -0.37679,92.29781,50.00000,0.0000e+000,20.00000,    -0.11030,0.95707
248.27100, 35.69000,    -0.38459,92.27983,50.00000,0.0000e+000,20.00000,    -0.10748,0.95507
249.93700, 35.86500,    -0.39253,92.26143,50.00000,0.0000e+000,20.00000,    -0.10560,0.95310
251.62199, 36.04000,    -0.39997,92.24374,50.00000,0.0000e+000,20.00000,    -0.10435,0.95112
253.28500, 36.21500,    -0.40809,92.22644,50.00000,0.0000e+000,20.00000,    -0.10287,0.94917
254.95799, 36.39000,    -0.41511,92.20929,50.00000,0.0000e+000,20.00000,    -0.10103,0.94720
256.64001, 36.56500,    -0.42256,92.19194,50.00000,0.0000e+000,20.00000,-9.9471e-002,0.94524
258.29401, 36.74000,    -0.42958,92.17443,50.00000,0.0000e+000,20.00000,-9.8450e-002,0.94331
259.97299, 36.91500,    -0.43673,92.15810,50.00000,0.0000e+000,20.00000,-9.6673e-002,0.94135
261.62601, 37.09000,    -0.44353,92.14209,50.00000,0.0000e+000,20.00000,-9.5306e-002,0.93943
263.30499, 37.26500,    -0.45044,92.12707,50.00000,0.0000e+000,20.00000,-9.4264e-002,0.93749
264.97000, 37.44000,    -0.45720,92.11099,50.00000,0.0000e+000,20.00000,-9.3651e-002,0.93556
266.65500, 37.61500,    -0.46399,92.09462,50.00000,0.0000e+000,20.00000,-9.3117e-002,0.93362
268.32101, 37.79000,    -0.47127,92.07788,50.00000,0.0000e+000,20.00000,-9.2335e-002,0.93170
269.99701, 37.96500,    -0.47857,92.06123,50.00000,0.0000e+000,20.00000,-9.1913e-002,0.92978
271.67200, 38.14000,    -0.48579,92.04648,50.00000,0.0000e+000,20.00000,-9.1386e-002,0.92786
273.36899, 38.31500,    -0.49295,92.03119,50.00000,0.0000e+000,20.00000,-9.0786e-002,0.92592
275.03201, 38.49000,    -0.49933,92.01476,50.00000,0.0000e+000,20.00000,-9.0181e-002,0.92403
276.73999, 38.66500,    -0.50560,91.99863,50.00000,0.0000e+000,20.00000,-9.0239e-002,0.92209
278.41501, 38.84000,    -0.51135,91.98295,50.00000,0.0000e+000,20.00000,-9.0696e-002,0.92019
280.11301, 39.01500,    -0.51747,91.96824,50.00000,0.0000e+000,20.00000,-9.1381e-002,0.91827
281.80301, 39.19000,    -0.52317,91.95266,50.00000,0.0000e+000,20.00000,-9.1908e-002,0.91636
283.50000, 39.36500,    -0.52917,91.93634,50.00000,0.0000e+000,20.00000,-9.2303e-002,0.91445
285.17999, 39.54000,    -0.53465,91.92073,50.00000,0.0000e+000,20.00000,-9.2784e-002,0.91257
286.87000, 39.71500,    -0.54052,91.90519,50.00000,0.0000e+000,20.00000,-9.3241e-002,0.91068
288.54501, 39.89000,    -0.54549,91.88954,50.00000,0.0000e+000,20.00000,-9.5019e-002,0.90881
290.24899, 40.06500,    -0.55110,91.87449,50.00000,0.0000e+000,20.00000,-9.6843e-002,0.90691
291.92899, 40.24000,    -0.55629,91.85949,50.00000,0.0000e+000,20.00000,-9.8160e-002,0.90504
293.60999, 40.41500,    -0.56146,91.84309,50.00000,0.0000e+000,20.00000,-9.9328e-002,0.90318
295.29901, 40.59000,    -0.56651,91.82556,50.00000,0.0000e+000,20.00000,    -0.10067,0.90132
296.99399, 40.76500,    -0.57159,91.80760,50.00000,0.0000e+000,20.00000,    -0.10235,0.89945
298.69000, 40.94000,    -0.57760,91.78995,50.00000,0.0000e+000,20.00000,    -0.10407,0.89759
300.39499, 41.11500,    -0.58278,91.77259,50.00000,0.0000e+000,20.00000,    -0.10544,0.89572
302.09601, 41.29000,    -0.58852,91.75418,50.00000,0.0000e+000,20.00000,    -0.10695,0.89386
303.79800, 41.46500,    -0.59405,91.73626,50.00000,0.0000e+000,20.00000,    -0.10858,0.89200
305.51801, 41.64000,    -0.59950,91.71557,50.00000,0.0000e+000,20.00000,    -0.11025,0.89013
307.22699, 41.81500,    -0.60468,91.69348,50.00000,0.0000e+000,20.00000,    -0.11239,0.88828
308.93500, 41.99000,    -0.60929,91.67253,50.00000,0.0000e+000,20.00000,    -0.11477,0.88644
310.64700, 42.16500,    -0.61408,91.65178,50.00000,0.0000e+000,20.00000,    -0.11691,0.88459
312.36301, 42.34000,    -0.61830,91.63116,50.00000,0.0000e+000,20.00000,    -0.11919,0.88275
314.08099, 42.51500,    -0.62207,91.61002,50.00000,0.0000e+000,20.00000,    -0.12182,0.88091
315.79700, 42.69000,    -0.62720,91.58878,50.00000,0.0000e+000,20.00000,    -0.12441,0.87907
317.51801, 42.86500,    -0.63147,91.56757,50.00000,0.0000e+000,20.00000,    -0.12700,0.87724
319.23700, 43.04000,    -0.63637,91.54622,50.00000,0.0000e+000,20.00000,    -0.12958,0.87541
320.94400, 43.21500,    -0.64023,91.52471,50.00000,0.0000e+000,20.00000,    -0.13252,0.87360
322.66400, 43.39000,    -0.64594,91.50326,50.00000,0.0000e+000,20.00000,    -0.13535,0.87179
324.39600, 43.56500,    -0.65001,91.48071,50.00000,0.0000e+000,20.00000,    -0.13762,0.86996
326.11700, 43.74000,    -0.65406,91.45714,50.00000,0.0000e+000,20.00000,    -0.14080,0.86815
327.84799, 43.91500,    -0.65803,91.43372,50.00000,0.0000e+000,20.00000,    -0.14439,0.86634
329.54800, 44.09000,    -0.66219,91.40943,50.00000,0.0000e+000,20.00000,    -0.14803,0.86457
331.28000, 44.26500,    -0.66580,91.38257,50.00000,0.0000e+000,20.00000,    -0.15205,0.86277
333.01300, 44.44000,    -0.66974,91.35497,50.00000,0.0000e+000,20.00000,    -0.15647,0.86097
334.72501, 44.61500,    -0.67322,91.32806,50.00000,0.0000e+000,20.00000,    -0.16139,0.85920
336.46500, 44.79000,    -0.67671,91.30105,50.00000,0.0000e+000,20.00000,    -0.16658,0.85740
338.19000, 44.96500,    -0.68065,91.27284,50.00000,0.0000e+000,20.00000,    -0.17159,0.85563
339.89801, 45.14000,    -0.68410,91.24356,50.00000,0.0000e+000,20.00000,    -0.17694,0.85388
341.65799, 45.31500,    -0.68777,91.21381,50.00000,0.0000e+000,20.00000,    -0.18299,0.85208
343.39700, 45.49000,    -0.69176,91.18203,50.00000,0.0000e+000,20.00000,    -0.18929,0.85031
345.14401, 45.66500,    -0.69476,91.14818,50.00000,0.0000e+000,20.00000,    -0.19506,0.84853
346.88599, 45.84000,    -0.69711,91.11440,50.00000,0.0000e+000,20.00000,    -0.20041,0.84677
348.63000, 46.01500,    -0.69832,91.07971,50.00000,0.0000e+000,20.00000,    -0.20531,0.84501
350.36499, 46.19000,    -0.69929,91.04308,50.00000,0.0000e+000,20.00000,    -0.21030,0.84327
352.10300, 46.36500,    -0.70096,91.00463,50.00000,0.0000e+000,20.00000,    -0.21522,0.84152
353.84000, 46.54000,    -0.70138,90.96469,50.00000,0.0000e+000,20.00000,    -0.22035,0.83979
355.57999, 46.71500,    -0.70283,90.92470,50.00000,0.0000e+000,20.00000,    -0.22516,0.83805
357.29501, 46.89000,    -0.70485,90.88448,50.00000,0.0000e+000,20.00000,    -0.22946,0.83635
359.00601, 47.06500,    -0.70751,90.84204,50.00000,0.0000e+000,20.00000,    -0.23364,0.83466
360.74100, 47.24000,    -0.71124,90.79622,50.00000,0.0000e+000,20.00000,    -0.23747,0.83295
362.48199, 47.41500,    -0.71527,90.75061,50.00000,0.0000e+000,20.00000,    -0.24007,0.83123
364.20999, 47.59000,    -0.71983,90.70696,50.00000,0.0000e+000,20.00000,    -0.24223,0.82954
365.92999, 47.76500,    -0.72565,90.66398,50.00000,0.0000e+000,20.00000,    -0.24497,0.82786
367.66501, 47.94000,    -0.73110,90.61881,50.00000,0.0000e+000,20.00000,    -0.24694,0.82617
369.38901, 48.11500,    -0.73655,90.57330,50.00000,0.0000e+000,20.00000,    -0.24793,0.82450
371.12701, 48.29000,    -0.74144,90.52791,50.00000,0.0000e+000,20.00000,    -0.24855,0.82282
372.85901, 48.46500,    -0.74706,90.48250,50.00000,0.0000e+000,20.00000,    -0.24873,0.82115
374.60001, 48.64000,    -0.75252,90.43761,50.00000,0.0000e+000,20.00000,    -0.24870,0.81947
376.34299, 48.81500,    -0.75844,90.39307,50.00000,0.0000e+000,20.00000,    -0.24832,0.81780
378.07300, 48.99000,    -0.76473,90.34811,50.00000,0.0000e+000,20.00000,    -0.24697,0.81615
379.80499, 49.16500,    -0.77096,90.30442,50.00000,0.0000e+000,20.00000,    -0.24505,0.81450
381.52802, 49.34000,    -0.77755,90.26267,50.00000,0.0000e+000,20.00000,    -0.24367,0.81287
383.25000, 49.51500,    -0.78473,90.21963,50.00000,0.0000e+000,20.00000,    -0.24247,0.81124
384.98700, 49.69000,    -0.79181,90.17562,50.00000,0.0000e+000,20.00000,    -0.24061,0.80961
386.73001, 49.86500,    -0.79996,90.13397,50.00000,0.0000e+000,20.00000,    -0.23804,0.80797
388.46399, 50.04000,    -0.80894,90.09251,50.00000,0.0000e+000,20.00000,    -0.23541,0.80635
390.19699, 50.21500,    -0.81812,90.05113,50.00000,0.0000e+000,20.00000,    -0.23250,0.80474
391.93900, 50.39000,    -0.82717,90.01100,50.00000,0.0000e+000,20.00000,    -0.22915,0.80312
393.69800, 50.56500,    -0.83624,89.97127,50.00000,0.0000e+000,20.00000,    -0.22675,0.80149
395.41400, 50.74000,    -0.84415,89.93158,50.00000,0.0000e+000,20.00000,    -0.22498,0.79991
397.16400, 50.91500,    -0.85134,89.89223,50.00000,0.0000e+000,20.00000,    -0.22369,0.79830
398.89499, 51.09000,    -0.85879,89.85297,50.00000,0.0000e+000,20.00000,    -0.22308,0.79672
400.63101, 51.26500,    -0.86556,89.81376,50.00000,0.0000e+000,20.00000,    -0.22213,0.79513
402.37201, 51.44000,    -0.87587,89.77605,50.00000,0.0000e+000,20.00000,    -0.21999,0.79355
404.14200, 51.61500,    -0.88488,89.73926,50.00000,0.0000e+000,20.00000,    -0.21861,0.79195
405.87601, 51.79000,    -0.89134,89.70342,50.00000,0.0000e+000,20.00000,    -0.21897,0.79038
407.60800, 51.96500,    -0.89559,89.66787,50.00000,0.0000e+000,20.00000,    -0.21891,0.78883
409.33899, 52.14000,    -0.90054,89.63454,50.00000,0.0000e+000,20.00000,    -0.21905,0.78728
411.06601, 52.31500,    -0.90674,89.60035,50.00000,0.0000e+000,20.00000,    -0.22016,0.78573
412.78799, 52.49000,    -0.91296,89.56289,50.00000,0.0000e+000,20.00000,    -0.22083,0.78420
414.53201, 52.66500,    -0.91901,89.52367,50.00000,0.0000e+000,20.00000,    -0.22123,0.78266
416.26901, 52.84000,    -0.92633,89.48342,50.00000,0.0000e+000,20.00000,    -0.22193,0.78112
418.01199, 53.01500,    -0.93458,89.44393,50.00000,0.0000e+000,20.00000,    -0.22276,0.77959
419.76099, 53.19000,    -0.94174,89.40673,50.00000,0.0000e+000,20.00000,    -0.22406,0.77805
421.52701, 53.36500,    -0.94904,89.37045,50.00000,0.0000e+000,20.00000,    -0.22562,0.77651
423.27802, 53.54000,    -0.95589,89.32985,50.00000,0.0000e+000,20.00000,    -0.22751,0.77499
425.04401, 53.71500,    -0.96238,89.28718,50.00000,0.0000e+000,20.00000,    -0.22995,0.77346
426.77499, 53.89000,    -0.96706,89.24659,50.00000,0.0000e+000,20.00000,    -0.23267,0.77196
428.54999, 54.06500,    -0.97171,89.20376,50.00000,0.0000e+000,20.00000,    -0.23580,0.77044
430.28799, 54.24000,    -0.97609,89.16027,50.00000,0.0000e+000,20.00000,    -0.23867,0.76895
432.03601, 54.41500,    -0.97896,89.11924,50.00000,0.0000e+000,20.00000,    -0.24145,0.76745
433.77301, 54.59000,    -0.98314,89.07783,50.00000,0.0000e+000,20.00000,    -0.24387,0.76598
435.51801, 54.76500,    -0.98746,89.03572,50.00000,0.0000e+000,20.00000,    -0.24597,0.76450
437.26901, 54.94000,    -0.99266,88.99276,50.00000,0.0000e+000,20.00000,    -0.24862,0.76302
438.98700, 55.11500,    -0.99801,88.94975,50.00000,0.0000e+000,20.00000,    -0.25193,0.76157
440.73401, 55.29000,    -1.00338,88.90690,50.00000,0.0000e+000,20.00000,    -0.25425,0.76011
442.48001, 55.46500,    -1.00858,88.86295,50.00000,0.0000e+000,20.00000,    -0.25585,0.75865
444.24500, 55.64000,    -1.01360,88.81817,50.00000,0.0000e+000,20.00000,    -0.25885,0.75719
445.96100, 55.81500,    -1.01779,88.77400,50.00000,0.0000e+000,20.00000,    -0.26140,0.75576
447.70801, 55.99000,    -1.02017,88.72844,50.00000,0.0000e+000,20.00000,    -0.26261,0.75432
449.42200, 56.16500,    -1.02463,88.68044,50.00000,0.0000e+000,20.00000,    -0.26441,0.75291
451.15799, 56.34000,    -1.02788,88.63142,50.00000,0.0000e+000,20.00000,    -0.26724,0.75149
452.88101, 56.51500,    -1.03239,88.58323,50.00000,0.0000e+000,20.00000,    -0.27056,0.75009
454.61600, 56.69000,    -1.03684,88.53558,50.00000,0.0000e+000,20.00000,    -0.27372,0.74868
456.33301, 56.86500,    -1.04190,88.48720,50.00000,0.0000e+000,20.00000,    -0.27642,0.74729
458.06400, 57.04000,    -1.04918,88.43978,50.00000,0.0000e+000,20.00000,    -0.27927,0.74589
459.82199, 57.21500,    -1.05610,88.39275,50.00000,0.0000e+000,20.00000,    -0.28271,0.74448
461.55600, 57.39000,    -1.06267,88.34172,50.00000,0.0000e+000,20.00000,    -0.28554,0.74309
463.32001, 57.56500,    -1.06882,88.28981,50.00000,0.0000e+000,20.00000,    -0.28884,0.74169
465.06201, 57.74000,    -1.07534,88.24061,50.00000,0.0000e+000,20.00000,    -0.29264,0.74031
466.80499, 57.91500,    -1.08190,88.19259,50.00000,0.0000e+000,20.00000,    -0.29591,0.73893
468.56000, 58.09000,    -1.08466,88.14272,50.00000,0.0000e+000,20.00000,    -0.29898,0.73755
470.29501, 58.26500,    -1.08619,88.08962,50.00000,0.0000e+000,20.00000,    -0.30197,0.73619
472.01901, 58.44000,    -1.08853,88.03531,50.00000,0.0000e+000,20.00000,    -0.30495,0.73484
473.75601, 58.61500,    -1.09251,87.98173,50.00000,0.0000e+000,20.00000,    -0.30800,0.73349
475.48901, 58.79000,    -1.09554,87.92906,50.00000,0.0000e+000,20.00000,    -0.31102,0.73215
477.20901, 58.96500,    -1.09958,87.87423,50.00000,0.0000e+000,20.00000,    -0.31464,0.73082
478.95801, 59.14000,    -1.10590,87.81845,50.00000,0.0000e+000,20.00000,    -0.31744,0.72947
480.75101, 59.31500,    -1.11866,87.76335,50.00000,0.0000e+000,20.00000,    -0.31964,0.72810
482.53500, 59.49000,    -1.13109,87.70528,50.00000,0.0000e+000,20.00000,    -0.32275,0.72674
484.33200, 59.66500,    -1.13938,87.64659,50.00000,0.0000e+000,20.00000,    -0.32713,0.72538
486.10599, 59.84000,    -1.14272,87.58708,50.00000,0.0000e+000,20.00000,    -0.33074,0.72404
487.85001, 60.01500,    -1.14084,87.52687,50.00000,0.0000e+000,20.00000,    -0.33309,0.72272
489.55099, 60.19000,    -1.13384,87.46818,50.00000,0.0000e+000,20.00000,    -0.33478,0.72145
491.22699, 60.36500,    -1.12895,87.40912,50.00000,0.0000e+000,20.00000,    -0.33701,0.72020
492.90799, 60.54000,    -1.12864,87.35007,50.00000,0.0000e+000,20.00000,    -0.33963,0.71895
494.62299, 60.71500,    -1.13390,87.29035,50.00000,0.0000e+000,20.00000,    -0.34157,0.71767
496.32901, 60.89000,    -1.14239,87.23084,50.00000,0.0000e+000,20.00000,    -0.34364,0.71642
498.06699, 61.06500,    -1.15180,87.17104,50.00000,0.0000e+000,20.00000,    -0.34645,0.71514
499.81500, 61.24000,    -1.16219,87.11025,50.00000,0.0000e+000,20.00000,    -0.34843,0.71386
501.55899, 61.41500,    -1.17034,87.04656,50.00000,0.0000e+000,20.00000,    -0.34961,0.71259
503.30701, 61.59000,    -1.17713,86.98345,50.00000,0.0000e+000,20.00000,    -0.35099,0.71132
505.05600, 61.76500,    -1.18381,86.92259,50.00000,0.0000e+000,20.00000,    -0.35268,0.71005
506.81400, 61.94000,    -1.18886,86.86257,50.00000,0.0000e+000,20.00000,    -0.35426,0.70879
508.55600, 62.11500,    -1.19347,86.80133,50.00000,0.0000e+000,20.00000,    -0.35536,0.70754
510.32300, 62.29000,    -1.19995,86.73843,50.00000,0.0000e+000,20.00000,    -0.35694,0.70628
512.10498, 62.46500,    -1.20586,86.67743,50.00000,0.0000e+000,20.00000,    -0.35930,0.70501
513.84998, 62.64000,    -1.20910,86.61548,50.00000,0.0000e+000,20.00000,    -0.36185,0.70377
515.59900, 62.81500,    -1.21282,86.55063,50.00000,0.0000e+000,20.00000,    -0.36425,0.70254
517.35797, 62.99000,    -1.21556,86.48583,50.00000,0.0000e+000,20.00000,    -0.36603,0.70131
519.11700, 63.16500,    -1.21833,86.42263,50.00000,0.0000e+000,20.00000,    -0.36679,0.70008
520.85699, 63.34000,    -1.22242,86.35936,50.00000,0.0000e+000,20.00000,    -0.36770,0.69886
522.60797, 63.51500,    -1.22726,86.29403,50.00000,0.0000e+000,20.00000,    -0.36994,0.69765
524.36102, 63.69000,    -1.23296,86.22752,50.00000,0.0000e+000,20.00000,    -0.37304,0.69644
526.14801, 63.86500,    -1.24046,86.16442,50.00000,0.0000e+000,20.00000,    -0.37563,0.69521
527.89600, 64.04000,    -1.24425,86.10067,50.00000,0.0000e+000,20.00000,    -0.37768,0.69402
529.63501, 64.21500,    -1.24475,86.03417,50.00000,0.0000e+000,20.00000,    -0.38033,0.69283
531.37903, 64.39000,    -1.24445,85.96503,50.00000,0.0000e+000,20.00000,    -0.38326,0.69165
533.09900, 64.56500,    -1.24427,85.89649,50.00000,0.0000e+000,20.00000,    -0.38513,0.69048
534.82501, 64.74000,    -1.24841,85.82874,50.00000,0.0000e+000,20.00000,    -0.38642,0.68932
536.60901, 64.91500,    -1.25612,85.76340,50.00000,0.0000e+000,20.00000,    -0.38839,0.68813
538.40997, 65.09000,    -1.27269,85.69729,50.00000,0.0000e+000,20.00000,    -0.39013,0.68692
540.22198, 65.26500,    -1.28554,85.62845,50.00000,0.0000e+000,20.00000,    -0.39167,0.68572
542.01501, 65.44000,    -1.29239,85.55742,50.00000,0.0000e+000,20.00000,    -0.39303,0.68453
543.79102, 65.61500,    -1.29319,85.48646,50.00000,0.0000e+000,20.00000,    -0.39502,0.68336
545.54199, 65.79000,    -1.29074,85.41717,50.00000,0.0000e+000,20.00000,    -0.39761,0.68222
547.30603, 65.96500,    -1.28880,85.34586,50.00000,0.0000e+000,20.00000,    -0.39933,0.68106
549.01398, 66.14000,    -1.28602,85.27422,50.00000,0.0000e+000,20.00000,    -0.39999,0.67995
550.73102, 66.31500,    -1.28626,85.20291,50.00000,0.0000e+000,20.00000,    -0.40034,0.67884
552.44702, 66.49000,    -1.28632,85.13308,50.00000,0.0000e+000,20.00000,    -0.40122,0.67774
554.15698, 66.66500,    -1.28810,85.06234,50.00000,0.0000e+000,20.00000,    -0.40279,0.67664
555.87903, 66.84000,    -1.29141,84.99208,50.00000,0.0000e+000,20.00000,    -0.40460,0.67554
557.59003, 67.01500,    -1.29565,84.92298,50.00000,0.0000e+000,20.00000,    -0.40674,0.67445
559.32898, 67.19000,    -1.30431,84.85203,50.00000,0.0000e+000,20.00000,    -0.40845,0.67334
561.08502, 67.36500,    -1.31210,84.78013,50.00000,0.0000e+000,20.00000,    -0.40858,0.67224
562.81702, 67.54000,    -1.31573,84.70799,50.00000,0.0000e+000,20.00000,    -0.40836,0.67115
564.53699, 67.71500,    -1.31690,84.63597,50.00000,0.0000e+000,20.00000,    -0.40753,0.67007
566.25403, 67.89000,    -1.31876,84.56502,50.00000,0.0000e+000,20.00000,    -0.40756,0.66900
567.93298, 68.06500,    -1.31504,84.49461,50.00000,0.0000e+000,20.00000,    -0.40893,0.66796
569.61102, 68.24000,    -1.31283,84.42397,50.00000,0.0000e+000,20.00000,    -0.41020,0.66692
571.31500, 68.41500,    -1.31459,84.35172,50.00000,0.0000e+000,20.00000,    -0.41082,0.66587
573.03003, 68.59000,    -1.32131,84.28014,50.00000,0.0000e+000,20.00000,    -0.41068,0.66482
574.76898, 68.76500,    -1.33309,84.20654,50.00000,0.0000e+000,20.00000,    -0.41169,0.66376
576.51898, 68.94000,    -1.34511,84.12965,50.00000,0.0000e+000,20.00000,    -0.41257,0.66269
578.28101, 69.11500,    -1.35676,84.05556,50.00000,0.0000e+000,20.00000,    -0.41315,0.66163
580.06201, 69.29000,    -1.36591,83.98557,50.00000,0.0000e+000,20.00000,    -0.41401,0.66055
581.82202, 69.46500,    -1.37346,83.91794,50.00000,0.0000e+000,20.00000,    -0.41540,0.65950
583.61401, 69.64000,    -1.38049,83.84916,50.00000,0.0000e+000,20.00000,    -0.41660,0.65843
585.45203, 69.81500,    -1.39386,83.77355,50.00000,0.0000e+000,20.00000,    -0.41748,0.65733
587.29999, 69.99000,    -1.40738,83.69776,50.00000,0.0000e+000,20.00000,    -0.41886,0.65624
589.12402, 70.16500,    -1.41501,83.62369,50.00000,0.0000e+000,20.00000,    -0.42107,0.65516
590.92401, 70.34000,    -1.41257,83.55337,50.00000,0.0000e+000,20.00000,    -0.42276,0.65411
592.67102, 70.51500,    -1.40711,83.48138,50.00000,0.0000e+000,20.00000,    -0.42360,0.65309
594.42603, 70.69000,    -1.40479,83.40827,50.00000,0.0000e+000,20.00000,    -0.42378,0.65207
596.18903, 70.86500,    -1.40610,83.33459,50.00000,0.0000e+000,20.00000,    -0.42496,0.65105
597.92200, 71.04000,    -1.40642,83.26047,50.00000,0.0000e+000,20.00000,    -0.42909,0.65005
599.65997, 71.21500,    -1.40650,83.18371,50.00000,0.0000e+000,20.00000,    -0.43274,0.64905
601.41803, 71.39000,    -1.41298,83.10694,50.00000,0.0000e+000,20.00000,    -0.43516,0.64804
603.22900, 71.56500,    -1.42688,83.03244,50.00000,0.0000e+000,20.00000,    -0.43705,0.64701
605.01599, 71.74000,    -1.43730,82.95838,50.00000,0.0000e+000,20.00000,    -0.43906,0.64600
606.76898, 71.91500,    -1.43980,82.88042,50.00000,0.0000e+000,20.00000,    -0.44191,0.64501
608.52698, 72.09000,    -1.43993,82.80058,50.00000,0.0000e+000,20.00000,    -0.44557,0.64402
610.27802, 72.26500,    -1.44100,82.72475,50.00000,0.0000e+000,20.00000,    -0.44963,0.64304
612.01801, 72.44000,    -1.44132,82.64898,50.00000,0.0000e+000,20.00000,    -0.45323,0.64207
613.72998, 72.61500,    -1.44009,82.57094,50.00000,0.0000e+000,20.00000,    -0.45674,0.64112
615.45001, 72.79000,    -1.44000,82.48659,50.00000,0.0000e+000,20.00000,    -0.46070,0.64017
617.17102, 72.96500,    -1.44155,82.40099,50.00000,0.0000e+000,20.00000,    -0.46482,0.63922
618.91199, 73.14000,    -1.44697,82.32360,50.00000,0.0000e+000,20.00000,    -0.46879,0.63827
620.62097, 73.31500,    -1.45122,82.24611,50.00000,0.0000e+000,20.00000,    -0.47319,0.63734
622.36102, 73.49000,    -1.45657,82.16378,50.00000,0.0000e+000,20.00000,    -0.47690,0.63639
624.11798, 73.66500,    -1.46623,82.07877,50.00000,0.0000e+000,20.00000,    -0.47958,0.63544
625.88202, 73.84000,    -1.47385,81.99346,50.00000,0.0000e+000,20.00000,    -0.48244,0.63449
627.64899, 74.01500,    -1.47960,81.90822,50.00000,0.0000e+000,20.00000,    -0.48615,0.63354
629.39801, 74.19000,    -1.48260,81.82225,50.00000,0.0000e+000,20.00000,    -0.49127,0.63261
631.13898, 74.36500,    -1.48407,81.73616,50.00000,0.0000e+000,20.00000,    -0.49655,0.63168
632.87500, 74.54000,    -1.48342,81.64907,50.00000,0.0000e+000,20.00000,    -0.50052,0.63076
634.61102, 74.71500,    -1.48424,81.55939,50.00000,0.0000e+000,20.00000,    -0.50228,0.62984
636.34698, 74.89000,    -1.48531,81.46803,50.00000,0.0000e+000,20.00000,    -0.50528,0.62893
638.09399, 75.06500,    -1.48870,81.37595,50.00000,0.0000e+000,20.00000,    -0.50983,0.62802
639.83398, 75.24000,    -1.49567,81.28626,50.00000,0.0000e+000,20.00000,    -0.51366,0.62711
641.59302, 75.41500,    -1.50024,81.20117,50.00000,0.0000e+000,20.00000,    -0.51610,0.62620
643.34998, 75.59000,    -1.50459,81.11273,50.00000,0.0000e+000,20.00000,    -0.51699,0.62529
645.09399, 75.76500,    -1.50777,81.02153,50.00000,0.0000e+000,20.00000,    -0.51802,0.62439
646.86102, 75.94000,    -1.51146,80.92920,50.00000,0.0000e+000,20.00000,    -0.51940,0.62348
648.62000, 76.11500,    -1.51529,80.83378,50.00000,0.0000e+000,20.00000,    -0.51975,0.62259
650.40100, 76.29000,    -1.52213,80.73751,50.00000,0.0000e+000,20.00000,    -0.51893,0.62168
652.18402, 76.46500,    -1.52585,80.64323,50.00000,0.0000e+000,20.00000,    -0.51856,0.62078
653.91101, 76.64000,    -1.52554,80.55106,50.00000,0.0000e+000,20.00000,    -0.51773,0.61991
655.63702, 76.81500,    -1.52397,80.45889,50.00000,0.0000e+000,20.00000,    -0.51567,0.61904
657.37299, 76.99000,    -1.52429,80.36514,50.00000,0.0000e+000,20.00000,    -0.51323,0.61817
659.08301, 77.16500,    -1.52481,80.27102,50.00000,0.0000e+000,20.00000,    -0.51122,0.61732
660.83002, 77.34000,    -1.52995,80.18033,50.00000,0.0000e+000,20.00000,    -0.50874,0.61645
662.59900, 77.51500,    -1.53950,80.09253,50.00000,0.0000e+000,20.00000,    -0.50468,0.61558
664.39301, 77.69000,    -1.55164,80.00202,50.00000,0.0000e+000,20.00000,    -0.49964,0.61470
666.16901, 77.86500,    -1.55991,79.91250,50.00000,0.0000e+000,20.00000,    -0.49443,0.61383
667.92902, 78.04000,    -1.56068,79.82831,50.00000,0.0000e+000,20.00000,    -0.48877,0.61297
669.66101, 78.21500,    -1.55904,79.74315,50.00000,0.0000e+000,20.00000,    -0.48279,0.61213
671.38098, 78.39000,    -1.55956,79.65482,50.00000,0.0000e+000,20.00000,    -0.47667,0.61129
673.12097, 78.56500,    -1.56040,79.56893,50.00000,0.0000e+000,20.00000,    -0.47008,0.61045
674.84302, 78.74000,    -1.56221,79.48581,50.00000,0.0000e+000,20.00000,    -0.46323,0.60963
676.57300, 78.91500,    -1.56706,79.40482,50.00000,0.0000e+000,20.00000,    -0.45612,0.60880
678.30603, 79.09000,    -1.57266,79.32721,50.00000,0.0000e+000,20.00000,    -0.44896,0.60797
680.06799, 79.26500,    -1.57826,79.25045,50.00000,0.0000e+000,20.00000,    -0.44183,0.60714
681.81299, 79.44000,    -1.58399,79.17659,50.00000,0.0000e+000,20.00000,    -0.43444,0.60631
683.55499, 79.61500,    -1.58618,79.10281,50.00000,0.0000e+000,20.00000,    -0.42662,0.60549
685.33801, 79.79000,    -1.59453,79.02679,50.00000,0.0000e+000,20.00000,    -0.41916,0.60465
687.11902, 79.96500,    -1.60394,78.95235,50.00000,0.0000e+000,20.00000,    -0.41196,0.60382
688.92102, 80.14000,    -1.61087,78.88032,50.00000,0.0000e+000,20.00000,    -0.40404,0.60298
690.67603, 80.31500,    -1.61487,78.81148,50.00000,0.0000e+000,20.00000,    -0.39627,0.60217
692.44397, 80.49000,    -1.61442,78.74405,50.00000,0.0000e+000,20.00000,    -0.38846,0.60135
694.20203, 80.66500,    -1.61496,78.67559,50.00000,0.0000e+000,20.00000,    -0.38112,0.60054
695.94897, 80.84000,    -1.61563,78.60782,50.00000,0.0000e+000,20.00000,    -0.37474,0.59974
697.70697, 81.01500,    -1.61803,78.54395,50.00000,0.0000e+000,20.00000,    -0.36859,0.59894
699.45502, 81.19000,    -1.62187,78.48217,50.00000,0.0000e+000,20.00000,    -0.36295,0.59814
701.21802, 81.36500,    -1.62509,78.41963,50.00000,0.0000e+000,20.00000,    -0.35843,0.59734
702.97101, 81.54000,    -1.62878,78.35895,50.00000,0.0000e+000,20.00000,    -0.35297,0.59655
704.72400, 81.71500,    -1.63102,78.30102,50.00000,0.0000e+000,20.00000,    -0.34794,0.59576
706.46100, 81.89000,    -1.63303,78.24351,50.00000,0.0000e+000,20.00000,    -0.34374,0.59498
708.20398, 82.06500,    -1.63419,78.18391,50.00000,0.0000e+000,20.00000,    -0.34064,0.59420
709.93597, 82.24000,    -1.63592,78.12688,50.00000,0.0000e+000,20.00000,    -0.33898,0.59343
711.69702, 82.41500,    -1.63871,78.07197,50.00000,0.0000e+000,20.00000,    -0.33656,0.59265
713.46802, 82.59000,    -1.64352,78.01614,50.00000,0.0000e+000,20.00000,    -0.33310,0.59187
715.21802, 82.76500,    -1.64368,77.96117,50.00000,0.0000e+000,20.00000,    -0.32860,0.59110
716.97601, 82.94000,    -1.64218,77.90685,50.00000,0.0000e+000,20.00000,    -0.32329,0.59033
718.75598, 83.11500,    -1.64272,77.85079,50.00000,0.0000e+000,20.00000,    -0.31706,0.58955
720.50299, 83.29000,    -1.64445,77.79487,50.00000,0.0000e+000,20.00000,    -0.31005,0.58879
722.27002, 83.46500,    -1.64532,77.73886,50.00000,0.0000e+000,20.00000,    -0.30276,0.58802
724.01099, 83.64000,    -1.64512,77.68108,50.00000,0.0000e+000,20.00000,    -0.29483,0.58727
725.74799, 83.81500,    -1.64471,77.62304,50.00000,0.0000e+000,20.00000,    -0.28528,0.58652
727.48901, 83.99000,    -1.64369,77.56234,50.00000,0.0000e+000,20.00000,    -0.27530,0.58577
729.22601, 84.16500,    -1.64342,77.50157,50.00000,0.0000e+000,20.00000,    -0.26642,0.58503
730.97400, 84.34000,    -1.64788,77.44428,50.00000,0.0000e+000,20.00000,    -0.25722,0.58428
732.72400, 84.51500,    -1.65411,77.39148,50.00000,0.0000e+000,20.00000,    -0.24778,0.58354
734.44897, 84.69000,    -1.66402,77.34636,50.00000,0.0000e+000,20.00000,    -0.23780,0.58281
736.23102, 84.86500,    -1.67755,77.30560,50.00000,0.0000e+000,20.00000,    -0.22750,0.58205
737.96997, 85.04000,    -1.69246,77.26779,50.00000,0.0000e+000,20.00000,    -0.21721,0.58132
739.71503, 85.21500,    -1.70701,77.23366,50.00000,0.0000e+000,20.00000,    -0.20716,0.58059
741.47302, 85.39000,    -1.71906,77.20362,50.00000,0.0000e+000,20.00000,    -0.19674,0.57986
743.21100, 85.56500,    -1.72654,77.17768,50.00000,0.0000e+000,20.00000,    -0.18572,0.57913
744.98401, 85.74000,    -1.73222,77.15539,50.00000,0.0000e+000,20.00000,    -0.17432,0.57839
746.73297, 85.91500,    -1.73800,77.13259,50.00000,0.0000e+000,20.00000,    -0.16210,0.57767
748.48901, 86.09000,    -1.74294,77.11035,50.00000,0.0000e+000,20.00000,    -0.15060,0.57695
750.26703, 86.26500,    -1.74589,77.08878,50.00000,0.0000e+000,20.00000,    -0.13963,0.57621
752.02698, 86.44000,    -1.74633,77.06930,50.00000,0.0000e+000,20.00000,    -0.13014,0.57549
753.78601, 86.61500,    -1.74737,77.05236,50.00000,0.0000e+000,20.00000,    -0.12201,0.57477
755.54602, 86.79000,    -1.74772,77.03382,50.00000,0.0000e+000,20.00000,    -0.11552,0.57406
757.30701, 86.96500,    -1.74921,77.01516,50.00000,0.0000e+000,20.00000,    -0.11010,0.57334
759.07001, 87.14000,    -1.75314,76.99598,50.00000,0.0000e+000,20.00000,    -0.10478,0.57263
760.82898, 87.31500,    -1.75250,76.97774,50.00000,0.0000e+000,20.00000,    -0.10070,0.57192
762.55902, 87.49000,    -1.74923,76.96026,50.00000,0.0000e+000,20.00000,-9.8340e-002,0.57122
764.30603, 87.66500,    -1.74637,76.94308,50.00000,0.0000e+000,20.00000,-9.6400e-002,0.57052
766.03198, 87.84000,    -1.74352,76.92608,50.00000,0.0000e+000,20.00000,-9.3927e-002,0.56983
767.85797, 88.01500,    -1.75443,76.91025,50.00000,0.0000e+000,20.00000,-9.1440e-002,0.56910
769.69299, 88.19000,    -1.76940,76.89576,50.00000,0.0000e+000,20.00000,-8.9008e-002,0.56837
771.50702, 88.36500,    -1.77486,76.88295,50.00000,0.0000e+000,20.00000,-8.7438e-002,0.56765
773.28003, 88.54000,    -1.77103,76.86924,50.00000,0.0000e+000,20.00000,-8.5826e-002,0.56695
775.02301, 88.71500,    -1.76417,76.85258,50.00000,0.0000e+000,20.00000,-8.4001e-002,0.56626
776.77802, 88.89000,    -1.76107,76.83866,50.00000,0.0000e+000,20.00000,-8.2600e-002,0.56557
778.55200, 89.06500,    -1.76203,76.82659,50.00000,0.0000e+000,20.00000,-8.1147e-002,0.56488
780.32501, 89.24000,    -1.76333,76.81245,50.00000,0.0000e+000,20.00000,-7.9689e-002,0.56418
782.10498, 89.41500,    -1.76766,76.79704,50.00000,0.0000e+000,20.00000,-7.7682e-002,0.56349
783.88202, 89.59000,    -1.77070,76.78262,50.00000,0.0000e+000,20.00000,-7.5731e-002,0.56280
785.62201, 89.76500,    -1.76683,76.76957,50.00000,0.0000e+000,20.00000,-7.4109e-002,0.56212
787.31897, 89.94000,    -1.75606,76.75736,50.00000,0.0000e+000,20.00000,-7.3412e-002,0.56147
788.98901, 90.11500,    -1.74890,76.74559,50.00000,0.0000e+000,20.00000,-7.3177e-002,0.56082
790.68597, 90.29000,    -1.74500,76.73366,50.00000,0.0000e+000,20.00000,-7.3213e-002,0.56017
792.37097, 90.46500,    -1.74597,76.72194,50.00000,0.0000e+000,20.00000,-7.2443e-002,0.55952
794.08502, 90.64000,    -1.75117,76.70885,50.00000,0.0000e+000,20.00000,-7.1201e-002,0.55887
795.84003, 90.81500,    -1.76140,76.69490,50.00000,0.0000e+000,20.00000,-7.1023e-002,0.55820
797.59399, 90.99000,    -1.77292,76.68193,50.00000,0.0000e+000,20.00000,-7.1257e-002,0.55753
799.36200, 91.16500,    -1.78245,76.67098,50.00000,0.0000e+000,20.00000,-7.1113e-002,0.55686
801.13898, 91.34000,    -1.78924,76.66120,50.00000,0.0000e+000,20.00000,-7.0277e-002,0.55618
802.87000, 91.51500,    -1.79110,76.65110,50.00000,0.0000e+000,20.00000,-6.9637e-002,0.55553
804.61798, 91.69000,    -1.79348,76.63938,50.00000,0.0000e+000,20.00000,-6.9107e-002,0.55487
806.38397, 91.86500,    -1.80040,76.62652,50.00000,0.0000e+000,20.00000,-6.9116e-002,0.55420
808.19598, 92.04000,    -1.81175,76.61398,50.00000,0.0000e+000,20.00000,-6.9367e-002,0.55352
809.97900, 92.21500,    -1.81931,76.60079,50.00000,0.0000e+000,20.00000,-6.9792e-002,0.55285
811.74200, 92.39000,    -1.81932,76.58882,50.00000,0.0000e+000,20.00000,-7.0184e-002,0.55220
813.50098, 92.56500,    -1.82017,76.57787,50.00000,0.0000e+000,20.00000,-7.0496e-002,0.55154
815.26703, 92.74000,    -1.82252,76.56501,50.00000,0.0000e+000,20.00000,-7.1466e-002,0.55088
816.99200, 92.91500,    -1.82247,76.55017,50.00000,0.0000e+000,20.00000,-7.2845e-002,0.55024
818.71899, 93.09000,    -1.82101,76.53704,50.00000,0.0000e+000,20.00000,-7.4192e-002,0.54960
820.45697, 93.26500,    -1.82413,76.52560,50.00000,0.0000e+000,20.00000,-7.5529e-002,0.54896
822.21503, 93.44000,    -1.82876,76.51483,50.00000,0.0000e+000,20.00000,-7.6998e-002,0.54831
823.97400, 93.61500,    -1.83259,76.50368,50.00000,0.0000e+000,20.00000,-7.8412e-002,0.54766
825.71100, 93.79000,    -1.83443,76.49106,50.00000,0.0000e+000,20.00000,-8.0528e-002,0.54702
827.46399, 93.96500,    -1.83702,76.47811,50.00000,0.0000e+000,20.00000,-8.2517e-002,0.54638
829.22198, 94.14000,    -1.83987,76.46441,50.00000,0.0000e+000,20.00000,-8.3991e-002,0.54574
830.97302, 94.31500,    -1.83954,76.45035,50.00000,0.0000e+000,20.00000,-8.6396e-002,0.54510
832.71997, 94.49000,    -1.83409,76.43399,50.00000,0.0000e+000,20.00000,-8.9134e-002,0.54446
834.46100, 94.66500,    -1.83162,76.41659,50.00000,0.0000e+000,20.00000,-9.1108e-002,0.54383
836.20801, 94.84000,    -1.83307,76.40082,50.00000,0.0000e+000,20.00000,-9.3459e-002,0.54319
837.95599, 95.01500,    -1.83301,76.38623,50.00000,0.0000e+000,20.00000,-9.7408e-002,0.54256
839.71399, 95.19000,    -1.83301,76.37079,50.00000,0.0000e+000,20.00000,    -0.10197,0.54192
841.46100, 95.36500,    -1.83272,76.35378,50.00000,0.0000e+000,20.00000,    -0.10642,0.54129
843.20898, 95.54000,    -1.83291,76.33445,50.00000,0.0000e+000,20.00000,    -0.11026,0.54066
844.90900, 95.71500,    -1.82806,76.31377,50.00000,0.0000e+000,20.00000,    -0.11402,0.54005
846.69000, 95.89000,    -1.83361,76.29479,50.00000,0.0000e+000,20.00000,    -0.11781,0.53940
848.54901, 96.06500,    -1.85235,76.27622,50.00000,0.0000e+000,20.00000,    -0.12127,0.53874
850.35797, 96.24000,    -1.86002,76.25492,50.00000,0.0000e+000,20.00000,    -0.12514,0.53809
852.13397, 96.41500,    -1.85913,76.23330,50.00000,0.0000e+000,20.00000,    -0.12917,0.53745
853.89697, 96.59000,    -1.85416,76.21140,50.00000,0.0000e+000,20.00000,    -0.13310,0.53682
855.64801, 96.76500,    -1.84956,76.18661,50.00000,0.0000e+000,20.00000,    -0.13685,0.53620
857.39001, 96.94000,    -1.84672,76.15909,50.00000,0.0000e+000,20.00000,    -0.14107,0.53558
859.12097, 97.11500,    -1.84276,76.13167,50.00000,0.0000e+000,20.00000,    -0.14481,0.53496
860.87799, 97.29000,    -1.84097,76.10526,50.00000,0.0000e+000,20.00000,    -0.14768,0.53434
862.61401, 97.46500,    -1.84196,76.07911,50.00000,0.0000e+000,20.00000,    -0.15077,0.53372
864.36798, 97.64000,    -1.84336,76.05188,50.00000,0.0000e+000,20.00000,    -0.15451,0.53310
866.10797, 97.81500,    -1.84321,76.02537,50.00000,0.0000e+000,20.00000,    -0.15813,0.53248
867.85101, 97.99000,    -1.84451,75.99757,50.00000,0.0000e+000,20.00000,    -0.16139,0.53187
869.63098, 98.16500,    -1.85162,75.96648,50.00000,0.0000e+000,20.00000,    -0.16485,0.53124
871.41400, 98.34000,    -1.85920,75.93442,50.00000,0.0000e+000,20.00000,    -0.16813,0.53061
873.18201, 98.51500,    -1.86001,75.90508,50.00000,0.0000e+000,20.00000,    -0.17085,0.52999
874.95099, 98.69000,    -1.85831,75.87594,50.00000,0.0000e+000,20.00000,    -0.17306,0.52937
876.73499, 98.86500,    -1.86472,75.84514,50.00000,0.0000e+000,20.00000,    -0.17466,0.52874
878.52301, 99.04000,    -1.87061,75.81647,50.00000,0.0000e+000,20.00000,    -0.17673,0.52811
880.28601, 99.21500,    -1.86978,75.78634,50.00000,0.0000e+000,20.00000,    -0.17974,0.52749
882.04498, 99.39000,    -1.86846,75.75298,50.00000,0.0000e+000,20.00000,    -0.18223,0.52688
883.77002, 99.56500,    -1.86505,75.72037,50.00000,0.0000e+000,20.00000,    -0.18428,0.52627
885.51898, 99.74000,    -1.86294,75.68940,50.00000,0.0000e+000,20.00000,    -0.18680,0.52566
887.26099, 99.91500,    -1.86260,75.65551,50.00000,0.0000e+000,20.00000,    -0.18875,0.52505
889.00299,100.09000,    -1.86177,75.62143,50.00000,0.0000e+000,20.00000,    -0.19029,0.52445
890.75800,100.26500,    -1.86354,75.58848,50.00000,0.0000e+000,20.00000,    -0.19271,0.52383
892.50201,100.44000,    -1.86499,75.55428,50.00000,0.0000e+000,20.00000,    -0.19526,0.52323
894.25098,100.61500,    -1.86484,75.51999,50.00000,0.0000e+000,20.00000,    -0.19698,0.52262
896.00000,100.79000,    -1.86661,75.48655,50.00000,0.0000e+000,20.00000,    -0.19886,0.52201
897.74500,100.96500,    -1.86860,75.45034,50.00000,0.0000e+000,20.00000,    -0.20130,0.52140
899.48297,101.14000,    -1.86941,75.41353,50.00000,0.0000e+000,20.00000,    -0.20346,0.52080
901.22900,101.31500,    -1.87087,75.37876,50.00000,0.0000e+000,20.00000,    -0.20541,0.52019
902.98798,101.49000,    -1.87406,75.34367,50.00000,0.0000e+000,20.00000,    -0.20748,0.51958
904.74103,101.66500,    -1.87598,75.30702,50.00000,0.0000e+000,20.00000,    -0.20906,0.51898
906.48199,101.84000,    -1.87649,75.26998,50.00000,0.0000e+000,20.00000,    -0.21087,0.51837
908.23401,102.01500,    -1.87860,75.23085,50.00000,0.0000e+000,20.00000,    -0.21308,0.51777
909.99701,102.19000,    -1.87932,75.19198,50.00000,0.0000e+000,20.00000,    -0.21500,0.51716
911.74103,102.36500,    -1.88170,75.15503,50.00000,0.0000e+000,20.00000,    -0.21719,0.51655
913.50000,102.54000,    -1.88151,75.11825,50.00000,0.0000e+000,20.00000,    -0.21976,0.51595
915.24298,102.71500,    -1.88385,75.08148,50.00000,0.0000e+000,20.00000,    -0.22166,0.51534
917.00897,102.89000,    -1.88635,75.04227,50.00000,0.0000e+000,20.00000,    -0.22285,0.51473
918.76599,103.06500,    -1.88548,75.00156,50.00000,0.0000e+000,20.00000,    -0.22396,0.51413
920.51801,103.24000,    -1.88738,74.96178,50.00000,0.0000e+000,20.00000,    -0.22540,0.51352
922.26703,103.41500,    -1.88956,74.92389,50.00000,0.0000e+000,20.00000,    -0.22635,0.51292
924.05701,103.59000,    -1.89206,74.88411,50.00000,0.0000e+000,20.00000,    -0.22663,0.51230
925.84399,103.76500,    -1.90189,74.84235,50.00000,0.0000e+000,20.00000,    -0.22709,0.51169
927.59003,103.94000,    -1.90106,74.80183,50.00000,0.0000e+000,20.00000,    -0.22788,0.51108
929.32898,104.11500,    -1.89591,74.76032,50.00000,0.0000e+000,20.00000,    -0.22956,0.51049
931.08301,104.29000,    -1.89320,74.71704,50.00000,0.0000e+000,20.00000,    -0.23136,0.50988
932.82703,104.46500,    -1.89152,74.67503,50.00000,0.0000e+000,20.00000,    -0.23258,0.50928
934.56897,104.64000,    -1.89127,74.63329,50.00000,0.0000e+000,20.00000,    -0.23247,0.50868
936.31897,104.81500,    -1.89125,74.59285,50.00000,0.0000e+000,20.00000,    -0.23201,0.50808
938.08801,104.99000,    -1.88974,74.55336,50.00000,0.0000e+000,20.00000,    -0.23188,0.50747
939.83899,105.16500,    -1.88626,74.51332,50.00000,0.0000e+000,20.00000,    -0.23154,0.50687
941.58502,105.34000,    -1.88259,74.47491,50.00000,0.0000e+000,20.00000,    -0.22973,0.50627
943.33600,105.51500,    -1.87905,74.43646,50.00000,0.0000e+000,20.00000,    -0.22673,0.50566
945.11902,105.69000,    -1.87619,74.39502,50.00000,0.0000e+000,20.00000,    -0.22318,0.50505
946.88000,105.86500,    -1.87167,74.35168,50.00000,0.0000e+000,20.00000,    -0.21892,0.50444
948.64899,106.04000,    -1.86780,74.30799,50.00000,0.0000e+000,20.00000,    -0.21427,0.50383
950.40900,106.21500,    -1.86191,74.26552,50.00000,0.0000e+000,20.00000,    -0.20958,0.50323
952.15302,106.39000,    -1.85221,74.22669,50.00000,0.0000e+000,20.00000,    -0.20451,0.50263
953.89801,106.56500,    -1.84609,74.18910,50.00000,0.0000e+000,20.00000,    -0.19823,0.50203
955.64502,106.74000,    -1.84041,74.14922,50.00000,0.0000e+000,20.00000,    -0.19252,0.50143
957.39301,106.91500,    -1.83851,74.11029,50.00000,0.0000e+000,20.00000,    -0.18672,0.50082
959.13702,107.09000,    -1.83824,74.07599,50.00000,0.0000e+000,20.00000,    -0.18059,0.50022
960.87201,107.26500,    -1.83768,74.04570,50.00000,0.0000e+000,20.00000,    -0.17437,0.49962
962.62500,107.44000,    -1.83784,74.01571,50.00000,0.0000e+000,20.00000,    -0.16729,0.49902
964.36298,107.61500,    -1.83897,73.99004,50.00000,0.0000e+000,20.00000,    -0.15887,0.49842
966.11298,107.79000,    -1.83984,73.96449,50.00000,0.0000e+000,20.00000,    -0.14940,0.49782
967.88501,107.96500,    -1.84106,73.93869,50.00000,0.0000e+000,20.00000,    -0.14018,0.49721
969.63202,108.14000,    -1.84123,73.91395,50.00000,0.0000e+000,20.00000,    -0.13185,0.49660
971.38898,108.31500,    -1.84286,73.89376,50.00000,0.0000e+000,20.00000,    -0.12465,0.49600
973.14001,108.49000,    -1.84502,73.87570,50.00000,0.0000e+000,20.00000,    -0.11665,0.49539
974.89697,108.66500,    -1.84634,73.85668,50.00000,0.0000e+000,20.00000,    -0.10881,0.49478
976.63898,108.84000,    -1.84504,73.83882,50.00000,0.0000e+000,20.00000,    -0.10145,0.49418
978.39203,109.01500,    -1.84450,73.82304,50.00000,0.0000e+000,20.00000,-9.5277e-002,0.49358
980.14301,109.19000,    -1.84516,73.80846,50.00000,0.0000e+000,20.00000,-9.0327e-002,0.49297
981.90002,109.36500,    -1.84497,73.79506,50.00000,0.0000e+000,20.00000,-8.3958e-002,0.49236
983.65997,109.54000,    -1.84806,73.78526,50.00000,0.0000e+000,20.00000,-7.6488e-002,0.49175
985.44299,109.71500,    -1.85229,73.77594,50.00000,0.0000e+000,20.00000,-7.1167e-002,0.49113
987.20398,109.89000,    -1.85498,73.76615,50.00000,0.0000e+000,20.00000,-6.5590e-002,0.49052
988.96600,110.06500,    -1.85562,73.75522,50.00000,0.0000e+000,20.00000,-6.1029e-002,0.48991
990.75098,110.24000,    -1.85817,73.74497,50.00000,0.0000e+000,20.00000,-5.8410e-002,0.48929
992.56598,110.41500,    -1.86923,73.73458,50.00000,0.0000e+000,20.00000,-5.9865e-002,0.48866
994.35101,110.59000,    -1.86892,73.72357,50.00000,0.0000e+000,20.00000,-5.9469e-002,0.48804
996.07599,110.76500,    -1.86321,73.71495,50.00000,0.0000e+000,20.00000,-5.8841e-002,0.48744
997.81598,110.94000,    -1.85836,73.70474,50.00000,0.0000e+000,20.00000,-7.3900e-002,0.48683
998.46002,111.00500,    -1.85619,73.69939,50.00000,0.0000e+000,20.00000,    -0.11910,0.48661