File: book/some_content/DG_ExpDat_OPC7%DC7; 23-1-2025-2.csv
#FILE:                       ,OPC7%DC7; 23-1-2025.ngb-ds3
#FORMAT:                     ,NETZSCH5
#IDENTITY:                   ,geopolymer paste
#DECIMAL:                    ,POINT
#SEPARATOR:                  ,COMMA
#MTYPE:                      ,DSC
#INSTRUMENT:                 ,Microlab TU Delft
#PROJECT:                    ,
#DATE/TIME:                  ,23/01/2025 8:10:38 PM
#CORR. FILE:                 ,Blank with cover; 13-1-2025.ngb-bs3
#LABORATORY:                 ,TU Delft Micro Lab
#OPERATOR:                   ,Ahmed
#REMARK:                     ,under Argon atmosphere, 10K/min
#SAMPLE:                     ,OPC7%DC7
#SAMPLE MASS /mg:            ,30.2
#MATERIAL:                   ,Geopolymer paste
#REFERENCE:                  ,blank
#REFERENCE MASS /mg:         ,0
#TYPE OF CRUCIBLE:           ,DSC/TG pan Al2O3
#SAMPLE CRUCIBLE MASS /mg:   ,0
#REFERENCE CRUCIBLE MASS /mg:,0
#CORR. CODE:                 ,020
#EXO:                        ,-1
#RANGE:                      ,40/10.0(K/min)/1000
#SEGMENT:                    ,S2/2

##Temp./øC,Time/min,DSC/(mW/mg),Mass/%,Gas Flow(purge1)/(ml/min),Gas Flow(purge2)/(ml/min),Gas Flow(protective)/(ml/min),DTG/(%/min),Sensit./(uV/mW)
 38.54300, 15.69000, 1.2046e-002,97.97379,50.00000,0.0000e+000,20.00000,-5.1918e-002,1.22895
 38.57500, 15.87000, 1.0669e-002,97.96224,50.00000,0.0000e+000,20.00000,-4.9798e-002,1.22891
 38.66000, 16.05000, 9.2722e-003,97.95602,50.00000,0.0000e+000,20.00000,-4.5644e-002,1.22879
 38.80500, 16.23000, 7.8549e-003,97.94509,50.00000,0.0000e+000,20.00000,-4.4246e-002,1.22859
 39.01100, 16.41000, 5.7383e-003,97.93398,50.00000,0.0000e+000,20.00000,-4.3567e-002,1.22831
 39.30200, 16.59000, 4.2588e-003,97.92469,50.00000,0.0000e+000,20.00000,-4.3565e-002,1.22790
 39.65700, 16.77000, 2.7580e-003,97.92048,50.00000,0.0000e+000,20.00000,-4.0276e-002,1.22742
 40.09500, 16.95000, 1.3797e-003,97.91787,50.00000,0.0000e+000,20.00000,-4.2130e-002,1.22681
 40.62800, 17.13000, 2.6786e-004,97.91015,50.00000,0.0000e+000,20.00000,-4.2346e-002,1.22608
 41.22500, 17.31000,-1.0103e-003,97.90417,50.00000,0.0000e+000,20.00000,-4.1994e-002,1.22525
 41.88400, 17.49000,-2.0840e-003,97.89707,50.00000,0.0000e+000,20.00000,-4.1526e-002,1.22434
 42.66100, 17.67000,-3.4282e-003,97.88934,50.00000,0.0000e+000,20.00000,-4.1236e-002,1.22327
 43.50500, 17.85000,-4.4030e-003,97.88346,50.00000,0.0000e+000,20.00000,-4.4212e-002,1.22211
 44.42800, 18.03000,-5.0491e-003,97.87637,50.00000,0.0000e+000,20.00000,-4.4783e-002,1.22084
 45.46000, 18.21000,-6.1323e-003,97.86735,50.00000,0.0000e+000,20.00000,-4.5628e-002,1.21942
 46.58000, 18.39000,-7.7788e-003,97.86451,50.00000,0.0000e+000,20.00000,-4.8513e-002,1.21787
 47.77300, 18.57000,-8.4540e-003,97.86423,50.00000,0.0000e+000,20.00000,-5.2532e-002,1.21623
 49.08100, 18.75000,-9.4443e-003,97.85640,50.00000,0.0000e+000,20.00000,-5.7208e-002,1.21443
 50.45600, 18.93000,-1.0480e-002,97.84704,50.00000,0.0000e+000,20.00000,-6.1113e-002,1.21253
 51.90800, 19.11000,-1.1478e-002,97.83749,50.00000,0.0000e+000,20.00000,-6.7334e-002,1.21053
 53.47000, 19.29000,-1.2481e-002,97.82587,50.00000,0.0000e+000,20.00000,-7.7177e-002,1.20838
 55.10600, 19.47000,-1.3845e-002,97.81501,50.00000,0.0000e+000,20.00000,-8.8183e-002,1.20613
 56.81900, 19.65000,-1.5047e-002,97.79793,50.00000,0.0000e+000,20.00000,-9.9321e-002,1.20378
 58.63700, 19.83000,-1.6067e-002,97.78505,50.00000,0.0000e+000,20.00000,    -0.11112,1.20128
 60.50900, 20.01000,-1.7029e-002,97.77144,50.00000,0.0000e+000,20.00000,    -0.12446,1.19870
 62.46500, 20.19000,-1.7891e-002,97.75180,50.00000,0.0000e+000,20.00000,    -0.14110,1.19601
 64.47300, 20.37000,-1.8546e-002,97.73164,50.00000,0.0000e+000,20.00000,    -0.16263,1.19326
 66.58100, 20.55000,-1.8952e-002,97.71257,50.00000,0.0000e+000,20.00000,    -0.18605,1.19036
 68.74100, 20.73000,-1.9212e-002,97.69155,50.00000,0.0000e+000,20.00000,    -0.21321,1.18740
 70.94200, 20.91000,-1.8877e-002,97.66426,50.00000,0.0000e+000,20.00000,    -0.24016,1.18438
 73.20100, 21.09000,-1.8178e-002,97.62339,50.00000,0.0000e+000,20.00000,    -0.26707,1.18129
 75.53000, 21.27000,-1.6490e-002,97.57542,50.00000,0.0000e+000,20.00000,    -0.29534,1.17810
 77.86700, 21.45000,-1.4471e-002,97.52841,50.00000,0.0000e+000,20.00000,    -0.32316,1.17490
 80.27500, 21.63000,-1.1083e-002,97.47969,50.00000,0.0000e+000,20.00000,    -0.35529,1.17161
 82.71900, 21.81000,-7.2008e-003,97.42290,50.00000,0.0000e+000,20.00000,    -0.38699,1.16828
 85.18900, 21.99000,-2.3638e-003,97.35939,50.00000,0.0000e+000,20.00000,    -0.41561,1.16491
 87.71400, 22.17000, 3.4149e-003,97.28312,50.00000,0.0000e+000,20.00000,    -0.44323,1.16146
 90.25100, 22.35000, 9.9916e-003,97.19327,50.00000,0.0000e+000,20.00000,    -0.47115,1.15801
 92.82400, 22.53000, 1.7506e-002,97.08604,50.00000,0.0000e+000,20.00000,    -0.49784,1.15451
 95.39100, 22.71000, 2.4999e-002,96.97757,50.00000,0.0000e+000,20.00000,    -0.52374,1.15102
 97.99700, 22.89000, 3.2892e-002,96.86871,50.00000,0.0000e+000,20.00000,    -0.54498,1.14749
100.60000, 23.07000, 4.0634e-002,96.75486,50.00000,0.0000e+000,20.00000,    -0.56285,1.14396
103.22600, 23.25000, 4.7517e-002,96.63848,50.00000,0.0000e+000,20.00000,    -0.58290,1.14041
105.83800, 23.43000, 5.2731e-002,96.50836,50.00000,0.0000e+000,20.00000,    -0.59993,1.13688
108.46500, 23.61000, 5.6084e-002,96.37877,50.00000,0.0000e+000,20.00000,    -0.61307,1.13333
111.08600, 23.79000, 5.7869e-002,96.25452,50.00000,0.0000e+000,20.00000,    -0.62622,1.12980
113.69200, 23.97000, 5.6928e-002,96.13327,50.00000,0.0000e+000,20.00000,    -0.63688,1.12629
116.29300, 24.15000, 5.4743e-002,96.01164,50.00000,0.0000e+000,20.00000,    -0.64031,1.12279
118.90600, 24.33000, 5.0897e-002,95.89361,50.00000,0.0000e+000,20.00000,    -0.63500,1.11929
121.49100, 24.51000, 4.5757e-002,95.77326,50.00000,0.0000e+000,20.00000,    -0.63052,1.11582
124.09800, 24.69000, 3.9177e-002,95.65575,50.00000,0.0000e+000,20.00000,    -0.62821,1.11234
126.66400, 24.87000, 3.1917e-002,95.54329,50.00000,0.0000e+000,20.00000,    -0.62390,1.10891
129.24699, 25.05000, 2.3927e-002,95.42337,50.00000,0.0000e+000,20.00000,    -0.61710,1.10547
131.79500, 25.23000, 1.4854e-002,95.31055,50.00000,0.0000e+000,20.00000,    -0.60409,1.10208
134.36099, 25.41000, 5.7255e-003,95.20762,50.00000,0.0000e+000,20.00000,    -0.59069,1.09867
136.87601, 25.59000,-3.6672e-003,95.09793,50.00000,0.0000e+000,20.00000,    -0.58247,1.09533
139.38901, 25.77000,-1.3464e-002,94.98505,50.00000,0.0000e+000,20.00000,    -0.57397,1.09201
141.86501, 25.95000,-2.2833e-002,94.88139,50.00000,0.0000e+000,20.00000,    -0.56044,1.08873
144.34399, 26.13000,-3.2909e-002,94.79548,50.00000,0.0000e+000,20.00000,    -0.54495,1.08546
146.75999, 26.31000,-4.2460e-002,94.70403,50.00000,0.0000e+000,20.00000,    -0.52828,1.08228
149.17999, 26.49000,-5.2464e-002,94.60506,50.00000,0.0000e+000,20.00000,    -0.51628,1.07910
151.58099, 26.67000,-6.2949e-002,94.50635,50.00000,0.0000e+000,20.00000,    -0.50598,1.07595
153.93100, 26.85000,-7.3937e-002,94.41488,50.00000,0.0000e+000,20.00000,    -0.48925,1.07288
156.24800, 27.03000,-8.4796e-002,94.33246,50.00000,0.0000e+000,20.00000,    -0.47105,1.06985
158.57600, 27.21000,-9.6428e-002,94.25258,50.00000,0.0000e+000,20.00000,    -0.45863,1.06681
160.86000, 27.39000,    -0.10786,94.15925,50.00000,0.0000e+000,20.00000,    -0.44607,1.06384
163.12399, 27.57000,    -0.11961,94.06641,50.00000,0.0000e+000,20.00000,    -0.42986,1.06090
165.36900, 27.75000,    -0.13128,93.99196,50.00000,0.0000e+000,20.00000,    -0.41529,1.05799
167.58800, 27.93000,    -0.14325,93.92859,50.00000,0.0000e+000,20.00000,    -0.40685,1.05512
169.77600, 28.11000,    -0.15545,93.87073,50.00000,0.0000e+000,20.00000,    -0.39584,1.05229
171.93700, 28.29000,    -0.16751,93.79840,50.00000,0.0000e+000,20.00000,    -0.37987,1.04950
174.09300, 28.47000,    -0.17884,93.72173,50.00000,0.0000e+000,20.00000,    -0.36436,1.04673
176.21700, 28.65000,    -0.19051,93.66158,50.00000,0.0000e+000,20.00000,    -0.35202,1.04400
178.31400, 28.83000,    -0.20163,93.61246,50.00000,0.0000e+000,20.00000,    -0.34016,1.04132
180.39600, 29.01000,    -0.21297,93.55719,50.00000,0.0000e+000,20.00000,    -0.33086,1.03865
182.45399, 29.19000,    -0.22395,93.49345,50.00000,0.0000e+000,20.00000,    -0.31787,1.03603
184.48700, 29.37000,    -0.23441,93.43920,50.00000,0.0000e+000,20.00000,    -0.30247,1.03344
186.51401, 29.55000,    -0.24475,93.38618,50.00000,0.0000e+000,20.00000,    -0.29184,1.03086
188.50101, 29.73000,    -0.25517,93.32999,50.00000,0.0000e+000,20.00000,    -0.28371,1.02834
190.48399, 29.91000,    -0.26506,93.27863,50.00000,0.0000e+000,20.00000,    -0.27676,1.02583
192.46500, 30.09000,    -0.27529,93.23783,50.00000,0.0000e+000,20.00000,    -0.26547,1.02333
194.40800, 30.27000,    -0.28532,93.19646,50.00000,0.0000e+000,20.00000,    -0.25114,1.02088
196.33600, 30.45000,    -0.29575,93.14867,50.00000,0.0000e+000,20.00000,    -0.24191,1.01845
198.24400, 30.63000,    -0.30498,93.10717,50.00000,0.0000e+000,20.00000,    -0.23720,1.01605
200.13800, 30.81000,    -0.31496,93.06349,50.00000,0.0000e+000,20.00000,    -0.23100,1.01368
202.03900, 30.99000,    -0.32445,93.01849,50.00000,0.0000e+000,20.00000,    -0.22167,1.01130
203.88200, 31.17000,    -0.33455,92.97972,50.00000,0.0000e+000,20.00000,    -0.21386,1.00900
205.72600, 31.35000,    -0.34390,92.94167,50.00000,0.0000e+000,20.00000,    -0.20682,1.00671
207.56599, 31.53000,    -0.35394,92.90557,50.00000,0.0000e+000,20.00000,    -0.19766,1.00442
209.39799, 31.71000,    -0.36391,92.87342,50.00000,0.0000e+000,20.00000,    -0.18812,1.00214
211.21100, 31.89000,    -0.37383,92.84406,50.00000,0.0000e+000,20.00000,    -0.18405,0.99990
213.00800, 32.07000,    -0.38413,92.81875,50.00000,0.0000e+000,20.00000,    -0.18069,0.99768
214.80701, 32.25000,    -0.39453,92.79030,50.00000,0.0000e+000,20.00000,    -0.17450,0.99546
216.58200, 32.43000,    -0.40453,92.75785,50.00000,0.0000e+000,20.00000,    -0.17037,0.99328
218.36700, 32.61000,    -0.41506,92.72688,50.00000,0.0000e+000,20.00000,    -0.16431,0.99109
220.12000, 32.79000,    -0.42569,92.69694,50.00000,0.0000e+000,20.00000,    -0.15595,0.98894
221.88901, 32.97000,    -0.43569,92.66954,50.00000,0.0000e+000,20.00000,    -0.15035,0.98677
223.65601, 33.15000,    -0.44616,92.64254,50.00000,0.0000e+000,20.00000,    -0.14734,0.98462
225.40800, 33.33000,    -0.45613,92.61911,50.00000,0.0000e+000,20.00000,    -0.14364,0.98248
227.15500, 33.51000,    -0.46608,92.60120,50.00000,0.0000e+000,20.00000,    -0.13916,0.98036
228.88800, 33.69000,    -0.47605,92.57574,50.00000,0.0000e+000,20.00000,    -0.13582,0.97826
230.63300, 33.87000,    -0.48642,92.54667,50.00000,0.0000e+000,20.00000,    -0.13384,0.97615
232.36900, 34.05000,    -0.49618,92.52216,50.00000,0.0000e+000,20.00000,    -0.13153,0.97405
234.10001, 34.23000,    -0.50652,92.49438,50.00000,0.0000e+000,20.00000,    -0.12851,0.97197
235.82500, 34.41000,    -0.51698,92.47272,50.00000,0.0000e+000,20.00000,    -0.12447,0.96989
237.56100, 34.59000,    -0.52700,92.45719,50.00000,0.0000e+000,20.00000,    -0.12033,0.96781
239.27299, 34.77000,    -0.53706,92.43949,50.00000,0.0000e+000,20.00000,    -0.11961,0.96576
241.00600, 34.95000,    -0.54692,92.41327,50.00000,0.0000e+000,20.00000,    -0.11760,0.96369
242.72701, 35.13000,    -0.55707,92.38855,50.00000,0.0000e+000,20.00000,    -0.11521,0.96164
244.43800, 35.31000,    -0.56649,92.37216,50.00000,0.0000e+000,20.00000,    -0.11474,0.95961
246.14400, 35.49000,    -0.57689,92.35455,50.00000,0.0000e+000,20.00000,    -0.11255,0.95759
247.86400, 35.67000,    -0.58669,92.33626,50.00000,0.0000e+000,20.00000,    -0.10930,0.95555
249.56900, 35.85000,    -0.59683,92.31742,50.00000,0.0000e+000,20.00000,    -0.10731,0.95354
251.30200, 36.03000,    -0.60637,92.29620,50.00000,0.0000e+000,20.00000,    -0.10369,0.95150
253.01801, 36.21000,    -0.61635,92.27865,50.00000,0.0000e+000,20.00000,    -0.10126,0.94948
254.72400, 36.39000,    -0.62643,92.26450,50.00000,0.0000e+000,20.00000,    -0.10148,0.94748
256.46201, 36.57000,    -0.63627,92.24049,50.00000,0.0000e+000,20.00000,    -0.10210,0.94544
258.17300, 36.75000,    -0.64635,92.21908,50.00000,0.0000e+000,20.00000,    -0.10087,0.94345
259.89899, 36.93000,    -0.65669,92.20371,50.00000,0.0000e+000,20.00000,-9.9863e-002,0.94144
261.61899, 37.11000,    -0.66656,92.18709,50.00000,0.0000e+000,20.00000,-9.9307e-002,0.93944
263.35599, 37.29000,    -0.67642,92.17139,50.00000,0.0000e+000,20.00000,-9.7726e-002,0.93743
265.08701, 37.47000,    -0.68649,92.15414,50.00000,0.0000e+000,20.00000,-9.6586e-002,0.93543
266.83200, 37.65000,    -0.69636,92.13612,50.00000,0.0000e+000,20.00000,-9.7797e-002,0.93342
268.57101, 37.83000,    -0.70561,92.12178,50.00000,0.0000e+000,20.00000,-9.8738e-002,0.93142
270.29901, 38.01000,    -0.71459,92.10750,50.00000,0.0000e+000,20.00000,-9.6886e-002,0.92943
272.03900, 38.19000,    -0.72315,92.09142,50.00000,0.0000e+000,20.00000,-9.6630e-002,0.92744
273.78500, 38.37000,    -0.73230,92.07242,50.00000,0.0000e+000,20.00000,-9.5405e-002,0.92545
275.52701, 38.55000,    -0.74076,92.05241,50.00000,0.0000e+000,20.00000,-9.4520e-002,0.92347
277.26099, 38.73000,    -0.74983,92.02973,50.00000,0.0000e+000,20.00000,-9.5991e-002,0.92150
279.00201, 38.91000,    -0.75864,92.01342,50.00000,0.0000e+000,20.00000,-9.7955e-002,0.91953
280.76099, 39.09000,    -0.76846,92.00202,50.00000,0.0000e+000,20.00000,-9.8907e-002,0.91754
282.49701, 39.27000,    -0.77686,91.98855,50.00000,0.0000e+000,20.00000,-9.8595e-002,0.91558
284.23599, 39.45000,    -0.78582,91.96723,50.00000,0.0000e+000,20.00000,-9.9555e-002,0.91363
285.98801, 39.63000,    -0.79455,91.94135,50.00000,0.0000e+000,20.00000,    -0.10166,0.91166
287.75500, 39.81000,    -0.80275,91.92825,50.00000,0.0000e+000,20.00000,    -0.10354,0.90969
289.49701, 39.99000,    -0.81139,91.91630,50.00000,0.0000e+000,20.00000,    -0.10489,0.90775
291.24799, 40.17000,    -0.81936,91.89881,50.00000,0.0000e+000,20.00000,    -0.10446,0.90580
292.99100, 40.35000,    -0.82782,91.87918,50.00000,0.0000e+000,20.00000,    -0.10438,0.90387
294.73300, 40.53000,    -0.83589,91.85871,50.00000,0.0000e+000,20.00000,    -0.10481,0.90194
296.50201, 40.71000,    -0.84424,91.83523,50.00000,0.0000e+000,20.00000,    -0.10682,0.89999
298.26001, 40.89000,    -0.85303,91.81455,50.00000,0.0000e+000,20.00000,    -0.11080,0.89806
300.00800, 41.07000,    -0.86089,91.79951,50.00000,0.0000e+000,20.00000,    -0.11318,0.89614
301.76999, 41.25000,    -0.86913,91.77818,50.00000,0.0000e+000,20.00000,    -0.11295,0.89421
303.53201, 41.43000,    -0.87734,91.75574,50.00000,0.0000e+000,20.00000,    -0.11131,0.89229
305.30399, 41.61000,    -0.88489,91.73447,50.00000,0.0000e+000,20.00000,    -0.11383,0.89037
307.06299, 41.79000,    -0.89225,91.71369,50.00000,0.0000e+000,20.00000,    -0.11871,0.88846
308.82199, 41.97000,    -0.89986,91.69612,50.00000,0.0000e+000,20.00000,    -0.12265,0.88656
310.59799, 42.15000,    -0.90795,91.67756,50.00000,0.0000e+000,20.00000,    -0.12477,0.88464
312.34698, 42.33000,    -0.91632,91.65376,50.00000,0.0000e+000,20.00000,    -0.12536,0.88276
314.12000, 42.51000,    -0.92449,91.62887,50.00000,0.0000e+000,20.00000,    -0.12670,0.88086
315.88199, 42.69000,    -0.93228,91.60264,50.00000,0.0000e+000,20.00000,    -0.12785,0.87898
317.67200, 42.87000,    -0.93891,91.58017,50.00000,0.0000e+000,20.00000,    -0.13248,0.87707
319.42200, 43.05000,    -0.94636,91.56133,50.00000,0.0000e+000,20.00000,    -0.13624,0.87521
321.20200, 43.23000,    -0.95352,91.54114,50.00000,0.0000e+000,20.00000,    -0.13795,0.87333
322.96701, 43.41000,    -0.96072,91.51768,50.00000,0.0000e+000,20.00000,    -0.14119,0.87147
324.73700, 43.59000,    -0.96775,91.48933,50.00000,0.0000e+000,20.00000,    -0.14533,0.86960
326.51801, 43.77000,    -0.97502,91.45814,50.00000,0.0000e+000,20.00000,    -0.15183,0.86773
328.27499, 43.95000,    -0.98318,91.42969,50.00000,0.0000e+000,20.00000,    -0.15709,0.86590
330.05301, 44.13000,    -0.99117,91.40759,50.00000,0.0000e+000,20.00000,    -0.15952,0.86404
331.83600, 44.31000,    -0.99940,91.38009,50.00000,0.0000e+000,20.00000,    -0.16188,0.86219
333.61099, 44.49000,    -1.00658,91.35394,50.00000,0.0000e+000,20.00000,    -0.16590,0.86035
335.39600, 44.67000,    -1.01345,91.32320,50.00000,0.0000e+000,20.00000,    -0.17189,0.85850
337.18600, 44.85000,    -1.01979,91.28854,50.00000,0.0000e+000,20.00000,    -0.17776,0.85666
338.95200, 45.03000,    -1.02491,91.25937,50.00000,0.0000e+000,20.00000,    -0.18338,0.85485
340.73099, 45.21000,    -1.03131,91.22702,50.00000,0.0000e+000,20.00000,    -0.18809,0.85303
342.52802, 45.39000,    -1.04056,91.19132,50.00000,0.0000e+000,20.00000,    -0.19205,0.85119
344.33600, 45.57000,    -1.05037,91.15024,50.00000,0.0000e+000,20.00000,    -0.19511,0.84935
346.15799, 45.75000,    -1.05817,91.11163,50.00000,0.0000e+000,20.00000,    -0.19961,0.84751
347.95300, 45.93000,    -1.06459,91.07948,50.00000,0.0000e+000,20.00000,    -0.20509,0.84569
349.75299, 46.11000,    -1.06948,91.04638,50.00000,0.0000e+000,20.00000,    -0.20893,0.84388
351.55301, 46.29000,    -1.07340,91.00725,50.00000,0.0000e+000,20.00000,    -0.21317,0.84207
353.34399, 46.47000,    -1.07701,90.96142,50.00000,0.0000e+000,20.00000,    -0.21671,0.84028
355.11899, 46.65000,    -1.08085,90.92075,50.00000,0.0000e+000,20.00000,    -0.21815,0.83851
356.88699, 46.83000,    -1.08599,90.88011,50.00000,0.0000e+000,20.00000,    -0.22121,0.83676
358.64499, 47.01000,    -1.09261,90.84052,50.00000,0.0000e+000,20.00000,    -0.22342,0.83501
360.39099, 47.19000,    -1.10105,90.79829,50.00000,0.0000e+000,20.00000,    -0.22384,0.83329
362.16800, 47.37000,    -1.11002,90.75657,50.00000,0.0000e+000,20.00000,    -0.22352,0.83154
363.93900, 47.55000,    -1.12026,90.71089,50.00000,0.0000e+000,20.00000,    -0.22372,0.82980
365.69199, 47.73000,    -1.12859,90.66763,50.00000,0.0000e+000,20.00000,    -0.22480,0.82809
367.44800, 47.91000,    -1.13686,90.62727,50.00000,0.0000e+000,20.00000,    -0.22557,0.82638
369.21600, 48.09000,    -1.14676,90.58509,50.00000,0.0000e+000,20.00000,    -0.22468,0.82466
370.98099, 48.27000,    -1.15955,90.54286,50.00000,0.0000e+000,20.00000,    -0.22077,0.82296
372.75201, 48.45000,    -1.17288,90.50223,50.00000,0.0000e+000,20.00000,    -0.21896,0.82125
374.52899, 48.63000,    -1.18435,90.46159,50.00000,0.0000e+000,20.00000,    -0.21811,0.81954
376.29999, 48.81000,    -1.19537,90.42141,50.00000,0.0000e+000,20.00000,    -0.21635,0.81784
378.08200, 48.99000,    -1.20659,90.38456,50.00000,0.0000e+000,20.00000,    -0.21337,0.81614
379.85999, 49.17000,    -1.21902,90.34604,50.00000,0.0000e+000,20.00000,    -0.21225,0.81445
381.63800, 49.35000,    -1.23109,90.30513,50.00000,0.0000e+000,20.00000,    -0.20938,0.81277
383.42999, 49.53000,    -1.24362,90.26823,50.00000,0.0000e+000,20.00000,    -0.20527,0.81107
385.23199, 49.71000,    -1.25494,90.23248,50.00000,0.0000e+000,20.00000,    -0.20203,0.80938
386.99799, 49.89000,    -1.26708,90.19789,50.00000,0.0000e+000,20.00000,    -0.19938,0.80772
388.78900, 50.07000,    -1.27927,90.16593,50.00000,0.0000e+000,20.00000,    -0.19697,0.80605
390.58401, 50.25000,    -1.29236,90.13237,50.00000,0.0000e+000,20.00000,    -0.19358,0.80438
392.37900, 50.43000,    -1.30596,90.09447,50.00000,0.0000e+000,20.00000,    -0.18944,0.80271
394.18500, 50.61000,    -1.31846,90.06081,50.00000,0.0000e+000,20.00000,    -0.18618,0.80104
395.97299, 50.79000,    -1.33024,90.02988,50.00000,0.0000e+000,20.00000,    -0.18398,0.79940
397.76801, 50.97000,    -1.34182,89.99328,50.00000,0.0000e+000,20.00000,    -0.18353,0.79775
399.54501, 51.15000,    -1.35135,89.95752,50.00000,0.0000e+000,20.00000,    -0.18226,0.79612
401.33200, 51.33000,    -1.36153,89.92781,50.00000,0.0000e+000,20.00000,    -0.17985,0.79450
403.12299, 51.51000,    -1.37079,89.89977,50.00000,0.0000e+000,20.00000,    -0.17881,0.79287
404.91501, 51.69000,    -1.38276,89.86785,50.00000,0.0000e+000,20.00000,    -0.17996,0.79125
406.71201, 51.87000,    -1.39449,89.83442,50.00000,0.0000e+000,20.00000,    -0.18118,0.78963
408.48801, 52.05000,    -1.40565,89.80457,50.00000,0.0000e+000,20.00000,    -0.18192,0.78804
410.29001, 52.23000,    -1.41601,89.77964,50.00000,0.0000e+000,20.00000,    -0.18100,0.78643
412.08401, 52.41000,    -1.42553,89.75124,50.00000,0.0000e+000,20.00000,    -0.17982,0.78483
413.86899, 52.59000,    -1.43522,89.72242,50.00000,0.0000e+000,20.00000,    -0.18030,0.78324
415.66400, 52.77000,    -1.44450,89.68741,50.00000,0.0000e+000,20.00000,    -0.18086,0.78166
417.45401, 52.95000,    -1.45338,89.64995,50.00000,0.0000e+000,20.00000,    -0.18212,0.78008
419.23199, 53.13000,    -1.46126,89.62071,50.00000,0.0000e+000,20.00000,    -0.18376,0.77852
421.01001, 53.31000,    -1.46958,89.58977,50.00000,0.0000e+000,20.00000,    -0.18638,0.77696
422.79099, 53.49000,    -1.47838,89.55143,50.00000,0.0000e+000,20.00000,    -0.18833,0.77541
424.57300, 53.67000,    -1.48751,89.51372,50.00000,0.0000e+000,20.00000,    -0.19013,0.77387
426.35300, 53.85000,    -1.49701,89.47857,50.00000,0.0000e+000,20.00000,    -0.19279,0.77233
428.14301, 54.03000,    -1.50744,89.44349,50.00000,0.0000e+000,20.00000,    -0.19755,0.77079
429.91299, 54.21000,    -1.51643,89.41299,50.00000,0.0000e+000,20.00000,    -0.20073,0.76927
431.71701, 54.39000,    -1.52546,89.38109,50.00000,0.0000e+000,20.00000,    -0.20301,0.76773
433.49399, 54.57000,    -1.53556,89.34428,50.00000,0.0000e+000,20.00000,    -0.20474,0.76621
435.30600, 54.75000,    -1.54968,89.30298,50.00000,0.0000e+000,20.00000,    -0.20577,0.76468
437.10599, 54.93000,    -1.56260,89.26589,50.00000,0.0000e+000,20.00000,    -0.20893,0.76316
438.92200, 55.11000,    -1.57250,89.22887,50.00000,0.0000e+000,20.00000,    -0.21127,0.76163
440.73199, 55.29000,    -1.58139,89.19052,50.00000,0.0000e+000,20.00000,    -0.21131,0.76011
442.53000, 55.47000,    -1.58862,89.15080,50.00000,0.0000e+000,20.00000,    -0.21233,0.75861
444.32101, 55.65000,    -1.59461,89.11018,50.00000,0.0000e+000,20.00000,    -0.21482,0.75712
446.10699, 55.83000,    -1.60030,89.06813,50.00000,0.0000e+000,20.00000,    -0.21736,0.75564
447.88699, 56.01000,    -1.60647,89.02768,50.00000,0.0000e+000,20.00000,    -0.22231,0.75418
449.67200, 56.19000,    -1.61477,88.99078,50.00000,0.0000e+000,20.00000,    -0.22590,0.75271
451.45200, 56.37000,    -1.62217,88.95124,50.00000,0.0000e+000,20.00000,    -0.22762,0.75125
453.22800, 56.55000,    -1.63059,88.90959,50.00000,0.0000e+000,20.00000,    -0.22821,0.74981
455.01300, 56.73000,    -1.63955,88.86747,50.00000,0.0000e+000,20.00000,    -0.23062,0.74836
456.79700, 56.91000,    -1.64870,88.82849,50.00000,0.0000e+000,20.00000,    -0.23415,0.74691
458.57599, 57.09000,    -1.65790,88.79124,50.00000,0.0000e+000,20.00000,    -0.23715,0.74548
460.35901, 57.27000,    -1.66744,88.74966,50.00000,0.0000e+000,20.00000,    -0.23849,0.74405
462.12900, 57.45000,    -1.67783,88.70568,50.00000,0.0000e+000,20.00000,    -0.23978,0.74264
463.92899, 57.63000,    -1.68731,88.66125,50.00000,0.0000e+000,20.00000,    -0.24108,0.74121
465.70599, 57.81000,    -1.69612,88.61244,50.00000,0.0000e+000,20.00000,    -0.24374,0.73980
467.51401, 57.99000,    -1.70501,88.56697,50.00000,0.0000e+000,20.00000,    -0.24945,0.73837
469.29199, 58.17000,    -1.71338,88.52485,50.00000,0.0000e+000,20.00000,    -0.25291,0.73697
471.07501, 58.35000,    -1.72292,88.48193,50.00000,0.0000e+000,20.00000,    -0.25559,0.73558
472.86899, 58.53000,    -1.73171,88.43573,50.00000,0.0000e+000,20.00000,    -0.25938,0.73418
474.65201, 58.71000,    -1.73901,88.38663,50.00000,0.0000e+000,20.00000,    -0.26376,0.73279
476.44601, 58.89000,    -1.74904,88.33676,50.00000,0.0000e+000,20.00000,    -0.26815,0.73141
478.25299, 59.07000,    -1.76366,88.29203,50.00000,0.0000e+000,20.00000,    -0.27008,0.73002
480.08801, 59.25000,    -1.77632,88.24713,50.00000,0.0000e+000,20.00000,    -0.27174,0.72861
481.89700, 59.43000,    -1.78498,88.20059,50.00000,0.0000e+000,20.00000,    -0.27672,0.72723
483.71201, 59.61000,    -1.79206,88.15118,50.00000,0.0000e+000,20.00000,    -0.27999,0.72585
485.51199, 59.79000,    -1.79979,88.09338,50.00000,0.0000e+000,20.00000,    -0.28026,0.72449
487.29999, 59.97000,    -1.80664,88.04052,50.00000,0.0000e+000,20.00000,    -0.28468,0.72314
489.12000, 60.15000,    -1.81331,87.99024,50.00000,0.0000e+000,20.00000,    -0.28914,0.72177
490.89899, 60.33000,    -1.81862,87.93426,50.00000,0.0000e+000,20.00000,    -0.29233,0.72044
492.69199, 60.51000,    -1.82340,87.87862,50.00000,0.0000e+000,20.00000,    -0.29425,0.71911
494.47800, 60.69000,    -1.83067,87.82478,50.00000,0.0000e+000,20.00000,    -0.29356,0.71778
496.25201, 60.87000,    -1.83998,87.77620,50.00000,0.0000e+000,20.00000,    -0.29517,0.71647
498.03900, 61.05000,    -1.84862,87.72766,50.00000,0.0000e+000,20.00000,    -0.29886,0.71516
499.82199, 61.23000,    -1.85756,87.66685,50.00000,0.0000e+000,20.00000,    -0.30133,0.71385
501.60999, 61.41000,    -1.86670,87.60465,50.00000,0.0000e+000,20.00000,    -0.30304,0.71255
503.39401, 61.59000,    -1.87607,87.55663,50.00000,0.0000e+000,20.00000,    -0.30433,0.71125
505.18701, 61.77000,    -1.88462,87.50042,50.00000,0.0000e+000,20.00000,    -0.30844,0.70996
506.99301, 61.95000,    -1.89499,87.44034,50.00000,0.0000e+000,20.00000,    -0.30906,0.70866
508.78201, 62.13000,    -1.90446,87.38353,50.00000,0.0000e+000,20.00000,    -0.30747,0.70738
510.55399, 62.31000,    -1.90991,87.32666,50.00000,0.0000e+000,20.00000,    -0.30896,0.70611
512.31500, 62.49000,    -1.91255,87.27839,50.00000,0.0000e+000,20.00000,    -0.31096,0.70486
514.09003, 62.67000,    -1.91549,87.22819,50.00000,0.0000e+000,20.00000,    -0.31366,0.70360
515.85400, 62.85000,    -1.92360,87.17085,50.00000,0.0000e+000,20.00000,    -0.31855,0.70236
517.64899, 63.03000,    -1.93902,87.11440,50.00000,0.0000e+000,20.00000,    -0.32024,0.70110
519.46100, 63.21000,    -1.95826,87.06044,50.00000,0.0000e+000,20.00000,    -0.31960,0.69984
521.29498, 63.39000,    -1.97507,87.00017,50.00000,0.0000e+000,20.00000,    -0.32194,0.69856
523.11603, 63.57000,    -1.98325,86.93062,50.00000,0.0000e+000,20.00000,    -0.32508,0.69730
524.91498, 63.75000,    -1.98736,86.87559,50.00000,0.0000e+000,20.00000,    -0.32891,0.69606
526.70502, 63.93000,    -1.99000,86.82769,50.00000,0.0000e+000,20.00000,    -0.32913,0.69483
528.49597, 64.11000,    -1.99250,86.76739,50.00000,0.0000e+000,20.00000,    -0.32747,0.69361
530.28003, 64.29000,    -1.99792,86.70541,50.00000,0.0000e+000,20.00000,    -0.33006,0.69239
532.05798, 64.47000,    -2.00645,86.64616,50.00000,0.0000e+000,20.00000,    -0.33475,0.69119
533.85602, 64.65000,    -2.01646,86.58167,50.00000,0.0000e+000,20.00000,    -0.33854,0.68997
535.63397, 64.83000,    -2.02568,86.51607,50.00000,0.0000e+000,20.00000,    -0.34193,0.68878
537.43799, 65.01000,    -2.03412,86.45404,50.00000,0.0000e+000,20.00000,    -0.34472,0.68757
539.21600, 65.19000,    -2.04260,86.39617,50.00000,0.0000e+000,20.00000,    -0.34643,0.68639
541.01898, 65.37000,    -2.05328,86.33274,50.00000,0.0000e+000,20.00000,    -0.34440,0.68519
542.82599, 65.55000,    -2.06218,86.25763,50.00000,0.0000e+000,20.00000,    -0.34479,0.68400
544.61700, 65.73000,    -2.07202,86.19714,50.00000,0.0000e+000,20.00000,    -0.35115,0.68282
546.44397, 65.91000,    -2.08652,86.14627,50.00000,0.0000e+000,20.00000,    -0.35334,0.68163
548.27802, 66.09000,    -2.09906,86.08860,50.00000,0.0000e+000,20.00000,    -0.35353,0.68043
550.09601, 66.27000,    -2.10839,86.02345,50.00000,0.0000e+000,20.00000,    -0.35599,0.67925
551.90900, 66.45000,    -2.11248,85.95334,50.00000,0.0000e+000,20.00000,    -0.35882,0.67808
553.70203, 66.63000,    -2.11272,85.88313,50.00000,0.0000e+000,20.00000,    -0.35933,0.67693
555.45398, 66.81000,    -2.11203,85.81870,50.00000,0.0000e+000,20.00000,    -0.35886,0.67581
557.23401, 66.99000,    -2.11559,85.75384,50.00000,0.0000e+000,20.00000,    -0.36071,0.67467
559.00897, 67.17000,    -2.12258,85.69121,50.00000,0.0000e+000,20.00000,    -0.36188,0.67355
560.80402, 67.35000,    -2.13382,85.63223,50.00000,0.0000e+000,20.00000,    -0.35964,0.67241
562.62598, 67.53000,    -2.15188,85.56340,50.00000,0.0000e+000,20.00000,    -0.36178,0.67127
564.45398, 67.71000,    -2.16607,85.49509,50.00000,0.0000e+000,20.00000,    -0.36647,0.67012
566.25800, 67.89000,    -2.17405,85.43244,50.00000,0.0000e+000,20.00000,    -0.37108,0.66900
568.06201, 68.07000,    -2.17887,85.36500,50.00000,0.0000e+000,20.00000,    -0.37052,0.66788
569.83600, 68.25000,    -2.17958,85.29173,50.00000,0.0000e+000,20.00000,    -0.36597,0.66678
571.61700, 68.43000,    -2.18301,85.22211,50.00000,0.0000e+000,20.00000,    -0.36595,0.66569
573.43402, 68.61000,    -2.19184,85.16103,50.00000,0.0000e+000,20.00000,    -0.36635,0.66457
575.24298, 68.79000,    -2.20371,85.09678,50.00000,0.0000e+000,20.00000,    -0.36630,0.66347
577.04401, 68.97000,    -2.21593,85.03058,50.00000,0.0000e+000,20.00000,    -0.36821,0.66238
578.85901, 69.15000,    -2.22667,84.96505,50.00000,0.0000e+000,20.00000,    -0.37181,0.66128
580.66803, 69.33000,    -2.23555,84.89352,50.00000,0.0000e+000,20.00000,    -0.37222,0.66019
582.46100, 69.51000,    -2.24137,84.82547,50.00000,0.0000e+000,20.00000,    -0.37084,0.65912
584.26599, 69.69000,    -2.24554,84.75274,50.00000,0.0000e+000,20.00000,    -0.37502,0.65804
586.06000, 69.87000,    -2.25168,84.68768,50.00000,0.0000e+000,20.00000,    -0.37958,0.65697
587.84601, 70.05000,    -2.25689,84.63563,50.00000,0.0000e+000,20.00000,    -0.37737,0.65592
589.64203, 70.23000,    -2.26497,84.56733,50.00000,0.0000e+000,20.00000,    -0.37222,0.65486
591.43597, 70.41000,    -2.27309,84.49870,50.00000,0.0000e+000,20.00000,    -0.37253,0.65381
593.23499, 70.59000,    -2.28224,84.43556,50.00000,0.0000e+000,20.00000,    -0.37819,0.65276
595.04700, 70.77000,    -2.29612,84.36527,50.00000,0.0000e+000,20.00000,    -0.38309,0.65171
596.89301, 70.95000,    -2.31181,84.29373,50.00000,0.0000e+000,20.00000,    -0.38548,0.65064
598.70203, 71.13000,    -2.32112,84.22386,50.00000,0.0000e+000,20.00000,    -0.38561,0.64960
600.51099, 71.31000,    -2.32681,84.15979,50.00000,0.0000e+000,20.00000,    -0.38873,0.64856
602.31897, 71.49000,    -2.33189,84.08448,50.00000,0.0000e+000,20.00000,    -0.38705,0.64753
604.10602, 71.67000,    -2.33332,84.00016,50.00000,0.0000e+000,20.00000,    -0.38503,0.64651
605.89801, 71.85000,    -2.33507,83.93230,50.00000,0.0000e+000,20.00000,    -0.39126,0.64550
607.66803, 72.03000,    -2.33821,83.87968,50.00000,0.0000e+000,20.00000,    -0.39499,0.64450
609.46002, 72.21000,    -2.34351,83.81987,50.00000,0.0000e+000,20.00000,    -0.39967,0.64350
611.23499, 72.39000,    -2.35165,83.73817,50.00000,0.0000e+000,20.00000,    -0.40503,0.64251
613.00702, 72.57000,    -2.35928,83.65245,50.00000,0.0000e+000,20.00000,    -0.40426,0.64152
614.81897, 72.75000,    -2.36857,83.57728,50.00000,0.0000e+000,20.00000,    -0.40691,0.64052
616.62500, 72.93000,    -2.37755,83.50651,50.00000,0.0000e+000,20.00000,    -0.41189,0.63952
618.41803, 73.11000,    -2.38640,83.42710,50.00000,0.0000e+000,20.00000,    -0.41582,0.63854
620.21198, 73.29000,    -2.39577,83.35807,50.00000,0.0000e+000,20.00000,    -0.41804,0.63756
622.03198, 73.47000,    -2.40466,83.29928,50.00000,0.0000e+000,20.00000,    -0.41854,0.63657
623.82001, 73.65000,    -2.41301,83.22592,50.00000,0.0000e+000,20.00000,    -0.42000,0.63560
625.62097, 73.83000,    -2.41949,83.14758,50.00000,0.0000e+000,20.00000,    -0.42524,0.63463
627.44202, 74.01000,    -2.42669,83.06102,50.00000,0.0000e+000,20.00000,    -0.43409,0.63365
629.25598, 74.19000,    -2.43477,82.97685,50.00000,0.0000e+000,20.00000,    -0.43943,0.63268
631.10901, 74.37000,    -2.45420,82.90865,50.00000,0.0000e+000,20.00000,    -0.43900,0.63170
632.95398, 74.55000,    -2.46197,82.83144,50.00000,0.0000e+000,20.00000,    -0.44253,0.63072
634.73901, 74.73000,    -2.45338,82.74144,50.00000,0.0000e+000,20.00000,    -0.44663,0.62978
636.51599, 74.91000,    -2.44831,82.66161,50.00000,0.0000e+000,20.00000,    -0.44610,0.62884
638.27802, 75.09000,    -2.45001,82.58230,50.00000,0.0000e+000,20.00000,    -0.44698,0.62792
640.09900, 75.27000,    -2.46564,82.49542,50.00000,0.0000e+000,20.00000,    -0.45448,0.62697
641.91803, 75.45000,    -2.47807,82.41730,50.00000,0.0000e+000,20.00000,    -0.45707,0.62603
643.74200, 75.63000,    -2.48650,82.34494,50.00000,0.0000e+000,20.00000,    -0.45941,0.62509
645.53497, 75.81000,    -2.48896,82.25897,50.00000,0.0000e+000,20.00000,    -0.46089,0.62416
647.33899, 75.99000,    -2.48965,82.15942,50.00000,0.0000e+000,20.00000,    -0.46024,0.62324
649.13800, 76.17000,    -2.49254,82.07348,50.00000,0.0000e+000,20.00000,    -0.45921,0.62232
650.92499, 76.35000,    -2.49944,81.98448,50.00000,0.0000e+000,20.00000,    -0.45860,0.62142
652.71600, 76.53000,    -2.50536,81.89771,50.00000,0.0000e+000,20.00000,    -0.46090,0.62051
654.51398, 76.71000,    -2.50947,81.82024,50.00000,0.0000e+000,20.00000,    -0.46242,0.61960
656.29700, 76.89000,    -2.51265,81.74548,50.00000,0.0000e+000,20.00000,    -0.45929,0.61871
658.08301, 77.07000,    -2.52053,81.66126,50.00000,0.0000e+000,20.00000,    -0.45381,0.61782
659.90900, 77.25000,    -2.53788,81.57918,50.00000,0.0000e+000,20.00000,    -0.45175,0.61691
661.72803, 77.43000,    -2.54561,81.49463,50.00000,0.0000e+000,20.00000,    -0.45144,0.61601
663.51898, 77.61000,    -2.54762,81.40378,50.00000,0.0000e+000,20.00000,    -0.45031,0.61513
665.33197, 77.79000,    -2.55666,81.31828,50.00000,0.0000e+000,20.00000,    -0.44274,0.61424
667.15002, 77.97000,    -2.56308,81.24959,50.00000,0.0000e+000,20.00000,    -0.43560,0.61335
668.94299, 78.15000,    -2.56273,81.18172,50.00000,0.0000e+000,20.00000,    -0.42945,0.61247
670.72601, 78.33000,    -2.56677,81.08536,50.00000,0.0000e+000,20.00000,    -0.42379,0.61161
672.52301, 78.51000,    -2.57352,80.99478,50.00000,0.0000e+000,20.00000,    -0.41871,0.61074
674.33502, 78.69000,    -2.58453,80.92597,50.00000,0.0000e+000,20.00000,    -0.41665,0.60987
676.15997, 78.87000,    -2.59422,80.86058,50.00000,0.0000e+000,20.00000,    -0.40863,0.60900
677.97302, 79.05000,    -2.60422,80.78844,50.00000,0.0000e+000,20.00000,    -0.40163,0.60813
679.78302, 79.23000,    -2.61003,80.71730,50.00000,0.0000e+000,20.00000,    -0.40054,0.60727
681.58502, 79.41000,    -2.61341,80.64003,50.00000,0.0000e+000,20.00000,    -0.39321,0.60642
683.37903, 79.59000,    -2.61356,80.56566,50.00000,0.0000e+000,20.00000,    -0.38237,0.60557
685.15698, 79.77000,    -2.61432,80.50359,50.00000,0.0000e+000,20.00000,    -0.37619,0.60474
686.93903, 79.95000,    -2.61835,80.43928,50.00000,0.0000e+000,20.00000,    -0.37206,0.60390
688.72803, 80.13000,    -2.62394,80.37098,50.00000,0.0000e+000,20.00000,    -0.36244,0.60307
690.52698, 80.31000,    -2.63525,80.31085,50.00000,0.0000e+000,20.00000,    -0.35395,0.60224
692.35699, 80.49000,    -2.64786,80.24420,50.00000,0.0000e+000,20.00000,    -0.34942,0.60139
694.15698, 80.67000,    -2.65278,80.18857,50.00000,0.0000e+000,20.00000,    -0.34467,0.60056
695.95697, 80.85000,    -2.65681,80.13363,50.00000,0.0000e+000,20.00000,    -0.34090,0.59974
697.76801, 81.03000,    -2.66242,80.05665,50.00000,0.0000e+000,20.00000,    -0.33916,0.59891
699.58502, 81.21000,    -2.66884,79.98814,50.00000,0.0000e+000,20.00000,    -0.33502,0.59808
701.39001, 81.39000,    -2.67326,79.94035,50.00000,0.0000e+000,20.00000,    -0.33067,0.59726
703.21198, 81.57000,    -2.68339,79.89148,50.00000,0.0000e+000,20.00000,    -0.32708,0.59644
705.07202, 81.75000,    -2.70060,79.84206,50.00000,0.0000e+000,20.00000,    -0.32235,0.59560
706.91400, 81.93000,    -2.70235,79.78537,50.00000,0.0000e+000,20.00000,    -0.31884,0.59478
708.70898, 82.11000,    -2.69604,79.72308,50.00000,0.0000e+000,20.00000,    -0.31774,0.59398
710.50598, 82.29000,    -2.68899,79.66575,50.00000,0.0000e+000,20.00000,    -0.31467,0.59318
712.29602, 82.47000,    -2.68653,79.61909,50.00000,0.0000e+000,20.00000,    -0.31312,0.59239
714.06201, 82.65000,    -2.68345,79.56312,50.00000,0.0000e+000,20.00000,    -0.31017,0.59161
715.84302, 82.83000,    -2.68316,79.49842,50.00000,0.0000e+000,20.00000,    -0.29894,0.59082
717.64398, 83.01000,    -2.68705,79.43692,50.00000,0.0000e+000,20.00000,    -0.28749,0.59003
719.45300, 83.19000,    -2.68945,79.37640,50.00000,0.0000e+000,20.00000,    -0.28079,0.58924
721.22900, 83.37000,    -2.69268,79.32410,50.00000,0.0000e+000,20.00000,    -0.27409,0.58847
723.02399, 83.55000,    -2.70015,79.27916,50.00000,0.0000e+000,20.00000,    -0.26843,0.58769
724.84601, 83.73000,    -2.71131,79.22442,50.00000,0.0000e+000,20.00000,    -0.25904,0.58691
726.64301, 83.91000,    -2.72113,79.16720,50.00000,0.0000e+000,20.00000,    -0.24737,0.58613
728.47498, 84.09000,    -2.72996,79.11268,50.00000,0.0000e+000,20.00000,    -0.23648,0.58535
730.26898, 84.27000,    -2.73808,79.05908,50.00000,0.0000e+000,20.00000,    -0.22744,0.58458
732.06598, 84.45000,    -2.75166,79.01529,50.00000,0.0000e+000,20.00000,    -0.21820,0.58382
733.88202, 84.63000,    -2.76864,78.98148,50.00000,0.0000e+000,20.00000,    -0.20653,0.58305
735.72601, 84.81000,    -2.78745,78.95011,50.00000,0.0000e+000,20.00000,    -0.19322,0.58227
737.57098, 84.99000,    -2.79913,78.92480,50.00000,0.0000e+000,20.00000,    -0.18085,0.58149
739.40698, 85.17000,    -2.80245,78.90117,50.00000,0.0000e+000,20.00000,    -0.17078,0.58072
741.22400, 85.35000,    -2.80660,78.87299,50.00000,0.0000e+000,20.00000,    -0.16363,0.57996
743.03601, 85.53000,    -2.80817,78.85035,50.00000,0.0000e+000,20.00000,    -0.15475,0.57920
744.83801, 85.71000,    -2.80071,78.83194,50.00000,0.0000e+000,20.00000,    -0.14468,0.57845
746.60498, 85.89000,    -2.79521,78.81146,50.00000,0.0000e+000,20.00000,    -0.13389,0.57772
748.38599, 86.07000,    -2.79382,78.79758,50.00000,0.0000e+000,20.00000,    -0.12216,0.57699
750.16998, 86.25000,    -2.79742,78.77847,50.00000,0.0000e+000,20.00000,    -0.11394,0.57625
751.98999, 86.43000,    -2.79938,78.75623,50.00000,0.0000e+000,20.00000,    -0.10959,0.57551
753.77197, 86.61000,    -2.79889,78.74174,50.00000,0.0000e+000,20.00000,    -0.10516,0.57478
755.58301, 86.79000,    -2.80196,78.72724,50.00000,0.0000e+000,20.00000,    -0.10053,0.57404
757.38300, 86.97000,    -2.80650,78.70962,50.00000,0.0000e+000,20.00000,-9.8845e-002,0.57331
759.20502, 87.15000,    -2.81069,78.69135,50.00000,0.0000e+000,20.00000,-9.6901e-002,0.57257
761.02502, 87.33000,    -2.81885,78.67101,50.00000,0.0000e+000,20.00000,-9.3543e-002,0.57184
762.80298, 87.51000,    -2.80969,78.64979,50.00000,0.0000e+000,20.00000,-9.0948e-002,0.57112
764.57898, 87.69000,    -2.80195,78.63357,50.00000,0.0000e+000,20.00000,-8.8044e-002,0.57041
766.35699, 87.87000,    -2.80003,78.62225,50.00000,0.0000e+000,20.00000,-8.9148e-002,0.56970
768.15302, 88.05000,    -2.80485,78.60744,50.00000,0.0000e+000,20.00000,-9.0308e-002,0.56898
769.95502, 88.23000,    -2.81194,78.58875,50.00000,0.0000e+000,20.00000,-8.7814e-002,0.56827
771.77502, 88.41000,    -2.82099,78.57210,50.00000,0.0000e+000,20.00000,-8.5457e-002,0.56754
773.57098, 88.59000,    -2.82314,78.56237,50.00000,0.0000e+000,20.00000,-8.6139e-002,0.56683
775.37701, 88.77000,    -2.82267,78.54722,50.00000,0.0000e+000,20.00000,-8.5383e-002,0.56612
777.15601, 88.95000,    -2.81946,78.52564,50.00000,0.0000e+000,20.00000,-8.4009e-002,0.56542
778.96100, 89.13000,    -2.82321,78.51277,50.00000,0.0000e+000,20.00000,-8.1955e-002,0.56472
780.77600, 89.31000,    -2.82833,78.50390,50.00000,0.0000e+000,20.00000,-7.9110e-002,0.56401
782.60602, 89.49000,    -2.84425,78.49438,50.00000,0.0000e+000,20.00000,-7.8525e-002,0.56329
784.44397, 89.67000,    -2.85185,78.47724,50.00000,0.0000e+000,20.00000,-8.0078e-002,0.56258
786.27100, 89.85000,    -2.85284,78.45492,50.00000,0.0000e+000,20.00000,-7.9938e-002,0.56187
788.06897, 90.03000,    -2.84808,78.43946,50.00000,0.0000e+000,20.00000,-7.7086e-002,0.56118
789.85602, 90.21000,    -2.84586,78.43288,50.00000,0.0000e+000,20.00000,-7.4664e-002,0.56049
791.66101, 90.39000,    -2.84903,78.41771,50.00000,0.0000e+000,20.00000,-7.6927e-002,0.55980
793.46100, 90.57000,    -2.85150,78.40216,50.00000,0.0000e+000,20.00000,-7.8757e-002,0.55911
795.26898, 90.75000,    -2.85648,78.38925,50.00000,0.0000e+000,20.00000,-7.4837e-002,0.55841
797.07300, 90.93000,    -2.86358,78.37645,50.00000,0.0000e+000,20.00000,-7.3670e-002,0.55773
798.88202, 91.11000,    -2.86997,78.36550,50.00000,0.0000e+000,20.00000,-7.6823e-002,0.55704
800.69098, 91.29000,    -2.87438,78.35131,50.00000,0.0000e+000,20.00000,-7.8169e-002,0.55635
802.48700, 91.47000,    -2.87553,78.33370,50.00000,0.0000e+000,20.00000,-7.7710e-002,0.55567
804.27399, 91.65000,    -2.87411,78.31962,50.00000,0.0000e+000,20.00000,-7.5496e-002,0.55500
806.04999, 91.83000,    -2.87603,78.31090,50.00000,0.0000e+000,20.00000,-7.4501e-002,0.55433
807.83698, 92.01000,    -2.88257,78.30312,50.00000,0.0000e+000,20.00000,-7.6209e-002,0.55366
809.62402, 92.19000,    -2.88808,78.28606,50.00000,0.0000e+000,20.00000,-7.7457e-002,0.55299
811.42401, 92.37000,    -2.89324,78.26475,50.00000,0.0000e+000,20.00000,-7.7513e-002,0.55231
813.20801, 92.55000,    -2.89815,78.25573,50.00000,0.0000e+000,20.00000,-7.9210e-002,0.55165
815.06897, 92.73000,    -2.92294,78.24747,50.00000,0.0000e+000,20.00000,-8.0757e-002,0.55096
816.96899, 92.91000,    -2.94404,78.22749,50.00000,0.0000e+000,20.00000,-8.2303e-002,0.55025
818.82800, 93.09000,    -2.94948,78.21210,50.00000,0.0000e+000,20.00000,-8.3305e-002,0.54956
820.66803, 93.27000,    -2.94701,78.19889,50.00000,0.0000e+000,20.00000,-8.2130e-002,0.54888
822.47699, 93.45000,    -2.93807,78.18420,50.00000,0.0000e+000,20.00000,-8.3372e-002,0.54821
824.24902, 93.63000,    -2.92930,78.17075,50.00000,0.0000e+000,20.00000,-8.6968e-002,0.54756
826.02301, 93.81000,    -2.92184,78.15782,50.00000,0.0000e+000,20.00000,-9.1849e-002,0.54691
827.80798, 93.99000,    -2.92506,78.14027,50.00000,0.0000e+000,20.00000,-9.2721e-002,0.54625
829.62402, 94.17000,    -2.93668,78.12332,50.00000,0.0000e+000,20.00000,-9.2312e-002,0.54559
831.41699, 94.35000,    -2.93400,78.10494,50.00000,0.0000e+000,20.00000,-9.4859e-002,0.54493
833.18799, 94.53000,    -2.92625,78.08564,50.00000,0.0000e+000,20.00000,-9.9420e-002,0.54429
834.92700, 94.71000,    -2.92413,78.06912,50.00000,0.0000e+000,20.00000,    -0.10111,0.54366
836.73297, 94.89000,    -2.92975,78.05165,50.00000,0.0000e+000,20.00000,    -0.10349,0.54300
838.50702, 95.07000,    -2.93560,78.03827,50.00000,0.0000e+000,20.00000,    -0.10699,0.54236
840.32800, 95.25000,    -2.94244,78.02010,50.00000,0.0000e+000,20.00000,    -0.11062,0.54170
842.14398, 95.43000,    -2.94731,77.99779,50.00000,0.0000e+000,20.00000,    -0.11570,0.54104
843.94702, 95.61000,    -2.95165,77.97241,50.00000,0.0000e+000,20.00000,    -0.11894,0.54039
845.77698, 95.79000,    -2.95947,77.95325,50.00000,0.0000e+000,20.00000,    -0.12211,0.53973
847.58899, 95.97000,    -2.96337,77.93327,50.00000,0.0000e+000,20.00000,    -0.12552,0.53908
849.41602, 96.15000,    -2.96412,77.91284,50.00000,0.0000e+000,20.00000,    -0.12908,0.53843
851.21399, 96.33000,    -2.96208,77.89012,50.00000,0.0000e+000,20.00000,    -0.13206,0.53778
853.03198, 96.51000,    -2.96421,77.86487,50.00000,0.0000e+000,20.00000,    -0.13668,0.53713
854.84497, 96.69000,    -2.96623,77.83959,50.00000,0.0000e+000,20.00000,    -0.13820,0.53648
856.65503, 96.87000,    -2.96966,77.81411,50.00000,0.0000e+000,20.00000,    -0.14167,0.53584
858.47198, 97.05000,    -2.97221,77.78665,50.00000,0.0000e+000,20.00000,    -0.14752,0.53519
860.26801, 97.23000,    -2.97113,77.75444,50.00000,0.0000e+000,20.00000,    -0.15033,0.53455
862.10101, 97.41000,    -2.97953,77.72887,50.00000,0.0000e+000,20.00000,    -0.15207,0.53390
863.93500, 97.59000,    -2.98463,77.70156,50.00000,0.0000e+000,20.00000,    -0.15696,0.53325
865.73999, 97.77000,    -2.98399,77.67143,50.00000,0.0000e+000,20.00000,    -0.15986,0.53261
867.53400, 97.95000,    -2.98161,77.64110,50.00000,0.0000e+000,20.00000,    -0.16086,0.53198
869.32501, 98.13000,    -2.98003,77.61040,50.00000,0.0000e+000,20.00000,    -0.16644,0.53135
871.10303, 98.31000,    -2.97941,77.57705,50.00000,0.0000e+000,20.00000,    -0.16814,0.53072
872.88397, 98.49000,    -2.97878,77.55188,50.00000,0.0000e+000,20.00000,    -0.16985,0.53009
874.70599, 98.67000,    -2.98535,77.52773,50.00000,0.0000e+000,20.00000,    -0.17393,0.52945
876.50299, 98.85000,    -2.98810,77.48990,50.00000,0.0000e+000,20.00000,    -0.17649,0.52882
878.30798, 99.03000,    -2.99542,77.45644,50.00000,0.0000e+000,20.00000,    -0.17692,0.52819
880.17102, 99.21000,    -3.01086,77.42559,50.00000,0.0000e+000,20.00000,    -0.17804,0.52753
881.99799, 99.39000,    -3.01365,77.38809,50.00000,0.0000e+000,20.00000,    -0.18077,0.52689
883.80603, 99.57000,    -3.00911,77.35570,50.00000,0.0000e+000,20.00000,    -0.18369,0.52626
885.57501, 99.75000,    -3.00424,77.33286,50.00000,0.0000e+000,20.00000,    -0.18558,0.52564
887.38000, 99.93000,    -3.00294,77.29224,50.00000,0.0000e+000,20.00000,    -0.18877,0.52501
889.19202,100.11000,    -3.01210,77.25785,50.00000,0.0000e+000,20.00000,    -0.19078,0.52438
891.01501,100.29000,    -3.01638,77.22864,50.00000,0.0000e+000,20.00000,    -0.19305,0.52374
892.81403,100.47000,    -3.01546,77.18821,50.00000,0.0000e+000,20.00000,    -0.19909,0.52312
894.61700,100.65000,    -3.01386,77.15148,50.00000,0.0000e+000,20.00000,    -0.20081,0.52249
896.41400,100.83000,    -3.01311,77.11749,50.00000,0.0000e+000,20.00000,    -0.20140,0.52187
898.20300,101.01000,    -3.01379,77.08652,50.00000,0.0000e+000,20.00000,    -0.20448,0.52124
900.00098,101.19000,    -3.01547,77.05158,50.00000,0.0000e+000,20.00000,    -0.20774,0.52062
901.80200,101.37000,    -3.01987,77.01050,50.00000,0.0000e+000,20.00000,    -0.21017,0.52000
903.57703,101.55000,    -3.01634,76.97337,50.00000,0.0000e+000,20.00000,    -0.21544,0.51938
905.36200,101.73000,    -3.01673,76.93194,50.00000,0.0000e+000,20.00000,    -0.21852,0.51876
907.15100,101.91000,    -3.01643,76.89039,50.00000,0.0000e+000,20.00000,    -0.21768,0.51814
908.94598,102.09000,    -3.02088,76.85510,50.00000,0.0000e+000,20.00000,    -0.21956,0.51752
910.77899,102.27000,    -3.03705,76.81208,50.00000,0.0000e+000,20.00000,    -0.22180,0.51689
912.62500,102.45000,    -3.04472,76.76767,50.00000,0.0000e+000,20.00000,    -0.22321,0.51625
914.42902,102.63000,    -3.04247,76.73075,50.00000,0.0000e+000,20.00000,    -0.22435,0.51563
916.23798,102.81000,    -3.04160,76.69015,50.00000,0.0000e+000,20.00000,    -0.22638,0.51500
918.03699,102.99000,    -3.04036,76.64230,50.00000,0.0000e+000,20.00000,    -0.22757,0.51438
919.84497,103.17000,    -3.04273,76.59728,50.00000,0.0000e+000,20.00000,    -0.22790,0.51376
921.65503,103.35000,    -3.04899,76.55696,50.00000,0.0000e+000,20.00000,    -0.22932,0.51313
923.46600,103.53000,    -3.04896,76.50717,50.00000,0.0000e+000,20.00000,    -0.22838,0.51251
925.27197,103.71000,    -3.04828,76.47081,50.00000,0.0000e+000,20.00000,    -0.22379,0.51188
927.10303,103.89000,    -3.05841,76.43784,50.00000,0.0000e+000,20.00000,    -0.22181,0.51125
928.95300,104.07000,    -3.06253,76.39123,50.00000,0.0000e+000,20.00000,    -0.21837,0.51062
930.74799,104.25000,    -3.06129,76.34679,50.00000,0.0000e+000,20.00000,    -0.21423,0.51000
932.56403,104.43000,    -3.05771,76.30861,50.00000,0.0000e+000,20.00000,    -0.21199,0.50937
934.34399,104.61000,    -3.04704,76.26948,50.00000,0.0000e+000,20.00000,    -0.20742,0.50876
936.11200,104.79000,    -3.04418,76.23179,50.00000,0.0000e+000,20.00000,    -0.20083,0.50815
937.92603,104.97000,    -3.05146,76.19029,50.00000,0.0000e+000,20.00000,    -0.19396,0.50753
939.74701,105.15000,    -3.05518,76.14722,50.00000,0.0000e+000,20.00000,    -0.18675,0.50690
941.54797,105.33000,    -3.05403,76.10865,50.00000,0.0000e+000,20.00000,    -0.17746,0.50628
943.35400,105.51000,    -3.05324,76.08216,50.00000,0.0000e+000,20.00000,    -0.17113,0.50566
945.16998,105.69000,    -3.05532,76.05431,50.00000,0.0000e+000,20.00000,    -0.16736,0.50503
947.00702,105.87000,    -3.05895,76.02563,50.00000,0.0000e+000,20.00000,    -0.15796,0.50440
948.81000,106.05000,    -3.05184,75.99548,50.00000,0.0000e+000,20.00000,    -0.14886,0.50378
950.59998,106.23000,    -3.04493,75.96570,50.00000,0.0000e+000,20.00000,    -0.14203,0.50316
952.40802,106.41000,    -3.04423,75.94194,50.00000,0.0000e+000,20.00000,    -0.13479,0.50254
954.25598,106.59000,    -3.04935,75.91952,50.00000,0.0000e+000,20.00000,    -0.12799,0.50190
956.15802,106.77000,    -3.06865,75.89715,50.00000,0.0000e+000,20.00000,    -0.11991,0.50125
958.00897,106.95000,    -3.06656,75.88317,50.00000,0.0000e+000,20.00000,    -0.11103,0.50061
959.81500,107.13000,    -3.05112,75.86838,50.00000,0.0000e+000,20.00000,    -0.10389,0.49999
961.58801,107.31000,    -3.03796,75.85250,50.00000,0.0000e+000,20.00000,    -0.10067,0.49938
963.35797,107.49000,    -3.02825,75.83445,50.00000,0.0000e+000,20.00000,-9.6259e-002,0.49877
965.12903,107.67000,    -3.02177,75.82287,50.00000,0.0000e+000,20.00000,-9.0517e-002,0.49816
966.92700,107.85000,    -3.02706,75.81098,50.00000,0.0000e+000,20.00000,-8.4310e-002,0.49754
968.71899,108.03000,    -3.02646,75.79741,50.00000,0.0000e+000,20.00000,-7.8279e-002,0.49692
970.50000,108.21000,    -3.02496,75.78457,50.00000,0.0000e+000,20.00000,-7.3032e-002,0.49630
972.27600,108.39000,    -3.02422,75.77190,50.00000,0.0000e+000,20.00000,-6.8440e-002,0.49569
974.03400,108.57000,    -3.02048,75.76009,50.00000,0.0000e+000,20.00000,-6.4873e-002,0.49508
975.84399,108.75000,    -3.02998,75.74974,50.00000,0.0000e+000,20.00000,-6.4509e-002,0.49446
977.64600,108.93000,    -3.03385,75.73647,50.00000,0.0000e+000,20.00000,-6.2123e-002,0.49383
979.45697,109.11000,    -3.03745,75.72013,50.00000,0.0000e+000,20.00000,-5.8700e-002,0.49321
981.25098,109.29000,    -3.03764,75.70846,50.00000,0.0000e+000,20.00000,-5.5058e-002,0.49259
983.03998,109.47000,    -3.03689,75.70010,50.00000,0.0000e+000,20.00000,-5.3847e-002,0.49197
984.81299,109.65000,    -3.03405,75.69339,50.00000,0.0000e+000,20.00000,-5.1557e-002,0.49135
986.57703,109.83000,    -3.03068,75.68490,50.00000,0.0000e+000,20.00000,-4.9553e-002,0.49074
988.35199,110.01000,    -3.03186,75.67908,50.00000,0.0000e+000,20.00000,-4.5063e-002,0.49012
990.16803,110.19000,    -3.04206,75.67392,50.00000,0.0000e+000,20.00000,-3.9807e-002,0.48949
991.97101,110.37000,    -3.04994,75.66504,50.00000,0.0000e+000,20.00000,-3.9543e-002,0.48887
993.78802,110.55000,    -3.05497,75.65100,50.00000,0.0000e+000,20.00000,-4.1334e-002,0.48824
995.61298,110.73000,    -3.06242,75.64415,50.00000,0.0000e+000,20.00000,-3.5338e-002,0.48760
997.43201,110.91000,    -3.06645,75.64133,50.00000,0.0000e+000,20.00000,-2.1450e-002,0.48697
998.34698,111.00000,    -3.06773,75.63907,50.00000,0.0000e+000,20.00000, 6.7617e-003,0.48665