File: book/some_content/DG_ExpDat_MgO5%DC7; 23-1-2025-2.csv
#FILE:                       ,MgO5%DC7; 23-1-2025.ngb-ds3
#FORMAT:                     ,NETZSCH5
#IDENTITY:                   ,GEOPOLMER PASTE
#DECIMAL:                    ,POINT
#SEPARATOR:                  ,COMMA
#MTYPE:                      ,DSC
#INSTRUMENT:                 ,Microlab TU Delft
#PROJECT:                    ,
#DATE/TIME:                  ,25/01/2025 10:21:53 AM
#CORR. FILE:                 ,Blank with cover; 13-1-2025.ngb-bs3
#LABORATORY:                 ,TU Delft Micro Lab
#OPERATOR:                   ,Ahmed
#REMARK:                     ,under Argon atmosphere, 10K/min
#SAMPLE:                     ,MgODC7
#SAMPLE MASS /mg:            ,41.2
#MATERIAL:                   ,Geopolymer paste
#REFERENCE:                  ,blank
#REFERENCE MASS /mg:         ,0
#TYPE OF CRUCIBLE:           ,DSC/TG pan Al2O3
#SAMPLE CRUCIBLE MASS /mg:   ,0
#REFERENCE CRUCIBLE MASS /mg:,0
#CORR. CODE:                 ,020
#EXO:                        ,-1
#RANGE:                      ,40/10.0(K/min)/1000
#SEGMENT:                    ,S2/2

##Temp./øC,Time/min,DSC/(mW/mg),Mass/%,Gas Flow(purge1)/(ml/min),Gas Flow(purge2)/(ml/min),Gas Flow(protective)/(ml/min),DTG/(%/min),Sensit./(uV/mW)
 40.91400, 15.01500, 4.1246e-002,98.19007,50.00000,0.0000e+000,20.00000,    -0.12823,1.22568
 40.96300, 15.19500, 4.0885e-002,98.17153,50.00000,0.0000e+000,20.00000,    -0.10511,1.22561
 41.01800, 15.37500, 4.0238e-002,98.15267,50.00000,0.0000e+000,20.00000,    -0.10680,1.22554
 41.10100, 15.55500, 4.0060e-002,98.13325,50.00000,0.0000e+000,20.00000,    -0.10676,1.22542
 41.20900, 15.73500, 3.9431e-002,98.11360,50.00000,0.0000e+000,20.00000,    -0.10898,1.22528
 41.41800, 15.91500, 3.9546e-002,98.09454,50.00000,0.0000e+000,20.00000,    -0.10948,1.22499
 41.64700, 16.09500, 3.9979e-002,98.07522,50.00000,0.0000e+000,20.00000,    -0.10834,1.22467
 41.96100, 16.27500, 4.0780e-002,98.05444,50.00000,0.0000e+000,20.00000,    -0.10965,1.22424
 42.36600, 16.45500, 4.2145e-002,98.03357,50.00000,0.0000e+000,20.00000,    -0.11128,1.22368
 42.83200, 16.63500, 4.3606e-002,98.01338,50.00000,0.0000e+000,20.00000,    -0.11304,1.22304
 43.37400, 16.81500, 4.6026e-002,97.99338,50.00000,0.0000e+000,20.00000,    -0.11541,1.22229
 44.00500, 16.99500, 4.8318e-002,97.97467,50.00000,0.0000e+000,20.00000,    -0.11867,1.22142
 44.70400, 17.17500, 5.0875e-002,97.95641,50.00000,0.0000e+000,20.00000,    -0.12258,1.22046
 45.50700, 17.35500, 5.4004e-002,97.93650,50.00000,0.0000e+000,20.00000,    -0.12698,1.21935
 46.36500, 17.53500, 5.7325e-002,97.91425,50.00000,0.0000e+000,20.00000,    -0.13205,1.21817
 47.31200, 17.71500, 6.0825e-002,97.89218,50.00000,0.0000e+000,20.00000,    -0.13799,1.21686
 48.37400, 17.89500, 6.4312e-002,97.87006,50.00000,0.0000e+000,20.00000,    -0.14459,1.21540
 49.48800, 18.07500, 6.8146e-002,97.84775,50.00000,0.0000e+000,20.00000,    -0.15158,1.21387
 50.69000, 18.25500, 7.2119e-002,97.82434,50.00000,0.0000e+000,20.00000,    -0.16022,1.21221
 51.95800, 18.43500, 7.6384e-002,97.80057,50.00000,0.0000e+000,20.00000,    -0.17105,1.21046
 53.31500, 18.61500, 8.0746e-002,97.77524,50.00000,0.0000e+000,20.00000,    -0.18368,1.20860
 54.74000, 18.79500, 8.4990e-002,97.74555,50.00000,0.0000e+000,20.00000,    -0.19806,1.20664
 56.26000, 18.97500, 8.9858e-002,97.71272,50.00000,0.0000e+000,20.00000,    -0.21475,1.20454
 57.83500, 19.15500, 9.4809e-002,97.67774,50.00000,0.0000e+000,20.00000,    -0.23406,1.20238
 59.50400, 19.33500,     0.10025,97.63996,50.00000,0.0000e+000,20.00000,    -0.25401,1.20008
 61.23300, 19.51500,     0.10575,97.59950,50.00000,0.0000e+000,20.00000,    -0.27456,1.19771
 63.02200, 19.69500,     0.11161,97.55653,50.00000,0.0000e+000,20.00000,    -0.29636,1.19525
 64.87400, 19.87500,     0.11781,97.51104,50.00000,0.0000e+000,20.00000,    -0.32002,1.19271
 66.81000, 20.05500,     0.12473,97.45962,50.00000,0.0000e+000,20.00000,    -0.34532,1.19005
 68.79100, 20.23500,     0.13208,97.40085,50.00000,0.0000e+000,20.00000,    -0.37157,1.18733
 70.82700, 20.41500,     0.13995,97.33555,50.00000,0.0000e+000,20.00000,    -0.40119,1.18454
 72.90000, 20.59500,     0.14815,97.26479,50.00000,0.0000e+000,20.00000,    -0.43019,1.18170
 75.01700, 20.77500,     0.15770,97.18722,50.00000,0.0000e+000,20.00000,    -0.45732,1.17880
 77.18000, 20.95500,     0.16731,97.09853,50.00000,0.0000e+000,20.00000,    -0.48435,1.17584
 79.38300, 21.13500,     0.17788,97.00390,50.00000,0.0000e+000,20.00000,    -0.51145,1.17283
 81.64200, 21.31500,     0.18883,96.90710,50.00000,0.0000e+000,20.00000,    -0.53682,1.16975
 83.93600, 21.49500,     0.20049,96.80621,50.00000,0.0000e+000,20.00000,    -0.56201,1.16661
 86.26300, 21.67500,     0.21255,96.69870,50.00000,0.0000e+000,20.00000,    -0.58571,1.16344
 88.62200, 21.85500,     0.22404,96.58377,50.00000,0.0000e+000,20.00000,    -0.60717,1.16023
 90.98500, 22.03500,     0.23574,96.46491,50.00000,0.0000e+000,20.00000,    -0.62693,1.15701
 93.40000, 22.21500,     0.24589,96.33434,50.00000,0.0000e+000,20.00000,    -0.64295,1.15373
 95.83500, 22.39500,     0.25512,96.19775,50.00000,0.0000e+000,20.00000,    -0.65614,1.15042
 98.28400, 22.57500,     0.26336,96.06700,50.00000,0.0000e+000,20.00000,    -0.67027,1.14710
100.72100, 22.75500,     0.26956,95.93315,50.00000,0.0000e+000,20.00000,    -0.67829,1.14380
103.17900, 22.93500,     0.27472,95.79765,50.00000,0.0000e+000,20.00000,    -0.68309,1.14047
105.61900, 23.11500,     0.27807,95.66369,50.00000,0.0000e+000,20.00000,    -0.68724,1.13717
108.12100, 23.29500,     0.28024,95.53002,50.00000,0.0000e+000,20.00000,    -0.68963,1.13379
110.57100, 23.47500,     0.28056,95.39697,50.00000,0.0000e+000,20.00000,    -0.68994,1.13049
113.01600, 23.65500,     0.27964,95.26869,50.00000,0.0000e+000,20.00000,    -0.68737,1.12720
115.49600, 23.83500,     0.27691,95.13844,50.00000,0.0000e+000,20.00000,    -0.68288,1.12386
117.97000, 24.01500,     0.27299,95.01393,50.00000,0.0000e+000,20.00000,    -0.67544,1.12054
120.42900, 24.19500,     0.26781,94.89643,50.00000,0.0000e+000,20.00000,    -0.66397,1.11725
122.87300, 24.37500,     0.26117,94.76927,50.00000,0.0000e+000,20.00000,    -0.65372,1.11398
125.33400, 24.55500,     0.25407,94.65043,50.00000,0.0000e+000,20.00000,    -0.64130,1.11069
127.77400, 24.73500,     0.24562,94.53905,50.00000,0.0000e+000,20.00000,    -0.62805,1.10743
130.22000, 24.91500,     0.23662,94.42698,50.00000,0.0000e+000,20.00000,    -0.61437,1.10417
132.66400, 25.09500,     0.22708,94.31797,50.00000,0.0000e+000,20.00000,    -0.60178,1.10092
135.07899, 25.27500,     0.21704,94.21017,50.00000,0.0000e+000,20.00000,    -0.58865,1.09771
137.47701, 25.45500,     0.20668,94.10504,50.00000,0.0000e+000,20.00000,    -0.57599,1.09454
139.87700, 25.63500,     0.19574,94.00301,50.00000,0.0000e+000,20.00000,    -0.56074,1.09136
142.24001, 25.81500,     0.18454,93.90182,50.00000,0.0000e+000,20.00000,    -0.54649,1.08824
144.61301, 25.99500,     0.17344,93.80536,50.00000,0.0000e+000,20.00000,    -0.53433,1.08511
146.95700, 26.17500,     0.16205,93.71210,50.00000,0.0000e+000,20.00000,    -0.51856,1.08202
149.27100, 26.35500,     0.15098,93.62267,50.00000,0.0000e+000,20.00000,    -0.50210,1.07898
151.56799, 26.53500,     0.13965,93.53636,50.00000,0.0000e+000,20.00000,    -0.48855,1.07597
153.85400, 26.71500,     0.12861,93.45112,50.00000,0.0000e+000,20.00000,    -0.47492,1.07298
156.11000, 26.89500,     0.11775,93.36472,50.00000,0.0000e+000,20.00000,    -0.46148,1.07003
158.34000, 27.07500,     0.10717,93.27815,50.00000,0.0000e+000,20.00000,    -0.44729,1.06712
160.56400, 27.25500, 9.6607e-002,93.19519,50.00000,0.0000e+000,20.00000,    -0.43420,1.06422
162.74500, 27.43500, 8.5542e-002,93.11998,50.00000,0.0000e+000,20.00000,    -0.42144,1.06139
164.89900, 27.61500, 7.4240e-002,93.04604,50.00000,0.0000e+000,20.00000,    -0.40726,1.05860
167.03600, 27.79500, 6.2298e-002,92.97280,50.00000,0.0000e+000,20.00000,    -0.39268,1.05583
169.16299, 27.97500, 5.0063e-002,92.90347,50.00000,0.0000e+000,20.00000,    -0.37904,1.05308
171.25700, 28.15500, 3.7886e-002,92.84159,50.00000,0.0000e+000,20.00000,    -0.36683,1.05038
173.35300, 28.33500, 2.5894e-002,92.78017,50.00000,0.0000e+000,20.00000,    -0.35511,1.04768
175.40800, 28.51500, 1.4140e-002,92.71757,50.00000,0.0000e+000,20.00000,    -0.34275,1.04504
177.46300, 28.69500, 2.7002e-003,92.65668,50.00000,0.0000e+000,20.00000,    -0.32988,1.04241
179.47099, 28.87500,-8.3700e-003,92.60029,50.00000,0.0000e+000,20.00000,    -0.31726,1.03984
181.47800, 29.05500,-1.9316e-002,92.54274,50.00000,0.0000e+000,20.00000,    -0.30567,1.03727
183.47900, 29.23500,-3.0174e-002,92.48631,50.00000,0.0000e+000,20.00000,    -0.29530,1.03472
185.45200, 29.41500,-4.0634e-002,92.43567,50.00000,0.0000e+000,20.00000,    -0.28486,1.03221
187.42500, 29.59500,-5.0840e-002,92.39110,50.00000,0.0000e+000,20.00000,    -0.27400,1.02971
189.36099, 29.77500,-6.0876e-002,92.34763,50.00000,0.0000e+000,20.00000,    -0.26348,1.02725
191.30600, 29.95500,-7.0943e-002,92.30221,50.00000,0.0000e+000,20.00000,    -0.25478,1.02479
193.21899, 30.13500,-8.0420e-002,92.25797,50.00000,0.0000e+000,20.00000,    -0.24635,1.02238
195.11700, 30.31500,-9.0049e-002,92.21736,50.00000,0.0000e+000,20.00000,    -0.23736,1.01998
196.99400, 30.49500,-9.9120e-002,92.17833,50.00000,0.0000e+000,20.00000,    -0.22814,1.01762
198.86400, 30.67500,    -0.10854,92.13811,50.00000,0.0000e+000,20.00000,    -0.21981,1.01528
200.72501, 30.85500,    -0.11773,92.09626,50.00000,0.0000e+000,20.00000,    -0.21131,1.01295
202.56000, 31.03500,    -0.12698,92.05758,50.00000,0.0000e+000,20.00000,    -0.20284,1.01065
204.40601, 31.21500,    -0.13590,92.02150,50.00000,0.0000e+000,20.00000,    -0.19512,1.00835
206.22400, 31.39500,    -0.14462,91.98745,50.00000,0.0000e+000,20.00000,    -0.18887,1.00609
208.03400, 31.57500,    -0.15392,91.95530,50.00000,0.0000e+000,20.00000,    -0.18345,1.00384
209.82899, 31.75500,    -0.16240,91.92432,50.00000,0.0000e+000,20.00000,    -0.17745,1.00161
211.61900, 31.93500,    -0.17101,91.89382,50.00000,0.0000e+000,20.00000,    -0.17124,0.99940
213.42599, 32.11500,    -0.17941,91.86408,50.00000,0.0000e+000,20.00000,    -0.16567,0.99716
215.21899, 32.29500,    -0.18778,91.83590,50.00000,0.0000e+000,20.00000,    -0.16055,0.99495
216.97600, 32.47500,    -0.19557,91.80943,50.00000,0.0000e+000,20.00000,    -0.15484,0.99279
218.73199, 32.65500,    -0.20310,91.78333,50.00000,0.0000e+000,20.00000,    -0.14862,0.99064
220.48900, 32.83500,    -0.21132,91.75708,50.00000,0.0000e+000,20.00000,    -0.14358,0.98849
222.25301, 33.01500,    -0.21878,91.73324,50.00000,0.0000e+000,20.00000,    -0.13944,0.98633
224.01199, 33.19500,    -0.22633,91.71083,50.00000,0.0000e+000,20.00000,    -0.13626,0.98418
225.75301, 33.37500,    -0.23402,91.68753,50.00000,0.0000e+000,20.00000,    -0.13324,0.98206
227.48399, 33.55500,    -0.24127,91.66408,50.00000,0.0000e+000,20.00000,    -0.12991,0.97996
229.22000, 33.73500,    -0.24844,91.64189,50.00000,0.0000e+000,20.00000,    -0.12660,0.97786
230.97900, 33.91500,    -0.25543,91.62102,50.00000,0.0000e+000,20.00000,    -0.12352,0.97573
232.70500, 34.09500,    -0.26283,91.60051,50.00000,0.0000e+000,20.00000,    -0.12094,0.97365
234.43900, 34.27500,    -0.26991,91.58136,50.00000,0.0000e+000,20.00000,    -0.11859,0.97156
236.15100, 34.45500,    -0.27713,91.56233,50.00000,0.0000e+000,20.00000,    -0.11680,0.96950
237.88400, 34.63500,    -0.28391,91.54175,50.00000,0.0000e+000,20.00000,    -0.11491,0.96743
239.61400, 34.81500,    -0.29096,91.52053,50.00000,0.0000e+000,20.00000,    -0.11364,0.96536
241.32401, 34.99500,    -0.29769,91.49802,50.00000,0.0000e+000,20.00000,    -0.11264,0.96331
243.05200, 35.17500,    -0.30432,91.47618,50.00000,0.0000e+000,20.00000,    -0.11087,0.96126
244.77400, 35.35500,    -0.31101,91.45705,50.00000,0.0000e+000,20.00000,    -0.10899,0.95921
246.48801, 35.53500,    -0.31744,91.43849,50.00000,0.0000e+000,20.00000,    -0.10741,0.95718
248.23000, 35.71500,    -0.32392,91.42001,50.00000,0.0000e+000,20.00000,    -0.10644,0.95512
249.95399, 35.89500,    -0.33069,91.40087,50.00000,0.0000e+000,20.00000,    -0.10550,0.95308
251.66299, 36.07500,    -0.33704,91.38279,50.00000,0.0000e+000,20.00000,    -0.10470,0.95107
253.39799, 36.25500,    -0.34395,91.36349,50.00000,0.0000e+000,20.00000,    -0.10400,0.94903
255.11700, 36.43500,    -0.35072,91.34395,50.00000,0.0000e+000,20.00000,    -0.10280,0.94702
256.84399, 36.61500,    -0.35805,91.32438,50.00000,0.0000e+000,20.00000,    -0.10127,0.94500
258.57999, 36.79500,    -0.36544,91.30529,50.00000,0.0000e+000,20.00000,-9.9639e-002,0.94297
260.30600, 36.97500,    -0.37334,91.28843,50.00000,0.0000e+000,20.00000,-9.7753e-002,0.94097
262.04401, 37.15500,    -0.38063,91.27180,50.00000,0.0000e+000,20.00000,-9.6796e-002,0.93895
263.77200, 37.33500,    -0.38852,91.25516,50.00000,0.0000e+000,20.00000,-9.6024e-002,0.93695
265.51700, 37.51500,    -0.39627,91.23789,50.00000,0.0000e+000,20.00000,-9.5165e-002,0.93493
267.24701, 37.69500,    -0.40429,91.22051,50.00000,0.0000e+000,20.00000,-9.4263e-002,0.93294
268.99600, 37.87500,    -0.41222,91.20406,50.00000,0.0000e+000,20.00000,-9.3217e-002,0.93093
270.72900, 38.05500,    -0.41996,91.18769,50.00000,0.0000e+000,20.00000,-9.1948e-002,0.92894
272.45599, 38.23500,    -0.42783,91.17162,50.00000,0.0000e+000,20.00000,-9.0952e-002,0.92697
274.20801, 38.41500,    -0.43530,91.15610,50.00000,0.0000e+000,20.00000,-9.0469e-002,0.92497
275.95001, 38.59500,    -0.44299,91.13982,50.00000,0.0000e+000,20.00000,-9.0024e-002,0.92299
277.70499, 38.77500,    -0.45020,91.12434,50.00000,0.0000e+000,20.00000,-9.0139e-002,0.92099
279.43500, 38.95500,    -0.45717,91.10859,50.00000,0.0000e+000,20.00000,-9.0518e-002,0.91904
281.17700, 39.13500,    -0.46431,91.09268,50.00000,0.0000e+000,20.00000,-9.0651e-002,0.91707
282.91299, 39.31500,    -0.47064,91.07744,50.00000,0.0000e+000,20.00000,-9.0584e-002,0.91511
284.66901, 39.49500,    -0.47689,91.06160,50.00000,0.0000e+000,20.00000,-9.0758e-002,0.91314
286.40900, 39.67500,    -0.48360,91.04696,50.00000,0.0000e+000,20.00000,-9.1375e-002,0.91119
288.16000, 39.85500,    -0.49010,91.03275,50.00000,0.0000e+000,20.00000,-9.2298e-002,0.90924
289.91000, 40.03500,    -0.49676,91.01704,50.00000,0.0000e+000,20.00000,-9.3332e-002,0.90729
291.66501, 40.21500,    -0.50311,90.99951,50.00000,0.0000e+000,20.00000,-9.4482e-002,0.90534
293.42099, 40.39500,    -0.50948,90.98167,50.00000,0.0000e+000,20.00000,-9.5691e-002,0.90339
295.16101, 40.57500,    -0.51552,90.96422,50.00000,0.0000e+000,20.00000,-9.7506e-002,0.90147
296.93201, 40.75500,    -0.52185,90.94622,50.00000,0.0000e+000,20.00000,-9.9340e-002,0.89952
298.69800, 40.93500,    -0.52807,90.92892,50.00000,0.0000e+000,20.00000,    -0.10098,0.89758
300.44000, 41.11500,    -0.53395,90.91217,50.00000,0.0000e+000,20.00000,    -0.10311,0.89567
302.20099, 41.29500,    -0.54032,90.89418,50.00000,0.0000e+000,20.00000,    -0.10517,0.89374
303.96799, 41.47500,    -0.54595,90.87551,50.00000,0.0000e+000,20.00000,    -0.10755,0.89182
305.72101, 41.65500,    -0.55162,90.85592,50.00000,0.0000e+000,20.00000,    -0.11020,0.88991
307.50000, 41.83500,    -0.55661,90.83589,50.00000,0.0000e+000,20.00000,    -0.11295,0.88799
309.26300, 42.01500,    -0.56080,90.81623,50.00000,0.0000e+000,20.00000,    -0.11561,0.88608
311.01001, 42.19500,    -0.56530,90.79582,50.00000,0.0000e+000,20.00000,    -0.11786,0.88420
312.79300, 42.37500,    -0.56967,90.77371,50.00000,0.0000e+000,20.00000,    -0.12042,0.88229
314.56201, 42.55500,    -0.57422,90.75136,50.00000,0.0000e+000,20.00000,    -0.12297,0.88039
316.31900, 42.73500,    -0.57844,90.72935,50.00000,0.0000e+000,20.00000,    -0.12598,0.87851
318.08401, 42.91500,    -0.58306,90.70652,50.00000,0.0000e+000,20.00000,    -0.12950,0.87664
319.84698, 43.09500,    -0.58812,90.68317,50.00000,0.0000e+000,20.00000,    -0.13275,0.87476
321.62500, 43.27500,    -0.59227,90.65960,50.00000,0.0000e+000,20.00000,    -0.13554,0.87288
323.38599, 43.45500,    -0.59728,90.63589,50.00000,0.0000e+000,20.00000,    -0.13892,0.87102
325.15500, 43.63500,    -0.60205,90.61081,50.00000,0.0000e+000,20.00000,    -0.14326,0.86916
326.93399, 43.81500,    -0.60644,90.58375,50.00000,0.0000e+000,20.00000,    -0.14819,0.86730
328.70801, 43.99500,    -0.61099,90.55760,50.00000,0.0000e+000,20.00000,    -0.15357,0.86544
330.47400, 44.17500,    -0.61530,90.53092,50.00000,0.0000e+000,20.00000,    -0.15911,0.86360
332.25101, 44.35500,    -0.61924,90.50374,50.00000,0.0000e+000,20.00000,    -0.16491,0.86176
334.01700, 44.53500,    -0.62307,90.47551,50.00000,0.0000e+000,20.00000,    -0.17076,0.85993
335.81400, 44.71500,    -0.62626,90.44598,50.00000,0.0000e+000,20.00000,    -0.17754,0.85807
337.57401, 44.89500,    -0.62879,90.41628,50.00000,0.0000e+000,20.00000,    -0.18513,0.85626
339.34201, 45.07500,    -0.63112,90.38745,50.00000,0.0000e+000,20.00000,    -0.19169,0.85445
341.13300, 45.25500,    -0.63311,90.35647,50.00000,0.0000e+000,20.00000,    -0.19850,0.85261
342.89600, 45.43500,    -0.63471,90.32086,50.00000,0.0000e+000,20.00000,    -0.20743,0.85082
344.68100, 45.61500,    -0.63569,90.28353,50.00000,0.0000e+000,20.00000,    -0.21553,0.84900
346.46399, 45.79500,    -0.63668,90.24395,50.00000,0.0000e+000,20.00000,    -0.22376,0.84720
348.23401, 45.97500,    -0.63734,90.20222,50.00000,0.0000e+000,20.00000,    -0.23053,0.84541
350.01700, 46.15500,    -0.63828,90.15862,50.00000,0.0000e+000,20.00000,    -0.23865,0.84362
351.79901, 46.33500,    -0.63951,90.11538,50.00000,0.0000e+000,20.00000,    -0.24676,0.84183
353.57199, 46.51500,    -0.64037,90.06880,50.00000,0.0000e+000,20.00000,    -0.25313,0.84005
355.35699, 46.69500,    -0.64197,90.01782,50.00000,0.0000e+000,20.00000,    -0.25914,0.83828
357.14499, 46.87500,    -0.64380,89.96956,50.00000,0.0000e+000,20.00000,    -0.26558,0.83650
358.93100, 47.05500,    -0.64592,89.92214,50.00000,0.0000e+000,20.00000,    -0.27164,0.83473
360.71100, 47.23500,    -0.64866,89.86551,50.00000,0.0000e+000,20.00000,    -0.27704,0.83297
362.47900, 47.41500,    -0.65182,89.80876,50.00000,0.0000e+000,20.00000,    -0.28128,0.83124
364.26300, 47.59500,    -0.65511,89.75200,50.00000,0.0000e+000,20.00000,    -0.28361,0.82949
366.04700, 47.77500,    -0.65969,89.70038,50.00000,0.0000e+000,20.00000,    -0.28576,0.82774
367.82700, 47.95500,    -0.66437,89.64469,50.00000,0.0000e+000,20.00000,    -0.28797,0.82601
369.60599, 48.13500,    -0.67035,89.58651,50.00000,0.0000e+000,20.00000,    -0.28892,0.82429
371.40302, 48.31500,    -0.67545,89.53313,50.00000,0.0000e+000,20.00000,    -0.28865,0.82255
373.17099, 48.49500,    -0.68087,89.48165,50.00000,0.0000e+000,20.00000,    -0.28766,0.82085
374.97299, 48.67500,    -0.68622,89.42907,50.00000,0.0000e+000,20.00000,    -0.28649,0.81911
376.73700, 48.85500,    -0.69246,89.37691,50.00000,0.0000e+000,20.00000,    -0.28578,0.81743
378.52100, 49.03500,    -0.69951,89.32223,50.00000,0.0000e+000,20.00000,    -0.28197,0.81573
380.29501, 49.21500,    -0.70745,89.26895,50.00000,0.0000e+000,20.00000,    -0.27765,0.81404
382.07199, 49.39500,    -0.71618,89.22073,50.00000,0.0000e+000,20.00000,    -0.27370,0.81236
383.86099, 49.57500,    -0.72576,89.17212,50.00000,0.0000e+000,20.00000,    -0.27028,0.81067
385.63501, 49.75500,    -0.73570,89.12049,50.00000,0.0000e+000,20.00000,    -0.26546,0.80900
387.42200, 49.93500,    -0.74608,89.07277,50.00000,0.0000e+000,20.00000,    -0.25952,0.80733
389.21600, 50.11500,    -0.75671,89.02836,50.00000,0.0000e+000,20.00000,    -0.25516,0.80565
390.99399, 50.29500,    -0.76730,88.98132,50.00000,0.0000e+000,20.00000,    -0.25099,0.80400
392.78299, 50.47500,    -0.77779,88.93623,50.00000,0.0000e+000,20.00000,    -0.24627,0.80234
394.58301, 50.65500,    -0.78841,88.89201,50.00000,0.0000e+000,20.00000,    -0.24153,0.80068
396.35999, 50.83500,    -0.79841,88.85006,50.00000,0.0000e+000,20.00000,    -0.23667,0.79904
398.15201, 51.01500,    -0.80825,88.80900,50.00000,0.0000e+000,20.00000,    -0.23266,0.79740
399.94299, 51.19500,    -0.81757,88.76647,50.00000,0.0000e+000,20.00000,    -0.22969,0.79576
401.72699, 51.37500,    -0.82687,88.72616,50.00000,0.0000e+000,20.00000,    -0.22635,0.79414
403.51801, 51.55500,    -0.83555,88.68891,50.00000,0.0000e+000,20.00000,    -0.22238,0.79251
405.30600, 51.73500,    -0.84391,88.65236,50.00000,0.0000e+000,20.00000,    -0.21999,0.79090
407.09500, 51.91500,    -0.85213,88.61417,50.00000,0.0000e+000,20.00000,    -0.21877,0.78929
408.88800, 52.09500,    -0.86010,88.57760,50.00000,0.0000e+000,20.00000,    -0.21598,0.78768
410.65900, 52.27500,    -0.86767,88.54234,50.00000,0.0000e+000,20.00000,    -0.21412,0.78610
412.46100, 52.45500,    -0.87553,88.50753,50.00000,0.0000e+000,20.00000,    -0.21319,0.78449
414.25601, 52.63500,    -0.88316,88.47146,50.00000,0.0000e+000,20.00000,    -0.21259,0.78290
416.03799, 52.81500,    -0.89013,88.43239,50.00000,0.0000e+000,20.00000,    -0.21207,0.78133
417.82401, 52.99500,    -0.89705,88.39401,50.00000,0.0000e+000,20.00000,    -0.21119,0.77975
419.60901, 53.17500,    -0.90371,88.35798,50.00000,0.0000e+000,20.00000,    -0.21080,0.77819
421.39899, 53.35500,    -0.91020,88.32136,50.00000,0.0000e+000,20.00000,    -0.21100,0.77662
423.19101, 53.53500,    -0.91641,88.28182,50.00000,0.0000e+000,20.00000,    -0.21182,0.77506
424.97101, 53.71500,    -0.92247,88.24157,50.00000,0.0000e+000,20.00000,    -0.21216,0.77352
426.75800, 53.89500,    -0.92852,88.20462,50.00000,0.0000e+000,20.00000,    -0.21346,0.77198
428.54800, 54.07500,    -0.93270,88.16659,50.00000,0.0000e+000,20.00000,    -0.21526,0.77044
430.31699, 54.25500,    -0.93835,88.12566,50.00000,0.0000e+000,20.00000,    -0.21627,0.76892
432.10400, 54.43500,    -0.94412,88.08540,50.00000,0.0000e+000,20.00000,    -0.21801,0.76740
433.89001, 54.61500,    -0.94969,88.04613,50.00000,0.0000e+000,20.00000,    -0.21978,0.76588
435.67200, 54.79500,    -0.95552,88.00713,50.00000,0.0000e+000,20.00000,    -0.22089,0.76437
437.44501, 54.97500,    -0.96108,87.96752,50.00000,0.0000e+000,20.00000,    -0.22236,0.76287
439.22699, 55.15500,    -0.96716,87.92918,50.00000,0.0000e+000,20.00000,    -0.22375,0.76137
441.00500, 55.33500,    -0.97234,87.88989,50.00000,0.0000e+000,20.00000,    -0.22436,0.75988
442.78601, 55.51500,    -0.97835,87.85066,50.00000,0.0000e+000,20.00000,    -0.22570,0.75840
444.56900, 55.69500,    -0.98381,87.80936,50.00000,0.0000e+000,20.00000,    -0.22777,0.75692
446.35999, 55.87500,    -0.98979,87.76709,50.00000,0.0000e+000,20.00000,    -0.22885,0.75543
448.14801, 56.05500,    -0.99567,87.72829,50.00000,0.0000e+000,20.00000,    -0.22925,0.75396
449.92700, 56.23500,    -1.00086,87.68717,50.00000,0.0000e+000,20.00000,    -0.23079,0.75250
451.70999, 56.41500,    -1.00457,87.64195,50.00000,0.0000e+000,20.00000,    -0.23214,0.75104
453.48801, 56.59500,    -1.00896,87.59875,50.00000,0.0000e+000,20.00000,    -0.23400,0.74959
455.26700, 56.77500,    -1.01430,87.55707,50.00000,0.0000e+000,20.00000,    -0.23627,0.74815
457.04501, 56.95500,    -1.02034,87.51555,50.00000,0.0000e+000,20.00000,    -0.23882,0.74671
458.82800, 57.13500,    -1.02665,87.47455,50.00000,0.0000e+000,20.00000,    -0.24072,0.74528
460.61301, 57.31500,    -1.03241,87.42970,50.00000,0.0000e+000,20.00000,    -0.24241,0.74385
462.40601, 57.49500,    -1.03849,87.38423,50.00000,0.0000e+000,20.00000,    -0.24399,0.74242
464.18600, 57.67500,    -1.04440,87.34250,50.00000,0.0000e+000,20.00000,    -0.24579,0.74100
465.98001, 57.85500,    -1.05031,87.30073,50.00000,0.0000e+000,20.00000,    -0.24833,0.73958
467.78299, 58.03500,    -1.05602,87.25499,50.00000,0.0000e+000,20.00000,    -0.25074,0.73816
469.57001, 58.21500,    -1.06176,87.21028,50.00000,0.0000e+000,20.00000,    -0.25162,0.73675
471.37701, 58.39500,    -1.06647,87.16509,50.00000,0.0000e+000,20.00000,    -0.25276,0.73534
473.17401, 58.57500,    -1.07143,87.11732,50.00000,0.0000e+000,20.00000,    -0.25497,0.73394
474.97198, 58.75500,    -1.07584,87.06933,50.00000,0.0000e+000,20.00000,    -0.25755,0.73255
476.76801, 58.93500,    -1.08110,87.02308,50.00000,0.0000e+000,20.00000,    -0.25970,0.73116
478.55801, 59.11500,    -1.08558,86.97758,50.00000,0.0000e+000,20.00000,    -0.26125,0.72978
480.36600, 59.29500,    -1.09059,86.93150,50.00000,0.0000e+000,20.00000,    -0.26243,0.72840
482.14999, 59.47500,    -1.09510,86.88239,50.00000,0.0000e+000,20.00000,    -0.26472,0.72704
483.94501, 59.65500,    -1.09951,86.83396,50.00000,0.0000e+000,20.00000,    -0.26807,0.72567
485.74701, 59.83500,    -1.10421,86.78486,50.00000,0.0000e+000,20.00000,    -0.26992,0.72431
487.54800, 60.01500,    -1.10939,86.73644,50.00000,0.0000e+000,20.00000,    -0.27096,0.72295
489.34900, 60.19500,    -1.11465,86.68872,50.00000,0.0000e+000,20.00000,    -0.27260,0.72160
491.13501, 60.37500,    -1.11913,86.63932,50.00000,0.0000e+000,20.00000,    -0.27386,0.72026
492.93701, 60.55500,    -1.12366,86.58819,50.00000,0.0000e+000,20.00000,    -0.27395,0.71892
494.73599, 60.73500,    -1.12861,86.53912,50.00000,0.0000e+000,20.00000,    -0.27455,0.71759
496.53000, 60.91500,    -1.13336,86.48969,50.00000,0.0000e+000,20.00000,    -0.27600,0.71627
498.32700, 61.09500,    -1.13797,86.43934,50.00000,0.0000e+000,20.00000,    -0.27728,0.71495
500.12500, 61.27500,    -1.14310,86.38914,50.00000,0.0000e+000,20.00000,    -0.27814,0.71363
501.91299, 61.45500,    -1.14711,86.33579,50.00000,0.0000e+000,20.00000,    -0.27902,0.71233
503.70200, 61.63500,    -1.15098,86.28319,50.00000,0.0000e+000,20.00000,    -0.27976,0.71103
505.49899, 61.81500,    -1.15525,86.23407,50.00000,0.0000e+000,20.00000,    -0.28082,0.70973
507.28299, 61.99500,    -1.16014,86.18381,50.00000,0.0000e+000,20.00000,    -0.28131,0.70845
509.06799, 62.17500,    -1.16383,86.13155,50.00000,0.0000e+000,20.00000,    -0.28176,0.70717
510.87701, 62.35500,    -1.16924,86.08245,50.00000,0.0000e+000,20.00000,    -0.28303,0.70588
512.66302, 62.53500,    -1.17513,86.03433,50.00000,0.0000e+000,20.00000,    -0.28501,0.70461
514.45898, 62.71500,    -1.18007,85.98344,50.00000,0.0000e+000,20.00000,    -0.28707,0.70334
516.25897, 62.89500,    -1.18439,85.93308,50.00000,0.0000e+000,20.00000,    -0.28794,0.70208
518.06000, 63.07500,    -1.18774,85.88134,50.00000,0.0000e+000,20.00000,    -0.28831,0.70081
519.83899, 63.25500,    -1.18974,85.82937,50.00000,0.0000e+000,20.00000,    -0.28812,0.69957
521.63300, 63.43500,    -1.19266,85.77788,50.00000,0.0000e+000,20.00000,    -0.28818,0.69833
523.40900, 63.61500,    -1.19519,85.72524,50.00000,0.0000e+000,20.00000,    -0.28989,0.69710
525.20599, 63.79500,    -1.19862,85.67528,50.00000,0.0000e+000,20.00000,    -0.29169,0.69586
526.98297, 63.97500,    -1.20288,85.62535,50.00000,0.0000e+000,20.00000,    -0.29192,0.69464
528.77301, 64.15500,    -1.20746,85.57014,50.00000,0.0000e+000,20.00000,    -0.29316,0.69342
530.56097, 64.33500,    -1.21148,85.51344,50.00000,0.0000e+000,20.00000,    -0.29538,0.69220
532.32898, 64.51500,    -1.21425,85.45670,50.00000,0.0000e+000,20.00000,    -0.29666,0.69100
534.09497, 64.69500,    -1.21556,85.40250,50.00000,0.0000e+000,20.00000,    -0.29795,0.68981
535.87000, 64.87500,    -1.21786,85.35104,50.00000,0.0000e+000,20.00000,    -0.29899,0.68862
537.63098, 65.05500,    -1.22134,85.29901,50.00000,0.0000e+000,20.00000,    -0.29989,0.68744
539.41602, 65.23500,    -1.22683,85.24599,50.00000,0.0000e+000,20.00000,    -0.30098,0.68626
541.21503, 65.41500,    -1.23537,85.19063,50.00000,0.0000e+000,20.00000,    -0.30136,0.68506
543.04401, 65.59500,    -1.24473,85.13399,50.00000,0.0000e+000,20.00000,    -0.30264,0.68386
544.87701, 65.77500,    -1.25379,85.08052,50.00000,0.0000e+000,20.00000,    -0.30504,0.68265
546.69800, 65.95500,    -1.26106,85.02665,50.00000,0.0000e+000,20.00000,    -0.30587,0.68146
548.53101, 66.13500,    -1.26384,84.97085,50.00000,0.0000e+000,20.00000,    -0.30530,0.68027
550.33698, 66.31500,    -1.26594,84.91535,50.00000,0.0000e+000,20.00000,    -0.30533,0.67910
552.15997, 66.49500,    -1.26863,84.86018,50.00000,0.0000e+000,20.00000,    -0.30605,0.67792
553.96899, 66.67500,    -1.27116,84.80503,50.00000,0.0000e+000,20.00000,    -0.30744,0.67676
555.76703, 66.85500,    -1.27108,84.74958,50.00000,0.0000e+000,20.00000,    -0.30907,0.67561
557.54303, 67.03500,    -1.27058,84.69414,50.00000,0.0000e+000,20.00000,    -0.31030,0.67448
559.33502, 67.21500,    -1.27412,84.63999,50.00000,0.0000e+000,20.00000,    -0.31126,0.67334
561.14899, 67.39500,    -1.27913,84.58516,50.00000,0.0000e+000,20.00000,    -0.31225,0.67219
562.92603, 67.57500,    -1.28270,84.52740,50.00000,0.0000e+000,20.00000,    -0.31313,0.67108
564.71198, 67.75500,    -1.28354,84.46936,50.00000,0.0000e+000,20.00000,    -0.31403,0.66996
566.47900, 67.93500,    -1.28379,84.41461,50.00000,0.0000e+000,20.00000,    -0.31517,0.66886
568.27899, 68.11500,    -1.28821,84.35818,50.00000,0.0000e+000,20.00000,    -0.31525,0.66774
570.07202, 68.29500,    -1.29308,84.30061,50.00000,0.0000e+000,20.00000,    -0.31534,0.66664
571.85498, 68.47500,    -1.29632,84.24391,50.00000,0.0000e+000,20.00000,    -0.31677,0.66554
573.67798, 68.65500,    -1.30340,84.18623,50.00000,0.0000e+000,20.00000,    -0.31776,0.66442
575.49200, 68.83500,    -1.31077,84.12875,50.00000,0.0000e+000,20.00000,    -0.31744,0.66332
577.30298, 69.01500,    -1.31680,84.07078,50.00000,0.0000e+000,20.00000,    -0.31794,0.66222
579.10400, 69.19500,    -1.31986,84.01031,50.00000,0.0000e+000,20.00000,    -0.31803,0.66113
580.88501, 69.37500,    -1.32136,83.95258,50.00000,0.0000e+000,20.00000,    -0.31762,0.66006
582.67499, 69.55500,    -1.32270,83.89624,50.00000,0.0000e+000,20.00000,    -0.31757,0.65899
584.50702, 69.73500,    -1.32940,83.83647,50.00000,0.0000e+000,20.00000,    -0.31920,0.65790
586.35797, 69.91500,    -1.34118,83.77986,50.00000,0.0000e+000,20.00000,    -0.32177,0.65680
588.20300, 70.09500,    -1.34973,83.72480,50.00000,0.0000e+000,20.00000,    -0.32255,0.65571
590.02802, 70.27500,    -1.35251,83.66515,50.00000,0.0000e+000,20.00000,    -0.32401,0.65463
591.83600, 70.45500,    -1.35292,83.60514,50.00000,0.0000e+000,20.00000,    -0.32449,0.65358
593.60400, 70.63500,    -1.34983,83.55073,50.00000,0.0000e+000,20.00000,    -0.32394,0.65254
595.37402, 70.81500,    -1.34849,83.49466,50.00000,0.0000e+000,20.00000,    -0.32547,0.65152
597.13702, 70.99500,    -1.34901,83.43966,50.00000,0.0000e+000,20.00000,    -0.32602,0.65050
598.92102, 71.17500,    -1.35334,83.38419,50.00000,0.0000e+000,20.00000,    -0.32597,0.64947
600.74597, 71.35500,    -1.36383,83.32624,50.00000,0.0000e+000,20.00000,    -0.32958,0.64843
602.57501, 71.53500,    -1.37398,83.26604,50.00000,0.0000e+000,20.00000,    -0.33274,0.64738
604.40802, 71.71500,    -1.37923,83.20066,50.00000,0.0000e+000,20.00000,    -0.33559,0.64634
606.19501, 71.89500,    -1.38041,83.13949,50.00000,0.0000e+000,20.00000,    -0.33784,0.64533
607.99200, 72.07500,    -1.38134,83.07802,50.00000,0.0000e+000,20.00000,    -0.33687,0.64432
609.82397, 72.25500,    -1.38738,83.01756,50.00000,0.0000e+000,20.00000,    -0.33797,0.64329
611.64001, 72.43500,    -1.39360,82.96236,50.00000,0.0000e+000,20.00000,    -0.34283,0.64228
613.46899, 72.61500,    -1.39772,82.90029,50.00000,0.0000e+000,20.00000,    -0.34666,0.64126
615.27899, 72.79500,    -1.40094,82.83683,50.00000,0.0000e+000,20.00000,    -0.34922,0.64026
617.08698, 72.97500,    -1.40211,82.77905,50.00000,0.0000e+000,20.00000,    -0.35308,0.63927
618.89600, 73.15500,    -1.40321,82.71175,50.00000,0.0000e+000,20.00000,    -0.35738,0.63828
620.66302, 73.33500,    -1.40278,82.63979,50.00000,0.0000e+000,20.00000,    -0.36137,0.63731
622.45697, 73.51500,    -1.40292,82.57204,50.00000,0.0000e+000,20.00000,    -0.36093,0.63634
624.27802, 73.69500,    -1.41014,82.50739,50.00000,0.0000e+000,20.00000,    -0.36092,0.63535
626.08099, 73.87500,    -1.41609,82.45206,50.00000,0.0000e+000,20.00000,    -0.36296,0.63438
627.88397, 74.05500,    -1.41963,82.38929,50.00000,0.0000e+000,20.00000,    -0.36626,0.63341
629.69000, 74.23500,    -1.42212,82.31713,50.00000,0.0000e+000,20.00000,    -0.37121,0.63245
631.48602, 74.41500,    -1.42386,82.24639,50.00000,0.0000e+000,20.00000,    -0.37354,0.63149
633.25098, 74.59500,    -1.42174,82.18158,50.00000,0.0000e+000,20.00000,    -0.37288,0.63056
635.02698, 74.77500,    -1.42156,82.11322,50.00000,0.0000e+000,20.00000,    -0.37603,0.62962
636.89398, 74.95500,    -1.43344,82.04050,50.00000,0.0000e+000,20.00000,    -0.37935,0.62864
638.75598, 75.13500,    -1.44551,81.96552,50.00000,0.0000e+000,20.00000,    -0.37787,0.62767
640.58398, 75.31500,    -1.45264,81.90059,50.00000,0.0000e+000,20.00000,    -0.37643,0.62672
642.40002, 75.49500,    -1.45355,81.83925,50.00000,0.0000e+000,20.00000,    -0.37700,0.62578
644.19501, 75.67500,    -1.45310,81.77202,50.00000,0.0000e+000,20.00000,    -0.37962,0.62485
645.97900, 75.85500,    -1.45137,81.69884,50.00000,0.0000e+000,20.00000,    -0.38086,0.62394
647.75000, 76.03500,    -1.45024,81.62535,50.00000,0.0000e+000,20.00000,    -0.38132,0.62303
649.54602, 76.21500,    -1.45172,81.55492,50.00000,0.0000e+000,20.00000,    -0.37937,0.62212
651.31799, 76.39500,    -1.45466,81.49267,50.00000,0.0000e+000,20.00000,    -0.37769,0.62122
653.12500, 76.57500,    -1.45862,81.42522,50.00000,0.0000e+000,20.00000,    -0.37643,0.62030
654.90002, 76.75500,    -1.46386,81.34784,50.00000,0.0000e+000,20.00000,    -0.37400,0.61941
656.69702, 76.93500,    -1.47018,81.27868,50.00000,0.0000e+000,20.00000,    -0.37167,0.61851
658.48999, 77.11500,    -1.47489,81.21660,50.00000,0.0000e+000,20.00000,    -0.37101,0.61762
660.27600, 77.29500,    -1.47878,81.14905,50.00000,0.0000e+000,20.00000,    -0.37066,0.61673
662.07300, 77.47500,    -1.48170,81.08266,50.00000,0.0000e+000,20.00000,    -0.36741,0.61584
663.85498, 77.65500,    -1.48463,81.01833,50.00000,0.0000e+000,20.00000,    -0.36196,0.61496
665.66602, 77.83500,    -1.49028,80.94561,50.00000,0.0000e+000,20.00000,    -0.35787,0.61407
667.47302, 78.01500,    -1.49523,80.87913,50.00000,0.0000e+000,20.00000,    -0.35465,0.61319
669.28601, 78.19500,    -1.50038,80.82041,50.00000,0.0000e+000,20.00000,    -0.35313,0.61231
671.07703, 78.37500,    -1.50393,80.75769,50.00000,0.0000e+000,20.00000,    -0.34966,0.61144
672.90100, 78.55500,    -1.50880,80.69489,50.00000,0.0000e+000,20.00000,    -0.34217,0.61056
674.71301, 78.73500,    -1.51521,80.62831,50.00000,0.0000e+000,20.00000,    -0.33752,0.60969
676.57397, 78.91500,    -1.52369,80.56335,50.00000,0.0000e+000,20.00000,    -0.33662,0.60880
678.40698, 79.09500,    -1.52859,80.50295,50.00000,0.0000e+000,20.00000,    -0.33262,0.60792
680.22803, 79.27500,    -1.52979,80.44781,50.00000,0.0000e+000,20.00000,    -0.32677,0.60706
682.02100, 79.45500,    -1.52934,80.39561,50.00000,0.0000e+000,20.00000,    -0.32225,0.60621
683.81799, 79.63500,    -1.52887,80.33768,50.00000,0.0000e+000,20.00000,    -0.31618,0.60537
685.60498, 79.81500,    -1.53035,80.27794,50.00000,0.0000e+000,20.00000,    -0.31091,0.60453
687.41498, 79.99500,    -1.53283,80.21988,50.00000,0.0000e+000,20.00000,    -0.30822,0.60368
689.21301, 80.17500,    -1.53490,80.16613,50.00000,0.0000e+000,20.00000,    -0.30381,0.60284
690.99402, 80.35500,    -1.53654,80.11661,50.00000,0.0000e+000,20.00000,    -0.29831,0.60202
692.77399, 80.53500,    -1.53744,80.06354,50.00000,0.0000e+000,20.00000,    -0.29163,0.60120
694.55902, 80.71500,    -1.53994,80.00484,50.00000,0.0000e+000,20.00000,    -0.28646,0.60038
696.36298, 80.89500,    -1.54318,79.95113,50.00000,0.0000e+000,20.00000,    -0.28323,0.59955
698.16101, 81.07500,    -1.54854,79.90504,50.00000,0.0000e+000,20.00000,    -0.27981,0.59873
699.97699, 81.25500,    -1.55409,79.85823,50.00000,0.0000e+000,20.00000,    -0.27693,0.59790
701.79102, 81.43500,    -1.55973,79.80883,50.00000,0.0000e+000,20.00000,    -0.27331,0.59708
703.62097, 81.61500,    -1.56552,79.75947,50.00000,0.0000e+000,20.00000,    -0.26943,0.59626
705.44397, 81.79500,    -1.56961,79.71053,50.00000,0.0000e+000,20.00000,    -0.26721,0.59544
707.26300, 81.97500,    -1.57141,79.66360,50.00000,0.0000e+000,20.00000,    -0.26577,0.59462
709.05798, 82.15500,    -1.56935,79.62072,50.00000,0.0000e+000,20.00000,    -0.26403,0.59382
710.83301, 82.33500,    -1.56510,79.57922,50.00000,0.0000e+000,20.00000,    -0.26190,0.59303
712.61298, 82.51500,    -1.56424,79.53348,50.00000,0.0000e+000,20.00000,    -0.25880,0.59225
714.40302, 82.69500,    -1.56570,79.48398,50.00000,0.0000e+000,20.00000,    -0.25516,0.59146
716.22198, 82.87500,    -1.56701,79.43944,50.00000,0.0000e+000,20.00000,    -0.25275,0.59066
718.02802, 83.05500,    -1.56829,79.39816,50.00000,0.0000e+000,20.00000,    -0.25044,0.58987
719.87000, 83.23500,    -1.57241,79.35466,50.00000,0.0000e+000,20.00000,    -0.24552,0.58906
721.69098, 83.41500,    -1.57421,79.30952,50.00000,0.0000e+000,20.00000,    -0.23919,0.58827
723.50299, 83.59500,    -1.57386,79.25974,50.00000,0.0000e+000,20.00000,    -0.23269,0.58749
725.30499, 83.77500,    -1.57323,79.20971,50.00000,0.0000e+000,20.00000,    -0.22548,0.58671
727.09003, 83.95500,    -1.57080,79.16561,50.00000,0.0000e+000,20.00000,    -0.21862,0.58594
728.89697, 84.13500,    -1.57190,79.12193,50.00000,0.0000e+000,20.00000,    -0.21281,0.58517
730.71399, 84.31500,    -1.57769,79.07493,50.00000,0.0000e+000,20.00000,    -0.20608,0.58439
732.51398, 84.49500,    -1.58208,79.03194,50.00000,0.0000e+000,20.00000,    -0.19846,0.58363
734.34497, 84.67500,    -1.58774,78.99407,50.00000,0.0000e+000,20.00000,    -0.19086,0.58285
736.17700, 84.85500,    -1.59892,78.95571,50.00000,0.0000e+000,20.00000,    -0.18415,0.58208
737.98401, 85.03500,    -1.60767,78.92332,50.00000,0.0000e+000,20.00000,    -0.17667,0.58132
739.76801, 85.21500,    -1.61335,78.89670,50.00000,0.0000e+000,20.00000,    -0.16863,0.58057
741.53198, 85.39500,    -1.61559,78.87119,50.00000,0.0000e+000,20.00000,    -0.16015,0.57983
743.35400, 85.57500,    -1.62023,78.84924,50.00000,0.0000e+000,20.00000,    -0.15154,0.57907
745.16101, 85.75500,    -1.62586,78.83098,50.00000,0.0000e+000,20.00000,    -0.14350,0.57832
746.97302, 85.93500,    -1.63182,78.81090,50.00000,0.0000e+000,20.00000,    -0.13474,0.57757
748.80298, 86.11500,    -1.63581,78.79087,50.00000,0.0000e+000,20.00000,    -0.12532,0.57682
750.62598, 86.29500,    -1.63842,78.76919,50.00000,0.0000e+000,20.00000,    -0.11768,0.57607
752.45599, 86.47500,    -1.63998,78.75075,50.00000,0.0000e+000,20.00000,    -0.11148,0.57532
754.30298, 86.65500,    -1.64252,78.73405,50.00000,0.0000e+000,20.00000,    -0.10404,0.57456
756.10999, 86.83500,    -1.64224,78.71802,50.00000,0.0000e+000,20.00000,-9.8097e-002,0.57383
757.90698, 87.01500,    -1.64190,78.70273,50.00000,0.0000e+000,20.00000,-9.3962e-002,0.57310
759.69800, 87.19500,    -1.64029,78.68524,50.00000,0.0000e+000,20.00000,-8.9669e-002,0.57237
761.49298, 87.37500,    -1.63777,78.66589,50.00000,0.0000e+000,20.00000,-8.6989e-002,0.57165
763.29199, 87.55500,    -1.63774,78.64962,50.00000,0.0000e+000,20.00000,-8.5565e-002,0.57093
765.11603, 87.73500,    -1.64244,78.63801,50.00000,0.0000e+000,20.00000,-8.3940e-002,0.57019
766.92102, 87.91500,    -1.64439,78.62622,50.00000,0.0000e+000,20.00000,-8.2251e-002,0.56947
768.70697, 88.09500,    -1.64423,78.61048,50.00000,0.0000e+000,20.00000,-7.9113e-002,0.56876
770.48102, 88.27500,    -1.64255,78.59451,50.00000,0.0000e+000,20.00000,-7.6186e-002,0.56806
772.27002, 88.45500,    -1.64301,78.58272,50.00000,0.0000e+000,20.00000,-7.4757e-002,0.56735
774.04602, 88.63500,    -1.64399,78.57117,50.00000,0.0000e+000,20.00000,-7.4629e-002,0.56665
775.83502, 88.81500,    -1.64630,78.55882,50.00000,0.0000e+000,20.00000,-7.4493e-002,0.56594
777.61401, 88.99500,    -1.64739,78.54893,50.00000,0.0000e+000,20.00000,-7.3429e-002,0.56524
779.40100, 89.17500,    -1.65084,78.53635,50.00000,0.0000e+000,20.00000,-7.2144e-002,0.56454
781.19598, 89.35500,    -1.65404,78.52311,50.00000,0.0000e+000,20.00000,-7.0528e-002,0.56384
782.98999, 89.53500,    -1.65724,78.50941,50.00000,0.0000e+000,20.00000,-6.9184e-002,0.56315
784.80298, 89.71500,    -1.66333,78.49526,50.00000,0.0000e+000,20.00000,-6.8573e-002,0.56244
786.59802, 89.89500,    -1.66674,78.48469,50.00000,0.0000e+000,20.00000,-6.7896e-002,0.56175
788.40698, 90.07500,    -1.67100,78.47615,50.00000,0.0000e+000,20.00000,-6.7019e-002,0.56105
790.22803, 90.25500,    -1.67768,78.46555,50.00000,0.0000e+000,20.00000,-6.7328e-002,0.56035
792.05402, 90.43500,    -1.68266,78.45006,50.00000,0.0000e+000,20.00000,-6.8404e-002,0.55965
793.89301, 90.61500,    -1.68707,78.43487,50.00000,0.0000e+000,20.00000,-6.8844e-002,0.55894
795.71503, 90.79500,    -1.69113,78.42191,50.00000,0.0000e+000,20.00000,-6.9486e-002,0.55824
797.52802, 90.97500,    -1.69429,78.40721,50.00000,0.0000e+000,20.00000,-6.9733e-002,0.55755
799.32397, 91.15500,    -1.69540,78.39531,50.00000,0.0000e+000,20.00000,-6.8973e-002,0.55687
801.12299, 91.33500,    -1.69678,78.38789,50.00000,0.0000e+000,20.00000,-6.7881e-002,0.55619
802.89899, 91.51500,    -1.69650,78.37927,50.00000,0.0000e+000,20.00000,-6.6914e-002,0.55552
804.67902, 91.69500,    -1.69655,78.36698,50.00000,0.0000e+000,20.00000,-6.7207e-002,0.55485
806.47198, 91.87500,    -1.69912,78.35372,50.00000,0.0000e+000,20.00000,-6.8819e-002,0.55417
808.24402, 92.05500,    -1.70133,78.34045,50.00000,0.0000e+000,20.00000,-7.0144e-002,0.55350
810.05798, 92.23500,    -1.70355,78.32543,50.00000,0.0000e+000,20.00000,-6.9832e-002,0.55283
811.83398, 92.41500,    -1.70735,78.31088,50.00000,0.0000e+000,20.00000,-6.9439e-002,0.55216
813.64203, 92.59500,    -1.71219,78.29847,50.00000,0.0000e+000,20.00000,-7.0121e-002,0.55149
815.44897, 92.77500,    -1.71603,78.28546,50.00000,0.0000e+000,20.00000,-7.0720e-002,0.55081
817.25201, 92.95500,    -1.71966,78.27440,50.00000,0.0000e+000,20.00000,-7.1825e-002,0.55014
819.04797, 93.13500,    -1.72168,78.26507,50.00000,0.0000e+000,20.00000,-7.4289e-002,0.54948
820.83197, 93.31500,    -1.72273,78.25442,50.00000,0.0000e+000,20.00000,-7.7311e-002,0.54882
822.63397, 93.49500,    -1.72388,78.24246,50.00000,0.0000e+000,20.00000,-7.9525e-002,0.54816
824.43597, 93.67500,    -1.72644,78.22823,50.00000,0.0000e+000,20.00000,-8.0648e-002,0.54749
826.24799, 93.85500,    -1.72935,78.21330,50.00000,0.0000e+000,20.00000,-8.2361e-002,0.54683
828.04999, 94.03500,    -1.73324,78.19945,50.00000,0.0000e+000,20.00000,-8.4309e-002,0.54617
829.86298, 94.21500,    -1.73664,78.18539,50.00000,0.0000e+000,20.00000,-8.6081e-002,0.54550
831.67902, 94.39500,    -1.73801,78.17017,50.00000,0.0000e+000,20.00000,-8.8649e-002,0.54484
833.52399, 94.57500,    -1.74260,78.15353,50.00000,0.0000e+000,20.00000,-9.1847e-002,0.54417
835.39203, 94.75500,    -1.75119,78.13677,50.00000,0.0000e+000,20.00000,-9.6348e-002,0.54349
837.22803, 94.93500,    -1.75276,78.12011,50.00000,0.0000e+000,20.00000,    -0.10084,0.54282
839.04700, 95.11500,    -1.75124,78.10137,50.00000,0.0000e+000,20.00000,    -0.10483,0.54216
840.93597, 95.29500,    -1.75707,78.08120,50.00000,0.0000e+000,20.00000,    -0.10885,0.54148
842.81000, 95.47500,    -1.76307,78.06360,50.00000,0.0000e+000,20.00000,    -0.11294,0.54080
844.63202, 95.65500,    -1.76237,78.04476,50.00000,0.0000e+000,20.00000,    -0.11716,0.54014
846.41998, 95.83500,    -1.75881,78.02298,50.00000,0.0000e+000,20.00000,    -0.12126,0.53950
848.20697, 96.01500,    -1.75300,78.00160,50.00000,0.0000e+000,20.00000,    -0.12463,0.53886
849.97302, 96.19500,    -1.74749,77.97975,50.00000,0.0000e+000,20.00000,    -0.12779,0.53823
851.73199, 96.37500,    -1.74471,77.95586,50.00000,0.0000e+000,20.00000,    -0.13118,0.53760
853.53998, 96.55500,    -1.74585,77.92793,50.00000,0.0000e+000,20.00000,    -0.13510,0.53695
855.33301, 96.73500,    -1.74973,77.90180,50.00000,0.0000e+000,20.00000,    -0.13898,0.53631
857.13599, 96.91500,    -1.75276,77.87687,50.00000,0.0000e+000,20.00000,    -0.14342,0.53567
858.91803, 97.09500,    -1.75446,77.85068,50.00000,0.0000e+000,20.00000,    -0.14619,0.53503
860.72101, 97.27500,    -1.75445,77.82240,50.00000,0.0000e+000,20.00000,    -0.14864,0.53439
862.50201, 97.45500,    -1.75455,77.79185,50.00000,0.0000e+000,20.00000,    -0.15179,0.53376
864.29401, 97.63500,    -1.75716,77.76262,50.00000,0.0000e+000,20.00000,    -0.15438,0.53313
866.08502, 97.81500,    -1.76155,77.73599,50.00000,0.0000e+000,20.00000,    -0.15656,0.53249
867.88098, 97.99500,    -1.76462,77.70968,50.00000,0.0000e+000,20.00000,    -0.15919,0.53186
869.66998, 98.17500,    -1.76557,77.68132,50.00000,0.0000e+000,20.00000,    -0.16192,0.53123
871.47400, 98.35500,    -1.76748,77.65019,50.00000,0.0000e+000,20.00000,    -0.16319,0.53059
873.26099, 98.53500,    -1.77000,77.61970,50.00000,0.0000e+000,20.00000,    -0.16447,0.52996
875.05902, 98.71500,    -1.77229,77.58546,50.00000,0.0000e+000,20.00000,    -0.16643,0.52933
876.88397, 98.89500,    -1.77808,77.55403,50.00000,0.0000e+000,20.00000,    -0.16854,0.52869
878.70599, 99.07500,    -1.78430,77.52718,50.00000,0.0000e+000,20.00000,    -0.17040,0.52805
880.52399, 99.25500,    -1.78874,77.49786,50.00000,0.0000e+000,20.00000,    -0.17164,0.52741
882.33301, 99.43500,    -1.78952,77.46668,50.00000,0.0000e+000,20.00000,    -0.17285,0.52678
884.12598, 99.61500,    -1.79038,77.43716,50.00000,0.0000e+000,20.00000,    -0.17469,0.52615
885.92499, 99.79500,    -1.79112,77.40624,50.00000,0.0000e+000,20.00000,    -0.17690,0.52552
887.72803, 99.97500,    -1.79192,77.37313,50.00000,0.0000e+000,20.00000,    -0.17913,0.52489
889.51398,100.15500,    -1.79285,77.34053,50.00000,0.0000e+000,20.00000,    -0.18060,0.52427
891.31097,100.33500,    -1.79344,77.30928,50.00000,0.0000e+000,20.00000,    -0.18191,0.52364
893.11603,100.51500,    -1.79598,77.27740,50.00000,0.0000e+000,20.00000,    -0.18219,0.52301
894.94202,100.69500,    -1.80001,77.24399,50.00000,0.0000e+000,20.00000,    -0.18322,0.52238
896.79102,100.87500,    -1.81153,77.20941,50.00000,0.0000e+000,20.00000,    -0.18600,0.52173
898.60699,101.05500,    -1.81639,77.17449,50.00000,0.0000e+000,20.00000,    -0.18825,0.52110
900.42902,101.23500,    -1.81678,77.14030,50.00000,0.0000e+000,20.00000,    -0.18963,0.52047
902.24103,101.41500,    -1.81805,77.10662,50.00000,0.0000e+000,20.00000,    -0.19125,0.51984
904.01898,101.59500,    -1.81828,77.07257,50.00000,0.0000e+000,20.00000,    -0.19266,0.51923
905.83801,101.77500,    -1.82056,77.03676,50.00000,0.0000e+000,20.00000,    -0.19422,0.51860
907.66101,101.95500,    -1.82325,77.00033,50.00000,0.0000e+000,20.00000,    -0.19588,0.51797
909.45398,102.13500,    -1.82364,76.96491,50.00000,0.0000e+000,20.00000,    -0.19791,0.51734
911.24200,102.31500,    -1.82360,76.93027,50.00000,0.0000e+000,20.00000,    -0.19957,0.51673
913.04602,102.49500,    -1.82491,76.89435,50.00000,0.0000e+000,20.00000,    -0.20062,0.51610
914.86499,102.67500,    -1.82739,76.85721,50.00000,0.0000e+000,20.00000,    -0.20187,0.51547
916.67798,102.85500,    -1.83152,76.82008,50.00000,0.0000e+000,20.00000,    -0.20284,0.51485
918.46301,103.03500,    -1.83014,76.78378,50.00000,0.0000e+000,20.00000,    -0.20411,0.51423
920.28101,103.21500,    -1.83047,76.74799,50.00000,0.0000e+000,20.00000,    -0.20646,0.51360
922.10199,103.39500,    -1.83618,76.71265,50.00000,0.0000e+000,20.00000,    -0.20805,0.51298
923.90302,103.57500,    -1.83844,76.67432,50.00000,0.0000e+000,20.00000,    -0.20866,0.51236
925.76202,103.75500,    -1.84443,76.63538,50.00000,0.0000e+000,20.00000,    -0.20899,0.51171
927.60199,103.93500,    -1.84900,76.59661,50.00000,0.0000e+000,20.00000,    -0.21018,0.51108
929.40900,104.11500,    -1.84825,76.55856,50.00000,0.0000e+000,20.00000,    -0.21177,0.51046
931.20898,104.29500,    -1.84574,76.52169,50.00000,0.0000e+000,20.00000,    -0.21292,0.50984
932.99200,104.47500,    -1.84331,76.48294,50.00000,0.0000e+000,20.00000,    -0.21379,0.50922
934.81598,104.65500,    -1.84424,76.44419,50.00000,0.0000e+000,20.00000,    -0.21443,0.50860
936.62402,104.83500,    -1.84631,76.40570,50.00000,0.0000e+000,20.00000,    -0.21514,0.50797
938.44702,105.01500,    -1.84447,76.36354,50.00000,0.0000e+000,20.00000,    -0.21608,0.50735
940.25299,105.19500,    -1.84129,76.32334,50.00000,0.0000e+000,20.00000,    -0.21789,0.50672
942.05298,105.37500,    -1.83809,76.28534,50.00000,0.0000e+000,20.00000,    -0.21836,0.50610
943.84998,105.55500,    -1.83239,76.24794,50.00000,0.0000e+000,20.00000,    -0.21785,0.50549
945.63202,105.73500,    -1.82571,76.20820,50.00000,0.0000e+000,20.00000,    -0.21667,0.50487
947.42902,105.91500,    -1.82001,76.16777,50.00000,0.0000e+000,20.00000,    -0.21516,0.50425
949.21100,106.09500,    -1.81400,76.12779,50.00000,0.0000e+000,20.00000,    -0.21360,0.50364
951.01001,106.27500,    -1.80920,76.08771,50.00000,0.0000e+000,20.00000,    -0.21106,0.50302
952.79797,106.45500,    -1.80637,76.04791,50.00000,0.0000e+000,20.00000,    -0.20795,0.50241
954.59601,106.63500,    -1.80590,76.00890,50.00000,0.0000e+000,20.00000,    -0.20450,0.50179
956.40900,106.81500,    -1.80527,75.96976,50.00000,0.0000e+000,20.00000,    -0.19977,0.50116
958.20502,106.99500,    -1.80332,75.92821,50.00000,0.0000e+000,20.00000,    -0.19498,0.50054
960.00897,107.17500,    -1.80349,75.88800,50.00000,0.0000e+000,20.00000,    -0.19021,0.49992
961.81403,107.35500,    -1.80481,75.85059,50.00000,0.0000e+000,20.00000,    -0.18485,0.49930
963.60303,107.53500,    -1.80633,75.81569,50.00000,0.0000e+000,20.00000,    -0.17831,0.49868
965.42603,107.71500,    -1.80709,75.78278,50.00000,0.0000e+000,20.00000,    -0.17098,0.49805
967.20898,107.89500,    -1.80906,75.75128,50.00000,0.0000e+000,20.00000,    -0.16376,0.49744
969.01001,108.07500,    -1.80924,75.72191,50.00000,0.0000e+000,20.00000,    -0.15634,0.49682
970.80103,108.25500,    -1.81295,75.69397,50.00000,0.0000e+000,20.00000,    -0.14875,0.49620
972.62903,108.43500,    -1.81997,75.66823,50.00000,0.0000e+000,20.00000,    -0.14120,0.49557
974.43701,108.61500,    -1.82391,75.64352,50.00000,0.0000e+000,20.00000,    -0.13357,0.49494
976.24103,108.79500,    -1.82636,75.62005,50.00000,0.0000e+000,20.00000,    -0.12509,0.49432
978.02399,108.97500,    -1.82707,75.59880,50.00000,0.0000e+000,20.00000,    -0.11654,0.49370
979.81702,109.15500,    -1.82944,75.58069,50.00000,0.0000e+000,20.00000,    -0.10905,0.49308
981.62000,109.33500,    -1.83368,75.56488,50.00000,0.0000e+000,20.00000,    -0.10061,0.49246
983.41803,109.51500,    -1.83687,75.55107,50.00000,0.0000e+000,20.00000,-9.1954e-002,0.49184
985.21503,109.69500,    -1.84014,75.53737,50.00000,0.0000e+000,20.00000,-8.3711e-002,0.49121
987.02502,109.87500,    -1.84385,75.52434,50.00000,0.0000e+000,20.00000,-7.5442e-002,0.49059
988.80902,110.05500,    -1.84527,75.51210,50.00000,0.0000e+000,20.00000,-6.8093e-002,0.48997
990.65100,110.23500,    -1.85090,75.50040,50.00000,0.0000e+000,20.00000,-6.4031e-002,0.48933
992.46997,110.41500,    -1.85576,75.48939,50.00000,0.0000e+000,20.00000,-6.0734e-002,0.48869
994.27100,110.59500,    -1.85787,75.47886,50.00000,0.0000e+000,20.00000,-5.7625e-002,0.48807
996.07800,110.77500,    -1.85814,75.46946,50.00000,0.0000e+000,20.00000,-5.5043e-002,0.48744
997.87201,110.95500,    -1.86033,75.45919,50.00000,0.0000e+000,20.00000,-5.9002e-002,0.48682
998.38202,111.00500,    -1.86174,75.45631,50.00000,0.0000e+000,20.00000,-5.8667e-002,0.48664