File: book/some_content/DG_ExpDat_A8%DC1; 17-1-2025-2.csv
#FILE:                       ,A8%DC1; 17-1-2025.ngb-ds3
#FORMAT:                     ,NETZSCH5
#IDENTITY:                   ,GEOPOLYMER PASTE
#DECIMAL:                    ,POINT
#SEPARATOR:                  ,COMMA
#MTYPE:                      ,DSC
#INSTRUMENT:                 ,Microlab TU Delft
#PROJECT:                    ,
#DATE/TIME:                  ,18/01/2025 8:32:08 AM
#CORR. FILE:                 ,Blank with cover; 13-1-2025.ngb-bs3
#LABORATORY:                 ,TU Delft Micro Lab
#OPERATOR:                   ,Ahmed
#REMARK:                     ,under Argon atmosphere, 10K/min
#SAMPLE:                     ,A8%DC1;18-1-2025
#SAMPLE MASS /mg:            ,38
#MATERIAL:                   ,Geopolymer paste
#REFERENCE:                  ,blank
#REFERENCE MASS /mg:         ,0
#TYPE OF CRUCIBLE:           ,DSC/TG pan Al2O3
#SAMPLE CRUCIBLE MASS /mg:   ,0
#REFERENCE CRUCIBLE MASS /mg:,0
#CORR. CODE:                 ,020
#EXO:                        ,-1
#RANGE:                      ,40/10.0(K/min)/1000
#SEGMENT:                    ,S2/2

##Temp./øC,Time/min,DSC/(mW/mg),Mass/%,Gas Flow(purge1)/(ml/min),Gas Flow(purge2)/(ml/min),Gas Flow(protective)/(ml/min),DTG/(%/min),Sensit./(uV/mW)
 40.70600, 15.03333, 5.5845e-002,97.33828,50.00000,0.0000e+000,20.00000,    -0.14267,1.22597
 40.75200, 15.21333, 5.5602e-002,97.31167,50.00000,0.0000e+000,20.00000,    -0.14259,1.22591
 40.78900, 15.39333, 5.5457e-002,97.28662,50.00000,0.0000e+000,20.00000,    -0.14286,1.22585
 40.86400, 15.57333, 5.5674e-002,97.26084,50.00000,0.0000e+000,20.00000,    -0.14524,1.22575
 40.98200, 15.75333, 5.6353e-002,97.23526,50.00000,0.0000e+000,20.00000,    -0.14787,1.22559
 41.15400, 15.93333, 5.7823e-002,97.20866,50.00000,0.0000e+000,20.00000,    -0.15118,1.22535
 41.39100, 16.11333, 6.0100e-002,97.18138,50.00000,0.0000e+000,20.00000,    -0.15421,1.22502
 41.68900, 16.29333, 6.3186e-002,97.15358,50.00000,0.0000e+000,20.00000,    -0.15851,1.22461
 42.08200, 16.47333, 6.7183e-002,97.12532,50.00000,0.0000e+000,20.00000,    -0.16414,1.22407
 42.55100, 16.65333, 7.1551e-002,97.09645,50.00000,0.0000e+000,20.00000,    -0.17170,1.22342
 43.09500, 16.83333, 7.6899e-002,97.06607,50.00000,0.0000e+000,20.00000,    -0.18166,1.22267
 43.73300, 17.01333, 8.2837e-002,97.03623,50.00000,0.0000e+000,20.00000,    -0.18943,1.22180
 44.42400, 17.19333, 8.9759e-002,97.00530,50.00000,0.0000e+000,20.00000,    -0.19888,1.22084
 45.23000, 17.37333, 9.6919e-002,96.97301,50.00000,0.0000e+000,20.00000,    -0.20958,1.21973
 46.11900, 17.55333,     0.10441,96.93918,50.00000,0.0000e+000,20.00000,    -0.22232,1.21851
 47.05600, 17.73333,     0.11276,96.90365,50.00000,0.0000e+000,20.00000,    -0.23678,1.21722
 48.11300, 17.91333,     0.12128,96.86617,50.00000,0.0000e+000,20.00000,    -0.25316,1.21576
 49.24000, 18.09333,     0.13012,96.82628,50.00000,0.0000e+000,20.00000,    -0.27169,1.21421
 50.46200, 18.27333,     0.13998,96.78318,50.00000,0.0000e+000,20.00000,    -0.29263,1.21252
 51.73400, 18.45333,     0.14997,96.73635,50.00000,0.0000e+000,20.00000,    -0.31617,1.21077
 53.10300, 18.63333,     0.16024,96.68605,50.00000,0.0000e+000,20.00000,    -0.34234,1.20889
 54.54300, 18.81333,     0.17114,96.63168,50.00000,0.0000e+000,20.00000,    -0.37182,1.20691
 56.04900, 18.99333,     0.18247,96.57291,50.00000,0.0000e+000,20.00000,    -0.40464,1.20483
 57.64500, 19.17333,     0.19451,96.50913,50.00000,0.0000e+000,20.00000,    -0.44096,1.20264
 59.32200, 19.35333,     0.20687,96.43808,50.00000,0.0000e+000,20.00000,    -0.48099,1.20033
 61.03900, 19.53333,     0.21992,96.36001,50.00000,0.0000e+000,20.00000,    -0.52501,1.19797
 62.86500, 19.71333,     0.23365,96.27418,50.00000,0.0000e+000,20.00000,    -0.57323,1.19547
 64.72200, 19.89333,     0.24842,96.18000,50.00000,0.0000e+000,20.00000,    -0.62578,1.19292
 66.64900, 20.07333,     0.26412,96.07672,50.00000,0.0000e+000,20.00000,    -0.68273,1.19027
 68.63900, 20.25333,     0.28089,95.96355,50.00000,0.0000e+000,20.00000,    -0.74410,1.18754
 70.66000, 20.43333,     0.29861,95.83959,50.00000,0.0000e+000,20.00000,    -0.81047,1.18477
 72.73800, 20.61333,     0.31761,95.70374,50.00000,0.0000e+000,20.00000,    -0.88203,1.18192
 74.88600, 20.79333,     0.33824,95.55510,50.00000,0.0000e+000,20.00000,    -0.95894,1.17898
 77.05800, 20.97333,     0.36025,95.39249,50.00000,0.0000e+000,20.00000,    -1.04135,1.17601
 79.28500, 21.15333,     0.38436,95.21496,50.00000,0.0000e+000,20.00000,    -1.12851,1.17297
 81.52500, 21.33333,     0.40970,95.02137,50.00000,0.0000e+000,20.00000,    -1.22042,1.16991
 83.83500, 21.51333,     0.43725,94.81063,50.00000,0.0000e+000,20.00000,    -1.31691,1.16675
 86.16800, 21.69333,     0.46695,94.58199,50.00000,0.0000e+000,20.00000,    -1.41767,1.16357
 88.50300, 21.87333,     0.49869,94.33419,50.00000,0.0000e+000,20.00000,    -1.52194,1.16039
 90.88100, 22.05333,     0.53237,94.06677,50.00000,0.0000e+000,20.00000,    -1.62889,1.15715
 93.28300, 22.23333,     0.56824,93.77787,50.00000,0.0000e+000,20.00000,    -1.73754,1.15389
 95.70100, 22.41333,     0.60621,93.46619,50.00000,0.0000e+000,20.00000,    -1.84667,1.15060
 98.12700, 22.59333,     0.64640,93.13069,50.00000,0.0000e+000,20.00000,    -1.95510,1.14731
100.55900, 22.77333,     0.68827,92.77043,50.00000,0.0000e+000,20.00000,    -2.06145,1.14402
102.98800, 22.95333,     0.73227,92.38560,50.00000,0.0000e+000,20.00000,    -2.16458,1.14073
105.42400, 23.13333,     0.77793,91.97651,50.00000,0.0000e+000,20.00000,    -2.26326,1.13744
107.87100, 23.31333,     0.82584,91.54292,50.00000,0.0000e+000,20.00000,    -2.35628,1.13413
110.30400, 23.49333,     0.87596,91.08536,50.00000,0.0000e+000,20.00000,    -2.44282,1.13085
112.72300, 23.67333,     0.92800,90.60556,50.00000,0.0000e+000,20.00000,    -2.52149,1.12759
115.13500, 23.85333,     0.98245,90.10587,50.00000,0.0000e+000,20.00000,    -2.59152,1.12435
117.57400, 24.03333,     1.03871,89.58888,50.00000,0.0000e+000,20.00000,    -2.65170,1.12107
119.96500, 24.21333,     1.09598,89.05786,50.00000,0.0000e+000,20.00000,    -2.70087,1.11787
122.34700, 24.39333,     1.15304,88.51623,50.00000,0.0000e+000,20.00000,    -2.73811,1.11468
124.73700, 24.57333,     1.20966,87.96783,50.00000,0.0000e+000,20.00000,    -2.76262,1.11148
127.13700, 24.75333,     1.26318,87.41599,50.00000,0.0000e+000,20.00000,    -2.77365,1.10828
129.50800, 24.93333,     1.31212,86.86393,50.00000,0.0000e+000,20.00000,    -2.77114,1.10512
131.88699, 25.11333,     1.35320,86.31508,50.00000,0.0000e+000,20.00000,    -2.75470,1.10195
134.25301, 25.29333,     1.38393,85.77191,50.00000,0.0000e+000,20.00000,    -2.72413,1.09881
136.61099, 25.47333,     1.40175,85.23779,50.00000,0.0000e+000,20.00000,    -2.68011,1.09568
138.95700, 25.65333,     1.40416,84.71547,50.00000,0.0000e+000,20.00000,    -2.62349,1.09258
141.30701, 25.83333,     1.38907,84.20757,50.00000,0.0000e+000,20.00000,    -2.55538,1.08947
143.63600, 26.01333,     1.35733,83.71688,50.00000,0.0000e+000,20.00000,    -2.47703,1.08640
145.97800, 26.19333,     1.31005,83.24580,50.00000,0.0000e+000,20.00000,    -2.38997,1.08331
148.31599, 26.37333,     1.25010,82.79629,50.00000,0.0000e+000,20.00000,    -2.29584,1.08024
150.64400, 26.55333,     1.18073,82.37087,50.00000,0.0000e+000,20.00000,    -2.19612,1.07718
152.95399, 26.73333,     1.10533,81.97096,50.00000,0.0000e+000,20.00000,    -2.09216,1.07415
155.25900, 26.91333,     1.02690,81.59694,50.00000,0.0000e+000,20.00000,    -1.98538,1.07114
157.56599, 27.09333,     0.94884,81.25055,50.00000,0.0000e+000,20.00000,    -1.87686,1.06813
159.84300, 27.27333,     0.87202,80.93087,50.00000,0.0000e+000,20.00000,    -1.76791,1.06516
162.13000, 27.45333,     0.79915,80.63715,50.00000,0.0000e+000,20.00000,    -1.65965,1.06219
164.38800, 27.63333,     0.73019,80.36794,50.00000,0.0000e+000,20.00000,    -1.55296,1.05926
166.61600, 27.81333,     0.66536,80.12183,50.00000,0.0000e+000,20.00000,    -1.44879,1.05637
168.85600, 27.99333,     0.60529,79.89681,50.00000,0.0000e+000,20.00000,    -1.34814,1.05348
171.05299, 28.17333,     0.54929,79.69058,50.00000,0.0000e+000,20.00000,    -1.25160,1.05064
173.21899, 28.35333,     0.49850,79.50115,50.00000,0.0000e+000,20.00000,    -1.16012,1.04785
175.39600, 28.53333,     0.45126,79.32673,50.00000,0.0000e+000,20.00000,    -1.07436,1.04506
177.52000, 28.71333,     0.40843,79.16558,50.00000,0.0000e+000,20.00000,    -0.99428,1.04233
179.63200, 28.89333,     0.36898,79.01630,50.00000,0.0000e+000,20.00000,    -0.92077,1.03963
181.69299, 29.07333,     0.33297,78.87740,50.00000,0.0000e+000,20.00000,    -0.85348,1.03700
183.77200, 29.25333,     0.29929,78.74745,50.00000,0.0000e+000,20.00000,    -0.79241,1.03435
185.80499, 29.43333,     0.26834,78.62594,50.00000,0.0000e+000,20.00000,    -0.73717,1.03176
187.82600, 29.61333,     0.24059,78.51211,50.00000,0.0000e+000,20.00000,    -0.68743,1.02920
189.81200, 29.79333,     0.21482,78.40482,50.00000,0.0000e+000,20.00000,    -0.64270,1.02668
191.78500, 29.97333,     0.19056,78.30379,50.00000,0.0000e+000,20.00000,    -0.60241,1.02419
193.72501, 30.15333,     0.16815,78.20820,50.00000,0.0000e+000,20.00000,    -0.56607,1.02174
195.65500, 30.33333,     0.14694,78.11719,50.00000,0.0000e+000,20.00000,    -0.53325,1.01931
197.59200, 30.51333,     0.12699,78.03104,50.00000,0.0000e+000,20.00000,    -0.50356,1.01687
199.50700, 30.69333,     0.10859,77.94858,50.00000,0.0000e+000,20.00000,    -0.47659,1.01447
201.38499, 30.87333, 9.1309e-002,77.87025,50.00000,0.0000e+000,20.00000,    -0.45192,1.01212
203.25700, 31.05333, 7.5018e-002,77.79535,50.00000,0.0000e+000,20.00000,    -0.42921,1.00978
205.10899, 31.23333, 6.0244e-002,77.72380,50.00000,0.0000e+000,20.00000,    -0.40841,1.00747
206.96201, 31.41333, 4.5841e-002,77.65562,50.00000,0.0000e+000,20.00000,    -0.38937,1.00517
208.78999, 31.59333, 3.2071e-002,77.59054,50.00000,0.0000e+000,20.00000,    -0.37175,1.00290
210.59900, 31.77333, 1.9121e-002,77.52841,50.00000,0.0000e+000,20.00000,    -0.35548,1.00066
212.37900, 31.95333, 6.8167e-003,77.46900,50.00000,0.0000e+000,20.00000,    -0.34038,0.99846
214.16499, 32.13334,-5.6831e-003,77.41197,50.00000,0.0000e+000,20.00000,    -0.32619,0.99625
215.92400, 32.31333,-1.7854e-002,77.35712,50.00000,0.0000e+000,20.00000,    -0.31294,0.99409
217.67999, 32.49333,-3.0361e-002,77.30434,50.00000,0.0000e+000,20.00000,    -0.30042,0.99193
219.43700, 32.67333,-4.3369e-002,77.25379,50.00000,0.0000e+000,20.00000,    -0.28880,0.98977
221.19701, 32.85333,-5.6128e-002,77.20525,50.00000,0.0000e+000,20.00000,    -0.27786,0.98762
222.93700, 33.03333,-6.9084e-002,77.15827,50.00000,0.0000e+000,20.00000,    -0.26760,0.98549
224.70000, 33.21333,-8.0914e-002,77.11277,50.00000,0.0000e+000,20.00000,    -0.25807,0.98335
226.43100, 33.39333,-9.2198e-002,77.06865,50.00000,0.0000e+000,20.00000,    -0.24923,0.98124
228.17599, 33.57333,    -0.10261,77.02596,50.00000,0.0000e+000,20.00000,    -0.24101,0.97912
229.91200, 33.75333,    -0.11278,76.98458,50.00000,0.0000e+000,20.00000,    -0.23340,0.97702
231.63800, 33.93333,    -0.12200,76.94459,50.00000,0.0000e+000,20.00000,    -0.22625,0.97494
233.36099, 34.11333,    -0.13107,76.90599,50.00000,0.0000e+000,20.00000,    -0.21957,0.97286
235.07300, 34.29333,    -0.13935,76.86853,50.00000,0.0000e+000,20.00000,    -0.21330,0.97080
236.75999, 34.47333,    -0.14721,76.83191,50.00000,0.0000e+000,20.00000,    -0.20754,0.96877
238.46899, 34.65333,    -0.15537,76.79635,50.00000,0.0000e+000,20.00000,    -0.20222,0.96672
240.16400, 34.83333,    -0.16402,76.76167,50.00000,0.0000e+000,20.00000,    -0.19719,0.96470
241.84599, 35.01333,    -0.17231,76.72770,50.00000,0.0000e+000,20.00000,    -0.19252,0.96269
243.55000, 35.19333,    -0.18028,76.69442,50.00000,0.0000e+000,20.00000,    -0.18811,0.96066
245.25101, 35.37333,    -0.18847,76.66178,50.00000,0.0000e+000,20.00000,    -0.18403,0.95864
246.95000, 35.55333,    -0.19691,76.62968,50.00000,0.0000e+000,20.00000,    -0.18018,0.95663
248.64799, 35.73333,    -0.20426,76.59832,50.00000,0.0000e+000,20.00000,    -0.17665,0.95462
250.34900, 35.91333,    -0.21122,76.56751,50.00000,0.0000e+000,20.00000,    -0.17345,0.95262
252.03700, 36.09333,    -0.21927,76.53725,50.00000,0.0000e+000,20.00000,    -0.17051,0.95063
253.75000, 36.27333,    -0.22672,76.50734,50.00000,0.0000e+000,20.00000,    -0.16781,0.94862
255.45500, 36.45333,    -0.23458,76.47789,50.00000,0.0000e+000,20.00000,    -0.16536,0.94662
257.17999, 36.63334,    -0.24211,76.44899,50.00000,0.0000e+000,20.00000,    -0.16316,0.94461
258.90900, 36.81333,    -0.24945,76.42031,50.00000,0.0000e+000,20.00000,    -0.16113,0.94259
260.63400, 36.99333,    -0.25585,76.39205,50.00000,0.0000e+000,20.00000,    -0.15933,0.94058
262.35101, 37.17333,    -0.26180,76.36404,50.00000,0.0000e+000,20.00000,    -0.15770,0.93859
264.09399, 37.35333,    -0.26790,76.33645,50.00000,0.0000e+000,20.00000,    -0.15622,0.93657
265.82199, 37.53333,    -0.27401,76.30913,50.00000,0.0000e+000,20.00000,    -0.15496,0.93458
267.55099, 37.71333,    -0.28002,76.28195,50.00000,0.0000e+000,20.00000,    -0.15387,0.93259
269.28000, 37.89333,    -0.28560,76.25507,50.00000,0.0000e+000,20.00000,    -0.15294,0.93060
271.01199, 38.07333,    -0.29093,76.22822,50.00000,0.0000e+000,20.00000,    -0.15209,0.92862
272.74899, 38.25333,    -0.29673,76.20142,50.00000,0.0000e+000,20.00000,    -0.15142,0.92663
274.47101, 38.43333,    -0.30218,76.17467,50.00000,0.0000e+000,20.00000,    -0.15092,0.92467
276.20599, 38.61333,    -0.30803,76.14799,50.00000,0.0000e+000,20.00000,    -0.15047,0.92269
277.94400, 38.79333,    -0.31431,76.12121,50.00000,0.0000e+000,20.00000,    -0.15014,0.92072
279.70901, 38.97333,    -0.32144,76.09443,50.00000,0.0000e+000,20.00000,    -0.14986,0.91873
281.45999, 39.15333,    -0.32737,76.06767,50.00000,0.0000e+000,20.00000,    -0.14977,0.91675
283.21100, 39.33333,    -0.33194,76.04078,50.00000,0.0000e+000,20.00000,    -0.14984,0.91478
284.94601, 39.51333,    -0.33562,76.01390,50.00000,0.0000e+000,20.00000,    -0.14995,0.91283
286.67999, 39.69333,    -0.33926,75.98695,50.00000,0.0000e+000,20.00000,    -0.15022,0.91089
288.39301, 39.87333,    -0.34384,75.96011,50.00000,0.0000e+000,20.00000,    -0.15057,0.90898
290.14099, 40.05333,    -0.34792,75.93303,50.00000,0.0000e+000,20.00000,    -0.15094,0.90703
291.85800, 40.23333,    -0.35251,75.90591,50.00000,0.0000e+000,20.00000,    -0.15139,0.90512
293.60400, 40.41333,    -0.35807,75.87882,50.00000,0.0000e+000,20.00000,    -0.15191,0.90319
295.33099, 40.59333,    -0.36433,75.85173,50.00000,0.0000e+000,20.00000,    -0.15248,0.90128
297.07700, 40.77333,    -0.37000,75.82471,50.00000,0.0000e+000,20.00000,    -0.15308,0.89936
298.84799, 40.95333,    -0.37610,75.79742,50.00000,0.0000e+000,20.00000,    -0.15380,0.89741
300.60400, 41.13334,    -0.38160,75.76985,50.00000,0.0000e+000,20.00000,    -0.15457,0.89549
302.36700, 41.31333,    -0.38655,75.74223,50.00000,0.0000e+000,20.00000,    -0.15544,0.89356
304.12799, 41.49333,    -0.39094,75.71441,50.00000,0.0000e+000,20.00000,    -0.15644,0.89164
305.89099, 41.67333,    -0.39506,75.68630,50.00000,0.0000e+000,20.00000,    -0.15761,0.88973
307.65100, 41.85333,    -0.39898,75.65812,50.00000,0.0000e+000,20.00000,    -0.15882,0.88782
309.41000, 42.03333,    -0.40247,75.62978,50.00000,0.0000e+000,20.00000,    -0.16019,0.88592
311.18500, 42.21333,    -0.40667,75.60121,50.00000,0.0000e+000,20.00000,    -0.16176,0.88401
312.95099, 42.39333,    -0.41062,75.57241,50.00000,0.0000e+000,20.00000,    -0.16355,0.88212
314.71301, 42.57333,    -0.41492,75.54346,50.00000,0.0000e+000,20.00000,    -0.16559,0.88023
316.49701, 42.75333,    -0.41900,75.51414,50.00000,0.0000e+000,20.00000,    -0.16776,0.87832
318.25299, 42.93333,    -0.42267,75.48449,50.00000,0.0000e+000,20.00000,    -0.16999,0.87646
320.03201, 43.11333,    -0.42562,75.45447,50.00000,0.0000e+000,20.00000,    -0.17245,0.87457
321.79199, 43.29333,    -0.42899,75.42398,50.00000,0.0000e+000,20.00000,    -0.17508,0.87271
323.56699, 43.47333,    -0.43268,75.39295,50.00000,0.0000e+000,20.00000,    -0.17786,0.87083
325.34799, 43.65333,    -0.43608,75.36152,50.00000,0.0000e+000,20.00000,    -0.18089,0.86896
327.11200, 43.83333,    -0.43866,75.32950,50.00000,0.0000e+000,20.00000,    -0.18414,0.86711
328.90201, 44.01333,    -0.44081,75.29679,50.00000,0.0000e+000,20.00000,    -0.18750,0.86524
330.67099, 44.19333,    -0.44287,75.26329,50.00000,0.0000e+000,20.00000,    -0.19098,0.86340
332.43900, 44.37333,    -0.44533,75.22893,50.00000,0.0000e+000,20.00000,    -0.19470,0.86156
334.19901, 44.55333,    -0.44737,75.19387,50.00000,0.0000e+000,20.00000,    -0.19858,0.85974
335.95099, 44.73333,    -0.44979,75.15825,50.00000,0.0000e+000,20.00000,    -0.20256,0.85793
337.72900, 44.91333,    -0.45234,75.12178,50.00000,0.0000e+000,20.00000,    -0.20660,0.85610
339.49899, 45.09333,    -0.45488,75.08452,50.00000,0.0000e+000,20.00000,    -0.21060,0.85429
341.27701, 45.27333,    -0.45846,75.04644,50.00000,0.0000e+000,20.00000,    -0.21461,0.85247
343.06000, 45.45333,    -0.46265,75.00732,50.00000,0.0000e+000,20.00000,    -0.21865,0.85065
344.84299, 45.63334,    -0.46643,74.96729,50.00000,0.0000e+000,20.00000,    -0.22253,0.84884
346.63501, 45.81333,    -0.46985,74.92658,50.00000,0.0000e+000,20.00000,    -0.22619,0.84702
348.41501, 45.99333,    -0.47268,74.88518,50.00000,0.0000e+000,20.00000,    -0.22965,0.84523
350.20599, 46.17333,    -0.47621,74.84283,50.00000,0.0000e+000,20.00000,    -0.23281,0.84343
351.99600, 46.35333,    -0.47973,74.79951,50.00000,0.0000e+000,20.00000,    -0.23569,0.84163
353.78400, 46.53333,    -0.48324,74.75546,50.00000,0.0000e+000,20.00000,    -0.23841,0.83984
355.55099, 46.71333,    -0.48653,74.71084,50.00000,0.0000e+000,20.00000,    -0.24082,0.83808
357.33801, 46.89333,    -0.48989,74.66583,50.00000,0.0000e+000,20.00000,    -0.24291,0.83631
359.12601, 47.07333,    -0.49403,74.62030,50.00000,0.0000e+000,20.00000,    -0.24462,0.83454
360.89899, 47.25333,    -0.49840,74.57424,50.00000,0.0000e+000,20.00000,    -0.24584,0.83279
362.69501, 47.43333,    -0.50330,74.52812,50.00000,0.0000e+000,20.00000,    -0.24661,0.83102
364.48700, 47.61333,    -0.50811,74.48214,50.00000,0.0000e+000,20.00000,    -0.24702,0.82927
366.26599, 47.79333,    -0.51221,74.43610,50.00000,0.0000e+000,20.00000,    -0.24707,0.82753
368.05399, 47.97333,    -0.51694,74.39031,50.00000,0.0000e+000,20.00000,    -0.24662,0.82579
369.85901, 48.15333,    -0.52213,74.34477,50.00000,0.0000e+000,20.00000,    -0.24560,0.82404
371.64700, 48.33333,    -0.52518,74.29931,50.00000,0.0000e+000,20.00000,    -0.24409,0.82231
373.43100, 48.51333,    -0.52807,74.25408,50.00000,0.0000e+000,20.00000,    -0.24214,0.82060
375.20200, 48.69333,    -0.53071,74.20923,50.00000,0.0000e+000,20.00000,    -0.23980,0.81890
376.97501, 48.87333,    -0.53468,74.16492,50.00000,0.0000e+000,20.00000,    -0.23707,0.81720
378.73300, 49.05333,    -0.53925,74.12138,50.00000,0.0000e+000,20.00000,    -0.23392,0.81552
380.51099, 49.23333,    -0.54375,74.07857,50.00000,0.0000e+000,20.00000,    -0.23050,0.81383
382.27899, 49.41333,    -0.54856,74.03636,50.00000,0.0000e+000,20.00000,    -0.22699,0.81216
384.07001, 49.59333,    -0.55438,73.99480,50.00000,0.0000e+000,20.00000,    -0.22324,0.81047
385.85501, 49.77333,    -0.56201,73.95407,50.00000,0.0000e+000,20.00000,    -0.21935,0.80879
387.63800, 49.95333,    -0.57034,73.91449,50.00000,0.0000e+000,20.00000,    -0.21537,0.80712
389.44000, 50.13334,    -0.57836,73.87588,50.00000,0.0000e+000,20.00000,    -0.21132,0.80544
391.23499, 50.31333,    -0.58406,73.83831,50.00000,0.0000e+000,20.00000,    -0.20716,0.80377
393.01501, 50.49333,    -0.58939,73.80179,50.00000,0.0000e+000,20.00000,    -0.20295,0.80212
394.81400, 50.67333,    -0.59462,73.76616,50.00000,0.0000e+000,20.00000,    -0.19877,0.80046
396.59000, 50.85333,    -0.60026,73.73153,50.00000,0.0000e+000,20.00000,    -0.19465,0.79883
398.37500, 51.03333,    -0.60578,73.69778,50.00000,0.0000e+000,20.00000,    -0.19059,0.79719
400.15302, 51.21333,    -0.61133,73.66452,50.00000,0.0000e+000,20.00000,    -0.18655,0.79557
401.94800, 51.39333,    -0.61704,73.63205,50.00000,0.0000e+000,20.00000,    -0.18256,0.79394
403.73001, 51.57333,    -0.62230,73.60035,50.00000,0.0000e+000,20.00000,    -0.17863,0.79232
405.49600, 51.75333,    -0.62744,73.56927,50.00000,0.0000e+000,20.00000,    -0.17490,0.79073
407.26300, 51.93333,    -0.63181,73.53851,50.00000,0.0000e+000,20.00000,    -0.17135,0.78914
409.04300, 52.11333,    -0.63778,73.50837,50.00000,0.0000e+000,20.00000,    -0.16803,0.78754
410.83701, 52.29333,    -0.64429,73.47878,50.00000,0.0000e+000,20.00000,    -0.16496,0.78594
412.65399, 52.47333,    -0.65092,73.44957,50.00000,0.0000e+000,20.00000,    -0.16204,0.78432
414.45499, 52.65333,    -0.65699,73.42088,50.00000,0.0000e+000,20.00000,    -0.15933,0.78272
416.25400, 52.83333,    -0.66205,73.39271,50.00000,0.0000e+000,20.00000,    -0.15681,0.78113
418.05099, 53.01333,    -0.66638,73.36509,50.00000,0.0000e+000,20.00000,    -0.15437,0.77955
419.85599, 53.19333,    -0.66949,73.33796,50.00000,0.0000e+000,20.00000,    -0.15205,0.77797
421.64001, 53.37333,    -0.67254,73.31133,50.00000,0.0000e+000,20.00000,    -0.14986,0.77641
423.42300, 53.55333,    -0.67648,73.28516,50.00000,0.0000e+000,20.00000,    -0.14775,0.77486
425.21799, 53.73333,    -0.68041,73.25936,50.00000,0.0000e+000,20.00000,    -0.14559,0.77331
426.99799, 53.91333,    -0.68458,73.23377,50.00000,0.0000e+000,20.00000,    -0.14346,0.77177
428.78400, 54.09333,    -0.68821,73.20827,50.00000,0.0000e+000,20.00000,    -0.14142,0.77023
430.53699, 54.27333,    -0.69010,73.18308,50.00000,0.0000e+000,20.00000,    -0.13931,0.76873
432.29999, 54.45333,    -0.69211,73.15817,50.00000,0.0000e+000,20.00000,    -0.13726,0.76723
434.09201, 54.63334,    -0.69737,73.13351,50.00000,0.0000e+000,20.00000,    -0.13527,0.76571
435.87900, 54.81333,    -0.70471,73.10904,50.00000,0.0000e+000,20.00000,    -0.13339,0.76419
437.68201, 54.99333,    -0.71017,73.08488,50.00000,0.0000e+000,20.00000,    -0.13158,0.76267
439.46799, 55.17333,    -0.71418,73.06103,50.00000,0.0000e+000,20.00000,    -0.12982,0.76117
441.26099, 55.35333,    -0.71771,73.03752,50.00000,0.0000e+000,20.00000,    -0.12814,0.75967
443.05099, 55.53333,    -0.72156,73.01450,50.00000,0.0000e+000,20.00000,    -0.12652,0.75818
444.85800, 55.71333,    -0.72564,72.99199,50.00000,0.0000e+000,20.00000,    -0.12480,0.75668
446.64099, 55.89333,    -0.72937,72.96976,50.00000,0.0000e+000,20.00000,    -0.12304,0.75520
448.43900, 56.07333,    -0.73355,72.94809,50.00000,0.0000e+000,20.00000,    -0.12128,0.75372
450.24301, 56.25333,    -0.73753,72.92679,50.00000,0.0000e+000,20.00000,    -0.11954,0.75224
452.04199, 56.43333,    -0.74044,72.90576,50.00000,0.0000e+000,20.00000,    -0.11782,0.75077
453.83499, 56.61333,    -0.74330,72.88491,50.00000,0.0000e+000,20.00000,    -0.11604,0.74931
455.61899, 56.79333,    -0.74657,72.86428,50.00000,0.0000e+000,20.00000,    -0.11427,0.74787
457.39499, 56.97333,    -0.75050,72.84395,50.00000,0.0000e+000,20.00000,    -0.11254,0.74643
459.18900, 57.15333,    -0.75476,72.82383,50.00000,0.0000e+000,20.00000,    -0.11084,0.74499
460.96799, 57.33333,    -0.75915,72.80388,50.00000,0.0000e+000,20.00000,    -0.10921,0.74356
462.75699, 57.51333,    -0.76356,72.78447,50.00000,0.0000e+000,20.00000,    -0.10767,0.74214
464.53299, 57.69333,    -0.76775,72.76533,50.00000,0.0000e+000,20.00000,    -0.10620,0.74073
466.31299, 57.87333,    -0.77201,72.74649,50.00000,0.0000e+000,20.00000,    -0.10491,0.73932
468.10599, 58.05333,    -0.77664,72.72789,50.00000,0.0000e+000,20.00000,    -0.10371,0.73790
469.89200, 58.23333,    -0.78071,72.70943,50.00000,0.0000e+000,20.00000,    -0.10248,0.73650
471.67899, 58.41333,    -0.78495,72.69139,50.00000,0.0000e+000,20.00000,    -0.10128,0.73511
473.49100, 58.59333,    -0.78975,72.67357,50.00000,0.0000e+000,20.00000,    -0.10009,0.73370
475.29800, 58.77333,    -0.79422,72.65598,50.00000,0.0000e+000,20.00000,-9.8928e-002,0.73229
477.09399, 58.95333,    -0.79803,72.63860,50.00000,0.0000e+000,20.00000,-9.7744e-002,0.73091
478.89600, 59.13334,    -0.80087,72.62144,50.00000,0.0000e+000,20.00000,-9.6553e-002,0.72952
480.68301, 59.31333,    -0.80439,72.60446,50.00000,0.0000e+000,20.00000,-9.5528e-002,0.72815
482.48001, 59.49333,    -0.80668,72.58753,50.00000,0.0000e+000,20.00000,-9.4600e-002,0.72678
484.26999, 59.67333,    -0.81001,72.57053,50.00000,0.0000e+000,20.00000,-9.3701e-002,0.72543
486.07800, 59.85333,    -0.81481,72.55354,50.00000,0.0000e+000,20.00000,-9.2820e-002,0.72406
487.88101, 60.03333,    -0.82021,72.53690,50.00000,0.0000e+000,20.00000,-9.1925e-002,0.72270
489.68900, 60.21333,    -0.82364,72.52040,50.00000,0.0000e+000,20.00000,-9.1096e-002,0.72134
491.48499, 60.39333,    -0.82576,72.50407,50.00000,0.0000e+000,20.00000,-9.0253e-002,0.72000
493.27499, 60.57333,    -0.82715,72.48790,50.00000,0.0000e+000,20.00000,-8.9438e-002,0.71867
495.04300, 60.75333,    -0.82816,72.47204,50.00000,0.0000e+000,20.00000,-8.8663e-002,0.71736
496.83499, 60.93333,    -0.82918,72.45638,50.00000,0.0000e+000,20.00000,-8.7925e-002,0.71604
498.60101, 61.11333,    -0.83330,72.44065,50.00000,0.0000e+000,20.00000,-8.7234e-002,0.71475
500.39001, 61.29333,    -0.83781,72.42487,50.00000,0.0000e+000,20.00000,-8.6508e-002,0.71344
502.17801, 61.47333,    -0.84148,72.40926,50.00000,0.0000e+000,20.00000,-8.5675e-002,0.71214
503.98300, 61.65333,    -0.84498,72.39382,50.00000,0.0000e+000,20.00000,-8.4768e-002,0.71083
505.76501, 61.83333,    -0.84807,72.37857,50.00000,0.0000e+000,20.00000,-8.3930e-002,0.70954
507.55301, 62.01333,    -0.85159,72.36345,50.00000,0.0000e+000,20.00000,-8.3089e-002,0.70826
509.34399, 62.19333,    -0.85569,72.34864,50.00000,0.0000e+000,20.00000,-8.2279e-002,0.70697
511.18201, 62.37333,    -0.86354,72.33398,50.00000,0.0000e+000,20.00000,-8.1513e-002,0.70567
513.00897, 62.55333,    -0.86915,72.31940,50.00000,0.0000e+000,20.00000,-8.0847e-002,0.70437
514.82501, 62.73333,    -0.87185,72.30488,50.00000,0.0000e+000,20.00000,-8.0228e-002,0.70309
516.60498, 62.91333,    -0.87243,72.29041,50.00000,0.0000e+000,20.00000,-7.9555e-002,0.70183
518.39502, 63.09333,    -0.87198,72.27610,50.00000,0.0000e+000,20.00000,-7.8795e-002,0.70058
520.19299, 63.27333,    -0.87426,72.26210,50.00000,0.0000e+000,20.00000,-7.8056e-002,0.69933
521.97498, 63.45333,    -0.87581,72.24838,50.00000,0.0000e+000,20.00000,-7.7362e-002,0.69809
523.77100, 63.63334,    -0.87763,72.23475,50.00000,0.0000e+000,20.00000,-7.6683e-002,0.69685
525.55902, 63.81333,    -0.88049,72.22126,50.00000,0.0000e+000,20.00000,-7.5995e-002,0.69562
527.34399, 63.99333,    -0.88392,72.20788,50.00000,0.0000e+000,20.00000,-7.5452e-002,0.69439
529.14398, 64.17333,    -0.88734,72.19448,50.00000,0.0000e+000,20.00000,-7.4910e-002,0.69316
530.92499, 64.35333,    -0.89019,72.18100,50.00000,0.0000e+000,20.00000,-7.4388e-002,0.69195
532.71802, 64.53333,    -0.89205,72.16759,50.00000,0.0000e+000,20.00000,-7.3880e-002,0.69074
534.51300, 64.71333,    -0.89454,72.15432,50.00000,0.0000e+000,20.00000,-7.3345e-002,0.68953
536.28101, 64.89333,    -0.89775,72.14127,50.00000,0.0000e+000,20.00000,-7.2807e-002,0.68835
538.07898, 65.07333,    -0.90113,72.12832,50.00000,0.0000e+000,20.00000,-7.2316e-002,0.68714
539.88599, 65.25333,    -0.90464,72.11539,50.00000,0.0000e+000,20.00000,-7.1905e-002,0.68594
541.68799, 65.43333,    -0.90868,72.10255,50.00000,0.0000e+000,20.00000,-7.1545e-002,0.68475
543.48297, 65.61333,    -0.91237,72.08992,50.00000,0.0000e+000,20.00000,-7.1213e-002,0.68357
545.27698, 65.79333,    -0.91403,72.07708,50.00000,0.0000e+000,20.00000,-7.0891e-002,0.68239
547.05902, 65.97334,    -0.91482,72.06435,50.00000,0.0000e+000,20.00000,-7.0470e-002,0.68123
548.85602, 66.15334,    -0.91805,72.05167,50.00000,0.0000e+000,20.00000,-6.9966e-002,0.68006
550.67499, 66.33334,    -0.92367,72.03900,50.00000,0.0000e+000,20.00000,-6.9455e-002,0.67888
552.49597, 66.51334,    -0.92850,72.02645,50.00000,0.0000e+000,20.00000,-6.8932e-002,0.67770
554.30701, 66.69334,    -0.93205,72.01404,50.00000,0.0000e+000,20.00000,-6.8444e-002,0.67654
556.11499, 66.87334,    -0.93323,72.00174,50.00000,0.0000e+000,20.00000,-6.7922e-002,0.67539
557.90302, 67.05334,    -0.93462,71.98951,50.00000,0.0000e+000,20.00000,-6.7371e-002,0.67425
559.75299, 67.23333,    -0.94016,71.97723,50.00000,0.0000e+000,20.00000,-6.6828e-002,0.67308
561.59497, 67.41333,    -0.94591,71.96490,50.00000,0.0000e+000,20.00000,-6.6278e-002,0.67191
563.41699, 67.59333,    -0.94902,71.95268,50.00000,0.0000e+000,20.00000,-6.5638e-002,0.67077
565.22601, 67.77333,    -0.94876,71.94073,50.00000,0.0000e+000,20.00000,-6.5033e-002,0.66964
567.00201, 67.95333,    -0.94652,71.92910,50.00000,0.0000e+000,20.00000,-6.4427e-002,0.66853
568.77002, 68.13333,    -0.94428,71.91752,50.00000,0.0000e+000,20.00000,-6.3822e-002,0.66744
570.53699, 68.31333,    -0.94212,71.90611,50.00000,0.0000e+000,20.00000,-6.3237e-002,0.66635
572.28400, 68.49333,    -0.94346,71.89479,50.00000,0.0000e+000,20.00000,-6.2686e-002,0.66528
574.06000, 68.67333,    -0.94742,71.88372,50.00000,0.0000e+000,20.00000,-6.2184e-002,0.66419
575.86603, 68.85333,    -0.95468,71.87277,50.00000,0.0000e+000,20.00000,-6.1699e-002,0.66309
577.67102, 69.03333,    -0.95975,71.86188,50.00000,0.0000e+000,20.00000,-6.1216e-002,0.66200
579.46002, 69.21333,    -0.96362,71.85122,50.00000,0.0000e+000,20.00000,-6.0692e-002,0.66092
581.26001, 69.39333,    -0.96700,71.84073,50.00000,0.0000e+000,20.00000,-6.0219e-002,0.65983
583.06000, 69.57333,    -0.96946,71.83021,50.00000,0.0000e+000,20.00000,-5.9861e-002,0.65876
584.85498, 69.75333,    -0.97147,71.81973,50.00000,0.0000e+000,20.00000,-5.9693e-002,0.65769
586.63599, 69.93333,    -0.97373,71.80925,50.00000,0.0000e+000,20.00000,-5.9581e-002,0.65663
588.43701, 70.11333,    -0.97562,71.79883,50.00000,0.0000e+000,20.00000,-5.9537e-002,0.65557
590.22400, 70.29333,    -0.97820,71.78840,50.00000,0.0000e+000,20.00000,-5.9560e-002,0.65452
592.02502, 70.47334,    -0.98057,71.77794,50.00000,0.0000e+000,20.00000,-5.9733e-002,0.65346
593.83002, 70.65334,    -0.98458,71.76746,50.00000,0.0000e+000,20.00000,-6.0003e-002,0.65241
595.62799, 70.83334,    -0.98798,71.75696,50.00000,0.0000e+000,20.00000,-6.0311e-002,0.65137
597.42902, 71.01334,    -0.98934,71.74654,50.00000,0.0000e+000,20.00000,-6.0750e-002,0.65033
599.25299, 71.19334,    -0.99521,71.73604,50.00000,0.0000e+000,20.00000,-6.1310e-002,0.64928
601.09802, 71.37334,    -1.00073,71.72540,50.00000,0.0000e+000,20.00000,-6.1903e-002,0.64822
602.92798, 71.55334,    -1.00408,71.71438,50.00000,0.0000e+000,20.00000,-6.2521e-002,0.64718
604.71301, 71.73333,    -1.00376,71.70324,50.00000,0.0000e+000,20.00000,-6.3130e-002,0.64617
606.51202, 71.91333,    -1.00133,71.69195,50.00000,0.0000e+000,20.00000,-6.3756e-002,0.64515
608.28302, 72.09333,    -1.00029,71.68059,50.00000,0.0000e+000,20.00000,-6.4418e-002,0.64416
610.07898, 72.27333,    -0.99995,71.66887,50.00000,0.0000e+000,20.00000,-6.5107e-002,0.64315
611.86200, 72.45333,    -1.00250,71.65696,50.00000,0.0000e+000,20.00000,-6.5854e-002,0.64216
613.66803, 72.63333,    -1.00563,71.64495,50.00000,0.0000e+000,20.00000,-6.6646e-002,0.64115
615.49597, 72.81333,    -1.01032,71.63272,50.00000,0.0000e+000,20.00000,-6.7506e-002,0.64014
617.31403, 72.99333,    -1.01476,71.62020,50.00000,0.0000e+000,20.00000,-6.8467e-002,0.63914
619.14502, 73.17333,    -1.01765,71.60750,50.00000,0.0000e+000,20.00000,-6.9416e-002,0.63814
620.95300, 73.35333,    -1.01982,71.59475,50.00000,0.0000e+000,20.00000,-7.0318e-002,0.63715
622.76599, 73.53333,    -1.02048,71.58203,50.00000,0.0000e+000,20.00000,-7.1222e-002,0.63617
624.55798, 73.71333,    -1.01970,71.56935,50.00000,0.0000e+000,20.00000,-7.2140e-002,0.63520
626.34399, 73.89333,    -1.01805,71.55653,50.00000,0.0000e+000,20.00000,-7.3122e-002,0.63424
628.13501, 74.07333,    -1.01785,71.54356,50.00000,0.0000e+000,20.00000,-7.4087e-002,0.63328
629.92700, 74.25333,    -1.01920,71.53040,50.00000,0.0000e+000,20.00000,-7.5081e-002,0.63232
631.73102, 74.43333,    -1.02284,71.51703,50.00000,0.0000e+000,20.00000,-7.6173e-002,0.63136
633.54303, 74.61333,    -1.02622,71.50349,50.00000,0.0000e+000,20.00000,-7.7297e-002,0.63041
635.35498, 74.79333,    -1.02863,71.48957,50.00000,0.0000e+000,20.00000,-7.8404e-002,0.62945
637.15601, 74.97334,    -1.02970,71.47549,50.00000,0.0000e+000,20.00000,-7.9523e-002,0.62851
638.97400, 75.15334,    -1.03126,71.46126,50.00000,0.0000e+000,20.00000,-8.0733e-002,0.62756
640.77399, 75.33334,    -1.03434,71.44685,50.00000,0.0000e+000,20.00000,-8.2051e-002,0.62662
642.55902, 75.51334,    -1.03452,71.43226,50.00000,0.0000e+000,20.00000,-8.3536e-002,0.62570
644.34198, 75.69334,    -1.03463,71.41738,50.00000,0.0000e+000,20.00000,-8.5055e-002,0.62478
646.15601, 75.87334,    -1.03749,71.40223,50.00000,0.0000e+000,20.00000,-8.6556e-002,0.62385
647.97498, 76.05334,    -1.03994,71.38676,50.00000,0.0000e+000,20.00000,-8.8052e-002,0.62292
649.79303, 76.23333,    -1.04207,71.37083,50.00000,0.0000e+000,20.00000,-8.9506e-002,0.62199
651.61298, 76.41333,    -1.04391,71.35459,50.00000,0.0000e+000,20.00000,-9.0956e-002,0.62107
653.40802, 76.59333,    -1.04505,71.33811,50.00000,0.0000e+000,20.00000,-9.2331e-002,0.62016
655.21100, 76.77333,    -1.04557,71.32138,50.00000,0.0000e+000,20.00000,-9.3648e-002,0.61925
656.99902, 76.95333,    -1.04517,71.30427,50.00000,0.0000e+000,20.00000,-9.4978e-002,0.61836
658.79999, 77.13333,    -1.04529,71.28676,50.00000,0.0000e+000,20.00000,-9.6292e-002,0.61746
660.60400, 77.31333,    -1.04700,71.26875,50.00000,0.0000e+000,20.00000,-9.7577e-002,0.61657
662.39697, 77.49333,    -1.04871,71.25040,50.00000,0.0000e+000,20.00000,-9.8814e-002,0.61568
664.20599, 77.67333,    -1.05055,71.23202,50.00000,0.0000e+000,20.00000,-9.9971e-002,0.61479
666.01501, 77.85333,    -1.05243,71.21345,50.00000,0.0000e+000,20.00000,    -0.10099,0.61390
667.79901, 78.03333,    -1.05353,71.19479,50.00000,0.0000e+000,20.00000,    -0.10181,0.61303
669.60602, 78.21333,    -1.05462,71.17602,50.00000,0.0000e+000,20.00000,    -0.10247,0.61215
671.37799, 78.39333,    -1.05577,71.15713,50.00000,0.0000e+000,20.00000,    -0.10301,0.61129
673.15900, 78.57333,    -1.05617,71.13825,50.00000,0.0000e+000,20.00000,    -0.10346,0.61044
674.95398, 78.75333,    -1.05908,71.11923,50.00000,0.0000e+000,20.00000,    -0.10371,0.60957
676.75598, 78.93333,    -1.06490,71.10003,50.00000,0.0000e+000,20.00000,    -0.10381,0.60871
678.56897, 79.11333,    -1.06965,71.08081,50.00000,0.0000e+000,20.00000,    -0.10368,0.60785
680.37000, 79.29333,    -1.07252,71.06144,50.00000,0.0000e+000,20.00000,    -0.10338,0.60699
682.17999, 79.47334,    -1.07622,71.04211,50.00000,0.0000e+000,20.00000,    -0.10304,0.60614
684.00201, 79.65334,    -1.08000,71.02292,50.00000,0.0000e+000,20.00000,    -0.10265,0.60528
685.80701, 79.83334,    -1.08340,71.00404,50.00000,0.0000e+000,20.00000,    -0.10217,0.60443
687.61700, 80.01334,    -1.08479,70.98541,50.00000,0.0000e+000,20.00000,    -0.10162,0.60359
689.41498, 80.19334,    -1.08579,70.96697,50.00000,0.0000e+000,20.00000,    -0.10097,0.60275
691.22198, 80.37334,    -1.08790,70.94862,50.00000,0.0000e+000,20.00000,    -0.10028,0.60191
693.01501, 80.55334,    -1.08903,70.93056,50.00000,0.0000e+000,20.00000,-9.9507e-002,0.60109
694.81702, 80.73333,    -1.09047,70.91275,50.00000,0.0000e+000,20.00000,-9.8606e-002,0.60026
696.61499, 80.91333,    -1.09130,70.89524,50.00000,0.0000e+000,20.00000,-9.7621e-002,0.59943
698.41101, 81.09333,    -1.09306,70.87796,50.00000,0.0000e+000,20.00000,-9.6453e-002,0.59862
700.21503, 81.27333,    -1.09513,70.86085,50.00000,0.0000e+000,20.00000,-9.5292e-002,0.59780
702.02502, 81.45333,    -1.09784,70.84373,50.00000,0.0000e+000,20.00000,-9.4111e-002,0.59698
703.87000, 81.63333,    -1.10331,70.82679,50.00000,0.0000e+000,20.00000,-9.2970e-002,0.59614
705.67999, 81.81333,    -1.10482,70.81003,50.00000,0.0000e+000,20.00000,-9.1896e-002,0.59533
707.47400, 81.99333,    -1.10466,70.79348,50.00000,0.0000e+000,20.00000,-9.0870e-002,0.59453
709.27301, 82.17333,    -1.10344,70.77714,50.00000,0.0000e+000,20.00000,-8.9783e-002,0.59373
711.07800, 82.35333,    -1.10538,70.76092,50.00000,0.0000e+000,20.00000,-8.8729e-002,0.59292
712.90002, 82.53333,    -1.10871,70.74497,50.00000,0.0000e+000,20.00000,-8.7720e-002,0.59212
714.70502, 82.71333,    -1.11010,70.72931,50.00000,0.0000e+000,20.00000,-8.6740e-002,0.59132
716.53003, 82.89333,    -1.11242,70.71416,50.00000,0.0000e+000,20.00000,-8.5781e-002,0.59052
718.33099, 83.07333,    -1.11228,70.69908,50.00000,0.0000e+000,20.00000,-8.4796e-002,0.58973
720.12799, 83.25333,    -1.11154,70.68414,50.00000,0.0000e+000,20.00000,-8.3760e-002,0.58895
721.89801, 83.43333,    -1.11166,70.66937,50.00000,0.0000e+000,20.00000,-8.2707e-002,0.58818
723.69897, 83.61333,    -1.11379,70.65462,50.00000,0.0000e+000,20.00000,-8.1649e-002,0.58740
725.49200, 83.79333,    -1.11584,70.63990,50.00000,0.0000e+000,20.00000,-8.0591e-002,0.58663
727.28003, 83.97334,    -1.11751,70.62546,50.00000,0.0000e+000,20.00000,-7.9547e-002,0.58586
729.07898, 84.15334,    -1.11932,70.61117,50.00000,0.0000e+000,20.00000,-7.8375e-002,0.58509
730.89301, 84.33334,    -1.12238,70.59701,50.00000,0.0000e+000,20.00000,-7.7185e-002,0.58432
732.69598, 84.51334,    -1.12427,70.58299,50.00000,0.0000e+000,20.00000,-7.6028e-002,0.58355
734.50403, 84.69334,    -1.12485,70.56914,50.00000,0.0000e+000,20.00000,-7.4989e-002,0.58278
736.29498, 84.87334,    -1.12469,70.55559,50.00000,0.0000e+000,20.00000,-7.3883e-002,0.58203
738.09698, 85.05334,    -1.12588,70.54220,50.00000,0.0000e+000,20.00000,-7.2722e-002,0.58127
739.89301, 85.23333,    -1.12731,70.52907,50.00000,0.0000e+000,20.00000,-7.1559e-002,0.58052
741.68402, 85.41333,    -1.12783,70.51611,50.00000,0.0000e+000,20.00000,-7.0271e-002,0.57977
743.49597, 85.59333,    -1.13062,70.50335,50.00000,0.0000e+000,20.00000,-6.8916e-002,0.57901
745.31598, 85.77333,    -1.13432,70.49080,50.00000,0.0000e+000,20.00000,-6.7603e-002,0.57826
747.12000, 85.95333,    -1.13568,70.47872,50.00000,0.0000e+000,20.00000,-6.6329e-002,0.57751
748.92902, 86.13333,    -1.13520,70.46703,50.00000,0.0000e+000,20.00000,-6.5030e-002,0.57676
750.72699, 86.31333,    -1.13526,70.45554,50.00000,0.0000e+000,20.00000,-6.3719e-002,0.57603
752.53400, 86.49333,    -1.13477,70.44412,50.00000,0.0000e+000,20.00000,-6.2380e-002,0.57528
754.33099, 86.67333,    -1.13426,70.43300,50.00000,0.0000e+000,20.00000,-6.1159e-002,0.57455
756.14600, 86.85333,    -1.13523,70.42225,50.00000,0.0000e+000,20.00000,-5.9940e-002,0.57381
757.94897, 87.03333,    -1.13661,70.41169,50.00000,0.0000e+000,20.00000,-5.8787e-002,0.57308
759.75098, 87.21333,    -1.13781,70.40154,50.00000,0.0000e+000,20.00000,-5.7697e-002,0.57235
761.57300, 87.39333,    -1.13896,70.39173,50.00000,0.0000e+000,20.00000,-5.6625e-002,0.57162
763.37799, 87.57333,    -1.13960,70.38203,50.00000,0.0000e+000,20.00000,-5.5605e-002,0.57089
765.19501, 87.75333,    -1.13831,70.37239,50.00000,0.0000e+000,20.00000,-5.4688e-002,0.57016
766.99103, 87.93333,    -1.13738,70.36291,50.00000,0.0000e+000,20.00000,-5.3952e-002,0.56945
768.77802, 88.11333,    -1.13601,70.35364,50.00000,0.0000e+000,20.00000,-5.3258e-002,0.56873
770.58197, 88.29333,    -1.13522,70.34459,50.00000,0.0000e+000,20.00000,-5.2622e-002,0.56802
772.37903, 88.47334,    -1.13473,70.33552,50.00000,0.0000e+000,20.00000,-5.2099e-002,0.56731
774.19202, 88.65334,    -1.13723,70.32652,50.00000,0.0000e+000,20.00000,-5.1750e-002,0.56659
776.00702, 88.83334,    -1.13874,70.31758,50.00000,0.0000e+000,20.00000,-5.1436e-002,0.56588
777.81201, 89.01334,    -1.13608,70.30858,50.00000,0.0000e+000,20.00000,-5.1201e-002,0.56517
779.60303, 89.19334,    -1.13311,70.29967,50.00000,0.0000e+000,20.00000,-5.1145e-002,0.56447
781.41302, 89.37334,    -1.13340,70.29080,50.00000,0.0000e+000,20.00000,-5.1127e-002,0.56376
783.24103, 89.55334,    -1.13575,70.28203,50.00000,0.0000e+000,20.00000,-5.1143e-002,0.56305
785.04303, 89.73333,    -1.13645,70.27297,50.00000,0.0000e+000,20.00000,-5.1200e-002,0.56235
786.85797, 89.91333,    -1.13441,70.26399,50.00000,0.0000e+000,20.00000,-5.1340e-002,0.56165
788.65900, 90.09333,    -1.13349,70.25491,50.00000,0.0000e+000,20.00000,-5.1538e-002,0.56095
790.47803, 90.27333,    -1.13390,70.24569,50.00000,0.0000e+000,20.00000,-5.1818e-002,0.56025
792.29901, 90.45333,    -1.13535,70.23618,50.00000,0.0000e+000,20.00000,-5.2123e-002,0.55955
794.11298, 90.63333,    -1.13493,70.22676,50.00000,0.0000e+000,20.00000,-5.2472e-002,0.55886
795.91998, 90.81333,    -1.13400,70.21737,50.00000,0.0000e+000,20.00000,-5.2744e-002,0.55817
797.70898, 90.99333,    -1.13167,70.20775,50.00000,0.0000e+000,20.00000,-5.3070e-002,0.55748
799.49902, 91.17333,    -1.12923,70.19815,50.00000,0.0000e+000,20.00000,-5.3465e-002,0.55680
801.28699, 91.35333,    -1.12902,70.18841,50.00000,0.0000e+000,20.00000,-5.3945e-002,0.55613
803.09399, 91.53333,    -1.12810,70.17870,50.00000,0.0000e+000,20.00000,-5.4327e-002,0.55544
804.87500, 91.71333,    -1.12581,70.16892,50.00000,0.0000e+000,20.00000,-5.4774e-002,0.55477
806.66803, 91.89333,    -1.12515,70.15909,50.00000,0.0000e+000,20.00000,-5.5234e-002,0.55410
808.46100, 92.07333,    -1.12460,70.14905,50.00000,0.0000e+000,20.00000,-5.5726e-002,0.55342
810.26001, 92.25333,    -1.12564,70.13891,50.00000,0.0000e+000,20.00000,-5.6128e-002,0.55275
812.06598, 92.43333,    -1.12713,70.12871,50.00000,0.0000e+000,20.00000,-5.6576e-002,0.55207
813.88898, 92.61333,    -1.13030,70.11869,50.00000,0.0000e+000,20.00000,-5.7075e-002,0.55139
815.72601, 92.79333,    -1.13280,70.10861,50.00000,0.0000e+000,20.00000,-5.7601e-002,0.55071
817.54498, 92.97334,    -1.13159,70.09830,50.00000,0.0000e+000,20.00000,-5.8190e-002,0.55004
819.37000, 93.15334,    -1.13423,70.08783,50.00000,0.0000e+000,20.00000,-5.8768e-002,0.54936
821.19800, 93.33334,    -1.13435,70.07736,50.00000,0.0000e+000,20.00000,-5.9433e-002,0.54868
823.01703, 93.51334,    -1.13214,70.06678,50.00000,0.0000e+000,20.00000,-6.0180e-002,0.54801
824.82898, 93.69334,    -1.12927,70.05606,50.00000,0.0000e+000,20.00000,-6.0992e-002,0.54735
826.62598, 93.87334,    -1.12622,70.04514,50.00000,0.0000e+000,20.00000,-6.1823e-002,0.54669
828.40900, 94.05334,    -1.12217,70.03415,50.00000,0.0000e+000,20.00000,-6.2707e-002,0.54603
830.19299, 94.23333,    -1.11979,70.02312,50.00000,0.0000e+000,20.00000,-6.3574e-002,0.54538
831.96802, 94.41333,    -1.11611,70.01195,50.00000,0.0000e+000,20.00000,-6.4553e-002,0.54473
833.75098, 94.59333,    -1.11464,70.00049,50.00000,0.0000e+000,20.00000,-6.5595e-002,0.54408
835.53900, 94.77333,    -1.11424,69.98875,50.00000,0.0000e+000,20.00000,-6.6584e-002,0.54343
837.34601, 94.95333,    -1.11547,69.97693,50.00000,0.0000e+000,20.00000,-6.7569e-002,0.54278
839.15802, 95.13333,    -1.11753,69.96484,50.00000,0.0000e+000,20.00000,-6.8586e-002,0.54212
840.96198, 95.31333,    -1.11605,69.95236,50.00000,0.0000e+000,20.00000,-6.9678e-002,0.54147
842.78601, 95.49333,    -1.11511,69.93964,50.00000,0.0000e+000,20.00000,-7.0745e-002,0.54081
844.64801, 95.67333,    -1.12107,69.92665,50.00000,0.0000e+000,20.00000,-7.1799e-002,0.54014
846.47498, 95.85333,    -1.12165,69.91333,50.00000,0.0000e+000,20.00000,-7.2871e-002,0.53948
848.31799, 96.03333,    -1.12087,69.89995,50.00000,0.0000e+000,20.00000,-7.4059e-002,0.53882
850.18201, 96.21333,    -1.12226,69.88638,50.00000,0.0000e+000,20.00000,-7.5242e-002,0.53815
852.00500, 96.39333,    -1.11828,69.87254,50.00000,0.0000e+000,20.00000,-7.6411e-002,0.53750
853.80200, 96.57333,    -1.11180,69.85867,50.00000,0.0000e+000,20.00000,-7.7528e-002,0.53686
855.58002, 96.75333,    -1.10436,69.84463,50.00000,0.0000e+000,20.00000,-7.8637e-002,0.53622
857.35400, 96.93333,    -1.09813,69.83045,50.00000,0.0000e+000,20.00000,-7.9691e-002,0.53559
859.13800, 97.11333,    -1.09391,69.81595,50.00000,0.0000e+000,20.00000,-8.0643e-002,0.53496
860.97803, 97.29333,    -1.09713,69.80138,50.00000,0.0000e+000,20.00000,-8.1554e-002,0.53430
862.80798, 97.47334,    -1.09888,69.78667,50.00000,0.0000e+000,20.00000,-8.2453e-002,0.53365
864.60602, 97.65334,    -1.09650,69.77176,50.00000,0.0000e+000,20.00000,-8.3287e-002,0.53302
866.38202, 97.83334,    -1.09255,69.75649,50.00000,0.0000e+000,20.00000,-8.4172e-002,0.53239
868.16901, 98.01334,    -1.08909,69.74105,50.00000,0.0000e+000,20.00000,-8.5123e-002,0.53176
869.94702, 98.19334,    -1.08558,69.72538,50.00000,0.0000e+000,20.00000,-8.6055e-002,0.53113
871.70599, 98.37334,    -1.08238,69.70962,50.00000,0.0000e+000,20.00000,-8.7029e-002,0.53051
873.47803, 98.55334,    -1.07903,69.69377,50.00000,0.0000e+000,20.00000,-8.8035e-002,0.52988
875.25702, 98.73333,    -1.07542,69.67787,50.00000,0.0000e+000,20.00000,-8.9160e-002,0.52926
877.03198, 98.91333,    -1.07391,69.66195,50.00000,0.0000e+000,20.00000,-9.0260e-002,0.52863
878.81000, 99.09333,    -1.07488,69.64598,50.00000,0.0000e+000,20.00000,-9.1437e-002,0.52801
880.60999, 99.27333,    -1.07639,69.62978,50.00000,0.0000e+000,20.00000,-9.2689e-002,0.52738
882.40802, 99.45333,    -1.07932,69.61347,50.00000,0.0000e+000,20.00000,-9.3964e-002,0.52675
884.23700, 99.63333,    -1.08132,69.59692,50.00000,0.0000e+000,20.00000,-9.5239e-002,0.52611
886.05798, 99.81333,    -1.08217,69.57997,50.00000,0.0000e+000,20.00000,-9.6568e-002,0.52547
887.86102, 99.99333,    -1.08125,69.56278,50.00000,0.0000e+000,20.00000,-9.7905e-002,0.52484
889.68903,100.17333,    -1.07927,69.54540,50.00000,0.0000e+000,20.00000,-9.9272e-002,0.52421
891.50201,100.35333,    -1.07754,69.52777,50.00000,0.0000e+000,20.00000,    -0.10076,0.52358
893.30103,100.53333,    -1.07576,69.50957,50.00000,0.0000e+000,20.00000,    -0.10233,0.52295
895.09802,100.71333,    -1.07493,69.49112,50.00000,0.0000e+000,20.00000,    -0.10406,0.52232
896.89203,100.89333,    -1.07287,69.47231,50.00000,0.0000e+000,20.00000,    -0.10590,0.52170
898.69702,101.07333,    -1.06911,69.45311,50.00000,0.0000e+000,20.00000,    -0.10773,0.52107
900.54199,101.25333,    -1.07271,69.43362,50.00000,0.0000e+000,20.00000,    -0.10961,0.52043
902.37402,101.43333,    -1.07313,69.41381,50.00000,0.0000e+000,20.00000,    -0.11155,0.51980
904.20203,101.61333,    -1.07456,69.39359,50.00000,0.0000e+000,20.00000,    -0.11346,0.51916
906.00299,101.79333,    -1.07039,69.37309,50.00000,0.0000e+000,20.00000,    -0.11534,0.51854
907.76398,101.97334,    -1.06103,69.35240,50.00000,0.0000e+000,20.00000,    -0.11723,0.51793
909.58502,102.15334,    -1.06267,69.33122,50.00000,0.0000e+000,20.00000,    -0.11913,0.51730
911.40198,102.33334,    -1.06443,69.30964,50.00000,0.0000e+000,20.00000,    -0.12096,0.51667
913.20203,102.51334,    -1.06217,69.28748,50.00000,0.0000e+000,20.00000,    -0.12276,0.51605
915.01001,102.69334,    -1.06038,69.26486,50.00000,0.0000e+000,20.00000,    -0.12454,0.51542
916.82501,102.87334,    -1.05914,69.24202,50.00000,0.0000e+000,20.00000,    -0.12618,0.51480
918.68201,103.05334,    -1.06124,69.21892,50.00000,0.0000e+000,20.00000,    -0.12773,0.51416
920.50800,103.23333,    -1.06320,69.19541,50.00000,0.0000e+000,20.00000,    -0.12918,0.51353
922.32898,103.41333,    -1.06169,69.17157,50.00000,0.0000e+000,20.00000,    -0.13053,0.51290
924.14398,103.59333,    -1.05946,69.14753,50.00000,0.0000e+000,20.00000,    -0.13179,0.51227
925.95099,103.77333,    -1.05651,69.12332,50.00000,0.0000e+000,20.00000,    -0.13295,0.51165
927.74902,103.95333,    -1.05245,69.09883,50.00000,0.0000e+000,20.00000,    -0.13394,0.51103
929.57501,104.13333,    -1.05127,69.07404,50.00000,0.0000e+000,20.00000,    -0.13470,0.51040
931.38202,104.31333,    -1.05235,69.04908,50.00000,0.0000e+000,20.00000,    -0.13519,0.50978
933.16998,104.49333,    -1.04598,69.02389,50.00000,0.0000e+000,20.00000,    -0.13548,0.50916
934.94800,104.67333,    -1.04226,68.99869,50.00000,0.0000e+000,20.00000,    -0.13556,0.50855
936.73700,104.85333,    -1.04111,68.97361,50.00000,0.0000e+000,20.00000,    -0.13536,0.50793
938.53601,105.03333,    -1.03997,68.94852,50.00000,0.0000e+000,20.00000,    -0.13486,0.50732
940.34698,105.21333,    -1.04058,68.92349,50.00000,0.0000e+000,20.00000,    -0.13408,0.50669
942.17102,105.39333,    -1.04472,68.89838,50.00000,0.0000e+000,20.00000,    -0.13307,0.50606
943.98499,105.57333,    -1.04474,68.87346,50.00000,0.0000e+000,20.00000,    -0.13189,0.50544
945.78699,105.75333,    -1.04106,68.84868,50.00000,0.0000e+000,20.00000,    -0.13042,0.50482
947.57300,105.93333,    -1.03755,68.82432,50.00000,0.0000e+000,20.00000,    -0.12859,0.50420
949.36798,106.11333,    -1.03746,68.80039,50.00000,0.0000e+000,20.00000,    -0.12643,0.50359
951.17999,106.29333,    -1.03763,68.77673,50.00000,0.0000e+000,20.00000,    -0.12396,0.50296
953.00201,106.47334,    -1.04077,68.75354,50.00000,0.0000e+000,20.00000,    -0.12121,0.50234
954.81299,106.65334,    -1.04234,68.73112,50.00000,0.0000e+000,20.00000,    -0.11832,0.50171
956.64001,106.83334,    -1.04525,68.70938,50.00000,0.0000e+000,20.00000,    -0.11517,0.50108
958.42700,107.01334,    -1.04626,68.68831,50.00000,0.0000e+000,20.00000,    -0.11178,0.50047
960.21899,107.19334,    -1.04594,68.66792,50.00000,0.0000e+000,20.00000,    -0.10806,0.49985
962.00702,107.37334,    -1.04872,68.64798,50.00000,0.0000e+000,20.00000,    -0.10427,0.49923
963.83002,107.55334,    -1.05423,68.62876,50.00000,0.0000e+000,20.00000,    -0.10094,0.49860
965.64203,107.73333,    -1.05693,68.61052,50.00000,0.0000e+000,20.00000,-9.7316e-002,0.49798
967.44202,107.91333,    -1.05849,68.59333,50.00000,0.0000e+000,20.00000,-9.3472e-002,0.49736
969.19098,108.09333,    -1.05319,68.57705,50.00000,0.0000e+000,20.00000,-8.9456e-002,0.49675
970.95203,108.27333,    -1.05270,68.56178,50.00000,0.0000e+000,20.00000,-8.5195e-002,0.49615
972.75000,108.45333,    -1.05880,68.54713,50.00000,0.0000e+000,20.00000,-8.0740e-002,0.49553
974.59003,108.63333,    -1.06559,68.53342,50.00000,0.0000e+000,20.00000,-7.6378e-002,0.49489
976.42902,108.81333,    -1.07245,68.52062,50.00000,0.0000e+000,20.00000,-7.1976e-002,0.49425
978.25299,108.99333,    -1.07427,68.50893,50.00000,0.0000e+000,20.00000,-6.7386e-002,0.49362
980.06598,109.17333,    -1.07881,68.49793,50.00000,0.0000e+000,20.00000,-6.2912e-002,0.49300
981.88098,109.35333,    -1.08076,68.48536,50.00000,0.0000e+000,20.00000,-5.8356e-002,0.49237
983.66901,109.53333,    -1.08077,68.47390,50.00000,0.0000e+000,20.00000,-5.4004e-002,0.49175
985.46399,109.71333,    -1.07989,68.46391,50.00000,0.0000e+000,20.00000,-4.9835e-002,0.49113
987.26898,109.89333,    -1.08233,68.45468,50.00000,0.0000e+000,20.00000,-4.5809e-002,0.49050
989.07098,110.07333,    -1.08351,68.44672,50.00000,0.0000e+000,20.00000,-4.2307e-002,0.48988
990.90997,110.25333,    -1.08960,68.44042,50.00000,0.0000e+000,20.00000,-3.6465e-002,0.48924
992.73199,110.43333,    -1.09217,68.43430,50.00000,0.0000e+000,20.00000,-3.0803e-002,0.48860
994.54199,110.61333,    -1.09189,68.42911,50.00000,0.0000e+000,20.00000,-2.6040e-002,0.48797
996.33502,110.79333,    -1.08987,68.42494,50.00000,0.0000e+000,20.00000,-2.1036e-002,0.48735
998.11902,110.97334,    -1.08709,68.42105,50.00000,0.0000e+000,20.00000,-1.7195e-002,0.48673
998.40698,111.00333,    -1.08736,68.42105,50.00000,0.0000e+000,20.00000, 5.3032e-013,0.48663