File: book/some_content/DG_ExpDat_MgO5%D28; 16-1-2025-2.csv
#FILE:                       ,MgO5%D28; 16-1-2025.ngb-ds3
#FORMAT:                     ,NETZSCH5
#IDENTITY:                   ,GEOPOLYMER PASTE
#DECIMAL:                    ,POINT
#SEPARATOR:                  ,COMMA
#MTYPE:                      ,DSC
#INSTRUMENT:                 ,Microlab TU Delft
#PROJECT:                    ,
#DATE/TIME:                  ,16/01/2025 2:49:26 PM
#CORR. FILE:                 ,Blank with cover; 13-1-2025.ngb-bs3
#LABORATORY:                 ,TU Delft Micro Lab
#OPERATOR:                   ,Ahmed
#REMARK:                     ,under Argon atmosphere, 10K/min
#SAMPLE:                     ,MgO5%D28;16-1-2025
#SAMPLE MASS /mg:            ,36
#MATERIAL:                   ,Geopolymer paste
#REFERENCE:                  ,blank
#REFERENCE MASS /mg:         ,0
#TYPE OF CRUCIBLE:           ,DSC/TG pan Al2O3
#SAMPLE CRUCIBLE MASS /mg:   ,0
#REFERENCE CRUCIBLE MASS /mg:,0
#CORR. CODE:                 ,020
#EXO:                        ,-1
#RANGE:                      ,40/10.0(K/min)/1000
#SEGMENT:                    ,S2/2

##Temp./øC,Time/min,DSC/(mW/mg),Mass/%,Gas Flow(purge1)/(ml/min),Gas Flow(purge2)/(ml/min),Gas Flow(protective)/(ml/min),DTG/(%/min),Sensit./(uV/mW)
 40.61000, 15.03917, 9.6172e-002,96.29358,50.00000,0.0000e+000,20.00000,    -0.35081,1.22610
 40.67300, 15.21917, 9.5971e-002,96.24459,50.00000,0.0000e+000,20.00000,    -0.27700,1.22601
 40.68400, 15.39917, 9.5938e-002,96.19829,50.00000,0.0000e+000,20.00000,    -0.27103,1.22600
 40.75800, 15.57917, 9.6032e-002,96.15186,50.00000,0.0000e+000,20.00000,    -0.27183,1.22590
 40.88800, 15.75917, 9.6582e-002,96.10390,50.00000,0.0000e+000,20.00000,    -0.27213,1.22572
 41.02400, 15.93917, 9.7617e-002,96.05461,50.00000,0.0000e+000,20.00000,    -0.27458,1.22553
 41.28500, 16.11917, 9.9307e-002,96.00537,50.00000,0.0000e+000,20.00000,    -0.27689,1.22517
 41.57000, 16.29917,     0.10166,95.95674,50.00000,0.0000e+000,20.00000,    -0.28229,1.22478
 41.95200, 16.47917,     0.10492,95.90745,50.00000,0.0000e+000,20.00000,    -0.28838,1.22425
 42.43500, 16.65917,     0.10841,95.85587,50.00000,0.0000e+000,20.00000,    -0.29738,1.22358
 42.97100, 16.83917,     0.11320,95.80479,50.00000,0.0000e+000,20.00000,    -0.31052,1.22285
 43.59400, 17.01917,     0.11840,95.75398,50.00000,0.0000e+000,20.00000,    -0.32069,1.22199
 44.29000, 17.19917,     0.12458,95.70141,50.00000,0.0000e+000,20.00000,    -0.33376,1.22103
 45.08300, 17.37917,     0.13095,95.64712,50.00000,0.0000e+000,20.00000,    -0.35016,1.21993
 45.95800, 17.55917,     0.13805,95.58894,50.00000,0.0000e+000,20.00000,    -0.36834,1.21873
 46.90700, 17.73917,     0.14614,95.52992,50.00000,0.0000e+000,20.00000,    -0.38730,1.21742
 47.93300, 17.91917,     0.15452,95.46988,50.00000,0.0000e+000,20.00000,    -0.40798,1.21601
 49.07600, 18.09917,     0.16353,95.40650,50.00000,0.0000e+000,20.00000,    -0.43169,1.21443
 50.26100, 18.27917,     0.17333,95.33823,50.00000,0.0000e+000,20.00000,    -0.46268,1.21280
 51.54600, 18.45917,     0.18413,95.26414,50.00000,0.0000e+000,20.00000,    -0.49717,1.21103
 52.88600, 18.63917,     0.19521,95.18174,50.00000,0.0000e+000,20.00000,    -0.53420,1.20919
 54.31300, 18.81917,     0.20739,95.09345,50.00000,0.0000e+000,20.00000,    -0.57534,1.20722
 55.85000, 18.99917,     0.22046,95.00054,50.00000,0.0000e+000,20.00000,    -0.62032,1.20511
 57.45200, 19.17917,     0.23443,94.89617,50.00000,0.0000e+000,20.00000,    -0.67072,1.20290
 59.10000, 19.35917,     0.24964,94.78276,50.00000,0.0000e+000,20.00000,    -0.72689,1.20064
 60.85200, 19.53917,     0.26574,94.66511,50.00000,0.0000e+000,20.00000,    -0.78880,1.19823
 62.62400, 19.71917,     0.28326,94.54120,50.00000,0.0000e+000,20.00000,    -0.85700,1.19580
 64.50300, 19.89917,     0.30249,94.40837,50.00000,0.0000e+000,20.00000,    -0.93281,1.19322
 66.40300, 20.07917,     0.32319,94.25071,50.00000,0.0000e+000,20.00000,    -1.01504,1.19061
 68.40400, 20.25917,     0.34567,94.07385,50.00000,0.0000e+000,20.00000,    -1.10404,1.18786
 70.42300, 20.43917,     0.37017,93.88967,50.00000,0.0000e+000,20.00000,    -1.20107,1.18509
 72.51800, 20.61917,     0.39680,93.69057,50.00000,0.0000e+000,20.00000,    -1.30541,1.18222
 74.63100, 20.79917,     0.42577,93.47659,50.00000,0.0000e+000,20.00000,    -1.41809,1.17933
 76.80100, 20.97917,     0.45745,93.24219,50.00000,0.0000e+000,20.00000,    -1.53910,1.17636
 79.00400, 21.15917,     0.49179,92.98294,50.00000,0.0000e+000,20.00000,    -1.66709,1.17335
 81.23900, 21.33917,     0.52914,92.70082,50.00000,0.0000e+000,20.00000,    -1.80256,1.17030
 83.53600, 21.51917,     0.56922,92.39608,50.00000,0.0000e+000,20.00000,    -1.94530,1.16716
 85.82800, 21.69917,     0.61335,92.06096,50.00000,0.0000e+000,20.00000,    -2.09346,1.16403
 88.17700, 21.87917,     0.66025,91.69702,50.00000,0.0000e+000,20.00000,    -2.24073,1.16083
 90.57400, 22.05917,     0.71094,91.30394,50.00000,0.0000e+000,20.00000,    -2.38512,1.15757
 92.95900, 22.23917,     0.76498,90.87391,50.00000,0.0000e+000,20.00000,    -2.52832,1.15433
 95.33500, 22.41917,     0.82206,90.40955,50.00000,0.0000e+000,20.00000,    -2.66421,1.15110
 97.76200, 22.59917,     0.88203,89.91187,50.00000,0.0000e+000,20.00000,    -2.79088,1.14781
100.16800, 22.77917,     0.94367,89.37329,50.00000,0.0000e+000,20.00000,    -2.90411,1.14455
102.60900, 22.95917,     1.00690,88.79790,50.00000,0.0000e+000,20.00000,    -2.99923,1.14124
105.05600, 23.13917,     1.07065,88.19073,50.00000,0.0000e+000,20.00000,    -3.07549,1.13793
107.47900, 23.31917,     1.13297,87.55103,50.00000,0.0000e+000,20.00000,    -3.12965,1.13466
109.88900, 23.49917,     1.19178,86.88223,50.00000,0.0000e+000,20.00000,    -3.15520,1.13141
112.33600, 23.67917,     1.24559,86.19358,50.00000,0.0000e+000,20.00000,    -3.15153,1.12811
114.74800, 23.85917,     1.29116,85.49123,50.00000,0.0000e+000,20.00000,    -3.12098,1.12487
117.18500, 24.03917,     1.32706,84.78517,50.00000,0.0000e+000,20.00000,    -3.06480,1.12160
119.60500, 24.21917,     1.35110,84.08896,50.00000,0.0000e+000,20.00000,    -2.98522,1.11835
122.03200, 24.39917,     1.35979,83.41115,50.00000,0.0000e+000,20.00000,    -2.88647,1.11510
124.45600, 24.57917,     1.35601,82.76097,50.00000,0.0000e+000,20.00000,    -2.77330,1.11186
126.90600, 24.75917,     1.33834,82.15109,50.00000,0.0000e+000,20.00000,    -2.64748,1.10859
129.34700, 24.93917,     1.29998,81.58613,50.00000,0.0000e+000,20.00000,    -2.51049,1.10533
131.77699, 25.11917,     1.23788,81.07698,50.00000,0.0000e+000,20.00000,    -2.36317,1.10210
134.21700, 25.29917,     1.15320,80.64141,50.00000,0.0000e+000,20.00000,    -2.20552,1.09886
136.68800, 25.47917,     1.04880,80.28347,50.00000,0.0000e+000,20.00000,    -2.04062,1.09558
139.13200, 25.65917,     0.93329,79.99712,50.00000,0.0000e+000,20.00000,    -1.87006,1.09235
141.59300, 25.83917,     0.81647,79.77016,50.00000,0.0000e+000,20.00000,    -1.69647,1.08909
144.02699, 26.01917,     0.70465,79.59411,50.00000,0.0000e+000,20.00000,    -1.52346,1.08588
146.49400, 26.19917,     0.60356,79.45907,50.00000,0.0000e+000,20.00000,    -1.35422,1.08263
148.93500, 26.37917,     0.51400,79.33943,50.00000,0.0000e+000,20.00000,    -1.19122,1.07942
151.35201, 26.55917,     0.43715,79.22748,50.00000,0.0000e+000,20.00000,    -1.03788,1.07625
153.75999, 26.73917,     0.37124,79.12484,50.00000,0.0000e+000,20.00000,    -0.89684,1.07310
156.14400, 26.91917,     0.31524,79.02771,50.00000,0.0000e+000,20.00000,    -0.76933,1.06998
158.49600, 27.09917,     0.26709,78.93777,50.00000,0.0000e+000,20.00000,    -0.65986,1.06692
160.81100, 27.27917,     0.22551,78.85370,50.00000,0.0000e+000,20.00000,    -0.57130,1.06390
163.10001, 27.45917,     0.18945,78.77545,50.00000,0.0000e+000,20.00000,    -0.50231,1.06093
165.35001, 27.63917,     0.15840,78.70272,50.00000,0.0000e+000,20.00000,    -0.44917,1.05801
167.59000, 27.81917,     0.13038,78.63583,50.00000,0.0000e+000,20.00000,    -0.40907,1.05511
169.78799, 27.99917,     0.10527,78.57300,50.00000,0.0000e+000,20.00000,    -0.38071,1.05227
171.95599, 28.17917, 8.2471e-002,78.51293,50.00000,0.0000e+000,20.00000,    -0.35766,1.04948
174.08400, 28.35917, 6.1853e-002,78.45653,50.00000,0.0000e+000,20.00000,    -0.33645,1.04674
176.19901, 28.53917, 4.2364e-002,78.40009,50.00000,0.0000e+000,20.00000,    -0.31750,1.04403
178.29201, 28.71917, 2.5073e-002,78.34613,50.00000,0.0000e+000,20.00000,    -0.29952,1.04134
180.34000, 28.89917, 8.7935e-003,78.29831,50.00000,0.0000e+000,20.00000,    -0.28314,1.03873
182.38400, 29.07917,-5.4203e-003,78.25226,50.00000,0.0000e+000,20.00000,    -0.26811,1.03612
184.39500, 29.25917,-1.8967e-002,78.20743,50.00000,0.0000e+000,20.00000,    -0.25367,1.03356
186.37000, 29.43917,-3.1449e-002,78.16577,50.00000,0.0000e+000,20.00000,    -0.24077,1.03104
188.34599, 29.61917,-4.3085e-002,78.12829,50.00000,0.0000e+000,20.00000,    -0.22947,1.02854
190.27000, 29.79917,-5.4071e-002,78.09219,50.00000,0.0000e+000,20.00000,    -0.21854,1.02610
192.19701, 29.97917,-6.5028e-002,78.05564,50.00000,0.0000e+000,20.00000,    -0.20754,1.02367
194.10001, 30.15917,-7.5266e-002,78.01961,50.00000,0.0000e+000,20.00000,    -0.19771,1.02127
195.99300, 30.33917,-8.4718e-002,77.98481,50.00000,0.0000e+000,20.00000,    -0.18811,1.01888
197.85600, 30.51917,-9.4629e-002,77.95223,50.00000,0.0000e+000,20.00000,    -0.17859,1.01654
199.71700, 30.69917,    -0.10394,77.92094,50.00000,0.0000e+000,20.00000,    -0.17077,1.01421
201.55000, 30.87917,    -0.11265,77.89055,50.00000,0.0000e+000,20.00000,    -0.16357,1.01191
203.38800, 31.05917,    -0.12131,77.86380,50.00000,0.0000e+000,20.00000,    -0.15634,1.00962
205.19600, 31.23917,    -0.12966,77.83756,50.00000,0.0000e+000,20.00000,    -0.14964,1.00736
206.99001, 31.41917,    -0.13768,77.81089,50.00000,0.0000e+000,20.00000,    -0.14386,1.00513
208.79601, 31.59917,    -0.14520,77.78699,50.00000,0.0000e+000,20.00000,    -0.13843,1.00289
210.56700, 31.77917,    -0.15229,77.76637,50.00000,0.0000e+000,20.00000,    -0.13304,1.00070
212.33400, 31.95917,    -0.16012,77.74566,50.00000,0.0000e+000,20.00000,    -0.12820,0.99851
214.10001, 32.13917,    -0.16778,77.72440,50.00000,0.0000e+000,20.00000,    -0.12291,0.99633
215.85699, 32.31917,    -0.17501,77.70419,50.00000,0.0000e+000,20.00000,    -0.11769,0.99417
217.61200, 32.49917,    -0.18182,77.68430,50.00000,0.0000e+000,20.00000,    -0.11303,0.99201
219.33800, 32.67916,    -0.18842,77.66438,50.00000,0.0000e+000,20.00000,    -0.10898,0.98990
221.07700, 32.85917,    -0.19567,77.64549,50.00000,0.0000e+000,20.00000,    -0.10644,0.98777
222.80600, 33.03917,    -0.20254,77.62760,50.00000,0.0000e+000,20.00000,    -0.10397,0.98565
224.53799, 33.21917,    -0.20907,77.61053,50.00000,0.0000e+000,20.00000,    -0.10155,0.98354
226.24300, 33.39917,    -0.21582,77.59425,50.00000,0.0000e+000,20.00000,-9.9113e-002,0.98147
227.99400, 33.57917,    -0.22250,77.57766,50.00000,0.0000e+000,20.00000,-9.7481e-002,0.97934
229.69299, 33.75917,    -0.22893,77.55922,50.00000,0.0000e+000,20.00000,-9.6229e-002,0.97729
231.41400, 33.93917,    -0.23540,77.54297,50.00000,0.0000e+000,20.00000,-9.4513e-002,0.97521
233.13000, 34.11917,    -0.24136,77.52901,50.00000,0.0000e+000,20.00000,-9.3130e-002,0.97314
234.83600, 34.29917,    -0.24774,77.51488,50.00000,0.0000e+000,20.00000,-9.1817e-002,0.97108
236.54700, 34.47917,    -0.25459,77.49923,50.00000,0.0000e+000,20.00000,-9.0742e-002,0.96903
238.26700, 34.65917,    -0.26160,77.48146,50.00000,0.0000e+000,20.00000,-8.9796e-002,0.96697
239.97301, 34.83917,    -0.26806,77.46425,50.00000,0.0000e+000,20.00000,-8.9328e-002,0.96493
241.70200, 35.01917,    -0.27449,77.44640,50.00000,0.0000e+000,20.00000,-8.9278e-002,0.96286
243.38600, 35.19917,    -0.28020,77.43031,50.00000,0.0000e+000,20.00000,-8.9030e-002,0.96086
245.12300, 35.37917,    -0.28595,77.41557,50.00000,0.0000e+000,20.00000,-8.8971e-002,0.95880
246.82600, 35.55917,    -0.29167,77.39955,50.00000,0.0000e+000,20.00000,-8.9094e-002,0.95678
248.54500, 35.73917,    -0.29727,77.38447,50.00000,0.0000e+000,20.00000,-8.9775e-002,0.95475
250.26100, 35.91917,    -0.30252,77.36915,50.00000,0.0000e+000,20.00000,-9.1084e-002,0.95272
251.95900, 36.09917,    -0.30842,77.35411,50.00000,0.0000e+000,20.00000,-9.2106e-002,0.95072
253.67200, 36.27917,    -0.31446,77.33821,50.00000,0.0000e+000,20.00000,-9.1869e-002,0.94871
255.38200, 36.45917,    -0.32050,77.32241,50.00000,0.0000e+000,20.00000,-9.1280e-002,0.94671
257.09799, 36.63917,    -0.32611,77.30644,50.00000,0.0000e+000,20.00000,-9.1210e-002,0.94470
258.81699, 36.81917,    -0.33150,77.28926,50.00000,0.0000e+000,20.00000,-9.1128e-002,0.94270
260.55301, 36.99917,    -0.33704,77.27364,50.00000,0.0000e+000,20.00000,-9.1392e-002,0.94068
262.27399, 37.17916,    -0.34191,77.25775,50.00000,0.0000e+000,20.00000,-9.2348e-002,0.93868
263.98999, 37.35917,    -0.34662,77.23938,50.00000,0.0000e+000,20.00000,-9.2988e-002,0.93670
265.71701, 37.53917,    -0.35144,77.22000,50.00000,0.0000e+000,20.00000,-9.4134e-002,0.93470
267.45901, 37.71917,    -0.35653,77.20109,50.00000,0.0000e+000,20.00000,-9.5456e-002,0.93269
269.17200, 37.89917,    -0.36159,77.18293,50.00000,0.0000e+000,20.00000,-9.6559e-002,0.93073
270.90701, 38.07917,    -0.36606,77.16812,50.00000,0.0000e+000,20.00000,-9.7699e-002,0.92874
272.63300, 38.25917,    -0.37098,77.15313,50.00000,0.0000e+000,20.00000,-9.8796e-002,0.92676
274.36200, 38.43917,    -0.37665,77.13610,50.00000,0.0000e+000,20.00000,    -0.10014,0.92479
276.09100, 38.61917,    -0.38111,77.11875,50.00000,0.0000e+000,20.00000,    -0.10118,0.92283
277.84601, 38.79917,    -0.38653,77.10124,50.00000,0.0000e+000,20.00000,    -0.10294,0.92083
279.57800, 38.97917,    -0.39190,77.08318,50.00000,0.0000e+000,20.00000,    -0.10461,0.91887
281.32901, 39.15917,    -0.39621,77.06493,50.00000,0.0000e+000,20.00000,    -0.10511,0.91690
283.07101, 39.33917,    -0.40105,77.04577,50.00000,0.0000e+000,20.00000,    -0.10571,0.91494
284.82599, 39.51917,    -0.40512,77.02558,50.00000,0.0000e+000,20.00000,    -0.10662,0.91297
286.56100, 39.69917,    -0.40933,77.00645,50.00000,0.0000e+000,20.00000,    -0.10730,0.91102
288.30399, 39.87917,    -0.41366,76.98668,50.00000,0.0000e+000,20.00000,    -0.10916,0.90908
290.07401, 40.05917,    -0.41792,76.96672,50.00000,0.0000e+000,20.00000,    -0.11150,0.90710
291.81299, 40.23917,    -0.42171,76.94621,50.00000,0.0000e+000,20.00000,    -0.11340,0.90517
293.57501, 40.41917,    -0.42584,76.92528,50.00000,0.0000e+000,20.00000,    -0.11543,0.90322
295.32401, 40.59917,    -0.42936,76.90319,50.00000,0.0000e+000,20.00000,    -0.11765,0.90129
297.06400, 40.77917,    -0.43325,76.88110,50.00000,0.0000e+000,20.00000,    -0.12018,0.89937
298.81699, 40.95917,    -0.43739,76.86119,50.00000,0.0000e+000,20.00000,    -0.12313,0.89745
300.57001, 41.13917,    -0.44126,76.84003,50.00000,0.0000e+000,20.00000,    -0.12607,0.89553
302.34900, 41.31917,    -0.44599,76.81756,50.00000,0.0000e+000,20.00000,    -0.12900,0.89358
304.09799, 41.49917,    -0.45075,76.79654,50.00000,0.0000e+000,20.00000,    -0.13211,0.89168
305.86401, 41.67916,    -0.45460,76.77474,50.00000,0.0000e+000,20.00000,    -0.13534,0.88976
307.63400, 41.85917,    -0.45849,76.75163,50.00000,0.0000e+000,20.00000,    -0.13891,0.88784
309.41599, 42.03917,    -0.46227,76.72796,50.00000,0.0000e+000,20.00000,    -0.14252,0.88592
311.17801, 42.21917,    -0.46515,76.70333,50.00000,0.0000e+000,20.00000,    -0.14616,0.88402
312.94901, 42.39917,    -0.46673,76.67790,50.00000,0.0000e+000,20.00000,    -0.15026,0.88212
314.72501, 42.57917,    -0.46815,76.65103,50.00000,0.0000e+000,20.00000,    -0.15456,0.88022
316.48700, 42.75917,    -0.46990,76.62215,50.00000,0.0000e+000,20.00000,    -0.15903,0.87834
318.26099, 42.93917,    -0.47101,76.59266,50.00000,0.0000e+000,20.00000,    -0.16331,0.87645
320.01999, 43.11917,    -0.47245,76.56185,50.00000,0.0000e+000,20.00000,    -0.16731,0.87458
321.78601, 43.29917,    -0.47421,76.53120,50.00000,0.0000e+000,20.00000,    -0.17133,0.87271
323.57101, 43.47917,    -0.47650,76.50000,50.00000,0.0000e+000,20.00000,    -0.17498,0.87083
325.33200, 43.65917,    -0.47903,76.46719,50.00000,0.0000e+000,20.00000,    -0.17802,0.86898
327.11899, 43.83917,    -0.48183,76.43363,50.00000,0.0000e+000,20.00000,    -0.18049,0.86710
328.91599, 44.01917,    -0.48444,76.39963,50.00000,0.0000e+000,20.00000,    -0.18234,0.86523
330.68799, 44.19917,    -0.48712,76.36325,50.00000,0.0000e+000,20.00000,    -0.18410,0.86338
332.47198, 44.37917,    -0.49043,76.32514,50.00000,0.0000e+000,20.00000,    -0.18504,0.86153
334.25000, 44.55917,    -0.49446,76.28845,50.00000,0.0000e+000,20.00000,    -0.18487,0.85969
336.02100, 44.73917,    -0.49898,76.25217,50.00000,0.0000e+000,20.00000,    -0.18465,0.85786
337.79501, 44.91917,    -0.50351,76.21502,50.00000,0.0000e+000,20.00000,    -0.18369,0.85603
339.58099, 45.09917,    -0.50893,76.17889,50.00000,0.0000e+000,20.00000,    -0.18214,0.85420
341.35400, 45.27917,    -0.51456,76.14393,50.00000,0.0000e+000,20.00000,    -0.18061,0.85239
343.13300, 45.45917,    -0.52214,76.10965,50.00000,0.0000e+000,20.00000,    -0.17855,0.85058
344.90500, 45.63917,    -0.53008,76.07680,50.00000,0.0000e+000,20.00000,    -0.17529,0.84878
346.69800, 45.81917,    -0.53845,76.04550,50.00000,0.0000e+000,20.00000,    -0.17137,0.84696
348.49100, 45.99917,    -0.54607,76.01377,50.00000,0.0000e+000,20.00000,    -0.16723,0.84515
350.26700, 46.17916,    -0.55366,75.98337,50.00000,0.0000e+000,20.00000,    -0.16316,0.84336
352.06100, 46.35917,    -0.56263,75.95517,50.00000,0.0000e+000,20.00000,    -0.15854,0.84157
353.85199, 46.53917,    -0.57165,75.92672,50.00000,0.0000e+000,20.00000,    -0.15363,0.83978
355.63599, 46.71917,    -0.58080,75.89914,50.00000,0.0000e+000,20.00000,    -0.14828,0.83800
357.43701, 46.89917,    -0.58909,75.87397,50.00000,0.0000e+000,20.00000,    -0.14296,0.83621
359.22601, 47.07917,    -0.59692,75.84863,50.00000,0.0000e+000,20.00000,    -0.13750,0.83444
361.00500, 47.25917,    -0.60487,75.82335,50.00000,0.0000e+000,20.00000,    -0.13200,0.83269
362.80399, 47.43917,    -0.61343,75.80116,50.00000,0.0000e+000,20.00000,    -0.12670,0.83092
364.59299, 47.61917,    -0.62109,75.78151,50.00000,0.0000e+000,20.00000,    -0.12154,0.82916
366.37201, 47.79917,    -0.62826,75.76120,50.00000,0.0000e+000,20.00000,    -0.11661,0.82743
368.13101, 47.97917,    -0.63472,75.73800,50.00000,0.0000e+000,20.00000,    -0.11197,0.82572
369.88599, 48.15917,    -0.64068,75.71737,50.00000,0.0000e+000,20.00000,    -0.10800,0.82401
371.67099, 48.33917,    -0.64829,75.69899,50.00000,0.0000e+000,20.00000,    -0.10396,0.82229
373.43900, 48.51917,    -0.65560,75.68138,50.00000,0.0000e+000,20.00000,-9.9791e-002,0.82059
375.20300, 48.69917,    -0.66384,75.66427,50.00000,0.0000e+000,20.00000,-9.6492e-002,0.81889
376.99399, 48.87917,    -0.67231,75.64884,50.00000,0.0000e+000,20.00000,-9.2971e-002,0.81718
378.77899, 49.05917,    -0.68073,75.63459,50.00000,0.0000e+000,20.00000,-8.9283e-002,0.81548
380.58301, 49.23917,    -0.68862,75.62055,50.00000,0.0000e+000,20.00000,-8.6134e-002,0.81377
382.36801, 49.41917,    -0.69637,75.60803,50.00000,0.0000e+000,20.00000,-8.3991e-002,0.81208
384.18399, 49.59917,    -0.70430,75.59454,50.00000,0.0000e+000,20.00000,-8.1875e-002,0.81036
385.98801, 49.77917,    -0.71050,75.58072,50.00000,0.0000e+000,20.00000,-7.8395e-002,0.80867
387.77899, 49.95917,    -0.71615,75.56678,50.00000,0.0000e+000,20.00000,-7.4974e-002,0.80699
389.59100, 50.13917,    -0.72207,75.55314,50.00000,0.0000e+000,20.00000,-7.2302e-002,0.80530
391.40900, 50.31917,    -0.73061,75.54039,50.00000,0.0000e+000,20.00000,-6.9672e-002,0.80361
393.22800, 50.49917,    -0.73621,75.52711,50.00000,0.0000e+000,20.00000,-6.8034e-002,0.80193
395.01501, 50.67916,    -0.73847,75.51457,50.00000,0.0000e+000,20.00000,-6.7513e-002,0.80028
396.78500, 50.85917,    -0.74117,75.50254,50.00000,0.0000e+000,20.00000,-6.7314e-002,0.79865
398.56799, 51.03917,    -0.74404,75.49123,50.00000,0.0000e+000,20.00000,-6.7356e-002,0.79702
400.32800, 51.21917,    -0.74763,75.47937,50.00000,0.0000e+000,20.00000,-6.8228e-002,0.79541
402.08600, 51.39917,    -0.75143,75.46706,50.00000,0.0000e+000,20.00000,-6.8795e-002,0.79381
403.85300, 51.57917,    -0.75554,75.45639,50.00000,0.0000e+000,20.00000,-6.9059e-002,0.79221
405.64200, 51.75917,    -0.76467,75.44760,50.00000,0.0000e+000,20.00000,-6.9693e-002,0.79059
407.44299, 51.93917,    -0.77263,75.43878,50.00000,0.0000e+000,20.00000,-6.9909e-002,0.78897
409.22198, 52.11917,    -0.77557,75.43071,50.00000,0.0000e+000,20.00000,-7.0090e-002,0.78738
410.99500, 52.29917,    -0.77584,75.42014,50.00000,0.0000e+000,20.00000,-7.0628e-002,0.78580
412.75500, 52.47917,    -0.77723,75.40644,50.00000,0.0000e+000,20.00000,-7.0887e-002,0.78423
414.55099, 52.65917,    -0.78184,75.39283,50.00000,0.0000e+000,20.00000,-7.0419e-002,0.78264
416.34399, 52.83917,    -0.78671,75.37870,50.00000,0.0000e+000,20.00000,-6.9857e-002,0.78106
418.12299, 53.01917,    -0.78959,75.36304,50.00000,0.0000e+000,20.00000,-6.9272e-002,0.77949
419.90601, 53.19917,    -0.79211,75.34747,50.00000,0.0000e+000,20.00000,-6.8246e-002,0.77793
421.65799, 53.37917,    -0.79435,75.33277,50.00000,0.0000e+000,20.00000,-6.7708e-002,0.77640
423.43500, 53.55917,    -0.79894,75.31665,50.00000,0.0000e+000,20.00000,-6.7776e-002,0.77485
425.22800, 53.73917,    -0.80633,75.30172,50.00000,0.0000e+000,20.00000,-6.7352e-002,0.77330
427.04099, 53.91917,    -0.81661,75.28830,50.00000,0.0000e+000,20.00000,-6.7440e-002,0.77173
428.86099, 54.09917,    -0.82771,75.27335,50.00000,0.0000e+000,20.00000,-6.7129e-002,0.77017
430.68100, 54.27917,    -0.83642,75.25918,50.00000,0.0000e+000,20.00000,-6.5025e-002,0.76861
432.48801, 54.45917,    -0.84266,75.24839,50.00000,0.0000e+000,20.00000,-6.2200e-002,0.76707
434.30499, 54.63917,    -0.84929,75.23910,50.00000,0.0000e+000,20.00000,-5.9657e-002,0.76552
436.08099, 54.81917,    -0.85213,75.22945,50.00000,0.0000e+000,20.00000,-5.7079e-002,0.76402
437.85300, 54.99917,    -0.85368,75.22073,50.00000,0.0000e+000,20.00000,-5.4933e-002,0.76253
439.62100, 55.17916,    -0.85602,75.21191,50.00000,0.0000e+000,20.00000,-5.2589e-002,0.76104
441.38901, 55.35917,    -0.86008,75.20237,50.00000,0.0000e+000,20.00000,-4.9627e-002,0.75956
443.12900, 55.53917,    -0.86416,75.19513,50.00000,0.0000e+000,20.00000,-4.7351e-002,0.75811
444.91699, 55.71917,    -0.86950,75.18681,50.00000,0.0000e+000,20.00000,-4.5466e-002,0.75663
446.68500, 55.89917,    -0.87483,75.17793,50.00000,0.0000e+000,20.00000,-4.2760e-002,0.75517
448.45599, 56.07917,    -0.88122,75.17153,50.00000,0.0000e+000,20.00000,-3.9862e-002,0.75371
450.23801, 56.25917,    -0.88820,75.16808,50.00000,0.0000e+000,20.00000,-3.8411e-002,0.75225
452.03299, 56.43917,    -0.89462,75.16373,50.00000,0.0000e+000,20.00000,-3.7765e-002,0.75078
453.83099, 56.61917,    -0.90120,75.15791,50.00000,0.0000e+000,20.00000,-3.6861e-002,0.74932
455.61801, 56.79917,    -0.90612,75.15019,50.00000,0.0000e+000,20.00000,-3.6045e-002,0.74787
457.41101, 56.97917,    -0.91078,75.14359,50.00000,0.0000e+000,20.00000,-3.5641e-002,0.74642
459.19501, 57.15917,    -0.91506,75.13869,50.00000,0.0000e+000,20.00000,-3.5070e-002,0.74498
460.98700, 57.33917,    -0.91897,75.13186,50.00000,0.0000e+000,20.00000,-3.4732e-002,0.74355
462.78201, 57.51917,    -0.92305,75.12512,50.00000,0.0000e+000,20.00000,-3.3667e-002,0.74212
464.57501, 57.69917,    -0.92763,75.12002,50.00000,0.0000e+000,20.00000,-3.2753e-002,0.74069
466.36700, 57.87917,    -0.93348,75.11617,50.00000,0.0000e+000,20.00000,-3.2375e-002,0.73927
468.17899, 58.05917,    -0.93922,75.11047,50.00000,0.0000e+000,20.00000,-3.3545e-002,0.73785
469.98099, 58.23917,    -0.94316,75.10360,50.00000,0.0000e+000,20.00000,-3.4703e-002,0.73643
471.80099, 58.41917,    -0.94596,75.09704,50.00000,0.0000e+000,20.00000,-3.4954e-002,0.73501
473.60501, 58.59917,    -0.94766,75.09124,50.00000,0.0000e+000,20.00000,-3.4431e-002,0.73361
475.37500, 58.77917,    -0.95062,75.08426,50.00000,0.0000e+000,20.00000,-3.4203e-002,0.73223
477.19400, 58.95917,    -0.95569,75.07665,50.00000,0.0000e+000,20.00000,-3.5152e-002,0.73083
479.00601, 59.13917,    -0.96060,75.07000,50.00000,0.0000e+000,20.00000,-3.5536e-002,0.72944
480.82101, 59.31917,    -0.96461,75.06586,50.00000,0.0000e+000,20.00000,-3.5587e-002,0.72805
482.62701, 59.49917,    -0.96828,75.06035,50.00000,0.0000e+000,20.00000,-3.6647e-002,0.72667
484.42999, 59.67916,    -0.97022,75.05488,50.00000,0.0000e+000,20.00000,-3.8497e-002,0.72530
486.22101, 59.85917,    -0.97130,75.04733,50.00000,0.0000e+000,20.00000,-3.9134e-002,0.72395
488.01099, 60.03917,    -0.97197,75.03882,50.00000,0.0000e+000,20.00000,-3.9081e-002,0.72260
489.78400, 60.21917,    -0.97247,75.03204,50.00000,0.0000e+000,20.00000,-3.9424e-002,0.72127
491.56400, 60.39917,    -0.97462,75.02644,50.00000,0.0000e+000,20.00000,-3.9826e-002,0.71995
493.37000, 60.57917,    -0.97989,75.02044,50.00000,0.0000e+000,20.00000,-3.9469e-002,0.71860
495.14600, 60.75917,    -0.98417,75.01242,50.00000,0.0000e+000,20.00000,-3.9361e-002,0.71729
496.94699, 60.93917,    -0.98848,75.00417,50.00000,0.0000e+000,20.00000,-4.0163e-002,0.71596
498.73801, 61.11917,    -0.99033,74.99715,50.00000,0.0000e+000,20.00000,-4.1554e-002,0.71465
500.51599, 61.29917,    -0.99314,74.98835,50.00000,0.0000e+000,20.00000,-4.2534e-002,0.71335
502.29700, 61.47917,    -0.99709,74.97759,50.00000,0.0000e+000,20.00000,-4.3857e-002,0.71205
504.10001, 61.65917,    -1.00095,74.96941,50.00000,0.0000e+000,20.00000,-4.4950e-002,0.71074
505.89899, 61.83917,    -1.00434,74.96295,50.00000,0.0000e+000,20.00000,-4.5523e-002,0.70945
507.68500, 62.01917,    -1.00655,74.95510,50.00000,0.0000e+000,20.00000,-4.5840e-002,0.70816
509.48001, 62.19917,    -1.00894,74.94758,50.00000,0.0000e+000,20.00000,-4.6659e-002,0.70688
511.27600, 62.37917,    -1.01047,74.94193,50.00000,0.0000e+000,20.00000,-4.7721e-002,0.70560
513.04901, 62.55917,    -1.01189,74.93534,50.00000,0.0000e+000,20.00000,-4.8524e-002,0.70434
514.81500, 62.73917,    -1.01308,74.92553,50.00000,0.0000e+000,20.00000,-4.8936e-002,0.70309
516.61298, 62.91917,    -1.01648,74.91602,50.00000,0.0000e+000,20.00000,-5.0158e-002,0.70183
518.40100, 63.09917,    -1.02216,74.90718,50.00000,0.0000e+000,20.00000,-5.0960e-002,0.70058
520.22498, 63.27917,    -1.02675,74.89711,50.00000,0.0000e+000,20.00000,-5.1166e-002,0.69930
522.02399, 63.45917,    -1.03047,74.88611,50.00000,0.0000e+000,20.00000,-5.1916e-002,0.69805
523.82397, 63.63917,    -1.03252,74.87510,50.00000,0.0000e+000,20.00000,-5.3492e-002,0.69681
525.60999, 63.81917,    -1.03179,74.86663,50.00000,0.0000e+000,20.00000,-5.4836e-002,0.69558
527.38501, 63.99917,    -1.03180,74.85815,50.00000,0.0000e+000,20.00000,-5.6251e-002,0.69436
529.16302, 64.17917,    -1.03330,74.84860,50.00000,0.0000e+000,20.00000,-5.8015e-002,0.69315
530.95599, 64.35917,    -1.03763,74.83801,50.00000,0.0000e+000,20.00000,-5.9771e-002,0.69193
532.77002, 64.53917,    -1.04521,74.82801,50.00000,0.0000e+000,20.00000,-6.0798e-002,0.69071
534.57703, 64.71917,    -1.04862,74.81674,50.00000,0.0000e+000,20.00000,-6.1958e-002,0.68949
536.39801, 64.89917,    -1.05064,74.80535,50.00000,0.0000e+000,20.00000,-6.3279e-002,0.68827
538.20099, 65.07917,    -1.05359,74.79392,50.00000,0.0000e+000,20.00000,-6.4335e-002,0.68706
540.00800, 65.25916,    -1.05716,74.78246,50.00000,0.0000e+000,20.00000,-6.5204e-002,0.68586
541.81897, 65.43916,    -1.06022,74.77040,50.00000,0.0000e+000,20.00000,-6.6140e-002,0.68466
543.64099, 65.61916,    -1.06401,74.75787,50.00000,0.0000e+000,20.00000,-6.7996e-002,0.68346
545.44098, 65.79916,    -1.06467,74.74497,50.00000,0.0000e+000,20.00000,-6.9968e-002,0.68228
547.22302, 65.97916,    -1.06415,74.73255,50.00000,0.0000e+000,20.00000,-7.1786e-002,0.68112
549.00098, 66.15916,    -1.06428,74.72009,50.00000,0.0000e+000,20.00000,-7.3394e-002,0.67996
550.79999, 66.33916,    -1.06720,74.70698,50.00000,0.0000e+000,20.00000,-7.5136e-002,0.67880
552.59497, 66.51917,    -1.07002,74.69304,50.00000,0.0000e+000,20.00000,-7.6396e-002,0.67764
554.40002, 66.69917,    -1.07373,74.67937,50.00000,0.0000e+000,20.00000,-7.7377e-002,0.67648
556.21002, 66.87917,    -1.07579,74.66571,50.00000,0.0000e+000,20.00000,-7.8562e-002,0.67532
558.01703, 67.05917,    -1.07923,74.65168,50.00000,0.0000e+000,20.00000,-7.9930e-002,0.67418
559.81598, 67.23917,    -1.08197,74.63722,50.00000,0.0000e+000,20.00000,-8.0873e-002,0.67304
561.61798, 67.41917,    -1.08241,74.62170,50.00000,0.0000e+000,20.00000,-8.1661e-002,0.67190
563.38599, 67.59917,    -1.08085,74.60617,50.00000,0.0000e+000,20.00000,-8.2430e-002,0.67079
565.17102, 67.77917,    -1.08133,74.59025,50.00000,0.0000e+000,20.00000,-8.2496e-002,0.66967
566.95099, 67.95917,    -1.08518,74.57389,50.00000,0.0000e+000,20.00000,-8.3064e-002,0.66857
568.75500, 68.13917,    -1.08903,74.55740,50.00000,0.0000e+000,20.00000,-8.4338e-002,0.66745
570.55798, 68.31917,    -1.09139,74.54164,50.00000,0.0000e+000,20.00000,-8.5303e-002,0.66634
572.36700, 68.49917,    -1.09324,74.52655,50.00000,0.0000e+000,20.00000,-8.5608e-002,0.66523
574.17401, 68.67917,    -1.09608,74.51105,50.00000,0.0000e+000,20.00000,-8.6335e-002,0.66412
575.97498, 68.85917,    -1.10032,74.49453,50.00000,0.0000e+000,20.00000,-8.7260e-002,0.66302
577.77301, 69.03917,    -1.10364,74.47900,50.00000,0.0000e+000,20.00000,-8.8032e-002,0.66193
579.57898, 69.21917,    -1.10677,74.46375,50.00000,0.0000e+000,20.00000,-8.8320e-002,0.66084
581.38000, 69.39917,    -1.10942,74.44789,50.00000,0.0000e+000,20.00000,-8.9121e-002,0.65976
583.15997, 69.57917,    -1.11151,74.43479,50.00000,0.0000e+000,20.00000,-9.0009e-002,0.65870
584.97699, 69.75916,    -1.11385,74.42089,50.00000,0.0000e+000,20.00000,-9.0899e-002,0.65762
586.76202, 69.93916,    -1.11661,74.40360,50.00000,0.0000e+000,20.00000,-9.1665e-002,0.65656
588.55798, 70.11916,    -1.11826,74.38583,50.00000,0.0000e+000,20.00000,-9.2301e-002,0.65550
590.34100, 70.29916,    -1.12060,74.37082,50.00000,0.0000e+000,20.00000,-9.3368e-002,0.65445
592.13702, 70.47916,    -1.12276,74.35489,50.00000,0.0000e+000,20.00000,-9.4407e-002,0.65340
593.92401, 70.65916,    -1.12669,74.33757,50.00000,0.0000e+000,20.00000,-9.5280e-002,0.65236
595.73297, 70.83916,    -1.13040,74.32025,50.00000,0.0000e+000,20.00000,-9.6453e-002,0.65131
597.51001, 71.01917,    -1.13280,74.30393,50.00000,0.0000e+000,20.00000,-9.7926e-002,0.65028
599.31299, 71.19917,    -1.13588,74.28570,50.00000,0.0000e+000,20.00000,-9.9299e-002,0.64925
601.12903, 71.37917,    -1.14012,74.26667,50.00000,0.0000e+000,20.00000,    -0.10150,0.64821
602.97198, 71.55917,    -1.14845,74.24722,50.00000,0.0000e+000,20.00000,    -0.10367,0.64716
604.79199, 71.73917,    -1.15118,74.22768,50.00000,0.0000e+000,20.00000,    -0.10496,0.64612
606.57800, 71.91917,    -1.15133,74.20946,50.00000,0.0000e+000,20.00000,    -0.10600,0.64512
608.39001, 72.09917,    -1.15282,74.19051,50.00000,0.0000e+000,20.00000,    -0.10779,0.64410
610.18201, 72.27917,    -1.15390,74.17139,50.00000,0.0000e+000,20.00000,    -0.10971,0.64309
611.99701, 72.45917,    -1.15677,74.15182,50.00000,0.0000e+000,20.00000,    -0.11126,0.64208
613.81598, 72.63917,    -1.16111,74.13185,50.00000,0.0000e+000,20.00000,    -0.11278,0.64107
615.61298, 72.81917,    -1.16344,74.11139,50.00000,0.0000e+000,20.00000,    -0.11464,0.64008
617.41400, 72.99917,    -1.16474,74.09055,50.00000,0.0000e+000,20.00000,    -0.11606,0.63909
619.21600, 73.17917,    -1.16840,74.06896,50.00000,0.0000e+000,20.00000,    -0.11701,0.63810
621.03003, 73.35917,    -1.17158,74.04759,50.00000,0.0000e+000,20.00000,    -0.11790,0.63711
622.83698, 73.53917,    -1.17402,74.02606,50.00000,0.0000e+000,20.00000,    -0.11863,0.63613
624.65399, 73.71917,    -1.17594,74.00426,50.00000,0.0000e+000,20.00000,    -0.11977,0.63515
626.45203, 73.89917,    -1.17713,73.98246,50.00000,0.0000e+000,20.00000,    -0.12117,0.63418
628.26398, 74.07917,    -1.17793,73.95994,50.00000,0.0000e+000,20.00000,    -0.12272,0.63321
630.04498, 74.25916,    -1.17886,73.93710,50.00000,0.0000e+000,20.00000,    -0.12432,0.63226
631.84900, 74.43916,    -1.17877,73.91412,50.00000,0.0000e+000,20.00000,    -0.12574,0.63130
633.64899, 74.61916,    -1.18086,73.89101,50.00000,0.0000e+000,20.00000,    -0.12720,0.63035
635.46399, 74.79916,    -1.18481,73.86791,50.00000,0.0000e+000,20.00000,    -0.12875,0.62939
637.27899, 74.97916,    -1.18748,73.84527,50.00000,0.0000e+000,20.00000,    -0.13011,0.62844
639.10797, 75.15916,    -1.19026,73.82284,50.00000,0.0000e+000,20.00000,    -0.13215,0.62749
640.94800, 75.33916,    -1.19682,73.80028,50.00000,0.0000e+000,20.00000,    -0.13402,0.62653
642.72198, 75.51917,    -1.19187,73.77806,50.00000,0.0000e+000,20.00000,    -0.13522,0.62561
644.49402, 75.69917,    -1.18757,73.75428,50.00000,0.0000e+000,20.00000,    -0.13629,0.62470
646.30603, 75.87917,    -1.19080,73.72963,50.00000,0.0000e+000,20.00000,    -0.13754,0.62377
648.14001, 76.05917,    -1.19559,73.70430,50.00000,0.0000e+000,20.00000,    -0.13911,0.62283
649.96899, 76.23917,    -1.19751,73.67919,50.00000,0.0000e+000,20.00000,    -0.14047,0.62190
651.78003, 76.41917,    -1.19683,73.65366,50.00000,0.0000e+000,20.00000,    -0.14195,0.62098
653.57599, 76.59917,    -1.19622,73.62716,50.00000,0.0000e+000,20.00000,    -0.14378,0.62008
655.36798, 76.77917,    -1.19495,73.60093,50.00000,0.0000e+000,20.00000,    -0.14581,0.61918
657.15399, 76.95917,    -1.19390,73.57229,50.00000,0.0000e+000,20.00000,    -0.14814,0.61828
658.95801, 77.13917,    -1.19526,73.54372,50.00000,0.0000e+000,20.00000,    -0.15036,0.61738
660.76801, 77.31917,    -1.19858,73.51728,50.00000,0.0000e+000,20.00000,    -0.15264,0.61649
662.55902, 77.49917,    -1.19734,73.49165,50.00000,0.0000e+000,20.00000,    -0.15409,0.61560
664.33899, 77.67917,    -1.19384,73.46497,50.00000,0.0000e+000,20.00000,    -0.15519,0.61472
666.12299, 77.85917,    -1.19244,73.43653,50.00000,0.0000e+000,20.00000,    -0.15680,0.61385
667.92102, 78.03917,    -1.19148,73.40845,50.00000,0.0000e+000,20.00000,    -0.15875,0.61297
669.70001, 78.21917,    -1.19112,73.38019,50.00000,0.0000e+000,20.00000,    -0.16070,0.61211
671.47699, 78.39917,    -1.19110,73.35047,50.00000,0.0000e+000,20.00000,    -0.16217,0.61125
673.26001, 78.57917,    -1.18979,73.32041,50.00000,0.0000e+000,20.00000,    -0.16397,0.61039
675.05402, 78.75916,    -1.19061,73.28957,50.00000,0.0000e+000,20.00000,    -0.16530,0.60953
676.85498, 78.93916,    -1.19421,73.25877,50.00000,0.0000e+000,20.00000,    -0.16617,0.60866
678.66400, 79.11916,    -1.19457,73.22826,50.00000,0.0000e+000,20.00000,    -0.16736,0.60780
680.47400, 79.29916,    -1.19515,73.19907,50.00000,0.0000e+000,20.00000,    -0.16875,0.60694
682.28400, 79.47916,    -1.19439,73.17078,50.00000,0.0000e+000,20.00000,    -0.16963,0.60609
684.08398, 79.65916,    -1.19364,73.13995,50.00000,0.0000e+000,20.00000,    -0.16926,0.60524
685.89099, 79.83916,    -1.19195,73.10773,50.00000,0.0000e+000,20.00000,    -0.16882,0.60439
687.70300, 80.01917,    -1.18958,73.07523,50.00000,0.0000e+000,20.00000,    -0.16871,0.60355
689.50299, 80.19917,    -1.18723,73.04329,50.00000,0.0000e+000,20.00000,    -0.16777,0.60271
691.32001, 80.37917,    -1.18811,73.01082,50.00000,0.0000e+000,20.00000,    -0.16587,0.60187
693.12299, 80.55917,    -1.18662,72.97761,50.00000,0.0000e+000,20.00000,    -0.16310,0.60104
694.95203, 80.73917,    -1.19234,72.94537,50.00000,0.0000e+000,20.00000,    -0.16051,0.60020
696.78003, 80.91917,    -1.19517,72.91427,50.00000,0.0000e+000,20.00000,    -0.15759,0.59936
698.61102, 81.09917,    -1.19680,72.88344,50.00000,0.0000e+000,20.00000,    -0.15440,0.59852
700.44800, 81.27917,    -1.20156,72.85355,50.00000,0.0000e+000,20.00000,    -0.15161,0.59769
702.27802, 81.45917,    -1.20358,72.82625,50.00000,0.0000e+000,20.00000,    -0.14838,0.59686
704.10101, 81.63917,    -1.20307,72.79982,50.00000,0.0000e+000,20.00000,    -0.14445,0.59604
705.90100, 81.81917,    -1.20182,72.77218,50.00000,0.0000e+000,20.00000,    -0.14083,0.59523
707.67999, 81.99917,    -1.19958,72.74567,50.00000,0.0000e+000,20.00000,    -0.13728,0.59444
709.46698, 82.17917,    -1.19751,72.72210,50.00000,0.0000e+000,20.00000,    -0.13333,0.59364
711.23499, 82.35917,    -1.19613,72.70131,50.00000,0.0000e+000,20.00000,    -0.12907,0.59286
713.00897, 82.53917,    -1.19600,72.68006,50.00000,0.0000e+000,20.00000,    -0.12494,0.59207
714.77698, 82.71917,    -1.19481,72.65979,50.00000,0.0000e+000,20.00000,    -0.12044,0.59129
716.51398, 82.89917,    -1.19033,72.64169,50.00000,0.0000e+000,20.00000,    -0.11559,0.59053
718.28302, 83.07917,    -1.18855,72.62396,50.00000,0.0000e+000,20.00000,    -0.11150,0.58975
720.04102, 83.25916,    -1.19117,72.60521,50.00000,0.0000e+000,20.00000,    -0.10797,0.58899
721.91400, 83.43916,    -1.20334,72.58751,50.00000,0.0000e+000,20.00000,    -0.10487,0.58817
723.77399, 83.61916,    -1.21473,72.56846,50.00000,0.0000e+000,20.00000,    -0.10141,0.58737
725.61700, 83.79916,    -1.21667,72.54917,50.00000,0.0000e+000,20.00000,-9.7780e-002,0.58658
727.42102, 83.97916,    -1.21187,72.53127,50.00000,0.0000e+000,20.00000,-9.4459e-002,0.58580
729.19897, 84.15916,    -1.20371,72.51359,50.00000,0.0000e+000,20.00000,-9.2505e-002,0.58504
730.98700, 84.33916,    -1.19799,72.49615,50.00000,0.0000e+000,20.00000,-9.0562e-002,0.58428
732.75897, 84.51917,    -1.19539,72.48078,50.00000,0.0000e+000,20.00000,-8.8447e-002,0.58352
734.61102, 84.69917,    -1.19824,72.46781,50.00000,0.0000e+000,20.00000,-8.6235e-002,0.58274
736.45898, 84.87917,    -1.20141,72.45280,50.00000,0.0000e+000,20.00000,-8.4651e-002,0.58196
738.29199, 85.05917,    -1.20118,72.43784,50.00000,0.0000e+000,20.00000,-8.3362e-002,0.58119
740.12000, 85.23917,    -1.19839,72.42297,50.00000,0.0000e+000,20.00000,-8.2226e-002,0.58042
741.91400, 85.41917,    -1.19142,72.40798,50.00000,0.0000e+000,20.00000,-8.1033e-002,0.57967
743.72302, 85.59917,    -1.18744,72.39403,50.00000,0.0000e+000,20.00000,-7.9220e-002,0.57892
745.53998, 85.77917,    -1.18595,72.38217,50.00000,0.0000e+000,20.00000,-7.6902e-002,0.57816
747.32202, 85.95917,    -1.18195,72.36854,50.00000,0.0000e+000,20.00000,-7.4774e-002,0.57743
749.13000, 86.13917,    -1.17514,72.35440,50.00000,0.0000e+000,20.00000,-7.3402e-002,0.57668
750.92200, 86.31917,    -1.16825,72.34130,50.00000,0.0000e+000,20.00000,-7.2002e-002,0.57595
752.69800, 86.49917,    -1.16328,72.33064,50.00000,0.0000e+000,20.00000,-7.0628e-002,0.57522
754.47803, 86.67917,    -1.15915,72.31946,50.00000,0.0000e+000,20.00000,-6.8797e-002,0.57449
756.31299, 86.85917,    -1.16054,72.30541,50.00000,0.0000e+000,20.00000,-6.7516e-002,0.57374
758.13098, 87.03917,    -1.16082,72.29186,50.00000,0.0000e+000,20.00000,-6.5970e-002,0.57301
759.92999, 87.21917,    -1.15763,72.27745,50.00000,0.0000e+000,20.00000,-6.4068e-002,0.57228
761.73700, 87.39917,    -1.15261,72.26423,50.00000,0.0000e+000,20.00000,-6.2586e-002,0.57155
763.51099, 87.57917,    -1.14681,72.25420,50.00000,0.0000e+000,20.00000,-6.1997e-002,0.57084
765.29797, 87.75916,    -1.14286,72.24476,50.00000,0.0000e+000,20.00000,-6.1192e-002,0.57012
767.11603, 87.93916,    -1.14265,72.23235,50.00000,0.0000e+000,20.00000,-6.0355e-002,0.56940
768.91400, 88.11916,    -1.14028,72.22116,50.00000,0.0000e+000,20.00000,-5.9450e-002,0.56868
770.70599, 88.29916,    -1.13802,72.21282,50.00000,0.0000e+000,20.00000,-5.8401e-002,0.56797
772.51202, 88.47916,    -1.13691,72.20517,50.00000,0.0000e+000,20.00000,-5.7717e-002,0.56725
774.30200, 88.65916,    -1.13650,72.19488,50.00000,0.0000e+000,20.00000,-5.6461e-002,0.56655
776.08801, 88.83916,    -1.13615,72.18540,50.00000,0.0000e+000,20.00000,-5.5469e-002,0.56584
777.89899, 89.01917,    -1.13814,72.17739,50.00000,0.0000e+000,20.00000,-5.4214e-002,0.56513
779.70599, 89.19917,    -1.13987,72.16861,50.00000,0.0000e+000,20.00000,-5.2807e-002,0.56443
781.50403, 89.37917,    -1.13873,72.15901,50.00000,0.0000e+000,20.00000,-5.1923e-002,0.56372
783.28699, 89.55917,    -1.14115,72.14868,50.00000,0.0000e+000,20.00000,-5.1193e-002,0.56303
785.08099, 89.73917,    -1.14347,72.13765,50.00000,0.0000e+000,20.00000,-4.9936e-002,0.56233
786.89398, 89.91917,    -1.14576,72.12720,50.00000,0.0000e+000,20.00000,-4.9375e-002,0.56163
788.71503, 90.09917,    -1.14996,72.11975,50.00000,0.0000e+000,20.00000,-4.9981e-002,0.56093
790.51703, 90.27917,    -1.15388,72.11186,50.00000,0.0000e+000,20.00000,-5.1203e-002,0.56024
792.33197, 90.45917,    -1.15683,72.10260,50.00000,0.0000e+000,20.00000,-5.1455e-002,0.55954
794.13898, 90.63917,    -1.15913,72.09282,50.00000,0.0000e+000,20.00000,-5.1429e-002,0.55885
795.95001, 90.81917,    -1.16122,72.08284,50.00000,0.0000e+000,20.00000,-5.1654e-002,0.55815
797.75897, 90.99917,    -1.16246,72.07436,50.00000,0.0000e+000,20.00000,-5.2172e-002,0.55747
799.56097, 91.17917,    -1.16359,72.06671,50.00000,0.0000e+000,20.00000,-5.2702e-002,0.55678
801.36798, 91.35917,    -1.16559,72.06038,50.00000,0.0000e+000,20.00000,-5.2711e-002,0.55610
803.18597, 91.53917,    -1.16856,72.05302,50.00000,0.0000e+000,20.00000,-5.1948e-002,0.55541
805.03101, 91.71917,    -1.17190,72.04380,50.00000,0.0000e+000,20.00000,-5.1507e-002,0.55471
806.82098, 91.89917,    -1.17160,72.03301,50.00000,0.0000e+000,20.00000,-5.2318e-002,0.55404
808.60797, 92.07917,    -1.16808,72.02117,50.00000,0.0000e+000,20.00000,-5.3144e-002,0.55337
810.39099, 92.25916,    -1.16712,72.01000,50.00000,0.0000e+000,20.00000,-5.3869e-002,0.55270
812.16998, 92.43916,    -1.16699,72.00014,50.00000,0.0000e+000,20.00000,-5.4233e-002,0.55204
813.97198, 92.61916,    -1.16983,71.99126,50.00000,0.0000e+000,20.00000,-5.4730e-002,0.55136
815.76501, 92.79916,    -1.17232,71.98102,50.00000,0.0000e+000,20.00000,-5.6109e-002,0.55070
817.57898, 92.97916,    -1.17303,71.96965,50.00000,0.0000e+000,20.00000,-5.7625e-002,0.55002
819.38599, 93.15916,    -1.17557,71.95901,50.00000,0.0000e+000,20.00000,-5.9120e-002,0.54935
821.20898, 93.33916,    -1.17852,71.95076,50.00000,0.0000e+000,20.00000,-6.0568e-002,0.54868
823.02399, 93.51917,    -1.18000,71.94185,50.00000,0.0000e+000,20.00000,-6.1795e-002,0.54801
824.82599, 93.69917,    -1.18050,71.93128,50.00000,0.0000e+000,20.00000,-6.2661e-002,0.54735
826.66699, 93.87917,    -1.18464,71.92059,50.00000,0.0000e+000,20.00000,-6.3442e-002,0.54667
828.55902, 94.05917,    -1.19325,71.90898,50.00000,0.0000e+000,20.00000,-6.4275e-002,0.54598
830.40002, 94.23917,    -1.19495,71.89779,50.00000,0.0000e+000,20.00000,-6.5532e-002,0.54531
832.21301, 94.41917,    -1.19166,71.88621,50.00000,0.0000e+000,20.00000,-6.7854e-002,0.54464
834.01599, 94.59917,    -1.18865,71.87269,50.00000,0.0000e+000,20.00000,-7.0080e-002,0.54399
835.82300, 94.77917,    -1.18639,71.85904,50.00000,0.0000e+000,20.00000,-7.1893e-002,0.54333
837.59302, 94.95917,    -1.18482,71.84709,50.00000,0.0000e+000,20.00000,-7.3692e-002,0.54269
839.39099, 95.13917,    -1.18429,71.83487,50.00000,0.0000e+000,20.00000,-7.6333e-002,0.54204
841.18103, 95.31917,    -1.18230,71.82150,50.00000,0.0000e+000,20.00000,-7.9499e-002,0.54139
842.95599, 95.49917,    -1.17982,71.80789,50.00000,0.0000e+000,20.00000,-8.2511e-002,0.54075
844.75403, 95.67917,    -1.18116,71.79337,50.00000,0.0000e+000,20.00000,-8.5586e-002,0.54010
846.54102, 95.85917,    -1.18327,71.77882,50.00000,0.0000e+000,20.00000,-8.8102e-002,0.53946
848.33801, 96.03917,    -1.18324,71.76448,50.00000,0.0000e+000,20.00000,-9.0262e-002,0.53881
850.14600, 96.21917,    -1.18470,71.74736,50.00000,0.0000e+000,20.00000,-9.3068e-002,0.53816
851.94598, 96.39917,    -1.18442,71.72933,50.00000,0.0000e+000,20.00000,-9.5744e-002,0.53752
853.73999, 96.57917,    -1.18446,71.71135,50.00000,0.0000e+000,20.00000,-9.8297e-002,0.53688
855.53802, 96.75916,    -1.18643,71.69379,50.00000,0.0000e+000,20.00000,    -0.10057,0.53624
857.35498, 96.93916,    -1.18766,71.67589,50.00000,0.0000e+000,20.00000,    -0.10342,0.53559
859.15002, 97.11916,    -1.18647,71.65594,50.00000,0.0000e+000,20.00000,    -0.10597,0.53495
860.94202, 97.29916,    -1.18499,71.63473,50.00000,0.0000e+000,20.00000,    -0.10800,0.53431
862.76599, 97.47916,    -1.18591,71.61269,50.00000,0.0000e+000,20.00000,    -0.11075,0.53367
864.56897, 97.65916,    -1.18701,71.59181,50.00000,0.0000e+000,20.00000,    -0.11399,0.53303
866.38202, 97.83916,    -1.18780,71.57257,50.00000,0.0000e+000,20.00000,    -0.11702,0.53239
868.17401, 98.01917,    -1.18695,71.55138,50.00000,0.0000e+000,20.00000,    -0.11880,0.53175
870.00299, 98.19917,    -1.18847,71.52849,50.00000,0.0000e+000,20.00000,    -0.12044,0.53111
871.84100, 98.37917,    -1.19112,71.50510,50.00000,0.0000e+000,20.00000,    -0.12203,0.53046
873.64398, 98.55917,    -1.18767,71.48442,50.00000,0.0000e+000,20.00000,    -0.12411,0.52983
875.43799, 98.73917,    -1.18504,71.46242,50.00000,0.0000e+000,20.00000,    -0.12653,0.52919
877.24298, 98.91917,    -1.18453,71.43945,50.00000,0.0000e+000,20.00000,    -0.12844,0.52856
879.04199, 99.09917,    -1.18386,71.41866,50.00000,0.0000e+000,20.00000,    -0.13034,0.52793
880.83398, 99.27917,    -1.18278,71.39477,50.00000,0.0000e+000,20.00000,    -0.13206,0.52730
882.62903, 99.45917,    -1.18407,71.36841,50.00000,0.0000e+000,20.00000,    -0.13325,0.52667
884.44800, 99.63917,    -1.18438,71.34273,50.00000,0.0000e+000,20.00000,    -0.13487,0.52604
886.33002, 99.81917,    -1.19199,71.31946,50.00000,0.0000e+000,20.00000,    -0.13674,0.52538
888.22198, 99.99917,    -1.20181,71.29558,50.00000,0.0000e+000,20.00000,    -0.13827,0.52472
890.04102,100.17917,    -1.19991,71.27173,50.00000,0.0000e+000,20.00000,    -0.13954,0.52408
891.83801,100.35917,    -1.19106,71.24681,50.00000,0.0000e+000,20.00000,    -0.14158,0.52346
893.61798,100.53917,    -1.18534,71.22032,50.00000,0.0000e+000,20.00000,    -0.14347,0.52284
895.36798,100.71917,    -1.18169,71.19380,50.00000,0.0000e+000,20.00000,    -0.14500,0.52223
897.14801,100.89917,    -1.18130,71.16603,50.00000,0.0000e+000,20.00000,    -0.14746,0.52161
898.93500,101.07917,    -1.18104,71.13752,50.00000,0.0000e+000,20.00000,    -0.14923,0.52099
900.72302,101.25916,    -1.18168,71.11160,50.00000,0.0000e+000,20.00000,    -0.15012,0.52037
902.47601,101.43916,    -1.18163,71.08658,50.00000,0.0000e+000,20.00000,    -0.15084,0.51976
904.26398,101.61916,    -1.18227,71.05933,50.00000,0.0000e+000,20.00000,    -0.15218,0.51914
906.02802,101.79916,    -1.18366,71.03098,50.00000,0.0000e+000,20.00000,    -0.15400,0.51853
907.84302,101.97916,    -1.18726,71.00286,50.00000,0.0000e+000,20.00000,    -0.15562,0.51790
909.63898,102.15916,    -1.19098,70.97440,50.00000,0.0000e+000,20.00000,    -0.15630,0.51728
911.43500,102.33916,    -1.19250,70.94592,50.00000,0.0000e+000,20.00000,    -0.15700,0.51666
913.23199,102.51917,    -1.19352,70.91730,50.00000,0.0000e+000,20.00000,    -0.15826,0.51604
915.04401,102.69917,    -1.19600,70.88753,50.00000,0.0000e+000,20.00000,    -0.15933,0.51541
916.86499,102.87917,    -1.19750,70.85774,50.00000,0.0000e+000,20.00000,    -0.16026,0.51478
918.67200,103.05917,    -1.19689,70.82827,50.00000,0.0000e+000,20.00000,    -0.16188,0.51416
920.50299,103.23917,    -1.20134,70.79943,50.00000,0.0000e+000,20.00000,    -0.16366,0.51353
922.32098,103.41917,    -1.20310,70.77125,50.00000,0.0000e+000,20.00000,    -0.16425,0.51290
924.16302,103.59917,    -1.20641,70.74113,50.00000,0.0000e+000,20.00000,    -0.16382,0.51227
926.01099,103.77917,    -1.20911,70.71088,50.00000,0.0000e+000,20.00000,    -0.16422,0.51163
927.83600,103.95917,    -1.20737,70.68364,50.00000,0.0000e+000,20.00000,    -0.16566,0.51100
929.62903,104.13917,    -1.20235,70.65518,50.00000,0.0000e+000,20.00000,    -0.16721,0.51038
931.40802,104.31917,    -1.19378,70.62422,50.00000,0.0000e+000,20.00000,    -0.16876,0.50977
933.20502,104.49917,    -1.18927,70.59286,50.00000,0.0000e+000,20.00000,    -0.16959,0.50915
934.99597,104.67917,    -1.18463,70.56095,50.00000,0.0000e+000,20.00000,    -0.17027,0.50853
936.80103,104.85917,    -1.17874,70.52867,50.00000,0.0000e+000,20.00000,    -0.17181,0.50791
938.60797,105.03917,    -1.17329,70.49698,50.00000,0.0000e+000,20.00000,    -0.17362,0.50729
940.38501,105.21917,    -1.16525,70.46758,50.00000,0.0000e+000,20.00000,    -0.17558,0.50668
942.19000,105.39917,    -1.15956,70.44057,50.00000,0.0000e+000,20.00000,    -0.17686,0.50606
944.00800,105.57917,    -1.15664,70.41183,50.00000,0.0000e+000,20.00000,    -0.17807,0.50543
945.81500,105.75916,    -1.15114,70.37851,50.00000,0.0000e+000,20.00000,    -0.17958,0.50481
947.62097,105.93916,    -1.14512,70.34433,50.00000,0.0000e+000,20.00000,    -0.18099,0.50419
949.41803,106.11916,    -1.14131,70.31006,50.00000,0.0000e+000,20.00000,    -0.18216,0.50357
951.21503,106.29916,    -1.13690,70.27716,50.00000,0.0000e+000,20.00000,    -0.18327,0.50295
953.06598,106.47916,    -1.13838,70.24503,50.00000,0.0000e+000,20.00000,    -0.18345,0.50231
954.92102,106.65916,    -1.14249,70.21028,50.00000,0.0000e+000,20.00000,    -0.18377,0.50167
956.74597,106.83916,    -1.14189,70.17454,50.00000,0.0000e+000,20.00000,    -0.18483,0.50105
958.53998,107.01917,    -1.13966,70.13928,50.00000,0.0000e+000,20.00000,    -0.18581,0.50043
960.34601,107.19917,    -1.13587,70.10466,50.00000,0.0000e+000,20.00000,    -0.18648,0.49981
962.22302,107.37917,    -1.14137,70.06979,50.00000,0.0000e+000,20.00000,    -0.18672,0.49916
964.06702,107.55917,    -1.14512,70.03625,50.00000,0.0000e+000,20.00000,    -0.18469,0.49852
965.85699,107.73917,    -1.14024,70.00345,50.00000,0.0000e+000,20.00000,    -0.18101,0.49791
967.62299,107.91917,    -1.13299,69.96863,50.00000,0.0000e+000,20.00000,    -0.17694,0.49730
969.38599,108.09917,    -1.12853,69.93311,50.00000,0.0000e+000,20.00000,    -0.17287,0.49669
971.14502,108.27917,    -1.12803,69.90018,50.00000,0.0000e+000,20.00000,    -0.16867,0.49608
972.88898,108.45917,    -1.12799,69.86732,50.00000,0.0000e+000,20.00000,    -0.16337,0.49548
974.68799,108.63917,    -1.13476,69.83153,50.00000,0.0000e+000,20.00000,    -0.15731,0.49486
976.50201,108.81917,    -1.14135,69.79761,50.00000,0.0000e+000,20.00000,    -0.15094,0.49423
978.33398,108.99917,    -1.15020,69.76744,50.00000,0.0000e+000,20.00000,    -0.14422,0.49360
980.14203,109.17917,    -1.15596,69.73847,50.00000,0.0000e+000,20.00000,    -0.13776,0.49297
981.93597,109.35917,    -1.15888,69.71217,50.00000,0.0000e+000,20.00000,    -0.13261,0.49235
983.73999,109.53917,    -1.16423,69.69102,50.00000,0.0000e+000,20.00000,    -0.12497,0.49172
985.54901,109.71917,    -1.16891,69.67144,50.00000,0.0000e+000,20.00000,    -0.11685,0.49110
987.34198,109.89917,    -1.17242,69.65292,50.00000,0.0000e+000,20.00000,    -0.10419,0.49048
989.17200,110.07917,    -1.17883,69.63600,50.00000,0.0000e+000,20.00000,-9.2194e-002,0.48984
990.98297,110.25916,    -1.18321,69.62077,50.00000,0.0000e+000,20.00000,-8.1725e-002,0.48921
992.80902,110.43916,    -1.18726,69.60702,50.00000,0.0000e+000,20.00000,-7.3751e-002,0.48858
994.61499,110.61916,    -1.19031,69.59458,50.00000,0.0000e+000,20.00000,-6.5785e-002,0.48795
996.40503,110.79916,    -1.19339,69.58441,50.00000,0.0000e+000,20.00000,-5.8475e-002,0.48733
998.18500,110.97916,    -1.19056,69.57257,50.00000,0.0000e+000,20.00000,-4.1598e-002,0.48671
998.38098,110.99917,    -1.19094,69.57222,50.00000,0.0000e+000,20.00000, 8.1138e-003,0.48664