File: book/some_content/DG_ExpDat_OPC7%DC28; 13-2-2025-2_ERROR_TIJDENS_EXPERIMENT.csv
#FILE:                       ,OPC7%DC28; 13-2-2025.ngb-ds3
#FORMAT:                     ,NETZSCH5
#IDENTITY:                   ,geopolymer paste
#DECIMAL:                    ,POINT
#SEPARATOR:                  ,COMMA
#MTYPE:                      ,DSC
#INSTRUMENT:                 ,Microlab TU Delft
#PROJECT:                    ,
#DATE/TIME:                  ,13/02/2025 1:33:34 PM
#CORR. FILE:                 ,Blank with cover; 13-1-2025.ngb-bs3
#LABORATORY:                 ,TU Delft Micro Lab
#OPERATOR:                   ,Ahmed
#REMARK:                     ,under Argon atmosphere, 10K/min
#SAMPLE:                     ,OPC7%DC28
#SAMPLE MASS /mg:            ,37.2
#MATERIAL:                   ,Geopolymer paste
#REFERENCE:                  ,blank
#REFERENCE MASS /mg:         ,0
#TYPE OF CRUCIBLE:           ,DSC/TG pan Al2O3
#SAMPLE CRUCIBLE MASS /mg:   ,0
#REFERENCE CRUCIBLE MASS /mg:,0
#CORR. CODE:                 ,020
#EXO:                        ,-1
#RANGE:                      ,40/10.0(K/min)/1000
#SEGMENT:                    ,S2/2

##Temp./øC,Time/min,DSC/(mW/mg),Mass/%,Gas Flow(purge1)/(ml/min),Gas Flow(purge2)/(ml/min),Gas Flow(protective)/(ml/min),DTG/(%/min),Sensit./(uV/mW)
 49.67800, 18.26167,-6.7243e-002,97.56718,50.00000,0.0000e+000,20.00000,-4.4027e-002,1.21360
 49.70900, 18.43667,-6.8681e-002,97.56514,50.00000,0.0000e+000,20.00000,-3.1177e-002,1.21356
 49.81400, 18.61167,-6.9856e-002,97.56761,50.00000,0.0000e+000,20.00000,    -0.10600,1.21342
 49.99600, 18.78667,-7.0310e-002,97.57026,50.00000,0.0000e+000,20.00000,    -1.32787,1.21317
 50.24000, 18.96167,-6.9737e-002,97.57511,50.00000,0.0000e+000,20.00000,    -1.72751,1.21283
 50.63500, 19.13667,-6.8517e-002,97.58329,50.00000,0.0000e+000,20.00000,    -0.18517,1.21229
 51.09300, 19.31167,-6.7131e-002,97.59451,50.00000,0.0000e+000,20.00000, 3.2878e-002,1.21166
 51.73600, 19.48667,-6.4910e-002,97.61006,50.00000,0.0000e+000,20.00000, 4.3911e-002,1.21077
 52.46100, 19.66167,-6.2251e-002,97.63065,50.00000,0.0000e+000,20.00000, 5.2602e-002,1.20977
 53.30200, 19.83667,-5.8849e-002,97.64970,50.00000,0.0000e+000,20.00000, 6.0688e-002,1.20861
 54.28100, 20.01167,-5.5721e-002,97.66287,50.00000,0.0000e+000,20.00000, 6.6896e-002,1.20727
 55.36300, 20.18667,-5.1554e-002,97.67731,50.00000,0.0000e+000,20.00000, 7.1583e-002,1.20578
 56.56700, 20.36167,-4.7725e-002,97.65755,50.00000,0.0000e+000,20.00000, 7.3998e-002,1.20412
 57.89200, 20.53667,-4.3652e-002,95.72483,50.00000,0.0000e+000,20.00000, 7.4154e-002,1.20230
 59.32800, 20.71167,-3.9879e-002,90.15854,50.00000,0.0000e+000,20.00000, 7.2863e-002,1.20033
 60.89100, 20.88667,-3.5792e-002,95.12858,50.00000,0.0000e+000,20.00000, 7.0409e-002,1.19818
 62.55400, 21.06167,-3.1658e-002,97.69516,50.00000,0.0000e+000,20.00000, 6.6784e-002,1.19589
 64.28000, 21.23667,-2.7941e-002,97.77551,50.00000,0.0000e+000,20.00000, 6.2056e-002,1.19352
 66.14300, 21.41167,-2.4677e-002,97.78606,50.00000,0.0000e+000,20.00000, 5.5246e-002,1.19096
 68.12500, 21.58667,-2.1109e-002,97.79884,50.00000,0.0000e+000,20.00000, 4.6715e-002,1.18825
 70.13700, 21.76167,-1.7490e-002,97.81048,50.00000,0.0000e+000,20.00000, 3.8562e-002,1.18549
 72.24800, 21.93667,-1.4186e-002,97.82137,50.00000,0.0000e+000,20.00000, 2.9672e-002,1.18259
 74.42900, 22.11167,-1.0953e-002,97.83303,50.00000,0.0000e+000,20.00000, 1.9193e-002,1.17961
 76.70200, 22.28667,-7.6354e-003,97.83956,50.00000,0.0000e+000,20.00000,     0.14349,1.17650
 79.03400, 22.46167,-4.8594e-003,97.83956,50.00000,0.0000e+000,20.00000,     1.53087,1.17331
 81.42100, 22.63667,-1.6477e-003,97.83767,50.00000,0.0000e+000,20.00000,     1.51502,1.17005
 83.89700, 22.81167, 1.6876e-003,97.83497,50.00000,0.0000e+000,20.00000, 9.5327e-002,1.16667
 86.42600, 22.98667, 5.2365e-003,97.83105,50.00000,0.0000e+000,20.00000,-6.0892e-002,1.16322
 88.99000, 23.16167, 9.1075e-003,97.82632,50.00000,0.0000e+000,20.00000,-8.1475e-002,1.15973
 91.60400, 23.33667, 1.3109e-002,97.81785,50.00000,0.0000e+000,20.00000,    -0.10452,1.15617
 94.25800, 23.51167, 1.8257e-002,97.80535,50.00000,0.0000e+000,20.00000,    -0.12777,1.15256
 96.94300, 23.68667, 2.3385e-002,97.78789,50.00000,0.0000e+000,20.00000,    -0.14988,1.14892
 99.65600, 23.86167, 2.8725e-002,97.76659,50.00000,0.0000e+000,20.00000,    -0.17432,1.14524
102.37900, 24.03667, 3.4818e-002,97.73823,50.00000,0.0000e+000,20.00000,    -0.20111,1.14155
105.12300, 24.21167, 4.1601e-002,97.70528,50.00000,0.0000e+000,20.00000,    -0.22599,1.13784
107.89600, 24.38667, 4.8429e-002,97.66775,50.00000,0.0000e+000,20.00000,    -0.24926,1.13410
110.66300, 24.56167, 5.6082e-002,97.62267,50.00000,0.0000e+000,20.00000,    -0.27194,1.13037
113.43500, 24.73667, 6.3877e-002,97.57155,50.00000,0.0000e+000,20.00000,    -0.29414,1.12664
116.18600, 24.91167, 7.2124e-002,97.51274,50.00000,0.0000e+000,20.00000,    -0.31705,1.12294
118.96700, 25.08667, 8.0226e-002,97.44359,50.00000,0.0000e+000,20.00000,    -0.33939,1.11921
121.73900, 25.26167, 8.8012e-002,97.37042,50.00000,0.0000e+000,20.00000,    -0.36171,1.11549
124.48700, 25.43667, 9.5774e-002,97.29959,50.00000,0.0000e+000,20.00000,    -0.38192,1.11182
127.23800, 25.61167,     0.10268,97.22717,50.00000,0.0000e+000,20.00000,    -0.39971,1.10815
129.98599, 25.78667,     0.10820,97.14215,50.00000,0.0000e+000,20.00000,    -0.41549,1.10448
132.73801, 25.96167,     0.11365,97.05316,50.00000,0.0000e+000,20.00000,    -0.42894,1.10082
135.45799, 26.13667,     0.11722,96.96550,50.00000,0.0000e+000,20.00000,    -0.43945,1.09721
138.15401, 26.31167,     0.11983,96.88010,50.00000,0.0000e+000,20.00000,    -0.44901,1.09364
140.85500, 26.48667,     0.12162,96.79545,50.00000,0.0000e+000,20.00000,    -0.45644,1.09007
143.52400, 26.66167,     0.12169,96.70909,50.00000,0.0000e+000,20.00000,    -0.46178,1.08654
146.18700, 26.83667,     0.12042,96.62105,50.00000,0.0000e+000,20.00000,    -0.46401,1.08304
148.79300, 27.01167,     0.11841,96.53056,50.00000,0.0000e+000,20.00000,    -0.46168,1.07961
151.37801, 27.18667,     0.11550,96.43896,50.00000,0.0000e+000,20.00000,    -0.45868,1.07622
153.95900, 27.36167,     0.11063,96.35273,50.00000,0.0000e+000,20.00000,    -0.45666,1.07284
156.48801, 27.53667,     0.10453,96.26985,50.00000,0.0000e+000,20.00000,    -0.45139,1.06954
158.98900, 27.71167, 9.7499e-002,96.18721,50.00000,0.0000e+000,20.00000,    -0.44211,1.06627
161.47701, 27.88667, 8.9346e-002,96.11133,50.00000,0.0000e+000,20.00000,    -0.43308,1.06304
163.93201, 28.06167, 7.9978e-002,96.03698,50.00000,0.0000e+000,20.00000,    -0.42479,1.05985
166.34100, 28.23667, 7.0063e-002,95.95954,50.00000,0.0000e+000,20.00000,    -0.41609,1.05673
168.72501, 28.41167, 5.9485e-002,95.88550,50.00000,0.0000e+000,20.00000,    -0.40621,1.05365
171.08600, 28.58667, 4.8589e-002,95.81072,50.00000,0.0000e+000,20.00000,    -0.39440,1.05060
173.41901, 28.76167, 3.7373e-002,95.74287,50.00000,0.0000e+000,20.00000,    -0.38205,1.04760
175.72000, 28.93667, 2.5974e-002,95.68136,50.00000,0.0000e+000,20.00000,    -0.36883,1.04464
177.98900, 29.11167, 1.4746e-002,95.61925,50.00000,0.0000e+000,20.00000,    -0.35642,1.04173
180.23000, 29.28667, 3.2574e-003,95.55714,50.00000,0.0000e+000,20.00000,    -0.34489,1.03887
182.45399, 29.46167,-8.0767e-003,95.50058,50.00000,0.0000e+000,20.00000,    -0.33308,1.03603
184.65300, 29.63667,-1.9036e-002,95.44599,50.00000,0.0000e+000,20.00000,    -0.32150,1.03323
186.80901, 29.81167,-2.9873e-002,95.38981,50.00000,0.0000e+000,20.00000,    -0.31075,1.03049
188.96400, 29.98667,-4.0988e-002,95.33519,50.00000,0.0000e+000,20.00000,    -0.29865,1.02775
191.06000, 30.16167,-5.1798e-002,95.28421,50.00000,0.0000e+000,20.00000,    -0.28673,1.02510
193.14900, 30.33667,-6.2342e-002,95.23797,50.00000,0.0000e+000,20.00000,    -0.27513,1.02246
195.22900, 30.51167,-7.2517e-002,95.19421,50.00000,0.0000e+000,20.00000,    -0.26435,1.01984
197.25500, 30.68667,-8.2738e-002,95.15053,50.00000,0.0000e+000,20.00000,    -0.25551,1.01730
199.26801, 30.86167,-9.2403e-002,95.10662,50.00000,0.0000e+000,20.00000,    -0.24698,1.01477
201.25400, 31.03667,    -0.10272,95.06419,50.00000,0.0000e+000,20.00000,    -0.23757,1.01228
203.21201, 31.21167,    -0.11207,95.02341,50.00000,0.0000e+000,20.00000,    -0.22859,1.00984
205.14301, 31.38667,    -0.12172,94.98511,50.00000,0.0000e+000,20.00000,    -0.22042,1.00743
207.06200, 31.56167,    -0.13101,94.94948,50.00000,0.0000e+000,20.00000,    -0.21177,1.00504
208.96300, 31.73667,    -0.14001,94.91657,50.00000,0.0000e+000,20.00000,    -0.20315,1.00268
210.85100, 31.91167,    -0.14897,94.88409,50.00000,0.0000e+000,20.00000,    -0.19582,1.00035
212.70700, 32.08667,    -0.15817,94.85255,50.00000,0.0000e+000,20.00000,    -0.18935,0.99805
214.57300, 32.26167,    -0.16617,94.81979,50.00000,0.0000e+000,20.00000,    -0.18332,0.99575
216.38300, 32.43667,    -0.17464,94.78810,50.00000,0.0000e+000,20.00000,    -0.17760,0.99352
218.21001, 32.61167,    -0.18273,94.75756,50.00000,0.0000e+000,20.00000,    -0.17202,0.99128
220.00600, 32.78667,    -0.19060,94.72822,50.00000,0.0000e+000,20.00000,    -0.16768,0.98908
221.80000, 32.96167,    -0.19855,94.70099,50.00000,0.0000e+000,20.00000,    -0.16268,0.98688
223.57100, 33.13667,    -0.20623,94.67550,50.00000,0.0000e+000,20.00000,    -0.15738,0.98472
225.33200, 33.31167,    -0.21424,94.65140,50.00000,0.0000e+000,20.00000,    -0.15277,0.98258
227.08099, 33.48667,    -0.22148,94.62734,50.00000,0.0000e+000,20.00000,    -0.14936,0.98045
228.83701, 33.66167,    -0.22901,94.60231,50.00000,0.0000e+000,20.00000,    -0.14635,0.97832
230.56100, 33.83667,    -0.23628,94.57630,50.00000,0.0000e+000,20.00000,    -0.14332,0.97624
232.28500, 34.01167,    -0.24348,94.55338,50.00000,0.0000e+000,20.00000,    -0.13969,0.97415
233.99200, 34.18667,    -0.25056,94.53091,50.00000,0.0000e+000,20.00000,    -0.13582,0.97210
235.71600, 34.36167,    -0.25796,94.50805,50.00000,0.0000e+000,20.00000,    -0.13223,0.97003
237.39999, 34.53667,    -0.26528,94.48225,50.00000,0.0000e+000,20.00000,    -0.12901,0.96800
239.10800, 34.71167,    -0.27173,94.45603,50.00000,0.0000e+000,20.00000,    -0.12609,0.96596
240.81500, 34.88667,    -0.27926,94.43552,50.00000,0.0000e+000,20.00000,    -0.12363,0.96392
242.49300, 35.06167,    -0.28640,94.41540,50.00000,0.0000e+000,20.00000,    -0.12129,0.96192
244.17700, 35.23667,    -0.29373,94.39481,50.00000,0.0000e+000,20.00000,    -0.11934,0.95992
245.85201, 35.41167,    -0.30066,94.37298,50.00000,0.0000e+000,20.00000,    -0.11737,0.95793
247.52699, 35.58667,    -0.30778,94.35169,50.00000,0.0000e+000,20.00000,    -0.11507,0.95595
249.20799, 35.76167,    -0.31492,94.33211,50.00000,0.0000e+000,20.00000,    -0.11395,0.95396
250.86301, 35.93667,    -0.32252,94.31352,50.00000,0.0000e+000,20.00000,    -0.11246,0.95201
252.54100, 36.11167,    -0.32980,94.29558,50.00000,0.0000e+000,20.00000,    -0.11056,0.95004
254.22400, 36.28667,    -0.33630,94.27760,50.00000,0.0000e+000,20.00000,    -0.10823,0.94806
255.89400, 36.46167,    -0.34391,94.25958,50.00000,0.0000e+000,20.00000,    -0.10486,0.94611
257.56699, 36.63667,    -0.35081,94.24231,50.00000,0.0000e+000,20.00000,    -0.10317,0.94415
259.23199, 36.81167,    -0.35791,94.22566,50.00000,0.0000e+000,20.00000,    -0.10267,0.94221
260.91599, 36.98667,    -0.36501,94.20958,50.00000,0.0000e+000,20.00000,    -0.10141,0.94026
262.58099, 37.16167,    -0.37105,94.19210,50.00000,0.0000e+000,20.00000,-9.9743e-002,0.93833
264.24301, 37.33667,    -0.37739,94.17533,50.00000,0.0000e+000,20.00000,-9.8438e-002,0.93640
265.93500, 37.51167,    -0.38347,94.15558,50.00000,0.0000e+000,20.00000,-9.7209e-002,0.93445
267.60400, 37.68667,    -0.38985,94.13697,50.00000,0.0000e+000,20.00000,-9.6032e-002,0.93253
269.25900, 37.86167,    -0.39607,94.12119,50.00000,0.0000e+000,20.00000,-9.5190e-002,0.93063
270.95001, 38.03667,    -0.40283,94.10542,50.00000,0.0000e+000,20.00000,-9.4562e-002,0.92869
272.61499, 38.21167,    -0.40946,94.09037,50.00000,0.0000e+000,20.00000,-9.4603e-002,0.92678
274.31299, 38.38667,    -0.41679,94.07485,50.00000,0.0000e+000,20.00000,-9.4684e-002,0.92485
276.00299, 38.56167,    -0.42335,94.05700,50.00000,0.0000e+000,20.00000,-9.4854e-002,0.92293
277.67801, 38.73667,    -0.42923,94.04007,50.00000,0.0000e+000,20.00000,-9.5936e-002,0.92102
279.37399, 38.91167,    -0.43511,94.02514,50.00000,0.0000e+000,20.00000,-9.6952e-002,0.91910
281.04099, 39.08667,    -0.44114,94.00884,50.00000,0.0000e+000,20.00000,-9.7109e-002,0.91722
282.72601, 39.26167,    -0.44622,93.99190,50.00000,0.0000e+000,20.00000,-9.7298e-002,0.91532
284.40900, 39.43667,    -0.45184,93.97736,50.00000,0.0000e+000,20.00000,-9.7634e-002,0.91343
286.08200, 39.61167,    -0.45792,93.96208,50.00000,0.0000e+000,20.00000,-9.8534e-002,0.91156
287.79099, 39.78667,    -0.46375,93.94732,50.00000,0.0000e+000,20.00000,-9.8747e-002,0.90965
289.46701, 39.96167,    -0.46979,93.92990,50.00000,0.0000e+000,20.00000,-9.9243e-002,0.90778
291.16299, 40.13667,    -0.47534,93.91167,50.00000,0.0000e+000,20.00000,    -0.10050,0.90589
292.85999, 40.31167,    -0.48159,93.89411,50.00000,0.0000e+000,20.00000,    -0.10210,0.90401
294.56201, 40.48667,    -0.48703,93.87545,50.00000,0.0000e+000,20.00000,    -0.10323,0.90213
296.25400, 40.66167,    -0.49196,93.85437,50.00000,0.0000e+000,20.00000,    -0.10457,0.90026
297.95499, 40.83667,    -0.49716,93.83542,50.00000,0.0000e+000,20.00000,    -0.10535,0.89839
299.66101, 41.01167,    -0.50255,93.81794,50.00000,0.0000e+000,20.00000,    -0.10602,0.89652
301.35999, 41.18667,    -0.50692,93.79724,50.00000,0.0000e+000,20.00000,    -0.10744,0.89466
303.04099, 41.36167,    -0.51168,93.77643,50.00000,0.0000e+000,20.00000,    -0.10959,0.89283
304.75201, 41.53667,    -0.51648,93.75849,50.00000,0.0000e+000,20.00000,    -0.11146,0.89097
306.46201, 41.71167,    -0.52157,93.74218,50.00000,0.0000e+000,20.00000,    -0.11299,0.88911
308.17599, 41.88667,    -0.52620,93.72367,50.00000,0.0000e+000,20.00000,    -0.11452,0.88726
309.86801, 42.06167,    -0.53080,93.70225,50.00000,0.0000e+000,20.00000,    -0.11682,0.88543
311.57401, 42.23667,    -0.53455,93.67942,50.00000,0.0000e+000,20.00000,    -0.11860,0.88359
313.28299, 42.41167,    -0.53855,93.65828,50.00000,0.0000e+000,20.00000,    -0.11885,0.88176
315.00201, 42.58667,    -0.54319,93.63936,50.00000,0.0000e+000,20.00000,    -0.11911,0.87992
316.70999, 42.76167,    -0.54738,93.62053,50.00000,0.0000e+000,20.00000,    -0.12131,0.87810
318.42499, 42.93667,    -0.55257,93.60042,50.00000,0.0000e+000,20.00000,    -0.12371,0.87627
320.13501, 43.11167,    -0.55700,93.57850,50.00000,0.0000e+000,20.00000,    -0.12573,0.87446
321.85101, 43.28667,    -0.56175,93.55598,50.00000,0.0000e+000,20.00000,    -0.12812,0.87264
323.56500, 43.46167,    -0.56744,93.53472,50.00000,0.0000e+000,20.00000,    -0.13152,0.87084
325.28000, 43.63667,    -0.57223,93.51210,50.00000,0.0000e+000,20.00000,    -0.13488,0.86903
327.01999, 43.81167,    -0.57641,93.48652,50.00000,0.0000e+000,20.00000,    -0.13756,0.86721
328.72501, 43.98667,    -0.58025,93.46089,50.00000,0.0000e+000,20.00000,    -0.13976,0.86543
330.45300, 44.16167,    -0.58474,93.43858,50.00000,0.0000e+000,20.00000,    -0.14296,0.86363
332.17099, 44.33667,    -0.58921,93.41777,50.00000,0.0000e+000,20.00000,    -0.14667,0.86184
333.88901, 44.51167,    -0.59351,93.39441,50.00000,0.0000e+000,20.00000,    -0.15082,0.86006
335.61801, 44.68667,    -0.59821,93.36708,50.00000,0.0000e+000,20.00000,    -0.15542,0.85827
337.33701, 44.86167,    -0.60181,93.33863,50.00000,0.0000e+000,20.00000,    -0.16040,0.85650
339.06299, 45.03667,    -0.60520,93.31010,50.00000,0.0000e+000,20.00000,    -0.16519,0.85473
340.79199, 45.21167,    -0.60830,93.28187,50.00000,0.0000e+000,20.00000,    -0.17024,0.85296
342.51001, 45.38667,    -0.61052,93.25236,50.00000,0.0000e+000,20.00000,    -0.17609,0.85121
344.23801, 45.56167,    -0.61338,93.22257,50.00000,0.0000e+000,20.00000,    -0.18169,0.84945
345.95801, 45.73667,    -0.61519,93.19254,50.00000,0.0000e+000,20.00000,    -0.18643,0.84771
347.67200, 45.91167,    -0.61745,93.16007,50.00000,0.0000e+000,20.00000,    -0.19179,0.84598
349.40601, 46.08667,    -0.61977,93.12610,50.00000,0.0000e+000,20.00000,    -0.19861,0.84423
351.12701, 46.26167,    -0.62131,93.09296,50.00000,0.0000e+000,20.00000,    -0.20573,0.84250
352.85901, 46.43667,    -0.62379,93.05800,50.00000,0.0000e+000,20.00000,    -0.21129,0.84077
354.57101, 46.61167,    -0.62596,93.01978,50.00000,0.0000e+000,20.00000,    -0.21574,0.83906
356.29700, 46.78667,    -0.62869,92.97986,50.00000,0.0000e+000,20.00000,    -0.21963,0.83734
358.04401, 46.96167,    -0.63142,92.93980,50.00000,0.0000e+000,20.00000,    -0.22389,0.83561
359.75400, 47.13667,    -0.63412,92.89842,50.00000,0.0000e+000,20.00000,    -0.22903,0.83392
361.48999, 47.31167,    -0.63750,92.85380,50.00000,0.0000e+000,20.00000,    -0.23336,0.83221
363.22800, 47.48667,    -0.64073,92.80969,50.00000,0.0000e+000,20.00000,    -0.23598,0.83050
364.95801, 47.66167,    -0.64447,92.76651,50.00000,0.0000e+000,20.00000,    -0.23856,0.82881
366.69901, 47.83667,    -0.64911,92.72193,50.00000,0.0000e+000,20.00000,    -0.24178,0.82711
368.43100, 48.01167,    -0.65315,92.67443,50.00000,0.0000e+000,20.00000,    -0.24480,0.82543
370.16400, 48.18667,    -0.65677,92.62752,50.00000,0.0000e+000,20.00000,    -0.24697,0.82375
371.89700, 48.36167,    -0.66060,92.58213,50.00000,0.0000e+000,20.00000,    -0.24889,0.82207
373.63199, 48.53667,    -0.66545,92.53890,50.00000,0.0000e+000,20.00000,    -0.25006,0.82040
375.36301, 48.71167,    -0.67030,92.49589,50.00000,0.0000e+000,20.00000,    -0.25049,0.81874
377.09399, 48.88667,    -0.67555,92.44998,50.00000,0.0000e+000,20.00000,    -0.25066,0.81709
378.83701, 49.06167,    -0.68166,92.40220,50.00000,0.0000e+000,20.00000,    -0.24975,0.81542
380.58099, 49.23667,    -0.68733,92.36043,50.00000,0.0000e+000,20.00000,    -0.24811,0.81377
382.32199, 49.41167,    -0.69307,92.32165,50.00000,0.0000e+000,20.00000,    -0.24710,0.81212
384.07101, 49.58667,    -0.69921,92.27783,50.00000,0.0000e+000,20.00000,    -0.24661,0.81047
385.78799, 49.76167,    -0.70474,92.23212,50.00000,0.0000e+000,20.00000,    -0.24490,0.80886
387.52802, 49.93667,    -0.71157,92.18967,50.00000,0.0000e+000,20.00000,    -0.24165,0.80723
389.28101, 50.11167,    -0.71859,92.14713,50.00000,0.0000e+000,20.00000,    -0.23867,0.80559
390.99899, 50.28667,    -0.72579,92.10272,50.00000,0.0000e+000,20.00000,    -0.23655,0.80399
392.74399, 50.46167,    -0.73349,92.06034,50.00000,0.0000e+000,20.00000,    -0.23527,0.80237
394.46399, 50.63667,    -0.74116,92.01908,50.00000,0.0000e+000,20.00000,    -0.23371,0.80079
396.20901, 50.81167,    -0.74884,91.97849,50.00000,0.0000e+000,20.00000,    -0.23109,0.79918
397.94901, 50.98667,    -0.75666,91.93934,50.00000,0.0000e+000,20.00000,    -0.22966,0.79758
399.69199, 51.16167,    -0.76434,91.90035,50.00000,0.0000e+000,20.00000,    -0.22956,0.79599
401.41199, 51.33667,    -0.77163,91.85942,50.00000,0.0000e+000,20.00000,    -0.22885,0.79442
403.15701, 51.51167,    -0.77870,91.81770,50.00000,0.0000e+000,20.00000,    -0.22687,0.79284
404.88300, 51.68667,    -0.78633,91.78038,50.00000,0.0000e+000,20.00000,    -0.22630,0.79128
406.62500, 51.86167,    -0.79420,91.74540,50.00000,0.0000e+000,20.00000,    -0.22713,0.78971
408.38501, 52.03667,    -0.80170,91.70962,50.00000,0.0000e+000,20.00000,    -0.22688,0.78813
410.12201, 52.21167,    -0.80837,91.67225,50.00000,0.0000e+000,20.00000,    -0.22760,0.78658
411.85199, 52.38667,    -0.81409,91.63359,50.00000,0.0000e+000,20.00000,    -0.22851,0.78503
413.57901, 52.56167,    -0.81969,91.59556,50.00000,0.0000e+000,20.00000,    -0.22857,0.78350
415.31000, 52.73667,    -0.82496,91.55620,50.00000,0.0000e+000,20.00000,    -0.22844,0.78197
417.02701, 52.91167,    -0.83153,91.51709,50.00000,0.0000e+000,20.00000,    -0.22857,0.78045
418.75601, 53.08667,    -0.83750,91.47861,50.00000,0.0000e+000,20.00000,    -0.22856,0.77893
420.51300, 53.26167,    -0.84395,91.44007,50.00000,0.0000e+000,20.00000,    -0.22832,0.77740
422.24500, 53.43667,    -0.84985,91.40032,50.00000,0.0000e+000,20.00000,    -0.23002,0.77589
423.98300, 53.61167,    -0.85490,91.35583,50.00000,0.0000e+000,20.00000,    -0.23370,0.77438
425.70901, 53.78667,    -0.85960,91.31231,50.00000,0.0000e+000,20.00000,    -0.23744,0.77288
427.45401, 53.96167,    -0.86482,91.26771,50.00000,0.0000e+000,20.00000,    -0.24003,0.77138
429.19000, 54.13667,    -0.86964,91.22150,50.00000,0.0000e+000,20.00000,    -0.24195,0.76989
430.91901, 54.31167,    -0.87555,91.17883,50.00000,0.0000e+000,20.00000,    -0.24342,0.76841
432.67401, 54.48667,    -0.88130,91.13893,50.00000,0.0000e+000,20.00000,    -0.24581,0.76691
434.41000, 54.66167,    -0.88729,91.09980,50.00000,0.0000e+000,20.00000,    -0.24779,0.76544
436.16000, 54.83667,    -0.89454,91.06021,50.00000,0.0000e+000,20.00000,    -0.24961,0.76395
437.92999, 55.01167,    -0.90062,91.02001,50.00000,0.0000e+000,20.00000,    -0.25248,0.76246
439.67700, 55.18667,    -0.90610,90.97652,50.00000,0.0000e+000,20.00000,    -0.25608,0.76100
441.44199, 55.36167,    -0.91029,90.92863,50.00000,0.0000e+000,20.00000,    -0.25776,0.75952
443.17801, 55.53667,    -0.91330,90.87917,50.00000,0.0000e+000,20.00000,    -0.25816,0.75807
444.90701, 55.71167,    -0.91560,90.83191,50.00000,0.0000e+000,20.00000,    -0.25897,0.75664
446.62201, 55.88667,    -0.91534,90.78631,50.00000,0.0000e+000,20.00000,    -0.25964,0.75522
448.31201, 56.06167,    -0.91515,90.74216,50.00000,0.0000e+000,20.00000,    -0.26209,0.75383
450.01999, 56.23667,    -0.91765,90.69680,50.00000,0.0000e+000,20.00000,    -0.26528,0.75242
451.72000, 56.41167,    -0.92175,90.64889,50.00000,0.0000e+000,20.00000,    -0.26847,0.75103
453.43500, 56.58667,    -0.92823,90.60360,50.00000,0.0000e+000,20.00000,    -0.27182,0.74964
455.15701, 56.76167,    -0.93569,90.55671,50.00000,0.0000e+000,20.00000,    -0.27487,0.74824
456.89499, 56.93667,    -0.94377,90.50533,50.00000,0.0000e+000,20.00000,    -0.27812,0.74683
458.62900, 57.11167,    -0.95046,90.45477,50.00000,0.0000e+000,20.00000,    -0.28130,0.74544
460.37701, 57.28667,    -0.95666,90.40809,50.00000,0.0000e+000,20.00000,    -0.28267,0.74404
462.10901, 57.46167,    -0.96159,90.36200,50.00000,0.0000e+000,20.00000,    -0.28343,0.74265
463.85101, 57.63667,    -0.96660,90.31497,50.00000,0.0000e+000,20.00000,    -0.28610,0.74127
465.58401, 57.81167,    -0.97100,90.26334,50.00000,0.0000e+000,20.00000,    -0.28932,0.73989
467.33899, 57.98667,    -0.97596,90.20961,50.00000,0.0000e+000,20.00000,    -0.29340,0.73851
469.10101, 58.16167,    -0.98263,90.15858,50.00000,0.0000e+000,20.00000,    -0.29593,0.73712
470.86401, 58.33667,    -0.98908,90.10718,50.00000,0.0000e+000,20.00000,    -0.29806,0.73574
472.64301, 58.51167,    -0.99553,90.05582,50.00000,0.0000e+000,20.00000,    -0.30186,0.73435
474.40500, 58.68667,    -1.00027,90.00439,50.00000,0.0000e+000,20.00000,    -0.30624,0.73299
476.16901, 58.86167,    -1.00432,89.94767,50.00000,0.0000e+000,20.00000,    -0.30882,0.73162
477.93701, 59.03667,    -1.00678,89.89123,50.00000,0.0000e+000,20.00000,    -0.31150,0.73026
479.68600, 59.21167,    -1.00970,89.83951,50.00000,0.0000e+000,20.00000,    -0.31519,0.72892
481.41901, 59.38667,    -1.01278,89.78592,50.00000,0.0000e+000,20.00000,    -0.31869,0.72759
483.16299, 59.56167,    -1.01610,89.72930,50.00000,0.0000e+000,20.00000,    -0.32136,0.72626
484.91699, 59.73667,    -1.02020,89.67132,50.00000,0.0000e+000,20.00000,    -0.32307,0.72494
486.63901, 59.91167,    -1.02408,89.61294,50.00000,0.0000e+000,20.00000,    -0.32573,0.72363
488.38400, 60.08667,    -1.02812,89.55821,50.00000,0.0000e+000,20.00000,    -0.32853,0.72232
490.12799, 60.26167,    -1.03223,89.50208,50.00000,0.0000e+000,20.00000,    -0.33120,0.72102
491.86899, 60.43667,    -1.03774,89.43841,50.00000,0.0000e+000,20.00000,    -0.33390,0.71972
493.62701, 60.61167,    -1.04257,89.37407,50.00000,0.0000e+000,20.00000,    -0.33525,0.71841
495.36801, 60.78667,    -1.04807,89.31588,50.00000,0.0000e+000,20.00000,    -0.33644,0.71712
497.10400, 60.96167,    -1.05364,89.25685,50.00000,0.0000e+000,20.00000,    -0.33876,0.71585
498.85599, 61.13667,    -1.05749,89.19751,50.00000,0.0000e+000,20.00000,    -0.34150,0.71456
500.60101, 61.31167,    -1.06363,89.13841,50.00000,0.0000e+000,20.00000,    -0.34327,0.71328
502.36301, 61.48667,    -1.07033,89.07931,50.00000,0.0000e+000,20.00000,    -0.34591,0.71200
504.13699, 61.66167,    -1.07634,89.01788,50.00000,0.0000e+000,20.00000,    -0.34802,0.71072
505.90302, 61.83667,    -1.08261,88.95641,50.00000,0.0000e+000,20.00000,    -0.34995,0.70944
507.67001, 62.01167,    -1.08822,88.89514,50.00000,0.0000e+000,20.00000,    -0.35155,0.70817
509.46899, 62.18667,    -1.09552,88.83387,50.00000,0.0000e+000,20.00000,    -0.35211,0.70689
511.25299, 62.36167,    -1.10191,88.77430,50.00000,0.0000e+000,20.00000,    -0.35157,0.70561
513.03198, 62.53667,    -1.10548,88.71382,50.00000,0.0000e+000,20.00000,    -0.35201,0.70435
514.77301, 62.71167,    -1.10669,88.65129,50.00000,0.0000e+000,20.00000,    -0.35341,0.70312
516.50897, 62.88667,    -1.10753,88.58946,50.00000,0.0000e+000,20.00000,    -0.35623,0.70190
518.23700, 63.06167,    -1.10751,88.52789,50.00000,0.0000e+000,20.00000,    -0.35924,0.70069
519.95697, 63.23667,    -1.10742,88.46296,50.00000,0.0000e+000,20.00000,    -0.36133,0.69949
521.66901, 63.41167,    -1.10848,88.39567,50.00000,0.0000e+000,20.00000,    -0.36323,0.69830
523.36798, 63.58667,    -1.11150,88.33070,50.00000,0.0000e+000,20.00000,    -0.36434,0.69713
525.08698, 63.76167,    -1.11537,88.26932,50.00000,0.0000e+000,20.00000,    -0.36519,0.69594
526.80603, 63.93667,    -1.12139,88.20868,50.00000,0.0000e+000,20.00000,    -0.36683,0.69476
528.54199, 64.11166,    -1.12778,88.14484,50.00000,0.0000e+000,20.00000,    -0.36913,0.69357
530.27002, 64.28667,    -1.13384,88.08213,50.00000,0.0000e+000,20.00000,    -0.37170,0.69240
532.02301, 64.46167,    -1.14024,88.02023,50.00000,0.0000e+000,20.00000,    -0.37327,0.69121
533.74902, 64.63667,    -1.14585,87.95328,50.00000,0.0000e+000,20.00000,    -0.37627,0.69005
535.48401, 64.81167,    -1.15059,87.88220,50.00000,0.0000e+000,20.00000,    -0.37963,0.68888
537.22198, 64.98666,    -1.15537,87.81424,50.00000,0.0000e+000,20.00000,    -0.38132,0.68772
538.95203, 65.16167,    -1.16056,87.74781,50.00000,0.0000e+000,20.00000,    -0.38142,0.68656
540.70001, 65.33667,    -1.16474,87.68048,50.00000,0.0000e+000,20.00000,    -0.38291,0.68540
542.44000, 65.51167,    -1.16883,87.61643,50.00000,0.0000e+000,20.00000,    -0.38547,0.68425
544.16998, 65.68667,    -1.17396,87.55028,50.00000,0.0000e+000,20.00000,    -0.38894,0.68312
545.91901, 65.86166,    -1.17903,87.48199,50.00000,0.0000e+000,20.00000,    -0.39089,0.68197
547.67902, 66.03667,    -1.18439,87.41278,50.00000,0.0000e+000,20.00000,    -0.39221,0.68082
549.41901, 66.21167,    -1.18974,87.34504,50.00000,0.0000e+000,20.00000,    -0.39402,0.67969
551.16199, 66.38667,    -1.19401,87.27459,50.00000,0.0000e+000,20.00000,    -0.39585,0.67856
552.91602, 66.56167,    -1.19782,87.19999,50.00000,0.0000e+000,20.00000,    -0.39756,0.67743
554.65900, 66.73666,    -1.20283,87.12864,50.00000,0.0000e+000,20.00000,    -0.39886,0.67632
556.41803, 66.91167,    -1.20626,87.06154,50.00000,0.0000e+000,20.00000,    -0.39988,0.67519
558.16199, 67.08667,    -1.21181,86.99169,50.00000,0.0000e+000,20.00000,    -0.40056,0.67408
559.94202, 67.26167,    -1.21725,86.91930,50.00000,0.0000e+000,20.00000,    -0.40306,0.67296
561.69000, 67.43667,    -1.22202,86.84653,50.00000,0.0000e+000,20.00000,    -0.40660,0.67185
563.44598, 67.61166,    -1.22632,86.77502,50.00000,0.0000e+000,20.00000,    -0.40801,0.67075
565.20697, 67.78667,    -1.22944,86.70654,50.00000,0.0000e+000,20.00000,    -0.40763,0.66965
566.95599, 67.96167,    -1.23151,86.63792,50.00000,0.0000e+000,20.00000,    -0.40866,0.66856
568.68103, 68.13667,    -1.23425,86.56923,50.00000,0.0000e+000,20.00000,    -0.41129,0.66749
570.43402, 68.31167,    -1.23757,86.49467,50.00000,0.0000e+000,20.00000,    -0.41165,0.66641
572.16498, 68.48666,    -1.24026,86.41850,50.00000,0.0000e+000,20.00000,    -0.41106,0.66535
573.95801, 68.66167,    -1.24438,86.34657,50.00000,0.0000e+000,20.00000,    -0.41259,0.66425
575.70099, 68.83667,    -1.25091,86.27730,50.00000,0.0000e+000,20.00000,    -0.41464,0.66319
577.42999, 69.01167,    -1.25571,86.20535,50.00000,0.0000e+000,20.00000,    -0.41541,0.66214
579.16400, 69.18667,    -1.25994,86.12797,50.00000,0.0000e+000,20.00000,    -0.41607,0.66109
580.90900, 69.36166,    -1.26458,86.05269,50.00000,0.0000e+000,20.00000,    -0.41666,0.66005
582.66199, 69.53667,    -1.27011,85.98316,50.00000,0.0000e+000,20.00000,    -0.41790,0.65900
584.41498, 69.71167,    -1.27487,85.91465,50.00000,0.0000e+000,20.00000,    -0.41998,0.65795
586.17102, 69.88667,    -1.28074,85.83775,50.00000,0.0000e+000,20.00000,    -0.42293,0.65691
587.93799, 70.06167,    -1.28769,85.76106,50.00000,0.0000e+000,20.00000,    -0.42513,0.65586
589.70300, 70.23666,    -1.29305,85.68877,50.00000,0.0000e+000,20.00000,    -0.42566,0.65482
591.45502, 70.41167,    -1.29699,85.61634,50.00000,0.0000e+000,20.00000,    -0.42672,0.65380
593.20898, 70.58667,    -1.30050,85.54113,50.00000,0.0000e+000,20.00000,    -0.42857,0.65277
594.96698, 70.76167,    -1.30386,85.46613,50.00000,0.0000e+000,20.00000,    -0.43199,0.65175
596.70300, 70.93667,    -1.30789,85.39137,50.00000,0.0000e+000,20.00000,    -0.43522,0.65075
598.45300, 71.11166,    -1.31156,85.31647,50.00000,0.0000e+000,20.00000,    -0.43685,0.64974
600.23102, 71.28667,    -1.31568,85.24207,50.00000,0.0000e+000,20.00000,    -0.43875,0.64872
601.96002, 71.46167,    -1.31996,85.16758,50.00000,0.0000e+000,20.00000,    -0.44244,0.64773
603.71198, 71.63667,    -1.32587,85.08940,50.00000,0.0000e+000,20.00000,    -0.44494,0.64674
605.49402, 71.81167,    -1.33191,85.00978,50.00000,0.0000e+000,20.00000,    -0.44597,0.64573
607.25897, 71.98666,    -1.33718,84.93095,50.00000,0.0000e+000,20.00000,    -0.44919,0.64473
609.01202, 72.16167,    -1.33932,84.85243,50.00000,0.0000e+000,20.00000,    -0.45443,0.64375
610.74597, 72.33667,    -1.34156,84.77578,50.00000,0.0000e+000,20.00000,    -0.45837,0.64278
612.50897, 72.51167,    -1.34569,84.69673,50.00000,0.0000e+000,20.00000,    -0.46163,0.64180
614.27197, 72.68667,    -1.35101,84.61030,50.00000,0.0000e+000,20.00000,    -0.46530,0.64082
616.04602, 72.86166,    -1.35676,84.52493,50.00000,0.0000e+000,20.00000,    -0.46953,0.63984
617.82703, 73.03667,    -1.36131,84.44441,50.00000,0.0000e+000,20.00000,    -0.47379,0.63886
619.58899, 73.21167,    -1.36510,84.36516,50.00000,0.0000e+000,20.00000,    -0.47894,0.63790
621.34497, 73.38667,    -1.36760,84.28257,50.00000,0.0000e+000,20.00000,    -0.48367,0.63694
623.08099, 73.56167,    -1.36824,84.20099,50.00000,0.0000e+000,20.00000,    -0.48695,0.63600
624.83197, 73.73666,    -1.36986,84.11740,50.00000,0.0000e+000,20.00000,    -0.49092,0.63505
626.56299, 73.91167,    -1.37052,84.02832,50.00000,0.0000e+000,20.00000,    -0.49665,0.63412
628.29999, 74.08667,    -1.37230,83.93811,50.00000,0.0000e+000,20.00000,    -0.50315,0.63319
630.03400, 74.26167,    -1.37480,83.85066,50.00000,0.0000e+000,20.00000,    -0.51007,0.63227
631.77301, 74.43667,    -1.37613,83.76325,50.00000,0.0000e+000,20.00000,    -0.51492,0.63134
633.51202, 74.61166,    -1.37830,83.67361,50.00000,0.0000e+000,20.00000,    -0.51913,0.63042
635.27100, 74.78667,    -1.38404,83.58333,50.00000,0.0000e+000,20.00000,    -0.52519,0.62950
637.06403, 74.96167,    -1.39222,83.49197,50.00000,0.0000e+000,20.00000,    -0.53127,0.62855
638.84998, 75.13667,    -1.39817,83.39793,50.00000,0.0000e+000,20.00000,    -0.53674,0.62762
640.62097, 75.31167,    -1.40173,83.30562,50.00000,0.0000e+000,20.00000,    -0.54244,0.62670
642.38098, 75.48666,    -1.40138,83.21374,50.00000,0.0000e+000,20.00000,    -0.54783,0.62579
644.12701, 75.66167,    -1.39888,83.11661,50.00000,0.0000e+000,20.00000,    -0.55179,0.62489
645.86102, 75.83667,    -1.39686,83.01540,50.00000,0.0000e+000,20.00000,    -0.55524,0.62400
647.57397, 76.01167,    -1.39521,82.91377,50.00000,0.0000e+000,20.00000,    -0.55921,0.62312
649.33698, 76.18667,    -1.39610,82.81173,50.00000,0.0000e+000,20.00000,    -0.56249,0.62222
651.09601, 76.36166,    -1.39979,82.71062,50.00000,0.0000e+000,20.00000,    -0.56503,0.62133
652.83698, 76.53667,    -1.40310,82.60626,50.00000,0.0000e+000,20.00000,    -0.56755,0.62045
654.59100, 76.71167,    -1.40603,82.50324,50.00000,0.0000e+000,20.00000,    -0.56979,0.61957
656.33197, 76.88667,    -1.40854,82.40283,50.00000,0.0000e+000,20.00000,    -0.57181,0.61869
658.07397, 77.06167,    -1.41099,82.30008,50.00000,0.0000e+000,20.00000,    -0.57294,0.61782
659.80200, 77.23666,    -1.41382,82.19757,50.00000,0.0000e+000,20.00000,    -0.57431,0.61696
661.55902, 77.41167,    -1.41791,82.09652,50.00000,0.0000e+000,20.00000,    -0.57376,0.61609
663.31897, 77.58667,    -1.42331,81.99446,50.00000,0.0000e+000,20.00000,    -0.57066,0.61523
665.07703, 77.76167,    -1.42765,81.89052,50.00000,0.0000e+000,20.00000,    -0.56654,0.61436
666.84302, 77.93667,    -1.43127,81.78976,50.00000,0.0000e+000,20.00000,    -0.56194,0.61350
668.58398, 78.11166,    -1.43425,81.69202,50.00000,0.0000e+000,20.00000,    -0.55772,0.61265
670.33301, 78.28667,    -1.43869,81.59287,50.00000,0.0000e+000,20.00000,    -0.55319,0.61180
672.10303, 78.46167,    -1.44258,81.49425,50.00000,0.0000e+000,20.00000,    -0.54768,0.61094
673.84003, 78.63667,    -1.44648,81.39405,50.00000,0.0000e+000,20.00000,    -0.54233,0.61011
675.58899, 78.81167,    -1.44861,81.29520,50.00000,0.0000e+000,20.00000,    -0.53646,0.60927
677.33698, 78.98666,    -1.45329,81.19802,50.00000,0.0000e+000,20.00000,    -0.52935,0.60843
679.09302, 79.16167,    -1.45893,81.10383,50.00000,0.0000e+000,20.00000,    -0.52205,0.60760
680.85101, 79.33667,    -1.46428,81.01355,50.00000,0.0000e+000,20.00000,    -0.51595,0.60676
682.60498, 79.51167,    -1.46950,80.92634,50.00000,0.0000e+000,20.00000,    -0.50824,0.60594
684.34497, 79.68667,    -1.47342,80.84063,50.00000,0.0000e+000,20.00000,    -0.49864,0.60512
686.10199, 79.86166,    -1.47590,80.75535,50.00000,0.0000e+000,20.00000,    -0.48979,0.60429
687.83899, 80.03667,    -1.47891,80.66903,50.00000,0.0000e+000,20.00000,    -0.48201,0.60348
689.58301, 80.21167,    -1.48338,80.58361,50.00000,0.0000e+000,20.00000,    -0.47414,0.60267
691.32898, 80.38667,    -1.48752,80.50088,50.00000,0.0000e+000,20.00000,    -0.46498,0.60186
693.08099, 80.56167,    -1.49082,80.42067,50.00000,0.0000e+000,20.00000,    -0.45454,0.60106
694.84802, 80.73666,    -1.49670,80.34139,50.00000,0.0000e+000,20.00000,    -0.44415,0.60024
696.60797, 80.91167,    -1.50168,80.26671,50.00000,0.0000e+000,20.00000,    -0.43418,0.59944
698.35797, 81.08667,    -1.50698,80.18958,50.00000,0.0000e+000,20.00000,    -0.42523,0.59864
700.16101, 81.26167,    -1.51549,80.11104,50.00000,0.0000e+000,20.00000,    -0.41778,0.59782
701.97400, 81.43667,    -1.52692,80.04083,50.00000,0.0000e+000,20.00000,    -0.41049,0.59700
703.78497, 81.61166,    -1.53476,79.97453,50.00000,0.0000e+000,20.00000,    -0.40200,0.59618
705.55298, 81.78667,    -1.53491,79.90690,50.00000,0.0000e+000,20.00000,    -0.39344,0.59539
707.31403, 81.96167,    -1.53391,79.83549,50.00000,0.0000e+000,20.00000,    -0.38544,0.59460
709.05603, 82.13667,    -1.53346,79.76777,50.00000,0.0000e+000,20.00000,    -0.37786,0.59382
710.79797, 82.31167,    -1.53197,79.70436,50.00000,0.0000e+000,20.00000,    -0.37140,0.59305
712.54102, 82.48666,    -1.53279,79.64383,50.00000,0.0000e+000,20.00000,    -0.36546,0.59228
714.27002, 82.66167,    -1.53556,79.58452,50.00000,0.0000e+000,20.00000,    -0.36012,0.59151
716.02502, 82.83667,    -1.53864,79.52520,50.00000,0.0000e+000,20.00000,    -0.35421,0.59074
717.76300, 83.01167,    -1.53945,79.46515,50.00000,0.0000e+000,20.00000,    -0.34777,0.58998
719.48199, 83.18667,    -1.53935,79.40384,50.00000,0.0000e+000,20.00000,    -0.34267,0.58923
721.20502, 83.36166,    -1.53989,79.34762,50.00000,0.0000e+000,20.00000,    -0.33862,0.58848
722.93903, 83.53667,    -1.54262,79.29388,50.00000,0.0000e+000,20.00000,    -0.33281,0.58773
724.69397, 83.71167,    -1.54437,79.23770,50.00000,0.0000e+000,20.00000,    -0.32318,0.58697
726.43799, 83.88667,    -1.54523,79.18104,50.00000,0.0000e+000,20.00000,    -0.31159,0.58622
728.18103, 84.06167,    -1.54636,79.12431,50.00000,0.0000e+000,20.00000,    -0.30109,0.58547
729.95502, 84.23666,    -1.54991,79.06630,50.00000,0.0000e+000,20.00000,    -0.29086,0.58472
731.72699, 84.41167,    -1.55234,79.00799,50.00000,0.0000e+000,20.00000,    -0.28066,0.58396
733.48102, 84.58667,    -1.55340,78.95353,50.00000,0.0000e+000,20.00000,    -0.27039,0.58322
735.24402, 84.76167,    -1.55462,78.89907,50.00000,0.0000e+000,20.00000,    -0.26012,0.58247
736.99902, 84.93667,    -1.55755,78.84285,50.00000,0.0000e+000,20.00000,    -0.24965,0.58173
738.73297, 85.11166,    -1.56236,78.78885,50.00000,0.0000e+000,20.00000,    -0.23911,0.58100
740.48297, 85.28667,    -1.57303,78.73971,50.00000,0.0000e+000,20.00000,    -0.22944,0.58027
742.22400, 85.46167,    -1.58834,78.70030,50.00000,0.0000e+000,20.00000,    -0.21913,0.57954
743.97302, 85.63667,    -1.60458,78.67007,50.00000,0.0000e+000,20.00000,    -0.20821,0.57881
745.72101, 85.81167,    -1.61465,78.64333,50.00000,0.0000e+000,20.00000,    -0.19693,0.57809
747.46698, 85.98666,    -1.61933,78.61763,50.00000,0.0000e+000,20.00000,    -0.18548,0.57737
749.20398, 86.16167,    -1.62284,78.59484,50.00000,0.0000e+000,20.00000,    -0.17406,0.57665
750.96503, 86.33667,    -1.62847,78.57274,50.00000,0.0000e+000,20.00000,    -0.16359,0.57593
752.74597, 86.51167,    -1.63439,78.55120,50.00000,0.0000e+000,20.00000,    -0.15347,0.57520
754.52802, 86.68667,    -1.63971,78.52844,50.00000,0.0000e+000,20.00000,    -0.14205,0.57447
756.27502, 86.86166,    -1.64181,78.50647,50.00000,0.0000e+000,20.00000,    -0.13080,0.57376
758.06598, 87.03667,    -1.64414,78.48738,50.00000,0.0000e+000,20.00000,    -0.12011,0.57303
759.82800, 87.21167,    -1.64744,78.46951,50.00000,0.0000e+000,20.00000,    -0.11128,0.57232
761.58600, 87.38667,    -1.64787,78.45246,50.00000,0.0000e+000,20.00000,    -0.10561,0.57161
763.33600, 87.56167,    -1.64444,78.43631,50.00000,0.0000e+000,20.00000,    -0.10146,0.57091
765.07599, 87.73666,    -1.64142,78.42139,50.00000,0.0000e+000,20.00000,-9.7680e-002,0.57021
766.80701, 87.91167,    -1.64154,78.40496,50.00000,0.0000e+000,20.00000,-9.5088e-002,0.56952
768.58099, 88.08667,    -1.64477,78.38743,50.00000,0.0000e+000,20.00000,-9.3351e-002,0.56881
770.34900, 88.26167,    -1.64796,78.36956,50.00000,0.0000e+000,20.00000,-9.1377e-002,0.56811
772.09601, 88.43667,    -1.64881,78.35474,50.00000,0.0000e+000,20.00000,-8.9087e-002,0.56742
773.85498, 88.61166,    -1.64906,78.34055,50.00000,0.0000e+000,20.00000,-8.6531e-002,0.56672
775.58801, 88.78667,    -1.64960,78.32687,50.00000,0.0000e+000,20.00000,-8.4282e-002,0.56604
777.33698, 88.96167,    -1.64870,78.31522,50.00000,0.0000e+000,20.00000,-8.2577e-002,0.56535
779.07898, 89.13667,    -1.64695,78.30236,50.00000,0.0000e+000,20.00000,-8.1564e-002,0.56467
780.81702, 89.31167,    -1.64799,78.28973,50.00000,0.0000e+000,20.00000,-8.1115e-002,0.56399
782.56299, 89.48666,    -1.64944,78.27743,50.00000,0.0000e+000,20.00000,-8.0130e-002,0.56331
784.28998, 89.66167,    -1.64900,78.26387,50.00000,0.0000e+000,20.00000,-7.8709e-002,0.56264
786.01099, 89.83667,    -1.64833,78.24831,50.00000,0.0000e+000,20.00000,-7.7245e-002,0.56197
787.74701, 90.01167,    -1.64829,78.23294,50.00000,0.0000e+000,20.00000,-7.5412e-002,0.56130
789.51001, 90.18667,    -1.65303,78.21924,50.00000,0.0000e+000,20.00000,-7.3955e-002,0.56062
791.25897, 90.36166,    -1.65750,78.20534,50.00000,0.0000e+000,20.00000,-7.3537e-002,0.55995
793.00897, 90.53667,    -1.65880,78.19281,50.00000,0.0000e+000,20.00000,-7.3134e-002,0.55928
794.77197, 90.71167,    -1.66326,78.18093,50.00000,0.0000e+000,20.00000,-7.3450e-002,0.55860
796.53198, 90.88667,    -1.66762,78.16823,50.00000,0.0000e+000,20.00000,-7.3902e-002,0.55793
798.27802, 91.06167,    -1.67155,78.15321,50.00000,0.0000e+000,20.00000,-7.4332e-002,0.55727
800.05603, 91.23666,    -1.67583,78.13996,50.00000,0.0000e+000,20.00000,-7.4982e-002,0.55659
801.81299, 91.41167,    -1.67916,78.12940,50.00000,0.0000e+000,20.00000,-7.5248e-002,0.55593
803.57800, 91.58667,    -1.68351,78.11846,50.00000,0.0000e+000,20.00000,-7.4648e-002,0.55526
805.33197, 91.76167,    -1.68755,78.10640,50.00000,0.0000e+000,20.00000,-7.4142e-002,0.55460
807.11798, 91.93667,    -1.69071,78.09574,50.00000,0.0000e+000,20.00000,-7.4244e-002,0.55393
808.90997, 92.11166,    -1.69969,78.08378,50.00000,0.0000e+000,20.00000,-7.4112e-002,0.55326
810.69299, 92.28667,    -1.70620,78.07109,50.00000,0.0000e+000,20.00000,-7.4771e-002,0.55259
812.46002, 92.46167,    -1.70898,78.05793,50.00000,0.0000e+000,20.00000,-7.6129e-002,0.55193
814.19800, 92.63667,    -1.70668,78.04426,50.00000,0.0000e+000,20.00000,-7.7380e-002,0.55128
815.90002, 92.81167,    -1.70205,78.03007,50.00000,0.0000e+000,20.00000,-7.8289e-002,0.55065
817.64001, 92.98666,    -1.70132,78.01535,50.00000,0.0000e+000,20.00000,-7.9022e-002,0.55000
819.40100, 93.16167,    -1.70439,78.00092,50.00000,0.0000e+000,20.00000,-8.0440e-002,0.54935
821.19501, 93.33667,    -1.71381,77.98823,50.00000,0.0000e+000,20.00000,-8.2055e-002,0.54869
823.00500, 93.51167,    -1.72301,77.97495,50.00000,0.0000e+000,20.00000,-8.3610e-002,0.54802
824.78101, 93.68667,    -1.72563,77.96016,50.00000,0.0000e+000,20.00000,-8.5872e-002,0.54737
826.53900, 93.86166,    -1.72489,77.94664,50.00000,0.0000e+000,20.00000,-8.8768e-002,0.54672
828.29401, 94.03667,    -1.72459,77.93211,50.00000,0.0000e+000,20.00000,-9.0977e-002,0.54608
830.05298, 94.21167,    -1.72272,77.91551,50.00000,0.0000e+000,20.00000,-9.2403e-002,0.54543
831.78101, 94.38667,    -1.71929,77.89860,50.00000,0.0000e+000,20.00000,-9.4450e-002,0.54480
833.52399, 94.56167,    -1.71847,77.88175,50.00000,0.0000e+000,20.00000,-9.7198e-002,0.54417
835.28101, 94.73666,    -1.72023,77.86411,50.00000,0.0000e+000,20.00000,-9.9786e-002,0.54353
837.02197, 94.91167,    -1.72306,77.84716,50.00000,0.0000e+000,20.00000,    -0.10264,0.54290
838.79602, 95.08667,    -1.72639,77.83102,50.00000,0.0000e+000,20.00000,    -0.10604,0.54225
840.54199, 95.26167,    -1.72768,77.81393,50.00000,0.0000e+000,20.00000,    -0.10955,0.54162
842.30701, 95.43667,    -1.72631,77.79560,50.00000,0.0000e+000,20.00000,    -0.11275,0.54098
844.04700, 95.61166,    -1.72672,77.77456,50.00000,0.0000e+000,20.00000,    -0.11607,0.54036
845.80200, 95.78667,    -1.72764,77.75295,50.00000,0.0000e+000,20.00000,    -0.11979,0.53972
847.53198, 95.96167,    -1.72800,77.73417,50.00000,0.0000e+000,20.00000,    -0.12258,0.53910
849.27399, 96.13667,    -1.72836,77.71494,50.00000,0.0000e+000,20.00000,    -0.12559,0.53848
851.02802, 96.31167,    -1.73095,77.69199,50.00000,0.0000e+000,20.00000,    -0.12904,0.53785
852.79303, 96.48666,    -1.73448,77.66780,50.00000,0.0000e+000,20.00000,    -0.13205,0.53722
854.54303, 96.66167,    -1.73654,77.64339,50.00000,0.0000e+000,20.00000,    -0.13455,0.53659
856.29797, 96.83667,    -1.73922,77.61762,50.00000,0.0000e+000,20.00000,    -0.13730,0.53597
858.04401, 97.01167,    -1.74242,77.59185,50.00000,0.0000e+000,20.00000,    -0.14066,0.53534
859.80298, 97.18667,    -1.74216,77.56635,50.00000,0.0000e+000,20.00000,    -0.14372,0.53472
861.55200, 97.36166,    -1.74353,77.54000,50.00000,0.0000e+000,20.00000,    -0.14631,0.53410
863.32800, 97.53667,    -1.74790,77.51304,50.00000,0.0000e+000,20.00000,    -0.14870,0.53347
865.08899, 97.71167,    -1.75229,77.48653,50.00000,0.0000e+000,20.00000,    -0.15121,0.53284
866.85303, 97.88667,    -1.75604,77.45974,50.00000,0.0000e+000,20.00000,    -0.15418,0.53222
868.60901, 98.06167,    -1.75709,77.43068,50.00000,0.0000e+000,20.00000,    -0.15652,0.53160
870.36401, 98.23666,    -1.75655,77.40170,50.00000,0.0000e+000,20.00000,    -0.15852,0.53098
872.11700, 98.41167,    -1.75906,77.37429,50.00000,0.0000e+000,20.00000,    -0.15998,0.53036
873.86902, 98.58667,    -1.75840,77.34825,50.00000,0.0000e+000,20.00000,    -0.16112,0.52975
875.60602, 98.76167,    -1.75880,77.32061,50.00000,0.0000e+000,20.00000,    -0.16240,0.52914
877.37097, 98.93667,    -1.76199,77.29124,50.00000,0.0000e+000,20.00000,    -0.16389,0.52852
879.13000, 99.11166,    -1.76311,77.26276,50.00000,0.0000e+000,20.00000,    -0.16581,0.52790
880.87500, 99.28667,    -1.76462,77.23224,50.00000,0.0000e+000,20.00000,    -0.16776,0.52729
882.62500, 99.46167,    -1.76573,77.20243,50.00000,0.0000e+000,20.00000,    -0.16934,0.52667
884.37097, 99.63667,    -1.76576,77.17322,50.00000,0.0000e+000,20.00000,    -0.17079,0.52606
886.10999, 99.81167,    -1.76542,77.14400,50.00000,0.0000e+000,20.00000,    -0.17200,0.52546
887.84802, 99.98666,    -1.76754,77.11289,50.00000,0.0000e+000,20.00000,    -0.17263,0.52485
889.60797,100.16167,    -1.76742,77.08244,50.00000,0.0000e+000,20.00000,    -0.17385,0.52424
891.36200,100.33667,    -1.76885,77.05344,50.00000,0.0000e+000,20.00000,    -0.17619,0.52362
893.14301,100.51167,    -1.77354,77.02327,50.00000,0.0000e+000,20.00000,    -0.17836,0.52300
894.92200,100.68667,    -1.77642,76.99246,50.00000,0.0000e+000,20.00000,    -0.17970,0.52238
896.67200,100.86166,    -1.77657,76.96073,50.00000,0.0000e+000,20.00000,    -0.18177,0.52178
898.41803,101.03667,    -1.77584,76.92673,50.00000,0.0000e+000,20.00000,    -0.18347,0.52117
900.19098,101.21167,    -1.77727,76.89354,50.00000,0.0000e+000,20.00000,    -0.18454,0.52055
901.96899,101.38667,    -1.78250,76.86159,50.00000,0.0000e+000,20.00000,    -0.18572,0.51994
903.75201,101.56167,    -1.78529,76.82963,50.00000,0.0000e+000,20.00000,    -0.18693,0.51932
905.49799,101.73666,    -1.78468,76.79727,50.00000,0.0000e+000,20.00000,    -0.18820,0.51871
907.25897,101.91167,    -1.78255,76.76560,50.00000,0.0000e+000,20.00000,    -0.18925,0.51810
909.01300,102.08667,    -1.78480,76.73146,50.00000,0.0000e+000,20.00000,    -0.19074,0.51750
910.76001,102.26167,    -1.78347,76.69642,50.00000,0.0000e+000,20.00000,    -0.19293,0.51689
912.49701,102.43667,    -1.78134,76.66260,50.00000,0.0000e+000,20.00000,    -0.19515,0.51629
914.24597,102.61166,    -1.78064,76.62738,50.00000,0.0000e+000,20.00000,    -0.19651,0.51569
915.98102,102.78667,    -1.78128,76.59096,50.00000,0.0000e+000,20.00000,    -0.19707,0.51509
917.73401,102.96167,    -1.78090,76.55613,50.00000,0.0000e+000,20.00000,    -0.19766,0.51448
919.47400,103.13667,    -1.78087,76.52209,50.00000,0.0000e+000,20.00000,    -0.19846,0.51388
921.22498,103.31167,    -1.78496,76.48881,50.00000,0.0000e+000,20.00000,    -0.19954,0.51328
922.97699,103.48666,    -1.78807,76.45468,50.00000,0.0000e+000,20.00000,    -0.20001,0.51268
924.72998,103.66167,    -1.79098,76.41927,50.00000,0.0000e+000,20.00000,    -0.19984,0.51207
926.48199,103.83667,    -1.78996,76.38479,50.00000,0.0000e+000,20.00000,    -0.20016,0.51147
928.22803,104.01167,    -1.78978,76.34874,50.00000,0.0000e+000,20.00000,    -0.20020,0.51087
929.98700,104.18667,    -1.79231,76.30984,50.00000,0.0000e+000,20.00000,    -0.20046,0.51026
931.73798,104.36166,    -1.79588,76.27246,50.00000,0.0000e+000,20.00000,    -0.20075,0.50966
933.57898,104.53667,    -1.80477,76.23737,50.00000,0.0000e+000,20.00000,    -0.19984,0.50902
935.39899,104.71167,    -1.81417,76.20152,50.00000,0.0000e+000,20.00000,    -0.19820,0.50840
937.16998,104.88667,    -1.81114,76.16589,50.00000,0.0000e+000,20.00000,    -0.19721,0.50779
938.91998,105.06167,    -1.80322,76.13045,50.00000,0.0000e+000,20.00000,    -0.19604,0.50718
940.69000,105.23666,    -1.79725,76.09515,50.00000,0.0000e+000,20.00000,    -0.19417,0.50657
942.45898,105.41167,    -1.79431,76.06307,50.00000,0.0000e+000,20.00000,    -0.19134,0.50596
944.18298,105.58667,    -1.78749,76.03096,50.00000,0.0000e+000,20.00000,    -0.18806,0.50537
945.93597,105.76167,    -1.77886,75.99561,50.00000,0.0000e+000,20.00000,    -0.18358,0.50477
947.65399,105.93667,    -1.76817,75.96050,50.00000,0.0000e+000,20.00000,    -0.17847,0.50418
949.35400,106.11166,    -1.75760,75.92518,50.00000,0.0000e+000,20.00000,    -0.17338,0.50359
951.09302,106.28667,    -1.75243,75.89066,50.00000,0.0000e+000,20.00000,    -0.16852,0.50299
952.83398,106.46167,    -1.75224,75.86002,50.00000,0.0000e+000,20.00000,    -0.16325,0.50239
954.57300,106.63667,    -1.75409,75.83005,50.00000,0.0000e+000,20.00000,    -0.15770,0.50179
956.31201,106.81167,    -1.75360,75.79957,50.00000,0.0000e+000,20.00000,    -0.15193,0.50120
958.05701,106.98666,    -1.75469,75.77191,50.00000,0.0000e+000,20.00000,    -0.14580,0.50059
959.77802,107.16167,    -1.75353,75.74642,50.00000,0.0000e+000,20.00000,    -0.14047,0.50000
961.50299,107.33667,    -1.75438,75.72238,50.00000,0.0000e+000,20.00000,    -0.13566,0.49941
963.27100,107.51167,    -1.76031,75.70199,50.00000,0.0000e+000,20.00000,    -0.13010,0.49880
965.03802,107.68667,    -1.76588,75.68380,50.00000,0.0000e+000,20.00000,    -0.12353,0.49819
966.81299,107.86166,    -1.77147,75.66356,50.00000,0.0000e+000,20.00000,    -0.11641,0.49758
968.56702,108.03667,    -1.77351,75.64464,50.00000,0.0000e+000,20.00000,    -0.10927,0.49697
970.31299,108.21167,    -1.77446,75.62777,50.00000,0.0000e+000,20.00000,    -0.10273,0.49637
972.06299,108.38667,    -1.77509,75.61213,50.00000,0.0000e+000,20.00000,-9.7027e-002,0.49576
973.76599,108.56167,    -1.77198,75.59688,50.00000,0.0000e+000,20.00000,-9.0947e-002,0.49517
975.49902,108.73666,    -1.77214,75.58371,50.00000,0.0000e+000,20.00000,-8.5325e-002,0.49458
977.27502,108.91167,    -1.77762,75.56969,50.00000,0.0000e+000,20.00000,-7.9739e-002,0.49396
979.07300,109.08667,    -1.78864,75.55588,50.00000,0.0000e+000,20.00000,-7.4816e-002,0.49334
980.94501,109.26167,    -1.81043,75.54201,50.00000,0.0000e+000,20.00000,-7.1862e-002,0.49269
982.76703,109.43667,    -1.81821,75.52903,50.00000,0.0000e+000,20.00000,-6.7589e-002,0.49206
984.56598,109.61166,    -1.81764,75.51946,50.00000,0.0000e+000,20.00000,-6.3287e-002,0.49144
986.34399,109.78667,    -1.81461,75.51017,50.00000,0.0000e+000,20.00000,-5.9723e-002,0.49082
988.09003,109.96167,    -1.80811,75.50160,50.00000,0.0000e+000,20.00000,-5.6687e-002,0.49022
989.82202,110.13667,    -1.80459,75.49261,50.00000,0.0000e+000,20.00000,-5.2162e-002,0.48961
991.56500,110.31167,    -1.80464,75.48440,50.00000,0.0000e+000,20.00000,-4.9206e-002,0.48901
993.30200,110.48666,    -1.80641,75.47541,50.00000,0.0000e+000,20.00000,-4.8613e-002,0.48841
995.03802,110.66167,    -1.80570,75.46852,50.00000,0.0000e+000,20.00000,-4.8336e-002,0.48780
996.76599,110.83667,    -1.80612,75.46266,50.00000,0.0000e+000,20.00000,-5.1892e-002,0.48720
998.35498,110.99667,    -1.80864,75.45161,50.00000,0.0000e+000,20.00000,    -0.27322,0.48665