File: book/some_content/DG_ExpDat_B50S50DC1.csv
#FILE:                       ,B50S50DC1; 14-1-2025.ngb-ds3
#FORMAT:                     ,NETZSCH5
#IDENTITY:                   ,geopolymer paste
#DECIMAL:                    ,POINT
#SEPARATOR:                  ,COMMA
#MTYPE:                      ,DSC
#INSTRUMENT:                 ,Microlab TU Delft
#PROJECT:                    ,
#DATE/TIME:                  ,17/01/2025 3:24:00 PM
#CORR. FILE:                 ,Blank with cover; 13-1-2025.ngb-bs3
#LABORATORY:                 ,TU Delft Micro Lab
#OPERATOR:                   ,Ahmed
#REMARK:                     ,under Argon atmosphere, 10K/min
#SAMPLE:                     ,B50S50DC1;17-1-2025
#SAMPLE MASS /mg:            ,53.6
#MATERIAL:                   ,Geopolymer paste
#REFERENCE:                  ,blank
#REFERENCE MASS /mg:         ,0
#TYPE OF CRUCIBLE:           ,DSC/TG pan Al2O3
#SAMPLE CRUCIBLE MASS /mg:   ,0
#REFERENCE CRUCIBLE MASS /mg:,0
#CORR. CODE:                 ,020
#EXO:                        ,-1
#RANGE:                      ,40/10.0(K/min)/1000
#SEGMENT:                    ,S2/2

##Temp./øC,Time/min,DSC/(mW/mg),Mass/%,Gas Flow(purge1)/(ml/min),Gas Flow(purge2)/(ml/min),Gas Flow(protective)/(ml/min),DTG/(%/min),Sensit./(uV/mW)
 38.97700, 15.95667, 3.9445e-002,95.72402,50.00000,0.0000e+000,20.00000,    -0.17718,1.22835
 38.99400, 16.13667, 3.8553e-002,95.68921,50.00000,0.0000e+000,20.00000,    -0.17585,1.22833
 39.00800, 16.31667, 3.7221e-002,95.65708,50.00000,0.0000e+000,20.00000,    -0.17305,1.22831
 39.11100, 16.49667, 3.6380e-002,95.62618,50.00000,0.0000e+000,20.00000,    -0.17020,1.22817
 39.24900, 16.67667, 3.5678e-002,95.59509,50.00000,0.0000e+000,20.00000,    -0.16773,1.22798
 39.44900, 16.85667, 3.4933e-002,95.56433,50.00000,0.0000e+000,20.00000,    -0.16765,1.22770
 39.68700, 17.03667, 3.4722e-002,95.53332,50.00000,0.0000e+000,20.00000,    -0.16775,1.22737
 40.04900, 17.21667, 3.4446e-002,95.50303,50.00000,0.0000e+000,20.00000,    -0.16783,1.22687
 40.44400, 17.39667, 3.4449e-002,95.47431,50.00000,0.0000e+000,20.00000,    -0.16875,1.22633
 40.94800, 17.57667, 3.5212e-002,95.44649,50.00000,0.0000e+000,20.00000,    -0.17021,1.22564
 41.53400, 17.75667, 3.6339e-002,95.41931,50.00000,0.0000e+000,20.00000,    -0.17214,1.22483
 42.19900, 17.93667, 3.7692e-002,95.39242,50.00000,0.0000e+000,20.00000,    -0.17486,1.22391
 42.95600, 18.11667, 3.9634e-002,95.36625,50.00000,0.0000e+000,20.00000,    -0.18001,1.22287
 43.82100, 18.29667, 4.1944e-002,95.33969,50.00000,0.0000e+000,20.00000,    -0.18868,1.22167
 44.79600, 18.47667, 4.4673e-002,95.31206,50.00000,0.0000e+000,20.00000,    -0.19898,1.22033
 45.82400, 18.65667, 4.7960e-002,95.28272,50.00000,0.0000e+000,20.00000,    -0.21056,1.21891
 46.97400, 18.83667, 5.1647e-002,95.25220,50.00000,0.0000e+000,20.00000,    -0.22302,1.21733
 48.25200, 19.01667, 5.5961e-002,95.22008,50.00000,0.0000e+000,20.00000,    -0.23760,1.21557
 49.60900, 19.19667, 6.0621e-002,95.18543,50.00000,0.0000e+000,20.00000,    -0.25774,1.21370
 51.05900, 19.37667, 6.5701e-002,95.14815,50.00000,0.0000e+000,20.00000,    -0.28277,1.21170
 52.59100, 19.55667, 7.1606e-002,95.10698,50.00000,0.0000e+000,20.00000,    -0.30904,1.20959
 54.23400, 19.73667, 7.7564e-002,95.06235,50.00000,0.0000e+000,20.00000,    -0.33950,1.20733
 55.96200, 19.91667, 8.4297e-002,95.01253,50.00000,0.0000e+000,20.00000,    -0.37313,1.20495
 57.77100, 20.09667, 9.1763e-002,94.95145,50.00000,0.0000e+000,20.00000,    -0.41051,1.20247
 59.68200, 20.27667, 9.9497e-002,94.88336,50.00000,0.0000e+000,20.00000,    -0.45236,1.19984
 61.64600, 20.45667,     0.10834,94.81088,50.00000,0.0000e+000,20.00000,    -0.49951,1.19714
 63.72100, 20.63667,     0.11804,94.73494,50.00000,0.0000e+000,20.00000,    -0.55205,1.19429
 65.82400, 20.81667,     0.12860,94.65280,50.00000,0.0000e+000,20.00000,    -0.61040,1.19140
 68.01200, 20.99667,     0.14060,94.55398,50.00000,0.0000e+000,20.00000,    -0.67425,1.18840
 70.27100, 21.17667,     0.15375,94.43548,50.00000,0.0000e+000,20.00000,    -0.74379,1.18530
 72.56600, 21.35667,     0.16828,94.31375,50.00000,0.0000e+000,20.00000,    -0.81881,1.18216
 74.93000, 21.53667,     0.18445,94.17755,50.00000,0.0000e+000,20.00000,    -0.89958,1.17892
 77.32200, 21.71667,     0.20212,94.03009,50.00000,0.0000e+000,20.00000,    -0.98600,1.17565
 79.77100, 21.89667,     0.22149,93.86942,50.00000,0.0000e+000,20.00000,    -1.07605,1.17230
 82.24800, 22.07667,     0.24247,93.69196,50.00000,0.0000e+000,20.00000,    -1.17001,1.16892
 84.77700, 22.25667,     0.26590,93.49382,50.00000,0.0000e+000,20.00000,    -1.26871,1.16547
 87.33500, 22.43667,     0.29100,93.27465,50.00000,0.0000e+000,20.00000,    -1.37149,1.16198
 89.93700, 22.61667,     0.31821,93.03320,50.00000,0.0000e+000,20.00000,    -1.47681,1.15844
 92.54300, 22.79667,     0.34734,92.76894,50.00000,0.0000e+000,20.00000,    -1.58097,1.15489
 95.17300, 22.97667,     0.37825,92.48163,50.00000,0.0000e+000,20.00000,    -1.68033,1.15132
 97.84600, 23.15667,     0.41122,92.17057,50.00000,0.0000e+000,20.00000,    -1.77882,1.14769
100.49600, 23.33667,     0.44552,91.83503,50.00000,0.0000e+000,20.00000,    -1.87360,1.14410
103.16400, 23.51667,     0.48113,91.47434,50.00000,0.0000e+000,20.00000,    -1.96489,1.14049
105.80900, 23.69667,     0.51709,91.08951,50.00000,0.0000e+000,20.00000,    -2.05172,1.13692
108.49400, 23.87667,     0.55303,90.68195,50.00000,0.0000e+000,20.00000,    -2.13004,1.13329
111.15700, 24.05667,     0.58840,90.25270,50.00000,0.0000e+000,20.00000,    -2.19346,1.12970
113.81200, 24.23667,     0.62198,89.80408,50.00000,0.0000e+000,20.00000,    -2.23560,1.12613
116.47200, 24.41667,     0.65309,89.34048,50.00000,0.0000e+000,20.00000,    -2.25329,1.12255
119.10600, 24.59667,     0.68075,88.86559,50.00000,0.0000e+000,20.00000,    -2.24818,1.11902
121.74800, 24.77667,     0.70435,88.38588,50.00000,0.0000e+000,20.00000,    -2.22450,1.11548
124.37600, 24.95667,     0.72298,87.90512,50.00000,0.0000e+000,20.00000,    -2.18503,1.11197
126.98800, 25.13667,     0.73798,87.42477,50.00000,0.0000e+000,20.00000,    -2.13252,1.10848
129.63400, 25.31667,     0.75357,86.94504,50.00000,0.0000e+000,20.00000,    -2.06926,1.10495
132.24001, 25.49667,     0.76417,86.46831,50.00000,0.0000e+000,20.00000,    -1.99622,1.10148
134.84100, 25.67667,     0.76494,86.00396,50.00000,0.0000e+000,20.00000,    -1.91354,1.09803
137.42700, 25.85667,     0.75248,85.57058,50.00000,0.0000e+000,20.00000,    -1.82144,1.09460
140.02100, 26.03667,     0.72270,85.19072,50.00000,0.0000e+000,20.00000,    -1.72226,1.09117
142.60100, 26.21667,     0.67350,84.87797,50.00000,0.0000e+000,20.00000,    -1.61860,1.08776
145.17200, 26.39667,     0.61013,84.62754,50.00000,0.0000e+000,20.00000,    -1.51074,1.08437
147.72501, 26.57667,     0.54090,84.42442,50.00000,0.0000e+000,20.00000,    -1.40035,1.08101
150.26700, 26.75667,     0.47211,84.25666,50.00000,0.0000e+000,20.00000,    -1.28872,1.07768
152.82300, 26.93667,     0.40748,84.11407,50.00000,0.0000e+000,20.00000,    -1.17577,1.07433
155.34300, 27.11667,     0.34840,83.98658,50.00000,0.0000e+000,20.00000,    -1.06136,1.07103
157.84500, 27.29667,     0.29554,83.87049,50.00000,0.0000e+000,20.00000,    -0.94619,1.06777
160.32100, 27.47667,     0.24960,83.76663,50.00000,0.0000e+000,20.00000,    -0.83330,1.06454
162.78700, 27.65667,     0.20839,83.67544,50.00000,0.0000e+000,20.00000,    -0.72783,1.06134
165.21500, 27.83667,     0.17214,83.59175,50.00000,0.0000e+000,20.00000,    -0.63485,1.05819
167.61501, 28.01667,     0.13985,83.50880,50.00000,0.0000e+000,20.00000,    -0.55865,1.05508
169.96700, 28.19667,     0.11096,83.42893,50.00000,0.0000e+000,20.00000,    -0.49965,1.05204
172.30600, 28.37667, 8.4845e-002,83.35260,50.00000,0.0000e+000,20.00000,    -0.45442,1.04903
174.59100, 28.55667, 6.1299e-002,83.27928,50.00000,0.0000e+000,20.00000,    -0.41862,1.04609
176.86800, 28.73667, 3.9829e-002,83.21076,50.00000,0.0000e+000,20.00000,    -0.38897,1.04317
179.10001, 28.91667, 2.0414e-002,83.14815,50.00000,0.0000e+000,20.00000,    -0.36361,1.04031
181.28999, 29.09667, 2.3186e-003,83.09092,50.00000,0.0000e+000,20.00000,    -0.34136,1.03751
183.47200, 29.27667,-1.4210e-002,83.03623,50.00000,0.0000e+000,20.00000,    -0.32232,1.03473
185.59599, 29.45667,-2.9584e-002,82.98189,50.00000,0.0000e+000,20.00000,    -0.30590,1.03203
187.69701, 29.63667,-4.3627e-002,82.93151,50.00000,0.0000e+000,20.00000,    -0.29075,1.02936
189.78600, 29.81667,-5.7104e-002,82.88636,50.00000,0.0000e+000,20.00000,    -0.27513,1.02671
191.82100, 29.99667,-6.9673e-002,82.84297,50.00000,0.0000e+000,20.00000,    -0.26027,1.02414
193.83099, 30.17667,-8.1661e-002,82.79883,50.00000,0.0000e+000,20.00000,    -0.24643,1.02160
195.84200, 30.35667,-9.2675e-002,82.75650,50.00000,0.0000e+000,20.00000,    -0.23335,1.01907
197.80299, 30.53667,    -0.10354,82.71857,50.00000,0.0000e+000,20.00000,    -0.22132,1.01661
199.76601, 30.71667,    -0.11414,82.68207,50.00000,0.0000e+000,20.00000,    -0.21053,1.01415
201.70700, 30.89667,    -0.12461,82.64534,50.00000,0.0000e+000,20.00000,    -0.20103,1.01172
203.62399, 31.07667,    -0.13362,82.60916,50.00000,0.0000e+000,20.00000,    -0.19217,1.00932
205.53101, 31.25667,    -0.14324,82.57528,50.00000,0.0000e+000,20.00000,    -0.18313,1.00695
207.41600, 31.43667,    -0.15178,82.54602,50.00000,0.0000e+000,20.00000,    -0.17503,1.00460
209.27499, 31.61667,    -0.15979,82.51965,50.00000,0.0000e+000,20.00000,    -0.16831,1.00230
211.10899, 31.79667,    -0.16749,82.49372,50.00000,0.0000e+000,20.00000,    -0.16189,1.00003
212.95200, 31.97667,    -0.17443,82.46734,50.00000,0.0000e+000,20.00000,    -0.15536,0.99775
214.73599, 32.15667,    -0.18115,82.44137,50.00000,0.0000e+000,20.00000,    -0.14881,0.99555
216.53300, 32.33667,    -0.18822,82.41575,50.00000,0.0000e+000,20.00000,    -0.14331,0.99334
218.30701, 32.51667,    -0.19525,82.39151,50.00000,0.0000e+000,20.00000,    -0.13830,0.99116
220.05000, 32.69667,    -0.20215,82.36816,50.00000,0.0000e+000,20.00000,    -0.13326,0.98902
221.80499, 32.87667,    -0.20905,82.34558,50.00000,0.0000e+000,20.00000,    -0.12865,0.98688
223.55701, 33.05667,    -0.21594,82.32402,50.00000,0.0000e+000,20.00000,    -0.12423,0.98474
225.27200, 33.23667,    -0.22261,82.30245,50.00000,0.0000e+000,20.00000,    -0.12128,0.98265
226.99200, 33.41667,    -0.22922,82.28105,50.00000,0.0000e+000,20.00000,    -0.11869,0.98056
228.71500, 33.59667,    -0.23591,82.26101,50.00000,0.0000e+000,20.00000,    -0.11626,0.97847
230.42400, 33.77667,    -0.24281,82.24078,50.00000,0.0000e+000,20.00000,    -0.11366,0.97640
232.13499, 33.95667,    -0.24948,82.22165,50.00000,0.0000e+000,20.00000,    -0.11101,0.97434
233.84500, 34.13667,    -0.25609,82.20317,50.00000,0.0000e+000,20.00000,    -0.10847,0.97227
235.57700, 34.31667,    -0.26240,82.18499,50.00000,0.0000e+000,20.00000,    -0.10613,0.97019
237.26601, 34.49667,    -0.26871,82.16675,50.00000,0.0000e+000,20.00000,    -0.10426,0.96817
238.97501, 34.67667,    -0.27471,82.14735,50.00000,0.0000e+000,20.00000,    -0.10244,0.96612
240.66499, 34.85667,    -0.28093,82.12896,50.00000,0.0000e+000,20.00000,    -0.10101,0.96410
242.38200, 35.03667,    -0.28749,82.10984,50.00000,0.0000e+000,20.00000,-9.9247e-002,0.96205
244.08800, 35.21667,    -0.29400,82.09233,50.00000,0.0000e+000,20.00000,-9.7356e-002,0.96002
245.79800, 35.39667,    -0.30059,82.07548,50.00000,0.0000e+000,20.00000,-9.6002e-002,0.95800
247.51100, 35.57667,    -0.30695,82.05844,50.00000,0.0000e+000,20.00000,-9.4748e-002,0.95597
249.23300, 35.75667,    -0.31241,82.04215,50.00000,0.0000e+000,20.00000,-9.3833e-002,0.95393
250.93700, 35.93667,    -0.31808,82.02559,50.00000,0.0000e+000,20.00000,-9.3148e-002,0.95192
252.65601, 36.11666,    -0.32331,82.00970,50.00000,0.0000e+000,20.00000,-9.2609e-002,0.94990
254.35800, 36.29667,    -0.32863,81.99315,50.00000,0.0000e+000,20.00000,-9.1993e-002,0.94791
256.06699, 36.47667,    -0.33393,81.97702,50.00000,0.0000e+000,20.00000,-9.1093e-002,0.94591
257.79001, 36.65667,    -0.34002,81.96059,50.00000,0.0000e+000,20.00000,-9.0475e-002,0.94389
259.48099, 36.83667,    -0.34602,81.94525,50.00000,0.0000e+000,20.00000,-8.9578e-002,0.94192
261.19400, 37.01667,    -0.35233,81.93069,50.00000,0.0000e+000,20.00000,-8.9043e-002,0.93993
262.90500, 37.19667,    -0.35831,81.91552,50.00000,0.0000e+000,20.00000,-8.8898e-002,0.93795
264.61801, 37.37667,    -0.36445,81.89998,50.00000,0.0000e+000,20.00000,-8.8822e-002,0.93597
266.34201, 37.55667,    -0.37030,81.88399,50.00000,0.0000e+000,20.00000,-8.9418e-002,0.93398
268.04800, 37.73667,    -0.37573,81.86801,50.00000,0.0000e+000,20.00000,-8.9756e-002,0.93202
269.76300, 37.91667,    -0.38143,81.85171,50.00000,0.0000e+000,20.00000,-8.9851e-002,0.93005
271.49399, 38.09667,    -0.38685,81.83582,50.00000,0.0000e+000,20.00000,-8.9767e-002,0.92807
273.21600, 38.27667,    -0.39238,81.81983,50.00000,0.0000e+000,20.00000,-8.9791e-002,0.92610
274.93201, 38.45667,    -0.39815,81.80356,50.00000,0.0000e+000,20.00000,-8.9993e-002,0.92414
276.64301, 38.63667,    -0.40391,81.78773,50.00000,0.0000e+000,20.00000,-9.0590e-002,0.92220
278.37500, 38.81667,    -0.40954,81.77191,50.00000,0.0000e+000,20.00000,-9.1755e-002,0.92023
280.09299, 38.99667,    -0.41546,81.75568,50.00000,0.0000e+000,20.00000,-9.2809e-002,0.91829
281.81400, 39.17667,    -0.42126,81.73903,50.00000,0.0000e+000,20.00000,-9.3812e-002,0.91635
283.57001, 39.35667,    -0.42672,81.72072,50.00000,0.0000e+000,20.00000,-9.4901e-002,0.91438
285.28900, 39.53667,    -0.43294,81.70260,50.00000,0.0000e+000,20.00000,-9.6117e-002,0.91245
287.03799, 39.71667,    -0.43840,81.68622,50.00000,0.0000e+000,20.00000,-9.7133e-002,0.91049
288.76801, 39.89667,    -0.44349,81.67006,50.00000,0.0000e+000,20.00000,-9.8585e-002,0.90856
290.50500, 40.07667,    -0.44891,81.65383,50.00000,0.0000e+000,20.00000,    -0.10005,0.90663
292.23999, 40.25667,    -0.45406,81.63686,50.00000,0.0000e+000,20.00000,    -0.10138,0.90470
293.99301, 40.43667,    -0.45916,81.61916,50.00000,0.0000e+000,20.00000,    -0.10303,0.90276
295.73300, 40.61666,    -0.46499,81.60052,50.00000,0.0000e+000,20.00000,    -0.10471,0.90084
297.47198, 40.79667,    -0.47054,81.58153,50.00000,0.0000e+000,20.00000,    -0.10657,0.89892
299.21399, 40.97667,    -0.47609,81.56249,50.00000,0.0000e+000,20.00000,    -0.10856,0.89701
300.96701, 41.15667,    -0.48190,81.54271,50.00000,0.0000e+000,20.00000,    -0.11018,0.89509
302.70901, 41.33667,    -0.48761,81.52224,50.00000,0.0000e+000,20.00000,    -0.11182,0.89319
304.48300, 41.51667,    -0.49300,81.50230,50.00000,0.0000e+000,20.00000,    -0.11419,0.89126
306.24899, 41.69667,    -0.49829,81.48122,50.00000,0.0000e+000,20.00000,    -0.11701,0.88934
308.00101, 41.87667,    -0.50314,81.45983,50.00000,0.0000e+000,20.00000,    -0.12020,0.88744
309.77100, 42.05667,    -0.50793,81.43878,50.00000,0.0000e+000,20.00000,    -0.12316,0.88553
311.54800, 42.23667,    -0.51267,81.41692,50.00000,0.0000e+000,20.00000,    -0.12616,0.88362
313.29099, 42.41667,    -0.51676,81.39504,50.00000,0.0000e+000,20.00000,    -0.12928,0.88175
315.05301, 42.59667,    -0.52162,81.37227,50.00000,0.0000e+000,20.00000,    -0.13231,0.87987
316.82401, 42.77667,    -0.52596,81.34851,50.00000,0.0000e+000,20.00000,    -0.13518,0.87798
318.60001, 42.95667,    -0.53008,81.32462,50.00000,0.0000e+000,20.00000,    -0.13782,0.87609
320.36401, 43.13667,    -0.53405,81.30030,50.00000,0.0000e+000,20.00000,    -0.14010,0.87422
322.13199, 43.31667,    -0.53782,81.27525,50.00000,0.0000e+000,20.00000,    -0.14231,0.87235
323.90201, 43.49667,    -0.54219,81.24907,50.00000,0.0000e+000,20.00000,    -0.14434,0.87048
325.66599, 43.67667,    -0.54633,81.22127,50.00000,0.0000e+000,20.00000,    -0.14607,0.86863
327.45401, 43.85667,    -0.55022,81.19364,50.00000,0.0000e+000,20.00000,    -0.14786,0.86675
329.21600, 44.03667,    -0.55464,81.16525,50.00000,0.0000e+000,20.00000,    -0.14913,0.86491
330.99600, 44.21667,    -0.55952,81.13559,50.00000,0.0000e+000,20.00000,    -0.15000,0.86306
332.79199, 44.39667,    -0.56460,81.10536,50.00000,0.0000e+000,20.00000,    -0.15051,0.86120
334.56799, 44.57667,    -0.56905,81.07588,50.00000,0.0000e+000,20.00000,    -0.15056,0.85936
336.33899, 44.75667,    -0.57384,81.04656,50.00000,0.0000e+000,20.00000,    -0.15064,0.85753
338.10800, 44.93667,    -0.57763,81.01763,50.00000,0.0000e+000,20.00000,    -0.15043,0.85571
339.87201, 45.11666,    -0.58241,80.98955,50.00000,0.0000e+000,20.00000,    -0.14968,0.85390
341.60999, 45.29667,    -0.58720,80.96131,50.00000,0.0000e+000,20.00000,    -0.14859,0.85213
343.35101, 45.47667,    -0.59383,80.93339,50.00000,0.0000e+000,20.00000,    -0.14692,0.85035
345.11899, 45.65667,    -0.60362,80.90582,50.00000,0.0000e+000,20.00000,    -0.14476,0.84856
346.91199, 45.83667,    -0.61382,80.87914,50.00000,0.0000e+000,20.00000,    -0.14215,0.84674
348.69199, 46.01667,    -0.62370,80.85395,50.00000,0.0000e+000,20.00000,    -0.13931,0.84495
350.49301, 46.19667,    -0.63284,80.82942,50.00000,0.0000e+000,20.00000,    -0.13637,0.84314
352.29501, 46.37667,    -0.64138,80.80551,50.00000,0.0000e+000,20.00000,    -0.13298,0.84133
354.09399, 46.55667,    -0.64955,80.78143,50.00000,0.0000e+000,20.00000,    -0.12927,0.83953
355.89001, 46.73667,    -0.65680,80.75774,50.00000,0.0000e+000,20.00000,    -0.12557,0.83775
357.68100, 46.91667,    -0.66427,80.73541,50.00000,0.0000e+000,20.00000,    -0.12197,0.83597
359.48401, 47.09667,    -0.67183,80.71350,50.00000,0.0000e+000,20.00000,    -0.11800,0.83418
361.27399, 47.27667,    -0.67955,80.69173,50.00000,0.0000e+000,20.00000,    -0.11387,0.83242
363.06699, 47.45667,    -0.68695,80.67176,50.00000,0.0000e+000,20.00000,    -0.10985,0.83066
364.84299, 47.63667,    -0.69471,80.65292,50.00000,0.0000e+000,20.00000,    -0.10613,0.82892
366.61801, 47.81667,    -0.70252,80.63408,50.00000,0.0000e+000,20.00000,    -0.10286,0.82719
368.39999, 47.99667,    -0.71030,80.61436,50.00000,0.0000e+000,20.00000,-9.9489e-002,0.82546
370.18201, 48.17667,    -0.71800,80.59684,50.00000,0.0000e+000,20.00000,-9.6131e-002,0.82373
371.97000, 48.35667,    -0.72562,80.58094,50.00000,0.0000e+000,20.00000,-9.2871e-002,0.82200
373.75500, 48.53667,    -0.73255,80.56543,50.00000,0.0000e+000,20.00000,-8.9954e-002,0.82028
375.51901, 48.71667,    -0.73840,80.55025,50.00000,0.0000e+000,20.00000,-8.7376e-002,0.81859
377.29199, 48.89667,    -0.74505,80.53640,50.00000,0.0000e+000,20.00000,-8.4700e-002,0.81690
379.04501, 49.07667,    -0.75181,80.52339,50.00000,0.0000e+000,20.00000,-8.1485e-002,0.81523
380.81601, 49.25667,    -0.75916,80.51050,50.00000,0.0000e+000,20.00000,-7.8794e-002,0.81355
382.58899, 49.43667,    -0.76688,80.49730,50.00000,0.0000e+000,20.00000,-7.6807e-002,0.81187
384.35901, 49.61666,    -0.77565,80.48379,50.00000,0.0000e+000,20.00000,-7.4611e-002,0.81020
386.16000, 49.79667,    -0.78581,80.47133,50.00000,0.0000e+000,20.00000,-7.1820e-002,0.80851
387.96899, 49.97667,    -0.79617,80.45958,50.00000,0.0000e+000,20.00000,-6.9579e-002,0.80681
389.78299, 50.15667,    -0.80534,80.44763,50.00000,0.0000e+000,20.00000,-6.7675e-002,0.80512
391.61301, 50.33667,    -0.81332,80.43454,50.00000,0.0000e+000,20.00000,-6.5503e-002,0.80342
393.41299, 50.51667,    -0.81946,80.42137,50.00000,0.0000e+000,20.00000,-6.3766e-002,0.80176
395.20499, 50.69667,    -0.82415,80.40903,50.00000,0.0000e+000,20.00000,-6.2698e-002,0.80010
396.97501, 50.87667,    -0.82688,80.39862,50.00000,0.0000e+000,20.00000,-6.1980e-002,0.79848
398.74100, 51.05667,    -0.82991,80.38845,50.00000,0.0000e+000,20.00000,-6.1325e-002,0.79686
400.51001, 51.23667,    -0.83432,80.37680,50.00000,0.0000e+000,20.00000,-6.0749e-002,0.79524
402.25699, 51.41667,    -0.84042,80.36587,50.00000,0.0000e+000,20.00000,-6.0113e-002,0.79366
404.03400, 51.59667,    -0.84940,80.35626,50.00000,0.0000e+000,20.00000,-5.9869e-002,0.79205
405.81601, 51.77667,    -0.85900,80.34655,50.00000,0.0000e+000,20.00000,-6.0320e-002,0.79044
407.61401, 51.95667,    -0.86782,80.33725,50.00000,0.0000e+000,20.00000,-6.0455e-002,0.78882
409.40500, 52.13667,    -0.87483,80.32957,50.00000,0.0000e+000,20.00000,-5.9974e-002,0.78722
411.19501, 52.31667,    -0.88123,80.32092,50.00000,0.0000e+000,20.00000,-5.9907e-002,0.78562
412.99200, 52.49667,    -0.88697,80.31088,50.00000,0.0000e+000,20.00000,-5.9824e-002,0.78402
414.77899, 52.67667,    -0.89214,80.30042,50.00000,0.0000e+000,20.00000,-6.0024e-002,0.78244
416.55600, 52.85667,    -0.89727,80.28996,50.00000,0.0000e+000,20.00000,-6.0390e-002,0.78087
418.33701, 53.03667,    -0.90191,80.27905,50.00000,0.0000e+000,20.00000,-6.0185e-002,0.77930
420.09399, 53.21667,    -0.90671,80.26781,50.00000,0.0000e+000,20.00000,-6.0000e-002,0.77776
421.86600, 53.39667,    -0.91235,80.25626,50.00000,0.0000e+000,20.00000,-6.0231e-002,0.77622
423.65100, 53.57667,    -0.92066,80.24298,50.00000,0.0000e+000,20.00000,-6.0573e-002,0.77466
425.45599, 53.75667,    -0.93000,80.23029,50.00000,0.0000e+000,20.00000,-6.1060e-002,0.77310
427.25201, 53.93667,    -0.93796,80.21919,50.00000,0.0000e+000,20.00000,-6.1889e-002,0.77155
429.05200, 54.11666,    -0.94457,80.20643,50.00000,0.0000e+000,20.00000,-6.2529e-002,0.77000
430.85800, 54.29667,    -0.95020,80.19392,50.00000,0.0000e+000,20.00000,-6.2697e-002,0.76846
432.64401, 54.47667,    -0.95491,80.18250,50.00000,0.0000e+000,20.00000,-6.2833e-002,0.76694
434.43399, 54.65667,    -0.95998,80.17107,50.00000,0.0000e+000,20.00000,-6.2976e-002,0.76542
436.21100, 54.83667,    -0.96541,80.16026,50.00000,0.0000e+000,20.00000,-6.3093e-002,0.76391
437.98599, 55.01667,    -0.97112,80.14973,50.00000,0.0000e+000,20.00000,-6.3048e-002,0.76242
439.76501, 55.19667,    -0.97760,80.13921,50.00000,0.0000e+000,20.00000,-6.2662e-002,0.76092
441.55801, 55.37667,    -0.98385,80.12835,50.00000,0.0000e+000,20.00000,-6.1857e-002,0.75942
443.34500, 55.55667,    -0.99021,80.11713,50.00000,0.0000e+000,20.00000,-6.1411e-002,0.75793
445.12201, 55.73667,    -0.99649,80.10616,50.00000,0.0000e+000,20.00000,-6.1671e-002,0.75646
446.90601, 55.91667,    -1.00286,80.09545,50.00000,0.0000e+000,20.00000,-6.1354e-002,0.75498
448.70801, 56.09667,    -1.00949,80.08493,50.00000,0.0000e+000,20.00000,-6.1045e-002,0.75350
450.49301, 56.27667,    -1.01582,80.07406,50.00000,0.0000e+000,20.00000,-6.1614e-002,0.75204
452.27499, 56.45667,    -1.02174,80.06307,50.00000,0.0000e+000,20.00000,-6.2232e-002,0.75058
454.08200, 56.63667,    -1.02781,80.05191,50.00000,0.0000e+000,20.00000,-6.2916e-002,0.74911
455.87299, 56.81667,    -1.03353,80.04072,50.00000,0.0000e+000,20.00000,-6.3735e-002,0.74766
457.64801, 56.99667,    -1.03901,80.03056,50.00000,0.0000e+000,20.00000,-6.4618e-002,0.74623
459.43900, 57.17667,    -1.04486,80.02063,50.00000,0.0000e+000,20.00000,-6.5441e-002,0.74479
461.22699, 57.35667,    -1.05114,80.00943,50.00000,0.0000e+000,20.00000,-6.6030e-002,0.74336
463.02301, 57.53667,    -1.05729,79.99735,50.00000,0.0000e+000,20.00000,-6.6791e-002,0.74193
464.81500, 57.71667,    -1.06484,79.98591,50.00000,0.0000e+000,20.00000,-6.8021e-002,0.74050
466.63599, 57.89667,    -1.07431,79.97451,50.00000,0.0000e+000,20.00000,-6.9508e-002,0.73906
468.45700, 58.07667,    -1.08178,79.96118,50.00000,0.0000e+000,20.00000,-7.0951e-002,0.73763
470.26401, 58.25667,    -1.08652,79.94741,50.00000,0.0000e+000,20.00000,-7.2249e-002,0.73621
472.06799, 58.43667,    -1.08997,79.93397,50.00000,0.0000e+000,20.00000,-7.3462e-002,0.73480
473.87500, 58.61666,    -1.09311,79.92049,50.00000,0.0000e+000,20.00000,-7.4799e-002,0.73340
475.63101, 58.79667,    -1.09228,79.90674,50.00000,0.0000e+000,20.00000,-7.6559e-002,0.73204
477.36499, 58.97667,    -1.09076,79.89300,50.00000,0.0000e+000,20.00000,-7.8459e-002,0.73070
479.08301, 59.15667,    -1.09343,79.87948,50.00000,0.0000e+000,20.00000,-8.0091e-002,0.72938
480.84399, 59.33667,    -1.10025,79.86595,50.00000,0.0000e+000,20.00000,-8.1612e-002,0.72803
482.61700, 59.51667,    -1.11023,79.85083,50.00000,0.0000e+000,20.00000,-8.3704e-002,0.72668
484.42200, 59.69667,    -1.12035,79.83496,50.00000,0.0000e+000,20.00000,-8.5832e-002,0.72531
486.20801, 59.87667,    -1.12966,79.81889,50.00000,0.0000e+000,20.00000,-8.7316e-002,0.72396
488.01599, 60.05667,    -1.13823,79.80305,50.00000,0.0000e+000,20.00000,-8.8806e-002,0.72260
489.84100, 60.23667,    -1.14514,79.78755,50.00000,0.0000e+000,20.00000,-9.0291e-002,0.72123
491.65900, 60.41667,    -1.15001,79.77153,50.00000,0.0000e+000,20.00000,-9.1874e-002,0.71987
493.46500, 60.59667,    -1.15422,79.75480,50.00000,0.0000e+000,20.00000,-9.2863e-002,0.71853
495.27200, 60.77667,    -1.15853,79.73802,50.00000,0.0000e+000,20.00000,-9.3919e-002,0.71720
497.05701, 60.95667,    -1.16183,79.72113,50.00000,0.0000e+000,20.00000,-9.5405e-002,0.71588
498.85001, 61.13667,    -1.16561,79.70368,50.00000,0.0000e+000,20.00000,-9.7308e-002,0.71456
500.63400, 61.31667,    -1.17057,79.68470,50.00000,0.0000e+000,20.00000,-9.8912e-002,0.71326
502.42599, 61.49667,    -1.17611,79.66544,50.00000,0.0000e+000,20.00000,    -0.10025,0.71196
504.23001, 61.67667,    -1.18196,79.64708,50.00000,0.0000e+000,20.00000,    -0.10157,0.71065
506.02399, 61.85667,    -1.18801,79.62783,50.00000,0.0000e+000,20.00000,    -0.10283,0.70936
507.83200, 62.03667,    -1.19298,79.60892,50.00000,0.0000e+000,20.00000,    -0.10384,0.70806
509.62399, 62.21667,    -1.19770,79.58967,50.00000,0.0000e+000,20.00000,    -0.10525,0.70678
511.42499, 62.39667,    -1.20200,79.57196,50.00000,0.0000e+000,20.00000,    -0.10682,0.70549
513.21399, 62.57667,    -1.20635,79.55468,50.00000,0.0000e+000,20.00000,    -0.10853,0.70422
515.00598, 62.75667,    -1.21129,79.53576,50.00000,0.0000e+000,20.00000,    -0.11035,0.70296
516.79700, 62.93667,    -1.21673,79.51568,50.00000,0.0000e+000,20.00000,    -0.11192,0.70170
518.60602, 63.11666,    -1.22468,79.49484,50.00000,0.0000e+000,20.00000,    -0.11293,0.70043
520.44800, 63.29667,    -1.23447,79.47417,50.00000,0.0000e+000,20.00000,    -0.11381,0.69915
522.27899, 63.47667,    -1.24173,79.45333,50.00000,0.0000e+000,20.00000,    -0.11505,0.69788
524.09399, 63.65667,    -1.24576,79.43260,50.00000,0.0000e+000,20.00000,    -0.11594,0.69662
525.89398, 63.83667,    -1.24739,79.41340,50.00000,0.0000e+000,20.00000,    -0.11701,0.69539
527.69000, 64.01667,    -1.24882,79.39271,50.00000,0.0000e+000,20.00000,    -0.11826,0.69416
529.46802, 64.19666,    -1.25078,79.37042,50.00000,0.0000e+000,20.00000,    -0.11997,0.69294
531.24902, 64.37666,    -1.25525,79.34748,50.00000,0.0000e+000,20.00000,    -0.12185,0.69173
533.04199, 64.55666,    -1.26094,79.32401,50.00000,0.0000e+000,20.00000,    -0.12344,0.69052
534.83398, 64.73666,    -1.26717,79.30080,50.00000,0.0000e+000,20.00000,    -0.12464,0.68932
536.63501, 64.91666,    -1.27392,79.27836,50.00000,0.0000e+000,20.00000,    -0.12554,0.68811
538.44202, 65.09666,    -1.28008,79.25581,50.00000,0.0000e+000,20.00000,    -0.12662,0.68690
540.23199, 65.27666,    -1.28547,79.23291,50.00000,0.0000e+000,20.00000,    -0.12779,0.68571
542.01898, 65.45667,    -1.28954,79.21044,50.00000,0.0000e+000,20.00000,    -0.12906,0.68453
543.82001, 65.63667,    -1.29353,79.18770,50.00000,0.0000e+000,20.00000,    -0.13064,0.68335
545.60999, 65.81667,    -1.29809,79.16408,50.00000,0.0000e+000,20.00000,    -0.13184,0.68217
547.38300, 65.99667,    -1.30212,79.13972,50.00000,0.0000e+000,20.00000,    -0.13279,0.68101
549.16998, 66.17667,    -1.30585,79.11581,50.00000,0.0000e+000,20.00000,    -0.13378,0.67985
550.92200, 66.35667,    -1.30820,79.09130,50.00000,0.0000e+000,20.00000,    -0.13449,0.67872
552.68103, 66.53667,    -1.30804,79.06695,50.00000,0.0000e+000,20.00000,    -0.13523,0.67758
554.43298, 66.71667,    -1.31238,79.04289,50.00000,0.0000e+000,20.00000,    -0.13619,0.67646
556.18402, 66.89667,    -1.32047,79.01835,50.00000,0.0000e+000,20.00000,    -0.13742,0.67534
557.98901, 67.07667,    -1.33018,78.99336,50.00000,0.0000e+000,20.00000,    -0.13844,0.67419
559.78900, 67.25667,    -1.33770,78.96788,50.00000,0.0000e+000,20.00000,    -0.13948,0.67305
561.57898, 67.43667,    -1.34452,78.94267,50.00000,0.0000e+000,20.00000,    -0.14062,0.67192
563.40198, 67.61667,    -1.35112,78.91795,50.00000,0.0000e+000,20.00000,    -0.14141,0.67078
565.21802, 67.79667,    -1.35762,78.89254,50.00000,0.0000e+000,20.00000,    -0.14141,0.66964
567.02301, 67.97667,    -1.36337,78.86612,50.00000,0.0000e+000,20.00000,    -0.14195,0.66852
568.83301, 68.15667,    -1.36831,78.84003,50.00000,0.0000e+000,20.00000,    -0.14282,0.66740
570.64398, 68.33667,    -1.37282,78.81401,50.00000,0.0000e+000,20.00000,    -0.14358,0.66628
572.47400, 68.51667,    -1.37715,78.78804,50.00000,0.0000e+000,20.00000,    -0.14448,0.66516
574.28601, 68.69666,    -1.38142,78.76118,50.00000,0.0000e+000,20.00000,    -0.14584,0.66405
576.10699, 68.87666,    -1.38770,78.73442,50.00000,0.0000e+000,20.00000,    -0.14701,0.66294
577.93103, 69.05666,    -1.39363,78.70812,50.00000,0.0000e+000,20.00000,    -0.14766,0.66184
579.72498, 69.23666,    -1.39904,78.68141,50.00000,0.0000e+000,20.00000,    -0.14832,0.66076
581.54303, 69.41666,    -1.40327,78.65481,50.00000,0.0000e+000,20.00000,    -0.14951,0.65966
583.34399, 69.59666,    -1.40738,78.63031,50.00000,0.0000e+000,20.00000,    -0.15033,0.65859
585.14099, 69.77666,    -1.41212,78.60478,50.00000,0.0000e+000,20.00000,    -0.15111,0.65752
586.95203, 69.95667,    -1.41675,78.57731,50.00000,0.0000e+000,20.00000,    -0.15251,0.65645
588.76703, 70.13667,    -1.42091,78.54997,50.00000,0.0000e+000,20.00000,    -0.15398,0.65537
590.55200, 70.31667,    -1.42530,78.52285,50.00000,0.0000e+000,20.00000,    -0.15533,0.65433
592.35901, 70.49667,    -1.43017,78.49366,50.00000,0.0000e+000,20.00000,    -0.15679,0.65327
594.15503, 70.67667,    -1.43556,78.46430,50.00000,0.0000e+000,20.00000,    -0.15828,0.65222
595.95697, 70.85667,    -1.44071,78.43623,50.00000,0.0000e+000,20.00000,    -0.15982,0.65118
597.76801, 71.03667,    -1.44541,78.40875,50.00000,0.0000e+000,20.00000,    -0.16135,0.65013
599.56201, 71.21667,    -1.44979,78.37971,50.00000,0.0000e+000,20.00000,    -0.16304,0.64910
601.36298, 71.39667,    -1.45429,78.35137,50.00000,0.0000e+000,20.00000,    -0.16527,0.64807
603.16699, 71.57667,    -1.45886,78.32249,50.00000,0.0000e+000,20.00000,    -0.16731,0.64705
604.96198, 71.75667,    -1.46367,78.29143,50.00000,0.0000e+000,20.00000,    -0.16851,0.64603
606.76300, 71.93667,    -1.46889,78.25995,50.00000,0.0000e+000,20.00000,    -0.16981,0.64501
608.57202, 72.11667,    -1.47400,78.22909,50.00000,0.0000e+000,20.00000,    -0.17162,0.64399
610.37201, 72.29667,    -1.47828,78.19725,50.00000,0.0000e+000,20.00000,    -0.17321,0.64299
612.15997, 72.47667,    -1.48261,78.16487,50.00000,0.0000e+000,20.00000,    -0.17455,0.64199
613.95300, 72.65667,    -1.48589,78.13289,50.00000,0.0000e+000,20.00000,    -0.17612,0.64100
615.74500, 72.83667,    -1.49001,78.10082,50.00000,0.0000e+000,20.00000,    -0.17807,0.64001
617.55200, 73.01667,    -1.49440,78.06791,50.00000,0.0000e+000,20.00000,    -0.17966,0.63901
619.35602, 73.19666,    -1.50146,78.03497,50.00000,0.0000e+000,20.00000,    -0.18126,0.63803
621.19098, 73.37666,    -1.51301,78.00226,50.00000,0.0000e+000,20.00000,    -0.18275,0.63703
623.03998, 73.55666,    -1.52072,77.97047,50.00000,0.0000e+000,20.00000,    -0.18325,0.63602
624.84998, 73.73666,    -1.52295,77.93845,50.00000,0.0000e+000,20.00000,    -0.18353,0.63504
626.64001, 73.91666,    -1.52097,77.90511,50.00000,0.0000e+000,20.00000,    -0.18459,0.63408
628.40399, 74.09666,    -1.52172,77.87045,50.00000,0.0000e+000,20.00000,    -0.18587,0.63314
630.18903, 74.27666,    -1.52518,77.83600,50.00000,0.0000e+000,20.00000,    -0.18725,0.63218
631.97803, 74.45667,    -1.53041,77.80192,50.00000,0.0000e+000,20.00000,    -0.18900,0.63123
633.77002, 74.63667,    -1.53666,77.76752,50.00000,0.0000e+000,20.00000,    -0.19077,0.63029
635.57800, 74.81667,    -1.54303,77.73283,50.00000,0.0000e+000,20.00000,    -0.19212,0.62933
637.39099, 74.99667,    -1.54756,77.69839,50.00000,0.0000e+000,20.00000,    -0.19320,0.62838
639.18701, 75.17667,    -1.55298,77.66426,50.00000,0.0000e+000,20.00000,    -0.19451,0.62745
640.99103, 75.35667,    -1.55790,77.63143,50.00000,0.0000e+000,20.00000,    -0.19620,0.62651
642.78497, 75.53667,    -1.56085,77.59902,50.00000,0.0000e+000,20.00000,    -0.19761,0.62558
644.57501, 75.71667,    -1.56482,77.56464,50.00000,0.0000e+000,20.00000,    -0.19887,0.62466
646.38599, 75.89667,    -1.56954,77.52846,50.00000,0.0000e+000,20.00000,    -0.20013,0.62373
648.17297, 76.07667,    -1.57345,77.49124,50.00000,0.0000e+000,20.00000,    -0.20132,0.62281
649.96899, 76.25667,    -1.57688,77.45286,50.00000,0.0000e+000,20.00000,    -0.20264,0.62190
651.77399, 76.43667,    -1.58051,77.41441,50.00000,0.0000e+000,20.00000,    -0.20421,0.62099
653.58398, 76.61667,    -1.58561,77.37645,50.00000,0.0000e+000,20.00000,    -0.20554,0.62007
655.41400, 76.79667,    -1.59441,77.33955,50.00000,0.0000e+000,20.00000,    -0.20665,0.61915
657.24902, 76.97667,    -1.60002,77.30211,50.00000,0.0000e+000,20.00000,    -0.20819,0.61823
659.06598, 77.15667,    -1.60310,77.26397,50.00000,0.0000e+000,20.00000,    -0.20987,0.61733
660.87299, 77.33667,    -1.60454,77.22683,50.00000,0.0000e+000,20.00000,    -0.21158,0.61643
662.67902, 77.51667,    -1.60647,77.18936,50.00000,0.0000e+000,20.00000,    -0.21246,0.61554
664.48700, 77.69666,    -1.61007,77.15030,50.00000,0.0000e+000,20.00000,    -0.21261,0.61465
666.29901, 77.87666,    -1.61142,77.11132,50.00000,0.0000e+000,20.00000,    -0.21256,0.61376
668.05902, 78.05666,    -1.60764,77.07252,50.00000,0.0000e+000,20.00000,    -0.21209,0.61290
669.81299, 78.23666,    -1.60825,77.03259,50.00000,0.0000e+000,20.00000,    -0.21105,0.61205
671.59399, 78.41666,    -1.61243,76.99279,50.00000,0.0000e+000,20.00000,    -0.20983,0.61119
673.37701, 78.59666,    -1.61736,76.95432,50.00000,0.0000e+000,20.00000,    -0.20915,0.61033
675.21399, 78.77666,    -1.63019,76.91459,50.00000,0.0000e+000,20.00000,    -0.20854,0.60945
677.05701, 78.95667,    -1.63975,76.87523,50.00000,0.0000e+000,20.00000,    -0.20754,0.60857
678.88599, 79.13667,    -1.64325,76.83657,50.00000,0.0000e+000,20.00000,    -0.20623,0.60770
680.70203, 79.31667,    -1.64549,76.79914,50.00000,0.0000e+000,20.00000,    -0.20460,0.60684
682.51599, 79.49667,    -1.64758,76.76258,50.00000,0.0000e+000,20.00000,    -0.20308,0.60598
684.31000, 79.67667,    -1.64945,76.72577,50.00000,0.0000e+000,20.00000,    -0.20153,0.60513
686.12000, 79.85667,    -1.65325,76.68906,50.00000,0.0000e+000,20.00000,    -0.19946,0.60429
687.91400, 80.03667,    -1.65467,76.65409,50.00000,0.0000e+000,20.00000,    -0.19703,0.60345
689.70300, 80.21667,    -1.65604,76.62043,50.00000,0.0000e+000,20.00000,    -0.19491,0.60262
691.47998, 80.39667,    -1.65745,76.58612,50.00000,0.0000e+000,20.00000,    -0.19290,0.60179
693.26801, 80.57667,    -1.66079,76.55102,50.00000,0.0000e+000,20.00000,    -0.19034,0.60097
695.07098, 80.75667,    -1.66517,76.51643,50.00000,0.0000e+000,20.00000,    -0.18783,0.60014
696.87097, 80.93667,    -1.66971,76.48352,50.00000,0.0000e+000,20.00000,    -0.18527,0.59932
698.65601, 81.11667,    -1.67446,76.45229,50.00000,0.0000e+000,20.00000,    -0.18255,0.59850
700.47699, 81.29667,    -1.67851,76.41930,50.00000,0.0000e+000,20.00000,    -0.17982,0.59768
702.27698, 81.47667,    -1.68133,76.38561,50.00000,0.0000e+000,20.00000,    -0.17678,0.59686
704.07202, 81.65667,    -1.68399,76.35416,50.00000,0.0000e+000,20.00000,    -0.17342,0.59605
705.88098, 81.83667,    -1.68624,76.32349,50.00000,0.0000e+000,20.00000,    -0.17036,0.59524
707.66803, 82.01667,    -1.68746,76.29129,50.00000,0.0000e+000,20.00000,    -0.16746,0.59444
709.45599, 82.19666,    -1.68960,76.25985,50.00000,0.0000e+000,20.00000,    -0.16392,0.59365
711.25403, 82.37666,    -1.69332,76.22967,50.00000,0.0000e+000,20.00000,    -0.15970,0.59285
713.07202, 82.55666,    -1.70324,76.19928,50.00000,0.0000e+000,20.00000,    -0.15541,0.59204
714.92999, 82.73666,    -1.71222,76.16970,50.00000,0.0000e+000,20.00000,    -0.15120,0.59122
716.76398, 82.91666,    -1.71675,76.14167,50.00000,0.0000e+000,20.00000,    -0.14763,0.59042
718.59900, 83.09666,    -1.71886,76.11500,50.00000,0.0000e+000,20.00000,    -0.14382,0.58962
720.39697, 83.27666,    -1.72038,76.08912,50.00000,0.0000e+000,20.00000,    -0.13949,0.58883
722.20801, 83.45667,    -1.72510,76.06449,50.00000,0.0000e+000,20.00000,    -0.13548,0.58805
724.00403, 83.63667,    -1.72922,76.04028,50.00000,0.0000e+000,20.00000,    -0.13165,0.58727
725.78601, 83.81667,    -1.73112,76.01697,50.00000,0.0000e+000,20.00000,    -0.12691,0.58650
727.57098, 83.99667,    -1.73385,75.99543,50.00000,0.0000e+000,20.00000,    -0.12195,0.58574
729.38202, 84.17667,    -1.73924,75.97566,50.00000,0.0000e+000,20.00000,    -0.11782,0.58496
731.18402, 84.35667,    -1.74489,75.95649,50.00000,0.0000e+000,20.00000,    -0.11359,0.58419
732.98700, 84.53667,    -1.74801,75.93844,50.00000,0.0000e+000,20.00000,    -0.10941,0.58343
734.79700, 84.71667,    -1.74906,75.92040,50.00000,0.0000e+000,20.00000,    -0.10514,0.58266
736.60101, 84.89667,    -1.74981,75.90166,50.00000,0.0000e+000,20.00000,    -0.10132,0.58190
738.38098, 85.07667,    -1.75116,75.88353,50.00000,0.0000e+000,20.00000,-9.8010e-002,0.58115
740.18103, 85.25667,    -1.75407,75.86624,50.00000,0.0000e+000,20.00000,-9.5138e-002,0.58040
741.98700, 85.43667,    -1.75643,75.84959,50.00000,0.0000e+000,20.00000,-9.2304e-002,0.57964
743.77698, 85.61667,    -1.75741,75.83447,50.00000,0.0000e+000,20.00000,-8.9572e-002,0.57890
745.56403, 85.79667,    -1.75895,75.82102,50.00000,0.0000e+000,20.00000,-8.6754e-002,0.57815
747.38098, 85.97667,    -1.76368,75.80601,50.00000,0.0000e+000,20.00000,-8.4237e-002,0.57740
749.18799, 86.15667,    -1.76537,75.79097,50.00000,0.0000e+000,20.00000,-8.2241e-002,0.57666
750.97900, 86.33667,    -1.76602,75.77639,50.00000,0.0000e+000,20.00000,-8.0747e-002,0.57592
752.78497, 86.51667,    -1.76846,75.76339,50.00000,0.0000e+000,20.00000,-7.8987e-002,0.57518
754.57599, 86.69666,    -1.76789,75.75081,50.00000,0.0000e+000,20.00000,-7.6659e-002,0.57445
756.39398, 86.87666,    -1.77064,75.73694,50.00000,0.0000e+000,20.00000,-7.4814e-002,0.57371
758.24103, 87.05666,    -1.77971,75.72267,50.00000,0.0000e+000,20.00000,-7.2946e-002,0.57296
760.08899, 87.23666,    -1.78154,75.70868,50.00000,0.0000e+000,20.00000,-7.1025e-002,0.57222
761.90302, 87.41666,    -1.78005,75.69508,50.00000,0.0000e+000,20.00000,-6.9827e-002,0.57148
763.72198, 87.59666,    -1.77934,75.68310,50.00000,0.0000e+000,20.00000,-6.9331e-002,0.57075
765.51300, 87.77666,    -1.77758,75.67249,50.00000,0.0000e+000,20.00000,-6.8424e-002,0.57004
767.31500, 87.95667,    -1.77658,75.66069,50.00000,0.0000e+000,20.00000,-6.7229e-002,0.56932
769.10901, 88.13667,    -1.77616,75.64795,50.00000,0.0000e+000,20.00000,-6.6034e-002,0.56860
770.88397, 88.31667,    -1.77603,75.63612,50.00000,0.0000e+000,20.00000,-6.4961e-002,0.56790
772.66400, 88.49667,    -1.77748,75.62599,50.00000,0.0000e+000,20.00000,-6.4206e-002,0.56719
774.46002, 88.67667,    -1.78086,75.61457,50.00000,0.0000e+000,20.00000,-6.3195e-002,0.56648
776.24402, 88.85667,    -1.78566,75.60372,50.00000,0.0000e+000,20.00000,-6.2287e-002,0.56578
778.04999, 89.03667,    -1.78911,75.59407,50.00000,0.0000e+000,20.00000,-6.1523e-002,0.56507
779.85797, 89.21667,    -1.79138,75.58315,50.00000,0.0000e+000,20.00000,-6.0697e-002,0.56437
781.65802, 89.39667,    -1.79508,75.57153,50.00000,0.0000e+000,20.00000,-6.0069e-002,0.56366
783.46503, 89.57667,    -1.80066,75.55999,50.00000,0.0000e+000,20.00000,-5.9893e-002,0.56296
785.26898, 89.75667,    -1.80538,75.54913,50.00000,0.0000e+000,20.00000,-5.9337e-002,0.56226
787.06299, 89.93667,    -1.80683,75.53875,50.00000,0.0000e+000,20.00000,-5.8576e-002,0.56157
788.86102, 90.11667,    -1.80853,75.52925,50.00000,0.0000e+000,20.00000,-5.8139e-002,0.56087
790.66101, 90.29667,    -1.81440,75.51967,50.00000,0.0000e+000,20.00000,-5.8365e-002,0.56018
792.46399, 90.47667,    -1.82048,75.50971,50.00000,0.0000e+000,20.00000,-5.8232e-002,0.55949
794.28998, 90.65667,    -1.82605,75.49892,50.00000,0.0000e+000,20.00000,-5.8258e-002,0.55879
796.12299, 90.83667,    -1.83096,75.48763,50.00000,0.0000e+000,20.00000,-5.8580e-002,0.55809
797.92603, 91.01667,    -1.83253,75.47685,50.00000,0.0000e+000,20.00000,-5.8978e-002,0.55740
799.71997, 91.19666,    -1.83275,75.46674,50.00000,0.0000e+000,20.00000,-5.8972e-002,0.55672
801.50702, 91.37666,    -1.83555,75.45677,50.00000,0.0000e+000,20.00000,-5.8745e-002,0.55604
803.32501, 91.55666,    -1.84033,75.44715,50.00000,0.0000e+000,20.00000,-5.8658e-002,0.55536
805.15002, 91.73666,    -1.84557,75.43738,50.00000,0.0000e+000,20.00000,-5.8780e-002,0.55467
806.96301, 91.91666,    -1.85015,75.42693,50.00000,0.0000e+000,20.00000,-5.9434e-002,0.55399
808.79199, 92.09666,    -1.85474,75.41594,50.00000,0.0000e+000,20.00000,-6.0129e-002,0.55330
810.58899, 92.27666,    -1.85396,75.40519,50.00000,0.0000e+000,20.00000,-6.0819e-002,0.55263
812.40302, 92.45667,    -1.85814,75.39401,50.00000,0.0000e+000,20.00000,-6.1542e-002,0.55195
814.23297, 92.63667,    -1.86826,75.38320,50.00000,0.0000e+000,20.00000,-6.2594e-002,0.55127
816.11902, 92.81667,    -1.87656,75.37123,50.00000,0.0000e+000,20.00000,-6.3968e-002,0.55057
817.94397, 92.99667,    -1.87693,75.35945,50.00000,0.0000e+000,20.00000,-6.5332e-002,0.54989
819.74103, 93.17667,    -1.87428,75.34865,50.00000,0.0000e+000,20.00000,-6.6352e-002,0.54922
821.52002, 93.35667,    -1.87188,75.33800,50.00000,0.0000e+000,20.00000,-6.7580e-002,0.54857
823.32300, 93.53667,    -1.87465,75.32717,50.00000,0.0000e+000,20.00000,-6.9172e-002,0.54790
825.11798, 93.71667,    -1.87657,75.31532,50.00000,0.0000e+000,20.00000,-7.0890e-002,0.54724
826.92999, 93.89667,    -1.87833,75.30324,50.00000,0.0000e+000,20.00000,-7.2720e-002,0.54658
828.71100, 94.07667,    -1.87974,75.29092,50.00000,0.0000e+000,20.00000,-7.4292e-002,0.54592
830.50500, 94.25667,    -1.88300,75.27785,50.00000,0.0000e+000,20.00000,-7.5554e-002,0.54527
832.30902, 94.43667,    -1.88624,75.26296,50.00000,0.0000e+000,20.00000,-7.7530e-002,0.54461
834.11603, 94.61667,    -1.88947,75.24708,50.00000,0.0000e+000,20.00000,-7.9375e-002,0.54395
835.91998, 94.79667,    -1.89198,75.23168,50.00000,0.0000e+000,20.00000,-8.1117e-002,0.54330
837.69397, 94.97667,    -1.89097,75.21784,50.00000,0.0000e+000,20.00000,-8.3297e-002,0.54265
839.47400, 95.15667,    -1.89238,75.20389,50.00000,0.0000e+000,20.00000,-8.5864e-002,0.54201
841.26099, 95.33667,    -1.89306,75.18851,50.00000,0.0000e+000,20.00000,-8.8658e-002,0.54136
843.03998, 95.51667,    -1.89360,75.17213,50.00000,0.0000e+000,20.00000,-9.1251e-002,0.54072
844.82703, 95.69666,    -1.89841,75.15451,50.00000,0.0000e+000,20.00000,-9.3827e-002,0.54007
846.61200, 95.87666,    -1.90342,75.13769,50.00000,0.0000e+000,20.00000,-9.6308e-002,0.53943
848.42499, 96.05666,    -1.90899,75.12212,50.00000,0.0000e+000,20.00000,-9.8336e-002,0.53878
850.25201, 96.23666,    -1.91489,75.10438,50.00000,0.0000e+000,20.00000,    -0.10052,0.53813
852.04602, 96.41666,    -1.91659,75.08580,50.00000,0.0000e+000,20.00000,    -0.10271,0.53748
853.86298, 96.59666,    -1.91955,75.06752,50.00000,0.0000e+000,20.00000,    -0.10472,0.53683
855.67902, 96.77666,    -1.92147,75.04878,50.00000,0.0000e+000,20.00000,    -0.10678,0.53619
857.48297, 96.95667,    -1.92388,75.02896,50.00000,0.0000e+000,20.00000,    -0.10964,0.53554
859.28699, 97.13667,    -1.92702,75.00803,50.00000,0.0000e+000,20.00000,    -0.11212,0.53490
861.11200, 97.31667,    -1.92999,74.98695,50.00000,0.0000e+000,20.00000,    -0.11424,0.53425
862.90900, 97.49667,    -1.93155,74.96546,50.00000,0.0000e+000,20.00000,    -0.11663,0.53362
864.71997, 97.67667,    -1.93396,74.94399,50.00000,0.0000e+000,20.00000,    -0.11920,0.53297
866.54700, 97.85667,    -1.93909,74.92374,50.00000,0.0000e+000,20.00000,    -0.12167,0.53233
868.35400, 98.03667,    -1.94176,74.90153,50.00000,0.0000e+000,20.00000,    -0.12382,0.53169
870.15997, 98.21667,    -1.94415,74.87780,50.00000,0.0000e+000,20.00000,    -0.12615,0.53105
871.98700, 98.39667,    -1.94774,74.85454,50.00000,0.0000e+000,20.00000,    -0.12807,0.53041
873.79303, 98.57667,    -1.94801,74.83307,50.00000,0.0000e+000,20.00000,    -0.12955,0.52977
875.58398, 98.75667,    -1.94796,74.80922,50.00000,0.0000e+000,20.00000,    -0.13114,0.52914
877.37097, 98.93667,    -1.94810,74.78470,50.00000,0.0000e+000,20.00000,    -0.13301,0.52852
879.16602, 99.11667,    -1.95128,74.76103,50.00000,0.0000e+000,20.00000,    -0.13524,0.52789
880.96600, 99.29667,    -1.95337,74.73506,50.00000,0.0000e+000,20.00000,    -0.13698,0.52725
882.75403, 99.47667,    -1.95653,74.70840,50.00000,0.0000e+000,20.00000,    -0.13841,0.52663
884.56000, 99.65667,    -1.96099,74.68355,50.00000,0.0000e+000,20.00000,    -0.14068,0.52600
886.36902, 99.83667,    -1.95601,74.65873,50.00000,0.0000e+000,20.00000,    -0.14273,0.52537
888.17200,100.01667,    -1.95982,74.63165,50.00000,0.0000e+000,20.00000,    -0.14411,0.52474
889.98999,100.19666,    -1.96244,74.60595,50.00000,0.0000e+000,20.00000,    -0.14574,0.52410
891.80103,100.37666,    -1.96665,74.58192,50.00000,0.0000e+000,20.00000,    -0.14812,0.52347
893.61102,100.55666,    -1.97101,74.55683,50.00000,0.0000e+000,20.00000,    -0.14990,0.52284
895.43597,100.73666,    -1.97509,74.52946,50.00000,0.0000e+000,20.00000,    -0.15108,0.52221
897.25598,100.91666,    -1.97959,74.50036,50.00000,0.0000e+000,20.00000,    -0.15261,0.52157
899.06500,101.09666,    -1.98165,74.47222,50.00000,0.0000e+000,20.00000,    -0.15363,0.52094
900.86499,101.27666,    -1.98288,74.44550,50.00000,0.0000e+000,20.00000,    -0.15435,0.52032
902.67798,101.45667,    -1.98676,74.41718,50.00000,0.0000e+000,20.00000,    -0.15559,0.51969
904.49402,101.63667,    -1.98925,74.38786,50.00000,0.0000e+000,20.00000,    -0.15706,0.51906
906.29700,101.81667,    -1.99176,74.35914,50.00000,0.0000e+000,20.00000,    -0.15786,0.51844
908.10999,101.99667,    -1.99450,74.32985,50.00000,0.0000e+000,20.00000,    -0.15882,0.51781
909.93597,102.17667,    -1.99878,74.29968,50.00000,0.0000e+000,20.00000,    -0.16000,0.51718
911.75800,102.35667,    -2.00301,74.26966,50.00000,0.0000e+000,20.00000,    -0.16118,0.51655
913.57703,102.53667,    -2.00247,74.24059,50.00000,0.0000e+000,20.00000,    -0.16206,0.51592
915.38501,102.71667,    -2.00484,74.21146,50.00000,0.0000e+000,20.00000,    -0.16262,0.51529
917.20203,102.89667,    -2.00643,74.18212,50.00000,0.0000e+000,20.00000,    -0.16356,0.51467
919.00299,103.07667,    -2.00584,74.15275,50.00000,0.0000e+000,20.00000,    -0.16493,0.51405
920.80603,103.25667,    -2.00636,74.12311,50.00000,0.0000e+000,20.00000,    -0.16584,0.51342
922.60101,103.43667,    -2.00542,74.09320,50.00000,0.0000e+000,20.00000,    -0.16629,0.51280
924.38702,103.61667,    -2.00502,74.06340,50.00000,0.0000e+000,20.00000,    -0.16681,0.51219
926.17700,103.79667,    -2.00566,74.03369,50.00000,0.0000e+000,20.00000,    -0.16782,0.51157
927.96997,103.97667,    -2.00516,74.00516,50.00000,0.0000e+000,20.00000,    -0.16903,0.51095
929.77100,104.15667,    -2.00724,73.97625,50.00000,0.0000e+000,20.00000,    -0.16993,0.51033
931.56897,104.33667,    -2.00708,73.94615,50.00000,0.0000e+000,20.00000,    -0.17102,0.50971
933.36700,104.51667,    -2.00572,73.91528,50.00000,0.0000e+000,20.00000,    -0.17235,0.50910
935.17102,104.69666,    -2.00478,73.88348,50.00000,0.0000e+000,20.00000,    -0.17346,0.50847
936.96899,104.87666,    -2.00072,73.85168,50.00000,0.0000e+000,20.00000,    -0.17514,0.50785
938.74298,105.05666,    -1.99645,73.82022,50.00000,0.0000e+000,20.00000,    -0.17742,0.50724
940.51898,105.23666,    -1.99187,73.78928,50.00000,0.0000e+000,20.00000,    -0.17957,0.50663
942.35400,105.41666,    -1.99486,73.75860,50.00000,0.0000e+000,20.00000,    -0.18143,0.50600
944.17902,105.59666,    -1.99537,73.72626,50.00000,0.0000e+000,20.00000,    -0.18370,0.50537
945.99902,105.77666,    -1.99155,73.69178,50.00000,0.0000e+000,20.00000,    -0.18662,0.50475
947.78802,105.95667,    -1.98433,73.65814,50.00000,0.0000e+000,20.00000,    -0.19010,0.50413
949.57001,106.13667,    -1.98189,73.62513,50.00000,0.0000e+000,20.00000,    -0.19336,0.50352
951.38098,106.31667,    -1.98168,73.59112,50.00000,0.0000e+000,20.00000,    -0.19630,0.50289
953.18799,106.49667,    -1.98130,73.55780,50.00000,0.0000e+000,20.00000,    -0.19865,0.50227
954.98901,106.67667,    -1.98137,73.52275,50.00000,0.0000e+000,20.00000,    -0.20139,0.50165
956.79700,106.85667,    -1.98071,73.48507,50.00000,0.0000e+000,20.00000,    -0.20538,0.50103
958.60999,107.03667,    -1.98247,73.44712,50.00000,0.0000e+000,20.00000,    -0.20985,0.50040
960.42499,107.21667,    -1.98284,73.41049,50.00000,0.0000e+000,20.00000,    -0.21396,0.49978
962.23297,107.39667,    -1.98341,73.37271,50.00000,0.0000e+000,20.00000,    -0.21732,0.49915
964.03802,107.57667,    -1.98420,73.33354,50.00000,0.0000e+000,20.00000,    -0.21966,0.49853
965.84601,107.75667,    -1.98566,73.29237,50.00000,0.0000e+000,20.00000,    -0.22179,0.49791
967.67902,107.93667,    -1.98858,73.25049,50.00000,0.0000e+000,20.00000,    -0.22379,0.49728
969.50098,108.11667,    -1.98858,73.20887,50.00000,0.0000e+000,20.00000,    -0.22501,0.49665
971.28198,108.29667,    -1.98728,73.16843,50.00000,0.0000e+000,20.00000,    -0.22562,0.49603
973.07098,108.47667,    -1.98738,73.12719,50.00000,0.0000e+000,20.00000,    -0.22501,0.49541
974.86401,108.65667,    -1.98794,73.08156,50.00000,0.0000e+000,20.00000,    -0.22260,0.49480
976.64600,108.83667,    -1.99016,73.03421,50.00000,0.0000e+000,20.00000,    -0.21863,0.49418
978.50702,109.01667,    -2.00201,72.98815,50.00000,0.0000e+000,20.00000,    -0.21446,0.49354
980.33398,109.19666,    -2.00530,72.94380,50.00000,0.0000e+000,20.00000,    -0.21074,0.49290
982.10303,109.37666,    -2.00103,72.90068,50.00000,0.0000e+000,20.00000,    -0.20940,0.49229
983.87097,109.55666,    -1.99941,72.85886,50.00000,0.0000e+000,20.00000,    -0.20659,0.49168
985.64301,109.73666,    -2.00229,72.81837,50.00000,0.0000e+000,20.00000,    -0.20373,0.49106
987.43500,109.91666,    -2.00799,72.77962,50.00000,0.0000e+000,20.00000,    -0.19475,0.49044
989.22803,110.09666,    -2.01443,72.74351,50.00000,0.0000e+000,20.00000,    -0.18345,0.48982
991.04901,110.27666,    -2.02792,72.71067,50.00000,0.0000e+000,20.00000,    -0.17036,0.48919
992.92297,110.45667,    -2.04204,72.68138,50.00000,0.0000e+000,20.00000,    -0.15378,0.48854
994.74799,110.63667,    -2.04855,72.65712,50.00000,0.0000e+000,20.00000,    -0.13480,0.48790
996.54401,110.81667,    -2.04595,72.63558,50.00000,0.0000e+000,20.00000,    -0.12018,0.48728
998.35901,110.99667,    -2.05229,72.61381,50.00000,0.0000e+000,20.00000,    -0.10329,0.48665