File: book/some_content/DG_ExpDat_OPC7%DC1.csv
#FILE:                       ,OPC7%DC1; 14-1-2025.ngb-ds3
#FORMAT:                     ,NETZSCH5
#IDENTITY:                   ,GEOPOLYMER PASTE
#DECIMAL:                    ,POINT
#SEPARATOR:                  ,COMMA
#MTYPE:                      ,DSC
#INSTRUMENT:                 ,Microlab TU Delft
#PROJECT:                    ,
#DATE/TIME:                  ,17/01/2025 6:09:10 PM
#CORR. FILE:                 ,Blank with cover; 13-1-2025.ngb-bs3
#LABORATORY:                 ,TU Delft Micro Lab
#OPERATOR:                   ,Ahmed
#REMARK:                     ,under Argon atmosphere, 10K/min
#SAMPLE:                     ,OPC7%DC1;17-1-2025
#SAMPLE MASS /mg:            ,43.2
#MATERIAL:                   ,Geopolymer paste
#REFERENCE:                  ,blank
#REFERENCE MASS /mg:         ,0
#TYPE OF CRUCIBLE:           ,DSC/TG pan Al2O3
#SAMPLE CRUCIBLE MASS /mg:   ,0
#REFERENCE CRUCIBLE MASS /mg:,0
#CORR. CODE:                 ,020
#EXO:                        ,-1
#RANGE:                      ,40/10.0(K/min)/1000
#SEGMENT:                    ,S2/2

##Temp./øC,Time/min,DSC/(mW/mg),Mass/%,Gas Flow(purge1)/(ml/min),Gas Flow(purge2)/(ml/min),Gas Flow(protective)/(ml/min),DTG/(%/min),Sensit./(uV/mW)
 46.48600, 18.18500, 3.5234e-003,91.92733,50.00000,0.0000e+000,20.00000,    -0.19783,1.21800
 46.57300, 18.36000, 1.8996e-003,91.89822,50.00000,0.0000e+000,20.00000,    -0.18644,1.21788
 46.69200, 18.53500, 1.3343e-003,91.87111,50.00000,0.0000e+000,20.00000,    -0.17580,1.21772
 46.90000, 18.71000, 1.1170e-003,91.84652,50.00000,0.0000e+000,20.00000,    -0.16547,1.21743
 47.22200, 18.88500, 2.3074e-003,91.82433,50.00000,0.0000e+000,20.00000,    -0.15539,1.21699
 47.60900, 19.06000, 4.5006e-003,91.80341,50.00000,0.0000e+000,20.00000,    -0.14673,1.21645
 48.14400, 19.23500, 7.1908e-003,91.78406,50.00000,0.0000e+000,20.00000,    -0.14069,1.21572
 48.77600, 19.41000, 1.0787e-002,91.76830,50.00000,0.0000e+000,20.00000,    -0.13718,1.21485
 49.51100, 19.58500, 1.5277e-002,91.75439,50.00000,0.0000e+000,20.00000,    -0.13584,1.21383
 50.39500, 19.76000, 2.0419e-002,91.74134,50.00000,0.0000e+000,20.00000,    -0.13737,1.21262
 51.37200, 19.93500, 2.6580e-002,91.72845,50.00000,0.0000e+000,20.00000,    -0.14351,1.21127
 52.50800, 20.11000, 3.3344e-002,91.71452,50.00000,0.0000e+000,20.00000,    -0.15402,1.20971
 53.72700, 20.28500, 4.1285e-002,91.69782,50.00000,0.0000e+000,20.00000,    -0.16795,1.20803
 55.06300, 20.46000, 4.9181e-002,91.67850,50.00000,0.0000e+000,20.00000,    -0.18452,1.20619
 56.53600, 20.63500, 5.7609e-002,91.66001,50.00000,0.0000e+000,20.00000,    -0.20410,1.20416
 58.12300, 20.81000, 6.6750e-002,91.63899,50.00000,0.0000e+000,20.00000,    -0.22774,1.20198
 59.83200, 20.98500, 7.6818e-002,91.61240,50.00000,0.0000e+000,20.00000,    -0.25812,1.19963
 61.60800, 21.16000, 8.7286e-002,91.57829,50.00000,0.0000e+000,20.00000,    -0.29320,1.19719
 63.49900, 21.33500, 9.8756e-002,91.53953,50.00000,0.0000e+000,20.00000,    -0.33076,1.19459
 65.47600, 21.51000,     0.11064,91.49655,50.00000,0.0000e+000,20.00000,    -0.37243,1.19188
 67.55400, 21.68500,     0.12377,91.44382,50.00000,0.0000e+000,20.00000,    -0.41853,1.18903
 69.70800, 21.86000,     0.13788,91.37973,50.00000,0.0000e+000,20.00000,    -0.46978,1.18607
 71.93000, 22.03500,     0.15336,91.30501,50.00000,0.0000e+000,20.00000,    -0.52533,1.18303
 74.24400, 22.21000,     0.16982,91.22181,50.00000,0.0000e+000,20.00000,    -0.58472,1.17986
 76.60300, 22.38500,     0.18799,91.13108,50.00000,0.0000e+000,20.00000,    -0.64980,1.17663
 79.03400, 22.56000,     0.20754,91.03024,50.00000,0.0000e+000,20.00000,    -0.71898,1.17331
 81.52400, 22.73500,     0.22857,90.91013,50.00000,0.0000e+000,20.00000,    -0.79146,1.16991
 84.06200, 22.91000,     0.25115,90.76813,50.00000,0.0000e+000,20.00000,    -0.86602,1.16644
 86.66300, 23.08500,     0.27581,90.62016,50.00000,0.0000e+000,20.00000,    -0.94167,1.16290
 89.31100, 23.26000,     0.30159,90.46106,50.00000,0.0000e+000,20.00000,    -1.01882,1.15929
 91.96400, 23.43500,     0.32889,90.28696,50.00000,0.0000e+000,20.00000,    -1.09463,1.15568
 94.67800, 23.61000,     0.35846,90.09521,50.00000,0.0000e+000,20.00000,    -1.16495,1.15199
 97.41900, 23.78500,     0.38966,89.88416,50.00000,0.0000e+000,20.00000,    -1.22658,1.14827
100.15200, 23.96000,     0.42164,89.65697,50.00000,0.0000e+000,20.00000,    -1.27695,1.14457
102.93200, 24.13500,     0.45534,89.40911,50.00000,0.0000e+000,20.00000,    -1.31561,1.14080
105.70100, 24.31000,     0.48975,89.14343,50.00000,0.0000e+000,20.00000,    -1.34332,1.13706
108.48300, 24.48500,     0.52318,88.86220,50.00000,0.0000e+000,20.00000,    -1.36039,1.13331
111.27400, 24.66000,     0.55644,88.56475,50.00000,0.0000e+000,20.00000,    -1.36557,1.12954
114.04700, 24.83500,     0.58996,88.25530,50.00000,0.0000e+000,20.00000,    -1.36282,1.12581
116.85400, 25.01000,     0.62595,87.93649,50.00000,0.0000e+000,20.00000,    -1.35456,1.12204
119.63500, 25.18500,     0.65762,87.61107,50.00000,0.0000e+000,20.00000,    -1.34031,1.11831
122.40100, 25.36000,     0.67776,87.28988,50.00000,0.0000e+000,20.00000,    -1.32038,1.11461
125.19100, 25.53500,     0.68358,86.98342,50.00000,0.0000e+000,20.00000,    -1.29493,1.11088
127.96200, 25.71000,     0.67136,86.70492,50.00000,0.0000e+000,20.00000,    -1.26307,1.10718
130.72800, 25.88500,     0.64251,86.46046,50.00000,0.0000e+000,20.00000,    -1.22458,1.10350
133.49899, 26.06000,     0.60214,86.25056,50.00000,0.0000e+000,20.00000,    -1.18017,1.09981
136.26199, 26.23500,     0.55680,86.06789,50.00000,0.0000e+000,20.00000,    -1.13046,1.09615
139.03200, 26.41000,     0.51029,85.90685,50.00000,0.0000e+000,20.00000,    -1.07569,1.09248
141.78000, 26.58500,     0.46534,85.76349,50.00000,0.0000e+000,20.00000,    -1.01703,1.08885
144.49300, 26.76000,     0.42315,85.63569,50.00000,0.0000e+000,20.00000,    -0.95632,1.08527
147.20500, 26.93500,     0.38384,85.51724,50.00000,0.0000e+000,20.00000,    -0.89272,1.08170
149.88300, 27.11000,     0.34773,85.40539,50.00000,0.0000e+000,20.00000,    -0.82768,1.07818
152.54201, 27.28500,     0.31493,85.29511,50.00000,0.0000e+000,20.00000,    -0.76403,1.07469
155.17799, 27.46000,     0.28483,85.18784,50.00000,0.0000e+000,20.00000,    -0.70486,1.07125
157.76900, 27.63500,     0.25786,85.08875,50.00000,0.0000e+000,20.00000,    -0.65328,1.06786
160.35800, 27.81000,     0.23358,84.99164,50.00000,0.0000e+000,20.00000,    -0.61082,1.06449
162.88600, 27.98500,     0.21224,84.89741,50.00000,0.0000e+000,20.00000,    -0.57577,1.06121
165.41000, 28.16000,     0.19373,84.80651,50.00000,0.0000e+000,20.00000,    -0.54617,1.05793
167.88699, 28.33500,     0.17804,84.71646,50.00000,0.0000e+000,20.00000,    -0.52057,1.05473
170.32401, 28.51000,     0.16556,84.62474,50.00000,0.0000e+000,20.00000,    -0.49878,1.05158
172.73300, 28.68500,     0.15451,84.53226,50.00000,0.0000e+000,20.00000,    -0.48026,1.04848
175.10500, 28.86000,     0.14268,84.44359,50.00000,0.0000e+000,20.00000,    -0.46406,1.04543
177.45500, 29.03500,     0.12940,84.35957,50.00000,0.0000e+000,20.00000,    -0.44897,1.04242
179.75101, 29.21000,     0.11465,84.28083,50.00000,0.0000e+000,20.00000,    -0.43282,1.03948
182.01199, 29.38500, 9.9208e-002,84.20799,50.00000,0.0000e+000,20.00000,    -0.41742,1.03659
184.24400, 29.56000, 8.3319e-002,84.13757,50.00000,0.0000e+000,20.00000,    -0.40251,1.03375
186.43800, 29.73500, 6.7699e-002,84.07002,50.00000,0.0000e+000,20.00000,    -0.38735,1.03096
188.59100, 29.91000, 5.2695e-002,84.00645,50.00000,0.0000e+000,20.00000,    -0.37275,1.02823
190.73100, 30.08500, 3.8128e-002,83.94714,50.00000,0.0000e+000,20.00000,    -0.35869,1.02552
192.84599, 30.26000, 2.3965e-002,83.89164,50.00000,0.0000e+000,20.00000,    -0.34428,1.02285
194.93500, 30.43500, 1.0646e-002,83.83758,50.00000,0.0000e+000,20.00000,    -0.32860,1.02021
196.97501, 30.61000,-1.9958e-003,83.78288,50.00000,0.0000e+000,20.00000,    -0.31285,1.01765
198.99500, 30.78500,-1.4179e-002,83.72705,50.00000,0.0000e+000,20.00000,    -0.29805,1.01511
200.99200, 30.96000,-2.5603e-002,83.67426,50.00000,0.0000e+000,20.00000,    -0.28428,1.01261
202.96300, 31.13500,-3.6662e-002,83.62619,50.00000,0.0000e+000,20.00000,    -0.27205,1.01015
204.90199, 31.31000,-4.7546e-002,83.58218,50.00000,0.0000e+000,20.00000,    -0.26080,1.00773
206.82100, 31.48500,-5.7356e-002,83.54039,50.00000,0.0000e+000,20.00000,    -0.24987,1.00534
208.70799, 31.66000,-6.6769e-002,83.50127,50.00000,0.0000e+000,20.00000,    -0.23962,1.00300
210.57201, 31.83500,-7.5906e-002,83.46249,50.00000,0.0000e+000,20.00000,    -0.23033,1.00069
212.41100, 32.01000,-8.5242e-002,83.42398,50.00000,0.0000e+000,20.00000,    -0.22248,0.99842
214.22000, 32.18500,-9.4297e-002,83.38722,50.00000,0.0000e+000,20.00000,    -0.21461,0.99618
216.03400, 32.36000,    -0.10432,83.35327,50.00000,0.0000e+000,20.00000,    -0.20628,0.99395
217.82899, 32.53500,    -0.11411,83.32093,50.00000,0.0000e+000,20.00000,    -0.19727,0.99175
219.61900, 32.71000,    -0.12420,83.28946,50.00000,0.0000e+000,20.00000,    -0.18850,0.98955
221.38400, 32.88500,    -0.13413,83.25890,50.00000,0.0000e+000,20.00000,    -0.18122,0.98739
223.14000, 33.06000,    -0.14349,83.22854,50.00000,0.0000e+000,20.00000,    -0.17479,0.98525
224.90900, 33.23500,    -0.15219,83.19898,50.00000,0.0000e+000,20.00000,    -0.16918,0.98309
226.64900, 33.41000,    -0.16107,83.17047,50.00000,0.0000e+000,20.00000,    -0.16388,0.98098
228.39301, 33.58500,    -0.16929,83.14323,50.00000,0.0000e+000,20.00000,    -0.15892,0.97886
230.12700, 33.76000,    -0.17835,83.11513,50.00000,0.0000e+000,20.00000,    -0.15371,0.97676
231.86099, 33.93500,    -0.18747,83.08810,50.00000,0.0000e+000,20.00000,    -0.14870,0.97467
233.61501, 34.11000,    -0.19561,83.06369,50.00000,0.0000e+000,20.00000,    -0.14473,0.97255
235.34399, 34.28500,    -0.20362,83.04061,50.00000,0.0000e+000,20.00000,    -0.14118,0.97047
237.08200, 34.46000,    -0.21124,83.01825,50.00000,0.0000e+000,20.00000,    -0.13784,0.96839
238.80099, 34.63500,    -0.21787,82.99486,50.00000,0.0000e+000,20.00000,    -0.13448,0.96633
240.50999, 34.81000,    -0.22399,82.97218,50.00000,0.0000e+000,20.00000,    -0.13123,0.96429
242.21001, 34.98500,    -0.22914,82.95002,50.00000,0.0000e+000,20.00000,    -0.12804,0.96226
243.90601, 35.16000,    -0.23475,82.92846,50.00000,0.0000e+000,20.00000,    -0.12484,0.96024
245.58501, 35.33500,    -0.24024,82.90796,50.00000,0.0000e+000,20.00000,    -0.12195,0.95825
247.24800, 35.51000,    -0.24627,82.88769,50.00000,0.0000e+000,20.00000,    -0.11931,0.95628
248.92200, 35.68500,    -0.25228,82.86843,50.00000,0.0000e+000,20.00000,    -0.11669,0.95430
250.58099, 35.86000,    -0.25856,82.84818,50.00000,0.0000e+000,20.00000,    -0.11475,0.95234
252.23100, 36.03500,    -0.26470,82.82782,50.00000,0.0000e+000,20.00000,    -0.11332,0.95040
253.89900, 36.21000,    -0.27115,82.80814,50.00000,0.0000e+000,20.00000,    -0.11230,0.94844
255.54500, 36.38500,    -0.27682,82.78895,50.00000,0.0000e+000,20.00000,    -0.11119,0.94652
257.20700, 36.56000,    -0.28373,82.77058,50.00000,0.0000e+000,20.00000,    -0.10978,0.94457
258.84799, 36.73500,    -0.29024,82.75195,50.00000,0.0000e+000,20.00000,    -0.10862,0.94266
260.51099, 36.91000,    -0.29677,82.73424,50.00000,0.0000e+000,20.00000,    -0.10767,0.94073
262.18399, 37.08500,    -0.30335,82.71716,50.00000,0.0000e+000,20.00000,    -0.10719,0.93879
263.84698, 37.26000,    -0.30940,82.69965,50.00000,0.0000e+000,20.00000,    -0.10662,0.93686
265.49100, 37.43500,    -0.31467,82.68143,50.00000,0.0000e+000,20.00000,    -0.10621,0.93496
267.15100, 37.61000,    -0.32009,82.66286,50.00000,0.0000e+000,20.00000,    -0.10585,0.93305
268.80899, 37.78500,    -0.32505,82.64480,50.00000,0.0000e+000,20.00000,    -0.10540,0.93114
270.46701, 37.96000,    -0.33009,82.62599,50.00000,0.0000e+000,20.00000,    -0.10527,0.92924
272.12399, 38.13500,    -0.33497,82.60729,50.00000,0.0000e+000,20.00000,    -0.10498,0.92735
273.77499, 38.31000,    -0.34029,82.58868,50.00000,0.0000e+000,20.00000,    -0.10508,0.92546
275.45300, 38.48500,    -0.34545,82.57086,50.00000,0.0000e+000,20.00000,    -0.10550,0.92355
277.11499, 38.66000,    -0.35066,82.55265,50.00000,0.0000e+000,20.00000,    -0.10632,0.92166
278.78699, 38.83500,    -0.35614,82.53361,50.00000,0.0000e+000,20.00000,    -0.10766,0.91977
280.44901, 39.01000,    -0.36126,82.51496,50.00000,0.0000e+000,20.00000,    -0.10889,0.91789
282.12799, 39.18500,    -0.36594,82.49677,50.00000,0.0000e+000,20.00000,    -0.10977,0.91600
283.80499, 39.36000,    -0.37077,82.47862,50.00000,0.0000e+000,20.00000,    -0.11088,0.91411
285.50400, 39.53500,    -0.37588,82.45999,50.00000,0.0000e+000,20.00000,    -0.11234,0.91221
287.17599, 39.71000,    -0.38055,82.44061,50.00000,0.0000e+000,20.00000,    -0.11357,0.91034
288.88000, 39.88500,    -0.38421,82.42172,50.00000,0.0000e+000,20.00000,    -0.11508,0.90843
290.54700, 40.06000,    -0.38786,82.40317,50.00000,0.0000e+000,20.00000,    -0.11651,0.90658
292.24899, 40.23500,    -0.39210,82.38361,50.00000,0.0000e+000,20.00000,    -0.11795,0.90469
293.93799, 40.41000,    -0.39601,82.36287,50.00000,0.0000e+000,20.00000,    -0.11945,0.90282
295.61899, 40.58500,    -0.40013,82.34111,50.00000,0.0000e+000,20.00000,    -0.12072,0.90096
297.32199, 40.76000,    -0.40368,82.31896,50.00000,0.0000e+000,20.00000,    -0.12210,0.89909
299.00699, 40.93500,    -0.40774,82.29777,50.00000,0.0000e+000,20.00000,    -0.12355,0.89724
300.69101, 41.11000,    -0.41120,82.27609,50.00000,0.0000e+000,20.00000,    -0.12509,0.89539
302.39401, 41.28500,    -0.41548,82.25252,50.00000,0.0000e+000,20.00000,    -0.12695,0.89353
304.07700, 41.46000,    -0.41934,82.22953,50.00000,0.0000e+000,20.00000,    -0.12912,0.89170
305.78500, 41.63500,    -0.42393,82.20588,50.00000,0.0000e+000,20.00000,    -0.13171,0.88984
307.46799, 41.81000,    -0.42778,82.18146,50.00000,0.0000e+000,20.00000,    -0.13469,0.88802
309.18301, 41.98500,    -0.43197,82.15797,50.00000,0.0000e+000,20.00000,    -0.13776,0.88617
310.88599, 42.16000,    -0.43588,82.13458,50.00000,0.0000e+000,20.00000,    -0.14058,0.88433
312.60001, 42.33500,    -0.43963,82.11128,50.00000,0.0000e+000,20.00000,    -0.14314,0.88249
314.31400, 42.51000,    -0.44353,82.08752,50.00000,0.0000e+000,20.00000,    -0.14584,0.88066
316.02200, 42.68500,    -0.44725,82.06363,50.00000,0.0000e+000,20.00000,    -0.14902,0.87883
317.74399, 42.86000,    -0.45082,82.04011,50.00000,0.0000e+000,20.00000,    -0.15232,0.87700
319.44800, 43.03500,    -0.45387,82.01567,50.00000,0.0000e+000,20.00000,    -0.15497,0.87519
321.15701, 43.21000,    -0.45633,81.98956,50.00000,0.0000e+000,20.00000,    -0.15761,0.87338
322.88000, 43.38500,    -0.45927,81.96142,50.00000,0.0000e+000,20.00000,    -0.16052,0.87156
324.58099, 43.56000,    -0.46145,81.93225,50.00000,0.0000e+000,20.00000,    -0.16308,0.86977
326.30499, 43.73500,    -0.46343,81.90241,50.00000,0.0000e+000,20.00000,    -0.16569,0.86796
328.01999, 43.91000,    -0.46545,81.87187,50.00000,0.0000e+000,20.00000,    -0.16834,0.86616
329.74500, 44.08500,    -0.46763,81.84140,50.00000,0.0000e+000,20.00000,    -0.17099,0.86436
331.47000, 44.26000,    -0.47018,81.81004,50.00000,0.0000e+000,20.00000,    -0.17354,0.86257
333.20099, 44.43500,    -0.47268,81.77717,50.00000,0.0000e+000,20.00000,    -0.17568,0.86077
334.91800, 44.61000,    -0.47493,81.74384,50.00000,0.0000e+000,20.00000,    -0.17765,0.85900
336.64899, 44.78500,    -0.47789,81.71099,50.00000,0.0000e+000,20.00000,    -0.17962,0.85721
338.37000, 44.96000,    -0.48066,81.67835,50.00000,0.0000e+000,20.00000,    -0.18091,0.85544
340.07401, 45.13500,    -0.48450,81.64479,50.00000,0.0000e+000,20.00000,    -0.18150,0.85370
341.82199, 45.31000,    -0.48818,81.61108,50.00000,0.0000e+000,20.00000,    -0.18181,0.85191
343.54501, 45.48500,    -0.49293,81.57741,50.00000,0.0000e+000,20.00000,    -0.18189,0.85016
345.27200, 45.66000,    -0.49807,81.54433,50.00000,0.0000e+000,20.00000,    -0.18137,0.84840
347.00800, 45.83500,    -0.50361,81.51122,50.00000,0.0000e+000,20.00000,    -0.18007,0.84665
348.71799, 46.01000,    -0.50928,81.47833,50.00000,0.0000e+000,20.00000,    -0.17809,0.84492
350.44299, 46.18500,    -0.51567,81.44593,50.00000,0.0000e+000,20.00000,    -0.17589,0.84319
352.17599, 46.36000,    -0.52267,81.41488,50.00000,0.0000e+000,20.00000,    -0.17284,0.84145
353.92001, 46.53500,    -0.52942,81.38387,50.00000,0.0000e+000,20.00000,    -0.16948,0.83971
355.64401, 46.71000,    -0.53722,81.35328,50.00000,0.0000e+000,20.00000,    -0.16608,0.83799
357.36899, 46.88500,    -0.54491,81.32375,50.00000,0.0000e+000,20.00000,    -0.16221,0.83628
359.11301, 47.06000,    -0.55315,81.29409,50.00000,0.0000e+000,20.00000,    -0.15822,0.83455
360.83701, 47.23500,    -0.56121,81.26393,50.00000,0.0000e+000,20.00000,    -0.15397,0.83285
362.57501, 47.41000,    -0.56934,81.23498,50.00000,0.0000e+000,20.00000,    -0.14940,0.83114
364.30801, 47.58500,    -0.57749,81.20761,50.00000,0.0000e+000,20.00000,    -0.14456,0.82944
366.04300, 47.76000,    -0.58579,81.18372,50.00000,0.0000e+000,20.00000,    -0.13989,0.82775
367.76599, 47.93500,    -0.59335,81.15959,50.00000,0.0000e+000,20.00000,    -0.13516,0.82607
369.51401, 48.11000,    -0.60122,81.13643,50.00000,0.0000e+000,20.00000,    -0.13052,0.82438
371.24200, 48.28500,    -0.60888,81.11513,50.00000,0.0000e+000,20.00000,    -0.12622,0.82270
372.98499, 48.46000,    -0.61668,81.09466,50.00000,0.0000e+000,20.00000,    -0.12181,0.82102
374.71701, 48.63500,    -0.62406,81.07521,50.00000,0.0000e+000,20.00000,    -0.11766,0.81936
376.44601, 48.81000,    -0.63139,81.05620,50.00000,0.0000e+000,20.00000,    -0.11346,0.81770
378.18399, 48.98500,    -0.63845,81.03737,50.00000,0.0000e+000,20.00000,    -0.10903,0.81605
379.92200, 49.16000,    -0.64523,81.02005,50.00000,0.0000e+000,20.00000,    -0.10473,0.81439
381.65900, 49.33500,    -0.65163,81.00430,50.00000,0.0000e+000,20.00000,    -0.10093,0.81275
383.37299, 49.51000,    -0.65815,80.98868,50.00000,0.0000e+000,20.00000,-9.7967e-002,0.81113
385.10999, 49.68500,    -0.66424,80.97283,50.00000,0.0000e+000,20.00000,-9.5158e-002,0.80949
386.84900, 49.86000,    -0.67043,80.95796,50.00000,0.0000e+000,20.00000,-9.1819e-002,0.80786
388.58301, 50.03500,    -0.67640,80.94310,50.00000,0.0000e+000,20.00000,-8.8920e-002,0.80624
390.30899, 50.21000,    -0.68256,80.92795,50.00000,0.0000e+000,20.00000,-8.6391e-002,0.80463
392.04599, 50.38500,    -0.68877,80.91321,50.00000,0.0000e+000,20.00000,-8.4383e-002,0.80302
393.76300, 50.56000,    -0.69538,80.89879,50.00000,0.0000e+000,20.00000,-8.3029e-002,0.80143
395.50400, 50.73500,    -0.70128,80.88486,50.00000,0.0000e+000,20.00000,-8.0872e-002,0.79983
397.24100, 50.91000,    -0.70693,80.87101,50.00000,0.0000e+000,20.00000,-7.8957e-002,0.79823
398.96600, 51.08500,    -0.71234,80.85691,50.00000,0.0000e+000,20.00000,-7.7724e-002,0.79665
400.70499, 51.26000,    -0.71812,80.84236,50.00000,0.0000e+000,20.00000,-7.6887e-002,0.79507
402.43900, 51.43500,    -0.72362,80.82830,50.00000,0.0000e+000,20.00000,-7.6228e-002,0.79349
404.17999, 51.61000,    -0.72876,80.81592,50.00000,0.0000e+000,20.00000,-7.6030e-002,0.79191
405.91000, 51.78500,    -0.73395,80.80441,50.00000,0.0000e+000,20.00000,-7.6623e-002,0.79035
407.65302, 51.96000,    -0.73904,80.79306,50.00000,0.0000e+000,20.00000,-7.6924e-002,0.78879
409.38501, 52.13500,    -0.74408,80.78116,50.00000,0.0000e+000,20.00000,-7.7166e-002,0.78723
411.10800, 52.31000,    -0.74858,80.76725,50.00000,0.0000e+000,20.00000,-7.7952e-002,0.78570
412.86700, 52.48500,    -0.75390,80.75464,50.00000,0.0000e+000,20.00000,-7.8915e-002,0.78413
414.58499, 52.66000,    -0.75868,80.74402,50.00000,0.0000e+000,20.00000,-7.9783e-002,0.78261
416.32700, 52.83500,    -0.76332,80.73230,50.00000,0.0000e+000,20.00000,-8.0699e-002,0.78107
418.06601, 53.01000,    -0.76756,80.72032,50.00000,0.0000e+000,20.00000,-8.1514e-002,0.77954
419.80399, 53.18500,    -0.77083,80.70723,50.00000,0.0000e+000,20.00000,-8.2411e-002,0.77802
421.52802, 53.36000,    -0.77342,80.69327,50.00000,0.0000e+000,20.00000,-8.3352e-002,0.77651
423.26901, 53.53500,    -0.77634,80.67733,50.00000,0.0000e+000,20.00000,-8.4362e-002,0.77500
425.00299, 53.71000,    -0.77899,80.66045,50.00000,0.0000e+000,20.00000,-8.5102e-002,0.77349
426.74301, 53.88500,    -0.78122,80.64478,50.00000,0.0000e+000,20.00000,-8.5407e-002,0.77199
428.46201, 54.06000,    -0.78361,80.62815,50.00000,0.0000e+000,20.00000,-8.5106e-002,0.77051
430.19501, 54.23500,    -0.78669,80.61022,50.00000,0.0000e+000,20.00000,-8.4361e-002,0.76903
431.92801, 54.41000,    -0.78837,80.59312,50.00000,0.0000e+000,20.00000,-8.4234e-002,0.76755
433.66501, 54.58500,    -0.79035,80.57590,50.00000,0.0000e+000,20.00000,-8.4250e-002,0.76607
435.39301, 54.76000,    -0.79249,80.55868,50.00000,0.0000e+000,20.00000,-8.4307e-002,0.76460
437.08099, 54.93500,    -0.79239,80.54093,50.00000,0.0000e+000,20.00000,-8.3867e-002,0.76318
438.75500, 55.11000,    -0.79434,80.52375,50.00000,0.0000e+000,20.00000,-8.2629e-002,0.76177
440.45801, 55.28500,    -0.79983,80.50781,50.00000,0.0000e+000,20.00000,-8.0553e-002,0.76034
442.16199, 55.46000,    -0.80824,80.49308,50.00000,0.0000e+000,20.00000,-7.8195e-002,0.75892
443.87399, 55.63500,    -0.81806,80.47991,50.00000,0.0000e+000,20.00000,-7.6379e-002,0.75749
445.60901, 55.81000,    -0.82835,80.46767,50.00000,0.0000e+000,20.00000,-7.4694e-002,0.75606
447.35199, 55.98500,    -0.83932,80.45631,50.00000,0.0000e+000,20.00000,-7.2309e-002,0.75462
449.09500, 56.16000,    -0.84966,80.44552,50.00000,0.0000e+000,20.00000,-7.0125e-002,0.75318
450.84100, 56.33500,    -0.85666,80.43484,50.00000,0.0000e+000,20.00000,-6.8056e-002,0.75175
452.56601, 56.51000,    -0.86027,80.42288,50.00000,0.0000e+000,20.00000,-6.6014e-002,0.75034
454.31100, 56.68500,    -0.86428,80.41124,50.00000,0.0000e+000,20.00000,-6.3708e-002,0.74893
456.03299, 56.86000,    -0.86958,80.40131,50.00000,0.0000e+000,20.00000,-6.1116e-002,0.74753
457.79700, 57.03500,    -0.87644,80.39345,50.00000,0.0000e+000,20.00000,-5.9088e-002,0.74611
459.56500, 57.21000,    -0.88530,80.38589,50.00000,0.0000e+000,20.00000,-5.7183e-002,0.74469
461.34000, 57.38500,    -0.89286,80.37678,50.00000,0.0000e+000,20.00000,-5.5534e-002,0.74327
463.11499, 57.56000,    -0.89916,80.36702,50.00000,0.0000e+000,20.00000,-5.4924e-002,0.74185
464.89200, 57.73500,    -0.90500,80.35776,50.00000,0.0000e+000,20.00000,-5.5325e-002,0.74044
466.66000, 57.91000,    -0.90941,80.34860,50.00000,0.0000e+000,20.00000,-5.5910e-002,0.73904
468.42499, 58.08500,    -0.91227,80.33903,50.00000,0.0000e+000,20.00000,-5.6445e-002,0.73765
470.19000, 58.26000,    -0.91396,80.32938,50.00000,0.0000e+000,20.00000,-5.6471e-002,0.73627
471.95200, 58.43500,    -0.91599,80.31983,50.00000,0.0000e+000,20.00000,-5.6098e-002,0.73489
473.69699, 58.61000,    -0.91682,80.31144,50.00000,0.0000e+000,20.00000,-5.6114e-002,0.73354
475.42899, 58.78500,    -0.91691,80.30286,50.00000,0.0000e+000,20.00000,-5.6632e-002,0.73219
477.16599, 58.96000,    -0.91755,80.29396,50.00000,0.0000e+000,20.00000,-5.7752e-002,0.73085
478.87701, 59.13500,    -0.91947,80.28611,50.00000,0.0000e+000,20.00000,-5.8619e-002,0.72954
480.60999, 59.31000,    -0.92296,80.27738,50.00000,0.0000e+000,20.00000,-5.9388e-002,0.72821
482.32901, 59.48500,    -0.92490,80.26502,50.00000,0.0000e+000,20.00000,-6.0492e-002,0.72690
484.04700, 59.66000,    -0.92632,80.25159,50.00000,0.0000e+000,20.00000,-6.2336e-002,0.72559
485.77802, 59.83500,    -0.92960,80.23883,50.00000,0.0000e+000,20.00000,-6.3815e-002,0.72428
487.50101, 60.01000,    -0.93400,80.22683,50.00000,0.0000e+000,20.00000,-6.5125e-002,0.72299
489.24200, 60.18500,    -0.93856,80.21588,50.00000,0.0000e+000,20.00000,-6.6274e-002,0.72168
491.02100, 60.36000,    -0.94441,80.20516,50.00000,0.0000e+000,20.00000,-6.7517e-002,0.72035
492.76401, 60.53500,    -0.94995,80.19448,50.00000,0.0000e+000,20.00000,-6.8910e-002,0.71905
494.51001, 60.71000,    -0.95252,80.18342,50.00000,0.0000e+000,20.00000,-7.0064e-002,0.71776
496.25400, 60.88500,    -0.95361,80.17195,50.00000,0.0000e+000,20.00000,-7.2038e-002,0.71647
498.00000, 61.06000,    -0.95666,80.15982,50.00000,0.0000e+000,20.00000,-7.4305e-002,0.71519
499.76501, 61.23500,    -0.96121,80.14706,50.00000,0.0000e+000,20.00000,-7.5699e-002,0.71389
501.51801, 61.41000,    -0.96482,80.13189,50.00000,0.0000e+000,20.00000,-7.6615e-002,0.71262
503.27802, 61.58500,    -0.96740,80.11650,50.00000,0.0000e+000,20.00000,-7.7449e-002,0.71134
505.02200, 61.76000,    -0.97041,80.10196,50.00000,0.0000e+000,20.00000,-7.8541e-002,0.71008
506.77802, 61.93500,    -0.97157,80.08784,50.00000,0.0000e+000,20.00000,-7.9644e-002,0.70881
508.50201, 62.11000,    -0.97217,80.07420,50.00000,0.0000e+000,20.00000,-8.0765e-002,0.70758
510.24500, 62.28500,    -0.97255,80.06077,50.00000,0.0000e+000,20.00000,-8.2507e-002,0.70633
511.97198, 62.46000,    -0.97400,80.04776,50.00000,0.0000e+000,20.00000,-8.4495e-002,0.70510
513.69800, 62.63500,    -0.97669,80.03330,50.00000,0.0000e+000,20.00000,-8.6401e-002,0.70388
515.44598, 62.81000,    -0.97916,80.01716,50.00000,0.0000e+000,20.00000,-8.8187e-002,0.70265
517.17999, 62.98500,    -0.98255,80.00123,50.00000,0.0000e+000,20.00000,-8.9921e-002,0.70143
518.91498, 63.16000,    -0.98526,79.98488,50.00000,0.0000e+000,20.00000,-9.1531e-002,0.70022
520.65100, 63.33500,    -0.98785,79.96841,50.00000,0.0000e+000,20.00000,-9.2692e-002,0.69901
522.40997, 63.51000,    -0.99066,79.95226,50.00000,0.0000e+000,20.00000,-9.4138e-002,0.69779
524.13599, 63.68500,    -0.99302,79.93604,50.00000,0.0000e+000,20.00000,-9.6025e-002,0.69660
525.88098, 63.86000,    -0.99534,79.92157,50.00000,0.0000e+000,20.00000,-9.8142e-002,0.69539
527.62299, 64.03500,    -0.99764,79.90540,50.00000,0.0000e+000,20.00000,    -0.10023,0.69420
529.35101, 64.21000,    -1.00002,79.88763,50.00000,0.0000e+000,20.00000,    -0.10239,0.69302
531.10400, 64.38500,    -1.00363,79.86940,50.00000,0.0000e+000,20.00000,    -0.10466,0.69183
532.87201, 64.56000,    -1.00708,79.85106,50.00000,0.0000e+000,20.00000,    -0.10640,0.69064
534.60602, 64.73500,    -1.01017,79.83264,50.00000,0.0000e+000,20.00000,    -0.10811,0.68947
536.35901, 64.91000,    -1.01215,79.81326,50.00000,0.0000e+000,20.00000,    -0.11005,0.68829
538.11902, 65.08500,    -1.01479,79.79316,50.00000,0.0000e+000,20.00000,    -0.11186,0.68712
539.86102, 65.26000,    -1.01678,79.77327,50.00000,0.0000e+000,20.00000,    -0.11350,0.68596
541.59900, 65.43500,    -1.01880,79.75260,50.00000,0.0000e+000,20.00000,    -0.11492,0.68481
543.34100, 65.61000,    -1.02116,79.73100,50.00000,0.0000e+000,20.00000,    -0.11682,0.68366
545.07599, 65.78500,    -1.02328,79.70964,50.00000,0.0000e+000,20.00000,    -0.11910,0.68252
546.82703, 65.96000,    -1.02601,79.68869,50.00000,0.0000e+000,20.00000,    -0.12106,0.68138
548.56598, 66.13500,    -1.02849,79.66717,50.00000,0.0000e+000,20.00000,    -0.12266,0.68024
550.31598, 66.31000,    -1.03130,79.64525,50.00000,0.0000e+000,20.00000,    -0.12427,0.67911
552.06201, 66.48500,    -1.03395,79.62309,50.00000,0.0000e+000,20.00000,    -0.12604,0.67798
553.81799, 66.66000,    -1.03696,79.60033,50.00000,0.0000e+000,20.00000,    -0.12766,0.67685
555.56799, 66.83500,    -1.03988,79.57697,50.00000,0.0000e+000,20.00000,    -0.12902,0.67573
557.31702, 67.01000,    -1.04254,79.55432,50.00000,0.0000e+000,20.00000,    -0.13067,0.67462
559.08099, 67.18500,    -1.04676,79.53262,50.00000,0.0000e+000,20.00000,    -0.13257,0.67350
560.84003, 67.36000,    -1.04952,79.51084,50.00000,0.0000e+000,20.00000,    -0.13425,0.67239
562.60999, 67.53500,    -1.05407,79.48812,50.00000,0.0000e+000,20.00000,    -0.13565,0.67128
564.39899, 67.71000,    -1.05773,79.46396,50.00000,0.0000e+000,20.00000,    -0.13661,0.67016
566.15601, 67.88500,    -1.05938,79.43969,50.00000,0.0000e+000,20.00000,    -0.13720,0.66906
567.87701, 68.06000,    -1.05891,79.41585,50.00000,0.0000e+000,20.00000,    -0.13802,0.66799
569.61102, 68.23500,    -1.05635,79.39115,50.00000,0.0000e+000,20.00000,    -0.13895,0.66692
571.37402, 68.41000,    -1.05762,79.36636,50.00000,0.0000e+000,20.00000,    -0.13973,0.66583
573.14502, 68.58500,    -1.06262,79.34159,50.00000,0.0000e+000,20.00000,    -0.14036,0.66475
574.89899, 68.76000,    -1.06784,79.31614,50.00000,0.0000e+000,20.00000,    -0.14170,0.66368
576.63300, 68.93500,    -1.06829,79.28951,50.00000,0.0000e+000,20.00000,    -0.14334,0.66262
578.34100, 69.11000,    -1.06694,79.26205,50.00000,0.0000e+000,20.00000,    -0.14446,0.66159
580.06097, 69.28500,    -1.06722,79.23486,50.00000,0.0000e+000,20.00000,    -0.14560,0.66055
581.80402, 69.46000,    -1.07261,79.20919,50.00000,0.0000e+000,20.00000,    -0.14699,0.65951
583.56702, 69.63500,    -1.07891,79.18581,50.00000,0.0000e+000,20.00000,    -0.14813,0.65846
585.34601, 69.81000,    -1.08414,79.16158,50.00000,0.0000e+000,20.00000,    -0.14928,0.65740
587.08301, 69.98500,    -1.08738,79.13646,50.00000,0.0000e+000,20.00000,    -0.15060,0.65637
588.84003, 70.16000,    -1.08982,79.11079,50.00000,0.0000e+000,20.00000,    -0.15181,0.65533
590.61200, 70.33500,    -1.09353,79.08597,50.00000,0.0000e+000,20.00000,    -0.15285,0.65429
592.38000, 70.51000,    -1.09753,79.05883,50.00000,0.0000e+000,20.00000,    -0.15408,0.65326
594.09698, 70.68500,    -1.09631,79.03048,50.00000,0.0000e+000,20.00000,    -0.15517,0.65226
595.83801, 70.86000,    -1.09652,79.00368,50.00000,0.0000e+000,20.00000,    -0.15621,0.65125
597.57397, 71.03500,    -1.09884,78.97825,50.00000,0.0000e+000,20.00000,    -0.15742,0.65025
599.32703, 71.21000,    -1.10302,78.95036,50.00000,0.0000e+000,20.00000,    -0.15873,0.64924
601.09003, 71.38500,    -1.10721,78.92144,50.00000,0.0000e+000,20.00000,    -0.16081,0.64823
602.86298, 71.56000,    -1.11107,78.89340,50.00000,0.0000e+000,20.00000,    -0.16342,0.64722
604.61798, 71.73500,    -1.11481,78.86471,50.00000,0.0000e+000,20.00000,    -0.16568,0.64622
606.38098, 71.91000,    -1.11751,78.83529,50.00000,0.0000e+000,20.00000,    -0.16792,0.64523
608.13501, 72.08500,    -1.11826,78.80662,50.00000,0.0000e+000,20.00000,    -0.17015,0.64424
609.89099, 72.26000,    -1.11910,78.77757,50.00000,0.0000e+000,20.00000,    -0.17227,0.64326
611.65601, 72.43500,    -1.12095,78.74771,50.00000,0.0000e+000,20.00000,    -0.17386,0.64227
613.41498, 72.61000,    -1.12222,78.71716,50.00000,0.0000e+000,20.00000,    -0.17564,0.64129
615.17798, 72.78500,    -1.12437,78.68553,50.00000,0.0000e+000,20.00000,    -0.17837,0.64032
616.93402, 72.96000,    -1.12507,78.65395,50.00000,0.0000e+000,20.00000,    -0.18103,0.63935
618.68799, 73.13500,    -1.12544,78.62252,50.00000,0.0000e+000,20.00000,    -0.18321,0.63839
620.42603, 73.31000,    -1.12725,78.58994,50.00000,0.0000e+000,20.00000,    -0.18570,0.63744
622.17603, 73.48500,    -1.12811,78.55678,50.00000,0.0000e+000,20.00000,    -0.18780,0.63649
623.93500, 73.66000,    -1.12999,78.52334,50.00000,0.0000e+000,20.00000,    -0.18934,0.63554
625.68799, 73.83500,    -1.13268,78.48977,50.00000,0.0000e+000,20.00000,    -0.19173,0.63459
627.44800, 74.01000,    -1.13512,78.45650,50.00000,0.0000e+000,20.00000,    -0.19478,0.63365
629.20599, 74.18500,    -1.13714,78.42267,50.00000,0.0000e+000,20.00000,    -0.19754,0.63271
630.96899, 74.36000,    -1.13751,78.38845,50.00000,0.0000e+000,20.00000,    -0.20056,0.63177
632.70801, 74.53500,    -1.13683,78.35367,50.00000,0.0000e+000,20.00000,    -0.20399,0.63085
634.45001, 74.71000,    -1.13756,78.31748,50.00000,0.0000e+000,20.00000,    -0.20711,0.62993
636.20801, 74.88500,    -1.13794,78.28094,50.00000,0.0000e+000,20.00000,    -0.20950,0.62900
637.95300, 75.06000,    -1.13794,78.24367,50.00000,0.0000e+000,20.00000,    -0.21176,0.62809
639.69800, 75.23500,    -1.13990,78.20666,50.00000,0.0000e+000,20.00000,    -0.21412,0.62718
641.45300, 75.41000,    -1.14203,78.17199,50.00000,0.0000e+000,20.00000,    -0.21667,0.62627
643.21100, 75.58500,    -1.14330,78.13555,50.00000,0.0000e+000,20.00000,    -0.21887,0.62536
644.94501, 75.76000,    -1.14465,78.09636,50.00000,0.0000e+000,20.00000,    -0.22083,0.62447
646.69202, 75.93500,    -1.14528,78.05657,50.00000,0.0000e+000,20.00000,    -0.22280,0.62357
648.44897, 76.11000,    -1.14500,78.01633,50.00000,0.0000e+000,20.00000,    -0.22474,0.62267
650.22803, 76.28500,    -1.14891,77.97366,50.00000,0.0000e+000,20.00000,    -0.22645,0.62177
651.99902, 76.46000,    -1.15213,77.92961,50.00000,0.0000e+000,20.00000,    -0.22794,0.62087
653.74799, 76.63500,    -1.15317,77.88829,50.00000,0.0000e+000,20.00000,    -0.22903,0.61999
655.52002, 76.81000,    -1.15349,77.84859,50.00000,0.0000e+000,20.00000,    -0.23028,0.61910
657.25598, 76.98500,    -1.15217,77.80752,50.00000,0.0000e+000,20.00000,    -0.23147,0.61823
658.99402, 77.16000,    -1.15172,77.76510,50.00000,0.0000e+000,20.00000,    -0.23305,0.61737
660.73798, 77.33500,    -1.15208,77.72293,50.00000,0.0000e+000,20.00000,    -0.23410,0.61650
662.49402, 77.51000,    -1.15264,77.68195,50.00000,0.0000e+000,20.00000,    -0.23322,0.61563
664.25500, 77.68500,    -1.15479,77.64157,50.00000,0.0000e+000,20.00000,    -0.23215,0.61477
666.00403, 77.86000,    -1.15718,77.60036,50.00000,0.0000e+000,20.00000,    -0.23209,0.61391
667.77301, 78.03500,    -1.15788,77.55956,50.00000,0.0000e+000,20.00000,    -0.23204,0.61304
669.52399, 78.21000,    -1.15840,77.51865,50.00000,0.0000e+000,20.00000,    -0.23156,0.61219
671.26599, 78.38500,    -1.15751,77.47794,50.00000,0.0000e+000,20.00000,    -0.23124,0.61135
673.00000, 78.56000,    -1.15661,77.43716,50.00000,0.0000e+000,20.00000,    -0.23106,0.61051
674.77002, 78.73500,    -1.15808,77.39520,50.00000,0.0000e+000,20.00000,    -0.23077,0.60966
676.51501, 78.91000,    -1.16022,77.35369,50.00000,0.0000e+000,20.00000,    -0.23012,0.60883
678.27698, 79.08500,    -1.16299,77.31311,50.00000,0.0000e+000,20.00000,    -0.22909,0.60799
680.02899, 79.26000,    -1.16441,77.27679,50.00000,0.0000e+000,20.00000,    -0.22832,0.60715
681.77802, 79.43500,    -1.16535,77.24196,50.00000,0.0000e+000,20.00000,    -0.22811,0.60633
683.52399, 79.61000,    -1.16527,77.20397,50.00000,0.0000e+000,20.00000,    -0.22759,0.60550
685.28699, 79.78500,    -1.16646,77.16314,50.00000,0.0000e+000,20.00000,    -0.22698,0.60468
687.04498, 79.96000,    -1.16644,77.12144,50.00000,0.0000e+000,20.00000,    -0.22642,0.60385
688.79901, 80.13500,    -1.16612,77.07912,50.00000,0.0000e+000,20.00000,    -0.22578,0.60304
690.54401, 80.31000,    -1.16540,77.03891,50.00000,0.0000e+000,20.00000,    -0.22533,0.60223
692.29700, 80.48500,    -1.16471,76.99999,50.00000,0.0000e+000,20.00000,    -0.22425,0.60142
694.06201, 80.66000,    -1.16663,76.96031,50.00000,0.0000e+000,20.00000,    -0.22272,0.60060
695.83197, 80.83500,    -1.16821,76.92123,50.00000,0.0000e+000,20.00000,    -0.22107,0.59979
697.56598, 81.01000,    -1.16705,76.88273,50.00000,0.0000e+000,20.00000,    -0.21941,0.59900
699.31500, 81.18500,    -1.16544,76.84329,50.00000,0.0000e+000,20.00000,    -0.21817,0.59820
701.06097, 81.36000,    -1.16314,76.80403,50.00000,0.0000e+000,20.00000,    -0.21641,0.59741
702.79999, 81.53500,    -1.16180,76.76514,50.00000,0.0000e+000,20.00000,    -0.21276,0.59663
704.55499, 81.71000,    -1.16263,76.72632,50.00000,0.0000e+000,20.00000,    -0.20810,0.59584
706.33301, 81.88500,    -1.16449,76.68781,50.00000,0.0000e+000,20.00000,    -0.20310,0.59504
708.09198, 82.06000,    -1.16725,76.64898,50.00000,0.0000e+000,20.00000,    -0.19808,0.59425
709.86102, 82.23500,    -1.16903,76.61057,50.00000,0.0000e+000,20.00000,    -0.19351,0.59347
711.64502, 82.41000,    -1.17235,76.57398,50.00000,0.0000e+000,20.00000,    -0.18847,0.59267
713.39301, 82.58500,    -1.17329,76.53806,50.00000,0.0000e+000,20.00000,    -0.18300,0.59190
715.13202, 82.76000,    -1.17307,76.50433,50.00000,0.0000e+000,20.00000,    -0.17722,0.59114
716.88501, 82.93500,    -1.17379,76.47352,50.00000,0.0000e+000,20.00000,    -0.17140,0.59037
718.62201, 83.11000,    -1.17477,76.44334,50.00000,0.0000e+000,20.00000,    -0.16564,0.58961
720.35602, 83.28500,    -1.17903,76.41500,50.00000,0.0000e+000,20.00000,    -0.15980,0.58885
722.09100, 83.46000,    -1.18421,76.39017,50.00000,0.0000e+000,20.00000,    -0.15380,0.58810
723.83801, 83.63500,    -1.18925,76.36594,50.00000,0.0000e+000,20.00000,    -0.14772,0.58734
725.62500, 83.81000,    -1.19819,76.34250,50.00000,0.0000e+000,20.00000,    -0.14134,0.58657
727.39203, 83.98500,    -1.20288,76.31981,50.00000,0.0000e+000,20.00000,    -0.13463,0.58581
729.13898, 84.16000,    -1.20242,76.29811,50.00000,0.0000e+000,20.00000,    -0.12854,0.58506
730.89001, 84.33500,    -1.20236,76.27798,50.00000,0.0000e+000,20.00000,    -0.12277,0.58432
732.68799, 84.51000,    -1.20529,76.25962,50.00000,0.0000e+000,20.00000,    -0.11739,0.58355
734.47998, 84.68500,    -1.20677,76.24244,50.00000,0.0000e+000,20.00000,    -0.11236,0.58279
736.27399, 84.86000,    -1.20807,76.22406,50.00000,0.0000e+000,20.00000,    -0.10765,0.58204
738.04901, 85.03500,    -1.20625,76.20599,50.00000,0.0000e+000,20.00000,    -0.10347,0.58129
739.79602, 85.21000,    -1.20056,76.18874,50.00000,0.0000e+000,20.00000,    -0.10017,0.58056
741.51898, 85.38500,    -1.19313,76.17221,50.00000,0.0000e+000,20.00000,-9.7302e-002,0.57984
743.23401, 85.56000,    -1.18863,76.15614,50.00000,0.0000e+000,20.00000,-9.4655e-002,0.57912
744.96997, 85.73500,    -1.18678,76.14176,50.00000,0.0000e+000,20.00000,-9.1875e-002,0.57840
746.71997, 85.91000,    -1.18497,76.12691,50.00000,0.0000e+000,20.00000,-8.8881e-002,0.57768
748.45398, 86.08500,    -1.18270,76.11183,50.00000,0.0000e+000,20.00000,-8.6609e-002,0.57696
750.20099, 86.26000,    -1.17937,76.09657,50.00000,0.0000e+000,20.00000,-8.4877e-002,0.57624
751.93103, 86.43500,    -1.17545,76.08187,50.00000,0.0000e+000,20.00000,-8.3641e-002,0.57553
753.68597, 86.61000,    -1.17258,76.06925,50.00000,0.0000e+000,20.00000,-8.1465e-002,0.57481
755.42999, 86.78500,    -1.17127,76.05528,50.00000,0.0000e+000,20.00000,-7.9102e-002,0.57410
757.19702, 86.96000,    -1.17086,76.04096,50.00000,0.0000e+000,20.00000,-7.7186e-002,0.57339
758.94202, 87.13500,    -1.16949,76.02714,50.00000,0.0000e+000,20.00000,-7.4930e-002,0.57268
760.65503, 87.31000,    -1.16436,76.01312,50.00000,0.0000e+000,20.00000,-7.2903e-002,0.57199
762.34998, 87.48500,    -1.15741,75.99928,50.00000,0.0000e+000,20.00000,-7.1476e-002,0.57130
764.07501, 87.66000,    -1.15281,75.98780,50.00000,0.0000e+000,20.00000,-7.0242e-002,0.57061
765.83698, 87.83500,    -1.15458,75.97576,50.00000,0.0000e+000,20.00000,-6.9074e-002,0.56991
767.64001, 88.01000,    -1.16171,75.96305,50.00000,0.0000e+000,20.00000,-6.8165e-002,0.56919
769.45398, 88.18500,    -1.16580,75.94989,50.00000,0.0000e+000,20.00000,-6.6679e-002,0.56846
771.27399, 88.36000,    -1.16871,75.93858,50.00000,0.0000e+000,20.00000,-6.5258e-002,0.56774
773.04498, 88.53500,    -1.16657,75.92931,50.00000,0.0000e+000,20.00000,-6.4350e-002,0.56704
774.81403, 88.71000,    -1.16340,75.91874,50.00000,0.0000e+000,20.00000,-6.3365e-002,0.56634
776.57397, 88.88500,    -1.16235,75.90917,50.00000,0.0000e+000,20.00000,-6.2284e-002,0.56565
778.33398, 89.06000,    -1.16084,75.90084,50.00000,0.0000e+000,20.00000,-6.1238e-002,0.56496
780.09497, 89.23500,    -1.15975,75.89117,50.00000,0.0000e+000,20.00000,-5.9989e-002,0.56427
781.83002, 89.41000,    -1.15716,75.88124,50.00000,0.0000e+000,20.00000,-5.9000e-002,0.56360
783.55402, 89.58500,    -1.15355,75.87107,50.00000,0.0000e+000,20.00000,-5.8168e-002,0.56293
785.28400, 89.76000,    -1.15483,75.85939,50.00000,0.0000e+000,20.00000,-5.6910e-002,0.56225
787.02002, 89.93500,    -1.15445,75.84837,50.00000,0.0000e+000,20.00000,-5.5637e-002,0.56158
788.75897, 90.11000,    -1.15681,75.83995,50.00000,0.0000e+000,20.00000,-5.4703e-002,0.56091
790.49200, 90.28500,    -1.15945,75.83108,50.00000,0.0000e+000,20.00000,-5.4463e-002,0.56024
792.24799, 90.46000,    -1.16413,75.82036,50.00000,0.0000e+000,20.00000,-5.4331e-002,0.55957
794.01001, 90.63500,    -1.16724,75.81000,50.00000,0.0000e+000,20.00000,-5.3954e-002,0.55890
795.80298, 90.81000,    -1.17510,75.79997,50.00000,0.0000e+000,20.00000,-5.3939e-002,0.55821
797.59497, 90.98500,    -1.18259,75.79017,50.00000,0.0000e+000,20.00000,-5.4327e-002,0.55753
799.35699, 91.16000,    -1.18302,75.78084,50.00000,0.0000e+000,20.00000,-5.4865e-002,0.55686
801.12299, 91.33500,    -1.18585,75.77237,50.00000,0.0000e+000,20.00000,-5.5159e-002,0.55619
802.89801, 91.51000,    -1.18769,75.76417,50.00000,0.0000e+000,20.00000,-5.4863e-002,0.55552
804.66998, 91.68500,    -1.18842,75.75622,50.00000,0.0000e+000,20.00000,-5.4115e-002,0.55485
806.40698, 91.86000,    -1.18846,75.74726,50.00000,0.0000e+000,20.00000,-5.4207e-002,0.55419
808.15002, 92.03500,    -1.18728,75.73830,50.00000,0.0000e+000,20.00000,-5.4870e-002,0.55354
809.89203, 92.21000,    -1.18743,75.72926,50.00000,0.0000e+000,20.00000,-5.5030e-002,0.55289
811.59698, 92.38500,    -1.18490,75.71971,50.00000,0.0000e+000,20.00000,-5.4713e-002,0.55225
813.31799, 92.56000,    -1.18276,75.71131,50.00000,0.0000e+000,20.00000,-5.4587e-002,0.55161
815.05603, 92.73500,    -1.18380,75.70201,50.00000,0.0000e+000,20.00000,-5.4977e-002,0.55096
816.81097, 92.91000,    -1.18574,75.69029,50.00000,0.0000e+000,20.00000,-5.5903e-002,0.55031
818.56000, 93.08500,    -1.18827,75.67886,50.00000,0.0000e+000,20.00000,-5.6894e-002,0.54966
820.32800, 93.26000,    -1.19194,75.66840,50.00000,0.0000e+000,20.00000,-5.7718e-002,0.54901
822.08600, 93.43500,    -1.19483,75.65913,50.00000,0.0000e+000,20.00000,-5.8993e-002,0.54836
823.84100, 93.61000,    -1.19475,75.64989,50.00000,0.0000e+000,20.00000,-6.0091e-002,0.54771
825.60498, 93.78500,    -1.19682,75.63942,50.00000,0.0000e+000,20.00000,-6.1264e-002,0.54706
827.35901, 93.96000,    -1.19713,75.62881,50.00000,0.0000e+000,20.00000,-6.2786e-002,0.54642
829.19702, 94.13500,    -1.20472,75.61850,50.00000,0.0000e+000,20.00000,-6.3769e-002,0.54575
831.02100, 94.31000,    -1.21238,75.60939,50.00000,0.0000e+000,20.00000,-6.5275e-002,0.54508
832.80902, 94.48500,    -1.21211,75.59875,50.00000,0.0000e+000,20.00000,-6.7250e-002,0.54443
834.55701, 94.66000,    -1.20928,75.58644,50.00000,0.0000e+000,20.00000,-6.8207e-002,0.54379
836.27802, 94.83500,    -1.20365,75.57336,50.00000,0.0000e+000,20.00000,-6.9082e-002,0.54317
837.99200, 95.01000,    -1.19809,75.56189,50.00000,0.0000e+000,20.00000,-7.0465e-002,0.54254
839.71698, 95.18500,    -1.19527,75.54987,50.00000,0.0000e+000,20.00000,-7.2446e-002,0.54192
841.44702, 95.36000,    -1.19411,75.53722,50.00000,0.0000e+000,20.00000,-7.4864e-002,0.54129
843.24500, 95.53500,    -1.20050,75.52442,50.00000,0.0000e+000,20.00000,-7.7110e-002,0.54064
845.06702, 95.71000,    -1.21122,75.51020,50.00000,0.0000e+000,20.00000,-7.9193e-002,0.53999
846.85797, 95.88500,    -1.21594,75.49649,50.00000,0.0000e+000,20.00000,-8.1096e-002,0.53934
848.61700, 96.06000,    -1.21425,75.48310,50.00000,0.0000e+000,20.00000,-8.3045e-002,0.53871
850.35199, 96.23500,    -1.21073,75.46748,50.00000,0.0000e+000,20.00000,-8.5302e-002,0.53809
852.10797, 96.41000,    -1.21205,75.45262,50.00000,0.0000e+000,20.00000,-8.7218e-002,0.53746
853.84601, 96.58500,    -1.21105,75.43809,50.00000,0.0000e+000,20.00000,-8.8454e-002,0.53684
855.60101, 96.76000,    -1.21092,75.42253,50.00000,0.0000e+000,20.00000,-8.9714e-002,0.53621
857.39600, 96.93500,    -1.21701,75.40602,50.00000,0.0000e+000,20.00000,-9.1872e-002,0.53558
859.18500, 97.11000,    -1.22199,75.38844,50.00000,0.0000e+000,20.00000,-9.3807e-002,0.53494
860.94299, 97.28500,    -1.22223,75.37037,50.00000,0.0000e+000,20.00000,-9.5726e-002,0.53431
862.68103, 97.46000,    -1.21964,75.35215,50.00000,0.0000e+000,20.00000,-9.7959e-002,0.53370
864.40698, 97.63500,    -1.21869,75.33408,50.00000,0.0000e+000,20.00000,    -0.10018,0.53309
866.14203, 97.81000,    -1.21857,75.31732,50.00000,0.0000e+000,20.00000,    -0.10240,0.53247
867.84100, 97.98500,    -1.21675,75.30010,50.00000,0.0000e+000,20.00000,    -0.10405,0.53187
869.58600, 98.16000,    -1.21940,75.28150,50.00000,0.0000e+000,20.00000,    -0.10607,0.53126
871.33197, 98.33500,    -1.22291,75.26334,50.00000,0.0000e+000,20.00000,    -0.10827,0.53064
873.08600, 98.51000,    -1.22480,75.24649,50.00000,0.0000e+000,20.00000,    -0.11004,0.53002
874.79303, 98.68500,    -1.22449,75.22850,50.00000,0.0000e+000,20.00000,    -0.11144,0.52942
876.54797, 98.86000,    -1.22632,75.20843,50.00000,0.0000e+000,20.00000,    -0.11251,0.52880
878.28198, 99.03500,    -1.22960,75.18927,50.00000,0.0000e+000,20.00000,    -0.11390,0.52820
880.04797, 99.21000,    -1.23252,75.16841,50.00000,0.0000e+000,20.00000,    -0.11570,0.52758
881.81000, 99.38500,    -1.23644,75.14607,50.00000,0.0000e+000,20.00000,    -0.11748,0.52696
883.55402, 99.56000,    -1.23844,75.12415,50.00000,0.0000e+000,20.00000,    -0.11947,0.52635
885.30402, 99.73500,    -1.23817,75.10366,50.00000,0.0000e+000,20.00000,    -0.12139,0.52574
887.04401, 99.91000,    -1.23893,75.08159,50.00000,0.0000e+000,20.00000,    -0.12290,0.52513
888.77197,100.08500,    -1.23952,75.05868,50.00000,0.0000e+000,20.00000,    -0.12442,0.52453
890.52899,100.26000,    -1.23925,75.03686,50.00000,0.0000e+000,20.00000,    -0.12662,0.52391
892.28198,100.43500,    -1.24073,75.01544,50.00000,0.0000e+000,20.00000,    -0.12944,0.52330
894.05902,100.61000,    -1.24496,74.99452,50.00000,0.0000e+000,20.00000,    -0.13164,0.52268
895.84497,100.78500,    -1.25047,74.97262,50.00000,0.0000e+000,20.00000,    -0.13358,0.52206
897.63501,100.96000,    -1.25504,74.94839,50.00000,0.0000e+000,20.00000,    -0.13557,0.52144
899.40302,101.13500,    -1.25558,74.92351,50.00000,0.0000e+000,20.00000,    -0.13710,0.52083
901.15900,101.31000,    -1.25464,74.89880,50.00000,0.0000e+000,20.00000,    -0.13825,0.52022
902.90900,101.48500,    -1.25505,74.87464,50.00000,0.0000e+000,20.00000,    -0.13966,0.51961
904.66699,101.66000,    -1.25747,74.85113,50.00000,0.0000e+000,20.00000,    -0.14131,0.51900
906.42603,101.83500,    -1.25902,74.82728,50.00000,0.0000e+000,20.00000,    -0.14281,0.51839
908.18701,102.01000,    -1.25985,74.80253,50.00000,0.0000e+000,20.00000,    -0.14442,0.51778
909.93903,102.18500,    -1.26188,74.77600,50.00000,0.0000e+000,20.00000,    -0.14595,0.51718
911.70398,102.36000,    -1.26429,74.74831,50.00000,0.0000e+000,20.00000,    -0.14779,0.51657
913.46399,102.53500,    -1.26647,74.72119,50.00000,0.0000e+000,20.00000,    -0.14987,0.51596
915.21503,102.71000,    -1.26860,74.69463,50.00000,0.0000e+000,20.00000,    -0.15164,0.51535
916.96802,102.88500,    -1.26852,74.66698,50.00000,0.0000e+000,20.00000,    -0.15301,0.51475
918.71399,103.06000,    -1.26770,74.64005,50.00000,0.0000e+000,20.00000,    -0.15422,0.51415
920.45300,103.23500,    -1.26801,74.61377,50.00000,0.0000e+000,20.00000,    -0.15547,0.51355
922.19702,103.41000,    -1.26871,74.58747,50.00000,0.0000e+000,20.00000,    -0.15673,0.51294
923.92102,103.58500,    -1.26777,74.55936,50.00000,0.0000e+000,20.00000,    -0.15761,0.51235
925.70001,103.76000,    -1.27281,74.53091,50.00000,0.0000e+000,20.00000,    -0.15869,0.51174
927.47101,103.93500,    -1.27771,74.50341,50.00000,0.0000e+000,20.00000,    -0.15988,0.51113
929.22302,104.11000,    -1.27677,74.47606,50.00000,0.0000e+000,20.00000,    -0.16086,0.51052
930.97601,104.28500,    -1.27586,74.44765,50.00000,0.0000e+000,20.00000,    -0.16217,0.50992
932.74402,104.46000,    -1.27502,74.41839,50.00000,0.0000e+000,20.00000,    -0.16367,0.50931
934.51501,104.63500,    -1.27405,74.38836,50.00000,0.0000e+000,20.00000,    -0.16424,0.50870
936.27197,104.81000,    -1.27119,74.35897,50.00000,0.0000e+000,20.00000,    -0.16495,0.50809
938.02399,104.98500,    -1.26776,74.32981,50.00000,0.0000e+000,20.00000,    -0.16647,0.50749
939.78003,105.16000,    -1.26241,74.30101,50.00000,0.0000e+000,20.00000,    -0.16819,0.50689
941.53900,105.33500,    -1.25861,74.27368,50.00000,0.0000e+000,20.00000,    -0.16922,0.50628
943.29199,105.51000,    -1.25362,74.24645,50.00000,0.0000e+000,20.00000,    -0.17002,0.50568
945.05298,105.68500,    -1.24806,74.21702,50.00000,0.0000e+000,20.00000,    -0.17094,0.50507
946.81097,105.86000,    -1.24284,74.18654,50.00000,0.0000e+000,20.00000,    -0.17182,0.50447
948.60303,106.03500,    -1.24026,74.15475,50.00000,0.0000e+000,20.00000,    -0.17295,0.50385
950.34497,106.21000,    -1.23556,74.12220,50.00000,0.0000e+000,20.00000,    -0.17384,0.50325
952.11401,106.38500,    -1.23252,74.09169,50.00000,0.0000e+000,20.00000,    -0.17396,0.50264
953.87500,106.56000,    -1.23021,74.06260,50.00000,0.0000e+000,20.00000,    -0.17296,0.50203
955.59998,106.73500,    -1.22590,74.03125,50.00000,0.0000e+000,20.00000,    -0.17192,0.50144
957.35101,106.91000,    -1.22427,73.99878,50.00000,0.0000e+000,20.00000,    -0.17085,0.50084
959.08801,107.08500,    -1.22340,73.96710,50.00000,0.0000e+000,20.00000,    -0.16980,0.50024
960.83801,107.26000,    -1.22371,73.93618,50.00000,0.0000e+000,20.00000,    -0.16853,0.49964
962.60602,107.43500,    -1.22563,73.90429,50.00000,0.0000e+000,20.00000,    -0.16650,0.49903
964.34601,107.61000,    -1.22760,73.87390,50.00000,0.0000e+000,20.00000,    -0.16316,0.49843
966.09802,107.78500,    -1.22775,73.84252,50.00000,0.0000e+000,20.00000,    -0.15871,0.49782
967.85199,107.96000,    -1.22846,73.81021,50.00000,0.0000e+000,20.00000,    -0.15368,0.49722
969.61102,108.13500,    -1.23081,73.77881,50.00000,0.0000e+000,20.00000,    -0.14852,0.49661
971.38000,108.31000,    -1.23603,73.75089,50.00000,0.0000e+000,20.00000,    -0.14405,0.49600
973.18903,108.48500,    -1.24487,73.72568,50.00000,0.0000e+000,20.00000,    -0.13914,0.49537
974.97498,108.66000,    -1.25088,73.70023,50.00000,0.0000e+000,20.00000,    -0.13389,0.49476
976.74402,108.83500,    -1.25200,73.67548,50.00000,0.0000e+000,20.00000,    -0.12812,0.49415
978.46899,109.01000,    -1.24968,73.65239,50.00000,0.0000e+000,20.00000,    -0.12235,0.49355
980.18201,109.18500,    -1.24760,73.63085,50.00000,0.0000e+000,20.00000,    -0.11727,0.49296
981.90399,109.36000,    -1.24747,73.61117,50.00000,0.0000e+000,20.00000,    -0.11101,0.49236
983.64502,109.53500,    -1.25176,73.59538,50.00000,0.0000e+000,20.00000,    -0.10242,0.49176
985.38898,109.71000,    -1.25643,73.58095,50.00000,0.0000e+000,20.00000,-9.4810e-002,0.49115
987.12299,109.88500,    -1.25728,73.56759,50.00000,0.0000e+000,20.00000,-8.7097e-002,0.49055
988.88397,110.06000,    -1.25990,73.55478,50.00000,0.0000e+000,20.00000,-7.8918e-002,0.48994
990.68500,110.23500,    -1.26829,73.54236,50.00000,0.0000e+000,20.00000,-7.2052e-002,0.48931
992.46301,110.41000,    -1.27402,73.52952,50.00000,0.0000e+000,20.00000,-6.9166e-002,0.48870
994.20099,110.58500,    -1.27444,73.51725,50.00000,0.0000e+000,20.00000,-6.7585e-002,0.48809
995.92999,110.76000,    -1.27184,73.50724,50.00000,0.0000e+000,20.00000,-6.4176e-002,0.48749
997.64697,110.93500,    -1.27061,73.49683,50.00000,0.0000e+000,20.00000,-7.5152e-002,0.48689
998.34802,111.00500,    -1.27139,73.49074,50.00000,0.0000e+000,20.00000,    -0.19597,0.48665