File: book/some_content/DG_ExpDat_CEM_III_D28; 16-1-2025-2.csv
#FILE:                       ,CEM_III_D28; 16-1-2025.ngb-ds3
#FORMAT:                     ,NETZSCH5
#IDENTITY:                   ,GEOPOLYMER PASTE
#DECIMAL:                    ,POINT
#SEPARATOR:                  ,COMMA
#MTYPE:                      ,DSC
#INSTRUMENT:                 ,Microlab TU Delft
#PROJECT:                    ,
#DATE/TIME:                  ,16/01/2025 8:58:57 PM
#CORR. FILE:                 ,Blank with cover; 13-1-2025.ngb-bs3
#LABORATORY:                 ,TU Delft Micro Lab
#OPERATOR:                   ,Ahmed
#REMARK:                     ,under Argon atmosphere, 10K/min
#SAMPLE:                     ,CEMIIID28;16-1-2025
#SAMPLE MASS /mg:            ,44.4
#MATERIAL:                   ,Geopolymer paste
#REFERENCE:                  ,blank
#REFERENCE MASS /mg:         ,0
#TYPE OF CRUCIBLE:           ,DSC/TG pan Al2O3
#SAMPLE CRUCIBLE MASS /mg:   ,0
#REFERENCE CRUCIBLE MASS /mg:,0
#CORR. CODE:                 ,020
#EXO:                        ,-1
#RANGE:                      ,40/10.0(K/min)/1000
#SEGMENT:                    ,S2/2

##Temp./øC,Time/min,DSC/(mW/mg),Mass/%,Gas Flow(purge1)/(ml/min),Gas Flow(purge2)/(ml/min),Gas Flow(protective)/(ml/min),DTG/(%/min),Sensit./(uV/mW)
 40.88700, 15.55250, 5.0132e-002,97.28553,50.00000,0.0000e+000,20.00000,    -0.15846,1.22572
 40.91300, 15.73250, 5.0540e-002,97.25583,50.00000,0.0000e+000,20.00000,    -0.15774,1.22568
 40.98200, 15.91250, 5.1679e-002,97.22555,50.00000,0.0000e+000,20.00000,    -0.15828,1.22559
 41.16800, 16.09250, 5.3373e-002,97.19646,50.00000,0.0000e+000,20.00000,    -0.15796,1.22533
 41.37600, 16.27250, 5.5714e-002,97.16882,50.00000,0.0000e+000,20.00000,    -0.15907,1.22504
 41.66500, 16.45250, 5.8763e-002,97.14054,50.00000,0.0000e+000,20.00000,    -0.16094,1.22465
 42.04200, 16.63250, 6.2227e-002,97.11129,50.00000,0.0000e+000,20.00000,    -0.16354,1.22413
 42.48400, 16.81250, 6.6752e-002,97.08269,50.00000,0.0000e+000,20.00000,    -0.16959,1.22352
 43.03800, 16.99250, 7.1544e-002,97.05487,50.00000,0.0000e+000,20.00000,    -0.17512,1.22275
 43.68000, 17.17250, 7.7038e-002,97.02649,50.00000,0.0000e+000,20.00000,    -0.18065,1.22187
 44.37000, 17.35250, 8.3094e-002,96.99708,50.00000,0.0000e+000,20.00000,    -0.18711,1.22092
 45.19500, 17.53250, 8.9623e-002,96.96690,50.00000,0.0000e+000,20.00000,    -0.19476,1.21978
 46.04600, 17.71250, 9.6520e-002,96.93592,50.00000,0.0000e+000,20.00000,    -0.20467,1.21861
 47.02400, 17.89250,     0.10401,96.90429,50.00000,0.0000e+000,20.00000,    -0.21719,1.21726
 48.08600, 18.07250,     0.11205,96.87242,50.00000,0.0000e+000,20.00000,    -0.23152,1.21580
 49.23700, 18.25250,     0.12042,96.83820,50.00000,0.0000e+000,20.00000,    -0.24819,1.21421
 50.45400, 18.43250,     0.12924,96.79995,50.00000,0.0000e+000,20.00000,    -0.26623,1.21254
 51.77300, 18.61250,     0.13835,96.75789,50.00000,0.0000e+000,20.00000,    -0.28592,1.21072
 53.17000, 18.79250,     0.14799,96.71328,50.00000,0.0000e+000,20.00000,    -0.30848,1.20880
 54.65200, 18.97250,     0.15823,96.66570,50.00000,0.0000e+000,20.00000,    -0.33728,1.20676
 56.21000, 19.15250,     0.16906,96.61433,50.00000,0.0000e+000,20.00000,    -0.37049,1.20461
 57.82900, 19.33250,     0.18041,96.55790,50.00000,0.0000e+000,20.00000,    -0.40545,1.20239
 59.51500, 19.51250,     0.19244,96.49296,50.00000,0.0000e+000,20.00000,    -0.44393,1.20007
 61.29700, 19.69250,     0.20536,96.41879,50.00000,0.0000e+000,20.00000,    -0.48522,1.19762
 63.14500, 19.87250,     0.21927,96.33960,50.00000,0.0000e+000,20.00000,    -0.53139,1.19508
 65.05600, 20.05250,     0.23422,96.25197,50.00000,0.0000e+000,20.00000,    -0.58210,1.19246
 67.01700, 20.23250,     0.25035,96.15758,50.00000,0.0000e+000,20.00000,    -0.63656,1.18977
 69.03500, 20.41250,     0.26751,96.05783,50.00000,0.0000e+000,20.00000,    -0.69600,1.18700
 71.11700, 20.59250,     0.28642,95.94962,50.00000,0.0000e+000,20.00000,    -0.76129,1.18414
 73.22300, 20.77250,     0.30689,95.82040,50.00000,0.0000e+000,20.00000,    -0.83330,1.18126
 75.38300, 20.95250,     0.32914,95.67074,50.00000,0.0000e+000,20.00000,    -0.91169,1.17830
 77.58500, 21.13250,     0.35357,95.51481,50.00000,0.0000e+000,20.00000,    -0.99663,1.17529
 79.84100, 21.31250,     0.37955,95.34500,50.00000,0.0000e+000,20.00000,    -1.08788,1.17221
 82.12700, 21.49250,     0.40789,95.16461,50.00000,0.0000e+000,20.00000,    -1.18568,1.16908
 84.42800, 21.67250,     0.43824,94.96712,50.00000,0.0000e+000,20.00000,    -1.29216,1.16594
 86.80500, 21.85250,     0.47079,94.75071,50.00000,0.0000e+000,20.00000,    -1.40645,1.16270
 89.17600, 22.03250,     0.50520,94.51700,50.00000,0.0000e+000,20.00000,    -1.52737,1.15947
 91.59500, 22.21250,     0.54180,94.26178,50.00000,0.0000e+000,20.00000,    -1.65525,1.15618
 94.01900, 22.39250,     0.57448,93.98274,50.00000,0.0000e+000,20.00000,    -1.78770,1.15289
 96.45700, 22.57250,     0.61482,93.67682,50.00000,0.0000e+000,20.00000,    -1.91879,1.14958
 98.91500, 22.75250,     0.65752,93.34359,50.00000,0.0000e+000,20.00000,    -2.04346,1.14624
101.36900, 22.93250,     0.70293,92.98238,50.00000,0.0000e+000,20.00000,    -2.16181,1.14292
103.82700, 23.11250,     0.75043,92.59014,50.00000,0.0000e+000,20.00000,    -2.26791,1.13959
106.29800, 23.29250,     0.80078,92.16514,50.00000,0.0000e+000,20.00000,    -2.36147,1.13625
108.74400, 23.47250,     0.85312,91.70328,50.00000,0.0000e+000,20.00000,    -2.44251,1.13295
111.22200, 23.65250,     0.90862,91.20470,50.00000,0.0000e+000,20.00000,    -2.51600,1.12961
113.65400, 23.83250,     0.96518,90.67375,50.00000,0.0000e+000,20.00000,    -2.58529,1.12634
116.11600, 24.01250,     1.02153,90.11209,50.00000,0.0000e+000,20.00000,    -2.64656,1.12303
118.55300, 24.19250,     1.07686,89.52456,50.00000,0.0000e+000,20.00000,    -2.69260,1.11976
121.01900, 24.37250,     1.12736,88.92167,50.00000,0.0000e+000,20.00000,    -2.71657,1.11646
123.46400, 24.55250,     1.17042,88.31681,50.00000,0.0000e+000,20.00000,    -2.71435,1.11319
125.87900, 24.73250,     1.20266,87.72615,50.00000,0.0000e+000,20.00000,    -2.68840,1.10996
128.32401, 24.91250,     1.22127,87.16516,50.00000,0.0000e+000,20.00000,    -2.64258,1.10670
130.75700, 25.09250,     1.22741,86.63930,50.00000,0.0000e+000,20.00000,    -2.58025,1.10346
133.17200, 25.27250,     1.23244,86.14527,50.00000,0.0000e+000,20.00000,    -2.50284,1.10025
135.57201, 25.45250,     1.23757,85.66295,50.00000,0.0000e+000,20.00000,    -2.41187,1.09706
137.99899, 25.63250,     1.23830,85.17882,50.00000,0.0000e+000,20.00000,    -2.30832,1.09384
140.39301, 25.81250,     1.23085,84.70050,50.00000,0.0000e+000,20.00000,    -2.19330,1.09068
142.76199, 25.99250,     1.20809,84.25047,50.00000,0.0000e+000,20.00000,    -2.06732,1.08755
145.16901, 26.17250,     1.15700,83.85159,50.00000,0.0000e+000,20.00000,    -1.93599,1.08438
147.52901, 26.35250,     1.07765,83.52016,50.00000,0.0000e+000,20.00000,    -1.80146,1.08127
149.89799, 26.53250,     0.97835,83.25050,50.00000,0.0000e+000,20.00000,    -1.66724,1.07816
152.28500, 26.71250,     0.87786,83.02513,50.00000,0.0000e+000,20.00000,    -1.54143,1.07503
154.63699, 26.89250,     0.78521,82.82963,50.00000,0.0000e+000,20.00000,    -1.42457,1.07195
157.01801, 27.07250,     0.70242,82.65416,50.00000,0.0000e+000,20.00000,    -1.31508,1.06884
159.38200, 27.25250,     0.62975,82.49159,50.00000,0.0000e+000,20.00000,    -1.20881,1.06576
161.70500, 27.43250,     0.56588,82.34191,50.00000,0.0000e+000,20.00000,    -1.10119,1.06274
164.01100, 27.61250,     0.50995,82.20351,50.00000,0.0000e+000,20.00000,    -0.99406,1.05975
166.33200, 27.79250,     0.46156,82.07799,50.00000,0.0000e+000,20.00000,    -0.89314,1.05674
168.58900, 27.97250,     0.41889,81.95710,50.00000,0.0000e+000,20.00000,    -0.80446,1.05382
170.83099, 28.15250,     0.38162,81.84081,50.00000,0.0000e+000,20.00000,    -0.73333,1.05093
173.03000, 28.33250,     0.34882,81.73713,50.00000,0.0000e+000,20.00000,    -0.67907,1.04810
175.21899, 28.51250,     0.31952,81.63124,50.00000,0.0000e+000,20.00000,    -0.63695,1.04528
177.37399, 28.69250,     0.29332,81.52614,50.00000,0.0000e+000,20.00000,    -0.60279,1.04252
179.48700, 28.87250,     0.26971,81.42756,50.00000,0.0000e+000,20.00000,    -0.57332,1.03982
181.61200, 29.05250,     0.24835,81.33277,50.00000,0.0000e+000,20.00000,    -0.54703,1.03710
183.69200, 29.23250,     0.22933,81.24170,50.00000,0.0000e+000,20.00000,    -0.52267,1.03445
185.73700, 29.41250,     0.21221,81.15273,50.00000,0.0000e+000,20.00000,    -0.50056,1.03185
187.77499, 29.59250,     0.19730,81.06529,50.00000,0.0000e+000,20.00000,    -0.48187,1.02926
189.76401, 29.77250,     0.18431,80.98091,50.00000,0.0000e+000,20.00000,    -0.46449,1.02674
191.75000, 29.95250,     0.17240,80.89867,50.00000,0.0000e+000,20.00000,    -0.44706,1.02423
193.70799, 30.13250,     0.16062,80.81848,50.00000,0.0000e+000,20.00000,    -0.43290,1.02176
195.63100, 30.31250,     0.14804,80.74109,50.00000,0.0000e+000,20.00000,    -0.41827,1.01934
197.54601, 30.49250,     0.13548,80.66594,50.00000,0.0000e+000,20.00000,    -0.40318,1.01693
199.45200, 30.67250,     0.12290,80.59527,50.00000,0.0000e+000,20.00000,    -0.38941,1.01454
201.32001, 30.85250,     0.11089,80.52642,50.00000,0.0000e+000,20.00000,    -0.37687,1.01220
203.18700, 31.03250, 9.9047e-002,80.46291,50.00000,0.0000e+000,20.00000,    -0.36509,1.00987
205.05499, 31.21250, 8.8275e-002,80.40347,50.00000,0.0000e+000,20.00000,    -0.35324,1.00754
206.88901, 31.39250, 7.7502e-002,80.34419,50.00000,0.0000e+000,20.00000,    -0.34141,1.00526
208.69299, 31.57250, 6.7858e-002,80.28664,50.00000,0.0000e+000,20.00000,    -0.33017,1.00302
210.50400, 31.75250, 5.8704e-002,80.23174,50.00000,0.0000e+000,20.00000,    -0.31922,1.00077
212.30099, 31.93250, 4.9818e-002,80.17864,50.00000,0.0000e+000,20.00000,    -0.30894,0.99855
214.05800, 32.11250, 4.1786e-002,80.12678,50.00000,0.0000e+000,20.00000,    -0.29894,0.99638
215.85699, 32.29250, 3.4015e-002,80.07581,50.00000,0.0000e+000,20.00000,    -0.28898,0.99417
217.62100, 32.47250, 2.6710e-002,80.02655,50.00000,0.0000e+000,20.00000,    -0.27995,0.99200
219.36000, 32.65250, 2.0067e-002,79.97718,50.00000,0.0000e+000,20.00000,    -0.27098,0.98987
221.11200, 32.83250, 1.3361e-002,79.92833,50.00000,0.0000e+000,20.00000,    -0.26297,0.98772
222.85201, 33.01250, 6.8343e-003,79.88206,50.00000,0.0000e+000,20.00000,    -0.25568,0.98560
224.58400, 33.19250, 3.8438e-004,79.83743,50.00000,0.0000e+000,20.00000,    -0.24844,0.98349
226.30200, 33.37250,-6.6184e-003,79.79350,50.00000,0.0000e+000,20.00000,    -0.24120,0.98140
228.03000, 33.55250,-1.3897e-002,79.75090,50.00000,0.0000e+000,20.00000,    -0.23450,0.97930
229.75600, 33.73250,-2.1787e-002,79.70796,50.00000,0.0000e+000,20.00000,    -0.22854,0.97721
231.46899, 33.91250,-2.9833e-002,79.66629,50.00000,0.0000e+000,20.00000,    -0.22279,0.97514
233.17000, 34.09250,-3.8019e-002,79.62691,50.00000,0.0000e+000,20.00000,    -0.21711,0.97309
234.88200, 34.27250,-4.6134e-002,79.58843,50.00000,0.0000e+000,20.00000,    -0.21170,0.97103
236.60800, 34.45250,-5.4000e-002,79.55180,50.00000,0.0000e+000,20.00000,    -0.20631,0.96895
238.30400, 34.63250,-6.1417e-002,79.51635,50.00000,0.0000e+000,20.00000,    -0.20056,0.96692
240.01700, 34.81250,-6.8653e-002,79.48297,50.00000,0.0000e+000,20.00000,    -0.19541,0.96487
241.72301, 34.99250,-7.5294e-002,79.45019,50.00000,0.0000e+000,20.00000,    -0.19076,0.96284
243.43500, 35.17250,-8.2071e-002,79.41837,50.00000,0.0000e+000,20.00000,    -0.18609,0.96080
245.15100, 35.35250,-8.8106e-002,79.38772,50.00000,0.0000e+000,20.00000,    -0.18140,0.95876
246.85201, 35.53250,-9.4291e-002,79.35617,50.00000,0.0000e+000,20.00000,    -0.17661,0.95675
248.55400, 35.71250,    -0.10030,79.32509,50.00000,0.0000e+000,20.00000,    -0.17230,0.95473
250.27299, 35.89250,    -0.10566,79.29455,50.00000,0.0000e+000,20.00000,    -0.16882,0.95271
251.97800, 36.07250,    -0.11112,79.26483,50.00000,0.0000e+000,20.00000,    -0.16557,0.95070
253.67999, 36.25250,    -0.11670,79.23516,50.00000,0.0000e+000,20.00000,    -0.16240,0.94870
255.39500, 36.43250,    -0.12167,79.20685,50.00000,0.0000e+000,20.00000,    -0.15920,0.94669
257.10699, 36.61250,    -0.12665,79.17904,50.00000,0.0000e+000,20.00000,    -0.15635,0.94469
258.82199, 36.79250,    -0.13161,79.15122,50.00000,0.0000e+000,20.00000,    -0.15390,0.94269
260.53000, 36.97250,    -0.13625,79.12405,50.00000,0.0000e+000,20.00000,    -0.15167,0.94071
262.25601, 37.15250,    -0.14075,79.09822,50.00000,0.0000e+000,20.00000,    -0.14986,0.93870
263.96600, 37.33250,    -0.14534,79.07298,50.00000,0.0000e+000,20.00000,    -0.14777,0.93672
265.69199, 37.51250,    -0.14997,79.04683,50.00000,0.0000e+000,20.00000,    -0.14565,0.93473
267.41000, 37.69250,    -0.15436,79.01992,50.00000,0.0000e+000,20.00000,    -0.14362,0.93275
269.15100, 37.87250,    -0.15873,78.99313,50.00000,0.0000e+000,20.00000,    -0.14177,0.93075
270.85001, 38.05250,    -0.16334,78.96747,50.00000,0.0000e+000,20.00000,    -0.14007,0.92880
272.56699, 38.23250,    -0.16793,78.94341,50.00000,0.0000e+000,20.00000,    -0.13883,0.92684
274.29800, 38.41250,    -0.17249,78.92008,50.00000,0.0000e+000,20.00000,    -0.13763,0.92486
276.02701, 38.59250,    -0.17664,78.89637,50.00000,0.0000e+000,20.00000,    -0.13609,0.92290
277.77600, 38.77250,    -0.18120,78.87242,50.00000,0.0000e+000,20.00000,    -0.13495,0.92091
279.49701, 38.95250,    -0.18555,78.84836,50.00000,0.0000e+000,20.00000,    -0.13415,0.91897
281.24899, 39.13250,    -0.18984,78.82454,50.00000,0.0000e+000,20.00000,    -0.13333,0.91699
282.97800, 39.31250,    -0.19378,78.80102,50.00000,0.0000e+000,20.00000,    -0.13254,0.91504
284.72198, 39.49250,    -0.19781,78.77776,50.00000,0.0000e+000,20.00000,    -0.13178,0.91308
286.47601, 39.67250,    -0.20217,78.75473,50.00000,0.0000e+000,20.00000,    -0.13057,0.91112
288.20401, 39.85250,    -0.20587,78.73133,50.00000,0.0000e+000,20.00000,    -0.12946,0.90919
289.96201, 40.03250,    -0.20990,78.70733,50.00000,0.0000e+000,20.00000,    -0.12899,0.90723
291.71701, 40.21250,    -0.21360,78.68376,50.00000,0.0000e+000,20.00000,    -0.12849,0.90528
293.47198, 40.39250,    -0.21731,78.66145,50.00000,0.0000e+000,20.00000,    -0.12795,0.90334
295.22400, 40.57250,    -0.22105,78.63852,50.00000,0.0000e+000,20.00000,    -0.12740,0.90140
296.96899, 40.75250,    -0.22443,78.61524,50.00000,0.0000e+000,20.00000,    -0.12668,0.89948
298.73099, 40.93250,    -0.22807,78.59292,50.00000,0.0000e+000,20.00000,    -0.12592,0.89754
300.47101, 41.11250,    -0.23126,78.57017,50.00000,0.0000e+000,20.00000,    -0.12524,0.89563
302.23999, 41.29250,    -0.23480,78.54599,50.00000,0.0000e+000,20.00000,    -0.12449,0.89370
303.98099, 41.47250,    -0.23852,78.52326,50.00000,0.0000e+000,20.00000,    -0.12382,0.89180
305.74301, 41.65250,    -0.24181,78.50155,50.00000,0.0000e+000,20.00000,    -0.12310,0.88989
307.50500, 41.83250,    -0.24543,78.47891,50.00000,0.0000e+000,20.00000,    -0.12213,0.88798
309.25699, 42.01250,    -0.24840,78.45729,50.00000,0.0000e+000,20.00000,    -0.12129,0.88609
311.01599, 42.19250,    -0.25200,78.43570,50.00000,0.0000e+000,20.00000,    -0.12071,0.88419
312.75900, 42.37250,    -0.25540,78.41379,50.00000,0.0000e+000,20.00000,    -0.12007,0.88232
314.52301, 42.55250,    -0.25917,78.39225,50.00000,0.0000e+000,20.00000,    -0.11936,0.88043
316.28201, 42.73250,    -0.26238,78.37116,50.00000,0.0000e+000,20.00000,    -0.11883,0.87855
318.05200, 42.91250,    -0.26592,78.35007,50.00000,0.0000e+000,20.00000,    -0.11842,0.87667
319.81000, 43.09250,    -0.26879,78.32941,50.00000,0.0000e+000,20.00000,    -0.11784,0.87480
321.59399, 43.27250,    -0.27199,78.30888,50.00000,0.0000e+000,20.00000,    -0.11745,0.87292
323.35800, 43.45250,    -0.27466,78.28817,50.00000,0.0000e+000,20.00000,    -0.11754,0.87105
325.11600, 43.63250,    -0.27775,78.26778,50.00000,0.0000e+000,20.00000,    -0.11734,0.86921
326.88599, 43.81250,    -0.28063,78.24712,50.00000,0.0000e+000,20.00000,    -0.11747,0.86735
328.66699, 43.99250,    -0.28353,78.22673,50.00000,0.0000e+000,20.00000,    -0.11802,0.86549
330.45801, 44.17250,    -0.28640,78.20642,50.00000,0.0000e+000,20.00000,    -0.11892,0.86362
332.23001, 44.35250,    -0.28908,78.18565,50.00000,0.0000e+000,20.00000,    -0.11916,0.86178
334.00400, 44.53250,    -0.29164,78.16511,50.00000,0.0000e+000,20.00000,    -0.11917,0.85994
335.78299, 44.71250,    -0.29370,78.14428,50.00000,0.0000e+000,20.00000,    -0.11949,0.85810
337.54199, 44.89250,    -0.29551,78.12232,50.00000,0.0000e+000,20.00000,    -0.12019,0.85629
339.32401, 45.07250,    -0.29763,78.10063,50.00000,0.0000e+000,20.00000,    -0.12137,0.85447
341.09000, 45.25250,    -0.29973,78.07873,50.00000,0.0000e+000,20.00000,    -0.12322,0.85266
342.85999, 45.43250,    -0.30170,78.05679,50.00000,0.0000e+000,20.00000,    -0.12586,0.85085
344.62701, 45.61250,    -0.30369,78.03463,50.00000,0.0000e+000,20.00000,    -0.12780,0.84906
346.41599, 45.79250,    -0.30682,78.01145,50.00000,0.0000e+000,20.00000,    -0.12952,0.84725
348.23599, 45.97250,    -0.31065,77.98625,50.00000,0.0000e+000,20.00000,    -0.13138,0.84541
350.04700, 46.15250,    -0.31359,77.96323,50.00000,0.0000e+000,20.00000,    -0.13354,0.84358
351.87500, 46.33250,    -0.31568,77.94211,50.00000,0.0000e+000,20.00000,    -0.13584,0.84175
353.67999, 46.51250,    -0.31634,77.92004,50.00000,0.0000e+000,20.00000,    -0.13819,0.83995
355.48901, 46.69250,    -0.31683,77.89687,50.00000,0.0000e+000,20.00000,    -0.13994,0.83814
357.27100, 46.87250,    -0.31625,77.87239,50.00000,0.0000e+000,20.00000,    -0.14154,0.83637
359.05099, 47.05250,    -0.31583,77.84537,50.00000,0.0000e+000,20.00000,    -0.14334,0.83461
360.82999, 47.23250,    -0.31552,77.81544,50.00000,0.0000e+000,20.00000,    -0.14565,0.83286
362.58401, 47.41250,    -0.31568,77.78729,50.00000,0.0000e+000,20.00000,    -0.14678,0.83113
364.34500, 47.59250,    -0.31613,77.76052,50.00000,0.0000e+000,20.00000,    -0.14690,0.82941
366.11401, 47.77250,    -0.31712,77.73360,50.00000,0.0000e+000,20.00000,    -0.14750,0.82768
367.85999, 47.95250,    -0.31738,77.70519,50.00000,0.0000e+000,20.00000,    -0.14849,0.82598
369.59799, 48.13250,    -0.31744,77.67621,50.00000,0.0000e+000,20.00000,    -0.14978,0.82429
371.34399, 48.31250,    -0.31839,77.64686,50.00000,0.0000e+000,20.00000,    -0.15100,0.82261
373.09100, 48.49250,    -0.32000,77.61853,50.00000,0.0000e+000,20.00000,    -0.15215,0.82092
374.83600, 48.67250,    -0.32259,77.59078,50.00000,0.0000e+000,20.00000,    -0.15207,0.81925
376.60001, 48.85250,    -0.32574,77.56275,50.00000,0.0000e+000,20.00000,    -0.15082,0.81756
378.36801, 49.03250,    -0.32925,77.53233,50.00000,0.0000e+000,20.00000,    -0.14887,0.81587
380.14099, 49.21250,    -0.33295,77.50517,50.00000,0.0000e+000,20.00000,    -0.14723,0.81419
381.92801, 49.39250,    -0.33684,77.48202,50.00000,0.0000e+000,20.00000,    -0.14541,0.81249
383.72000, 49.57250,    -0.34000,77.45532,50.00000,0.0000e+000,20.00000,    -0.14339,0.81080
385.50699, 49.75250,    -0.34334,77.42779,50.00000,0.0000e+000,20.00000,    -0.14119,0.80912
387.29300, 49.93250,    -0.34726,77.40191,50.00000,0.0000e+000,20.00000,    -0.13882,0.80745
389.09201, 50.11250,    -0.35155,77.37570,50.00000,0.0000e+000,20.00000,    -0.13556,0.80577
390.90900, 50.29250,    -0.35676,77.34844,50.00000,0.0000e+000,20.00000,    -0.13205,0.80408
392.74100, 50.47250,    -0.36325,77.32385,50.00000,0.0000e+000,20.00000,    -0.12849,0.80238
394.55600, 50.65250,    -0.36798,77.30185,50.00000,0.0000e+000,20.00000,    -0.12534,0.80070
396.36499, 50.83250,    -0.37208,77.27943,50.00000,0.0000e+000,20.00000,    -0.12187,0.79904
398.17899, 51.01250,    -0.37587,77.25662,50.00000,0.0000e+000,20.00000,    -0.11893,0.79737
399.98001, 51.19250,    -0.37963,77.23614,50.00000,0.0000e+000,20.00000,    -0.11726,0.79573
401.77600, 51.37250,    -0.38191,77.21664,50.00000,0.0000e+000,20.00000,    -0.11484,0.79409
403.55399, 51.55250,    -0.38333,77.19679,50.00000,0.0000e+000,20.00000,    -0.11180,0.79248
405.31100, 51.73250,    -0.38569,77.17619,50.00000,0.0000e+000,20.00000,    -0.10978,0.79089
407.07501, 51.91250,    -0.38799,77.15841,50.00000,0.0000e+000,20.00000,    -0.10786,0.78930
408.84201, 52.09250,    -0.39259,77.14243,50.00000,0.0000e+000,20.00000,    -0.10519,0.78772
410.62100, 52.27250,    -0.39675,77.12768,50.00000,0.0000e+000,20.00000,    -0.10345,0.78613
412.42999, 52.45250,    -0.40148,77.11169,50.00000,0.0000e+000,20.00000,    -0.10306,0.78452
414.22800, 52.63250,    -0.40645,77.09425,50.00000,0.0000e+000,20.00000,    -0.10314,0.78292
416.04800, 52.81250,    -0.41052,77.07683,50.00000,0.0000e+000,20.00000,    -0.10368,0.78132
417.84100, 52.99250,    -0.41362,77.05971,50.00000,0.0000e+000,20.00000,    -0.10529,0.77974
419.64499, 53.17250,    -0.41572,77.04253,50.00000,0.0000e+000,20.00000,    -0.10824,0.77816
421.42801, 53.35250,    -0.41750,77.02575,50.00000,0.0000e+000,20.00000,    -0.11233,0.77660
423.21600, 53.53250,    -0.41947,77.00767,50.00000,0.0000e+000,20.00000,    -0.11731,0.77504
424.99200, 53.71250,    -0.42108,76.98828,50.00000,0.0000e+000,20.00000,    -0.12454,0.77350
426.78500, 53.89250,    -0.42237,76.97085,50.00000,0.0000e+000,20.00000,    -0.13338,0.77195
428.57401, 54.07250,    -0.42306,76.95224,50.00000,0.0000e+000,20.00000,    -0.14354,0.77042
430.35101, 54.25250,    -0.42202,76.93182,50.00000,0.0000e+000,20.00000,    -0.15374,0.76889
432.14001, 54.43250,    -0.41785,76.90956,50.00000,0.0000e+000,20.00000,    -0.16356,0.76736
433.93799, 54.61250,    -0.41020,76.88500,50.00000,0.0000e+000,20.00000,    -0.17366,0.76584
435.69901, 54.79250,    -0.39976,76.85858,50.00000,0.0000e+000,20.00000,    -0.18350,0.76434
437.50800, 54.97250,    -0.38837,76.82893,50.00000,0.0000e+000,20.00000,    -0.19301,0.76282
439.28699, 55.15250,    -0.37611,76.79492,50.00000,0.0000e+000,20.00000,    -0.20187,0.76132
441.07599, 55.33250,    -0.36277,76.75672,50.00000,0.0000e+000,20.00000,    -0.20935,0.75982
442.88101, 55.51250,    -0.34898,76.71301,50.00000,0.0000e+000,20.00000,    -0.21558,0.75832
444.64899, 55.69250,    -0.33524,76.66486,50.00000,0.0000e+000,20.00000,    -0.22110,0.75685
446.43799, 55.87250,    -0.32196,76.61347,50.00000,0.0000e+000,20.00000,    -0.22467,0.75537
448.20099, 56.05250,    -0.31063,76.56037,50.00000,0.0000e+000,20.00000,    -0.22652,0.75392
449.98499, 56.23250,    -0.30208,76.50740,50.00000,0.0000e+000,20.00000,    -0.22743,0.75245
451.74600, 56.41250,    -0.29499,76.45301,50.00000,0.0000e+000,20.00000,    -0.22665,0.75101
453.52600, 56.59250,    -0.29093,76.39969,50.00000,0.0000e+000,20.00000,    -0.22464,0.74956
455.29401, 56.77250,    -0.29037,76.34753,50.00000,0.0000e+000,20.00000,    -0.22141,0.74813
457.05499, 56.95250,    -0.29430,76.29772,50.00000,0.0000e+000,20.00000,    -0.21663,0.74671
458.85199, 57.13250,    -0.30306,76.25216,50.00000,0.0000e+000,20.00000,    -0.21055,0.74526
460.64401, 57.31250,    -0.31630,76.20943,50.00000,0.0000e+000,20.00000,    -0.20253,0.74382
462.47601, 57.49250,    -0.33408,76.17077,50.00000,0.0000e+000,20.00000,    -0.19268,0.74236
464.28101, 57.67250,    -0.35458,76.13849,50.00000,0.0000e+000,20.00000,    -0.18226,0.74093
466.09601, 57.85250,    -0.37678,76.11111,50.00000,0.0000e+000,20.00000,    -0.17107,0.73949
467.90500, 58.03250,    -0.39695,76.08554,50.00000,0.0000e+000,20.00000,    -0.16005,0.73806
469.73700, 58.21250,    -0.41345,76.06350,50.00000,0.0000e+000,20.00000,    -0.14875,0.73662
471.54300, 58.39250,    -0.42647,76.04451,50.00000,0.0000e+000,20.00000,    -0.13749,0.73521
473.33099, 58.57250,    -0.43697,76.02702,50.00000,0.0000e+000,20.00000,    -0.12627,0.73382
475.12000, 58.75250,    -0.44481,76.01099,50.00000,0.0000e+000,20.00000,    -0.11559,0.73243
476.90900, 58.93250,    -0.45033,75.99562,50.00000,0.0000e+000,20.00000,    -0.10619,0.73105
478.68301, 59.11250,    -0.45546,75.98169,50.00000,0.0000e+000,20.00000,-9.7469e-002,0.72969
480.46301, 59.29250,    -0.46091,75.97004,50.00000,0.0000e+000,20.00000,-8.9457e-002,0.72832
482.27301, 59.47250,    -0.46680,75.95733,50.00000,0.0000e+000,20.00000,-8.3203e-002,0.72694
484.05301, 59.65250,    -0.47170,75.94504,50.00000,0.0000e+000,20.00000,-7.8716e-002,0.72559
485.85101, 59.83250,    -0.47517,75.93263,50.00000,0.0000e+000,20.00000,-7.4560e-002,0.72423
487.64200, 60.01250,    -0.47853,75.91961,50.00000,0.0000e+000,20.00000,-7.0982e-002,0.72288
489.42999, 60.19250,    -0.48082,75.90706,50.00000,0.0000e+000,20.00000,-6.8223e-002,0.72154
491.21201, 60.37250,    -0.48352,75.89558,50.00000,0.0000e+000,20.00000,-6.5830e-002,0.72021
493.00601, 60.55250,    -0.48619,75.88440,50.00000,0.0000e+000,20.00000,-6.3603e-002,0.71887
494.81601, 60.73250,    -0.48952,75.87258,50.00000,0.0000e+000,20.00000,-6.1428e-002,0.71753
496.62299, 60.91250,    -0.49376,75.86122,50.00000,0.0000e+000,20.00000,-6.0045e-002,0.71620
498.43399, 61.09250,    -0.49605,75.85082,50.00000,0.0000e+000,20.00000,-5.9441e-002,0.71487
500.23300, 61.27250,    -0.49805,75.84065,50.00000,0.0000e+000,20.00000,-5.8569e-002,0.71355
502.03900, 61.45250,    -0.49916,75.82915,50.00000,0.0000e+000,20.00000,-5.7710e-002,0.71224
503.85599, 61.63250,    -0.50132,75.81836,50.00000,0.0000e+000,20.00000,-5.6686e-002,0.71092
505.65500, 61.81250,    -0.50326,75.80858,50.00000,0.0000e+000,20.00000,-5.5207e-002,0.70962
507.47000, 61.99250,    -0.50457,75.79937,50.00000,0.0000e+000,20.00000,-5.3121e-002,0.70832
509.24899, 62.17250,    -0.50461,75.79033,50.00000,0.0000e+000,20.00000,-5.1547e-002,0.70704
511.03601, 62.35250,    -0.50466,75.78205,50.00000,0.0000e+000,20.00000,-5.0551e-002,0.70577
512.80298, 62.53250,    -0.50561,75.77466,50.00000,0.0000e+000,20.00000,-4.9054e-002,0.70451
514.56201, 62.71250,    -0.50655,75.76568,50.00000,0.0000e+000,20.00000,-4.7860e-002,0.70327
516.34802, 62.89250,    -0.50834,75.75599,50.00000,0.0000e+000,20.00000,-4.7190e-002,0.70201
518.13501, 63.07250,    -0.51097,75.74671,50.00000,0.0000e+000,20.00000,-4.6615e-002,0.70076
519.92798, 63.25250,    -0.51348,75.73729,50.00000,0.0000e+000,20.00000,-4.5655e-002,0.69951
521.71997, 63.43250,    -0.51577,75.72872,50.00000,0.0000e+000,20.00000,-4.4886e-002,0.69827
523.51501, 63.61250,    -0.51768,75.72079,50.00000,0.0000e+000,20.00000,-4.4433e-002,0.69702
525.31799, 63.79250,    -0.51956,75.71546,50.00000,0.0000e+000,20.00000,-4.4040e-002,0.69578
527.10901, 63.97250,    -0.52132,75.70999,50.00000,0.0000e+000,20.00000,-4.3573e-002,0.69455
528.90997, 64.15250,    -0.52314,75.70246,50.00000,0.0000e+000,20.00000,-4.3404e-002,0.69332
530.70001, 64.33250,    -0.52495,75.69604,50.00000,0.0000e+000,20.00000,-4.3419e-002,0.69211
532.51202, 64.51250,    -0.52698,75.68919,50.00000,0.0000e+000,20.00000,-4.2683e-002,0.69088
534.31097, 64.69250,    -0.52883,75.68109,50.00000,0.0000e+000,20.00000,-4.1787e-002,0.68967
536.11798, 64.87250,    -0.53018,75.67313,50.00000,0.0000e+000,20.00000,-4.1433e-002,0.68845
537.91199, 65.05250,    -0.53196,75.66525,50.00000,0.0000e+000,20.00000,-4.1028e-002,0.68726
539.69000, 65.23250,    -0.53313,75.65715,50.00000,0.0000e+000,20.00000,-4.0798e-002,0.68607
541.47498, 65.41250,    -0.53382,75.64886,50.00000,0.0000e+000,20.00000,-4.0624e-002,0.68489
543.29498, 65.59250,    -0.53707,75.64094,50.00000,0.0000e+000,20.00000,-4.1140e-002,0.68369
545.10303, 65.77250,    -0.53974,75.63359,50.00000,0.0000e+000,20.00000,-4.2043e-002,0.68250
546.90997, 65.95250,    -0.54149,75.62579,50.00000,0.0000e+000,20.00000,-4.2079e-002,0.68132
548.69897, 66.13250,    -0.54274,75.61818,50.00000,0.0000e+000,20.00000,-4.2315e-002,0.68016
550.51501, 66.31250,    -0.54474,75.61205,50.00000,0.0000e+000,20.00000,-4.2675e-002,0.67898
552.33398, 66.49250,    -0.54706,75.60580,50.00000,0.0000e+000,20.00000,-4.2833e-002,0.67781
554.14600, 66.67250,    -0.54906,75.59797,50.00000,0.0000e+000,20.00000,-4.2847e-002,0.67664
555.94702, 66.85250,    -0.54972,75.58993,50.00000,0.0000e+000,20.00000,-4.2500e-002,0.67549
557.73199, 67.03250,    -0.55054,75.58207,50.00000,0.0000e+000,20.00000,-4.2172e-002,0.67436
559.54901, 67.21250,    -0.55166,75.57454,50.00000,0.0000e+000,20.00000,-4.1822e-002,0.67320
561.31702, 67.39250,    -0.55197,75.56698,50.00000,0.0000e+000,20.00000,-4.1172e-002,0.67209
563.11902, 67.57250,    -0.55374,75.55864,50.00000,0.0000e+000,20.00000,-4.0581e-002,0.67096
564.90503, 67.75250,    -0.55526,75.55088,50.00000,0.0000e+000,20.00000,-3.9532e-002,0.66984
566.69598, 67.93250,    -0.55662,75.54350,50.00000,0.0000e+000,20.00000,-3.8698e-002,0.66872
568.48297, 68.11250,    -0.55852,75.53561,50.00000,0.0000e+000,20.00000,-3.8804e-002,0.66762
570.28601, 68.29250,    -0.55976,75.52713,50.00000,0.0000e+000,20.00000,-3.8984e-002,0.66650
572.07001, 68.47250,    -0.56138,75.51884,50.00000,0.0000e+000,20.00000,-3.8137e-002,0.66541
573.86902, 68.65250,    -0.56317,75.51211,50.00000,0.0000e+000,20.00000,-3.7145e-002,0.66431
575.65399, 68.83250,    -0.56526,75.50538,50.00000,0.0000e+000,20.00000,-3.6880e-002,0.66322
577.43903, 69.01250,    -0.56706,75.49825,50.00000,0.0000e+000,20.00000,-3.6271e-002,0.66214
579.24799, 69.19250,    -0.56948,75.49243,50.00000,0.0000e+000,20.00000,-3.5028e-002,0.66104
581.04797, 69.37250,    -0.57180,75.48716,50.00000,0.0000e+000,20.00000,-3.4271e-002,0.65996
582.84900, 69.55250,    -0.57239,75.48304,50.00000,0.0000e+000,20.00000,-3.4028e-002,0.65888
584.63397, 69.73250,    -0.57287,75.47873,50.00000,0.0000e+000,20.00000,-3.4177e-002,0.65782
586.42603, 69.91250,    -0.57398,75.47216,50.00000,0.0000e+000,20.00000,-3.4451e-002,0.65676
588.25098, 70.09250,    -0.57634,75.46532,50.00000,0.0000e+000,20.00000,-3.4278e-002,0.65568
590.08197, 70.27250,    -0.57950,75.46040,50.00000,0.0000e+000,20.00000,-3.3694e-002,0.65460
591.92999, 70.45250,    -0.58398,75.45622,50.00000,0.0000e+000,20.00000,-3.3732e-002,0.65352
593.77899, 70.63250,    -0.58705,75.44961,50.00000,0.0000e+000,20.00000,-3.4129e-002,0.65244
595.61200, 70.81250,    -0.58906,75.44359,50.00000,0.0000e+000,20.00000,-3.4298e-002,0.65138
597.41199, 70.99250,    -0.58937,75.44077,50.00000,0.0000e+000,20.00000,-3.4921e-002,0.65034
599.20697, 71.17250,    -0.58880,75.43562,50.00000,0.0000e+000,20.00000,-3.5604e-002,0.64931
601.00000, 71.35250,    -0.58796,75.42879,50.00000,0.0000e+000,20.00000,-3.6669e-002,0.64828
602.76599, 71.53250,    -0.58783,75.42100,50.00000,0.0000e+000,20.00000,-3.8059e-002,0.64727
604.53198, 71.71250,    -0.58843,75.41230,50.00000,0.0000e+000,20.00000,-3.8857e-002,0.64627
606.30402, 71.89250,    -0.59089,75.40422,50.00000,0.0000e+000,20.00000,-3.9237e-002,0.64527
608.10498, 72.07250,    -0.59358,75.39782,50.00000,0.0000e+000,20.00000,-3.9821e-002,0.64426
609.91101, 72.25250,    -0.59627,75.39099,50.00000,0.0000e+000,20.00000,-4.0811e-002,0.64325
611.71301, 72.43250,    -0.59849,75.38295,50.00000,0.0000e+000,20.00000,-4.1334e-002,0.64224
613.50897, 72.61250,    -0.59990,75.37514,50.00000,0.0000e+000,20.00000,-4.1801e-002,0.64124
615.29901, 72.79250,    -0.60158,75.36689,50.00000,0.0000e+000,20.00000,-4.2972e-002,0.64025
617.08801, 72.97250,    -0.60283,75.35897,50.00000,0.0000e+000,20.00000,-4.3644e-002,0.63927
618.90198, 73.15250,    -0.60538,75.35089,50.00000,0.0000e+000,20.00000,-4.4129e-002,0.63827
620.69598, 73.33250,    -0.60796,75.34187,50.00000,0.0000e+000,20.00000,-4.4349e-002,0.63729
622.51599, 73.51250,    -0.61004,75.33259,50.00000,0.0000e+000,20.00000,-4.3990e-002,0.63631
624.31000, 73.69250,    -0.61246,75.32409,50.00000,0.0000e+000,20.00000,-4.3240e-002,0.63534
626.11499, 73.87250,    -0.61443,75.31657,50.00000,0.0000e+000,20.00000,-4.3284e-002,0.63436
627.92297, 74.05250,    -0.61588,75.30902,50.00000,0.0000e+000,20.00000,-4.3579e-002,0.63339
629.72101, 74.23250,    -0.61717,75.30094,50.00000,0.0000e+000,20.00000,-4.3369e-002,0.63243
631.51099, 74.41250,    -0.61843,75.29266,50.00000,0.0000e+000,20.00000,-4.3542e-002,0.63148
633.30798, 74.59250,    -0.61988,75.28525,50.00000,0.0000e+000,20.00000,-4.3750e-002,0.63053
635.11700, 74.77250,    -0.62188,75.27822,50.00000,0.0000e+000,20.00000,-4.3429e-002,0.62958
636.93103, 74.95250,    -0.62435,75.26992,50.00000,0.0000e+000,20.00000,-4.2790e-002,0.62862
638.73798, 75.13250,    -0.62718,75.26143,50.00000,0.0000e+000,20.00000,-4.1977e-002,0.62768
640.58398, 75.31250,    -0.63245,75.25382,50.00000,0.0000e+000,20.00000,-4.1024e-002,0.62672
642.41400, 75.49250,    -0.63489,75.24817,50.00000,0.0000e+000,20.00000,-4.0329e-002,0.62577
644.23199, 75.67250,    -0.63686,75.24170,50.00000,0.0000e+000,20.00000,-4.0213e-002,0.62483
646.03101, 75.85250,    -0.63728,75.23401,50.00000,0.0000e+000,20.00000,-4.0135e-002,0.62391
647.84003, 76.03250,    -0.63748,75.22678,50.00000,0.0000e+000,20.00000,-3.9754e-002,0.62298
649.64203, 76.21250,    -0.63812,75.21862,50.00000,0.0000e+000,20.00000,-3.8960e-002,0.62207
651.43597, 76.39250,    -0.63966,75.20951,50.00000,0.0000e+000,20.00000,-3.8924e-002,0.62116
653.23999, 76.57250,    -0.64207,75.20232,50.00000,0.0000e+000,20.00000,-3.9320e-002,0.62025
655.02600, 76.75250,    -0.64425,75.19669,50.00000,0.0000e+000,20.00000,-3.9143e-002,0.61935
656.82703, 76.93250,    -0.64638,75.19074,50.00000,0.0000e+000,20.00000,-3.8790e-002,0.61845
658.61902, 77.11250,    -0.64826,75.18495,50.00000,0.0000e+000,20.00000,-3.8700e-002,0.61755
660.41699, 77.29250,    -0.64996,75.17893,50.00000,0.0000e+000,20.00000,-3.9264e-002,0.61666
662.20898, 77.47250,    -0.65209,75.17182,50.00000,0.0000e+000,20.00000,-3.9112e-002,0.61577
664.01300, 77.65250,    -0.65410,75.16462,50.00000,0.0000e+000,20.00000,-3.8224e-002,0.61488
665.81897, 77.83250,    -0.65624,75.15779,50.00000,0.0000e+000,20.00000,-3.7884e-002,0.61400
667.63300, 78.01250,    -0.65786,75.15241,50.00000,0.0000e+000,20.00000,-3.7467e-002,0.61311
669.42902, 78.19250,    -0.65906,75.14533,50.00000,0.0000e+000,20.00000,-3.6614e-002,0.61224
671.22198, 78.37250,    -0.66089,75.13687,50.00000,0.0000e+000,20.00000,-3.6336e-002,0.61137
673.02197, 78.55250,    -0.66180,75.12929,50.00000,0.0000e+000,20.00000,-3.6576e-002,0.61050
674.83197, 78.73250,    -0.66371,75.12204,50.00000,0.0000e+000,20.00000,-3.6543e-002,0.60963
676.63898, 78.91250,    -0.66654,75.11460,50.00000,0.0000e+000,20.00000,-3.6356e-002,0.60877
678.45801, 79.09250,    -0.67009,75.10663,50.00000,0.0000e+000,20.00000,-3.6045e-002,0.60790
680.28400, 79.27250,    -0.67360,75.10054,50.00000,0.0000e+000,20.00000,-3.5560e-002,0.60703
682.09802, 79.45250,    -0.67571,75.09623,50.00000,0.0000e+000,20.00000,-3.4772e-002,0.60618
683.87201, 79.63250,    -0.67573,75.09041,50.00000,0.0000e+000,20.00000,-3.3802e-002,0.60534
685.63599, 79.81250,    -0.67521,75.08400,50.00000,0.0000e+000,20.00000,-3.3234e-002,0.60451
687.39899, 79.99250,    -0.67576,75.07794,50.00000,0.0000e+000,20.00000,-3.2287e-002,0.60369
689.19098, 80.17250,    -0.67906,75.07150,50.00000,0.0000e+000,20.00000,-3.0757e-002,0.60285
690.98999, 80.35250,    -0.68340,75.06482,50.00000,0.0000e+000,20.00000,-2.9491e-002,0.60202
692.81000, 80.53250,    -0.68776,75.05895,50.00000,0.0000e+000,20.00000,-2.8282e-002,0.60118
694.64099, 80.71250,    -0.69110,75.05364,50.00000,0.0000e+000,20.00000,-2.6951e-002,0.60034
696.43103, 80.89250,    -0.69296,75.04900,50.00000,0.0000e+000,20.00000,-2.5671e-002,0.59952
698.22101, 81.07250,    -0.69445,75.04369,50.00000,0.0000e+000,20.00000,-2.4945e-002,0.59870
700.01398, 81.25250,    -0.69675,75.03925,50.00000,0.0000e+000,20.00000,-2.4869e-002,0.59789
701.80402, 81.43250,    -0.69959,75.03567,50.00000,0.0000e+000,20.00000,-2.4284e-002,0.59708
703.63098, 81.61250,    -0.70275,75.03232,50.00000,0.0000e+000,20.00000,-2.3378e-002,0.59625
705.43597, 81.79250,    -0.70492,75.02903,50.00000,0.0000e+000,20.00000,-2.3008e-002,0.59544
707.24200, 81.97250,    -0.70700,75.02615,50.00000,0.0000e+000,20.00000,-2.2760e-002,0.59463
709.04401, 82.15250,    -0.70866,75.02308,50.00000,0.0000e+000,20.00000,-2.2186e-002,0.59383
710.85901, 82.33250,    -0.71031,75.02019,50.00000,0.0000e+000,20.00000,-2.1435e-002,0.59302
712.68201, 82.51250,    -0.71241,75.01769,50.00000,0.0000e+000,20.00000,-2.0682e-002,0.59222
714.48401, 82.69250,    -0.71491,75.01454,50.00000,0.0000e+000,20.00000,-2.0269e-002,0.59142
716.31598, 82.87250,    -0.71842,75.01072,50.00000,0.0000e+000,20.00000,-1.9578e-002,0.59062
718.13898, 83.05250,    -0.71863,75.00666,50.00000,0.0000e+000,20.00000,-1.9438e-002,0.58982
719.92999, 83.23250,    -0.71909,75.00305,50.00000,0.0000e+000,20.00000,-1.9933e-002,0.58904
721.74298, 83.41250,    -0.72230,75.00011,50.00000,0.0000e+000,20.00000,-2.0485e-002,0.58825
723.59302, 83.59250,    -0.72776,74.99557,50.00000,0.0000e+000,20.00000,-2.1041e-002,0.58745
725.38397, 83.77250,    -0.72998,74.99016,50.00000,0.0000e+000,20.00000,-2.1519e-002,0.58668
727.16901, 83.95250,    -0.72876,74.98532,50.00000,0.0000e+000,20.00000,-2.1386e-002,0.58591
728.96899, 84.13250,    -0.72964,74.98190,50.00000,0.0000e+000,20.00000,-2.1712e-002,0.58514
730.76001, 84.31250,    -0.73085,74.97922,50.00000,0.0000e+000,20.00000,-2.2427e-002,0.58437
732.56299, 84.49250,    -0.73226,74.97615,50.00000,0.0000e+000,20.00000,-2.3117e-002,0.58361
734.43799, 84.67250,    -0.73712,74.97334,50.00000,0.0000e+000,20.00000,-2.2894e-002,0.58281
736.29700, 84.85250,    -0.74103,74.96960,50.00000,0.0000e+000,20.00000,-2.2558e-002,0.58203
738.11902, 85.03250,    -0.74204,74.96417,50.00000,0.0000e+000,20.00000,-2.3079e-002,0.58126
739.91901, 85.21250,    -0.74141,74.95878,50.00000,0.0000e+000,20.00000,-2.4101e-002,0.58050
741.69202, 85.39250,    -0.74007,74.95344,50.00000,0.0000e+000,20.00000,-2.4365e-002,0.57976
743.46802, 85.57250,    -0.73977,74.94847,50.00000,0.0000e+000,20.00000,-2.4301e-002,0.57902
745.23297, 85.75250,    -0.74077,74.94582,50.00000,0.0000e+000,20.00000,-2.3894e-002,0.57829
747.04498, 85.93250,    -0.74352,74.94201,50.00000,0.0000e+000,20.00000,-2.3465e-002,0.57754
748.85101, 86.11250,    -0.74611,74.93691,50.00000,0.0000e+000,20.00000,-2.3846e-002,0.57680
750.64203, 86.29250,    -0.74701,74.93138,50.00000,0.0000e+000,20.00000,-2.4470e-002,0.57606
752.42297, 86.47250,    -0.74754,74.92788,50.00000,0.0000e+000,20.00000,-2.5123e-002,0.57533
754.22900, 86.65250,    -0.74841,74.92551,50.00000,0.0000e+000,20.00000,-2.5252e-002,0.57459
756.02100, 86.83250,    -0.75074,74.92014,50.00000,0.0000e+000,20.00000,-2.5213e-002,0.57386
757.80499, 87.01250,    -0.75432,74.91350,50.00000,0.0000e+000,20.00000,-2.4942e-002,0.57314
759.60797, 87.19250,    -0.75745,74.90806,50.00000,0.0000e+000,20.00000,-2.4591e-002,0.57241
761.40100, 87.37250,    -0.76030,74.90293,50.00000,0.0000e+000,20.00000,-2.4891e-002,0.57169
763.19702, 87.55250,    -0.76373,74.89899,50.00000,0.0000e+000,20.00000,-2.5949e-002,0.57096
765.01001, 87.73250,    -0.76720,74.89699,50.00000,0.0000e+000,20.00000,-2.6964e-002,0.57024
766.79602, 87.91250,    -0.77175,74.89323,50.00000,0.0000e+000,20.00000,-2.7876e-002,0.56952
768.60699, 88.09250,    -0.77657,74.88804,50.00000,0.0000e+000,20.00000,-2.8729e-002,0.56880
770.40997, 88.27250,    -0.78109,74.88264,50.00000,0.0000e+000,20.00000,-2.9590e-002,0.56809
772.21503, 88.45250,    -0.78625,74.87867,50.00000,0.0000e+000,20.00000,-3.1146e-002,0.56737
774.02301, 88.63250,    -0.79128,74.87369,50.00000,0.0000e+000,20.00000,-3.2133e-002,0.56666
775.84100, 88.81250,    -0.79635,74.86898,50.00000,0.0000e+000,20.00000,-3.2678e-002,0.56594
777.63898, 88.99250,    -0.80050,74.86517,50.00000,0.0000e+000,20.00000,-3.3310e-002,0.56523
779.46399, 89.17250,    -0.80529,74.85914,50.00000,0.0000e+000,20.00000,-3.4091e-002,0.56452
781.29102, 89.35250,    -0.81076,74.85240,50.00000,0.0000e+000,20.00000,-3.5143e-002,0.56381
783.11298, 89.53250,    -0.81532,74.84532,50.00000,0.0000e+000,20.00000,-3.6889e-002,0.56310
784.92999, 89.71250,    -0.81824,74.83721,50.00000,0.0000e+000,20.00000,-3.8130e-002,0.56239
786.71002, 89.89250,    -0.81838,74.82840,50.00000,0.0000e+000,20.00000,-3.8851e-002,0.56170
788.50098, 90.07250,    -0.81878,74.82110,50.00000,0.0000e+000,20.00000,-4.0075e-002,0.56101
790.28302, 90.25250,    -0.81957,74.81350,50.00000,0.0000e+000,20.00000,-4.1829e-002,0.56033
792.05200, 90.43250,    -0.81875,74.80501,50.00000,0.0000e+000,20.00000,-4.3201e-002,0.55965
793.87097, 90.61250,    -0.81928,74.79628,50.00000,0.0000e+000,20.00000,-4.4265e-002,0.55895
795.69000, 90.79250,    -0.82196,74.78831,50.00000,0.0000e+000,20.00000,-4.5536e-002,0.55825
797.50702, 90.97250,    -0.82283,74.78033,50.00000,0.0000e+000,20.00000,-4.6519e-002,0.55756
799.33398, 91.15250,    -0.82253,74.77221,50.00000,0.0000e+000,20.00000,-4.7558e-002,0.55687
801.12500, 91.33250,    -0.82081,74.76385,50.00000,0.0000e+000,20.00000,-4.8396e-002,0.55619
802.90302, 91.51250,    -0.81816,74.75569,50.00000,0.0000e+000,20.00000,-4.9005e-002,0.55552
804.66901, 91.69250,    -0.81521,74.74819,50.00000,0.0000e+000,20.00000,-4.9218e-002,0.55485
806.44598, 91.87250,    -0.81526,74.73854,50.00000,0.0000e+000,20.00000,-4.9903e-002,0.55418
808.25702, 92.05250,    -0.81726,74.72797,50.00000,0.0000e+000,20.00000,-5.0843e-002,0.55350
810.07800, 92.23250,    -0.82119,74.71801,50.00000,0.0000e+000,20.00000,-5.1792e-002,0.55282
811.89502, 92.41250,    -0.82537,74.70914,50.00000,0.0000e+000,20.00000,-5.2896e-002,0.55214
813.69397, 92.59250,    -0.82999,74.70069,50.00000,0.0000e+000,20.00000,-5.4421e-002,0.55147
815.50702, 92.77250,    -0.83484,74.69170,50.00000,0.0000e+000,20.00000,-5.6034e-002,0.55079
817.32599, 92.95250,    -0.84262,74.68116,50.00000,0.0000e+000,20.00000,-5.7507e-002,0.55012
819.13098, 93.13250,    -0.85096,74.67113,50.00000,0.0000e+000,20.00000,-5.8609e-002,0.54945
820.97198, 93.31250,    -0.86125,74.66095,50.00000,0.0000e+000,20.00000,-5.9632e-002,0.54877
822.76501, 93.49250,    -0.86928,74.65122,50.00000,0.0000e+000,20.00000,-6.1098e-002,0.54811
824.58398, 93.67250,    -0.87753,74.64141,50.00000,0.0000e+000,20.00000,-6.2480e-002,0.54744
826.40399, 93.85250,    -0.88385,74.63060,50.00000,0.0000e+000,20.00000,-6.3601e-002,0.54677
828.31799, 94.03250,    -0.89484,74.61896,50.00000,0.0000e+000,20.00000,-6.4512e-002,0.54607
830.19000, 94.21250,    -0.90315,74.60623,50.00000,0.0000e+000,20.00000,-6.5427e-002,0.54538
832.01001, 94.39250,    -0.90434,74.59275,50.00000,0.0000e+000,20.00000,-6.7047e-002,0.54472
833.82300, 94.57250,    -0.90348,74.57886,50.00000,0.0000e+000,20.00000,-6.8896e-002,0.54406
835.62097, 94.75250,    -0.90128,74.56527,50.00000,0.0000e+000,20.00000,-7.0374e-002,0.54340
837.38599, 94.93250,    -0.89978,74.55279,50.00000,0.0000e+000,20.00000,-7.2044e-002,0.54276
839.15399, 95.11250,    -0.89682,74.54077,50.00000,0.0000e+000,20.00000,-7.3576e-002,0.54212
840.93903, 95.29250,    -0.89646,74.52814,50.00000,0.0000e+000,20.00000,-7.5121e-002,0.54148
842.72302, 95.47250,    -0.89514,74.51406,50.00000,0.0000e+000,20.00000,-7.6786e-002,0.54083
844.47601, 95.65250,    -0.89349,74.49931,50.00000,0.0000e+000,20.00000,-7.8212e-002,0.54020
846.23499, 95.83250,    -0.89450,74.48557,50.00000,0.0000e+000,20.00000,-7.9408e-002,0.53957
848.01801, 96.01250,    -0.89608,74.47333,50.00000,0.0000e+000,20.00000,-7.9922e-002,0.53893
849.82599, 96.19250,    -0.89869,74.45923,50.00000,0.0000e+000,20.00000,-8.0571e-002,0.53828
851.62598, 96.37250,    -0.90178,74.44379,50.00000,0.0000e+000,20.00000,-8.1284e-002,0.53763
853.44897, 96.55250,    -0.90537,74.42800,50.00000,0.0000e+000,20.00000,-8.1964e-002,0.53698
855.24902, 96.73250,    -0.90825,74.41184,50.00000,0.0000e+000,20.00000,-8.2650e-002,0.53634
857.06403, 96.91250,    -0.91034,74.39592,50.00000,0.0000e+000,20.00000,-8.4259e-002,0.53569
858.87201, 97.09250,    -0.91262,74.38052,50.00000,0.0000e+000,20.00000,-8.5757e-002,0.53505
860.67102, 97.27250,    -0.91349,74.36476,50.00000,0.0000e+000,20.00000,-8.6233e-002,0.53441
862.48401, 97.45250,    -0.91549,74.34886,50.00000,0.0000e+000,20.00000,-8.6829e-002,0.53377
864.27197, 97.63250,    -0.91838,74.33293,50.00000,0.0000e+000,20.00000,-8.8025e-002,0.53313
866.08600, 97.81250,    -0.92217,74.31834,50.00000,0.0000e+000,20.00000,-8.9132e-002,0.53249
867.89099, 97.99250,    -0.92534,74.30289,50.00000,0.0000e+000,20.00000,-8.9606e-002,0.53185
869.70099, 98.17250,    -0.92746,74.28639,50.00000,0.0000e+000,20.00000,-9.0174e-002,0.53121
871.49597, 98.35250,    -0.93087,74.27012,50.00000,0.0000e+000,20.00000,-9.0480e-002,0.53058
873.30298, 98.53250,    -0.93357,74.25493,50.00000,0.0000e+000,20.00000,-9.0495e-002,0.52995
875.09698, 98.71250,    -0.93585,74.23760,50.00000,0.0000e+000,20.00000,-9.0670e-002,0.52931
876.93402, 98.89250,    -0.94041,74.21921,50.00000,0.0000e+000,20.00000,-9.1048e-002,0.52867
878.74902, 99.07250,    -0.94538,74.20356,50.00000,0.0000e+000,20.00000,-9.1792e-002,0.52803
880.56201, 99.25250,    -0.94981,74.18690,50.00000,0.0000e+000,20.00000,-9.2992e-002,0.52740
882.37402, 99.43250,    -0.95448,74.16859,50.00000,0.0000e+000,20.00000,-9.3962e-002,0.52676
884.21100, 99.61250,    -0.95921,74.15177,50.00000,0.0000e+000,20.00000,-9.4835e-002,0.52612
886.01300, 99.79250,    -0.96137,74.13654,50.00000,0.0000e+000,20.00000,-9.5576e-002,0.52549
887.79602, 99.97250,    -0.96127,74.11929,50.00000,0.0000e+000,20.00000,-9.6354e-002,0.52487
889.58197,100.15250,    -0.96133,74.10221,50.00000,0.0000e+000,20.00000,-9.7307e-002,0.52424
891.38098,100.33250,    -0.96231,74.08609,50.00000,0.0000e+000,20.00000,-9.8516e-002,0.52362
893.21698,100.51250,    -0.96664,74.06944,50.00000,0.0000e+000,20.00000,-9.9457e-002,0.52298
895.03998,100.69250,    -0.97042,74.05275,50.00000,0.0000e+000,20.00000,-9.9847e-002,0.52234
896.93402,100.87250,    -0.97602,74.03466,50.00000,0.0000e+000,20.00000,    -0.10093,0.52169
898.79999,101.05250,    -0.98218,74.01453,50.00000,0.0000e+000,20.00000,    -0.10180,0.52104
900.54303,101.23250,    -0.97619,73.99477,50.00000,0.0000e+000,20.00000,    -0.10222,0.52043
902.28302,101.41250,    -0.96893,73.97657,50.00000,0.0000e+000,20.00000,    -0.10280,0.51983
904.04102,101.59250,    -0.96745,73.95889,50.00000,0.0000e+000,20.00000,    -0.10391,0.51922
905.82300,101.77250,    -0.96788,73.93974,50.00000,0.0000e+000,20.00000,    -0.10487,0.51860
907.60199,101.95250,    -0.96886,73.91994,50.00000,0.0000e+000,20.00000,    -0.10577,0.51799
909.40399,102.13250,    -0.97235,73.90022,50.00000,0.0000e+000,20.00000,    -0.10683,0.51736
911.19397,102.31250,    -0.97428,73.88006,50.00000,0.0000e+000,20.00000,    -0.10786,0.51674
912.99902,102.49250,    -0.97506,73.85995,50.00000,0.0000e+000,20.00000,    -0.10909,0.51612
914.81000,102.67250,    -0.97605,73.84003,50.00000,0.0000e+000,20.00000,    -0.11011,0.51549
916.67999,102.85250,    -0.97904,73.82051,50.00000,0.0000e+000,20.00000,    -0.11048,0.51485
918.58398,103.03250,    -0.98631,73.80081,50.00000,0.0000e+000,20.00000,    -0.11070,0.51419
920.42902,103.21250,    -0.98656,73.78129,50.00000,0.0000e+000,20.00000,    -0.11175,0.51355
922.24799,103.39250,    -0.98271,73.76225,50.00000,0.0000e+000,20.00000,    -0.11309,0.51293
924.02301,103.57250,    -0.97637,73.74187,50.00000,0.0000e+000,20.00000,    -0.11357,0.51231
925.81097,103.75250,    -0.97096,73.72127,50.00000,0.0000e+000,20.00000,    -0.11413,0.51170
927.60699,103.93250,    -0.96639,73.70116,50.00000,0.0000e+000,20.00000,    -0.11538,0.51108
929.40002,104.11250,    -0.96123,73.68095,50.00000,0.0000e+000,20.00000,    -0.11642,0.51046
931.18298,104.29250,    -0.95608,73.65986,50.00000,0.0000e+000,20.00000,    -0.11745,0.50985
932.96503,104.47250,    -0.94995,73.63845,50.00000,0.0000e+000,20.00000,    -0.11873,0.50923
934.75403,104.65250,    -0.94407,73.61703,50.00000,0.0000e+000,20.00000,    -0.11987,0.50862
936.53003,104.83250,    -0.93729,73.59632,50.00000,0.0000e+000,20.00000,    -0.12112,0.50801
938.31500,105.01250,    -0.93003,73.57432,50.00000,0.0000e+000,20.00000,    -0.12221,0.50739
940.09399,105.19250,    -0.92356,73.55167,50.00000,0.0000e+000,20.00000,    -0.12347,0.50678
941.89697,105.37250,    -0.91861,73.53071,50.00000,0.0000e+000,20.00000,    -0.12417,0.50616
943.70502,105.55250,    -0.91573,73.50944,50.00000,0.0000e+000,20.00000,    -0.12441,0.50554
945.52399,105.73250,    -0.91084,73.48525,50.00000,0.0000e+000,20.00000,    -0.12431,0.50491
947.32703,105.91250,    -0.90457,73.46128,50.00000,0.0000e+000,20.00000,    -0.12434,0.50429
949.12500,106.09250,    -0.89814,73.43744,50.00000,0.0000e+000,20.00000,    -0.12466,0.50367
950.90601,106.27250,    -0.89162,73.41285,50.00000,0.0000e+000,20.00000,    -0.12485,0.50306
952.71997,106.45250,    -0.88705,73.38896,50.00000,0.0000e+000,20.00000,    -0.12443,0.50243
954.55298,106.63250,    -0.88433,73.36486,50.00000,0.0000e+000,20.00000,    -0.12366,0.50180
956.38300,106.81250,    -0.88236,73.34111,50.00000,0.0000e+000,20.00000,    -0.12295,0.50117
958.20398,106.99250,    -0.87787,73.31756,50.00000,0.0000e+000,20.00000,    -0.12205,0.50054
960.01898,107.17250,    -0.87082,73.29455,50.00000,0.0000e+000,20.00000,    -0.12147,0.49992
961.92902,107.35250,    -0.87307,73.27290,50.00000,0.0000e+000,20.00000,    -0.12074,0.49926
963.77899,107.53250,    -0.87202,73.25276,50.00000,0.0000e+000,20.00000,    -0.11868,0.49862
965.60303,107.71250,    -0.86715,73.23295,50.00000,0.0000e+000,20.00000,    -0.11602,0.49799
967.37201,107.89250,    -0.85944,73.21087,50.00000,0.0000e+000,20.00000,    -0.11363,0.49738
969.13000,108.07250,    -0.85188,73.18876,50.00000,0.0000e+000,20.00000,    -0.11094,0.49678
970.87402,108.25250,    -0.84796,73.16825,50.00000,0.0000e+000,20.00000,    -0.10834,0.49617
972.64099,108.43250,    -0.84633,73.15034,50.00000,0.0000e+000,20.00000,    -0.10587,0.49556
974.42499,108.61250,    -0.84770,73.13140,50.00000,0.0000e+000,20.00000,    -0.10346,0.49495
976.19702,108.79250,    -0.84864,73.11195,50.00000,0.0000e+000,20.00000,    -0.10097,0.49433
977.97302,108.97250,    -0.84897,73.09272,50.00000,0.0000e+000,20.00000,-9.8136e-002,0.49372
979.74799,109.15250,    -0.85111,73.07432,50.00000,0.0000e+000,20.00000,-9.5733e-002,0.49311
981.53601,109.33250,    -0.85287,73.05756,50.00000,0.0000e+000,20.00000,-9.3824e-002,0.49249
983.35699,109.51250,    -0.85809,73.04306,50.00000,0.0000e+000,20.00000,-9.0449e-002,0.49186
985.16998,109.69250,    -0.86195,73.02813,50.00000,0.0000e+000,20.00000,-8.7770e-002,0.49123
986.96802,109.87250,    -0.86389,73.01332,50.00000,0.0000e+000,20.00000,-8.4953e-002,0.49060
988.78802,110.05250,    -0.86689,72.99887,50.00000,0.0000e+000,20.00000,-8.1018e-002,0.48997
990.60602,110.23250,    -0.86949,72.98393,50.00000,0.0000e+000,20.00000,-7.8935e-002,0.48934
992.40802,110.41250,    -0.87183,72.96884,50.00000,0.0000e+000,20.00000,-7.7871e-002,0.48872
994.21802,110.59250,    -0.87440,72.95424,50.00000,0.0000e+000,20.00000,-7.6387e-002,0.48809
996.02600,110.77250,    -0.87672,72.94120,50.00000,0.0000e+000,20.00000,-7.1137e-002,0.48746
997.82397,110.95250,    -0.87778,72.92815,50.00000,0.0000e+000,20.00000,-6.4875e-002,0.48683
998.27802,110.99750,    -0.87867,72.92568,50.00000,0.0000e+000,20.00000,-1.3404e-002,0.48667