File: book/some_content/DG_ExpDat_OPC9%DC1.csv
#FILE:                       ,OPC9%DC1; 14-1-2025.ngb-ds3
#FORMAT:                     ,NETZSCH5
#IDENTITY:                   ,GEOPOLYMER PASTE
#DECIMAL:                    ,POINT
#SEPARATOR:                  ,COMMA
#MTYPE:                      ,DSC
#INSTRUMENT:                 ,Microlab TU Delft
#PROJECT:                    ,
#DATE/TIME:                  ,17/01/2025 9:15:30 PM
#CORR. FILE:                 ,Blank with cover; 13-1-2025.ngb-bs3
#LABORATORY:                 ,TU Delft Micro Lab
#OPERATOR:                   ,Ahmed
#REMARK:                     ,under Argon atmosphere, 10K/min
#SAMPLE:                     ,OPC9%DC1;17-1-2025
#SAMPLE MASS /mg:            ,37
#MATERIAL:                   ,Geopolymer paste
#REFERENCE:                  ,blank
#REFERENCE MASS /mg:         ,0
#TYPE OF CRUCIBLE:           ,DSC/TG pan Al2O3
#SAMPLE CRUCIBLE MASS /mg:   ,0
#REFERENCE CRUCIBLE MASS /mg:,0
#CORR. CODE:                 ,020
#EXO:                        ,-1
#RANGE:                      ,40/10.0(K/min)/1000
#SEGMENT:                    ,S2/2

##Temp./øC,Time/min,DSC/(mW/mg),Mass/%,Gas Flow(purge1)/(ml/min),Gas Flow(purge2)/(ml/min),Gas Flow(protective)/(ml/min),DTG/(%/min),Sensit./(uV/mW)
 40.21300, 15.02917, 7.8133e-002,97.29084,50.00000,0.0000e+000,20.00000,    -0.28746,1.22665
 40.26600, 15.20917, 7.7885e-002,97.25569,50.00000,0.0000e+000,20.00000,    -0.20686,1.22658
 40.31700, 15.38917, 7.8226e-002,97.22062,50.00000,0.0000e+000,20.00000,    -0.20510,1.22651
 40.40300, 15.56917, 7.8066e-002,97.18404,50.00000,0.0000e+000,20.00000,    -0.20387,1.22639
 40.52900, 15.74917, 7.8548e-002,97.14756,50.00000,0.0000e+000,20.00000,    -0.20441,1.22621
 40.71800, 15.92917, 7.9742e-002,97.11098,50.00000,0.0000e+000,20.00000,    -0.20585,1.22595
 40.95300, 16.10917, 8.1613e-002,97.07504,50.00000,0.0000e+000,20.00000,    -0.20694,1.22563
 41.27200, 16.28917, 8.4032e-002,97.03862,50.00000,0.0000e+000,20.00000,    -0.21052,1.22519
 41.67700, 16.46917, 8.7118e-002,97.00118,50.00000,0.0000e+000,20.00000,    -0.21594,1.22463
 42.14600, 16.64917, 9.0601e-002,96.96227,50.00000,0.0000e+000,20.00000,    -0.22226,1.22398
 42.68700, 16.82917, 9.5123e-002,96.92463,50.00000,0.0000e+000,20.00000,    -0.23171,1.22324
 43.33100, 17.00917, 9.9967e-002,96.88764,50.00000,0.0000e+000,20.00000,    -0.23904,1.22235
 44.03500, 17.18917,     0.10545,96.84862,50.00000,0.0000e+000,20.00000,    -0.24971,1.22138
 44.83200, 17.36917,     0.11163,96.80824,50.00000,0.0000e+000,20.00000,    -0.26216,1.22028
 45.71300, 17.54917,     0.11774,96.76559,50.00000,0.0000e+000,20.00000,    -0.27558,1.21907
 46.69200, 17.72917,     0.12493,96.72070,50.00000,0.0000e+000,20.00000,    -0.29067,1.21772
 47.72100, 17.90917,     0.13232,96.67431,50.00000,0.0000e+000,20.00000,    -0.30954,1.21630
 48.85900, 18.08917,     0.14042,96.62681,50.00000,0.0000e+000,20.00000,    -0.33022,1.21473
 50.07300, 18.26917,     0.14863,96.57657,50.00000,0.0000e+000,20.00000,    -0.35254,1.21306
 51.36700, 18.44917,     0.15789,96.52288,50.00000,0.0000e+000,20.00000,    -0.37768,1.21128
 52.73100, 18.62917,     0.16733,96.46369,50.00000,0.0000e+000,20.00000,    -0.40875,1.20940
 54.16800, 18.80917,     0.17749,96.39786,50.00000,0.0000e+000,20.00000,    -0.44436,1.20742
 55.68400, 18.98917,     0.18861,96.32529,50.00000,0.0000e+000,20.00000,    -0.48164,1.20534
 57.27400, 19.16917,     0.20093,96.24433,50.00000,0.0000e+000,20.00000,    -0.52437,1.20315
 58.94200, 19.34917,     0.21344,96.15916,50.00000,0.0000e+000,20.00000,    -0.57108,1.20086
 60.67000, 19.52917,     0.22719,96.06898,50.00000,0.0000e+000,20.00000,    -0.62176,1.19848
 62.47500, 19.70917,     0.24185,95.96588,50.00000,0.0000e+000,20.00000,    -0.67713,1.19600
 64.34000, 19.88917,     0.25829,95.85463,50.00000,0.0000e+000,20.00000,    -0.73810,1.19344
 66.29100, 20.06917,     0.27578,95.73733,50.00000,0.0000e+000,20.00000,    -0.80495,1.19076
 68.25200, 20.24917,     0.29508,95.60876,50.00000,0.0000e+000,20.00000,    -0.87701,1.18807
 70.28600, 20.42917,     0.31598,95.46114,50.00000,0.0000e+000,20.00000,    -0.95501,1.18528
 72.39100, 20.60917,     0.33900,95.29474,50.00000,0.0000e+000,20.00000,    -1.03870,1.18240
 74.50600, 20.78917,     0.36375,95.12260,50.00000,0.0000e+000,20.00000,    -1.12821,1.17950
 76.67400, 20.96917,     0.39113,94.92898,50.00000,0.0000e+000,20.00000,    -1.22255,1.17654
 78.88900, 21.14917,     0.42090,94.71869,50.00000,0.0000e+000,20.00000,    -1.32252,1.17351
 81.14800, 21.32917,     0.45238,94.49135,50.00000,0.0000e+000,20.00000,    -1.42826,1.17042
 83.43000, 21.50917,     0.48675,94.24595,50.00000,0.0000e+000,20.00000,    -1.53685,1.16731
 85.75600, 21.68917,     0.52382,93.97924,50.00000,0.0000e+000,20.00000,    -1.64968,1.16413
 88.08600, 21.86917,     0.56323,93.68881,50.00000,0.0000e+000,20.00000,    -1.76802,1.16096
 90.45000, 22.04917,     0.60406,93.37586,50.00000,0.0000e+000,20.00000,    -1.88918,1.15774
 92.83400, 22.22917,     0.64754,93.03692,50.00000,0.0000e+000,20.00000,    -2.01027,1.15450
 95.27400, 22.40917,     0.69233,92.67032,50.00000,0.0000e+000,20.00000,    -2.12773,1.15118
 97.69200, 22.58917,     0.73861,92.27601,50.00000,0.0000e+000,20.00000,    -2.24102,1.14790
100.14100, 22.76917,     0.78586,91.85516,50.00000,0.0000e+000,20.00000,    -2.34162,1.14458
102.59600, 22.94917,     0.83341,91.40907,50.00000,0.0000e+000,20.00000,    -2.42836,1.14126
105.05000, 23.12917,     0.88029,90.93723,50.00000,0.0000e+000,20.00000,    -2.49671,1.13794
107.47700, 23.30917,     0.92652,90.44291,50.00000,0.0000e+000,20.00000,    -2.54205,1.13466
109.93200, 23.48917,     0.97226,89.92389,50.00000,0.0000e+000,20.00000,    -2.56052,1.13135
112.38800, 23.66917,     1.01666,89.37913,50.00000,0.0000e+000,20.00000,    -2.55374,1.12804
114.83000, 23.84917,     1.06041,88.81253,50.00000,0.0000e+000,20.00000,    -2.52876,1.12476
117.27300, 24.02917,     1.10061,88.22832,50.00000,0.0000e+000,20.00000,    -2.48842,1.12148
119.71200, 24.20917,     1.13525,87.63407,50.00000,0.0000e+000,20.00000,    -2.43185,1.11821
122.13500, 24.38917,     1.15971,87.04702,50.00000,0.0000e+000,20.00000,    -2.36291,1.11496
124.57700, 24.56917,     1.17471,86.48435,50.00000,0.0000e+000,20.00000,    -2.28250,1.11170
127.00600, 24.74917,     1.17865,85.95359,50.00000,0.0000e+000,20.00000,    -2.19353,1.10845
129.42799, 24.92917,     1.15667,85.47011,50.00000,0.0000e+000,20.00000,    -2.09656,1.10523
131.86301, 25.10917,     1.10212,85.05086,50.00000,0.0000e+000,20.00000,    -1.99191,1.10199
134.29700, 25.28917,     1.01689,84.70826,50.00000,0.0000e+000,20.00000,    -1.87977,1.09875
136.73199, 25.46917,     0.91436,84.43719,50.00000,0.0000e+000,20.00000,    -1.75969,1.09552
139.18500, 25.64917,     0.80972,84.21385,50.00000,0.0000e+000,20.00000,    -1.63225,1.09228
141.62900, 25.82917,     0.71129,84.02166,50.00000,0.0000e+000,20.00000,    -1.49911,1.08904
144.05600, 26.00917,     0.62281,83.86190,50.00000,0.0000e+000,20.00000,    -1.36244,1.08584
146.50600, 26.18917,     0.54439,83.72173,50.00000,0.0000e+000,20.00000,    -1.22630,1.08262
148.92599, 26.36917,     0.47653,83.59654,50.00000,0.0000e+000,20.00000,    -1.09574,1.07944
151.33099, 26.54917,     0.41729,83.47935,50.00000,0.0000e+000,20.00000,    -0.97256,1.07628
153.71201, 26.72917,     0.36609,83.36484,50.00000,0.0000e+000,20.00000,    -0.86072,1.07316
156.06700, 26.90917,     0.32219,83.25574,50.00000,0.0000e+000,20.00000,    -0.76470,1.07009
158.40700, 27.08917,     0.28517,83.15021,50.00000,0.0000e+000,20.00000,    -0.68690,1.06703
160.71201, 27.26917,     0.25290,83.04748,50.00000,0.0000e+000,20.00000,    -0.62839,1.06403
162.98599, 27.44917,     0.22641,82.94916,50.00000,0.0000e+000,20.00000,    -0.58364,1.06108
165.22701, 27.62917,     0.20430,82.85366,50.00000,0.0000e+000,20.00000,    -0.54658,1.05817
167.42900, 27.80917,     0.18617,82.75949,50.00000,0.0000e+000,20.00000,    -0.51768,1.05532
169.61099, 27.98917,     0.17015,82.66722,50.00000,0.0000e+000,20.00000,    -0.49411,1.05250
171.76801, 28.16917,     0.15477,82.57708,50.00000,0.0000e+000,20.00000,    -0.47440,1.04972
173.89101, 28.34917,     0.13845,82.49032,50.00000,0.0000e+000,20.00000,    -0.45681,1.04699
176.00200, 28.52917,     0.12108,82.40702,50.00000,0.0000e+000,20.00000,    -0.43900,1.04428
178.07201, 28.70917,     0.10339,82.32672,50.00000,0.0000e+000,20.00000,    -0.42179,1.04163
180.11800, 28.88917, 8.5853e-002,82.25543,50.00000,0.0000e+000,20.00000,    -0.40609,1.03901
182.16100, 29.06917, 6.9197e-002,82.18831,50.00000,0.0000e+000,20.00000,    -0.39144,1.03640
184.18500, 29.24917, 5.3434e-002,82.12247,50.00000,0.0000e+000,20.00000,    -0.37665,1.03382
186.17101, 29.42917, 3.8149e-002,82.06036,50.00000,0.0000e+000,20.00000,    -0.36187,1.03130
188.15300, 29.60917, 2.3811e-002,82.00129,50.00000,0.0000e+000,20.00000,    -0.34733,1.02878
190.10001, 29.78917, 1.0488e-002,81.94480,50.00000,0.0000e+000,20.00000,    -0.33262,1.02632
192.03200, 29.96917,-2.5778e-003,81.88925,50.00000,0.0000e+000,20.00000,    -0.31815,1.02387
193.94501, 30.14917,-1.4292e-002,81.83545,50.00000,0.0000e+000,20.00000,    -0.30465,1.02146
195.83701, 30.32917,-2.5454e-002,81.78486,50.00000,0.0000e+000,20.00000,    -0.29197,1.01908
197.73100, 30.50917,-3.6344e-002,81.73759,50.00000,0.0000e+000,20.00000,    -0.27950,1.01670
199.59399, 30.68917,-4.6531e-002,81.68967,50.00000,0.0000e+000,20.00000,    -0.26870,1.01436
201.44800, 30.86917,-5.6275e-002,81.63949,50.00000,0.0000e+000,20.00000,    -0.25892,1.01204
203.28400, 31.04917,-6.6041e-002,81.59388,50.00000,0.0000e+000,20.00000,    -0.24907,1.00975
205.10699, 31.22917,-7.5196e-002,81.55182,50.00000,0.0000e+000,20.00000,    -0.24003,1.00748
206.91400, 31.40917,-8.4574e-002,81.51051,50.00000,0.0000e+000,20.00000,    -0.23149,1.00523
208.70799, 31.58917,-9.3520e-002,81.47118,50.00000,0.0000e+000,20.00000,    -0.22317,1.00300
210.50800, 31.76917,    -0.10251,81.43368,50.00000,0.0000e+000,20.00000,    -0.21505,1.00077
212.28300, 31.94917,    -0.11136,81.39553,50.00000,0.0000e+000,20.00000,    -0.20774,0.99857
214.05099, 32.12917,    -0.12030,81.35815,50.00000,0.0000e+000,20.00000,    -0.20093,0.99639
215.83501, 32.30917,    -0.12942,81.32217,50.00000,0.0000e+000,20.00000,    -0.19465,0.99420
217.57300, 32.48917,    -0.13839,81.28870,50.00000,0.0000e+000,20.00000,    -0.18815,0.99206
219.32700, 32.66917,    -0.14785,81.25691,50.00000,0.0000e+000,20.00000,    -0.18090,0.98991
221.07600, 32.84917,    -0.15717,81.22656,50.00000,0.0000e+000,20.00000,    -0.17489,0.98777
222.81700, 33.02917,    -0.16642,81.19678,50.00000,0.0000e+000,20.00000,    -0.16963,0.98564
224.54601, 33.20917,    -0.17550,81.16826,50.00000,0.0000e+000,20.00000,    -0.16469,0.98353
226.28200, 33.38917,    -0.18506,81.14157,50.00000,0.0000e+000,20.00000,    -0.15971,0.98142
228.00000, 33.56917,    -0.19406,81.11574,50.00000,0.0000e+000,20.00000,    -0.15517,0.97934
229.73000, 33.74917,    -0.20279,81.08842,50.00000,0.0000e+000,20.00000,    -0.15071,0.97724
231.44701, 33.92916,    -0.21162,81.06182,50.00000,0.0000e+000,20.00000,    -0.14614,0.97517
233.14999, 34.10917,    -0.22050,81.03695,50.00000,0.0000e+000,20.00000,    -0.14209,0.97311
234.88000, 34.28917,    -0.22845,81.01315,50.00000,0.0000e+000,20.00000,    -0.13851,0.97103
236.59801, 34.46917,    -0.23717,80.98950,50.00000,0.0000e+000,20.00000,    -0.13547,0.96897
238.31300, 34.64917,    -0.24565,80.96500,50.00000,0.0000e+000,20.00000,    -0.13264,0.96691
240.03000, 34.82917,    -0.25348,80.94167,50.00000,0.0000e+000,20.00000,    -0.12994,0.96486
241.73399, 35.00917,    -0.26153,80.91836,50.00000,0.0000e+000,20.00000,    -0.12721,0.96283
243.44299, 35.18917,    -0.26911,80.89640,50.00000,0.0000e+000,20.00000,    -0.12510,0.96079
245.14700, 35.36917,    -0.27711,80.87561,50.00000,0.0000e+000,20.00000,    -0.12337,0.95877
246.87601, 35.54917,    -0.28458,80.85375,50.00000,0.0000e+000,20.00000,    -0.12122,0.95672
248.57500, 35.72917,    -0.29242,80.83289,50.00000,0.0000e+000,20.00000,    -0.11950,0.95471
250.30099, 35.90917,    -0.29993,80.81142,50.00000,0.0000e+000,20.00000,    -0.11841,0.95267
252.01401, 36.08917,    -0.30724,80.79060,50.00000,0.0000e+000,20.00000,    -0.11771,0.95066
253.72800, 36.26917,    -0.31426,80.76969,50.00000,0.0000e+000,20.00000,    -0.11663,0.94865
255.45000, 36.44917,    -0.32108,80.74943,50.00000,0.0000e+000,20.00000,    -0.11505,0.94663
257.16599, 36.62917,    -0.32787,80.72936,50.00000,0.0000e+000,20.00000,    -0.11390,0.94462
258.89499, 36.80917,    -0.33476,80.71039,50.00000,0.0000e+000,20.00000,    -0.11289,0.94261
260.60800, 36.98917,    -0.34130,80.69130,50.00000,0.0000e+000,20.00000,    -0.11208,0.94061
262.32700, 37.16917,    -0.34752,80.67175,50.00000,0.0000e+000,20.00000,    -0.11166,0.93862
264.05301, 37.34917,    -0.35363,80.65262,50.00000,0.0000e+000,20.00000,    -0.11116,0.93662
265.78699, 37.52917,    -0.36008,80.63217,50.00000,0.0000e+000,20.00000,    -0.11084,0.93462
267.49600, 37.70917,    -0.36619,80.61115,50.00000,0.0000e+000,20.00000,    -0.11044,0.93265
269.23099, 37.88917,    -0.37212,80.58971,50.00000,0.0000e+000,20.00000,    -0.11029,0.93066
270.96399, 38.06917,    -0.37773,80.56973,50.00000,0.0000e+000,20.00000,    -0.11047,0.92867
272.70499, 38.24917,    -0.38339,80.55112,50.00000,0.0000e+000,20.00000,    -0.11077,0.92668
274.44601, 38.42916,    -0.38847,80.53183,50.00000,0.0000e+000,20.00000,    -0.11095,0.92470
276.16800, 38.60917,    -0.39408,80.51229,50.00000,0.0000e+000,20.00000,    -0.11142,0.92274
277.91299, 38.78917,    -0.39896,80.49290,50.00000,0.0000e+000,20.00000,    -0.11242,0.92076
279.64401, 38.96917,    -0.40342,80.47372,50.00000,0.0000e+000,20.00000,    -0.11334,0.91880
281.37399, 39.14917,    -0.40743,80.45386,50.00000,0.0000e+000,20.00000,    -0.11415,0.91685
283.11600, 39.32917,    -0.41216,80.43394,50.00000,0.0000e+000,20.00000,    -0.11502,0.91489
284.85199, 39.50917,    -0.41665,80.41411,50.00000,0.0000e+000,20.00000,    -0.11589,0.91294
286.58301, 39.68917,    -0.42188,80.39381,50.00000,0.0000e+000,20.00000,    -0.11677,0.91100
288.32501, 39.86917,    -0.42737,80.37245,50.00000,0.0000e+000,20.00000,    -0.11837,0.90905
290.07401, 40.04917,    -0.43224,80.35085,50.00000,0.0000e+000,20.00000,    -0.12034,0.90710
291.81100, 40.22917,    -0.43731,80.33000,50.00000,0.0000e+000,20.00000,    -0.12169,0.90518
293.56699, 40.40917,    -0.44236,80.30925,50.00000,0.0000e+000,20.00000,    -0.12307,0.90323
295.32700, 40.58917,    -0.44739,80.28699,50.00000,0.0000e+000,20.00000,    -0.12455,0.90129
297.06400, 40.76917,    -0.45157,80.26383,50.00000,0.0000e+000,20.00000,    -0.12623,0.89937
298.83099, 40.94917,    -0.45558,80.24178,50.00000,0.0000e+000,20.00000,    -0.12771,0.89743
300.58801, 41.12917,    -0.46004,80.21865,50.00000,0.0000e+000,20.00000,    -0.12916,0.89551
302.32901, 41.30917,    -0.46429,80.19448,50.00000,0.0000e+000,20.00000,    -0.13116,0.89360
304.09000, 41.48917,    -0.46816,80.17004,50.00000,0.0000e+000,20.00000,    -0.13335,0.89169
305.83600, 41.66917,    -0.47317,80.14406,50.00000,0.0000e+000,20.00000,    -0.13558,0.88979
307.62701, 41.84917,    -0.47933,80.11791,50.00000,0.0000e+000,20.00000,    -0.13820,0.88785
309.41699, 42.02917,    -0.48531,80.09372,50.00000,0.0000e+000,20.00000,    -0.14117,0.88592
311.20901, 42.20917,    -0.49069,80.06922,50.00000,0.0000e+000,20.00000,    -0.14440,0.88399
312.99799, 42.38917,    -0.49463,80.04444,50.00000,0.0000e+000,20.00000,    -0.14729,0.88207
314.78000, 42.56917,    -0.49751,80.01917,50.00000,0.0000e+000,20.00000,    -0.14974,0.88016
316.55600, 42.74917,    -0.50018,79.99397,50.00000,0.0000e+000,20.00000,    -0.15242,0.87826
318.34399, 42.92916,    -0.50204,79.96882,50.00000,0.0000e+000,20.00000,    -0.15507,0.87636
320.10800, 43.10917,    -0.50361,79.94201,50.00000,0.0000e+000,20.00000,    -0.15743,0.87449
321.86600, 43.28917,    -0.50544,79.91392,50.00000,0.0000e+000,20.00000,    -0.15995,0.87263
323.62399, 43.46917,    -0.50654,79.88487,50.00000,0.0000e+000,20.00000,    -0.16268,0.87077
325.37000, 43.64917,    -0.50823,79.85380,50.00000,0.0000e+000,20.00000,    -0.16550,0.86894
327.14301, 43.82917,    -0.50982,79.82210,50.00000,0.0000e+000,20.00000,    -0.16895,0.86708
328.89899, 44.00917,    -0.51187,79.78968,50.00000,0.0000e+000,20.00000,    -0.17237,0.86524
330.67401, 44.18917,    -0.51498,79.75713,50.00000,0.0000e+000,20.00000,    -0.17548,0.86340
332.43201, 44.36917,    -0.51806,79.72488,50.00000,0.0000e+000,20.00000,    -0.17807,0.86157
334.18701, 44.54917,    -0.52148,79.69295,50.00000,0.0000e+000,20.00000,    -0.18054,0.85975
335.97101, 44.72917,    -0.52526,79.66054,50.00000,0.0000e+000,20.00000,    -0.18325,0.85791
337.74399, 44.90917,    -0.52886,79.62777,50.00000,0.0000e+000,20.00000,    -0.18520,0.85609
339.53101, 45.08917,    -0.53316,79.59449,50.00000,0.0000e+000,20.00000,    -0.18695,0.85425
341.31299, 45.26917,    -0.53720,79.55911,50.00000,0.0000e+000,20.00000,    -0.18897,0.85243
343.09100, 45.44917,    -0.54143,79.52249,50.00000,0.0000e+000,20.00000,    -0.18985,0.85062
344.86200, 45.62917,    -0.54649,79.48552,50.00000,0.0000e+000,20.00000,    -0.18877,0.84882
346.62399, 45.80917,    -0.55197,79.44857,50.00000,0.0000e+000,20.00000,    -0.18702,0.84704
348.41901, 45.98917,    -0.55791,79.41229,50.00000,0.0000e+000,20.00000,    -0.18577,0.84522
350.18500, 46.16917,    -0.56471,79.37740,50.00000,0.0000e+000,20.00000,    -0.18494,0.84345
351.96701, 46.34917,    -0.57135,79.34322,50.00000,0.0000e+000,20.00000,    -0.18320,0.84166
353.76001, 46.52917,    -0.57804,79.30826,50.00000,0.0000e+000,20.00000,    -0.18071,0.83987
355.53299, 46.70917,    -0.58605,79.27439,50.00000,0.0000e+000,20.00000,    -0.17784,0.83810
357.30701, 46.88917,    -0.59340,79.24035,50.00000,0.0000e+000,20.00000,    -0.17473,0.83634
359.09601, 47.06917,    -0.60202,79.20431,50.00000,0.0000e+000,20.00000,    -0.17060,0.83457
360.87900, 47.24917,    -0.61082,79.16947,50.00000,0.0000e+000,20.00000,    -0.16591,0.83281
362.64999, 47.42916,    -0.61877,79.14098,50.00000,0.0000e+000,20.00000,    -0.16108,0.83107
364.44101, 47.60917,    -0.62749,79.11512,50.00000,0.0000e+000,20.00000,    -0.15592,0.82931
366.22198, 47.78917,    -0.63628,79.08761,50.00000,0.0000e+000,20.00000,    -0.15094,0.82757
368.00101, 47.96917,    -0.64493,79.05813,50.00000,0.0000e+000,20.00000,    -0.14611,0.82584
369.78799, 48.14917,    -0.65415,79.03193,50.00000,0.0000e+000,20.00000,    -0.14168,0.82411
371.58499, 48.32917,    -0.66242,79.00847,50.00000,0.0000e+000,20.00000,    -0.13700,0.82237
373.37000, 48.50917,    -0.67087,78.98615,50.00000,0.0000e+000,20.00000,    -0.13233,0.82065
375.15601, 48.68917,    -0.67897,78.96428,50.00000,0.0000e+000,20.00000,    -0.12765,0.81894
376.94800, 48.86917,    -0.68661,78.94404,50.00000,0.0000e+000,20.00000,    -0.12212,0.81723
378.73999, 49.04917,    -0.69479,78.92471,50.00000,0.0000e+000,20.00000,    -0.11627,0.81552
380.52701, 49.22917,    -0.70260,78.90524,50.00000,0.0000e+000,20.00000,    -0.11191,0.81382
382.31201, 49.40917,    -0.71008,78.88712,50.00000,0.0000e+000,20.00000,    -0.10862,0.81213
384.09900, 49.58917,    -0.71680,78.86878,50.00000,0.0000e+000,20.00000,    -0.10509,0.81044
385.87900, 49.76917,    -0.72323,78.85129,50.00000,0.0000e+000,20.00000,    -0.10097,0.80877
387.65799, 49.94917,    -0.73073,78.83341,50.00000,0.0000e+000,20.00000,-9.7448e-002,0.80711
389.43799, 50.12917,    -0.73774,78.81555,50.00000,0.0000e+000,20.00000,-9.4070e-002,0.80544
391.23199, 50.30917,    -0.74466,78.79838,50.00000,0.0000e+000,20.00000,-9.0648e-002,0.80378
393.01599, 50.48917,    -0.75159,78.78165,50.00000,0.0000e+000,20.00000,-8.7661e-002,0.80212
394.79700, 50.66917,    -0.75834,78.76581,50.00000,0.0000e+000,20.00000,-8.5359e-002,0.80048
396.58401, 50.84917,    -0.76444,78.75160,50.00000,0.0000e+000,20.00000,-8.3681e-002,0.79884
398.36099, 51.02917,    -0.77037,78.73802,50.00000,0.0000e+000,20.00000,-8.2013e-002,0.79721
400.14301, 51.20917,    -0.77607,78.72430,50.00000,0.0000e+000,20.00000,-8.0624e-002,0.79558
401.92700, 51.38917,    -0.78147,78.71004,50.00000,0.0000e+000,20.00000,-7.9176e-002,0.79396
403.70801, 51.56917,    -0.78720,78.69573,50.00000,0.0000e+000,20.00000,-7.8189e-002,0.79234
405.48700, 51.74917,    -0.79313,78.68150,50.00000,0.0000e+000,20.00000,-7.7787e-002,0.79073
407.26901, 51.92916,    -0.79879,78.66971,50.00000,0.0000e+000,20.00000,-7.7554e-002,0.78913
409.04501, 52.10917,    -0.80510,78.65977,50.00000,0.0000e+000,20.00000,-7.7695e-002,0.78754
410.84299, 52.28917,    -0.81073,78.64892,50.00000,0.0000e+000,20.00000,-7.8705e-002,0.78593
412.63800, 52.46917,    -0.81619,78.63695,50.00000,0.0000e+000,20.00000,-7.9775e-002,0.78433
414.41000, 52.64917,    -0.82018,78.62393,50.00000,0.0000e+000,20.00000,-8.1031e-002,0.78276
416.17899, 52.82917,    -0.82438,78.61038,50.00000,0.0000e+000,20.00000,-8.2745e-002,0.78120
417.96500, 53.00917,    -0.82900,78.59721,50.00000,0.0000e+000,20.00000,-8.4557e-002,0.77963
419.74399, 53.18917,    -0.83289,78.58419,50.00000,0.0000e+000,20.00000,-8.6168e-002,0.77807
421.51501, 53.36917,    -0.83744,78.57041,50.00000,0.0000e+000,20.00000,-8.7882e-002,0.77652
423.29700, 53.54917,    -0.84252,78.55450,50.00000,0.0000e+000,20.00000,-8.9384e-002,0.77497
425.07501, 53.72917,    -0.84788,78.53735,50.00000,0.0000e+000,20.00000,-9.0813e-002,0.77343
426.88800, 53.90917,    -0.85203,78.51988,50.00000,0.0000e+000,20.00000,-9.2492e-002,0.77187
428.67801, 54.08917,    -0.85564,78.49972,50.00000,0.0000e+000,20.00000,-9.3856e-002,0.77033
430.47299, 54.26917,    -0.85802,78.47948,50.00000,0.0000e+000,20.00000,-9.4826e-002,0.76879
432.25699, 54.44917,    -0.85891,78.46049,50.00000,0.0000e+000,20.00000,-9.5276e-002,0.76727
434.02301, 54.62917,    -0.85931,78.44072,50.00000,0.0000e+000,20.00000,-9.5435e-002,0.76576
435.81900, 54.80917,    -0.86096,78.42050,50.00000,0.0000e+000,20.00000,-9.5521e-002,0.76424
437.60999, 54.98917,    -0.86342,78.40033,50.00000,0.0000e+000,20.00000,-9.5498e-002,0.76273
439.41000, 55.16917,    -0.86812,78.37991,50.00000,0.0000e+000,20.00000,-9.4883e-002,0.76122
441.20300, 55.34917,    -0.87529,78.35975,50.00000,0.0000e+000,20.00000,-9.3395e-002,0.75972
443.00500, 55.52917,    -0.88382,78.34196,50.00000,0.0000e+000,20.00000,-9.1730e-002,0.75822
444.80200, 55.70917,    -0.89314,78.32565,50.00000,0.0000e+000,20.00000,-8.9943e-002,0.75672
446.60101, 55.88917,    -0.90233,78.31000,50.00000,0.0000e+000,20.00000,-8.7384e-002,0.75524
448.40799, 56.06917,    -0.90994,78.29454,50.00000,0.0000e+000,20.00000,-8.4161e-002,0.75375
450.17499, 56.24917,    -0.91610,78.27995,50.00000,0.0000e+000,20.00000,-8.1600e-002,0.75230
451.97101, 56.42916,    -0.92146,78.26572,50.00000,0.0000e+000,20.00000,-7.9332e-002,0.75083
453.75299, 56.60917,    -0.92787,78.25213,50.00000,0.0000e+000,20.00000,-7.6893e-002,0.74938
455.53900, 56.78917,    -0.93546,78.23905,50.00000,0.0000e+000,20.00000,-7.4509e-002,0.74793
457.33499, 56.96917,    -0.94407,78.22739,50.00000,0.0000e+000,20.00000,-7.2073e-002,0.74648
459.12500, 57.14917,    -0.95179,78.21734,50.00000,0.0000e+000,20.00000,-6.9958e-002,0.74504
460.92999, 57.32917,    -0.95852,78.20637,50.00000,0.0000e+000,20.00000,-6.7928e-002,0.74359
462.72400, 57.50917,    -0.96448,78.19555,50.00000,0.0000e+000,20.00000,-6.6022e-002,0.74216
464.52499, 57.68917,    -0.96860,78.18506,50.00000,0.0000e+000,20.00000,-6.5085e-002,0.74073
466.30301, 57.86917,    -0.97242,78.17612,50.00000,0.0000e+000,20.00000,-6.4216e-002,0.73933
468.09399, 58.04917,    -0.97618,78.16678,50.00000,0.0000e+000,20.00000,-6.4077e-002,0.73791
469.88400, 58.22917,    -0.98017,78.15560,50.00000,0.0000e+000,20.00000,-6.4021e-002,0.73651
471.66699, 58.40917,    -0.98419,78.14427,50.00000,0.0000e+000,20.00000,-6.3892e-002,0.73512
473.45801, 58.58917,    -0.98837,78.13283,50.00000,0.0000e+000,20.00000,-6.4121e-002,0.73372
475.25800, 58.76917,    -0.99306,78.12143,50.00000,0.0000e+000,20.00000,-6.4767e-002,0.73233
477.06699, 58.94917,    -0.99934,78.10897,50.00000,0.0000e+000,20.00000,-6.5966e-002,0.73093
478.87201, 59.12917,    -1.00355,78.09764,50.00000,0.0000e+000,20.00000,-6.6899e-002,0.72954
480.64401, 59.30917,    -1.00608,78.08846,50.00000,0.0000e+000,20.00000,-6.7906e-002,0.72818
482.43701, 59.48917,    -1.00740,78.07639,50.00000,0.0000e+000,20.00000,-6.9622e-002,0.72682
484.23700, 59.66917,    -1.01134,78.06410,50.00000,0.0000e+000,20.00000,-7.2078e-002,0.72545
486.02600, 59.84917,    -1.01631,78.05023,50.00000,0.0000e+000,20.00000,-7.4141e-002,0.72410
487.83099, 60.02917,    -1.02082,78.03587,50.00000,0.0000e+000,20.00000,-7.5507e-002,0.72274
489.63599, 60.20917,    -1.02405,78.02274,50.00000,0.0000e+000,20.00000,-7.6982e-002,0.72138
491.42401, 60.38917,    -1.02557,78.00879,50.00000,0.0000e+000,20.00000,-7.8730e-002,0.72005
493.20001, 60.56917,    -1.02711,77.99451,50.00000,0.0000e+000,20.00000,-8.0141e-002,0.71873
494.98099, 60.74917,    -1.02863,77.98001,50.00000,0.0000e+000,20.00000,-8.1290e-002,0.71741
496.75601, 60.92916,    -1.03189,77.96573,50.00000,0.0000e+000,20.00000,-8.2878e-002,0.71610
498.55499, 61.10917,    -1.03556,77.95129,50.00000,0.0000e+000,20.00000,-8.5050e-002,0.71478
500.34201, 61.28917,    -1.03965,77.93491,50.00000,0.0000e+000,20.00000,-8.6843e-002,0.71347
502.13800, 61.46917,    -1.04350,77.91665,50.00000,0.0000e+000,20.00000,-8.8723e-002,0.71217
503.94000, 61.64917,    -1.04727,77.89981,50.00000,0.0000e+000,20.00000,-9.0435e-002,0.71086
505.73801, 61.82917,    -1.05105,77.88385,50.00000,0.0000e+000,20.00000,-9.2022e-002,0.70956
507.53400, 62.00917,    -1.05358,77.86727,50.00000,0.0000e+000,20.00000,-9.3469e-002,0.70827
509.32001, 62.18917,    -1.05443,77.84954,50.00000,0.0000e+000,20.00000,-9.5041e-002,0.70699
511.11899, 62.36917,    -1.05719,77.83266,50.00000,0.0000e+000,20.00000,-9.6830e-002,0.70571
512.90100, 62.54917,    -1.06047,77.81650,50.00000,0.0000e+000,20.00000,-9.8749e-002,0.70445
514.69897, 62.72917,    -1.06382,77.79883,50.00000,0.0000e+000,20.00000,    -0.10079,0.70317
516.48602, 62.90917,    -1.06634,77.78179,50.00000,0.0000e+000,20.00000,    -0.10306,0.70192
518.27197, 63.08917,    -1.06878,77.76380,50.00000,0.0000e+000,20.00000,    -0.10496,0.70067
520.06897, 63.26917,    -1.07052,77.74465,50.00000,0.0000e+000,20.00000,    -0.10619,0.69941
521.86700, 63.44917,    -1.07533,77.72509,50.00000,0.0000e+000,20.00000,    -0.10768,0.69816
523.66699, 63.62917,    -1.07864,77.70458,50.00000,0.0000e+000,20.00000,    -0.10969,0.69692
525.45398, 63.80917,    -1.08087,77.68595,50.00000,0.0000e+000,20.00000,    -0.11189,0.69569
527.29498, 63.98917,    -1.08931,77.66669,50.00000,0.0000e+000,20.00000,    -0.11377,0.69443
529.16602, 64.16917,    -1.10253,77.64601,50.00000,0.0000e+000,20.00000,    -0.11574,0.69315
531.04102, 64.34917,    -1.11165,77.62462,50.00000,0.0000e+000,20.00000,    -0.11797,0.69188
532.88800, 64.52917,    -1.11396,77.60287,50.00000,0.0000e+000,20.00000,    -0.11998,0.69063
534.72198, 64.70917,    -1.11171,77.58036,50.00000,0.0000e+000,20.00000,    -0.12230,0.68939
536.50403, 64.88917,    -1.10657,77.55746,50.00000,0.0000e+000,20.00000,    -0.12447,0.68820
538.29498, 65.06917,    -1.10219,77.53474,50.00000,0.0000e+000,20.00000,    -0.12639,0.68700
540.05902, 65.24917,    -1.10029,77.51214,50.00000,0.0000e+000,20.00000,    -0.12801,0.68583
541.83899, 65.42917,    -1.09971,77.48904,50.00000,0.0000e+000,20.00000,    -0.12946,0.68465
543.59497, 65.60917,    -1.10115,77.46467,50.00000,0.0000e+000,20.00000,    -0.13157,0.68349
545.37201, 65.78917,    -1.10279,77.44016,50.00000,0.0000e+000,20.00000,    -0.13377,0.68233
547.12598, 65.96917,    -1.10443,77.41575,50.00000,0.0000e+000,20.00000,    -0.13586,0.68118
548.87402, 66.14917,    -1.10395,77.39165,50.00000,0.0000e+000,20.00000,    -0.13767,0.68004
550.61603, 66.32917,    -1.10581,77.36689,50.00000,0.0000e+000,20.00000,    -0.13932,0.67892
552.38702, 66.50916,    -1.11005,77.34128,50.00000,0.0000e+000,20.00000,    -0.14084,0.67777
554.15503, 66.68916,    -1.11511,77.31568,50.00000,0.0000e+000,20.00000,    -0.14228,0.67664
555.93701, 66.86916,    -1.12059,77.28960,50.00000,0.0000e+000,20.00000,    -0.14352,0.67550
557.72198, 67.04916,    -1.12652,77.26411,50.00000,0.0000e+000,20.00000,    -0.14467,0.67436
559.53400, 67.22916,    -1.13239,77.23850,50.00000,0.0000e+000,20.00000,    -0.14606,0.67321
561.33197, 67.40916,    -1.13627,77.21190,50.00000,0.0000e+000,20.00000,    -0.14748,0.67208
563.11499, 67.58916,    -1.13779,77.18504,50.00000,0.0000e+000,20.00000,    -0.14857,0.67096
564.89203, 67.76917,    -1.13944,77.15698,50.00000,0.0000e+000,20.00000,    -0.14875,0.66985
566.69299, 67.94917,    -1.14156,77.12894,50.00000,0.0000e+000,20.00000,    -0.14937,0.66873
568.47998, 68.12917,    -1.14547,77.10126,50.00000,0.0000e+000,20.00000,    -0.15054,0.66762
570.28400, 68.30917,    -1.14784,77.07333,50.00000,0.0000e+000,20.00000,    -0.15138,0.66650
572.09998, 68.48917,    -1.15070,77.04524,50.00000,0.0000e+000,20.00000,    -0.15177,0.66539
573.90601, 68.66917,    -1.15457,77.01772,50.00000,0.0000e+000,20.00000,    -0.15299,0.66428
575.70203, 68.84917,    -1.16092,76.99096,50.00000,0.0000e+000,20.00000,    -0.15460,0.66319
577.52899, 69.02917,    -1.16560,76.96319,50.00000,0.0000e+000,20.00000,    -0.15547,0.66208
579.33002, 69.20917,    -1.16967,76.93392,50.00000,0.0000e+000,20.00000,    -0.15594,0.66099
581.15698, 69.38917,    -1.17349,76.90501,50.00000,0.0000e+000,20.00000,    -0.15716,0.65990
582.97900, 69.56917,    -1.17769,76.87952,50.00000,0.0000e+000,20.00000,    -0.15801,0.65881
584.80402, 69.74917,    -1.18211,76.85366,50.00000,0.0000e+000,20.00000,    -0.15908,0.65772
586.63300, 69.92917,    -1.18639,76.82499,50.00000,0.0000e+000,20.00000,    -0.16047,0.65663
588.44501, 70.10917,    -1.18886,76.79611,50.00000,0.0000e+000,20.00000,    -0.16172,0.65556
590.26202, 70.28917,    -1.18970,76.76914,50.00000,0.0000e+000,20.00000,    -0.16319,0.65450
592.07898, 70.46917,    -1.19078,76.73928,50.00000,0.0000e+000,20.00000,    -0.16493,0.65343
593.88202, 70.64917,    -1.19336,76.70758,50.00000,0.0000e+000,20.00000,    -0.16686,0.65238
595.69202, 70.82917,    -1.19570,76.67838,50.00000,0.0000e+000,20.00000,    -0.16864,0.65133
597.50098, 71.00916,    -1.19740,76.65061,50.00000,0.0000e+000,20.00000,    -0.17036,0.65029
599.29102, 71.18916,    -1.19872,76.61954,50.00000,0.0000e+000,20.00000,    -0.17185,0.64926
601.10498, 71.36916,    -1.20067,76.58857,50.00000,0.0000e+000,20.00000,    -0.17415,0.64822
602.89899, 71.54916,    -1.20209,76.55672,50.00000,0.0000e+000,20.00000,    -0.17681,0.64720
604.69897, 71.72916,    -1.20476,76.52398,50.00000,0.0000e+000,20.00000,    -0.17888,0.64618
606.50403, 71.90916,    -1.20864,76.49152,50.00000,0.0000e+000,20.00000,    -0.18105,0.64516
608.30902, 72.08916,    -1.21080,76.45825,50.00000,0.0000e+000,20.00000,    -0.18390,0.64414
610.10498, 72.26917,    -1.21260,76.42423,50.00000,0.0000e+000,20.00000,    -0.18619,0.64314
611.91101, 72.44917,    -1.21415,76.39033,50.00000,0.0000e+000,20.00000,    -0.18789,0.64213
613.72998, 72.62917,    -1.21725,76.35647,50.00000,0.0000e+000,20.00000,    -0.19034,0.64112
615.55499, 72.80917,    -1.22191,76.32116,50.00000,0.0000e+000,20.00000,    -0.19348,0.64011
617.37299, 72.98917,    -1.22669,76.28640,50.00000,0.0000e+000,20.00000,    -0.19573,0.63911
619.17499, 73.16917,    -1.22552,76.25200,50.00000,0.0000e+000,20.00000,    -0.19786,0.63812
620.95203, 73.34917,    -1.22230,76.21704,50.00000,0.0000e+000,20.00000,    -0.19996,0.63716
622.74799, 73.52917,    -1.22068,76.18120,50.00000,0.0000e+000,20.00000,    -0.20138,0.63618
624.53302, 73.70917,    -1.22234,76.14437,50.00000,0.0000e+000,20.00000,    -0.20283,0.63522
626.34399, 73.88917,    -1.22642,76.10691,50.00000,0.0000e+000,20.00000,    -0.20495,0.63424
628.15698, 74.06917,    -1.23007,76.06931,50.00000,0.0000e+000,20.00000,    -0.20760,0.63327
629.95898, 74.24917,    -1.23089,76.03147,50.00000,0.0000e+000,20.00000,    -0.21023,0.63231
631.76501, 74.42917,    -1.23169,75.99281,50.00000,0.0000e+000,20.00000,    -0.21314,0.63135
633.55798, 74.60917,    -1.23056,75.95391,50.00000,0.0000e+000,20.00000,    -0.21541,0.63040
635.34302, 74.78917,    -1.23014,75.91488,50.00000,0.0000e+000,20.00000,    -0.21728,0.62946
637.12299, 74.96917,    -1.22882,75.87608,50.00000,0.0000e+000,20.00000,    -0.21934,0.62852
638.92499, 75.14917,    -1.23017,75.83681,50.00000,0.0000e+000,20.00000,    -0.22195,0.62758
640.75800, 75.32917,    -1.23652,75.79859,50.00000,0.0000e+000,20.00000,    -0.22410,0.62663
642.56201, 75.50916,    -1.23896,75.76108,50.00000,0.0000e+000,20.00000,    -0.22558,0.62570
644.41101, 75.68916,    -1.24530,75.72079,50.00000,0.0000e+000,20.00000,    -0.22674,0.62474
646.25000, 75.86916,    -1.25079,75.67736,50.00000,0.0000e+000,20.00000,    -0.22828,0.62380
648.06799, 76.04916,    -1.24819,75.63377,50.00000,0.0000e+000,20.00000,    -0.23047,0.62287
649.82501, 76.22916,    -1.23695,75.58949,50.00000,0.0000e+000,20.00000,    -0.23182,0.62197
651.55103, 76.40916,    -1.22419,75.54578,50.00000,0.0000e+000,20.00000,    -0.23326,0.62110
653.28198, 76.58916,    -1.21946,75.50377,50.00000,0.0000e+000,20.00000,    -0.23489,0.62022
655.04401, 76.76917,    -1.22221,75.46218,50.00000,0.0000e+000,20.00000,    -0.23636,0.61934
656.84302, 76.94917,    -1.22929,75.41801,50.00000,0.0000e+000,20.00000,    -0.23779,0.61844
658.68597, 77.12917,    -1.24284,75.37416,50.00000,0.0000e+000,20.00000,    -0.23925,0.61752
660.54797, 77.30917,    -1.25537,75.33193,50.00000,0.0000e+000,20.00000,    -0.24084,0.61659
662.40503, 77.48917,    -1.25811,75.29027,50.00000,0.0000e+000,20.00000,    -0.24141,0.61568
664.23901, 77.66917,    -1.25483,75.24752,50.00000,0.0000e+000,20.00000,    -0.24067,0.61477
666.03699, 77.84917,    -1.25129,75.20187,50.00000,0.0000e+000,20.00000,    -0.24037,0.61389
667.83698, 78.02917,    -1.24753,75.15798,50.00000,0.0000e+000,20.00000,    -0.24062,0.61301
669.64001, 78.20917,    -1.24703,75.11420,50.00000,0.0000e+000,20.00000,    -0.24122,0.61214
671.45801, 78.38917,    -1.24738,75.06913,50.00000,0.0000e+000,20.00000,    -0.24248,0.61126
673.23401, 78.56917,    -1.24585,75.02485,50.00000,0.0000e+000,20.00000,    -0.24400,0.61040
675.02301, 78.74917,    -1.24300,74.98049,50.00000,0.0000e+000,20.00000,    -0.24478,0.60954
676.81702, 78.92917,    -1.24259,74.93646,50.00000,0.0000e+000,20.00000,    -0.24524,0.60868
678.61200, 79.10917,    -1.24308,74.89322,50.00000,0.0000e+000,20.00000,    -0.24608,0.60783
680.38501, 79.28917,    -1.24304,74.85111,50.00000,0.0000e+000,20.00000,    -0.24694,0.60699
682.18500, 79.46917,    -1.24356,74.81061,50.00000,0.0000e+000,20.00000,    -0.24730,0.60613
683.99402, 79.64917,    -1.24361,74.76862,50.00000,0.0000e+000,20.00000,    -0.24604,0.60528
685.78101, 79.82917,    -1.24168,74.72376,50.00000,0.0000e+000,20.00000,    -0.24487,0.60444
687.57001, 80.00916,    -1.23834,74.67780,50.00000,0.0000e+000,20.00000,    -0.24393,0.60361
689.32501, 80.18916,    -1.23513,74.63102,50.00000,0.0000e+000,20.00000,    -0.24293,0.60279
691.08801, 80.36916,    -1.22814,74.58403,50.00000,0.0000e+000,20.00000,    -0.24209,0.60198
692.87402, 80.54916,    -1.22626,74.53724,50.00000,0.0000e+000,20.00000,    -0.24001,0.60115
694.69702, 80.72916,    -1.23621,74.49136,50.00000,0.0000e+000,20.00000,    -0.23768,0.60031
696.54901, 80.90916,    -1.24604,74.44581,50.00000,0.0000e+000,20.00000,    -0.23571,0.59946
698.40503, 81.08916,    -1.25249,74.40087,50.00000,0.0000e+000,20.00000,    -0.23351,0.59862
700.23102, 81.26917,    -1.25516,74.35692,50.00000,0.0000e+000,20.00000,    -0.23104,0.59779
702.05902, 81.44917,    -1.25307,74.31566,50.00000,0.0000e+000,20.00000,    -0.22761,0.59696
703.87598, 81.62917,    -1.25064,74.27568,50.00000,0.0000e+000,20.00000,    -0.22269,0.59614
705.66699, 81.80917,    -1.24710,74.23560,50.00000,0.0000e+000,20.00000,    -0.21684,0.59534
707.45099, 81.98917,    -1.24596,74.19454,50.00000,0.0000e+000,20.00000,    -0.21032,0.59454
709.25098, 82.16917,    -1.24754,74.15275,50.00000,0.0000e+000,20.00000,    -0.20346,0.59374
711.05603, 82.34917,    -1.24819,74.11549,50.00000,0.0000e+000,20.00000,    -0.19665,0.59293
712.85199, 82.52917,    -1.25104,74.07987,50.00000,0.0000e+000,20.00000,    -0.18988,0.59214
714.66602, 82.70917,    -1.25431,74.04376,50.00000,0.0000e+000,20.00000,    -0.18244,0.59134
716.44397, 82.88917,    -1.25757,74.00895,50.00000,0.0000e+000,20.00000,    -0.17465,0.59056
718.23700, 83.06917,    -1.26075,73.97701,50.00000,0.0000e+000,20.00000,    -0.16753,0.58977
720.03998, 83.24917,    -1.26593,73.94757,50.00000,0.0000e+000,20.00000,    -0.16131,0.58899
721.84302, 83.42917,    -1.27337,73.92071,50.00000,0.0000e+000,20.00000,    -0.15549,0.58821
723.64697, 83.60917,    -1.28008,73.89592,50.00000,0.0000e+000,20.00000,    -0.14950,0.58742
725.44598, 83.78917,    -1.28437,73.87289,50.00000,0.0000e+000,20.00000,    -0.14302,0.58665
727.25800, 83.96917,    -1.28685,73.85089,50.00000,0.0000e+000,20.00000,    -0.13561,0.58587
729.04999, 84.14917,    -1.28748,73.82895,50.00000,0.0000e+000,20.00000,    -0.12951,0.58510
730.84399, 84.32917,    -1.28804,73.80744,50.00000,0.0000e+000,20.00000,    -0.12396,0.58434
732.66199, 84.50916,    -1.28650,73.78848,50.00000,0.0000e+000,20.00000,    -0.11821,0.58356
734.47198, 84.68916,    -1.28564,73.77198,50.00000,0.0000e+000,20.00000,    -0.11227,0.58280
736.28601, 84.86916,    -1.28542,73.75403,50.00000,0.0000e+000,20.00000,    -0.10741,0.58203
738.07599, 85.04916,    -1.28365,73.73508,50.00000,0.0000e+000,20.00000,    -0.10362,0.58128
739.90399, 85.22916,    -1.28268,73.71632,50.00000,0.0000e+000,20.00000,    -0.10033,0.58051
741.74701, 85.40916,    -1.28780,73.69803,50.00000,0.0000e+000,20.00000,-9.7550e-002,0.57974
743.56702, 85.58916,    -1.28934,73.68064,50.00000,0.0000e+000,20.00000,-9.5211e-002,0.57898
745.39099, 85.76917,    -1.28746,73.66557,50.00000,0.0000e+000,20.00000,-9.2293e-002,0.57823
747.21600, 85.94917,    -1.28204,73.64999,50.00000,0.0000e+000,20.00000,-8.9290e-002,0.57747
749.00500, 86.12917,    -1.27696,73.63459,50.00000,0.0000e+000,20.00000,-8.7274e-002,0.57673
750.78998, 86.30917,    -1.27128,73.61947,50.00000,0.0000e+000,20.00000,-8.5710e-002,0.57600
752.60199, 86.48917,    -1.26758,73.60570,50.00000,0.0000e+000,20.00000,-8.4470e-002,0.57526
754.40698, 86.66917,    -1.26440,73.59160,50.00000,0.0000e+000,20.00000,-8.2683e-002,0.57452
756.20001, 86.84917,    -1.26227,73.57556,50.00000,0.0000e+000,20.00000,-8.1135e-002,0.57379
757.99200, 87.02917,    -1.26024,73.56025,50.00000,0.0000e+000,20.00000,-7.9266e-002,0.57306
759.78900, 87.20917,    -1.25816,73.54532,50.00000,0.0000e+000,20.00000,-7.6772e-002,0.57234
761.58600, 87.38917,    -1.25554,73.53047,50.00000,0.0000e+000,20.00000,-7.4983e-002,0.57161
763.37402, 87.56917,    -1.25325,73.51835,50.00000,0.0000e+000,20.00000,-7.4218e-002,0.57089
765.20203, 87.74917,    -1.25497,73.50795,50.00000,0.0000e+000,20.00000,-7.3348e-002,0.57016
767.03101, 87.92917,    -1.25828,73.49385,50.00000,0.0000e+000,20.00000,-7.2460e-002,0.56943
768.83398, 88.10917,    -1.25588,73.47986,50.00000,0.0000e+000,20.00000,-7.1457e-002,0.56871
770.60602, 88.28917,    -1.25069,73.46752,50.00000,0.0000e+000,20.00000,-7.0333e-002,0.56801
772.39600, 88.46917,    -1.24600,73.45648,50.00000,0.0000e+000,20.00000,-6.9535e-002,0.56730
774.22498, 88.64917,    -1.25061,73.44351,50.00000,0.0000e+000,20.00000,-6.7988e-002,0.56658
776.05200, 88.82917,    -1.25511,73.43102,50.00000,0.0000e+000,20.00000,-6.6265e-002,0.56586
777.85797, 89.00916,    -1.25490,73.42166,50.00000,0.0000e+000,20.00000,-6.5112e-002,0.56515
779.65002, 89.18916,    -1.25244,73.41093,50.00000,0.0000e+000,20.00000,-6.3932e-002,0.56445
781.45801, 89.36916,    -1.25082,73.39847,50.00000,0.0000e+000,20.00000,-6.2918e-002,0.56374
783.25403, 89.54916,    -1.25157,73.38620,50.00000,0.0000e+000,20.00000,-6.2783e-002,0.56304
785.05499, 89.72916,    -1.25423,73.37391,50.00000,0.0000e+000,20.00000,-6.1711e-002,0.56234
786.86401, 89.90916,    -1.25465,73.36224,50.00000,0.0000e+000,20.00000,-6.0778e-002,0.56164
788.65399, 90.08916,    -1.25443,73.35212,50.00000,0.0000e+000,20.00000,-6.0520e-002,0.56095
790.43298, 90.26917,    -1.25457,73.34153,50.00000,0.0000e+000,20.00000,-6.0267e-002,0.56027
792.24597, 90.44917,    -1.25701,73.33094,50.00000,0.0000e+000,20.00000,-5.9706e-002,0.55957
794.05103, 90.62917,    -1.26041,73.32180,50.00000,0.0000e+000,20.00000,-5.9176e-002,0.55888
795.84998, 90.80917,    -1.26385,73.31135,50.00000,0.0000e+000,20.00000,-5.9194e-002,0.55819
797.65100, 90.98917,    -1.26737,73.30052,50.00000,0.0000e+000,20.00000,-5.9221e-002,0.55751
799.44897, 91.16917,    -1.26929,73.29128,50.00000,0.0000e+000,20.00000,-5.9103e-002,0.55682
801.24402, 91.34917,    -1.27066,73.28186,50.00000,0.0000e+000,20.00000,-5.8936e-002,0.55614
803.03601, 91.52917,    -1.27314,73.27201,50.00000,0.0000e+000,20.00000,-5.8801e-002,0.55547
804.84900, 91.70917,    -1.27616,73.26154,50.00000,0.0000e+000,20.00000,-5.8961e-002,0.55478
806.66602, 91.88917,    -1.28026,73.24978,50.00000,0.0000e+000,20.00000,-5.9492e-002,0.55410
808.48999, 92.06917,    -1.28300,73.23945,50.00000,0.0000e+000,20.00000,-6.0017e-002,0.55341
810.30499, 92.24917,    -1.28417,73.22907,50.00000,0.0000e+000,20.00000,-6.0345e-002,0.55273
812.09998, 92.42917,    -1.28334,73.21803,50.00000,0.0000e+000,20.00000,-6.1017e-002,0.55206
813.89899, 92.60917,    -1.28408,73.20814,50.00000,0.0000e+000,20.00000,-6.1918e-002,0.55139
815.71802, 92.78917,    -1.28610,73.19803,50.00000,0.0000e+000,20.00000,-6.2825e-002,0.55071
817.57001, 92.96917,    -1.29064,73.18618,50.00000,0.0000e+000,20.00000,-6.4086e-002,0.55003
819.39203, 93.14917,    -1.29271,73.17444,50.00000,0.0000e+000,20.00000,-6.5373e-002,0.54935
821.19202, 93.32917,    -1.29123,73.16271,50.00000,0.0000e+000,20.00000,-6.6738e-002,0.54869
822.99402, 93.50916,    -1.28881,73.15033,50.00000,0.0000e+000,20.00000,-6.7990e-002,0.54802
824.78900, 93.68916,    -1.28547,73.13802,50.00000,0.0000e+000,20.00000,-6.8937e-002,0.54736
826.57501, 93.86916,    -1.28426,73.12576,50.00000,0.0000e+000,20.00000,-7.0709e-002,0.54671
828.35901, 94.04916,    -1.28217,73.11364,50.00000,0.0000e+000,20.00000,-7.2227e-002,0.54605
830.14099, 94.22916,    -1.28151,73.10206,50.00000,0.0000e+000,20.00000,-7.3161e-002,0.54540
831.94598, 94.40916,    -1.28154,73.08890,50.00000,0.0000e+000,20.00000,-7.5268e-002,0.54474
833.76300, 94.58916,    -1.28326,73.07466,50.00000,0.0000e+000,20.00000,-7.7759e-002,0.54408
835.58600, 94.76917,    -1.28653,73.06048,50.00000,0.0000e+000,20.00000,-8.0077e-002,0.54342
837.37903, 94.94917,    -1.28762,73.04664,50.00000,0.0000e+000,20.00000,-8.2351e-002,0.54277
839.19299, 95.12917,    -1.28823,73.03189,50.00000,0.0000e+000,20.00000,-8.4469e-002,0.54211
841.01501, 95.30917,    -1.28751,73.01696,50.00000,0.0000e+000,20.00000,-8.6417e-002,0.54145
842.84302, 95.48917,    -1.28713,73.00207,50.00000,0.0000e+000,20.00000,-8.8368e-002,0.54079
844.64001, 95.66917,    -1.28646,72.98510,50.00000,0.0000e+000,20.00000,-9.0386e-002,0.54014
846.44397, 95.84917,    -1.28671,72.96898,50.00000,0.0000e+000,20.00000,-9.2517e-002,0.53949
848.23798, 96.02917,    -1.28576,72.95465,50.00000,0.0000e+000,20.00000,-9.4751e-002,0.53885
850.06000, 96.20917,    -1.28541,72.93735,50.00000,0.0000e+000,20.00000,-9.7090e-002,0.53820
851.86798, 96.38917,    -1.28396,72.91844,50.00000,0.0000e+000,20.00000,-9.9357e-002,0.53755
853.66199, 96.56917,    -1.28596,72.89849,50.00000,0.0000e+000,20.00000,    -0.10159,0.53691
855.47101, 96.74917,    -1.28589,72.87822,50.00000,0.0000e+000,20.00000,    -0.10345,0.53626
857.25800, 96.92917,    -1.28538,72.85875,50.00000,0.0000e+000,20.00000,    -0.10555,0.53562
859.06799, 97.10917,    -1.28593,72.83937,50.00000,0.0000e+000,20.00000,    -0.10774,0.53498
860.85797, 97.28917,    -1.28456,72.81988,50.00000,0.0000e+000,20.00000,    -0.10965,0.53434
862.65302, 97.46917,    -1.28610,72.80031,50.00000,0.0000e+000,20.00000,    -0.11163,0.53371
864.45898, 97.64917,    -1.28764,72.78032,50.00000,0.0000e+000,20.00000,    -0.11405,0.53307
866.26801, 97.82917,    -1.29058,72.76066,50.00000,0.0000e+000,20.00000,    -0.11652,0.53243
868.07300, 98.00916,    -1.29271,72.73952,50.00000,0.0000e+000,20.00000,    -0.11838,0.53179
869.88000, 98.18916,    -1.29333,72.71719,50.00000,0.0000e+000,20.00000,    -0.12048,0.53115
871.68903, 98.36916,    -1.29640,72.69458,50.00000,0.0000e+000,20.00000,    -0.12183,0.53051
873.49298, 98.54916,    -1.29648,72.67383,50.00000,0.0000e+000,20.00000,    -0.12253,0.52988
875.30103, 98.72916,    -1.29504,72.65201,50.00000,0.0000e+000,20.00000,    -0.12391,0.52924
877.11700, 98.90916,    -1.29691,72.62875,50.00000,0.0000e+000,20.00000,    -0.12556,0.52860
878.90900, 99.08916,    -1.29705,72.60715,50.00000,0.0000e+000,20.00000,    -0.12731,0.52798
880.71399, 99.26917,    -1.29806,72.58355,50.00000,0.0000e+000,20.00000,    -0.12931,0.52734
882.50800, 99.44917,    -1.29871,72.55823,50.00000,0.0000e+000,20.00000,    -0.13064,0.52672
884.31799, 99.62917,    -1.29866,72.53445,50.00000,0.0000e+000,20.00000,    -0.13216,0.52608
886.12097, 99.80917,    -1.29833,72.51138,50.00000,0.0000e+000,20.00000,    -0.13354,0.52545
887.92499, 99.98917,    -1.30084,72.48505,50.00000,0.0000e+000,20.00000,    -0.13445,0.52482
889.72601,100.16917,    -1.30110,72.45988,50.00000,0.0000e+000,20.00000,    -0.13581,0.52419
891.58600,100.34917,    -1.30680,72.43700,50.00000,0.0000e+000,20.00000,    -0.13840,0.52355
893.40802,100.52917,    -1.31048,72.41267,50.00000,0.0000e+000,20.00000,    -0.14072,0.52291
895.24597,100.70917,    -1.31023,72.38730,50.00000,0.0000e+000,20.00000,    -0.14239,0.52227
897.04602,100.88917,    -1.30789,72.36161,50.00000,0.0000e+000,20.00000,    -0.14486,0.52165
898.83698,101.06917,    -1.30478,72.33470,50.00000,0.0000e+000,20.00000,    -0.14703,0.52102
900.63000,101.24917,    -1.30372,72.30961,50.00000,0.0000e+000,20.00000,    -0.14852,0.52040
902.41400,101.42917,    -1.30274,72.28456,50.00000,0.0000e+000,20.00000,    -0.14990,0.51978
904.20398,101.60917,    -1.30334,72.25871,50.00000,0.0000e+000,20.00000,    -0.15168,0.51916
906.00403,101.78917,    -1.30411,72.23317,50.00000,0.0000e+000,20.00000,    -0.15328,0.51854
907.80798,101.96917,    -1.30465,72.20604,50.00000,0.0000e+000,20.00000,    -0.15484,0.51791
909.62000,102.14917,    -1.30739,72.17580,50.00000,0.0000e+000,20.00000,    -0.15641,0.51729
911.41699,102.32917,    -1.30900,72.14565,50.00000,0.0000e+000,20.00000,    -0.15802,0.51667
913.21698,102.50916,    -1.30846,72.11633,50.00000,0.0000e+000,20.00000,    -0.15967,0.51604
915.00702,102.68916,    -1.30903,72.08578,50.00000,0.0000e+000,20.00000,    -0.16152,0.51543
916.81897,102.86916,    -1.31054,72.05465,50.00000,0.0000e+000,20.00000,    -0.16315,0.51480
918.63501,103.04916,    -1.31057,72.02387,50.00000,0.0000e+000,20.00000,    -0.16491,0.51417
920.43201,103.22916,    -1.31127,71.99434,50.00000,0.0000e+000,20.00000,    -0.16692,0.51355
922.22498,103.40916,    -1.31265,71.96540,50.00000,0.0000e+000,20.00000,    -0.16830,0.51293
924.03998,103.58916,    -1.31317,71.93383,50.00000,0.0000e+000,20.00000,    -0.16910,0.51231
925.85199,103.76917,    -1.31501,71.90216,50.00000,0.0000e+000,20.00000,    -0.16967,0.51168
927.66302,103.94917,    -1.31553,71.87321,50.00000,0.0000e+000,20.00000,    -0.17022,0.51106
929.47699,104.12917,    -1.31443,71.84366,50.00000,0.0000e+000,20.00000,    -0.17099,0.51043
931.28802,104.30917,    -1.31244,71.81242,50.00000,0.0000e+000,20.00000,    -0.17232,0.50981
933.09198,104.48917,    -1.30813,71.78030,50.00000,0.0000e+000,20.00000,    -0.17294,0.50919
934.89203,104.66917,    -1.30498,71.74741,50.00000,0.0000e+000,20.00000,    -0.17283,0.50857
936.69897,104.84917,    -1.30159,71.71544,50.00000,0.0000e+000,20.00000,    -0.17333,0.50795
938.52600,105.02917,    -1.29654,71.68329,50.00000,0.0000e+000,20.00000,    -0.17425,0.50732
940.37701,105.20917,    -1.29442,71.65207,50.00000,0.0000e+000,20.00000,    -0.17485,0.50668
942.28003,105.38917,    -1.30123,71.62324,50.00000,0.0000e+000,20.00000,    -0.17407,0.50603
944.10303,105.56917,    -1.29477,71.59489,50.00000,0.0000e+000,20.00000,    -0.17343,0.50540
945.89398,105.74917,    -1.27858,71.56337,50.00000,0.0000e+000,20.00000,    -0.17313,0.50478
947.66400,105.92917,    -1.26614,71.53032,50.00000,0.0000e+000,20.00000,    -0.17290,0.50417
949.45599,106.10917,    -1.25926,71.49624,50.00000,0.0000e+000,20.00000,    -0.17235,0.50356
951.23499,106.28917,    -1.25308,71.46319,50.00000,0.0000e+000,20.00000,    -0.17100,0.50294
953.01801,106.46917,    -1.24805,71.43247,50.00000,0.0000e+000,20.00000,    -0.16822,0.50233
954.82001,106.64917,    -1.24716,71.40010,50.00000,0.0000e+000,20.00000,    -0.16509,0.50171
956.64203,106.82917,    -1.25070,71.36685,50.00000,0.0000e+000,20.00000,    -0.16204,0.50108
958.43500,107.00916,    -1.25018,71.33535,50.00000,0.0000e+000,20.00000,    -0.15881,0.50046
960.21002,107.18916,    -1.24903,71.30691,50.00000,0.0000e+000,20.00000,    -0.15604,0.49985
962.00403,107.36916,    -1.24980,71.27748,50.00000,0.0000e+000,20.00000,    -0.15302,0.49923
963.78198,107.54916,    -1.24972,71.24893,50.00000,0.0000e+000,20.00000,    -0.14875,0.49862
965.58801,107.72916,    -1.25128,71.22082,50.00000,0.0000e+000,20.00000,    -0.14351,0.49800
967.38599,107.90916,    -1.25562,71.19168,50.00000,0.0000e+000,20.00000,    -0.13775,0.49738
969.16803,108.08916,    -1.25560,71.16416,50.00000,0.0000e+000,20.00000,    -0.13202,0.49676
970.94800,108.26917,    -1.25827,71.14074,50.00000,0.0000e+000,20.00000,    -0.12736,0.49615
972.73297,108.44917,    -1.26084,71.12010,50.00000,0.0000e+000,20.00000,    -0.12215,0.49553
974.53699,108.62917,    -1.26664,71.09909,50.00000,0.0000e+000,20.00000,    -0.11601,0.49491
976.33398,108.80917,    -1.26981,71.07924,50.00000,0.0000e+000,20.00000,    -0.10987,0.49429
978.14899,108.98917,    -1.27218,71.05997,50.00000,0.0000e+000,20.00000,    -0.10423,0.49366
979.94897,109.16917,    -1.27554,71.04262,50.00000,0.0000e+000,20.00000,-9.8605e-002,0.49304
981.76202,109.34917,    -1.28006,71.02692,50.00000,0.0000e+000,20.00000,-9.2215e-002,0.49241
983.58002,109.52917,    -1.28421,71.01295,50.00000,0.0000e+000,20.00000,-8.4070e-002,0.49178
985.38800,109.70917,    -1.28652,70.99988,50.00000,0.0000e+000,20.00000,-7.8314e-002,0.49115
987.20599,109.88917,    -1.28973,70.98750,50.00000,0.0000e+000,20.00000,-7.2514e-002,0.49052
989.03699,110.06917,    -1.29351,70.97384,50.00000,0.0000e+000,20.00000,-6.6553e-002,0.48989
990.88000,110.24917,    -1.29794,70.96052,50.00000,0.0000e+000,20.00000,-6.2333e-002,0.48925
992.66998,110.42917,    -1.29626,70.94946,50.00000,0.0000e+000,20.00000,-5.9554e-002,0.48863
994.47198,110.60917,    -1.29446,70.93969,50.00000,0.0000e+000,20.00000,-5.2476e-002,0.48800
996.26099,110.78917,    -1.29344,70.93153,50.00000,0.0000e+000,20.00000,-4.6445e-002,0.48738
998.04102,110.96917,    -1.29179,70.92246,50.00000,0.0000e+000,20.00000,-4.1802e-002,0.48676
998.33301,110.99917,    -1.29329,70.92162,50.00000,0.0000e+000,20.00000,-5.8407e-003,0.48665