File: book/some_content/DG_ExpDat_CEM_III_DC1.csv
#FILE:                       ,CEM_III_DC1; 17-1-2025.ngb-ds3
#FORMAT:                     ,NETZSCH5
#IDENTITY:                   ,CEMIII
#DECIMAL:                    ,POINT
#SEPARATOR:                  ,COMMA
#MTYPE:                      ,DSC
#INSTRUMENT:                 ,Microlab TU Delft
#PROJECT:                    ,
#DATE/TIME:                  ,18/01/2025 1:58:24 PM
#CORR. FILE:                 ,Blank with cover; 13-1-2025.ngb-bs3
#LABORATORY:                 ,TU Delft Micro Lab
#OPERATOR:                   ,Ahmed
#REMARK:                     ,under Argon atmosphere, 10K/min
#SAMPLE:                     ,CEMIIIDC1;18-1-2025
#SAMPLE MASS /mg:            ,32.2
#MATERIAL:                   ,Geopolymer paste
#REFERENCE:                  ,blank
#REFERENCE MASS /mg:         ,0
#TYPE OF CRUCIBLE:           ,DSC/TG pan Al2O3
#SAMPLE CRUCIBLE MASS /mg:   ,0
#REFERENCE CRUCIBLE MASS /mg:,0
#CORR. CODE:                 ,020
#EXO:                        ,-1
#RANGE:                      ,40/10.0(K/min)/1000
#SEGMENT:                    ,S2/2

##Temp./øC,Time/min,DSC/(mW/mg),Mass/%,Gas Flow(purge1)/(ml/min),Gas Flow(purge2)/(ml/min),Gas Flow(protective)/(ml/min),DTG/(%/min),Sensit./(uV/mW)
 45.85000, 18.07167,-3.6934e-003,90.71753,50.00000,0.0000e+000,20.00000,    -0.24031,1.21888
 45.88700, 18.24667,-6.1430e-003,90.67985,50.00000,0.0000e+000,20.00000,    -0.22593,1.21883
 45.98100, 18.42167,-7.7379e-003,90.64815,50.00000,0.0000e+000,20.00000,    -0.21211,1.21870
 46.11700, 18.59667,-7.8168e-003,90.61812,50.00000,0.0000e+000,20.00000,    -0.19838,1.21851
 46.37400, 18.77167,-7.1189e-003,90.58918,50.00000,0.0000e+000,20.00000,    -0.18482,1.21816
 46.73700, 18.94667,-5.5651e-003,90.56591,50.00000,0.0000e+000,20.00000,    -0.17242,1.21766
 47.19600, 19.12167,-2.7840e-003,90.54759,50.00000,0.0000e+000,20.00000,    -0.16305,1.21702
 47.77300, 19.29667, 1.3442e-003,90.53163,50.00000,0.0000e+000,20.00000,    -0.15759,1.21623
 48.45300, 19.47167, 6.1609e-003,90.51645,50.00000,0.0000e+000,20.00000,    -0.15465,1.21529
 49.29600, 19.64667, 1.2509e-002,90.50205,50.00000,0.0000e+000,20.00000,    -0.15422,1.21413
 50.23500, 19.82167, 1.8676e-002,90.48933,50.00000,0.0000e+000,20.00000,    -0.15765,1.21284
 51.28700, 19.99667, 2.7031e-002,90.47634,50.00000,0.0000e+000,20.00000,    -0.16632,1.21139
 52.46200, 20.17167, 3.5802e-002,90.45915,50.00000,0.0000e+000,20.00000,    -0.18058,1.20977
 53.77000, 20.34667, 4.5368e-002,90.43927,50.00000,0.0000e+000,20.00000,    -0.20004,1.20797
 55.20900, 20.52167, 5.5168e-002,90.42039,50.00000,0.0000e+000,20.00000,    -0.22260,1.20599
 56.74600, 20.69667, 6.5991e-002,90.40068,50.00000,0.0000e+000,20.00000,    -0.24780,1.20388
 58.39800, 20.87167, 7.8105e-002,90.37459,50.00000,0.0000e+000,20.00000,    -0.27785,1.20160
 60.14500, 21.04667, 9.0669e-002,90.33811,50.00000,0.0000e+000,20.00000,    -0.31358,1.19920
 62.01300, 21.22167,     0.10403,90.29252,50.00000,0.0000e+000,20.00000,    -0.35673,1.19664
 63.96400, 21.39667,     0.11845,90.24317,50.00000,0.0000e+000,20.00000,    -0.40205,1.19396
 66.01800, 21.57167,     0.13379,90.18805,50.00000,0.0000e+000,20.00000,    -0.44996,1.19114
 68.14600, 21.74667,     0.15049,90.12161,50.00000,0.0000e+000,20.00000,    -0.50096,1.18822
 70.33300, 21.92167,     0.16858,90.04159,50.00000,0.0000e+000,20.00000,    -0.55338,1.18522
 72.64200, 22.09667,     0.18804,89.94709,50.00000,0.0000e+000,20.00000,    -0.60627,1.18205
 74.97000, 22.27167,     0.20923,89.83847,50.00000,0.0000e+000,20.00000,    -0.66037,1.17887
 77.38100, 22.44667,     0.23154,89.72310,50.00000,0.0000e+000,20.00000,    -0.71649,1.17557
 79.88400, 22.62167,     0.25603,89.59906,50.00000,0.0000e+000,20.00000,    -0.77320,1.17215
 82.40800, 22.79667,     0.28148,89.46055,50.00000,0.0000e+000,20.00000,    -0.82970,1.16870
 84.99000, 22.97167,     0.30842,89.29862,50.00000,0.0000e+000,20.00000,    -0.88773,1.16518
 87.62500, 23.14667,     0.33632,89.11859,50.00000,0.0000e+000,20.00000,    -0.94989,1.16159
 90.31800, 23.32167,     0.36489,88.93546,50.00000,0.0000e+000,20.00000,    -1.01882,1.15792
 93.02800, 23.49667,     0.39323,88.74036,50.00000,0.0000e+000,20.00000,    -1.09190,1.15423
 95.77800, 23.67167,     0.42078,88.53718,50.00000,0.0000e+000,20.00000,    -1.16758,1.15050
 98.53500, 23.84667,     0.44660,88.32692,50.00000,0.0000e+000,20.00000,    -1.24574,1.14676
101.32400, 24.02167,     0.47048,88.11180,50.00000,0.0000e+000,20.00000,    -1.32395,1.14298
104.12700, 24.19667,     0.49254,87.89111,50.00000,0.0000e+000,20.00000,    -1.39709,1.13919
106.94000, 24.37167,     0.51261,87.66368,50.00000,0.0000e+000,20.00000,    -1.45777,1.13539
109.73400, 24.54667,     0.53404,87.43008,50.00000,0.0000e+000,20.00000,    -1.49975,1.13162
112.56400, 24.72167,     0.56112,87.18377,50.00000,0.0000e+000,20.00000,    -1.52295,1.12781
115.37600, 24.89667,     0.59484,86.91855,50.00000,0.0000e+000,20.00000,    -1.52997,1.12403
118.17300, 25.07167,     0.63657,86.62790,50.00000,0.0000e+000,20.00000,    -1.52937,1.12027
120.96000, 25.24667,     0.68460,86.30969,50.00000,0.0000e+000,20.00000,    -1.52052,1.11654
123.73700, 25.42167,     0.73605,85.96936,50.00000,0.0000e+000,20.00000,    -1.50703,1.11282
126.51200, 25.59667,     0.78769,85.60579,50.00000,0.0000e+000,20.00000,    -1.49040,1.10911
129.28799, 25.77167,     0.83390,85.22178,50.00000,0.0000e+000,20.00000,    -1.46953,1.10541
132.03000, 25.94667,     0.86718,84.83374,50.00000,0.0000e+000,20.00000,    -1.44557,1.10176
134.76300, 26.12167,     0.87302,84.47192,50.00000,0.0000e+000,20.00000,    -1.41921,1.09813
137.48300, 26.29667,     0.84349,84.16141,50.00000,0.0000e+000,20.00000,    -1.39048,1.09453
140.18600, 26.47167,     0.78328,83.90640,50.00000,0.0000e+000,20.00000,    -1.35817,1.09095
142.91299, 26.64667,     0.71492,83.69216,50.00000,0.0000e+000,20.00000,    -1.32033,1.08735
145.59399, 26.82167,     0.64848,83.50456,50.00000,0.0000e+000,20.00000,    -1.27582,1.08382
148.28900, 26.99667,     0.58739,83.33805,50.00000,0.0000e+000,20.00000,    -1.22166,1.08027
150.95599, 27.17167,     0.53284,83.18656,50.00000,0.0000e+000,20.00000,    -1.15974,1.07677
153.57401, 27.34667,     0.48322,83.03717,50.00000,0.0000e+000,20.00000,    -1.08973,1.07334
156.19400, 27.52167,     0.43945,82.89595,50.00000,0.0000e+000,20.00000,    -1.01227,1.06992
158.77100, 27.69667,     0.40045,82.76336,50.00000,0.0000e+000,20.00000,    -0.93042,1.06656
161.31200, 27.87167,     0.36564,82.63458,50.00000,0.0000e+000,20.00000,    -0.85089,1.06325
163.83400, 28.04667,     0.33494,82.50739,50.00000,0.0000e+000,20.00000,    -0.78253,1.05998
166.30000, 28.22167,     0.30757,82.38411,50.00000,0.0000e+000,20.00000,    -0.72927,1.05678
168.74300, 28.39667,     0.28301,82.26484,50.00000,0.0000e+000,20.00000,    -0.68853,1.05362
171.15401, 28.57167,     0.26044,82.14759,50.00000,0.0000e+000,20.00000,    -0.65504,1.05051
173.53200, 28.74667,     0.23844,82.03589,50.00000,0.0000e+000,20.00000,    -0.62619,1.04745
175.86700, 28.92167,     0.21726,81.92944,50.00000,0.0000e+000,20.00000,    -0.60322,1.04445
178.16600, 29.09667,     0.19694,81.82890,50.00000,0.0000e+000,20.00000,    -0.58180,1.04151
180.44701, 29.27167,     0.17847,81.73472,50.00000,0.0000e+000,20.00000,    -0.56012,1.03859
182.69501, 29.44667,     0.16057,81.64314,50.00000,0.0000e+000,20.00000,    -0.53997,1.03572
184.92200, 29.62167,     0.14450,81.55505,50.00000,0.0000e+000,20.00000,    -0.52117,1.03288
187.09100, 29.79667,     0.12970,81.46940,50.00000,0.0000e+000,20.00000,    -0.50226,1.03013
189.26700, 29.97167,     0.11529,81.38469,50.00000,0.0000e+000,20.00000,    -0.48352,1.02737
191.38600, 30.14667,     0.10063,81.30210,50.00000,0.0000e+000,20.00000,    -0.46556,1.02469
193.48399, 30.32167, 8.5823e-002,81.22346,50.00000,0.0000e+000,20.00000,    -0.44797,1.02204
195.54800, 30.49667, 7.1376e-002,81.15143,50.00000,0.0000e+000,20.00000,    -0.43073,1.01944
197.58701, 30.67167, 5.7832e-002,81.08060,50.00000,0.0000e+000,20.00000,    -0.41487,1.01688
199.61600, 30.84667, 4.4919e-002,81.00775,50.00000,0.0000e+000,20.00000,    -0.40035,1.01433
201.59399, 31.02167, 3.1752e-002,80.93858,50.00000,0.0000e+000,20.00000,    -0.38753,1.01186
203.53500, 31.19667, 2.0045e-002,80.87509,50.00000,0.0000e+000,20.00000,    -0.37527,1.00944
205.48500, 31.37167, 8.3293e-003,80.81348,50.00000,0.0000e+000,20.00000,    -0.36291,1.00701
207.38200, 31.54667,-3.0188e-003,80.75334,50.00000,0.0000e+000,20.00000,    -0.35048,1.00465
209.27901, 31.72167,-1.3309e-002,80.69584,50.00000,0.0000e+000,20.00000,    -0.33822,1.00229
211.14700, 31.89667,-2.3599e-002,80.63992,50.00000,0.0000e+000,20.00000,    -0.32714,0.99998
213.00700, 32.07167,-3.2963e-002,80.58551,50.00000,0.0000e+000,20.00000,    -0.31631,0.99768
214.86099, 32.24667,-4.1846e-002,80.53276,50.00000,0.0000e+000,20.00000,    -0.30566,0.99539
216.69299, 32.42167,-4.9910e-002,80.48207,50.00000,0.0000e+000,20.00000,    -0.29573,0.99314
218.49300, 32.59667,-5.7409e-002,80.43155,50.00000,0.0000e+000,20.00000,    -0.28497,0.99093
220.29100, 32.77167,-6.4487e-002,80.38136,50.00000,0.0000e+000,20.00000,    -0.27479,0.98873
222.06500, 32.94667,-7.2050e-002,80.33258,50.00000,0.0000e+000,20.00000,    -0.26608,0.98656
223.83299, 33.12167,-8.0608e-002,80.28647,50.00000,0.0000e+000,20.00000,    -0.25775,0.98440
225.58200, 33.29667,-8.8839e-002,80.24397,50.00000,0.0000e+000,20.00000,    -0.24964,0.98227
227.30901, 33.47167,-9.8118e-002,80.20395,50.00000,0.0000e+000,20.00000,    -0.24179,0.98017
229.05299, 33.64667,    -0.10778,80.16211,50.00000,0.0000e+000,20.00000,    -0.23465,0.97806
230.77499, 33.82167,    -0.11745,80.11884,50.00000,0.0000e+000,20.00000,    -0.22786,0.97598
232.48801, 33.99667,    -0.12687,80.08110,50.00000,0.0000e+000,20.00000,    -0.22126,0.97391
234.19501, 34.17167,    -0.13604,80.04633,50.00000,0.0000e+000,20.00000,    -0.21506,0.97185
235.88499, 34.34667,    -0.14502,80.01296,50.00000,0.0000e+000,20.00000,    -0.20908,0.96982
237.59801, 34.52167,    -0.15370,79.97962,50.00000,0.0000e+000,20.00000,    -0.20281,0.96777
239.27299, 34.69667,    -0.16224,79.94471,50.00000,0.0000e+000,20.00000,    -0.19611,0.96576
240.93900, 34.87167,    -0.17025,79.91265,50.00000,0.0000e+000,20.00000,    -0.19037,0.96377
242.61800, 35.04667,    -0.17826,79.88088,50.00000,0.0000e+000,20.00000,    -0.18523,0.96177
244.29300, 35.22167,    -0.18589,79.85056,50.00000,0.0000e+000,20.00000,    -0.18099,0.95978
245.98300, 35.39667,    -0.19313,79.82043,50.00000,0.0000e+000,20.00000,    -0.17700,0.95778
247.64200, 35.57167,    -0.20042,79.78986,50.00000,0.0000e+000,20.00000,    -0.17219,0.95581
249.29601, 35.74667,    -0.20719,79.76018,50.00000,0.0000e+000,20.00000,    -0.16815,0.95386
250.95100, 35.92167,    -0.21381,79.73090,50.00000,0.0000e+000,20.00000,    -0.16547,0.95191
252.61301, 36.09667,    -0.22059,79.70255,50.00000,0.0000e+000,20.00000,    -0.16285,0.94995
254.27800, 36.27167,    -0.22739,79.67398,50.00000,0.0000e+000,20.00000,    -0.16009,0.94800
255.93401, 36.44667,    -0.23457,79.64827,50.00000,0.0000e+000,20.00000,    -0.15693,0.94606
257.59399, 36.62167,    -0.24140,79.62252,50.00000,0.0000e+000,20.00000,    -0.15413,0.94412
259.26901, 36.79667,    -0.24834,79.59631,50.00000,0.0000e+000,20.00000,    -0.15182,0.94217
260.92899, 36.97167,    -0.25517,79.57145,50.00000,0.0000e+000,20.00000,    -0.14963,0.94024
262.60101, 37.14667,    -0.26090,79.54566,50.00000,0.0000e+000,20.00000,    -0.14759,0.93830
264.25900, 37.32167,    -0.26766,79.51968,50.00000,0.0000e+000,20.00000,    -0.14522,0.93638
265.92300, 37.49667,    -0.27323,79.49401,50.00000,0.0000e+000,20.00000,    -0.14299,0.93446
267.59601, 37.67167,    -0.27857,79.46811,50.00000,0.0000e+000,20.00000,    -0.14110,0.93254
269.26901, 37.84667,    -0.28439,79.44291,50.00000,0.0000e+000,20.00000,    -0.13901,0.93061
270.94400, 38.02167,    -0.28934,79.41954,50.00000,0.0000e+000,20.00000,    -0.13669,0.92869
272.60001, 38.19667,    -0.29474,79.39675,50.00000,0.0000e+000,20.00000,    -0.13497,0.92680
274.26901, 38.37167,    -0.29986,79.37350,50.00000,0.0000e+000,20.00000,    -0.13386,0.92490
275.93201, 38.54667,    -0.30527,79.35030,50.00000,0.0000e+000,20.00000,    -0.13219,0.92301
277.60101, 38.72167,    -0.31063,79.32709,50.00000,0.0000e+000,20.00000,    -0.13070,0.92111
279.26401, 38.89667,    -0.31578,79.30427,50.00000,0.0000e+000,20.00000,    -0.12941,0.91923
280.95499, 39.07167,    -0.32150,79.28220,50.00000,0.0000e+000,20.00000,    -0.12768,0.91732
282.62601, 39.24667,    -0.32640,79.26044,50.00000,0.0000e+000,20.00000,    -0.12583,0.91544
284.30099, 39.42167,    -0.33102,79.23797,50.00000,0.0000e+000,20.00000,    -0.12454,0.91355
285.97299, 39.59667,    -0.33617,79.21611,50.00000,0.0000e+000,20.00000,    -0.12332,0.91168
287.65900, 39.77167,    -0.34088,79.19581,50.00000,0.0000e+000,20.00000,    -0.12232,0.90980
289.34100, 39.94667,    -0.34552,79.17537,50.00000,0.0000e+000,20.00000,    -0.12174,0.90792
291.02499, 40.12167,    -0.34966,79.15419,50.00000,0.0000e+000,20.00000,    -0.12110,0.90605
292.70700, 40.29667,    -0.35471,79.13346,50.00000,0.0000e+000,20.00000,    -0.12048,0.90418
294.38000, 40.47167,    -0.35911,79.11356,50.00000,0.0000e+000,20.00000,    -0.11977,0.90233
296.07800, 40.64667,    -0.36330,79.09337,50.00000,0.0000e+000,20.00000,    -0.11863,0.90046
297.78101, 40.82167,    -0.36762,79.07297,50.00000,0.0000e+000,20.00000,    -0.11739,0.89858
299.46500, 40.99667,    -0.37189,79.05404,50.00000,0.0000e+000,20.00000,    -0.11650,0.89674
301.16000, 41.17167,    -0.37642,79.03396,50.00000,0.0000e+000,20.00000,    -0.11579,0.89488
302.86700, 41.34667,    -0.38058,79.01242,50.00000,0.0000e+000,20.00000,    -0.11474,0.89302
304.55499, 41.52167,    -0.38503,78.99169,50.00000,0.0000e+000,20.00000,    -0.11406,0.89118
306.25800, 41.69667,    -0.38898,78.97108,50.00000,0.0000e+000,20.00000,    -0.11353,0.88933
307.98099, 41.87167,    -0.39335,78.95045,50.00000,0.0000e+000,20.00000,    -0.11272,0.88747
309.69199, 42.04667,    -0.39668,78.92951,50.00000,0.0000e+000,20.00000,    -0.11227,0.88562
311.40201, 42.22167,    -0.39984,78.90859,50.00000,0.0000e+000,20.00000,    -0.11227,0.88378
313.08899, 42.39667,    -0.40243,78.88883,50.00000,0.0000e+000,20.00000,    -0.11242,0.88197
314.81900, 42.57167,    -0.40627,78.87073,50.00000,0.0000e+000,20.00000,    -0.11200,0.88012
316.52100, 42.74667,    -0.40959,78.85271,50.00000,0.0000e+000,20.00000,    -0.11187,0.87830
318.20599, 42.92167,    -0.41348,78.83338,50.00000,0.0000e+000,20.00000,    -0.11207,0.87651
319.93600, 43.09667,    -0.41711,78.81432,50.00000,0.0000e+000,20.00000,    -0.11179,0.87467
321.64700, 43.27167,    -0.42034,78.79596,50.00000,0.0000e+000,20.00000,    -0.11175,0.87286
323.35101, 43.44667,    -0.42439,78.77761,50.00000,0.0000e+000,20.00000,    -0.11204,0.87106
325.06601, 43.62167,    -0.42816,78.75960,50.00000,0.0000e+000,20.00000,    -0.11236,0.86926
326.78699, 43.79667,    -0.43165,78.74100,50.00000,0.0000e+000,20.00000,    -0.11266,0.86745
328.51599, 43.97167,    -0.43490,78.72093,50.00000,0.0000e+000,20.00000,    -0.11288,0.86564
330.23901, 44.14667,    -0.43833,78.70052,50.00000,0.0000e+000,20.00000,    -0.11296,0.86385
331.94501, 44.32167,    -0.44132,78.68075,50.00000,0.0000e+000,20.00000,    -0.11377,0.86207
333.69699, 44.49667,    -0.44421,78.66205,50.00000,0.0000e+000,20.00000,    -0.11486,0.86026
335.40302, 44.67167,    -0.44700,78.64235,50.00000,0.0000e+000,20.00000,    -0.11608,0.85850
337.14200, 44.84667,    -0.44984,78.62241,50.00000,0.0000e+000,20.00000,    -0.11765,0.85670
338.86099, 45.02167,    -0.45204,78.60170,50.00000,0.0000e+000,20.00000,    -0.11931,0.85494
340.57700, 45.19667,    -0.45406,78.58039,50.00000,0.0000e+000,20.00000,    -0.12128,0.85318
342.30801, 45.37167,    -0.45658,78.55854,50.00000,0.0000e+000,20.00000,    -0.12419,0.85142
344.02600, 45.54667,    -0.45889,78.53682,50.00000,0.0000e+000,20.00000,    -0.12681,0.84967
345.75400, 45.72167,    -0.46112,78.51476,50.00000,0.0000e+000,20.00000,    -0.12830,0.84792
347.49799, 45.89667,    -0.46349,78.49363,50.00000,0.0000e+000,20.00000,    -0.12977,0.84615
349.21899, 46.07167,    -0.46545,78.47256,50.00000,0.0000e+000,20.00000,    -0.13190,0.84442
350.93600, 46.24667,    -0.46733,78.45057,50.00000,0.0000e+000,20.00000,    -0.13463,0.84269
352.66800, 46.42167,    -0.46925,78.42847,50.00000,0.0000e+000,20.00000,    -0.13670,0.84096
354.39999, 46.59667,    -0.47090,78.40373,50.00000,0.0000e+000,20.00000,    -0.13855,0.83923
356.11200, 46.77167,    -0.47293,78.37888,50.00000,0.0000e+000,20.00000,    -0.14047,0.83752
357.82999, 46.94667,    -0.47466,78.35412,50.00000,0.0000e+000,20.00000,    -0.14185,0.83582
359.57199, 47.12167,    -0.47615,78.32666,50.00000,0.0000e+000,20.00000,    -0.14238,0.83410
361.30801, 47.29667,    -0.47804,78.29773,50.00000,0.0000e+000,20.00000,    -0.14273,0.83239
363.04300, 47.47167,    -0.47988,78.27196,50.00000,0.0000e+000,20.00000,    -0.14287,0.83068
364.77802, 47.64667,    -0.48183,78.24688,50.00000,0.0000e+000,20.00000,    -0.14324,0.82898
366.50201, 47.82167,    -0.48370,78.21999,50.00000,0.0000e+000,20.00000,    -0.14432,0.82730
368.22501, 47.99667,    -0.48577,78.19082,50.00000,0.0000e+000,20.00000,    -0.14481,0.82563
369.95001, 48.17167,    -0.48745,78.16326,50.00000,0.0000e+000,20.00000,    -0.14482,0.82395
371.69000, 48.34667,    -0.48962,78.13674,50.00000,0.0000e+000,20.00000,    -0.14413,0.82227
373.42200, 48.52167,    -0.49293,78.10969,50.00000,0.0000e+000,20.00000,    -0.14290,0.82060
375.15701, 48.69667,    -0.49659,78.08261,50.00000,0.0000e+000,20.00000,    -0.14175,0.81894
376.90100, 48.87167,    -0.50019,78.05816,50.00000,0.0000e+000,20.00000,    -0.14001,0.81727
378.64099, 49.04667,    -0.50423,78.03496,50.00000,0.0000e+000,20.00000,    -0.13712,0.81561
380.38901, 49.22167,    -0.50718,78.01217,50.00000,0.0000e+000,20.00000,    -0.13460,0.81395
382.11301, 49.39667,    -0.51068,77.98976,50.00000,0.0000e+000,20.00000,    -0.13266,0.81232
383.86200, 49.57167,    -0.51452,77.96556,50.00000,0.0000e+000,20.00000,    -0.13058,0.81067
385.57501, 49.74667,    -0.51812,77.94114,50.00000,0.0000e+000,20.00000,    -0.12779,0.80906
387.31400, 49.92167,    -0.52275,77.91866,50.00000,0.0000e+000,20.00000,    -0.12489,0.80743
389.04199, 50.09667,    -0.52785,77.89740,50.00000,0.0000e+000,20.00000,    -0.12187,0.80581
390.77701, 50.27167,    -0.53318,77.87655,50.00000,0.0000e+000,20.00000,    -0.11791,0.80420
392.51401, 50.44667,    -0.53854,77.85613,50.00000,0.0000e+000,20.00000,    -0.11394,0.80259
394.24500, 50.62167,    -0.54431,77.83605,50.00000,0.0000e+000,20.00000,    -0.11100,0.80099
396.00500, 50.79667,    -0.55001,77.81718,50.00000,0.0000e+000,20.00000,    -0.10873,0.79937
397.73599, 50.97167,    -0.55524,77.79908,50.00000,0.0000e+000,20.00000,    -0.10639,0.79778
399.48099, 51.14667,    -0.55974,77.78110,50.00000,0.0000e+000,20.00000,    -0.10438,0.79618
401.22699, 51.32167,    -0.56384,77.76312,50.00000,0.0000e+000,20.00000,    -0.10214,0.79459
402.96899, 51.49667,    -0.56706,77.74476,50.00000,0.0000e+000,20.00000,-9.9523e-002,0.79301
404.68600, 51.67167,    -0.57042,77.72660,50.00000,0.0000e+000,20.00000,-9.7753e-002,0.79146
406.42700, 51.84667,    -0.57392,77.70954,50.00000,0.0000e+000,20.00000,-9.7080e-002,0.78989
408.16699, 52.02167,    -0.57728,77.69594,50.00000,0.0000e+000,20.00000,-9.5925e-002,0.78832
409.91000, 52.19667,    -0.58138,77.68405,50.00000,0.0000e+000,20.00000,-9.5027e-002,0.78676
411.63199, 52.37167,    -0.58502,77.66971,50.00000,0.0000e+000,20.00000,-9.4713e-002,0.78523
413.35599, 52.54667,    -0.58879,77.65440,50.00000,0.0000e+000,20.00000,-9.4568e-002,0.78370
415.09000, 52.72167,    -0.59265,77.63974,50.00000,0.0000e+000,20.00000,-9.5230e-002,0.78216
416.82101, 52.89667,    -0.59657,77.62501,50.00000,0.0000e+000,20.00000,-9.6644e-002,0.78064
418.56299, 53.07167,    -0.60042,77.60985,50.00000,0.0000e+000,20.00000,-9.9091e-002,0.77910
420.30399, 53.24667,    -0.60324,77.59481,50.00000,0.0000e+000,20.00000,    -0.10292,0.77758
422.03400, 53.42167,    -0.60612,77.57900,50.00000,0.0000e+000,20.00000,    -0.10794,0.77607
423.76901, 53.59667,    -0.60843,77.56034,50.00000,0.0000e+000,20.00000,    -0.11374,0.77456
425.51001, 53.77167,    -0.60968,77.54229,50.00000,0.0000e+000,20.00000,    -0.12091,0.77305
427.22699, 53.94667,    -0.61064,77.52582,50.00000,0.0000e+000,20.00000,    -0.12951,0.77157
428.99100, 54.12167,    -0.61079,77.50716,50.00000,0.0000e+000,20.00000,    -0.13817,0.77006
430.71899, 54.29667,    -0.60781,77.48819,50.00000,0.0000e+000,20.00000,    -0.14635,0.76858
432.46600, 54.47167,    -0.60167,77.46851,50.00000,0.0000e+000,20.00000,    -0.15409,0.76709
434.20001, 54.64667,    -0.59267,77.44639,50.00000,0.0000e+000,20.00000,    -0.16119,0.76561
435.92599, 54.82167,    -0.58172,77.42145,50.00000,0.0000e+000,20.00000,    -0.16712,0.76415
437.66400, 54.99667,    -0.57000,77.39171,50.00000,0.0000e+000,20.00000,    -0.17203,0.76269
439.38199, 55.17167,    -0.55758,77.35667,50.00000,0.0000e+000,20.00000,    -0.17537,0.76124
441.11499, 55.34667,    -0.54548,77.31865,50.00000,0.0000e+000,20.00000,    -0.17684,0.75979
442.84399, 55.52167,    -0.53518,77.27821,50.00000,0.0000e+000,20.00000,    -0.17724,0.75835
444.61700, 55.69667,    -0.52967,77.23561,50.00000,0.0000e+000,20.00000,    -0.17781,0.75688
446.38199, 55.87167,    -0.52656,77.19124,50.00000,0.0000e+000,20.00000,    -0.17741,0.75542
448.16101, 56.04667,    -0.52554,77.14611,50.00000,0.0000e+000,20.00000,    -0.17583,0.75395
449.91199, 56.22167,    -0.52881,77.10186,50.00000,0.0000e+000,20.00000,    -0.17443,0.75251
451.66199, 56.39667,    -0.53531,77.05990,50.00000,0.0000e+000,20.00000,    -0.17256,0.75108
453.41901, 56.57167,    -0.54572,77.02159,50.00000,0.0000e+000,20.00000,    -0.16981,0.74965
455.14600, 56.74667,    -0.55950,76.98676,50.00000,0.0000e+000,20.00000,    -0.16617,0.74825
456.87299, 56.92167,    -0.57622,76.95665,50.00000,0.0000e+000,20.00000,    -0.16079,0.74685
458.61301, 57.09667,    -0.59377,76.93229,50.00000,0.0000e+000,20.00000,    -0.15391,0.74545
460.34900, 57.27167,    -0.61035,76.91090,50.00000,0.0000e+000,20.00000,    -0.14558,0.74406
462.11301, 57.44667,    -0.62778,76.89141,50.00000,0.0000e+000,20.00000,    -0.13622,0.74265
463.89001, 57.62167,    -0.64301,76.87398,50.00000,0.0000e+000,20.00000,    -0.12730,0.74124
465.68100, 57.79667,    -0.65555,76.85966,50.00000,0.0000e+000,20.00000,    -0.11787,0.73982
467.43500, 57.97167,    -0.66310,76.84624,50.00000,0.0000e+000,20.00000,    -0.10839,0.73843
469.16800, 58.14667,    -0.66835,76.83201,50.00000,0.0000e+000,20.00000,    -0.10006,0.73707
470.85800, 58.32167,    -0.66745,76.81822,50.00000,0.0000e+000,20.00000,-9.2059e-002,0.73575
472.54099, 58.49667,    -0.66758,76.80454,50.00000,0.0000e+000,20.00000,-8.4615e-002,0.73443
474.20700, 58.67167,    -0.66925,76.79065,50.00000,0.0000e+000,20.00000,-7.8029e-002,0.73314
475.89499, 58.84667,    -0.67329,76.77819,50.00000,0.0000e+000,20.00000,-7.3078e-002,0.73183
477.58499, 59.02167,    -0.67923,76.76788,50.00000,0.0000e+000,20.00000,-6.9331e-002,0.73053
479.32700, 59.19667,    -0.68947,76.76034,50.00000,0.0000e+000,20.00000,-6.6181e-002,0.72919
481.08499, 59.37167,    -0.69963,76.75104,50.00000,0.0000e+000,20.00000,-6.3531e-002,0.72785
482.87500, 59.54667,    -0.70767,76.73963,50.00000,0.0000e+000,20.00000,-6.2151e-002,0.72648
484.63199, 59.72167,    -0.71348,76.72992,50.00000,0.0000e+000,20.00000,-6.1327e-002,0.72515
486.38699, 59.89667,    -0.71616,76.71806,50.00000,0.0000e+000,20.00000,-5.9978e-002,0.72382
488.14999, 60.07167,    -0.71790,76.70603,50.00000,0.0000e+000,20.00000,-5.8693e-002,0.72250
489.88199, 60.24667,    -0.71929,76.69642,50.00000,0.0000e+000,20.00000,-5.7750e-002,0.72120
491.64001, 60.42167,    -0.72139,76.68775,50.00000,0.0000e+000,20.00000,-5.6578e-002,0.71989
493.39099, 60.59667,    -0.72444,76.67930,50.00000,0.0000e+000,20.00000,-5.4502e-002,0.71859
495.15399, 60.77167,    -0.72804,76.67054,50.00000,0.0000e+000,20.00000,-5.2776e-002,0.71728
496.89801, 60.94667,    -0.73117,76.66187,50.00000,0.0000e+000,20.00000,-5.2644e-002,0.71600
498.65399, 61.12167,    -0.73332,76.65310,50.00000,0.0000e+000,20.00000,-5.3047e-002,0.71471
500.40302, 61.29667,    -0.73602,76.64350,50.00000,0.0000e+000,20.00000,-5.2219e-002,0.71343
502.16199, 61.47167,    -0.73971,76.63241,50.00000,0.0000e+000,20.00000,-5.1439e-002,0.71215
503.92599, 61.64667,    -0.74357,76.62316,50.00000,0.0000e+000,20.00000,-5.0551e-002,0.71087
505.67599, 61.82167,    -0.74617,76.61391,50.00000,0.0000e+000,20.00000,-4.9095e-002,0.70961
507.42700, 61.99667,    -0.74853,76.60419,50.00000,0.0000e+000,20.00000,-4.7479e-002,0.70835
509.17899, 62.17167,    -0.74922,76.59389,50.00000,0.0000e+000,20.00000,-4.6288e-002,0.70709
510.91101, 62.34667,    -0.74993,76.58623,50.00000,0.0000e+000,20.00000,-4.5896e-002,0.70586
512.63898, 62.52167,    -0.75103,76.58190,50.00000,0.0000e+000,20.00000,-4.5797e-002,0.70463
514.38202, 62.69667,    -0.75508,76.57486,50.00000,0.0000e+000,20.00000,-4.5584e-002,0.70340
516.13501, 62.87167,    -0.75843,76.56597,50.00000,0.0000e+000,20.00000,-4.5321e-002,0.70216
517.88397, 63.04667,    -0.76070,76.55708,50.00000,0.0000e+000,20.00000,-4.4936e-002,0.70094
519.62402, 63.22167,    -0.76297,76.54946,50.00000,0.0000e+000,20.00000,-4.4087e-002,0.69972
521.38202, 63.39667,    -0.76526,76.54217,50.00000,0.0000e+000,20.00000,-4.3483e-002,0.69850
523.13098, 63.57167,    -0.76686,76.53471,50.00000,0.0000e+000,20.00000,-4.3052e-002,0.69729
524.87000, 63.74667,    -0.76886,76.52861,50.00000,0.0000e+000,20.00000,-4.2529e-002,0.69609
526.60303, 63.92167,    -0.77123,76.52475,50.00000,0.0000e+000,20.00000,-4.1720e-002,0.69490
528.35699, 64.09666,    -0.77403,76.51863,50.00000,0.0000e+000,20.00000,-4.1405e-002,0.69370
530.09900, 64.27167,    -0.77663,76.51079,50.00000,0.0000e+000,20.00000,-4.2325e-002,0.69251
531.84998, 64.44666,    -0.77933,76.50252,50.00000,0.0000e+000,20.00000,-4.3439e-002,0.69133
533.60199, 64.62167,    -0.78187,76.49479,50.00000,0.0000e+000,20.00000,-4.3618e-002,0.69014
535.35999, 64.79667,    -0.78404,76.48707,50.00000,0.0000e+000,20.00000,-4.3284e-002,0.68896
537.10199, 64.97166,    -0.78574,76.47961,50.00000,0.0000e+000,20.00000,-4.3447e-002,0.68780
538.86200, 65.14667,    -0.78798,76.47156,50.00000,0.0000e+000,20.00000,-4.4041e-002,0.68662
540.59698, 65.32166,    -0.79021,76.46407,50.00000,0.0000e+000,20.00000,-4.4398e-002,0.68547
542.34998, 65.49667,    -0.79334,76.45641,50.00000,0.0000e+000,20.00000,-4.4633e-002,0.68431
544.09998, 65.67167,    -0.79631,76.44920,50.00000,0.0000e+000,20.00000,-4.5986e-002,0.68316
545.86798, 65.84666,    -0.79961,76.44143,50.00000,0.0000e+000,20.00000,-4.7151e-002,0.68200
547.64203, 66.02167,    -0.80222,76.43298,50.00000,0.0000e+000,20.00000,-4.7509e-002,0.68085
549.39301, 66.19666,    -0.80353,76.42397,50.00000,0.0000e+000,20.00000,-4.7504e-002,0.67971
551.12299, 66.37167,    -0.80342,76.41434,50.00000,0.0000e+000,20.00000,-4.7705e-002,0.67859
552.86499, 66.54667,    -0.80325,76.40619,50.00000,0.0000e+000,20.00000,-4.8042e-002,0.67747
554.59900, 66.72166,    -0.80391,76.39798,50.00000,0.0000e+000,20.00000,-4.8828e-002,0.67635
556.31897, 66.89667,    -0.80486,76.38859,50.00000,0.0000e+000,20.00000,-4.9469e-002,0.67526
558.05902, 67.07166,    -0.80643,76.37948,50.00000,0.0000e+000,20.00000,-4.9769e-002,0.67415
559.78998, 67.24667,    -0.80806,76.37133,50.00000,0.0000e+000,20.00000,-5.0515e-002,0.67305
561.54498, 67.42167,    -0.81182,76.36276,50.00000,0.0000e+000,20.00000,-5.1602e-002,0.67195
563.30298, 67.59666,    -0.81556,76.35322,50.00000,0.0000e+000,20.00000,-5.1999e-002,0.67084
565.06201, 67.77167,    -0.81871,76.34451,50.00000,0.0000e+000,20.00000,-5.1503e-002,0.66974
566.82098, 67.94666,    -0.82040,76.33613,50.00000,0.0000e+000,20.00000,-5.1423e-002,0.66865
568.55902, 68.12167,    -0.82119,76.32775,50.00000,0.0000e+000,20.00000,-5.1649e-002,0.66757
570.27899, 68.29667,    -0.82072,76.31890,50.00000,0.0000e+000,20.00000,-5.2165e-002,0.66651
572.01898, 68.47166,    -0.82151,76.30928,50.00000,0.0000e+000,20.00000,-5.2256e-002,0.66544
573.73999, 68.64667,    -0.82317,76.29860,50.00000,0.0000e+000,20.00000,-5.2846e-002,0.66439
575.47302, 68.82166,    -0.82516,76.28934,50.00000,0.0000e+000,20.00000,-5.3515e-002,0.66333
577.21503, 68.99667,    -0.82680,76.28008,50.00000,0.0000e+000,20.00000,-5.3961e-002,0.66227
578.96198, 69.17167,    -0.82969,76.26861,50.00000,0.0000e+000,20.00000,-5.4090e-002,0.66122
580.71802, 69.34666,    -0.83199,76.25848,50.00000,0.0000e+000,20.00000,-5.4409e-002,0.66016
582.46802, 69.52167,    -0.83410,76.25126,50.00000,0.0000e+000,20.00000,-5.5332e-002,0.65911
584.22302, 69.69666,    -0.83572,76.24427,50.00000,0.0000e+000,20.00000,-5.6151e-002,0.65806
585.99103, 69.87167,    -0.83882,76.23452,50.00000,0.0000e+000,20.00000,-5.6760e-002,0.65701
587.77502, 70.04667,    -0.84234,76.22348,50.00000,0.0000e+000,20.00000,-5.7636e-002,0.65596
589.51501, 70.22166,    -0.84304,76.21437,50.00000,0.0000e+000,20.00000,-5.8702e-002,0.65493
591.28497, 70.39667,    -0.84438,76.20506,50.00000,0.0000e+000,20.00000,-5.9603e-002,0.65390
593.04102, 70.57166,    -0.84628,76.19285,50.00000,0.0000e+000,20.00000,-6.0631e-002,0.65287
594.80798, 70.74667,    -0.84900,76.18187,50.00000,0.0000e+000,20.00000,-6.2363e-002,0.65185
596.54797, 70.92167,    -0.85046,76.17288,50.00000,0.0000e+000,20.00000,-6.3837e-002,0.65084
598.30499, 71.09666,    -0.85178,76.16352,50.00000,0.0000e+000,20.00000,-6.4795e-002,0.64983
600.05701, 71.27167,    -0.85274,76.15165,50.00000,0.0000e+000,20.00000,-6.6494e-002,0.64882
601.81500, 71.44666,    -0.85574,76.13942,50.00000,0.0000e+000,20.00000,-6.8543e-002,0.64782
603.57098, 71.62167,    -0.85802,76.12879,50.00000,0.0000e+000,20.00000,-7.0102e-002,0.64682
605.33301, 71.79667,    -0.85997,76.11762,50.00000,0.0000e+000,20.00000,-7.1182e-002,0.64582
607.08002, 71.97166,    -0.86183,76.10511,50.00000,0.0000e+000,20.00000,-7.2328e-002,0.64483
608.82202, 72.14667,    -0.86281,76.09148,50.00000,0.0000e+000,20.00000,-7.4026e-002,0.64385
610.54999, 72.32166,    -0.86392,76.07788,50.00000,0.0000e+000,20.00000,-7.5007e-002,0.64289
612.29199, 72.49667,    -0.86545,76.06335,50.00000,0.0000e+000,20.00000,-7.5870e-002,0.64192
614.04199, 72.67167,    -0.86724,76.04757,50.00000,0.0000e+000,20.00000,-7.7414e-002,0.64095
615.78400, 72.84666,    -0.86966,76.03212,50.00000,0.0000e+000,20.00000,-7.9305e-002,0.63999
617.54102, 73.02167,    -0.87219,76.01763,50.00000,0.0000e+000,20.00000,-8.0777e-002,0.63902
619.28198, 73.19666,    -0.87558,76.00326,50.00000,0.0000e+000,20.00000,-8.2195e-002,0.63807
621.02502, 73.37167,    -0.87804,75.98928,50.00000,0.0000e+000,20.00000,-8.3964e-002,0.63712
622.78101, 73.54667,    -0.88039,75.97474,50.00000,0.0000e+000,20.00000,-8.4814e-002,0.63616
624.55103, 73.72166,    -0.88586,75.96003,50.00000,0.0000e+000,20.00000,-8.5148e-002,0.63521
626.34100, 73.89667,    -0.89087,75.94567,50.00000,0.0000e+000,20.00000,-8.5785e-002,0.63424
628.10498, 74.07166,    -0.89317,75.93072,50.00000,0.0000e+000,20.00000,-8.6586e-002,0.63330
629.88202, 74.24667,    -0.89511,75.91590,50.00000,0.0000e+000,20.00000,-8.7271e-002,0.63235
631.63098, 74.42167,    -0.89609,75.90058,50.00000,0.0000e+000,20.00000,-8.7671e-002,0.63142
633.39001, 74.59666,    -0.89670,75.88505,50.00000,0.0000e+000,20.00000,-8.8124e-002,0.63049
635.12402, 74.77167,    -0.89747,75.86922,50.00000,0.0000e+000,20.00000,-8.9102e-002,0.62957
636.88300, 74.94666,    -0.89902,75.85225,50.00000,0.0000e+000,20.00000,-8.9901e-002,0.62865
638.65302, 75.12167,    -0.90250,75.83405,50.00000,0.0000e+000,20.00000,-9.1401e-002,0.62772
640.41498, 75.29667,    -0.90778,75.81836,50.00000,0.0000e+000,20.00000,-9.2835e-002,0.62681
642.16901, 75.47166,    -0.90903,75.80572,50.00000,0.0000e+000,20.00000,-9.3860e-002,0.62590
643.90302, 75.64667,    -0.91048,75.79116,50.00000,0.0000e+000,20.00000,-9.4900e-002,0.62500
645.66498, 75.82166,    -0.91211,75.77482,50.00000,0.0000e+000,20.00000,-9.6066e-002,0.62410
647.41101, 75.99667,    -0.91281,75.75824,50.00000,0.0000e+000,20.00000,-9.7731e-002,0.62320
649.15302, 76.17167,    -0.91297,75.74174,50.00000,0.0000e+000,20.00000,-9.9141e-002,0.62232
650.90002, 76.34666,    -0.91446,75.72457,50.00000,0.0000e+000,20.00000,    -0.10049,0.62143
652.65900, 76.52167,    -0.91653,75.70645,50.00000,0.0000e+000,20.00000,    -0.10234,0.62054
654.38300, 76.69666,    -0.91751,75.68870,50.00000,0.0000e+000,20.00000,    -0.10438,0.61967
656.12000, 76.87167,    -0.91850,75.67037,50.00000,0.0000e+000,20.00000,    -0.10621,0.61880
657.85797, 77.04667,    -0.92002,75.65034,50.00000,0.0000e+000,20.00000,    -0.10841,0.61793
659.60400, 77.22166,    -0.92423,75.63164,50.00000,0.0000e+000,20.00000,    -0.11179,0.61706
661.37097, 77.39667,    -0.92739,75.61318,50.00000,0.0000e+000,20.00000,    -0.11507,0.61619
663.12701, 77.57166,    -0.92947,75.59496,50.00000,0.0000e+000,20.00000,    -0.11735,0.61532
664.86700, 77.74667,    -0.92941,75.57464,50.00000,0.0000e+000,20.00000,    -0.11974,0.61446
666.61401, 77.92167,    -0.92963,75.55380,50.00000,0.0000e+000,20.00000,    -0.12316,0.61361
668.36902, 78.09666,    -0.93011,75.53399,50.00000,0.0000e+000,20.00000,    -0.12674,0.61275
670.10498, 78.27167,    -0.93128,75.51233,50.00000,0.0000e+000,20.00000,    -0.13016,0.61191
671.85999, 78.44666,    -0.93176,75.48915,50.00000,0.0000e+000,20.00000,    -0.13341,0.61106
673.60400, 78.62167,    -0.93118,75.46491,50.00000,0.0000e+000,20.00000,    -0.13688,0.61022
675.35797, 78.79667,    -0.93211,75.43978,50.00000,0.0000e+000,20.00000,    -0.13992,0.60938
677.09497, 78.97166,    -0.93459,75.41418,50.00000,0.0000e+000,20.00000,    -0.14255,0.60855
678.87000, 79.14667,    -0.93769,75.38842,50.00000,0.0000e+000,20.00000,    -0.14493,0.60770
680.61798, 79.32166,    -0.93858,75.36384,50.00000,0.0000e+000,20.00000,    -0.14708,0.60687
682.35901, 79.49667,    -0.93829,75.33955,50.00000,0.0000e+000,20.00000,    -0.14883,0.60605
684.10602, 79.67167,    -0.93768,75.31211,50.00000,0.0000e+000,20.00000,    -0.14961,0.60523
685.83600, 79.84666,    -0.93847,75.28226,50.00000,0.0000e+000,20.00000,    -0.15034,0.60442
687.59998, 80.02167,    -0.94175,75.25229,50.00000,0.0000e+000,20.00000,    -0.15097,0.60360
689.37903, 80.19666,    -0.94686,75.22203,50.00000,0.0000e+000,20.00000,    -0.15154,0.60277
691.12701, 80.37167,    -0.95085,75.19205,50.00000,0.0000e+000,20.00000,    -0.15169,0.60196
692.89203, 80.54667,    -0.95312,75.16126,50.00000,0.0000e+000,20.00000,    -0.15123,0.60114
694.63098, 80.72166,    -0.95692,75.13134,50.00000,0.0000e+000,20.00000,    -0.15036,0.60034
696.37000, 80.89667,    -0.95926,75.10345,50.00000,0.0000e+000,20.00000,    -0.14892,0.59955
698.07501, 81.07166,    -0.96248,75.07705,50.00000,0.0000e+000,20.00000,    -0.14643,0.59877
699.84900, 81.24667,    -0.97012,75.05117,50.00000,0.0000e+000,20.00000,    -0.14308,0.59796
701.63202, 81.42167,    -0.97881,75.02635,50.00000,0.0000e+000,20.00000,    -0.13857,0.59715
703.42603, 81.59666,    -0.98551,75.00337,50.00000,0.0000e+000,20.00000,    -0.13256,0.59634
705.20697, 81.77167,    -0.98922,74.98068,50.00000,0.0000e+000,20.00000,    -0.12631,0.59554
706.96698, 81.94666,    -0.99168,74.95678,50.00000,0.0000e+000,20.00000,    -0.11982,0.59476
708.72900, 82.12167,    -0.99455,74.93195,50.00000,0.0000e+000,20.00000,    -0.11345,0.59397
710.47400, 82.29667,    -0.99865,74.90835,50.00000,0.0000e+000,20.00000,    -0.10699,0.59319
712.24200, 82.47166,    -1.00321,74.88573,50.00000,0.0000e+000,20.00000,    -0.10033,0.59241
713.99597, 82.64667,    -1.01069,74.86420,50.00000,0.0000e+000,20.00000,-9.4162e-002,0.59164
715.75897, 82.82166,    -1.02204,74.84579,50.00000,0.0000e+000,20.00000,-8.7827e-002,0.59086
717.50299, 82.99667,    -1.03272,74.83240,50.00000,0.0000e+000,20.00000,-8.2351e-002,0.59010
719.24500, 83.17167,    -1.04089,74.82204,50.00000,0.0000e+000,20.00000,-7.7444e-002,0.58934
720.99200, 83.34666,    -1.05036,74.81416,50.00000,0.0000e+000,20.00000,-7.2926e-002,0.58857
722.73602, 83.52167,    -1.05776,74.80703,50.00000,0.0000e+000,20.00000,-6.8966e-002,0.58782
724.47998, 83.69666,    -1.06388,74.80030,50.00000,0.0000e+000,20.00000,-6.4803e-002,0.58707
726.23798, 83.87167,    -1.06950,74.79376,50.00000,0.0000e+000,20.00000,-5.9017e-002,0.58631
728.00201, 84.04667,    -1.07319,74.78685,50.00000,0.0000e+000,20.00000,-5.3824e-002,0.58555
729.73102, 84.22166,    -1.07612,74.78042,50.00000,0.0000e+000,20.00000,-4.9934e-002,0.58481
731.47601, 84.39667,    -1.07818,74.77392,50.00000,0.0000e+000,20.00000,-4.6430e-002,0.58407
733.21600, 84.57166,    -1.07898,74.76922,50.00000,0.0000e+000,20.00000,-4.3145e-002,0.58333
734.97302, 84.74667,    -1.08195,74.76471,50.00000,0.0000e+000,20.00000,-4.0169e-002,0.58259
736.74298, 84.92167,    -1.08944,74.75731,50.00000,0.0000e+000,20.00000,-3.8485e-002,0.58184
738.54498, 85.09666,    -1.09767,74.75011,50.00000,0.0000e+000,20.00000,-3.7909e-002,0.58108
740.35400, 85.27167,    -1.10392,74.74249,50.00000,0.0000e+000,20.00000,-3.7959e-002,0.58032
742.11603, 85.44666,    -1.10762,74.73386,50.00000,0.0000e+000,20.00000,-3.8441e-002,0.57959
743.90802, 85.62167,    -1.11084,74.72844,50.00000,0.0000e+000,20.00000,-3.8942e-002,0.57884
745.66803, 85.79667,    -1.11352,74.72478,50.00000,0.0000e+000,20.00000,-3.8529e-002,0.57811
747.41302, 85.97166,    -1.11417,74.71732,50.00000,0.0000e+000,20.00000,-3.8300e-002,0.57739
749.14600, 86.14667,    -1.11436,74.70786,50.00000,0.0000e+000,20.00000,-3.8861e-002,0.57667
750.89203, 86.32166,    -1.11398,74.69899,50.00000,0.0000e+000,20.00000,-3.9831e-002,0.57596
752.62097, 86.49667,    -1.11531,74.69270,50.00000,0.0000e+000,20.00000,-4.1016e-002,0.57525
754.35797, 86.67167,    -1.11862,74.68840,50.00000,0.0000e+000,20.00000,-4.1059e-002,0.57454
756.10602, 86.84666,    -1.12323,74.68188,50.00000,0.0000e+000,20.00000,-4.1646e-002,0.57383
757.85199, 87.02167,    -1.12904,74.67489,50.00000,0.0000e+000,20.00000,-4.2097e-002,0.57312
759.59802, 87.19666,    -1.13416,74.66673,50.00000,0.0000e+000,20.00000,-4.1673e-002,0.57241
761.32703, 87.37167,    -1.13878,74.65773,50.00000,0.0000e+000,20.00000,-4.2001e-002,0.57172
763.07898, 87.54667,    -1.14263,74.65115,50.00000,0.0000e+000,20.00000,-4.3827e-002,0.57101
764.82599, 87.72166,    -1.14802,74.64618,50.00000,0.0000e+000,20.00000,-4.5063e-002,0.57031
766.57001, 87.89667,    -1.15434,74.63876,50.00000,0.0000e+000,20.00000,-4.5389e-002,0.56961
768.32202, 88.07166,    -1.16054,74.62952,50.00000,0.0000e+000,20.00000,-4.5486e-002,0.56892
770.07501, 88.24667,    -1.16539,74.62043,50.00000,0.0000e+000,20.00000,-4.5562e-002,0.56822
771.81799, 88.42167,    -1.17273,74.61377,50.00000,0.0000e+000,20.00000,-4.6902e-002,0.56753
773.56897, 88.59666,    -1.17851,74.60555,50.00000,0.0000e+000,20.00000,-4.8618e-002,0.56684
775.32098, 88.77167,    -1.18338,74.59569,50.00000,0.0000e+000,20.00000,-4.9871e-002,0.56615
777.05298, 88.94666,    -1.18879,74.58839,50.00000,0.0000e+000,20.00000,-5.0786e-002,0.56546
778.79901, 89.12167,    -1.19421,74.58079,50.00000,0.0000e+000,20.00000,-5.1452e-002,0.56478
780.56799, 89.29667,    -1.20206,74.57114,50.00000,0.0000e+000,20.00000,-5.2222e-002,0.56409
782.34601, 89.47166,    -1.21081,74.56082,50.00000,0.0000e+000,20.00000,-5.3546e-002,0.56340
784.11401, 89.64667,    -1.21726,74.55067,50.00000,0.0000e+000,20.00000,-5.4689e-002,0.56271
785.88702, 89.82166,    -1.22166,74.54068,50.00000,0.0000e+000,20.00000,-5.5469e-002,0.56202
787.65399, 89.99667,    -1.22445,74.53187,50.00000,0.0000e+000,20.00000,-5.6166e-002,0.56134
789.40900, 90.17167,    -1.22750,74.52363,50.00000,0.0000e+000,20.00000,-5.7390e-002,0.56066
791.18298, 90.34666,    -1.23094,74.51262,50.00000,0.0000e+000,20.00000,-5.8783e-002,0.55998
792.93799, 90.52167,    -1.23034,74.50064,50.00000,0.0000e+000,20.00000,-5.9384e-002,0.55931
794.68402, 90.69666,    -1.23097,74.48979,50.00000,0.0000e+000,20.00000,-6.0370e-002,0.55864
796.42603, 90.87167,    -1.23209,74.47861,50.00000,0.0000e+000,20.00000,-6.1547e-002,0.55797
798.18799, 91.04667,    -1.23230,74.46740,50.00000,0.0000e+000,20.00000,-6.2527e-002,0.55730
799.92902, 91.22166,    -1.23317,74.45721,50.00000,0.0000e+000,20.00000,-6.3211e-002,0.55664
801.68103, 91.39667,    -1.23460,74.44714,50.00000,0.0000e+000,20.00000,-6.3354e-002,0.55598
803.44299, 91.57166,    -1.23552,74.43627,50.00000,0.0000e+000,20.00000,-6.3490e-002,0.55531
805.19501, 91.74667,    -1.23811,74.42426,50.00000,0.0000e+000,20.00000,-6.4070e-002,0.55465
806.95697, 91.92167,    -1.24083,74.41218,50.00000,0.0000e+000,20.00000,-6.5677e-002,0.55399
808.71503, 92.09666,    -1.24458,74.40004,50.00000,0.0000e+000,20.00000,-6.6750e-002,0.55333
810.46399, 92.27167,    -1.24721,74.38825,50.00000,0.0000e+000,20.00000,-6.7126e-002,0.55267
812.22601, 92.44666,    -1.25016,74.37590,50.00000,0.0000e+000,20.00000,-6.7618e-002,0.55201
813.95398, 92.62167,    -1.25561,74.36454,50.00000,0.0000e+000,20.00000,-6.8647e-002,0.55137
815.71002, 92.79667,    -1.26188,74.35273,50.00000,0.0000e+000,20.00000,-7.0054e-002,0.55072
817.46100, 92.97166,    -1.26875,74.33976,50.00000,0.0000e+000,20.00000,-7.1576e-002,0.55007
819.21301, 93.14667,    -1.27952,74.32822,50.00000,0.0000e+000,20.00000,-7.3023e-002,0.54942
820.96997, 93.32166,    -1.28907,74.31776,50.00000,0.0000e+000,20.00000,-7.4182e-002,0.54877
822.70099, 93.49667,    -1.29852,74.30674,50.00000,0.0000e+000,20.00000,-7.5075e-002,0.54813
824.46002, 93.67167,    -1.30699,74.29379,50.00000,0.0000e+000,20.00000,-7.5966e-002,0.54748
826.21002, 93.84666,    -1.31394,74.27974,50.00000,0.0000e+000,20.00000,-7.7060e-002,0.54684
827.97498, 94.02167,    -1.32200,74.26642,50.00000,0.0000e+000,20.00000,-7.7993e-002,0.54619
829.73700, 94.19666,    -1.32786,74.25320,50.00000,0.0000e+000,20.00000,-7.8304e-002,0.54555
831.48499, 94.37167,    -1.33025,74.23955,50.00000,0.0000e+000,20.00000,-7.9164e-002,0.54491
833.24103, 94.54667,    -1.33312,74.22364,50.00000,0.0000e+000,20.00000,-8.0536e-002,0.54427
835.00702, 94.72166,    -1.33657,74.20705,50.00000,0.0000e+000,20.00000,-8.1529e-002,0.54363
836.78601, 94.89667,    -1.34269,74.19142,50.00000,0.0000e+000,20.00000,-8.2814e-002,0.54298
838.54401, 95.07166,    -1.34528,74.17658,50.00000,0.0000e+000,20.00000,-8.4585e-002,0.54234
840.29498, 95.24667,    -1.34480,74.16181,50.00000,0.0000e+000,20.00000,-8.6129e-002,0.54171
842.04303, 95.42167,    -1.34185,74.14687,50.00000,0.0000e+000,20.00000,-8.7209e-002,0.54108
843.81000, 95.59666,    -1.34576,74.13086,50.00000,0.0000e+000,20.00000,-8.7589e-002,0.54044
845.59198, 95.77167,    -1.35412,74.11493,50.00000,0.0000e+000,20.00000,-8.7884e-002,0.53980
847.37402, 95.94666,    -1.35784,74.10102,50.00000,0.0000e+000,20.00000,-8.7271e-002,0.53916
849.13702, 96.12167,    -1.35860,74.08707,50.00000,0.0000e+000,20.00000,-8.7041e-002,0.53853
850.89697, 96.29667,    -1.35874,74.07105,50.00000,0.0000e+000,20.00000,-8.7449e-002,0.53790
852.64203, 96.47166,    -1.35807,74.05476,50.00000,0.0000e+000,20.00000,-8.7048e-002,0.53727
854.40002, 96.64667,    -1.36049,74.03808,50.00000,0.0000e+000,20.00000,-8.6215e-002,0.53664
856.14600, 96.82166,    -1.36278,74.02075,50.00000,0.0000e+000,20.00000,-8.5595e-002,0.53602
857.89301, 96.99667,    -1.36401,74.00405,50.00000,0.0000e+000,20.00000,-8.5837e-002,0.53540
859.65302, 97.17167,    -1.36379,73.98808,50.00000,0.0000e+000,20.00000,-8.5135e-002,0.53477
861.40002, 97.34666,    -1.36631,73.97248,50.00000,0.0000e+000,20.00000,-8.4034e-002,0.53415
863.17200, 97.52167,    -1.37080,73.95732,50.00000,0.0000e+000,20.00000,-8.3467e-002,0.53352
864.89899, 97.69666,    -1.37433,73.94451,50.00000,0.0000e+000,20.00000,-8.3464e-002,0.53291
866.61603, 97.87167,    -1.37412,73.93385,50.00000,0.0000e+000,20.00000,-8.3616e-002,0.53230
868.37097, 98.04667,    -1.37706,73.91869,50.00000,0.0000e+000,20.00000,-8.3327e-002,0.53168
870.10699, 98.22166,    -1.38168,73.90258,50.00000,0.0000e+000,20.00000,-8.3062e-002,0.53107
871.87598, 98.39667,    -1.38889,73.88860,50.00000,0.0000e+000,20.00000,-8.2585e-002,0.53045
873.63898, 98.57166,    -1.39249,73.87632,50.00000,0.0000e+000,20.00000,-8.1893e-002,0.52983
875.42297, 98.74667,    -1.39767,73.86158,50.00000,0.0000e+000,20.00000,-8.1500e-002,0.52920
877.19098, 98.92167,    -1.40290,73.84718,50.00000,0.0000e+000,20.00000,-8.1576e-002,0.52858
878.96002, 99.09666,    -1.40724,73.83643,50.00000,0.0000e+000,20.00000,-8.2260e-002,0.52796
880.70001, 99.27167,    -1.40905,73.82323,50.00000,0.0000e+000,20.00000,-8.3217e-002,0.52735
882.44598, 99.44666,    -1.41177,73.80842,50.00000,0.0000e+000,20.00000,-8.4435e-002,0.52674
884.21002, 99.62167,    -1.41356,73.79395,50.00000,0.0000e+000,20.00000,-8.5867e-002,0.52612
885.94202, 99.79667,    -1.41573,73.78021,50.00000,0.0000e+000,20.00000,-8.6025e-002,0.52551
887.67798, 99.97166,    -1.41682,73.76518,50.00000,0.0000e+000,20.00000,-8.5548e-002,0.52491
889.42700,100.14667,    -1.41770,73.75006,50.00000,0.0000e+000,20.00000,-8.6356e-002,0.52430
891.15601,100.32166,    -1.41580,73.73575,50.00000,0.0000e+000,20.00000,-8.7660e-002,0.52370
892.90002,100.49667,    -1.41717,73.72042,50.00000,0.0000e+000,20.00000,-8.8756e-002,0.52309
894.63397,100.67167,    -1.42008,73.70447,50.00000,0.0000e+000,20.00000,-8.9579e-002,0.52248
896.38599,100.84666,    -1.42369,73.68693,50.00000,0.0000e+000,20.00000,-9.1848e-002,0.52188
898.15698,101.02167,    -1.42714,73.66820,50.00000,0.0000e+000,20.00000,-9.4060e-002,0.52126
899.91803,101.19666,    -1.42946,73.64922,50.00000,0.0000e+000,20.00000,-9.5530e-002,0.52065
901.69098,101.37167,    -1.43420,73.63159,50.00000,0.0000e+000,20.00000,-9.6729e-002,0.52003
903.42798,101.54667,    -1.43194,73.61745,50.00000,0.0000e+000,20.00000,-9.7928e-002,0.51943
905.19299,101.72166,    -1.43267,73.60367,50.00000,0.0000e+000,20.00000,-9.8837e-002,0.51882
906.97998,101.89667,    -1.43776,73.58704,50.00000,0.0000e+000,20.00000,-9.9783e-002,0.51820
908.77002,102.07166,    -1.44223,73.56900,50.00000,0.0000e+000,20.00000,    -0.10087,0.51758
910.52698,102.24667,    -1.44246,73.55176,50.00000,0.0000e+000,20.00000,    -0.10148,0.51697
912.27197,102.42167,    -1.43905,73.53410,50.00000,0.0000e+000,20.00000,    -0.10218,0.51637
914.02502,102.59666,    -1.43868,73.51441,50.00000,0.0000e+000,20.00000,    -0.10325,0.51576
915.79700,102.77167,    -1.43758,73.49438,50.00000,0.0000e+000,20.00000,    -0.10392,0.51515
917.54498,102.94666,    -1.43623,73.47462,50.00000,0.0000e+000,20.00000,    -0.10411,0.51455
919.31097,103.12167,    -1.43613,73.45508,50.00000,0.0000e+000,20.00000,    -0.10456,0.51394
921.08600,103.29667,    -1.43715,73.43633,50.00000,0.0000e+000,20.00000,    -0.10611,0.51333
922.83099,103.47166,    -1.43422,73.41870,50.00000,0.0000e+000,20.00000,    -0.10770,0.51273
924.58301,103.64667,    -1.43188,73.40034,50.00000,0.0000e+000,20.00000,    -0.10818,0.51212
926.34399,103.82166,    -1.42946,73.38142,50.00000,0.0000e+000,20.00000,    -0.10880,0.51151
928.11902,103.99667,    -1.42746,73.36387,50.00000,0.0000e+000,20.00000,    -0.11046,0.51090
929.87500,104.17167,    -1.42479,73.34659,50.00000,0.0000e+000,20.00000,    -0.11230,0.51030
931.68799,104.34666,    -1.42463,73.32687,50.00000,0.0000e+000,20.00000,    -0.11374,0.50967
933.48199,104.52167,    -1.42184,73.30585,50.00000,0.0000e+000,20.00000,    -0.11486,0.50906
935.18799,104.69666,    -1.40708,73.28567,50.00000,0.0000e+000,20.00000,    -0.11563,0.50847
936.91803,104.87167,    -1.39544,73.26604,50.00000,0.0000e+000,20.00000,    -0.11687,0.50787
938.64899,105.04667,    -1.38727,73.24491,50.00000,0.0000e+000,20.00000,    -0.11807,0.50728
940.39301,105.22166,    -1.38115,73.22446,50.00000,0.0000e+000,20.00000,    -0.11927,0.50668
942.15503,105.39667,    -1.37859,73.20686,50.00000,0.0000e+000,20.00000,    -0.11983,0.50607
943.89301,105.57166,    -1.37483,73.18888,50.00000,0.0000e+000,20.00000,    -0.12056,0.50547
945.64697,105.74667,    -1.36901,73.16622,50.00000,0.0000e+000,20.00000,    -0.12120,0.50487
947.50702,105.92167,    -1.37780,73.14224,50.00000,0.0000e+000,20.00000,    -0.12204,0.50423
949.37097,106.09666,    -1.38309,73.11837,50.00000,0.0000e+000,20.00000,    -0.12291,0.50359
951.12903,106.27167,    -1.37349,73.09388,50.00000,0.0000e+000,20.00000,    -0.12302,0.50298
952.84998,106.44666,    -1.35879,73.07084,50.00000,0.0000e+000,20.00000,    -0.12266,0.50239
954.54901,106.62167,    -1.34456,73.04736,50.00000,0.0000e+000,20.00000,    -0.12208,0.50180
956.23798,106.79667,    -1.33161,73.02324,50.00000,0.0000e+000,20.00000,    -0.12147,0.50122
957.94501,106.97166,    -1.32588,73.00018,50.00000,0.0000e+000,20.00000,    -0.12058,0.50063
959.69397,107.14667,    -1.32426,72.97938,50.00000,0.0000e+000,20.00000,    -0.12042,0.50003
961.44000,107.32166,    -1.32410,72.95888,50.00000,0.0000e+000,20.00000,    -0.12108,0.49943
963.18402,107.49667,    -1.32327,72.93724,50.00000,0.0000e+000,20.00000,    -0.12064,0.49883
964.92200,107.67167,    -1.32206,72.91751,50.00000,0.0000e+000,20.00000,    -0.11826,0.49823
966.64301,107.84666,    -1.31864,72.89631,50.00000,0.0000e+000,20.00000,    -0.11541,0.49763
968.36298,108.02167,    -1.31349,72.87480,50.00000,0.0000e+000,20.00000,    -0.11297,0.49704
970.10400,108.19666,    -1.31312,72.85429,50.00000,0.0000e+000,20.00000,    -0.11096,0.49644
971.84198,108.37167,    -1.31486,72.83643,50.00000,0.0000e+000,20.00000,    -0.10939,0.49584
973.69098,108.54667,    -1.32952,72.81852,50.00000,0.0000e+000,20.00000,    -0.10704,0.49520
975.51202,108.72166,    -1.33801,72.80042,50.00000,0.0000e+000,20.00000,    -0.10482,0.49457
977.26501,108.89667,    -1.33611,72.78242,50.00000,0.0000e+000,20.00000,    -0.10274,0.49397
979.01501,109.07166,    -1.33400,72.76352,50.00000,0.0000e+000,20.00000,    -0.10127,0.49336
980.75500,109.24667,    -1.33183,72.74388,50.00000,0.0000e+000,20.00000,-9.9045e-002,0.49276
982.49298,109.42167,    -1.33336,72.72671,50.00000,0.0000e+000,20.00000,-9.7098e-002,0.49216
984.23401,109.59666,    -1.33524,72.71328,50.00000,0.0000e+000,20.00000,-9.4191e-002,0.49155
986.00897,109.77167,    -1.34107,72.69883,50.00000,0.0000e+000,20.00000,-9.3021e-002,0.49094
987.83301,109.94666,    -1.35348,72.68274,50.00000,0.0000e+000,20.00000,-9.1348e-002,0.49030
989.64600,110.12167,    -1.35928,72.66562,50.00000,0.0000e+000,20.00000,-8.7683e-002,0.48968
991.45099,110.29667,    -1.36650,72.64945,50.00000,0.0000e+000,20.00000,-8.7439e-002,0.48905
993.20898,110.47166,    -1.36549,72.63387,50.00000,0.0000e+000,20.00000,-8.7712e-002,0.48844
994.93903,110.64667,    -1.35921,72.61897,50.00000,0.0000e+000,20.00000,-8.4007e-002,0.48784
996.64099,110.82166,    -1.35527,72.60478,50.00000,0.0000e+000,20.00000,-8.0882e-002,0.48724
998.34302,110.99667,    -1.35307,72.59006,50.00000,0.0000e+000,20.00000,-2.9769e-002,0.48665
998.38898,111.00166,    -1.35312,72.59006,50.00000,0.0000e+000,20.00000,-8.5564e-003,0.48664