File: book/some_content/DG_ExpDat_CEM_III_DC14; 30-1-2025-2.csv
#FILE:                       ,CEM_III_DC14; 30-1-2025.ngb-ds3
#FORMAT:                     ,NETZSCH5
#IDENTITY:                   ,CEMENT PASTE
#DECIMAL:                    ,POINT
#SEPARATOR:                  ,COMMA
#MTYPE:                      ,DSC
#INSTRUMENT:                 ,Microlab TU Delft
#PROJECT:                    ,
#DATE/TIME:                  ,1/02/2025 2:57:00 PM
#CORR. FILE:                 ,Blank with cover; 13-1-2025.ngb-bs3
#LABORATORY:                 ,TU Delft Micro Lab
#OPERATOR:                   ,Ahmed
#REMARK:                     ,under Argon atmosphere, 10K/min
#SAMPLE:                     ,CEM_III_DC14
#SAMPLE MASS /mg:            ,38
#MATERIAL:                   ,Geopolymer paste
#REFERENCE:                  ,blank
#REFERENCE MASS /mg:         ,0
#TYPE OF CRUCIBLE:           ,DSC/TG pan Al2O3
#SAMPLE CRUCIBLE MASS /mg:   ,0
#REFERENCE CRUCIBLE MASS /mg:,0
#CORR. CODE:                 ,020
#EXO:                        ,-1
#RANGE:                      ,40/10.0(K/min)/1000
#SEGMENT:                    ,S2/2

##Temp./øC,Time/min,DSC/(mW/mg),Mass/%,Gas Flow(purge1)/(ml/min),Gas Flow(purge2)/(ml/min),Gas Flow(protective)/(ml/min),DTG/(%/min),Sensit./(uV/mW)
 53.87300, 18.47500,-6.5477e-002,93.62441,50.00000,0.0000e+000,20.00000,-5.8716e-002,1.20783
 53.90900, 18.65000,-6.6577e-002,93.61706,50.00000,0.0000e+000,20.00000,-4.5374e-002,1.20778
 54.00800, 18.82500,-6.6717e-002,93.61339,50.00000,0.0000e+000,20.00000,-3.2419e-002,1.20764
 54.20800, 19.00000,-6.6317e-002,93.61504,50.00000,0.0000e+000,20.00000,-1.9260e-002,1.20737
 54.50400, 19.17500,-6.4809e-002,93.61837,50.00000,0.0000e+000,20.00000,-7.1133e-003,1.20696
 54.89900, 19.35000,-6.2874e-002,93.62415,50.00000,0.0000e+000,20.00000, 3.1881e-003,1.20642
 55.41000, 19.52500,-6.0213e-002,93.63339,50.00000,0.0000e+000,20.00000, 1.2991e-002,1.20571
 56.02000, 19.70000,-5.7156e-002,93.64492,50.00000,0.0000e+000,20.00000, 2.2407e-002,1.20487
 56.75200, 19.87500,-5.2984e-002,93.65872,50.00000,0.0000e+000,20.00000, 2.9963e-002,1.20387
 57.60500, 20.05000,-4.8796e-002,93.67211,50.00000,0.0000e+000,20.00000, 3.5407e-002,1.20269
 58.57900, 20.22500,-4.4120e-002,93.68438,50.00000,0.0000e+000,20.00000, 3.9260e-002,1.20135
 59.65500, 20.40000,-3.8870e-002,93.69771,50.00000,0.0000e+000,20.00000, 4.1172e-002,1.19988
 60.86200, 20.57500,-3.3579e-002,93.71126,50.00000,0.0000e+000,20.00000, 4.1088e-002,1.19822
 62.17800, 20.75000,-2.8176e-002,93.72513,50.00000,0.0000e+000,20.00000, 3.8538e-002,1.19641
 63.60100, 20.92500,-2.2423e-002,93.73797,50.00000,0.0000e+000,20.00000, 3.3618e-002,1.19445
 65.12800, 21.10000,-1.6518e-002,93.74575,50.00000,0.0000e+000,20.00000, 2.7128e-002,1.19236
 66.74300, 21.27500,-1.0527e-002,93.75081,50.00000,0.0000e+000,20.00000, 1.8292e-002,1.19014
 68.46400, 21.45000,-4.6484e-003,93.75803,50.00000,0.0000e+000,20.00000, 7.3645e-003,1.18778
 70.28800, 21.62500, 1.7108e-003,93.76389,50.00000,0.0000e+000,20.00000,-6.4657e-003,1.18528
 72.18800, 21.80000, 8.0297e-003,93.76795,50.00000,0.0000e+000,20.00000,-2.2740e-002,1.18268
 74.21100, 21.97500, 1.4515e-002,93.77109,50.00000,0.0000e+000,20.00000,-4.2075e-002,1.17991
 76.28000, 22.15000, 2.1492e-002,93.77177,50.00000,0.0000e+000,20.00000,-6.6758e-002,1.17707
 78.42300, 22.32500, 2.9035e-002,93.76768,50.00000,0.0000e+000,20.00000,-9.4699e-002,1.17414
 80.63000, 22.50000, 3.7047e-002,93.75961,50.00000,0.0000e+000,20.00000,    -0.12419,1.17113
 82.91900, 22.67500, 4.5397e-002,93.74697,50.00000,0.0000e+000,20.00000,    -0.15646,1.16800
 85.26800, 22.85000, 5.4658e-002,93.72942,50.00000,0.0000e+000,20.00000,    -0.19322,1.16480
 87.68200, 23.02500, 6.5149e-002,93.70724,50.00000,0.0000e+000,20.00000,    -0.23462,1.16151
 90.17200, 23.20000, 7.6817e-002,93.68031,50.00000,0.0000e+000,20.00000,    -0.27658,1.15812
 92.66200, 23.37500, 8.9561e-002,93.64648,50.00000,0.0000e+000,20.00000,    -0.32014,1.15473
 95.24100, 23.55000,     0.10394,93.60459,50.00000,0.0000e+000,20.00000,    -0.36171,1.15123
 97.83000, 23.72500,     0.11955,93.55304,50.00000,0.0000e+000,20.00000,    -0.40184,1.14771
100.45600, 23.90000,     0.13770,93.48423,50.00000,0.0000e+000,20.00000,    -0.44102,1.14416
103.10000, 24.07500,     0.15698,93.39900,50.00000,0.0000e+000,20.00000,    -0.47746,1.14058
105.79200, 24.25000,     0.17846,93.30759,50.00000,0.0000e+000,20.00000,    -0.51328,1.13694
108.47700, 24.42500,     0.20221,93.20868,50.00000,0.0000e+000,20.00000,    -0.54658,1.13331
111.17000, 24.60000,     0.22758,93.09506,50.00000,0.0000e+000,20.00000,    -0.57607,1.12968
113.87400, 24.77500,     0.25399,92.95672,50.00000,0.0000e+000,20.00000,    -0.60607,1.12605
116.56000, 24.95000,     0.27953,92.80898,50.00000,0.0000e+000,20.00000,    -0.63452,1.12244
119.23800, 25.12500,     0.30239,92.65947,50.00000,0.0000e+000,20.00000,    -0.65906,1.11884
121.92700, 25.30000,     0.32061,92.50813,50.00000,0.0000e+000,20.00000,    -0.68217,1.11524
124.65000, 25.47500,     0.33353,92.36476,50.00000,0.0000e+000,20.00000,    -0.70356,1.11160
127.33100, 25.65000,     0.33961,92.22150,50.00000,0.0000e+000,20.00000,    -0.72011,1.10802
130.03101, 25.82500,     0.34111,92.08475,50.00000,0.0000e+000,20.00000,    -0.73030,1.10442
132.72301, 26.00000,     0.33998,91.94854,50.00000,0.0000e+000,20.00000,    -0.73757,1.10084
135.41400, 26.17500,     0.33666,91.81262,50.00000,0.0000e+000,20.00000,    -0.74282,1.09727
138.08200, 26.35000,     0.33216,91.68648,50.00000,0.0000e+000,20.00000,    -0.74384,1.09373
140.75999, 26.52500,     0.32656,91.56126,50.00000,0.0000e+000,20.00000,    -0.73838,1.09019
143.42200, 26.70000,     0.32106,91.42915,50.00000,0.0000e+000,20.00000,    -0.72756,1.08668
146.05299, 26.87500,     0.31443,91.30661,50.00000,0.0000e+000,20.00000,    -0.71600,1.08321
148.67000, 27.05000,     0.30771,91.18580,50.00000,0.0000e+000,20.00000,    -0.70168,1.07977
151.26900, 27.22500,     0.30031,91.06090,50.00000,0.0000e+000,20.00000,    -0.68785,1.07636
153.82600, 27.40000,     0.29279,90.93808,50.00000,0.0000e+000,20.00000,    -0.67401,1.07301
156.38901, 27.57500,     0.28412,90.81996,50.00000,0.0000e+000,20.00000,    -0.66029,1.06966
158.89301, 27.75000,     0.27501,90.70418,50.00000,0.0000e+000,20.00000,    -0.64695,1.06640
161.36600, 27.92500,     0.26547,90.58881,50.00000,0.0000e+000,20.00000,    -0.63219,1.06318
163.82001, 28.10000,     0.25529,90.47711,50.00000,0.0000e+000,20.00000,    -0.61854,1.06000
166.24800, 28.27500,     0.24438,90.36947,50.00000,0.0000e+000,20.00000,    -0.60592,1.05685
168.62300, 28.45000,     0.23305,90.26233,50.00000,0.0000e+000,20.00000,    -0.59013,1.05378
170.99100, 28.62500,     0.22158,90.15562,50.00000,0.0000e+000,20.00000,    -0.57388,1.05072
173.33200, 28.80000,     0.20964,90.05336,50.00000,0.0000e+000,20.00000,    -0.55936,1.04771
175.63300, 28.97500,     0.19677,89.95565,50.00000,0.0000e+000,20.00000,    -0.54495,1.04475
177.91000, 29.15000,     0.18398,89.86196,50.00000,0.0000e+000,20.00000,    -0.52967,1.04183
180.16701, 29.32500,     0.17099,89.77059,50.00000,0.0000e+000,20.00000,    -0.51463,1.03895
182.38600, 29.50000,     0.15800,89.68255,50.00000,0.0000e+000,20.00000,    -0.49984,1.03611
184.58900, 29.67500,     0.14509,89.59805,50.00000,0.0000e+000,20.00000,    -0.48417,1.03331
186.76199, 29.85000,     0.13308,89.51579,50.00000,0.0000e+000,20.00000,    -0.46847,1.03055
188.90199, 30.02500,     0.12097,89.43693,50.00000,0.0000e+000,20.00000,    -0.45405,1.02783
191.02400, 30.20000,     0.10840,89.36209,50.00000,0.0000e+000,20.00000,    -0.43978,1.02515
193.13699, 30.37500, 9.6393e-002,89.29181,50.00000,0.0000e+000,20.00000,    -0.42489,1.02248
195.19800, 30.55000, 8.4610e-002,89.22534,50.00000,0.0000e+000,20.00000,    -0.41062,1.01988
197.27400, 30.72500, 7.3360e-002,89.15624,50.00000,0.0000e+000,20.00000,    -0.39768,1.01727
199.28400, 30.90000, 6.2067e-002,89.08573,50.00000,0.0000e+000,20.00000,    -0.38588,1.01475
201.28900, 31.07500, 5.1491e-002,89.01934,50.00000,0.0000e+000,20.00000,    -0.37421,1.01224
203.27499, 31.25000, 4.0960e-002,88.95563,50.00000,0.0000e+000,20.00000,    -0.36275,1.00976
205.22600, 31.42500, 3.1212e-002,88.89549,50.00000,0.0000e+000,20.00000,    -0.35199,1.00733
207.16701, 31.60000, 2.1737e-002,88.83861,50.00000,0.0000e+000,20.00000,    -0.34133,1.00491
209.08299, 31.77500, 1.2557e-002,88.78223,50.00000,0.0000e+000,20.00000,    -0.33089,1.00254
210.97800, 31.95000, 3.6935e-003,88.72650,50.00000,0.0000e+000,20.00000,    -0.32142,1.00019
212.84500, 32.12500,-4.6075e-003,88.67284,50.00000,0.0000e+000,20.00000,    -0.31224,0.99788
214.72301, 32.30000,-1.2302e-002,88.62041,50.00000,0.0000e+000,20.00000,    -0.30386,0.99556
216.56500, 32.47500,-1.9809e-002,88.56805,50.00000,0.0000e+000,20.00000,    -0.29552,0.99330
218.39700, 32.65000,-2.7775e-002,88.51567,50.00000,0.0000e+000,20.00000,    -0.28585,0.99105
220.22701, 32.82500,-3.5594e-002,88.46461,50.00000,0.0000e+000,20.00000,    -0.27701,0.98881
222.03799, 33.00000,-4.3875e-002,88.41626,50.00000,0.0000e+000,20.00000,    -0.26867,0.98659
223.83900, 33.17500,-5.2356e-002,88.36902,50.00000,0.0000e+000,20.00000,    -0.26125,0.98439
225.61099, 33.35000,-6.1485e-002,88.32365,50.00000,0.0000e+000,20.00000,    -0.25427,0.98224
227.39400, 33.52500,-7.1290e-002,88.28061,50.00000,0.0000e+000,20.00000,    -0.24692,0.98007
229.15500, 33.70000,-8.0150e-002,88.23837,50.00000,0.0000e+000,20.00000,    -0.23934,0.97794
230.90500, 33.87500,-8.9747e-002,88.19783,50.00000,0.0000e+000,20.00000,    -0.23173,0.97582
232.61400, 34.05000,-9.8742e-002,88.16042,50.00000,0.0000e+000,20.00000,    -0.22470,0.97376
234.32401, 34.22500,    -0.10732,88.12347,50.00000,0.0000e+000,20.00000,    -0.21769,0.97170
236.01401, 34.40000,    -0.11678,88.08745,50.00000,0.0000e+000,20.00000,    -0.21067,0.96967
237.71400, 34.57500,    -0.12680,88.05174,50.00000,0.0000e+000,20.00000,    -0.20383,0.96763
239.41400, 34.75000,    -0.13655,88.01652,50.00000,0.0000e+000,20.00000,    -0.19757,0.96559
241.12000, 34.92500,    -0.14679,87.98228,50.00000,0.0000e+000,20.00000,    -0.19167,0.96356
242.81700, 35.10000,    -0.15662,87.94804,50.00000,0.0000e+000,20.00000,    -0.18562,0.96154
244.52200, 35.27500,    -0.16558,87.91768,50.00000,0.0000e+000,20.00000,    -0.17986,0.95951
246.20300, 35.45000,    -0.17345,87.88865,50.00000,0.0000e+000,20.00000,    -0.17443,0.95752
247.89799, 35.62500,    -0.18075,87.86113,50.00000,0.0000e+000,20.00000,    -0.16932,0.95551
249.59000, 35.80000,    -0.18759,87.83439,50.00000,0.0000e+000,20.00000,    -0.16535,0.95351
251.27200, 35.97500,    -0.19412,87.80726,50.00000,0.0000e+000,20.00000,    -0.16169,0.95153
252.94299, 36.15000,    -0.20034,87.78086,50.00000,0.0000e+000,20.00000,    -0.15807,0.94957
254.59900, 36.32500,    -0.20607,87.75371,50.00000,0.0000e+000,20.00000,    -0.15442,0.94762
256.27100, 36.50000,    -0.21258,87.72711,50.00000,0.0000e+000,20.00000,    -0.15062,0.94567
257.93399, 36.67500,    -0.21885,87.70061,50.00000,0.0000e+000,20.00000,    -0.14712,0.94373
259.60699, 36.85000,    -0.22566,87.67551,50.00000,0.0000e+000,20.00000,    -0.14319,0.94178
261.25299, 37.02500,    -0.23261,87.65211,50.00000,0.0000e+000,20.00000,    -0.13996,0.93987
262.91599, 37.20000,    -0.23938,87.62951,50.00000,0.0000e+000,20.00000,    -0.13767,0.93794
264.57901, 37.37500,    -0.24569,87.60684,50.00000,0.0000e+000,20.00000,    -0.13569,0.93601
266.25101, 37.55000,    -0.25253,87.58307,50.00000,0.0000e+000,20.00000,    -0.13382,0.93409
267.93600, 37.72500,    -0.25864,87.55928,50.00000,0.0000e+000,20.00000,    -0.13174,0.93215
269.62399, 37.90000,    -0.26470,87.53569,50.00000,0.0000e+000,20.00000,    -0.12989,0.93021
271.26599, 38.07500,    -0.27013,87.51303,50.00000,0.0000e+000,20.00000,    -0.12785,0.92833
272.96500, 38.25000,    -0.27594,87.49102,50.00000,0.0000e+000,20.00000,    -0.12588,0.92638
274.63901, 38.42500,    -0.28133,87.46925,50.00000,0.0000e+000,20.00000,    -0.12397,0.92448
276.33301, 38.60000,    -0.28644,87.44843,50.00000,0.0000e+000,20.00000,    -0.12218,0.92255
278.00699, 38.77500,    -0.29168,87.42820,50.00000,0.0000e+000,20.00000,    -0.12132,0.92065
279.69601, 38.95000,    -0.29687,87.40769,50.00000,0.0000e+000,20.00000,    -0.12104,0.91874
281.38199, 39.12500,    -0.30253,87.38634,50.00000,0.0000e+000,20.00000,    -0.12042,0.91684
283.07101, 39.30000,    -0.30728,87.36590,50.00000,0.0000e+000,20.00000,    -0.11969,0.91494
284.75000, 39.47500,    -0.31251,87.34637,50.00000,0.0000e+000,20.00000,    -0.11888,0.91305
286.48099, 39.65000,    -0.31741,87.32660,50.00000,0.0000e+000,20.00000,    -0.11778,0.91111
288.14401, 39.82500,    -0.32234,87.30702,50.00000,0.0000e+000,20.00000,    -0.11706,0.90925
289.84698, 40.00000,    -0.32644,87.28753,50.00000,0.0000e+000,20.00000,    -0.11721,0.90736
291.53101, 40.17500,    -0.33042,87.26778,50.00000,0.0000e+000,20.00000,    -0.11680,0.90549
293.24500, 40.35000,    -0.33465,87.24844,50.00000,0.0000e+000,20.00000,    -0.11602,0.90359
294.92700, 40.52500,    -0.33841,87.22846,50.00000,0.0000e+000,20.00000,    -0.11560,0.90173
296.63101, 40.70000,    -0.34267,87.20660,50.00000,0.0000e+000,20.00000,    -0.11522,0.89985
298.31601, 40.87500,    -0.34644,87.18564,50.00000,0.0000e+000,20.00000,    -0.11494,0.89800
300.00201, 41.05000,    -0.35056,87.16555,50.00000,0.0000e+000,20.00000,    -0.11483,0.89615
301.69699, 41.22500,    -0.35434,87.14442,50.00000,0.0000e+000,20.00000,    -0.11499,0.89429
303.39200, 41.40000,    -0.35851,87.12417,50.00000,0.0000e+000,20.00000,    -0.11523,0.89245
305.09000, 41.57500,    -0.36230,87.10455,50.00000,0.0000e+000,20.00000,    -0.11539,0.89060
306.78101, 41.75000,    -0.36635,87.08239,50.00000,0.0000e+000,20.00000,    -0.11556,0.88876
308.47400, 41.92500,    -0.37016,87.06056,50.00000,0.0000e+000,20.00000,    -0.11543,0.88693
310.17401, 42.10000,    -0.37426,87.04157,50.00000,0.0000e+000,20.00000,    -0.11551,0.88510
311.89099, 42.27500,    -0.37841,87.02302,50.00000,0.0000e+000,20.00000,    -0.11596,0.88325
313.59201, 42.45000,    -0.38258,87.00415,50.00000,0.0000e+000,20.00000,    -0.11600,0.88143
315.31699, 42.62500,    -0.38733,86.98477,50.00000,0.0000e+000,20.00000,    -0.11589,0.87958
317.03799, 42.80000,    -0.39176,86.96418,50.00000,0.0000e+000,20.00000,    -0.11616,0.87775
318.75900, 42.97500,    -0.39581,86.94373,50.00000,0.0000e+000,20.00000,    -0.11620,0.87592
320.48901, 43.15000,    -0.39969,86.92327,50.00000,0.0000e+000,20.00000,    -0.11636,0.87408
322.20200, 43.32500,    -0.40276,86.90289,50.00000,0.0000e+000,20.00000,    -0.11683,0.87227
323.92300, 43.50000,    -0.40505,86.88263,50.00000,0.0000e+000,20.00000,    -0.11688,0.87046
325.64301, 43.67500,    -0.40691,86.86306,50.00000,0.0000e+000,20.00000,    -0.11638,0.86865
327.32501, 43.85000,    -0.40899,86.84376,50.00000,0.0000e+000,20.00000,    -0.11653,0.86689
329.03799, 44.02500,    -0.41167,86.82313,50.00000,0.0000e+000,20.00000,    -0.11701,0.86510
330.76700, 44.20000,    -0.41592,86.80182,50.00000,0.0000e+000,20.00000,    -0.11765,0.86330
332.46500, 44.37500,    -0.42085,86.78052,50.00000,0.0000e+000,20.00000,    -0.11845,0.86154
334.20801, 44.55000,    -0.42512,86.75926,50.00000,0.0000e+000,20.00000,    -0.11908,0.85973
335.94299, 44.72500,    -0.42952,86.73841,50.00000,0.0000e+000,20.00000,    -0.12011,0.85794
337.66800, 44.90000,    -0.43367,86.71715,50.00000,0.0000e+000,20.00000,    -0.12123,0.85616
339.40100, 45.07500,    -0.43661,86.69575,50.00000,0.0000e+000,20.00000,    -0.12194,0.85439
341.12799, 45.25000,    -0.43973,86.67458,50.00000,0.0000e+000,20.00000,    -0.12310,0.85262
342.85501, 45.42500,    -0.44180,86.65374,50.00000,0.0000e+000,20.00000,    -0.12520,0.85086
344.57999, 45.60000,    -0.44430,86.63285,50.00000,0.0000e+000,20.00000,    -0.12697,0.84911
346.31601, 45.77500,    -0.44678,86.61264,50.00000,0.0000e+000,20.00000,    -0.12787,0.84735
348.04199, 45.95000,    -0.44903,86.59198,50.00000,0.0000e+000,20.00000,    -0.12880,0.84560
349.76599, 46.12500,    -0.45157,86.57033,50.00000,0.0000e+000,20.00000,    -0.13036,0.84387
351.47800, 46.30000,    -0.45397,86.54823,50.00000,0.0000e+000,20.00000,    -0.13166,0.84215
353.21399, 46.47500,    -0.45634,86.52478,50.00000,0.0000e+000,20.00000,    -0.13272,0.84041
354.94299, 46.65000,    -0.45922,86.49990,50.00000,0.0000e+000,20.00000,    -0.13376,0.83869
356.66400, 46.82500,    -0.46210,86.47636,50.00000,0.0000e+000,20.00000,    -0.13454,0.83698
358.38800, 47.00000,    -0.46488,86.45297,50.00000,0.0000e+000,20.00000,    -0.13550,0.83527
360.12900, 47.17500,    -0.46733,86.42635,50.00000,0.0000e+000,20.00000,    -0.13669,0.83355
361.84900, 47.35000,    -0.47004,86.39919,50.00000,0.0000e+000,20.00000,    -0.13784,0.83186
363.57901, 47.52500,    -0.47337,86.37533,50.00000,0.0000e+000,20.00000,    -0.13855,0.83016
365.32300, 47.70000,    -0.47663,86.35171,50.00000,0.0000e+000,20.00000,    -0.13965,0.82845
367.06699, 47.87500,    -0.47979,86.32558,50.00000,0.0000e+000,20.00000,    -0.14068,0.82675
368.79099, 48.05000,    -0.48174,86.29869,50.00000,0.0000e+000,20.00000,    -0.14142,0.82508
370.53400, 48.22500,    -0.48399,86.27351,50.00000,0.0000e+000,20.00000,    -0.14211,0.82339
372.26700, 48.40000,    -0.48701,86.24868,50.00000,0.0000e+000,20.00000,    -0.14238,0.82172
373.99500, 48.57500,    -0.49039,86.22419,50.00000,0.0000e+000,20.00000,    -0.14286,0.82005
375.76401, 48.75000,    -0.49399,86.19970,50.00000,0.0000e+000,20.00000,    -0.14357,0.81836
377.49200, 48.92500,    -0.49631,86.17464,50.00000,0.0000e+000,20.00000,    -0.14347,0.81671
379.21201, 49.10000,    -0.49827,86.14915,50.00000,0.0000e+000,20.00000,    -0.14251,0.81507
380.94299, 49.27500,    -0.50014,86.12525,50.00000,0.0000e+000,20.00000,    -0.14226,0.81343
382.66400, 49.45000,    -0.50228,86.10188,50.00000,0.0000e+000,20.00000,    -0.14255,0.81180
384.39200, 49.62500,    -0.50527,86.07684,50.00000,0.0000e+000,20.00000,    -0.14217,0.81017
386.12000, 49.80000,    -0.50820,86.05211,50.00000,0.0000e+000,20.00000,    -0.14123,0.80855
387.84799, 49.97500,    -0.51166,86.02724,50.00000,0.0000e+000,20.00000,    -0.14057,0.80693
389.57401, 50.15000,    -0.51570,86.00185,50.00000,0.0000e+000,20.00000,    -0.13982,0.80532
391.28900, 50.32500,    -0.51987,85.97601,50.00000,0.0000e+000,20.00000,    -0.13897,0.80372
393.02701, 50.50000,    -0.52384,85.95003,50.00000,0.0000e+000,20.00000,    -0.13865,0.80211
394.76199, 50.67500,    -0.52820,85.92500,50.00000,0.0000e+000,20.00000,    -0.13850,0.80051
396.50201, 50.85000,    -0.53310,85.90069,50.00000,0.0000e+000,20.00000,    -0.13790,0.79891
398.24600, 51.02500,    -0.53704,85.87648,50.00000,0.0000e+000,20.00000,    -0.13696,0.79731
399.99399, 51.20000,    -0.54145,85.85205,50.00000,0.0000e+000,20.00000,    -0.13631,0.79571
401.75101, 51.37500,    -0.54525,85.82820,50.00000,0.0000e+000,20.00000,    -0.13541,0.79412
403.48499, 51.55000,    -0.54889,85.80475,50.00000,0.0000e+000,20.00000,    -0.13466,0.79254
405.22501, 51.72500,    -0.55272,85.78094,50.00000,0.0000e+000,20.00000,    -0.13443,0.79097
406.95901, 51.90000,    -0.55641,85.75833,50.00000,0.0000e+000,20.00000,    -0.13421,0.78941
408.71301, 52.07500,    -0.55999,85.73662,50.00000,0.0000e+000,20.00000,    -0.13307,0.78784
410.44400, 52.25000,    -0.56375,85.71444,50.00000,0.0000e+000,20.00000,    -0.13210,0.78629
412.17300, 52.42500,    -0.56713,85.69026,50.00000,0.0000e+000,20.00000,    -0.13162,0.78475
413.90900, 52.60000,    -0.57114,85.66649,50.00000,0.0000e+000,20.00000,    -0.13075,0.78321
415.63800, 52.77500,    -0.57593,85.64421,50.00000,0.0000e+000,20.00000,    -0.12995,0.78168
417.37201, 52.95000,    -0.57994,85.62345,50.00000,0.0000e+000,20.00000,    -0.12907,0.78015
419.10300, 53.12500,    -0.58355,85.60255,50.00000,0.0000e+000,20.00000,    -0.12840,0.77863
420.84201, 53.30000,    -0.58764,85.58081,50.00000,0.0000e+000,20.00000,    -0.12822,0.77711
422.56500, 53.47500,    -0.59074,85.55783,50.00000,0.0000e+000,20.00000,    -0.12795,0.77561
424.28500, 53.65000,    -0.59474,85.53309,50.00000,0.0000e+000,20.00000,    -0.12773,0.77412
426.01300, 53.82500,    -0.59880,85.51041,50.00000,0.0000e+000,20.00000,    -0.12792,0.77262
427.74600, 54.00000,    -0.60287,85.48909,50.00000,0.0000e+000,20.00000,    -0.12836,0.77113
429.48199, 54.17500,    -0.60751,85.46508,50.00000,0.0000e+000,20.00000,    -0.12866,0.76964
431.21500, 54.35000,    -0.61192,85.44286,50.00000,0.0000e+000,20.00000,    -0.12899,0.76815
432.97000, 54.52500,    -0.61558,85.42170,50.00000,0.0000e+000,20.00000,    -0.12970,0.76666
434.70700, 54.70000,    -0.61957,85.40047,50.00000,0.0000e+000,20.00000,    -0.13116,0.76518
436.44601, 54.87500,    -0.62392,85.37914,50.00000,0.0000e+000,20.00000,    -0.13324,0.76371
438.21701, 55.05000,    -0.62759,85.35668,50.00000,0.0000e+000,20.00000,    -0.13593,0.76222
439.95099, 55.22500,    -0.63114,85.33381,50.00000,0.0000e+000,20.00000,    -0.13895,0.76077
441.68399, 55.40000,    -0.63391,85.31127,50.00000,0.0000e+000,20.00000,    -0.14203,0.75932
443.44101, 55.57500,    -0.63635,85.28871,50.00000,0.0000e+000,20.00000,    -0.14619,0.75785
445.17499, 55.75000,    -0.63806,85.26577,50.00000,0.0000e+000,20.00000,    -0.15149,0.75641
446.92401, 55.92500,    -0.64059,85.24189,50.00000,0.0000e+000,20.00000,    -0.15562,0.75497
448.66699, 56.10000,    -0.64309,85.21668,50.00000,0.0000e+000,20.00000,    -0.15886,0.75353
450.41501, 56.27500,    -0.64530,85.19121,50.00000,0.0000e+000,20.00000,    -0.16265,0.75210
452.16901, 56.45000,    -0.64503,85.16512,50.00000,0.0000e+000,20.00000,    -0.16607,0.75067
453.92801, 56.62500,    -0.64353,85.13771,50.00000,0.0000e+000,20.00000,    -0.16897,0.74924
455.67599, 56.80000,    -0.63909,85.10795,50.00000,0.0000e+000,20.00000,    -0.17095,0.74782
457.39700, 56.97500,    -0.63433,85.07526,50.00000,0.0000e+000,20.00000,    -0.17228,0.74643
459.14200, 57.15000,    -0.62946,85.04112,50.00000,0.0000e+000,20.00000,    -0.17324,0.74503
460.87399, 57.32500,    -0.62610,85.00349,50.00000,0.0000e+000,20.00000,    -0.17329,0.74364
462.61401, 57.50000,    -0.62543,84.96292,50.00000,0.0000e+000,20.00000,    -0.17299,0.74225
464.34201, 57.67500,    -0.62727,84.92341,50.00000,0.0000e+000,20.00000,    -0.17327,0.74088
466.09201, 57.85000,    -0.63184,84.88726,50.00000,0.0000e+000,20.00000,    -0.17283,0.73949
467.82501, 58.02500,    -0.63897,84.85211,50.00000,0.0000e+000,20.00000,    -0.17203,0.73813
469.55701, 58.20000,    -0.64710,84.81757,50.00000,0.0000e+000,20.00000,    -0.17124,0.73677
471.30899, 58.37500,    -0.65605,84.78489,50.00000,0.0000e+000,20.00000,    -0.17001,0.73539
473.06500, 58.55000,    -0.66611,84.75453,50.00000,0.0000e+000,20.00000,    -0.16837,0.73403
474.81601, 58.72500,    -0.67587,84.72643,50.00000,0.0000e+000,20.00000,    -0.16603,0.73267
476.56201, 58.90000,    -0.68475,84.69925,50.00000,0.0000e+000,20.00000,    -0.16322,0.73132
478.30701, 59.07500,    -0.69269,84.67495,50.00000,0.0000e+000,20.00000,    -0.15986,0.72997
480.07199, 59.25000,    -0.69902,84.65363,50.00000,0.0000e+000,20.00000,    -0.15552,0.72862
481.80200, 59.42500,    -0.70440,84.63023,50.00000,0.0000e+000,20.00000,    -0.15168,0.72730
483.54800, 59.60000,    -0.70951,84.60619,50.00000,0.0000e+000,20.00000,    -0.14938,0.72597
485.27499, 59.77500,    -0.71384,84.58385,50.00000,0.0000e+000,20.00000,    -0.14748,0.72466
487.03900, 59.95000,    -0.71823,84.56090,50.00000,0.0000e+000,20.00000,    -0.14562,0.72333
488.75900, 60.12500,    -0.72174,84.53851,50.00000,0.0000e+000,20.00000,    -0.14422,0.72204
490.50601, 60.30000,    -0.72522,84.51617,50.00000,0.0000e+000,20.00000,    -0.14362,0.72073
492.25601, 60.47500,    -0.72673,84.49335,50.00000,0.0000e+000,20.00000,    -0.14365,0.71943
493.96899, 60.65000,    -0.72808,84.47023,50.00000,0.0000e+000,20.00000,    -0.14376,0.71816
495.69800, 60.82500,    -0.72873,84.44682,50.00000,0.0000e+000,20.00000,    -0.14505,0.71688
497.44400, 61.00000,    -0.72990,84.42326,50.00000,0.0000e+000,20.00000,    -0.14755,0.71560
499.19800, 61.17500,    -0.73363,84.39837,50.00000,0.0000e+000,20.00000,    -0.15009,0.71431
500.95001, 61.35000,    -0.73776,84.36992,50.00000,0.0000e+000,20.00000,    -0.15195,0.71303
502.71301, 61.52500,    -0.74129,84.34108,50.00000,0.0000e+000,20.00000,    -0.15398,0.71175
504.47400, 61.70000,    -0.74370,84.31293,50.00000,0.0000e+000,20.00000,    -0.15660,0.71047
506.23801, 61.87500,    -0.74475,84.28466,50.00000,0.0000e+000,20.00000,    -0.15947,0.70920
507.97101, 62.05000,    -0.74367,84.25576,50.00000,0.0000e+000,20.00000,    -0.16169,0.70796
509.68301, 62.22500,    -0.74238,84.22633,50.00000,0.0000e+000,20.00000,    -0.16417,0.70673
511.41000, 62.40000,    -0.74162,84.19819,50.00000,0.0000e+000,20.00000,    -0.16701,0.70550
513.14203, 62.57500,    -0.74272,84.16895,50.00000,0.0000e+000,20.00000,    -0.17002,0.70427
514.88300, 62.75000,    -0.74581,84.13753,50.00000,0.0000e+000,20.00000,    -0.17311,0.70305
516.61700, 62.92500,    -0.74966,84.10631,50.00000,0.0000e+000,20.00000,    -0.17611,0.70183
518.36603, 63.10000,    -0.75214,84.07493,50.00000,0.0000e+000,20.00000,    -0.17861,0.70060
520.09998, 63.27500,    -0.75565,84.04434,50.00000,0.0000e+000,20.00000,    -0.18042,0.69939
521.85999, 63.45000,    -0.75798,84.01337,50.00000,0.0000e+000,20.00000,    -0.18248,0.69817
523.60199, 63.62500,    -0.76001,83.97992,50.00000,0.0000e+000,20.00000,    -0.18491,0.69696
525.34998, 63.80000,    -0.76231,83.94841,50.00000,0.0000e+000,20.00000,    -0.18777,0.69576
527.10303, 63.97500,    -0.76525,83.91783,50.00000,0.0000e+000,20.00000,    -0.19025,0.69456
528.84601, 64.15000,    -0.76830,83.88495,50.00000,0.0000e+000,20.00000,    -0.19261,0.69337
530.59802, 64.32500,    -0.77032,83.85110,50.00000,0.0000e+000,20.00000,    -0.19522,0.69218
532.35400, 64.50000,    -0.77344,83.81639,50.00000,0.0000e+000,20.00000,    -0.19714,0.69099
534.10797, 64.67500,    -0.77719,83.78166,50.00000,0.0000e+000,20.00000,    -0.19933,0.68980
535.89099, 64.85000,    -0.78067,83.74610,50.00000,0.0000e+000,20.00000,    -0.20159,0.68861
537.66901, 65.02500,    -0.78383,83.71000,50.00000,0.0000e+000,20.00000,    -0.20365,0.68742
539.41498, 65.20000,    -0.78571,83.67438,50.00000,0.0000e+000,20.00000,    -0.20627,0.68626
541.16101, 65.37500,    -0.78642,83.63806,50.00000,0.0000e+000,20.00000,    -0.20836,0.68510
542.88599, 65.55000,    -0.78656,83.59978,50.00000,0.0000e+000,20.00000,    -0.20997,0.68396
544.59698, 65.72500,    -0.78744,83.56078,50.00000,0.0000e+000,20.00000,    -0.21221,0.68284
546.35999, 65.90000,    -0.79151,83.52306,50.00000,0.0000e+000,20.00000,    -0.21431,0.68168
548.12799, 66.07500,    -0.79737,83.48549,50.00000,0.0000e+000,20.00000,    -0.21618,0.68053
549.87701, 66.25000,    -0.80210,83.44782,50.00000,0.0000e+000,20.00000,    -0.21785,0.67939
551.63501, 66.42500,    -0.80451,83.40920,50.00000,0.0000e+000,20.00000,    -0.21989,0.67826
553.37299, 66.60000,    -0.80577,83.36935,50.00000,0.0000e+000,20.00000,    -0.22193,0.67714
555.10699, 66.77500,    -0.80585,83.33054,50.00000,0.0000e+000,20.00000,    -0.22286,0.67603
556.82800, 66.95000,    -0.80672,83.29132,50.00000,0.0000e+000,20.00000,    -0.22354,0.67493
558.54602, 67.12500,    -0.80838,83.25095,50.00000,0.0000e+000,20.00000,    -0.22493,0.67384
560.29102, 67.30000,    -0.81120,83.21153,50.00000,0.0000e+000,20.00000,    -0.22618,0.67274
562.03802, 67.47500,    -0.81606,83.17312,50.00000,0.0000e+000,20.00000,    -0.22711,0.67164
563.78601, 67.65000,    -0.82047,83.13411,50.00000,0.0000e+000,20.00000,    -0.22793,0.67054
565.53601, 67.82500,    -0.82352,83.09391,50.00000,0.0000e+000,20.00000,    -0.22824,0.66945
567.30298, 68.00000,    -0.82917,83.05363,50.00000,0.0000e+000,20.00000,    -0.22881,0.66835
569.04901, 68.17500,    -0.83346,83.01229,50.00000,0.0000e+000,20.00000,    -0.22990,0.66727
570.86603, 68.35000,    -0.83827,82.96943,50.00000,0.0000e+000,20.00000,    -0.23057,0.66615
572.60199, 68.52500,    -0.84016,82.92846,50.00000,0.0000e+000,20.00000,    -0.23101,0.66508
574.33899, 68.70000,    -0.84099,82.89027,50.00000,0.0000e+000,20.00000,    -0.23219,0.66402
576.06897, 68.87500,    -0.84196,82.85058,50.00000,0.0000e+000,20.00000,    -0.23280,0.66297
577.79797, 69.05000,    -0.84338,82.80895,50.00000,0.0000e+000,20.00000,    -0.23277,0.66192
579.52600, 69.22500,    -0.84708,82.76667,50.00000,0.0000e+000,20.00000,    -0.23266,0.66088
581.29700, 69.40000,    -0.85207,82.72447,50.00000,0.0000e+000,20.00000,    -0.23368,0.65981
583.05701, 69.57500,    -0.85678,82.68494,50.00000,0.0000e+000,20.00000,    -0.23519,0.65876
584.82300, 69.75000,    -0.86084,82.64610,50.00000,0.0000e+000,20.00000,    -0.23654,0.65771
586.55603, 69.92500,    -0.86408,82.60505,50.00000,0.0000e+000,20.00000,    -0.23715,0.65668
588.30499, 70.10000,    -0.86630,82.56258,50.00000,0.0000e+000,20.00000,    -0.23735,0.65565
590.05902, 70.27500,    -0.86972,82.52160,50.00000,0.0000e+000,20.00000,    -0.23775,0.65462
591.83398, 70.45000,    -0.87433,82.47940,50.00000,0.0000e+000,20.00000,    -0.23931,0.65358
593.60999, 70.62500,    -0.87907,82.43649,50.00000,0.0000e+000,20.00000,    -0.24109,0.65254
595.36798, 70.80000,    -0.88294,82.39525,50.00000,0.0000e+000,20.00000,    -0.24183,0.65152
597.13702, 70.97500,    -0.88572,82.35697,50.00000,0.0000e+000,20.00000,    -0.24218,0.65050
598.87799, 71.15000,    -0.88814,82.31670,50.00000,0.0000e+000,20.00000,    -0.24236,0.64950
600.61798, 71.32500,    -0.88898,82.27246,50.00000,0.0000e+000,20.00000,    -0.24333,0.64850
602.34900, 71.50000,    -0.88978,82.22665,50.00000,0.0000e+000,20.00000,    -0.24534,0.64751
604.08398, 71.67500,    -0.89247,82.18291,50.00000,0.0000e+000,20.00000,    -0.24706,0.64653
605.82599, 71.85000,    -0.89629,82.14016,50.00000,0.0000e+000,20.00000,    -0.24830,0.64554
607.59399, 72.02500,    -0.90147,82.09665,50.00000,0.0000e+000,20.00000,    -0.24965,0.64454
609.34198, 72.20000,    -0.90568,82.05238,50.00000,0.0000e+000,20.00000,    -0.25106,0.64356
611.12097, 72.37500,    -0.91040,82.00719,50.00000,0.0000e+000,20.00000,    -0.25172,0.64257
612.87701, 72.55000,    -0.91388,81.96279,50.00000,0.0000e+000,20.00000,    -0.25227,0.64159
614.62000, 72.72500,    -0.91676,81.91949,50.00000,0.0000e+000,20.00000,    -0.25346,0.64063
616.39001, 72.90000,    -0.91929,81.87631,50.00000,0.0000e+000,20.00000,    -0.25559,0.63965
618.14099, 73.07500,    -0.92193,81.83262,50.00000,0.0000e+000,20.00000,    -0.25668,0.63869
619.90302, 73.25000,    -0.92540,81.78725,50.00000,0.0000e+000,20.00000,    -0.25648,0.63773
621.66803, 73.42500,    -0.92901,81.74102,50.00000,0.0000e+000,20.00000,    -0.25619,0.63677
623.42401, 73.60000,    -0.93273,81.69455,50.00000,0.0000e+000,20.00000,    -0.25615,0.63581
625.16998, 73.77500,    -0.93456,81.64774,50.00000,0.0000e+000,20.00000,    -0.25639,0.63487
626.91302, 73.95000,    -0.93604,81.60121,50.00000,0.0000e+000,20.00000,    -0.25700,0.63393
628.65900, 74.12500,    -0.93809,81.55536,50.00000,0.0000e+000,20.00000,    -0.25758,0.63300
630.39600, 74.30000,    -0.94013,81.51048,50.00000,0.0000e+000,20.00000,    -0.25789,0.63207
632.16498, 74.47500,    -0.94347,81.46696,50.00000,0.0000e+000,20.00000,    -0.25807,0.63113
633.89502, 74.65000,    -0.94662,81.42173,50.00000,0.0000e+000,20.00000,    -0.25815,0.63022
635.65997, 74.82500,    -0.95003,81.37473,50.00000,0.0000e+000,20.00000,    -0.25866,0.62929
637.40399, 75.00000,    -0.95106,81.32908,50.00000,0.0000e+000,20.00000,    -0.25948,0.62838
639.14502, 75.17500,    -0.95346,81.28488,50.00000,0.0000e+000,20.00000,    -0.26030,0.62747
640.88599, 75.35000,    -0.96064,81.24181,50.00000,0.0000e+000,20.00000,    -0.26051,0.62656
642.71002, 75.52500,    -0.96668,81.19869,50.00000,0.0000e+000,20.00000,    -0.26001,0.62562
644.47699, 75.70000,    -0.97136,81.15338,50.00000,0.0000e+000,20.00000,    -0.25927,0.62471
646.23602, 75.87500,    -0.97402,81.10661,50.00000,0.0000e+000,20.00000,    -0.25916,0.62380
647.97498, 76.05000,    -0.97384,81.05985,50.00000,0.0000e+000,20.00000,    -0.26002,0.62292
649.72699, 76.22500,    -0.97433,81.01477,50.00000,0.0000e+000,20.00000,    -0.26104,0.62202
651.47101, 76.40000,    -0.97678,80.97123,50.00000,0.0000e+000,20.00000,    -0.26186,0.62114
653.22900, 76.57500,    -0.98090,80.92698,50.00000,0.0000e+000,20.00000,    -0.26243,0.62025
654.97198, 76.75000,    -0.98423,80.88064,50.00000,0.0000e+000,20.00000,    -0.26274,0.61937
656.72803, 76.92500,    -0.98855,80.83163,50.00000,0.0000e+000,20.00000,    -0.26326,0.61850
658.50403, 77.10000,    -0.99270,80.78365,50.00000,0.0000e+000,20.00000,    -0.26441,0.61761
660.28003, 77.27500,    -0.99806,80.73776,50.00000,0.0000e+000,20.00000,    -0.26604,0.61673
662.03497, 77.45000,    -1.00120,80.69366,50.00000,0.0000e+000,20.00000,    -0.26706,0.61586
663.79602, 77.62500,    -1.00281,80.64904,50.00000,0.0000e+000,20.00000,    -0.26736,0.61499
665.52802, 77.80000,    -1.00380,80.60145,50.00000,0.0000e+000,20.00000,    -0.26808,0.61414
667.25702, 77.97500,    -1.00453,80.55292,50.00000,0.0000e+000,20.00000,    -0.27004,0.61330
668.98999, 78.15000,    -1.00595,80.50611,50.00000,0.0000e+000,20.00000,    -0.27254,0.61245
670.71100, 78.32500,    -1.00732,80.45800,50.00000,0.0000e+000,20.00000,    -0.27534,0.61162
672.44202, 78.50000,    -1.00959,80.40951,50.00000,0.0000e+000,20.00000,    -0.27805,0.61078
674.17297, 78.67500,    -1.01294,80.36284,50.00000,0.0000e+000,20.00000,    -0.28033,0.60995
675.91901, 78.85000,    -1.01667,80.31564,50.00000,0.0000e+000,20.00000,    -0.28269,0.60911
677.66803, 79.02500,    -1.02114,80.26720,50.00000,0.0000e+000,20.00000,    -0.28604,0.60828
679.42999, 79.20000,    -1.02496,80.21870,50.00000,0.0000e+000,20.00000,    -0.29014,0.60744
681.16602, 79.37500,    -1.02833,80.17122,50.00000,0.0000e+000,20.00000,    -0.29436,0.60662
682.92798, 79.55000,    -1.03144,80.12312,50.00000,0.0000e+000,20.00000,    -0.29770,0.60578
684.68402, 79.72500,    -1.03274,80.07117,50.00000,0.0000e+000,20.00000,    -0.30007,0.60496
686.42999, 79.90000,    -1.03431,80.01783,50.00000,0.0000e+000,20.00000,    -0.30306,0.60414
688.16803, 80.07500,    -1.03486,79.96448,50.00000,0.0000e+000,20.00000,    -0.30620,0.60333
689.93500, 80.25000,    -1.03787,79.90982,50.00000,0.0000e+000,20.00000,    -0.30936,0.60251
691.68201, 80.42500,    -1.04114,79.85396,50.00000,0.0000e+000,20.00000,    -0.31293,0.60170
693.44800, 80.60000,    -1.04248,79.79704,50.00000,0.0000e+000,20.00000,    -0.31596,0.60089
695.20099, 80.77500,    -1.04462,79.73869,50.00000,0.0000e+000,20.00000,    -0.31893,0.60008
696.95502, 80.95000,    -1.04555,79.67904,50.00000,0.0000e+000,20.00000,    -0.32239,0.59928
698.71100, 81.12500,    -1.04554,79.61946,50.00000,0.0000e+000,20.00000,    -0.32634,0.59848
700.45502, 81.30000,    -1.04820,79.56044,50.00000,0.0000e+000,20.00000,    -0.33101,0.59769
702.22699, 81.47500,    -1.05220,79.50290,50.00000,0.0000e+000,20.00000,    -0.33530,0.59688
703.99402, 81.65000,    -1.05606,79.44507,50.00000,0.0000e+000,20.00000,    -0.33915,0.59609
705.76599, 81.82500,    -1.05933,79.38645,50.00000,0.0000e+000,20.00000,    -0.34449,0.59529
707.51801, 82.00000,    -1.06187,79.32710,50.00000,0.0000e+000,20.00000,    -0.34991,0.59451
709.27600, 82.17500,    -1.06432,79.26600,50.00000,0.0000e+000,20.00000,    -0.35590,0.59373
711.06000, 82.35000,    -1.06879,79.20737,50.00000,0.0000e+000,20.00000,    -0.36165,0.59293
712.84100, 82.52500,    -1.07171,79.14941,50.00000,0.0000e+000,20.00000,    -0.36676,0.59214
714.61102, 82.70000,    -1.07197,79.08916,50.00000,0.0000e+000,20.00000,    -0.37097,0.59136
716.36499, 82.87500,    -1.07041,79.02707,50.00000,0.0000e+000,20.00000,    -0.37453,0.59059
718.12201, 83.05000,    -1.06796,78.96388,50.00000,0.0000e+000,20.00000,    -0.37776,0.58983
719.87903, 83.22500,    -1.06495,78.89814,50.00000,0.0000e+000,20.00000,    -0.38132,0.58906
721.60999, 83.40000,    -1.06163,78.83227,50.00000,0.0000e+000,20.00000,    -0.38560,0.58831
723.34998, 83.57500,    -1.05849,78.76168,50.00000,0.0000e+000,20.00000,    -0.38971,0.58755
725.08600, 83.75000,    -1.05587,78.68817,50.00000,0.0000e+000,20.00000,    -0.39324,0.58680
726.83398, 83.92500,    -1.05342,78.61264,50.00000,0.0000e+000,20.00000,    -0.39648,0.58605
728.57599, 84.10000,    -1.05123,78.53465,50.00000,0.0000e+000,20.00000,    -0.40084,0.58531
730.31897, 84.27500,    -1.05047,78.45792,50.00000,0.0000e+000,20.00000,    -0.40521,0.58456
732.07397, 84.45000,    -1.05216,78.38238,50.00000,0.0000e+000,20.00000,    -0.40956,0.58381
733.80402, 84.62500,    -1.05603,78.30892,50.00000,0.0000e+000,20.00000,    -0.41353,0.58308
735.57001, 84.80000,    -1.06204,78.23711,50.00000,0.0000e+000,20.00000,    -0.41712,0.58233
737.31201, 84.97500,    -1.07046,78.16619,50.00000,0.0000e+000,20.00000,    -0.42040,0.58160
739.09100, 85.15000,    -1.07644,78.09405,50.00000,0.0000e+000,20.00000,    -0.42237,0.58085
740.83502, 85.32500,    -1.07859,78.02045,50.00000,0.0000e+000,20.00000,    -0.42242,0.58012
742.59802, 85.50000,    -1.08079,77.94776,50.00000,0.0000e+000,20.00000,    -0.41988,0.57939
744.36401, 85.67500,    -1.08181,77.87660,50.00000,0.0000e+000,20.00000,    -0.41405,0.57865
746.13300, 85.85000,    -1.08280,77.80149,50.00000,0.0000e+000,20.00000,    -0.40157,0.57792
747.88397, 86.02500,    -1.08336,77.72664,50.00000,0.0000e+000,20.00000,    -0.38515,0.57719
749.62097, 86.20000,    -1.08335,77.65283,50.00000,0.0000e+000,20.00000,    -0.36767,0.57648
751.36902, 86.37500,    -1.08334,77.57668,50.00000,0.0000e+000,20.00000,    -0.35008,0.57576
753.15503, 86.55000,    -1.08485,77.50133,50.00000,0.0000e+000,20.00000,    -0.33235,0.57503
754.89502, 86.72500,    -1.08749,77.42466,50.00000,0.0000e+000,20.00000,    -0.31492,0.57432
756.65503, 86.90000,    -1.09304,77.34943,50.00000,0.0000e+000,20.00000,    -0.29757,0.57361
758.39899, 87.07500,    -1.10284,77.27945,50.00000,0.0000e+000,20.00000,    -0.27912,0.57290
760.15601, 87.25000,    -1.11709,77.21356,50.00000,0.0000e+000,20.00000,    -0.26052,0.57219
761.90302, 87.42500,    -1.14193,77.15447,50.00000,0.0000e+000,20.00000,    -0.24302,0.57148
763.66803, 87.60000,    -1.18925,77.11284,50.00000,0.0000e+000,20.00000,    -0.22526,0.57077
765.42902, 87.77500,    -1.23566,77.09077,50.00000,0.0000e+000,20.00000,    -0.20685,0.57007
767.19598, 87.95000,    -1.26177,77.07689,50.00000,0.0000e+000,20.00000,    -0.18922,0.56936
768.96503, 88.12500,    -1.27605,77.06589,50.00000,0.0000e+000,20.00000,    -0.17090,0.56866
770.71002, 88.30000,    -1.28605,77.05709,50.00000,0.0000e+000,20.00000,    -0.15206,0.56797
772.47101, 88.47500,    -1.29287,77.05005,50.00000,0.0000e+000,20.00000,    -0.13283,0.56727
774.21899, 88.65000,    -1.29905,77.04201,50.00000,0.0000e+000,20.00000,    -0.11337,0.56658
775.98401, 88.82500,    -1.30526,77.03508,50.00000,0.0000e+000,20.00000,-9.5450e-002,0.56588
777.75500, 89.00000,    -1.31198,77.03020,50.00000,0.0000e+000,20.00000,-7.9102e-002,0.56519
779.51801, 89.17500,    -1.31696,77.02342,50.00000,0.0000e+000,20.00000,-6.3704e-002,0.56450
781.27301, 89.35000,    -1.32212,77.01560,50.00000,0.0000e+000,20.00000,-5.0976e-002,0.56381
783.02197, 89.52500,    -1.32597,77.00720,50.00000,0.0000e+000,20.00000,-4.4006e-002,0.56313
784.75897, 89.70000,    -1.32992,76.99826,50.00000,0.0000e+000,20.00000,-4.0962e-002,0.56246
786.50800, 89.87500,    -1.33552,76.98944,50.00000,0.0000e+000,20.00000,-3.9274e-002,0.56178
788.25800, 90.05000,    -1.34121,76.98170,50.00000,0.0000e+000,20.00000,-3.8365e-002,0.56111
790.00702, 90.22500,    -1.34687,76.97568,50.00000,0.0000e+000,20.00000,-3.8236e-002,0.56043
791.76898, 90.40000,    -1.35277,76.97040,50.00000,0.0000e+000,20.00000,-3.8190e-002,0.55975
793.52802, 90.57500,    -1.35713,76.96413,50.00000,0.0000e+000,20.00000,-3.8076e-002,0.55908
795.27197, 90.75000,    -1.36227,76.95669,50.00000,0.0000e+000,20.00000,-3.8152e-002,0.55841
797.01202, 90.92500,    -1.36836,76.94907,50.00000,0.0000e+000,20.00000,-3.8173e-002,0.55775
798.78198, 91.10000,    -1.37372,76.94379,50.00000,0.0000e+000,20.00000,-3.8357e-002,0.55708
800.59302, 91.27500,    -1.38444,76.94014,50.00000,0.0000e+000,20.00000,-3.7955e-002,0.55639
802.38397, 91.45000,    -1.39357,76.93514,50.00000,0.0000e+000,20.00000,-3.6590e-002,0.55571
804.16699, 91.62500,    -1.39743,76.92970,50.00000,0.0000e+000,20.00000,-3.4831e-002,0.55504
805.91901, 91.80000,    -1.39725,76.92340,50.00000,0.0000e+000,20.00000,-3.3239e-002,0.55438
807.65698, 91.97500,    -1.39785,76.91657,50.00000,0.0000e+000,20.00000,-3.2244e-002,0.55373
809.40100, 92.15000,    -1.39939,76.90941,50.00000,0.0000e+000,20.00000,-3.1498e-002,0.55307
811.13898, 92.32500,    -1.40082,76.90180,50.00000,0.0000e+000,20.00000,-3.1029e-002,0.55242
812.88599, 92.50000,    -1.40298,76.89524,50.00000,0.0000e+000,20.00000,-3.0266e-002,0.55177
814.63599, 92.67500,    -1.40676,76.89001,50.00000,0.0000e+000,20.00000,-2.9493e-002,0.55112
816.37402, 92.85000,    -1.40990,76.88271,50.00000,0.0000e+000,20.00000,-2.9107e-002,0.55047
818.11499, 93.02500,    -1.41397,76.87476,50.00000,0.0000e+000,20.00000,-2.9394e-002,0.54983
819.85101, 93.20000,    -1.41793,76.86992,50.00000,0.0000e+000,20.00000,-2.9362e-002,0.54918
821.58899, 93.37500,    -1.42288,76.86707,50.00000,0.0000e+000,20.00000,-2.9002e-002,0.54854
823.33099, 93.55000,    -1.42755,76.86465,50.00000,0.0000e+000,20.00000,-2.8434e-002,0.54790
825.07202, 93.72500,    -1.43263,76.86161,50.00000,0.0000e+000,20.00000,-2.7781e-002,0.54726
826.78802, 93.90000,    -1.43653,76.85896,50.00000,0.0000e+000,20.00000,-2.7469e-002,0.54663
828.48199, 94.07500,    -1.43985,76.85547,50.00000,0.0000e+000,20.00000,-2.6668e-002,0.54601
830.20099, 94.25000,    -1.44773,76.85145,50.00000,0.0000e+000,20.00000,-2.5377e-002,0.54538
831.96698, 94.42500,    -1.45774,76.84676,50.00000,0.0000e+000,20.00000,-2.5016e-002,0.54473
833.73499, 94.60000,    -1.47157,76.84162,50.00000,0.0000e+000,20.00000,-2.4809e-002,0.54409
835.50098, 94.77500,    -1.48273,76.83657,50.00000,0.0000e+000,20.00000,-2.4321e-002,0.54345
837.25500, 94.95000,    -1.49094,76.83190,50.00000,0.0000e+000,20.00000,-2.4305e-002,0.54281
839.00403, 95.12500,    -1.50064,76.82802,50.00000,0.0000e+000,20.00000,-2.4829e-002,0.54218
840.78900, 95.30000,    -1.50881,76.82393,50.00000,0.0000e+000,20.00000,-2.5361e-002,0.54153
842.55499, 95.47500,    -1.51619,76.82021,50.00000,0.0000e+000,20.00000,-2.5801e-002,0.54089
844.33502, 95.65000,    -1.52632,76.81493,50.00000,0.0000e+000,20.00000,-2.6215e-002,0.54025
846.10303, 95.82500,    -1.53593,76.80927,50.00000,0.0000e+000,20.00000,-2.6461e-002,0.53962
847.89301, 96.00000,    -1.54332,76.80638,50.00000,0.0000e+000,20.00000,-2.5820e-002,0.53897
849.63599, 96.17500,    -1.54779,76.80297,50.00000,0.0000e+000,20.00000,-2.5629e-002,0.53835
851.39502, 96.35000,    -1.55215,76.79813,50.00000,0.0000e+000,20.00000,-2.5864e-002,0.53772
853.14502, 96.52500,    -1.55646,76.79208,50.00000,0.0000e+000,20.00000,-2.6119e-002,0.53709
854.90601, 96.70000,    -1.56225,76.78552,50.00000,0.0000e+000,20.00000,-2.5601e-002,0.53646
856.69299, 96.87500,    -1.56977,76.77978,50.00000,0.0000e+000,20.00000,-2.5335e-002,0.53583
858.46301, 97.05000,    -1.57750,76.77484,50.00000,0.0000e+000,20.00000,-2.5479e-002,0.53520
860.23999, 97.22500,    -1.58106,76.77069,50.00000,0.0000e+000,20.00000,-2.5236e-002,0.53456
861.98999, 97.40000,    -1.58297,76.76626,50.00000,0.0000e+000,20.00000,-2.5116e-002,0.53394
863.73700, 97.57500,    -1.58711,76.76189,50.00000,0.0000e+000,20.00000,-2.5106e-002,0.53332
865.49103, 97.75000,    -1.59035,76.75946,50.00000,0.0000e+000,20.00000,-2.5201e-002,0.53270
867.30200, 97.92500,    -1.60155,76.75736,50.00000,0.0000e+000,20.00000,-2.4949e-002,0.53206
869.10602, 98.10000,    -1.61171,76.75208,50.00000,0.0000e+000,20.00000,-2.4774e-002,0.53142
870.86798, 98.27500,    -1.61374,76.74584,50.00000,0.0000e+000,20.00000,-2.4512e-002,0.53080
872.68402, 98.45000,    -1.62198,76.74122,50.00000,0.0000e+000,20.00000,-2.3830e-002,0.53016
874.46301, 98.62500,    -1.62678,76.73891,50.00000,0.0000e+000,20.00000,-2.3452e-002,0.52954
876.20099, 98.80000,    -1.62801,76.73447,50.00000,0.0000e+000,20.00000,-2.3210e-002,0.52893
877.92902, 98.97500,    -1.62547,76.73085,50.00000,0.0000e+000,20.00000,-2.3542e-002,0.52832
879.62299, 99.15000,    -1.62338,76.72779,50.00000,0.0000e+000,20.00000,-2.4497e-002,0.52773
881.33801, 99.32500,    -1.62363,76.72250,50.00000,0.0000e+000,20.00000,-2.5374e-002,0.52712
883.08002, 99.50000,    -1.63085,76.71683,50.00000,0.0000e+000,20.00000,-2.6263e-002,0.52651
884.85699, 99.67500,    -1.63870,76.71433,50.00000,0.0000e+000,20.00000,-2.7786e-002,0.52589
886.57599, 99.85000,    -1.64355,76.71177,50.00000,0.0000e+000,20.00000,-2.8757e-002,0.52529
888.31702,100.02500,    -1.64565,76.70725,50.00000,0.0000e+000,20.00000,-2.9241e-002,0.52469
890.03101,100.20000,    -1.64484,76.70312,50.00000,0.0000e+000,20.00000,-3.0129e-002,0.52409
891.76398,100.37500,    -1.64382,76.69862,50.00000,0.0000e+000,20.00000,-3.1931e-002,0.52348
893.48401,100.55000,    -1.64625,76.69405,50.00000,0.0000e+000,20.00000,-3.3603e-002,0.52288
895.22498,100.72500,    -1.65081,76.68920,50.00000,0.0000e+000,20.00000,-3.5353e-002,0.52228
896.96997,100.90000,    -1.65438,76.68238,50.00000,0.0000e+000,20.00000,-3.7939e-002,0.52167
898.71100,101.07500,    -1.65765,76.67420,50.00000,0.0000e+000,20.00000,-4.0186e-002,0.52107
900.45099,101.25000,    -1.66181,76.66725,50.00000,0.0000e+000,20.00000,-4.1778e-002,0.52046
902.20801,101.42500,    -1.66407,76.66024,50.00000,0.0000e+000,20.00000,-4.3776e-002,0.51985
904.01801,101.60000,    -1.67149,76.65298,50.00000,0.0000e+000,20.00000,-4.6494e-002,0.51923
905.86700,101.77500,    -1.68951,76.64526,50.00000,0.0000e+000,20.00000,-4.8946e-002,0.51859
907.58801,101.95000,    -1.68254,76.63685,50.00000,0.0000e+000,20.00000,-5.1567e-002,0.51799
909.32098,102.12500,    -1.67921,76.62744,50.00000,0.0000e+000,20.00000,-5.3969e-002,0.51739
911.06799,102.30000,    -1.67806,76.61813,50.00000,0.0000e+000,20.00000,-5.6359e-002,0.51679
912.81403,102.47500,    -1.67847,76.60792,50.00000,0.0000e+000,20.00000,-5.9406e-002,0.51618
914.56897,102.65000,    -1.68029,76.59629,50.00000,0.0000e+000,20.00000,-6.2438e-002,0.51558
916.32300,102.82500,    -1.68195,76.58362,50.00000,0.0000e+000,20.00000,-6.5258e-002,0.51497
918.06702,103.00000,    -1.68224,76.57160,50.00000,0.0000e+000,20.00000,-6.8141e-002,0.51437
919.83301,103.17500,    -1.68283,76.56002,50.00000,0.0000e+000,20.00000,-7.1668e-002,0.51376
921.60400,103.35000,    -1.68808,76.54869,50.00000,0.0000e+000,20.00000,-7.5609e-002,0.51315
923.38800,103.52500,    -1.68995,76.53626,50.00000,0.0000e+000,20.00000,-7.9019e-002,0.51253
925.13000,103.70000,    -1.68837,76.52264,50.00000,0.0000e+000,20.00000,-8.2083e-002,0.51193
926.88202,103.87500,    -1.68526,76.50900,50.00000,0.0000e+000,20.00000,-8.5948e-002,0.51133
928.64099,104.05000,    -1.68439,76.49631,50.00000,0.0000e+000,20.00000,-9.0504e-002,0.51072
930.41998,104.22500,    -1.68507,76.48143,50.00000,0.0000e+000,20.00000,-9.5623e-002,0.51011
932.18103,104.40000,    -1.68349,76.46521,50.00000,0.0000e+000,20.00000,    -0.10075,0.50950
933.93103,104.57500,    -1.67688,76.44737,50.00000,0.0000e+000,20.00000,    -0.10526,0.50890
935.67700,104.75000,    -1.67073,76.42920,50.00000,0.0000e+000,20.00000,    -0.10989,0.50830
937.43500,104.92500,    -1.66379,76.41050,50.00000,0.0000e+000,20.00000,    -0.11554,0.50769
939.15100,105.10000,    -1.65527,76.38950,50.00000,0.0000e+000,20.00000,    -0.12182,0.50710
940.89697,105.27500,    -1.64752,76.36836,50.00000,0.0000e+000,20.00000,    -0.12758,0.50650
942.65100,105.45000,    -1.64382,76.34956,50.00000,0.0000e+000,20.00000,    -0.13244,0.50590
944.40601,105.62500,    -1.64077,76.32826,50.00000,0.0000e+000,20.00000,    -0.13729,0.50529
946.16602,105.80000,    -1.63407,76.30327,50.00000,0.0000e+000,20.00000,    -0.14222,0.50469
947.91998,105.97500,    -1.62858,76.27597,50.00000,0.0000e+000,20.00000,    -0.14724,0.50409
949.66602,106.15000,    -1.62199,76.24658,50.00000,0.0000e+000,20.00000,    -0.15183,0.50348
951.43298,106.32500,    -1.61625,76.21709,50.00000,0.0000e+000,20.00000,    -0.15577,0.50288
953.18201,106.50000,    -1.60883,76.18856,50.00000,0.0000e+000,20.00000,    -0.15836,0.50227
954.96802,106.67500,    -1.60876,76.15746,50.00000,0.0000e+000,20.00000,    -0.16082,0.50166
956.75403,106.85000,    -1.60845,76.12379,50.00000,0.0000e+000,20.00000,    -0.16351,0.50104
958.55200,107.02500,    -1.60736,76.08974,50.00000,0.0000e+000,20.00000,    -0.16574,0.50042
960.31702,107.20000,    -1.60268,76.05849,50.00000,0.0000e+000,20.00000,    -0.16807,0.49982
962.05902,107.37500,    -1.59625,76.02711,50.00000,0.0000e+000,20.00000,    -0.17024,0.49921
963.80798,107.55000,    -1.59153,75.99581,50.00000,0.0000e+000,20.00000,    -0.17094,0.49861
965.56097,107.72500,    -1.58742,75.96457,50.00000,0.0000e+000,20.00000,    -0.17033,0.49801
967.32300,107.90000,    -1.58536,75.93193,50.00000,0.0000e+000,20.00000,    -0.16916,0.49740
969.06500,108.07500,    -1.58461,75.89978,50.00000,0.0000e+000,20.00000,    -0.16756,0.49680
970.81500,108.25000,    -1.58557,75.87014,50.00000,0.0000e+000,20.00000,    -0.16607,0.49619
972.55902,108.42500,    -1.58628,75.84363,50.00000,0.0000e+000,20.00000,    -0.16441,0.49559
974.31299,108.60000,    -1.58697,75.81477,50.00000,0.0000e+000,20.00000,    -0.16181,0.49499
976.04602,108.77500,    -1.58755,75.78474,50.00000,0.0000e+000,20.00000,    -0.15841,0.49439
977.91699,108.95000,    -1.59756,75.75578,50.00000,0.0000e+000,20.00000,    -0.15529,0.49374
979.74103,109.12500,    -1.60909,75.72815,50.00000,0.0000e+000,20.00000,    -0.15337,0.49311
981.50500,109.30000,    -1.60925,75.70120,50.00000,0.0000e+000,20.00000,    -0.15082,0.49250
983.23297,109.47500,    -1.60341,75.67630,50.00000,0.0000e+000,20.00000,    -0.14707,0.49190
984.95502,109.65000,    -1.59723,75.65232,50.00000,0.0000e+000,20.00000,    -0.14372,0.49130
986.66302,109.82500,    -1.59449,75.62798,50.00000,0.0000e+000,20.00000,    -0.14129,0.49071
988.37402,110.00000,    -1.59241,75.60468,50.00000,0.0000e+000,20.00000,    -0.13679,0.49012
990.08698,110.17500,    -1.59434,75.58114,50.00000,0.0000e+000,20.00000,    -0.13304,0.48952
991.82202,110.35000,    -1.59849,75.55770,50.00000,0.0000e+000,20.00000,    -0.13152,0.48892
993.55103,110.52500,    -1.60107,75.53507,50.00000,0.0000e+000,20.00000,    -0.13012,0.48832
995.27899,110.70000,    -1.60461,75.51400,50.00000,0.0000e+000,20.00000,    -0.12787,0.48772
997.06897,110.87500,    -1.61268,75.49162,50.00000,0.0000e+000,20.00000,    -0.13323,0.48710
998.38300,111.00500,    -1.61712,75.47369,50.00000,0.0000e+000,20.00000,-7.7809e-002,0.48664