File: book/some_content/ExpDat_A8%DC14; 30-1-2025-2.csv
#FILE:                       ,A8%DC14; 30-1-2025.ngb-ds3         ,,,,,,,
#FORMAT:                     ,NETZSCH5                           ,,,,,,,
#IDENTITY:                   ,GEOPOLYMER PASTE                   ,,,,,,,
#DECIMAL:                    ,POINT                              ,,,,,,,
#SEPARATOR:                  ,COMMA                              ,,,,,,,
#MTYPE:                      ,DSC                                ,,,,,,,
#INSTRUMENT:                 ,Microlab TU Delft                  ,,,,,,,
#PROJECT:                    ,                                   ,,,,,,,
#DATE/TIME:                  ,31/01/2025 4:40:42 PM              ,,,,,,,
#CORR. FILE:                 ,Blank with cover; 13-1-2025.ngb-bs3,,,,,,,
#LABORATORY:                 ,TU Delft Micro Lab                 ,,,,,,,
#OPERATOR:                   ,Ahmed                              ,,,,,,,
#REMARK:                     ,under Argon atmosphere, 10K/min    ,,,,,,
#SAMPLE:                     ,A8%DC14                            ,,,,,,,
#SAMPLE MASS /mg:            ,32.8,,,,,,,
#MATERIAL:                   ,Geopolymer paste                   ,,,,,,,
#REFERENCE:                  ,blank                              ,,,,,,,
#REFERENCE MASS /mg:         ,0,,,,,,,
#TYPE OF CRUCIBLE:           ,DSC/TG pan Al2O3                   ,,,,,,,
#SAMPLE CRUCIBLE MASS /mg:   ,0,,,,,,,
#REFERENCE CRUCIBLE MASS /mg:,0,,,,,,,
#CORR. CODE:                 ,20,,,,,,,
#EXO:                        ,-1,,,,,,,
#RANGE:                      ,40/10.0(K/min)/1000                ,,,,,,,
#SEGMENT:                    ,S2/2                               ,,,,,,,
,,,,,,,,
##Temp./øC,Time/min,DSC/(mW/mg),Mass/%,Gas Flow(purge1)/(ml/min),Gas Flow(purge2)/(ml/min),Gas Flow(protective)/(ml/min),DTG/(%/min),Sensit./(uV/mW)
50.407,18.32583,-4.59E-02,92.77021,50,0.00E+00,20,-0.11865,1.2126
50.434,18.45583,-4.71E-02,92.75559,50,0.00E+00,20,-0.10665,1.21256
50.533,18.58583,-4.81E-02,92.74249,50,0.00E+00,20,-9.49E-02,1.21243
50.632,18.71583,-4.82E-02,92.73083,50,0.00E+00,20,-8.43E-02,1.21229
50.801,18.84583,-4.82E-02,92.72073,50,0.00E+00,20,-7.15E-02,1.21206
51.025,18.97583,-4.74E-02,92.71199,50,0.00E+00,20,-6.12E-02,1.21175
51.282,19.10583,-4.61E-02,92.70468,50,0.00E+00,20,-5.09E-02,1.2114
51.628,19.23583,-4.42E-02,92.69865,50,0.00E+00,20,-4.27E-02,1.21092
52.018,19.36583,-4.23E-02,92.69355,50,0.00E+00,20,-3.53E-02,1.21038
52.449,19.49583,-3.95E-02,92.68934,50,0.00E+00,20,-2.87E-02,1.20979
52.979,19.62583,-3.62E-02,92.68595,50,0.00E+00,20,-2.19E-02,1.20906
53.562,19.75583,-3.30E-02,92.68343,50,0.00E+00,20,-1.71E-02,1.20826
54.206,19.88583,-2.89E-02,92.68142,50,0.00E+00,20,-1.46E-02,1.20737
54.925,20.01583,-2.48E-02,92.67979,50,0.00E+00,20,-1.14E-02,1.20638
55.708,20.14583,-2.03E-02,92.67846,50,0.00E+00,20,-9.16E-03,1.2053
56.54,20.27583,-1.55E-02,92.67723,50,0.00E+00,20,-9.58E-03,1.20416
57.459,20.40583,-1.03E-02,92.67594,50,0.00E+00,20,-1.12E-02,1.20289
58.442,20.53583,-5.46E-03,92.67431,50,0.00E+00,20,-1.36E-02,1.20154
59.48,20.66583,-9.69E-05,92.67214,50,0.00E+00,20,-1.92E-02,1.20012
60.564,20.79583,5.47E-03,92.66915,50,0.00E+00,20,-2.71E-02,1.19863
61.721,20.92583,1.13E-02,92.66505,50,0.00E+00,20,-3.54E-02,1.19704
62.93,21.05583,1.70E-02,92.65984,50,0.00E+00,20,-4.49E-02,1.19538
64.2,21.18583,2.29E-02,92.65326,50,0.00E+00,20,-5.68E-02,1.19363
65.523,21.31583,2.87E-02,92.64502,50,0.00E+00,20,-7.05E-02,1.19182
66.888,21.44583,3.50E-02,92.63483,50,0.00E+00,20,-8.55E-02,1.18994
68.323,21.57583,4.15E-02,92.62256,50,0.00E+00,20,-0.10424,1.18797
69.793,21.70583,4.82E-02,92.60762,50,0.00E+00,20,-0.12633,1.18596
71.318,21.83583,5.46E-02,92.58977,50,0.00E+00,20,-0.1487,1.18387
72.879,21.96583,6.20E-02,92.569,50,0.00E+00,20,-0.17091,1.18173
74.47,22.09583,6.92E-02,92.54527,50,0.00E+00,20,-0.19436,1.17955
76.138,22.22583,7.71E-02,92.51836,50,0.00E+00,20,-0.21959,1.17727
77.789,22.35583,8.51E-02,92.48807,50,0.00E+00,20,-0.24704,1.17501
79.524,22.48583,9.39E-02,92.45389,50,0.00E+00,20,-0.27923,1.17264
81.295,22.61583,0.10302,92.41515,50,0.00E+00,20,-0.3188,1.17022
83.071,22.74583,0.11278,92.37154,50,0.00E+00,20,-0.35165,1.1678
84.9,22.87583,0.1227,92.32393,50,0.00E+00,20,-0.38094,1.1653
86.758,23.00583,0.13419,92.27207,50,0.00E+00,20,-0.41825,1.16277
88.635,23.13583,0.14605,92.21543,50,0.00E+00,20,-0.45383,1.16021
90.542,23.26583,0.15844,92.15426,50,0.00E+00,20,-0.48865,1.15761
92.476,23.39583,0.17177,92.08808,50,0.00E+00,20,-0.5275,1.15498
94.415,23.52583,0.1857,92.01695,50,0.00E+00,20,-0.56505,1.15235
96.386,23.65583,0.20086,91.94121,50,0.00E+00,20,-0.6013,1.14967
98.364,23.78583,0.21634,91.86052,50,0.00E+00,20,-0.63976,1.14699
100.363,23.91583,0.23255,91.77494,50,0.00E+00,20,-0.67713,1.14428
102.372,24.04583,0.24901,91.6843,50,0.00E+00,20,-0.71456,1.14156
104.393,24.17583,0.26658,91.58896,50,0.00E+00,20,-0.75132,1.13883
106.406,24.30583,0.28393,91.48911,50,0.00E+00,20,-0.7856,1.13611
108.423,24.43583,0.30152,91.38496,50,0.00E+00,20,-0.81702,1.13339
110.448,24.56583,0.31906,91.27674,50,0.00E+00,20,-0.8479,1.13066
112.494,24.69583,0.33623,91.16456,50,0.00E+00,20,-0.87757,1.1279
114.521,24.82583,0.35313,91.04858,50,0.00E+00,20,-0.90594,1.12518
116.578,24.95583,0.36878,90.92908,50,0.00E+00,20,-0.93212,1.12241
118.603,25.08583,0.38376,90.80641,50,0.00E+00,20,-0.95596,1.11969
120.642,25.21583,0.39763,90.6808,50,0.00E+00,20,-0.97599,1.11696
122.672,25.34583,0.41018,90.55275,50,0.00E+00,20,-0.99412,1.11424
124.709,25.47583,0.42117,90.42255,50,0.00E+00,20,-1.00819,1.11152
126.739,25.60583,0.43074,90.2908,50,0.00E+00,20,-1.0198,1.10881
128.78,25.73583,0.43869,90.15709,50,0.00E+00,20,-1.03412,1.10609
130.79401,25.86583,0.44505,90.02212,50,0.00E+00,20,-1.04265,1.10341
132.82899,25.99583,0.44963,89.88611,50,0.00E+00,20,-1.04899,1.1007
134.85001,26.12583,0.45236,89.74945,50,0.00E+00,20,-1.05193,1.09802
136.84801,26.25583,0.4536,89.61317,50,0.00E+00,20,-1.04274,1.09537
138.84801,26.38583,0.45326,89.47767,50,0.00E+00,20,-1.04241,1.09272
140.85001,26.51583,0.45088,89.34223,50,0.00E+00,20,-1.04045,1.09007
142.834,26.64583,0.44749,89.20744,50,0.00E+00,20,-1.03068,1.08745
144.804,26.77583,0.4422,89.07367,50,0.00E+00,20,-1.02612,1.08486
146.748,26.90583,0.43639,88.94069,50,0.00E+00,20,-1.01957,1.0823
148.69901,27.03583,0.42915,88.80894,50,0.00E+00,20,-1.00734,1.07973
150.63699,27.16583,0.42047,88.67905,50,0.00E+00,20,-0.99203,1.07719
152.57401,27.29583,0.4109,88.55096,50,0.00E+00,20,-0.97829,1.07465
154.47,27.42583,0.40083,88.42484,50,0.00E+00,20,-0.96172,1.07217
156.354,27.55583,0.38988,88.30081,50,0.00E+00,20,-0.9466,1.06971
158.22701,27.68583,0.37833,88.17904,50,0.00E+00,20,-0.92806,1.06727
160.09801,27.81583,0.36648,88.05959,50,0.00E+00,20,-0.90867,1.06483
161.92101,27.94583,0.35375,87.94262,50,0.00E+00,20,-0.89048,1.06246
163.74899,28.07583,0.34056,87.82789,50,0.00E+00,20,-0.87378,1.06009
165.554,28.20583,0.32759,87.71539,50,0.00E+00,20,-0.85654,1.05775
167.354,28.33583,0.31373,87.60523,50,0.00E+00,20,-0.8382,1.05542
169.12199,28.46583,0.29998,87.49747,50,0.00E+00,20,-0.81983,1.05313
170.892,28.59583,0.2858,87.39213,50,0.00E+00,20,-0.8011,1.05085
172.627,28.72583,0.27173,87.28915,50,0.00E+00,20,-0.78194,1.04862
174.35699,28.85583,0.25786,87.18875,50,0.00E+00,20,-0.76347,1.04639
176.08701,28.98583,0.24364,87.09068,50,0.00E+00,20,-0.74514,1.04417
177.77,29.11583,0.2297,86.99504,50,0.00E+00,20,-0.72796,1.04201
179.45399,29.24583,0.2161,86.90129,50,0.00E+00,20,-0.71249,1.03986
181.14101,29.37583,0.20261,86.81012,50,0.00E+00,20,-0.69228,1.0377
182.782,29.50583,0.18914,86.72104,50,0.00E+00,20,-0.67709,1.03561
184.423,29.63583,0.17582,86.63409,50,0.00E+00,20,-0.66073,1.03352
186.03799,29.76583,0.16279,86.54936,50,0.00E+00,20,-0.64408,1.03147
187.63901,29.89583,0.14985,86.46651,50,0.00E+00,20,-0.63043,1.02943
189.226,30.02583,0.13722,86.38569,50,0.00E+00,20,-0.61286,1.02742
190.813,30.15583,0.12478,86.30694,50,0.00E+00,20,-0.59988,1.02541
192.37199,30.28583,0.11277,86.22987,50,0.00E+00,20,-0.58534,1.02344
193.909,30.41583,0.10119,86.15489,50,0.00E+00,20,-0.56757,1.02151
195.44901,30.54583,8.93E-02,86.08204,50,0.00E+00,20,-0.55296,1.01957
196.959,30.67583,7.83E-02,86.01112,50,0.00E+00,20,-0.53853,1.01767
198.46001,30.80583,6.74E-02,85.94189,50,0.00E+00,20,-0.52684,1.01578
199.972,30.93583,5.65E-02,85.8742,50,0.00E+00,20,-0.51449,1.01389
201.44299,31.06583,4.59E-02,85.80804,50,0.00E+00,20,-0.50298,1.01205
202.89999,31.19583,3.56E-02,85.74341,50,0.00E+00,20,-0.49101,1.01023
204.35699,31.32583,2.52E-02,85.68046,50,0.00E+00,20,-0.47842,1.00841
205.798,31.45583,1.56E-02,85.61909,50,0.00E+00,20,-0.46635,1.00662
207.222,31.58583,6.00E-03,85.55918,50,0.00E+00,20,-0.45508,1.00484
208.65199,31.71583,-3.83E-03,85.50082,50,0.00E+00,20,-0.44303,1.00307
210.06,31.84583,-1.31E-02,85.44405,50,0.00E+00,20,-0.43089,1.00132
211.46201,31.97583,-2.19E-02,85.38866,50,0.00E+00,20,-0.42156,0.99959
212.84,32.10583,-3.09E-02,85.33461,50,0.00E+00,20,-0.41028,0.99789
214.226,32.23583,-4.01E-02,85.28199,50,0.00E+00,20,-0.39951,0.99618
215.578,32.36583,-4.93E-02,85.23076,50,0.00E+00,20,-0.38944,0.99451
216.944,32.49583,-5.83E-02,85.18075,50,0.00E+00,20,-0.37931,0.99283
218.304,32.62583,-6.82E-02,85.13213,50,0.00E+00,20,-0.3681,0.99116
219.651,32.75583,-7.80E-02,85.08493,50,0.00E+00,20,-0.35807,0.98951
220.97,32.88583,-8.74E-02,85.0388,50,0.00E+00,20,-0.35183,0.9879
222.315,33.01583,-9.78E-02,84.99362,50,0.00E+00,20,-0.34306,0.98625
223.633,33.14583,-0.1081,84.9496,50,0.00E+00,20,-0.33478,0.98465
224.948,33.27583,-0.11871,84.90653,50,0.00E+00,20,-0.32724,0.98304
226.244,33.40583,-0.12938,84.86455,50,0.00E+00,20,-0.31942,0.98147
227.55099,33.53583,-0.14013,84.82359,50,0.00E+00,20,-0.31092,0.97988
228.86301,33.66583,-0.15065,84.78358,50,0.00E+00,20,-0.30451,0.97829
230.15401,33.79583,-0.16068,84.74447,50,0.00E+00,20,-0.29723,0.97673
231.43401,33.92583,-0.17112,84.70629,50,0.00E+00,20,-0.29058,0.97518
232.72,34.05583,-0.18121,84.66901,50,0.00E+00,20,-0.28373,0.97363
234,34.18583,-0.19095,84.63251,50,0.00E+00,20,-0.27789,0.97209
235.26199,34.31583,-0.201,84.59682,50,0.00E+00,20,-0.27115,0.97057
236.55701,34.44584,-0.21054,84.56193,50,0.00E+00,20,-0.26629,0.96902
237.813,34.57583,-0.21998,84.52766,50,0.00E+00,20,-0.26087,0.96751
239.086,34.70583,-0.22899,84.49423,50,0.00E+00,20,-0.25392,0.96599
240.339,34.83583,-0.23794,84.46156,50,0.00E+00,20,-0.2485,0.96449
241.605,34.96583,-0.24681,84.42955,50,0.00E+00,20,-0.24357,0.96298
242.858,35.09583,-0.25496,84.39812,50,0.00E+00,20,-0.2396,0.96149
244.114,35.22583,-0.26316,84.36728,50,0.00E+00,20,-0.23501,0.95999
245.35699,35.35583,-0.27065,84.33694,50,0.00E+00,20,-0.23146,0.95852
246.617,35.48583,-0.27868,84.30707,50,0.00E+00,20,-0.22853,0.95703
247.86301,35.61583,-0.28595,84.27766,50,0.00E+00,20,-0.22369,0.95555
249.09801,35.74583,-0.2929,84.24868,50,0.00E+00,20,-0.22174,0.95409
250.34399,35.87583,-0.29984,84.22004,50,0.00E+00,20,-0.21919,0.95262
251.584,36.00583,-0.30695,84.19167,50,0.00E+00,20,-0.21708,0.95116
252.811,36.13583,-0.31354,84.16347,50,0.00E+00,20,-0.21687,0.94972
254.04601,36.26583,-0.3205,84.13542,50,0.00E+00,20,-0.21511,0.94827
255.284,36.39583,-0.32733,84.10755,50,0.00E+00,20,-0.21376,0.94682
256.53799,36.52583,-0.33406,84.07999,50,0.00E+00,20,-0.21002,0.94536
257.76001,36.65583,-0.34036,84.05274,50,0.00E+00,20,-0.20919,0.94393
259.009,36.78583,-0.34722,84.02555,50,0.00E+00,20,-0.20784,0.94247
260.25299,36.91583,-0.35376,83.99878,50,0.00E+00,20,-0.20491,0.94103
261.48401,37.04583,-0.3596,83.97213,50,0.00E+00,20,-0.2049,0.9396
262.71399,37.17583,-0.36535,83.94555,50,0.00E+00,20,-0.20447,0.93817
263.957,37.30583,-0.37098,83.91908,50,0.00E+00,20,-0.20268,0.93673
265.19901,37.43583,-0.37608,83.89278,50,0.00E+00,20,-0.2018,0.9353
266.448,37.56583,-0.38131,83.86651,50,0.00E+00,20,-0.20216,0.93386
267.68301,37.69584,-0.38634,83.84022,50,0.00E+00,20,-0.20211,0.93244
268.927,37.82583,-0.39215,83.81402,50,0.00E+00,20,-0.20174,0.93101
270.15799,37.95583,-0.3974,83.78789,50,0.00E+00,20,-0.20105,0.9296
271.41501,38.08583,-0.40198,83.76177,50,0.00E+00,20,-0.20033,0.92816
272.651,38.21583,-0.40673,83.73572,50,0.00E+00,20,-0.20027,0.92674
273.89401,38.34583,-0.41125,83.70964,50,0.00E+00,20,-0.20052,0.92533
275.116,38.47583,-0.41542,83.68354,50,0.00E+00,20,-0.20035,0.92393
276.37601,38.60583,-0.41977,83.65741,50,0.00E+00,20,-0.20173,0.9225
277.61801,38.73583,-0.4242,83.63112,50,0.00E+00,20,-0.20283,0.92109
278.86499,38.86583,-0.42905,83.60461,50,0.00E+00,20,-0.20455,0.91968
280.12399,38.99583,-0.43351,83.57796,50,0.00E+00,20,-0.20576,0.91826
281.35699,39.12583,-0.43861,83.55119,50,0.00E+00,20,-0.20598,0.91687
282.61099,39.25583,-0.44313,83.52437,50,0.00E+00,20,-0.20649,0.91545
283.862,39.38583,-0.44742,83.4975,50,0.00E+00,20,-0.20745,0.91405
285.12799,39.51583,-0.45189,83.47045,50,0.00E+00,20,-0.20837,0.91263
286.35699,39.64583,-0.45551,83.44332,50,0.00E+00,20,-0.20952,0.91125
287.616,39.77583,-0.45969,83.41611,50,0.00E+00,20,-0.2096,0.90984
288.86301,39.90583,-0.46298,83.38871,50,0.00E+00,20,-0.21181,0.90845
290.13501,40.03583,-0.46665,83.36106,50,0.00E+00,20,-0.21334,0.90704
291.37201,40.16583,-0.47013,83.33321,50,0.00E+00,20,-0.21495,0.90566
292.63699,40.29583,-0.47346,83.30517,50,0.00E+00,20,-0.21626,0.90426
293.883,40.42583,-0.47689,83.27699,50,0.00E+00,20,-0.2182,0.90288
295.13699,40.55583,-0.48023,83.24838,50,0.00E+00,20,-0.22148,0.9015
296.384,40.68583,-0.48341,83.21944,50,0.00E+00,20,-0.22387,0.90012
297.64001,40.81583,-0.48755,83.19025,50,0.00E+00,20,-0.22521,0.89874
298.89899,40.94584,-0.49182,83.16086,50,0.00E+00,20,-0.22712,0.89736
300.16901,41.07583,-0.49612,83.13119,50,0.00E+00,20,-0.22931,0.89596
301.42401,41.20583,-0.5,83.10127,50,0.00E+00,20,-0.23124,0.89459
302.67801,41.33583,-0.50374,83.07105,50,0.00E+00,20,-0.23391,0.89322
303.94601,41.46583,-0.50733,83.04048,50,0.00E+00,20,-0.23615,0.89184
305.211,41.59583,-0.51031,83.00956,50,0.00E+00,20,-0.23907,0.89047
306.48801,41.72583,-0.51388,82.97834,50,0.00E+00,20,-0.24102,0.88908
307.74799,41.85583,-0.51666,82.94693,50,0.00E+00,20,-0.24289,0.88772
309.01901,41.98583,-0.5194,82.91526,50,0.00E+00,20,-0.245,0.88635
310.293,42.11583,-0.52255,82.88325,50,0.00E+00,20,-0.2473,0.88497
311.556,42.24583,-0.52638,82.85092,50,0.00E+00,20,-0.2498,0.88361
312.83301,42.37583,-0.52988,82.81827,50,0.00E+00,20,-0.25243,0.88224
314.108,42.50583,-0.53364,82.7853,50,0.00E+00,20,-0.25508,0.88088
315.388,42.63583,-0.53717,82.7519,50,0.00E+00,20,-0.2583,0.87951
316.65399,42.76583,-0.54038,82.71824,50,0.00E+00,20,-0.26048,0.87816
317.93201,42.89583,-0.54328,82.68419,50,0.00E+00,20,-0.26368,0.8768
319.216,43.02583,-0.54641,82.64969,50,0.00E+00,20,-0.26682,0.87543
320.479,43.15583,-0.54927,82.61471,50,0.00E+00,20,-0.27117,0.87409
321.76901,43.28583,-0.55205,82.57925,50,0.00E+00,20,-0.2742,0.87273
323.04199,43.41583,-0.55466,82.54349,50,0.00E+00,20,-0.27612,0.87139
324.31201,43.54583,-0.55757,82.50747,50,0.00E+00,20,-0.27738,0.87005
325.59399,43.67583,-0.56018,82.47123,50,0.00E+00,20,-0.28084,0.8687
326.883,43.80583,-0.5629,82.43457,50,0.00E+00,20,-0.28356,0.86735
328.14499,43.93583,-0.56535,82.39742,50,0.00E+00,20,-0.28731,0.86603
329.423,44.06583,-0.56802,82.3598,50,0.00E+00,20,-0.29097,0.8647
330.69699,44.19584,-0.57091,82.32182,50,0.00E+00,20,-0.29376,0.86337
331.95801,44.32583,-0.57421,82.2834,50,0.00E+00,20,-0.29688,0.86206
333.233,44.45583,-0.57704,82.24451,50,0.00E+00,20,-0.30114,0.86074
334.513,44.58583,-0.5805,82.20506,50,0.00E+00,20,-0.30577,0.85942
335.802,44.71583,-0.58405,82.16506,50,0.00E+00,20,-0.30957,0.85808
337.07901,44.84583,-0.58843,82.12448,50,0.00E+00,20,-0.31397,0.85677
338.35501,44.97583,-0.59286,82.08346,50,0.00E+00,20,-0.31687,0.85546
339.65201,45.10583,-0.59667,82.04211,50,0.00E+00,20,-0.31956,0.85413
340.94199,45.23583,-0.59964,82.00031,50,0.00E+00,20,-0.32352,0.85281
342.24701,45.36583,-0.60241,81.95798,50,0.00E+00,20,-0.32749,0.85148
343.51501,45.49583,-0.60464,81.91493,50,0.00E+00,20,-0.33374,0.85019
344.80801,45.62583,-0.60664,81.87126,50,0.00E+00,20,-0.33822,0.84887
346.103,45.75583,-0.60816,81.82699,50,0.00E+00,20,-0.34275,0.84756
347.38,45.88583,-0.60977,81.78215,50,0.00E+00,20,-0.34724,0.84627
348.655,46.01583,-0.61097,81.73675,50,0.00E+00,20,-0.35085,0.84499
349.94299,46.14583,-0.61238,81.69082,50,0.00E+00,20,-0.35524,0.84369
351.211,46.27583,-0.61516,81.64452,50,0.00E+00,20,-0.35798,0.84242
352.51401,46.40583,-0.61874,81.59764,50,0.00E+00,20,-0.36235,0.84111
353.802,46.53583,-0.62209,81.55033,50,0.00E+00,20,-0.36544,0.83983
355.099,46.66583,-0.6258,81.50272,50,0.00E+00,20,-0.36716,0.83853
356.40302,46.79583,-0.62785,81.45491,50,0.00E+00,20,-0.36812,0.83724
357.69199,46.92583,-0.63001,81.40683,50,0.00E+00,20,-0.37173,0.83596
358.98499,47.05583,-0.63089,81.35832,50,0.00E+00,20,-0.37525,0.83468
360.27701,47.18583,-0.63267,81.30938,50,0.00E+00,20,-0.37736,0.8334
361.56699,47.31583,-0.6333,81.26013,50,0.00E+00,20,-0.3793,0.83213
362.85101,47.44584,-0.63378,81.21071,50,0.00E+00,20,-0.38138,0.83087
364.12399,47.57583,-0.63468,81.16118,50,0.00E+00,20,-0.38162,0.82962
365.40601,47.70583,-0.63654,81.11148,50,0.00E+00,20,-0.38309,0.82837
366.673,47.83583,-0.63887,81.06162,50,0.00E+00,20,-0.38342,0.82713
367.957,47.96583,-0.64138,81.0117,50,0.00E+00,20,-0.38477,0.82589
369.23001,48.09583,-0.64319,80.96173,50,0.00E+00,20,-0.38425,0.82465
370.49301,48.22583,-0.64471,80.91176,50,0.00E+00,20,-0.38422,0.82343
371.77701,48.35583,-0.64826,80.86184,50,0.00E+00,20,-0.38352,0.82219
373.06,48.48583,-0.65399,80.81211,50,0.00E+00,20,-0.38231,0.82095
374.33401,48.61583,-0.66008,80.76248,50,0.00E+00,20,-0.38201,0.81973
375.633,48.74583,-0.66628,80.71292,50,0.00E+00,20,-0.38073,0.81848
376.909,48.87583,-0.67112,80.66347,50,0.00E+00,20,-0.37998,0.81726
378.19699,49.00583,-0.67523,80.61419,50,0.00E+00,20,-0.37842,0.81603
379.47699,49.13583,-0.67878,80.56522,50,0.00E+00,20,-0.37566,0.81482
380.741,49.26583,-0.68233,80.5165,50,0.00E+00,20,-0.37445,0.81362
382.022,49.39583,-0.68601,80.46794,50,0.00E+00,20,-0.37234,0.8124
383.29099,49.52583,-0.6917,80.41966,50,0.00E+00,20,-0.37023,0.81121
384.577,49.65583,-0.69753,80.37171,50,0.00E+00,20,-0.36729,0.80999
385.85999,49.78583,-0.7053,80.32417,50,0.00E+00,20,-0.36315,0.80879
387.16101,49.91583,-0.71247,80.27704,50,0.00E+00,20,-0.36115,0.80757
388.42999,50.04583,-0.71998,80.23024,50,0.00E+00,20,-0.35838,0.80638
389.73401,50.17583,-0.72629,80.18379,50,0.00E+00,20,-0.35631,0.80517
391.02301,50.30583,-0.73328,80.13772,50,0.00E+00,20,-0.3523,0.80397
392.32101,50.43583,-0.73983,80.09215,50,0.00E+00,20,-0.34948,0.80277
393.61801,50.56583,-0.74598,80.04681,50,0.00E+00,20,-0.34703,0.80157
394.897,50.69584,-0.75138,80.0018,50,0.00E+00,20,-0.34529,0.80039
396.186,50.82583,-0.7568,79.95699,50,0.00E+00,20,-0.34418,0.7992
397.478,50.95583,-0.76294,79.91234,50,0.00E+00,20,-0.34263,0.79801
398.77399,51.08583,-0.76857,79.86786,50,0.00E+00,20,-0.34109,0.79683
400.04401,51.21583,-0.7742,79.82358,50,0.00E+00,20,-0.3398,0.79567
401.35501,51.34583,-0.7804,79.77947,50,0.00E+00,20,-0.33824,0.79448
402.64301,51.47583,-0.78589,79.73561,50,0.00E+00,20,-0.33682,0.79331
403.94901,51.60583,-0.79211,79.69184,50,0.00E+00,20,-0.33561,0.79212
405.24701,51.73583,-0.79817,79.64819,50,0.00E+00,20,-0.33612,0.79095
406.565,51.86583,-0.80688,79.60442,50,0.00E+00,20,-0.33658,0.78976
407.88699,51.99583,-0.81529,79.56077,50,0.00E+00,20,-0.3352,0.78858
409.21301,52.12583,-0.82278,79.51715,50,0.00E+00,20,-0.33528,0.78739
410.54001,52.25583,-0.82813,79.47365,50,0.00E+00,20,-0.33384,0.7862
411.83801,52.38583,-0.83175,79.43017,50,0.00E+00,20,-0.33468,0.78505
413.155,52.51583,-0.83481,79.38676,50,0.00E+00,20,-0.33273,0.78388
414.47699,52.64583,-0.83724,79.34357,50,0.00E+00,20,-0.33235,0.7827
415.75699,52.77583,-0.83941,79.30036,50,0.00E+00,20,-0.33196,0.78157
417.04901,52.90583,-0.84209,79.25715,50,0.00E+00,20,-0.33184,0.78043
418.33401,53.03583,-0.84436,79.214,50,0.00E+00,20,-0.33225,0.77931
419.625,53.16583,-0.84687,79.17081,50,0.00E+00,20,-0.3324,0.77817
420.89301,53.29583,-0.84916,79.12759,50,0.00E+00,20,-0.33296,0.77707
422.18201,53.42583,-0.8529,79.08421,50,0.00E+00,20,-0.33473,0.77594
423.461,53.55583,-0.8583,79.04069,50,0.00E+00,20,-0.33494,0.77483
424.76199,53.68583,-0.86352,78.99721,50,0.00E+00,20,-0.33424,0.7737
426.04501,53.81583,-0.86916,78.95369,50,0.00E+00,20,-0.33516,0.77259
427.33701,53.94584,-0.87376,78.91,50,0.00E+00,20,-0.33796,0.77148
428.62601,54.07583,-0.87827,78.86594,50,0.00E+00,20,-0.3392,0.77037
429.922,54.20583,-0.88311,78.82179,50,0.00E+00,20,-0.34027,0.76926
431.22299,54.33583,-0.88721,78.77753,50,0.00E+00,20,-0.34085,0.76815
432.505,54.46583,-0.89108,78.73321,50,0.00E+00,20,-0.34115,0.76705
433.77899,54.59583,-0.89477,78.68885,50,0.00E+00,20,-0.34154,0.76597
435.06601,54.72583,-0.89826,78.64446,50,0.00E+00,20,-0.34186,0.76488
436.35501,54.85583,-0.90226,78.59993,50,0.00E+00,20,-0.34283,0.76379
437.634,54.98583,-0.90606,78.55537,50,0.00E+00,20,-0.34298,0.76271
438.931,55.11583,-0.91011,78.51071,50,0.00E+00,20,-0.3442,0.76162
440.22101,55.24583,-0.9141,78.46597,50,0.00E+00,20,-0.34393,0.76054
441.49301,55.37583,-0.91764,78.42126,50,0.00E+00,20,-0.34367,0.75948
442.78101,55.50583,-0.92118,78.37673,50,0.00E+00,20,-0.34207,0.7584
444.06201,55.63583,-0.92456,78.33221,50,0.00E+00,20,-0.34306,0.75734
445.35901,55.76583,-0.92825,78.28759,50,0.00E+00,20,-0.34365,0.75626
446.63101,55.89583,-0.93197,78.24282,50,0.00E+00,20,-0.34508,0.75521
447.914,56.02583,-0.93578,78.19807,50,0.00E+00,20,-0.34443,0.75415
449.189,56.15583,-0.93983,78.15325,50,0.00E+00,20,-0.34538,0.75311
450.48801,56.28583,-0.94385,78.10823,50,0.00E+00,20,-0.34676,0.75204
451.77399,56.41583,-0.94765,78.06304,50,0.00E+00,20,-0.34851,0.75099
453.06,56.54583,-0.95195,78.01771,50,0.00E+00,20,-0.3494,0.74994
454.32599,56.67583,-0.95369,77.97229,50,0.00E+00,20,-0.34908,0.74891
455.58301,56.80583,-0.95344,77.92688,50,0.00E+00,20,-0.3497,0.74789
456.84799,56.93583,-0.95434,77.88138,50,0.00E+00,20,-0.35084,0.74687
458.10501,57.06583,-0.95763,77.83575,50,0.00E+00,20,-0.35083,0.74586
459.38699,57.19584,-0.96364,77.79006,50,0.00E+00,20,-0.35229,0.74483
460.659,57.32583,-0.97027,77.74417,50,0.00E+00,20,-0.35408,0.74381
461.95401,57.45583,-0.97764,77.69813,50,0.00E+00,20,-0.35361,0.74278
463.25699,57.58583,-0.98484,77.65208,50,0.00E+00,20,-0.35449,0.74174
464.561,57.71583,-0.99064,77.60601,50,0.00E+00,20,-0.35501,0.7407
465.87299,57.84583,-0.99684,77.5598,50,0.00E+00,20,-0.35576,0.73967
467.16699,57.97583,-1.00131,77.51345,50,0.00E+00,20,-0.35717,0.73864
468.466,58.10583,-1.00604,77.467,50,0.00E+00,20,-0.35847,0.73762
469.76801,58.23583,-1.00993,77.42033,50,0.00E+00,20,-0.35943,0.7366
471.06699,58.36583,-1.01287,77.37358,50,0.00E+00,20,-0.35977,0.73558
472.379,58.49583,-1.01625,77.32675,50,0.00E+00,20,-0.36092,0.73456
473.685,58.62583,-1.01911,77.27983,50,0.00E+00,20,-0.36108,0.73354
474.97699,58.75583,-1.02165,77.23288,50,0.00E+00,20,-0.36165,0.73254
476.28201,58.88583,-1.02522,77.18581,50,0.00E+00,20,-0.36283,0.73153
477.58499,59.01583,-1.02918,77.1385,50,0.00E+00,20,-0.36467,0.73053
478.90201,59.14583,-1.03389,77.091,50,0.00E+00,20,-0.36602,0.72952
480.19601,59.27583,-1.03833,77.04335,50,0.00E+00,20,-0.36744,0.72853
481.505,59.40583,-1.04158,76.9955,50,0.00E+00,20,-0.36932,0.72753
482.80801,59.53583,-1.0446,76.94739,50,0.00E+00,20,-0.37214,0.72653
484.104,59.66583,-1.04752,76.89887,50,0.00E+00,20,-0.37416,0.72555
485.405,59.79583,-1.05039,76.8502,50,0.00E+00,20,-0.37534,0.72457
486.69699,59.92583,-1.05319,76.80147,50,0.00E+00,20,-0.3746,0.72359
488.01099,60.05583,-1.05775,76.75272,50,0.00E+00,20,-0.37466,0.7226
489.31299,60.18583,-1.06318,76.70398,50,0.00E+00,20,-0.37563,0.72163
490.62601,60.31583,-1.06908,76.65518,50,0.00E+00,20,-0.37605,0.72064
491.94601,60.44584,-1.07371,76.60621,50,0.00E+00,20,-0.37677,0.71966
493.24799,60.57583,-1.07736,76.55713,50,0.00E+00,20,-0.37796,0.71869
494.54401,60.70583,-1.07961,76.50813,50,0.00E+00,20,-0.37687,0.71773
495.849,60.83583,-1.08191,76.45912,50,0.00E+00,20,-0.37752,0.71677
497.138,60.96583,-1.08367,76.41003,50,0.00E+00,20,-0.37775,0.71582
498.431,61.09583,-1.08562,76.36078,50,0.00E+00,20,-0.38011,0.71487
499.71899,61.22583,-1.08833,76.31127,50,0.00E+00,20,-0.38143,0.71393
501.01001,61.35583,-1.09146,76.26163,50,0.00E+00,20,-0.38214,0.71299
502.302,61.48583,-1.09542,76.21192,50,0.00E+00,20,-0.38255,0.71205
503.591,61.61583,-1.09925,76.1621,50,0.00E+00,20,-0.38397,0.71111
504.86801,61.74583,-1.10349,76.11209,50,0.00E+00,20,-0.38429,0.71019
506.16501,61.87583,-1.10787,76.06204,50,0.00E+00,20,-0.38557,0.70925
507.457,62.00583,-1.11181,76.01189,50,0.00E+00,20,-0.38534,0.70833
508.76999,62.13583,-1.11563,75.96172,50,0.00E+00,20,-0.38608,0.70739
510.07001,62.26583,-1.1188,75.91151,50,0.00E+00,20,-0.38653,0.70646
511.35001,62.39583,-1.12259,75.86119,50,0.00E+00,20,-0.38746,0.70555
512.651,62.52583,-1.12601,75.81076,50,0.00E+00,20,-0.38801,0.70462
513.95001,62.65583,-1.12966,75.76017,50,0.00E+00,20,-0.38954,0.7037
515.24402,62.78583,-1.13361,75.70943,50,0.00E+00,20,-0.39191,0.70279
516.534,62.91583,-1.13683,75.65837,50,0.00E+00,20,-0.39305,0.70188
517.83301,63.04583,-1.14106,75.60735,50,0.00E+00,20,-0.39147,0.70097
519.14203,63.17583,-1.14521,75.55649,50,0.00E+00,20,-0.39085,0.70006
520.44501,63.30583,-1.14883,75.5058,50,0.00E+00,20,-0.38978,0.69915
521.72803,63.43583,-1.15183,75.45512,50,0.00E+00,20,-0.38986,0.69826
523.03497,63.56583,-1.15452,75.40438,50,0.00E+00,20,-0.39082,0.69736
524.328,63.69584,-1.15804,75.35355,50,0.00E+00,20,-0.39102,0.69646
525.63,63.82583,-1.16177,75.30271,50,0.00E+00,20,-0.39076,0.69557
526.92102,63.95583,-1.16439,75.25186,50,0.00E+00,20,-0.39195,0.69468
528.21802,64.08583,-1.16671,75.20096,50,0.00E+00,20,-0.3916,0.6938
529.49701,64.21584,-1.16895,75.15007,50,0.00E+00,20,-0.39091,0.69292
530.77899,64.34583,-1.17133,75.09913,50,0.00E+00,20,-0.39205,0.69205
532.06799,64.47583,-1.17402,75.04814,50,0.00E+00,20,-0.39147,0.69118
533.36401,64.60583,-1.17726,74.99728,50,0.00E+00,20,-0.39114,0.6903
534.64203,64.73583,-1.18049,74.9465,50,0.00E+00,20,-0.39046,0.68944
535.93799,64.86584,-1.18495,74.89582,50,0.00E+00,20,-0.38908,0.68858
537.23999,64.99583,-1.18933,74.84531,50,0.00E+00,20,-0.38753,0.6877
538.54401,65.12583,-1.19483,74.79503,50,0.00E+00,20,-0.38661,0.68683
539.83197,65.25584,-1.20022,74.74489,50,0.00E+00,20,-0.38444,0.68598
541.138,65.38583,-1.20543,74.69504,50,0.00E+00,20,-0.38288,0.68511
542.44702,65.51583,-1.20991,74.64545,50,0.00E+00,20,-0.38013,0.68425
543.73499,65.64584,-1.21233,74.59611,50,0.00E+00,20,-0.37941,0.6834
545.03802,65.77583,-1.21655,74.54695,50,0.00E+00,20,-0.3773,0.68255
546.32703,65.90583,-1.22235,74.49794,50,0.00E+00,20,-0.37645,0.6817
547.65601,66.03584,-1.22801,74.44914,50,0.00E+00,20,-0.37371,0.68084
548.95697,66.16583,-1.23196,74.40077,50,0.00E+00,20,-0.37088,0.67999
550.24799,66.29583,-1.23629,74.35283,50,0.00E+00,20,-0.367,0.67915
551.55103,66.42583,-1.23984,74.30532,50,0.00E+00,20,-0.3634,0.67831
552.862,66.55583,-1.24201,74.25833,50,0.00E+00,20,-0.36011,0.67747
554.13599,66.68584,-1.24492,74.21164,50,0.00E+00,20,-0.35877,0.67665
555.42999,66.81583,-1.2473,74.16523,50,0.00E+00,20,-0.35539,0.67582
556.72601,66.94583,-1.25148,74.11932,50,0.00E+00,20,-0.35122,0.675
558.02399,67.07584,-1.25702,74.07378,50,0.00E+00,20,-0.34953,0.67417
559.32898,67.20583,-1.26122,74.02862,50,0.00E+00,20,-0.3459,0.67334
560.62402,67.33583,-1.2657,73.98392,50,0.00E+00,20,-0.34144,0.67253
561.91302,67.46584,-1.27051,73.93971,50,0.00E+00,20,-0.33873,0.67171
563.22198,67.59583,-1.27581,73.89589,50,0.00E+00,20,-0.33514,0.67089
564.51001,67.72583,-1.28068,73.85263,50,0.00E+00,20,-0.3307,0.67009
565.81702,67.85583,-1.28572,73.81,50,0.00E+00,20,-0.32578,0.66927
567.11902,67.98583,-1.29121,73.76792,50,0.00E+00,20,-0.32169,0.66846
568.42297,68.11584,-1.29587,73.72634,50,0.00E+00,20,-0.31804,0.66765
569.71997,68.24583,-1.3006,73.68524,50,0.00E+00,20,-0.31403,0.66685
571.02899,68.37583,-1.30462,73.64468,50,0.00E+00,20,-0.31024,0.66605
572.349,68.50584,-1.31051,73.60486,50,0.00E+00,20,-0.30324,0.66524
573.66302,68.63583,-1.31815,73.56571,50,0.00E+00,20,-0.29923,0.66443
574.97601,68.76583,-1.32349,73.52701,50,0.00E+00,20,-0.29579,0.66363
576.27002,68.89584,-1.32647,73.48883,50,0.00E+00,20,-0.29176,0.66284
577.57202,69.02583,-1.32836,73.45118,50,0.00E+00,20,-0.2871,0.66206
578.83899,69.15583,-1.33103,73.4142,50,0.00E+00,20,-0.28194,0.66129
580.14203,69.28584,-1.33634,73.37784,50,0.00E+00,20,-0.27777,0.66051
581.45398,69.41583,-1.34248,73.34195,50,0.00E+00,20,-0.27377,0.65972
582.77197,69.54583,-1.34822,73.30663,50,0.00E+00,20,-0.26928,0.65893
584.07599,69.67583,-1.35229,73.27186,50,0.00E+00,20,-0.26604,0.65815
585.38599,69.80583,-1.35594,73.23752,50,0.00E+00,20,-0.26209,0.65737
586.67798,69.93584,-1.3577,73.20365,50,0.00E+00,20,-0.2587,0.65661
587.95697,70.06583,-1.35774,73.17026,50,0.00E+00,20,-0.25483,0.65585
589.22302,70.19583,-1.3584,73.13742,50,0.00E+00,20,-0.2503,0.65511
590.51801,70.32584,-1.36104,73.1051,50,0.00E+00,20,-0.24701,0.65435
591.836,70.45583,-1.36952,73.07321,50,0.00E+00,20,-0.24354,0.65358
593.17999,70.58583,-1.38296,73.04173,50,0.00E+00,20,-0.24038,0.65279
594.51202,70.71584,-1.39466,73.0107,50,0.00E+00,20,-0.23612,0.65202
595.85498,70.84583,-1.4035,72.98014,50,0.00E+00,20,-0.23365,0.65124
597.19299,70.97583,-1.408,72.95,50,0.00E+00,20,-0.23038,0.65047
598.505,71.10583,-1.40967,72.92014,50,0.00E+00,20,-0.2279,0.64971
599.81598,71.23583,-1.41105,72.89077,50,0.00E+00,20,-0.2247,0.64896
601.117,71.36584,-1.41299,72.86177,50,0.00E+00,20,-0.22139,0.64821
602.43298,71.49583,-1.41557,72.83308,50,0.00E+00,20,-0.2193,0.64746
603.72498,71.62583,-1.41707,72.80476,50,0.00E+00,20,-0.21648,0.64673
605.03802,71.75584,-1.41877,72.77685,50,0.00E+00,20,-0.21309,0.64599
606.33002,71.88583,-1.42091,72.74934,50,0.00E+00,20,-0.2102,0.64526
607.62201,72.01583,-1.42421,72.72219,50,0.00E+00,20,-0.20721,0.64453
608.92102,72.14584,-1.42731,72.69526,50,0.00E+00,20,-0.20691,0.6438
610.21997,72.27583,-1.43059,72.66847,50,0.00E+00,20,-0.20533,0.64307
611.51398,72.40583,-1.43357,72.64196,50,0.00E+00,20,-0.20267,0.64235
612.79303,72.53584,-1.43494,72.61577,50,0.00E+00,20,-0.20006,0.64164
614.07202,72.66583,-1.43533,72.58988,50,0.00E+00,20,-0.19867,0.64093
615.36798,72.79583,-1.43755,72.56402,50,0.00E+00,20,-0.1989,0.64022
616.65302,72.92583,-1.44042,72.53835,50,0.00E+00,20,-0.19681,0.63951
617.94397,73.05583,-1.44413,72.51289,50,0.00E+00,20,-0.19469,0.6388
619.23297,73.18584,-1.44915,72.48772,50,0.00E+00,20,-0.193,0.63809
620.51001,73.31583,-1.45281,72.46274,50,0.00E+00,20,-0.19107,0.6374
621.80701,73.44583,-1.45603,72.43795,50,0.00E+00,20,-0.19063,0.63669
623.091,73.57584,-1.45964,72.41337,50,0.00E+00,20,-0.18729,0.63599
624.375,73.70583,-1.46328,72.3891,50,0.00E+00,20,-0.18614,0.6353
625.66803,73.83583,-1.46654,72.36511,50,0.00E+00,20,-0.18436,0.6346
626.96301,73.96584,-1.47108,72.34127,50,0.00E+00,20,-0.18241,0.63391
628.271,74.09583,-1.47631,72.31762,50,0.00E+00,20,-0.18082,0.63321
629.59698,74.22583,-1.48546,72.29415,50,0.00E+00,20,-0.18027,0.6325
630.94897,74.35583,-1.49673,72.27075,50,0.00E+00,20,-0.17974,0.63178
632.28101,74.48583,-1.50342,72.24748,50,0.00E+00,20,-0.17834,0.63107
633.60199,74.61584,-1.50663,72.22434,50,0.00E+00,20,-0.17782,0.63038
634.90601,74.74583,-1.50639,72.20123,50,0.00E+00,20,-0.17762,0.62969
636.20801,74.87583,-1.50433,72.17812,50,0.00E+00,20,-0.17708,0.629
637.49298,75.00584,-1.5005,72.15507,50,0.00E+00,20,-0.17781,0.62833
638.77399,75.13583,-1.49777,72.13194,50,0.00E+00,20,-0.17822,0.62766
640.05499,75.26583,-1.49751,72.10867,50,0.00E+00,20,-0.17982,0.62699
641.328,75.39584,-1.49693,72.0852,50,0.00E+00,20,-0.18144,0.62633
642.61798,75.52583,-1.49771,72.06161,50,0.00E+00,20,-0.18205,0.62567
643.89001,75.65583,-1.50003,72.03782,50,0.00E+00,20,-0.1834,0.62501
645.17499,75.78584,-1.50132,72.01398,50,0.00E+00,20,-0.18434,0.62435
646.45898,75.91583,-1.50413,71.98988,50,0.00E+00,20,-0.18582,0.62369
647.76202,76.04583,-1.5069,71.96552,50,0.00E+00,20,-0.18867,0.62302
649.08002,76.17583,-1.51137,71.94083,50,0.00E+00,20,-0.19141,0.62235
650.38898,76.30583,-1.51482,71.91588,50,0.00E+00,20,-0.19342,0.62169
651.69299,76.43584,-1.51744,71.89063,50,0.00E+00,20,-0.19543,0.62103
652.995,76.56583,-1.51826,71.86491,50,0.00E+00,20,-0.19951,0.62037
654.28497,76.69583,-1.51722,71.8387,50,0.00E+00,20,-0.2036,0.61972
655.57001,76.82584,-1.51572,71.81194,50,0.00E+00,20,-0.20767,0.61907
656.85999,76.95583,-1.51456,71.78475,50,0.00E+00,20,-0.21054,0.61843
658.16998,77.08583,-1.51428,71.75724,50,0.00E+00,20,-0.21241,0.61778
659.47699,77.21584,-1.51614,71.72941,50,0.00E+00,20,-0.21623,0.61713
660.79602,77.34583,-1.51945,71.70116,50,0.00E+00,20,-0.21776,0.61647
662.159,77.47583,-1.53036,71.67259,50,0.00E+00,20,-0.22019,0.6158
663.52802,77.60583,-1.53821,71.64388,50,0.00E+00,20,-0.22211,0.61512
664.86603,77.73583,-1.54027,71.61501,50,0.00E+00,20,-0.22317,0.61447
666.19897,77.86584,-1.53785,71.58589,50,0.00E+00,20,-0.22414,0.61381
667.50403,77.99583,-1.53281,71.55666,50,0.00E+00,20,-0.2256,0.61318
668.81897,78.12583,-1.52712,71.52726,50,0.00E+00,20,-0.22639,0.61253
670.12299,78.25584,-1.52357,71.49779,50,0.00E+00,20,-0.22704,0.6119
671.422,78.38583,-1.52053,71.46832,50,0.00E+00,20,-0.22662,0.61127
672.72101,78.51583,-1.51931,71.4389,50,0.00E+00,20,-0.22606,0.61065
674.02002,78.64584,-1.51843,71.40951,50,0.00E+00,20,-0.22575,0.61002
675.32397,78.77583,-1.51896,71.38026,50,0.00E+00,20,-0.22463,0.6094
676.62299,78.90583,-1.52158,71.35121,50,0.00E+00,20,-0.22233,0.60877
677.93402,79.03584,-1.52586,71.32247,50,0.00E+00,20,-0.21986,0.60815
679.25598,79.16583,-1.53203,71.29395,50,0.00E+00,20,-0.21812,0.60752
680.58899,79.29583,-1.53696,71.2657,50,0.00E+00,20,-0.21605,0.60689
681.89502,79.42583,-1.53925,71.23765,50,0.00E+00,20,-0.21456,0.60627
683.18298,79.55583,-1.53876,71.21002,50,0.00E+00,20,-0.21088,0.60566
684.47198,79.68584,-1.53496,71.18288,50,0.00E+00,20,-0.20611,0.60506
685.73102,79.81583,-1.53203,71.15638,50,0.00E+00,20,-0.20174,0.60447
687.00201,79.94583,-1.52865,71.13038,50,0.00E+00,20,-0.19742,0.60387
688.26001,80.07584,-1.52547,71.10496,50,0.00E+00,20,-0.19365,0.60329
689.53198,80.20583,-1.52503,71.08011,50,0.00E+00,20,-0.18869,0.6027
690.79602,80.33583,-1.52602,71.05594,50,0.00E+00,20,-0.18311,0.60211
692.09003,80.46584,-1.52931,71.03248,50,0.00E+00,20,-0.17699,0.60151
693.37598,80.59583,-1.53341,71.0098,50,0.00E+00,20,-0.17167,0.60092
694.65302,80.72583,-1.53794,70.98776,50,0.00E+00,20,-0.167,0.60033
695.94299,80.85583,-1.54135,70.9663,50,0.00E+00,20,-0.16327,0.59974
697.23499,80.98583,-1.54438,70.94539,50,0.00E+00,20,-0.15847,0.59915
698.53003,81.11584,-1.54602,70.92504,50,0.00E+00,20,-0.15346,0.59856
699.82098,81.24583,-1.54754,70.9052,50,0.00E+00,20,-0.15058,0.59797
701.11603,81.37583,-1.54953,70.88577,50,0.00E+00,20,-0.14767,0.59739
702.414,81.50584,-1.553,70.86681,50,0.00E+00,20,-0.1436,0.5968
703.70898,81.63583,-1.55589,70.8484,50,0.00E+00,20,-0.13964,0.59622
705.00403,81.76583,-1.55788,70.83049,50,0.00E+00,20,-0.13628,0.59563
706.315,81.89584,-1.56063,70.81306,50,0.00E+00,20,-0.13193,0.59505
707.66803,82.02583,-1.56914,70.79608,50,0.00E+00,20,-0.12931,0.59444
709.03601,82.15583,-1.58031,70.77946,50,0.00E+00,20,-0.12621,0.59383
710.383,82.28584,-1.58669,70.76322,50,0.00E+00,20,-0.12302,0.59323
711.70801,82.41583,-1.58799,70.74737,50,0.00E+00,20,-0.12069,0.59265
713.026,82.54583,-1.58574,70.73182,50,0.00E+00,20,-0.11843,0.59206
714.32599,82.67583,-1.58193,70.71651,50,0.00E+00,20,-0.11655,0.59149
715.64301,82.80583,-1.57919,70.70162,50,0.00E+00,20,-0.11268,0.59091
716.927,82.93584,-1.57719,70.68714,50,0.00E+00,20,-0.11011,0.59035
718.23999,83.06583,-1.57576,70.67294,50,0.00E+00,20,-0.10803,0.58977
719.54102,83.19583,-1.57641,70.65898,50,0.00E+00,20,-0.10635,0.58921
720.836,83.32584,-1.57733,70.64526,50,0.00E+00,20,-0.10534,0.58864
722.14697,83.45583,-1.57933,70.63163,50,0.00E+00,20,-0.10414,0.58807
723.44598,83.58583,-1.58136,70.6182,50,0.00E+00,20,-0.10324,0.58751
724.737,83.71584,-1.58282,70.60489,50,0.00E+00,20,-0.10069,0.58695
726.04401,83.84583,-1.58335,70.592,50,0.00E+00,20,-9.69E-02,0.58639
727.341,83.97583,-1.58366,70.57954,50,0.00E+00,20,-9.50E-02,0.58583
728.63202,84.10583,-1.58472,70.56734,50,0.00E+00,20,-9.27E-02,0.58528
729.92102,84.23583,-1.5853,70.55533,50,0.00E+00,20,-9.12E-02,0.58473
731.237,84.36584,-1.58897,70.54349,50,0.00E+00,20,-9.01E-02,0.58417
732.56702,84.49583,-1.59485,70.53185,50,0.00E+00,20,-8.87E-02,0.5836
733.88898,84.62583,-1.59854,70.52047,50,0.00E+00,20,-8.71E-02,0.58304
735.185,84.75584,-1.60048,70.5094,50,0.00E+00,20,-8.41E-02,0.5825
736.508,84.88583,-1.59914,70.49859,50,0.00E+00,20,-8.23E-02,0.58194
737.78998,85.01583,-1.59826,70.48806,50,0.00E+00,20,-7.99E-02,0.5814
739.08502,85.14584,-1.59724,70.47773,50,0.00E+00,20,-7.95E-02,0.58085
740.36603,85.27583,-1.59583,70.46747,50,0.00E+00,20,-7.84E-02,0.58032
741.651,85.40583,-1.59666,70.45738,50,0.00E+00,20,-7.65E-02,0.57978
742.93597,85.53584,-1.59601,70.44749,50,0.00E+00,20,-7.62E-02,0.57925
744.185,85.66583,-1.59142,70.43772,50,0.00E+00,20,-7.44E-02,0.57873
745.453,85.79583,-1.58864,70.42817,50,0.00E+00,20,-7.22E-02,0.5782
746.737,85.92583,-1.59083,70.41895,50,0.00E+00,20,-7.04E-02,0.57767
748.02197,86.05583,-1.59531,70.40986,50,0.00E+00,20,-6.94E-02,0.57714
749.32898,86.18584,-1.60079,70.40101,50,0.00E+00,20,-6.75E-02,0.5766
750.64899,86.31583,-1.60767,70.39238,50,0.00E+00,20,-6.59E-02,0.57606
751.979,86.44583,-1.61534,70.38378,50,0.00E+00,20,-6.62E-02,0.57551
753.30103,86.57584,-1.62013,70.37525,50,0.00E+00,20,-6.42E-02,0.57497
754.64099,86.70583,-1.62407,70.36703,50,0.00E+00,20,-6.32E-02,0.57442
755.98798,86.83583,-1.6323,70.35887,50,0.00E+00,20,-6.25E-02,0.57388
757.33099,86.96584,-1.63836,70.3508,50,0.00E+00,20,-6.14E-02,0.57333
758.65698,87.09583,-1.64075,70.34294,50,0.00E+00,20,-5.91E-02,0.57279
759.97699,87.22583,-1.64041,70.33539,50,0.00E+00,20,-5.75E-02,0.57226
761.297,87.35583,-1.63856,70.32805,50,0.00E+00,20,-5.60E-02,0.57173
762.59698,87.48583,-1.63615,70.32074,50,0.00E+00,20,-5.66E-02,0.5712
763.88397,87.61584,-1.63193,70.31336,50,0.00E+00,20,-5.61E-02,0.57069
765.17297,87.74583,-1.62839,70.30606,50,0.00E+00,20,-5.53E-02,0.57017
766.48297,87.87583,-1.62719,70.29888,50,0.00E+00,20,-5.50E-02,0.56965
767.76202,88.00584,-1.62624,70.29177,50,0.00E+00,20,-5.41E-02,0.56914
769.04901,88.13583,-1.6259,70.2848,50,0.00E+00,20,-5.26E-02,0.56863
770.35199,88.26583,-1.6271,70.27786,50,0.00E+00,20,-5.28E-02,0.56811
771.63702,88.39584,-1.62864,70.27094,50,0.00E+00,20,-5.41E-02,0.5676
772.94,88.52583,-1.62987,70.26389,50,0.00E+00,20,-5.41E-02,0.56708
774.237,88.65583,-1.63249,70.25684,50,0.00E+00,20,-5.48E-02,0.56657
775.526,88.78584,-1.63408,70.24979,50,0.00E+00,20,-5.40E-02,0.56606
776.83502,88.91583,-1.63622,70.24283,50,0.00E+00,20,-5.37E-02,0.56555
778.13898,89.04583,-1.63787,70.23588,50,0.00E+00,20,-5.37E-02,0.56504
779.42999,89.17583,-1.63913,70.22889,50,0.00E+00,20,-5.33E-02,0.56453
780.742,89.30583,-1.63955,70.22197,50,0.00E+00,20,-5.38E-02,0.56402
782.03998,89.43584,-1.64135,70.21507,50,0.00E+00,20,-5.25E-02,0.56352
783.34003,89.56583,-1.64315,70.20812,50,0.00E+00,20,-5.48E-02,0.56301
784.64398,89.69583,-1.64426,70.20107,50,0.00E+00,20,-5.41E-02,0.5625
785.95099,89.82584,-1.64508,70.19409,50,0.00E+00,20,-5.34E-02,0.562
787.23901,89.95583,-1.64538,70.18712,50,0.00E+00,20,-5.34E-02,0.5615
788.54199,90.08583,-1.64661,70.18017,50,0.00E+00,20,-5.34E-02,0.561
789.85797,90.21584,-1.64859,70.17325,50,0.00E+00,20,-5.38E-02,0.56049
791.16498,90.34583,-1.65115,70.16613,50,0.00E+00,20,-5.44E-02,0.55999
792.48102,90.47583,-1.65281,70.15908,50,0.00E+00,20,-5.50E-02,0.55948
793.78497,90.60583,-1.65324,70.1521,50,0.00E+00,20,-5.28E-02,0.55898
795.08899,90.73583,-1.6536,70.14511,50,0.00E+00,20,-5.41E-02,0.55848
796.39301,90.86584,-1.65436,70.13811,50,0.00E+00,20,-5.31E-02,0.55799
797.69702,90.99583,-1.65525,70.13109,50,0.00E+00,20,-5.42E-02,0.55749
798.99103,91.12583,-1.65504,70.12407,50,0.00E+00,20,-5.42E-02,0.557
800.30798,91.25584,-1.65783,70.11699,50,0.00E+00,20,-5.37E-02,0.5565
801.60999,91.38583,-1.65913,70.11008,50,0.00E+00,20,-5.34E-02,0.556
802.89502,91.51583,-1.65493,70.10314,50,0.00E+00,20,-5.34E-02,0.55552
804.177,91.64584,-1.64912,70.09618,50,0.00E+00,20,-5.34E-02,0.55503
805.47101,91.77583,-1.65007,70.08925,50,0.00E+00,20,-5.31E-02,0.55455
806.80798,91.90583,-1.65706,70.08231,50,0.00E+00,20,-5.30E-02,0.55404
808.12903,92.03584,-1.66389,70.07533,50,0.00E+00,20,-5.34E-02,0.55355
809.45001,92.16583,-1.66748,70.06845,50,0.00E+00,20,-5.29E-02,0.55305
810.76001,92.29583,-1.66782,70.06153,50,0.00E+00,20,-5.25E-02,0.55256
812.06799,92.42583,-1.66614,70.05469,50,0.00E+00,20,-5.26E-02,0.55207
813.38702,92.55583,-1.66497,70.0478,50,0.00E+00,20,-5.39E-02,0.55158
814.71399,92.68584,-1.67093,70.04088,50,0.00E+00,20,-5.40E-02,0.55109
816.008,92.81583,-1.66779,70.03392,50,0.00E+00,20,-5.38E-02,0.55061
817.284,92.94583,-1.6617,70.02698,50,0.00E+00,20,-5.32E-02,0.55013
818.56403,93.07584,-1.65788,70.02003,50,0.00E+00,20,-5.41E-02,0.54966
819.86401,93.20583,-1.65658,70.01305,50,0.00E+00,20,-5.40E-02,0.54918
821.16199,93.33583,-1.65481,70.0061,50,0.00E+00,20,-5.37E-02,0.5487
822.427,93.46584,-1.65329,69.99898,50,0.00E+00,20,-5.58E-02,0.54823
823.71198,93.59583,-1.65238,69.9917,50,0.00E+00,20,-5.59E-02,0.54776
825.00403,93.72583,-1.65199,69.98446,50,0.00E+00,20,-5.55E-02,0.54728
826.29401,93.85583,-1.65266,69.97721,50,0.00E+00,20,-5.61E-02,0.54681
827.599,93.98583,-1.65334,69.9699,50,0.00E+00,20,-5.67E-02,0.54633
828.94202,94.11584,-1.6619,69.96263,50,0.00E+00,20,-5.47E-02,0.54584
830.27698,94.24583,-1.67158,69.95553,50,0.00E+00,20,-5.59E-02,0.54535
831.60999,94.37583,-1.67495,69.94827,50,0.00E+00,20,-5.61E-02,0.54486
832.93799,94.50584,-1.67494,69.94078,50,0.00E+00,20,-5.92E-02,0.54438
834.27502,94.63583,-1.67649,69.9331,50,0.00E+00,20,-5.94E-02,0.54389
835.60797,94.76583,-1.67824,69.92532,50,0.00E+00,20,-6.00E-02,0.54341
836.92603,94.89584,-1.67745,69.9175,50,0.00E+00,20,-6.05E-02,0.54293
838.237,95.02583,-1.67274,69.90944,50,0.00E+00,20,-6.23E-02,0.54245
839.53699,95.15583,-1.66746,69.90121,50,0.00E+00,20,-6.34E-02,0.54198
840.841,95.28584,-1.66264,69.89289,50,0.00E+00,20,-6.50E-02,0.54151
842.14001,95.41583,-1.65746,69.88438,50,0.00E+00,20,-6.67E-02,0.54104
843.42499,95.54583,-1.65337,69.87574,50,0.00E+00,20,-6.61E-02,0.54058
844.69598,95.67583,-1.65034,69.86703,50,0.00E+00,20,-6.76E-02,0.54012
845.97699,95.80583,-1.64726,69.85816,50,0.00E+00,20,-6.85E-02,0.53966
847.24902,95.93584,-1.64154,69.84924,50,0.00E+00,20,-6.92E-02,0.5392
848.52502,96.06583,-1.63923,69.84038,50,0.00E+00,20,-6.92E-02,0.53875
849.82397,96.19583,-1.63866,69.83131,50,0.00E+00,20,-6.89E-02,0.53828
851.112,96.32584,-1.63911,69.8222,50,0.00E+00,20,-7.05E-02,0.53782
852.39801,96.45583,-1.63995,69.81297,50,0.00E+00,20,-7.09E-02,0.53736
853.69397,96.58583,-1.64028,69.80361,50,0.00E+00,20,-7.36E-02,0.5369
854.99902,96.71584,-1.64023,69.79411,50,0.00E+00,20,-7.19E-02,0.53643
856.27002,96.84583,-1.63967,69.78459,50,0.00E+00,20,-7.32E-02,0.53598
857.578,96.97583,-1.6401,69.77501,50,0.00E+00,20,-7.48E-02,0.53551
858.88397,97.10583,-1.64056,69.76534,50,0.00E+00,20,-7.43E-02,0.53505
860.18799,97.23583,-1.63994,69.75568,50,0.00E+00,20,-7.37E-02,0.53458
861.48499,97.36584,-1.63909,69.74596,50,0.00E+00,20,-7.58E-02,0.53412
862.79498,97.49583,-1.63912,69.73604,50,0.00E+00,20,-7.74E-02,0.53366
864.12402,97.62583,-1.64319,69.72594,50,0.00E+00,20,-7.78E-02,0.53319
865.45203,97.75584,-1.64752,69.7156,50,0.00E+00,20,-8.04E-02,0.53272
866.76898,97.88583,-1.64774,69.705,50,0.00E+00,20,-8.09E-02,0.53225
868.07397,98.01583,-1.64475,69.69435,50,0.00E+00,20,-8.21E-02,0.53179
869.38098,98.14584,-1.64154,69.68361,50,0.00E+00,20,-8.28E-02,0.53133
870.68201,98.27583,-1.63888,69.67275,50,0.00E+00,20,-8.40E-02,0.53087
871.98999,98.40583,-1.63838,69.66187,50,0.00E+00,20,-8.42E-02,0.53041
873.29303,98.53584,-1.6344,69.65093,50,0.00E+00,20,-8.37E-02,0.52995
874.59198,98.66583,-1.63185,69.63995,50,0.00E+00,20,-8.58E-02,0.52949
875.89801,98.79583,-1.62988,69.62893,50,0.00E+00,20,-8.55E-02,0.52903
877.19598,98.92583,-1.62896,69.61775,50,0.00E+00,20,-8.54E-02,0.52858
878.49103,99.05583,-1.62666,69.60649,50,0.00E+00,20,-8.70E-02,0.52812
879.78101,99.18584,-1.62563,69.59514,50,0.00E+00,20,-8.84E-02,0.52767
881.07703,99.31583,-1.62253,69.58361,50,0.00E+00,20,-8.93E-02,0.52722
882.362,99.44583,-1.62096,69.57188,50,0.00E+00,20,-9.06E-02,0.52677
883.672,99.57584,-1.62206,69.56,50,0.00E+00,20,-9.17E-02,0.52631
884.99799,99.70583,-1.62499,69.54787,50,0.00E+00,20,-9.39E-02,0.52584
886.284,99.83583,-1.62412,69.5356,50,0.00E+00,20,-9.51E-02,0.52539
887.60699,99.96584,-1.62622,69.52313,50,0.00E+00,20,-9.53E-02,0.52493
888.94202,100.09583,-1.62921,69.51063,50,0.00E+00,20,-9.72E-02,0.52447
890.25897,100.22583,-1.62869,69.49796,50,0.00E+00,20,-9.80E-02,0.52401
891.56702,100.35583,-1.62673,69.48514,50,0.00E+00,20,-0.101,0.52355
892.87402,100.48583,-1.62325,69.47189,50,0.00E+00,20,-0.10245,0.5231
894.16998,100.61584,-1.61971,69.45842,50,0.00E+00,20,-0.10412,0.52265
895.474,100.74583,-1.61907,69.44478,50,0.00E+00,20,-0.10506,0.52219
896.81598,100.87583,-1.62154,69.43103,50,0.00E+00,20,-0.10817,0.52173
898.12701,101.00584,-1.62533,69.41694,50,0.00E+00,20,-0.10923,0.52127
899.45599,101.13583,-1.62619,69.40263,50,0.00E+00,20,-0.11115,0.52081
900.79199,101.26583,-1.62428,69.38808,50,0.00E+00,20,-0.11288,0.52035
902.08197,101.39584,-1.61991,69.37334,50,0.00E+00,20,-0.11344,0.5199
903.37903,101.52583,-1.61585,69.35845,50,0.00E+00,20,-0.11579,0.51945
904.67297,101.65583,-1.61075,69.34339,50,0.00E+00,20,-0.1168,0.519
905.95801,101.78584,-1.60666,69.32815,50,0.00E+00,20,-0.11804,0.51855
907.25403,101.91583,-1.60315,69.31267,50,0.00E+00,20,-0.11975,0.51811
908.57898,102.04583,-1.60705,69.29699,50,0.00E+00,20,-0.12175,0.51765
909.86902,102.17583,-1.60771,69.28115,50,0.00E+00,20,-0.12304,0.5172
911.17603,102.30583,-1.60745,69.26517,50,0.00E+00,20,-0.12256,0.51675
912.48102,102.43584,-1.60467,69.24905,50,0.00E+00,20,-0.12452,0.5163
913.77301,102.56583,-1.60141,69.23276,50,0.00E+00,20,-0.12674,0.51585
915.06799,102.69583,-1.59969,69.21623,50,0.00E+00,20,-0.12709,0.5154
916.35999,102.82584,-1.59818,69.1995,50,0.00E+00,20,-0.1293,0.51496
917.68103,102.95583,-1.59594,69.18261,50,0.00E+00,20,-0.13028,0.5145
918.95697,103.08583,-1.59355,69.1656,50,0.00E+00,20,-0.13208,0.51406
920.258,103.21584,-1.59245,69.14836,50,0.00E+00,20,-0.13345,0.51361
921.55298,103.34583,-1.59275,69.13085,50,0.00E+00,20,-0.13567,0.51317
922.83398,103.47583,-1.58913,69.11326,50,0.00E+00,20,-0.1355,0.51272
924.11902,103.60583,-1.58451,69.09564,50,0.00E+00,20,-0.13653,0.51228
925.40503,103.73583,-1.5837,69.07795,50,0.00E+00,20,-0.13561,0.51184
926.71698,103.86584,-1.58397,69.06019,50,0.00E+00,20,-0.13634,0.51139
928.01599,103.99583,-1.58413,69.04235,50,0.00E+00,20,-0.13728,0.51094
929.31598,104.12583,-1.5867,69.0244,50,0.00E+00,20,-0.13897,0.51049
930.64001,104.25584,-1.58962,69.00632,50,0.00E+00,20,-0.13987,0.51003
931.95898,104.38583,-1.58999,68.98804,50,0.00E+00,20,-0.14098,0.50958
933.271,104.51583,-1.58871,68.96959,50,0.00E+00,20,-0.14244,0.50913
934.57599,104.64584,-1.58732,68.95116,50,0.00E+00,20,-0.14064,0.50868
935.86401,104.77583,-1.58354,68.93284,50,0.00E+00,20,-0.14097,0.50824
937.18903,104.90583,-1.5829,68.91455,50,0.00E+00,20,-0.14105,0.50778
938.521,105.03584,-1.58744,68.89623,50,0.00E+00,20,-0.1412,0.50732
939.84399,105.16583,-1.59048,68.87774,50,0.00E+00,20,-0.14275,0.50687
941.16498,105.29583,-1.59149,68.85917,50,0.00E+00,20,-0.14259,0.50641
942.48499,105.42583,-1.59209,68.84077,50,0.00E+00,20,-0.14057,0.50596
943.79498,105.55583,-1.59085,68.82255,50,0.00E+00,20,-0.13956,0.50551
945.09497,105.68584,-1.58723,68.80447,50,0.00E+00,20,-0.1393,0.50506
946.38898,105.81583,-1.58135,68.78653,50,0.00E+00,20,-0.13645,0.50461
947.67401,105.94583,-1.57467,68.76872,50,0.00E+00,20,-0.13622,0.50417
948.96997,106.07584,-1.57214,68.75113,50,0.00E+00,20,-0.13534,0.50372
950.26599,106.20583,-1.57307,68.73373,50,0.00E+00,20,-0.13232,0.50328
951.53198,106.33583,-1.56661,68.71664,50,0.00E+00,20,-0.13026,0.50284
952.81,106.46584,-1.56303,68.69988,50,0.00E+00,20,-0.12723,0.5024
954.10303,106.59583,-1.56678,68.68369,50,0.00E+00,20,-0.12262,0.50196
955.40503,106.72583,-1.56962,68.66791,50,0.00E+00,20,-0.11888,0.50151
956.70203,106.85583,-1.5732,68.65265,50,0.00E+00,20,-0.11526,0.50106
958.02197,106.98583,-1.58021,68.63792,50,0.00E+00,20,-0.11113,0.50061
959.35901,107.11584,-1.58599,68.62356,50,0.00E+00,20,-0.10871,0.50015
960.664,107.24583,-1.58937,68.60953,50,0.00E+00,20,-0.10686,0.4997
961.98102,107.37583,-1.59375,68.59583,50,0.00E+00,20,-0.10397,0.49924
963.29797,107.50584,-1.59725,68.58254,50,0.00E+00,20,-0.10015,0.49879
964.617,107.63583,-1.59871,68.56969,50,0.00E+00,20,-9.66E-02,0.49833
965.92499,107.76583,-1.59768,68.5576,50,0.00E+00,20,-9.05E-02,0.49788
967.229,107.89584,-1.5974,68.54605,50,0.00E+00,20,-8.63E-02,0.49743
968.52698,108.02583,-1.59594,68.53518,50,0.00E+00,20,-8.18E-02,0.49698
969.85303,108.15583,-1.59989,68.52495,50,0.00E+00,20,-7.57E-02,0.49653
971.18799,108.28584,-1.60625,68.51521,50,0.00E+00,20,-7.40E-02,0.49607
972.51398,108.41583,-1.61149,68.50597,50,0.00E+00,20,-6.92E-02,0.49561
973.83099,108.54583,-1.61373,68.49728,50,0.00E+00,20,-6.41E-02,0.49515
975.15302,108.67583,-1.61305,68.48921,50,0.00E+00,20,-6.07E-02,0.4947
976.45398,108.80583,-1.60977,68.4816,50,0.00E+00,20,-5.60E-02,0.49425
977.763,108.93584,-1.60616,68.47458,50,0.00E+00,20,-5.18E-02,0.49379
979.06299,109.06583,-1.60319,68.46801,50,0.00E+00,20,-4.95E-02,0.49334
980.36102,109.19583,-1.60059,68.46175,50,0.00E+00,20,-5.57E-02,0.49289
981.63898,109.32584,-1.59919,68.4545,50,0.00E+00,20,-5.48E-02,0.49245
982.922,109.45583,-1.59785,68.44786,50,0.00E+00,20,-4.75E-02,0.49201
984.216,109.58583,-1.59524,68.44218,50,0.00E+00,20,-4.02E-02,0.49156
985.505,109.71584,-1.5938,68.43712,50,0.00E+00,20,-4.01E-02,0.49111
986.79797,109.84583,-1.59227,68.43224,50,0.00E+00,20,-3.72E-02,0.49066
988.08899,109.97583,-1.58998,68.42775,50,0.00E+00,20,-3.20E-02,0.49022
989.35699,110.10583,-1.58746,68.42413,50,0.00E+00,20,-2.58E-02,0.48978
990.66302,110.23583,-1.58855,68.42127,50,0.00E+00,20,-2.09E-02,0.48932
991.93298,110.36584,-1.58704,68.4181,50,0.00E+00,20,-2.28E-02,0.48888
993.237,110.49583,-1.58689,68.4152,50,0.00E+00,20,-2.71E-02,0.48843
994.52802,110.62583,-1.58701,68.41212,50,0.00E+00,20,-2.53E-02,0.48798
995.83099,110.75584,-1.5882,68.40839,50,0.00E+00,20,-2.06E-02,0.48753
997.11102,110.88583,-1.58908,68.40652,50,0.00E+00,20,-1.64E-02,0.48708
998.31,111.00584,-1.58959,68.40244,50,0.00E+00,20,1.19E-02,0.48666