File: book/some_content/TG_ExpDat_CEM_I_DC7; 23-1-2025-2.csv
#FILE:                       ,CEM_I_DC7; 23-1-2025.ngb-ds3
#FORMAT:                     ,NETZSCH5
#IDENTITY:                   ,GEOPOLYMER PASTE
#DECIMAL:                    ,POINT
#SEPARATOR:                  ,COMMA
#MTYPE:                      ,DSC
#INSTRUMENT:                 ,Microlab TU Delft
#PROJECT:                    ,
#DATE/TIME:                  ,24/01/2025 1:49:47 PM
#CORR. FILE:                 ,Blank with cover; 13-1-2025.ngb-bs3
#LABORATORY:                 ,TU Delft Micro Lab
#OPERATOR:                   ,Ahmed
#REMARK:                     ,under Argon atmosphere, 10K/min
#SAMPLE:                     ,OPC9%DC7
#SAMPLE MASS /mg:            ,34.4
#MATERIAL:                   ,Geopolymer paste
#REFERENCE:                  ,blank
#REFERENCE MASS /mg:         ,0
#TYPE OF CRUCIBLE:           ,DSC/TG pan Al2O3
#SAMPLE CRUCIBLE MASS /mg:   ,0
#REFERENCE CRUCIBLE MASS /mg:,0
#CORR. CODE:                 ,020
#EXO:                        ,-1
#RANGE:                      ,40/10.0(K/min)/1000
#SEGMENT:                    ,S2/2

##Temp./øC,Time/min,DSC/(mW/mg),Mass/%,Gas Flow(purge1)/(ml/min),Gas Flow(purge2)/(ml/min),Gas Flow(protective)/(ml/min),DTG/(%/min),Sensit./(uV/mW)
 40.82000, 15.52333, 2.4986e-002,98.17250,50.00000,0.0000e+000,20.00000,-9.0234e-002,1.22581
 40.88000, 15.70333, 2.4427e-002,98.15364,50.00000,0.0000e+000,20.00000,-9.0256e-002,1.22573
 40.95300, 15.88333, 2.4610e-002,98.13716,50.00000,0.0000e+000,20.00000,-8.8551e-002,1.22563
 41.10000, 16.06333, 2.4487e-002,98.12674,50.00000,0.0000e+000,20.00000,-8.4839e-002,1.22543
 41.34100, 16.24333, 2.4729e-002,98.11325,50.00000,0.0000e+000,20.00000,-8.2356e-002,1.22509
 41.62100, 16.42333, 2.5697e-002,98.09283,50.00000,0.0000e+000,20.00000,-8.3464e-002,1.22471
 41.99900, 16.60333, 2.6994e-002,98.07610,50.00000,0.0000e+000,20.00000,-8.1891e-002,1.22419
 42.44500, 16.78333, 2.8168e-002,98.06439,50.00000,0.0000e+000,20.00000,-8.2844e-002,1.22357
 43.00600, 16.96333, 3.0435e-002,98.05153,50.00000,0.0000e+000,20.00000,-8.4471e-002,1.22280
 43.61300, 17.14333, 3.2634e-002,98.04051,50.00000,0.0000e+000,20.00000,-8.7174e-002,1.22196
 44.35900, 17.32333, 3.5041e-002,98.02969,50.00000,0.0000e+000,20.00000,-8.8676e-002,1.22093
 45.15700, 17.50333, 3.7763e-002,98.01545,50.00000,0.0000e+000,20.00000,-8.9826e-002,1.21983
 46.04000, 17.68333, 4.0731e-002,97.99858,50.00000,0.0000e+000,20.00000,-9.2176e-002,1.21862
 46.99900, 17.86333, 4.3781e-002,97.98289,50.00000,0.0000e+000,20.00000,-9.7309e-002,1.21729
 48.07500, 18.04333, 4.7191e-002,97.97129,50.00000,0.0000e+000,20.00000,    -0.10333,1.21581
 49.19900, 18.22333, 5.0649e-002,97.95768,50.00000,0.0000e+000,20.00000,    -0.10682,1.21426
 50.45800, 18.40333, 5.4014e-002,97.94165,50.00000,0.0000e+000,20.00000,    -0.11283,1.21253
 51.78700, 18.58333, 5.7851e-002,97.92451,50.00000,0.0000e+000,20.00000,    -0.12283,1.21070
 53.18200, 18.76333, 6.1924e-002,97.90395,50.00000,0.0000e+000,20.00000,    -0.13368,1.20878
 54.63800, 18.94333, 6.6088e-002,97.87839,50.00000,0.0000e+000,20.00000,    -0.14508,1.20678
 56.20800, 19.12333, 7.0184e-002,97.85480,50.00000,0.0000e+000,20.00000,    -0.15898,1.20462
 57.81300, 19.30333, 7.4795e-002,97.83171,50.00000,0.0000e+000,20.00000,    -0.17649,1.20241
 59.55700, 19.48333, 7.8918e-002,97.80669,50.00000,0.0000e+000,20.00000,    -0.19527,1.20001
 61.31900, 19.66333, 8.3596e-002,97.77734,50.00000,0.0000e+000,20.00000,    -0.21521,1.19759
 63.16900, 19.84333, 8.8989e-002,97.74351,50.00000,0.0000e+000,20.00000,    -0.23825,1.19505
 65.10100, 20.02333, 9.4748e-002,97.71066,50.00000,0.0000e+000,20.00000,    -0.26473,1.19239
 67.08400, 20.20333,     0.10084,97.67257,50.00000,0.0000e+000,20.00000,    -0.29316,1.18967
 69.11500, 20.38333,     0.10741,97.62506,50.00000,0.0000e+000,20.00000,    -0.32581,1.18689
 71.18700, 20.56333,     0.11467,97.57287,50.00000,0.0000e+000,20.00000,    -0.35486,1.18405
 73.32800, 20.74333,     0.12267,97.52019,50.00000,0.0000e+000,20.00000,    -0.38812,1.18111
 75.51200, 20.92333,     0.13119,97.46089,50.00000,0.0000e+000,20.00000,    -0.42362,1.17813
 77.74400, 21.10333,     0.14088,97.38539,50.00000,0.0000e+000,20.00000,    -0.46366,1.17507
 79.99200, 21.28333,     0.15143,97.30086,50.00000,0.0000e+000,20.00000,    -0.50390,1.17200
 82.28400, 21.46333,     0.16274,97.21216,50.00000,0.0000e+000,20.00000,    -0.54404,1.16887
 84.64800, 21.64333,     0.17562,97.11798,50.00000,0.0000e+000,20.00000,    -0.58973,1.16564
 86.98500, 21.82333,     0.18854,97.00959,50.00000,0.0000e+000,20.00000,    -0.63962,1.16246
 89.38000, 22.00333,     0.20217,96.89245,50.00000,0.0000e+000,20.00000,    -0.69354,1.15920
 91.80300, 22.18333,     0.21678,96.75673,50.00000,0.0000e+000,20.00000,    -0.74773,1.15590
 94.23400, 22.36333,     0.23141,96.63018,50.00000,0.0000e+000,20.00000,    -0.80321,1.15260
 96.70700, 22.54333,     0.24658,96.48759,50.00000,0.0000e+000,20.00000,    -0.86400,1.14924
 99.15900, 22.72333,     0.26250,96.33361,50.00000,0.0000e+000,20.00000,    -0.92734,1.14591
101.65100, 22.90333,     0.27964,96.16755,50.00000,0.0000e+000,20.00000,    -0.99139,1.14254
104.11500, 23.08333,     0.29802,95.99494,50.00000,0.0000e+000,20.00000,    -1.05224,1.13920
106.61000, 23.26333,     0.31898,95.82157,50.00000,0.0000e+000,20.00000,    -1.10842,1.13583
109.06800, 23.44333,     0.34202,95.62559,50.00000,0.0000e+000,20.00000,    -1.15548,1.13252
111.57300, 23.62333,     0.36774,95.41150,50.00000,0.0000e+000,20.00000,    -1.19040,1.12914
114.05300, 23.80333,     0.39530,95.18120,50.00000,0.0000e+000,20.00000,    -1.21301,1.12580
116.50600, 23.98333,     0.42533,94.93717,50.00000,0.0000e+000,20.00000,    -1.22532,1.12251
118.96600, 24.16333,     0.45736,94.68578,50.00000,0.0000e+000,20.00000,    -1.23509,1.11921
121.43100, 24.34333,     0.49145,94.41311,50.00000,0.0000e+000,20.00000,    -1.23964,1.11591
123.90000, 24.52333,     0.52609,94.12716,50.00000,0.0000e+000,20.00000,    -1.23735,1.11260
126.33700, 24.70333,     0.55947,93.82136,50.00000,0.0000e+000,20.00000,    -1.23090,1.10935
128.75900, 24.88333,     0.58863,93.51460,50.00000,0.0000e+000,20.00000,    -1.22192,1.10612
131.19000, 25.06333,     0.60321,93.21761,50.00000,0.0000e+000,20.00000,    -1.21154,1.10288
133.56900, 25.24333,     0.59389,92.94863,50.00000,0.0000e+000,20.00000,    -1.19552,1.09972
135.97800, 25.42333,     0.56233,92.70882,50.00000,0.0000e+000,20.00000,    -1.17609,1.09652
138.38600, 25.60333,     0.52170,92.50688,50.00000,0.0000e+000,20.00000,    -1.14339,1.09333
140.78900, 25.78333,     0.47988,92.32470,50.00000,0.0000e+000,20.00000,    -1.10551,1.09015
143.17300, 25.96333,     0.44034,92.16020,50.00000,0.0000e+000,20.00000,    -1.07291,1.08701
145.55600, 26.14333,     0.40389,92.00267,50.00000,0.0000e+000,20.00000,    -1.02739,1.08387
147.92700, 26.32333,     0.37082,91.85646,50.00000,0.0000e+000,20.00000,    -0.97709,1.08075
150.29500, 26.50333,     0.34090,91.71654,50.00000,0.0000e+000,20.00000,    -0.92360,1.07764
152.62300, 26.68333,     0.31413,91.57629,50.00000,0.0000e+000,20.00000,    -0.86642,1.07459
154.94400, 26.86333,     0.28950,91.44018,50.00000,0.0000e+000,20.00000,    -0.80915,1.07155
157.23000, 27.04333,     0.26652,91.30947,50.00000,0.0000e+000,20.00000,    -0.75822,1.06857
159.47501, 27.22333,     0.24469,91.16622,50.00000,0.0000e+000,20.00000,    -0.71442,1.06564
161.72501, 27.40333,     0.22464,91.05302,50.00000,0.0000e+000,20.00000,    -0.67994,1.06272
163.92599, 27.58333,     0.20505,90.95247,50.00000,0.0000e+000,20.00000,    -0.65033,1.05986
166.13200, 27.76333,     0.18718,90.82297,50.00000,0.0000e+000,20.00000,    -0.62869,1.05700
168.30701, 27.94333,     0.16907,90.71486,50.00000,0.0000e+000,20.00000,    -0.60839,1.05419
170.46001, 28.12333,     0.15137,90.61711,50.00000,0.0000e+000,20.00000,    -0.58876,1.05141
172.58200, 28.30333,     0.13389,90.50896,50.00000,0.0000e+000,20.00000,    -0.56836,1.04867
174.70200, 28.48333,     0.11696,90.40877,50.00000,0.0000e+000,20.00000,    -0.54726,1.04595
176.80600, 28.66333,     0.10060,90.31755,50.00000,0.0000e+000,20.00000,    -0.52582,1.04325
178.87000, 28.84333, 8.5487e-002,90.22995,50.00000,0.0000e+000,20.00000,    -0.50767,1.04061
180.92900, 29.02333, 7.0960e-002,90.14466,50.00000,0.0000e+000,20.00000,    -0.48548,1.03797
182.96600, 29.20333, 5.7750e-002,90.06276,50.00000,0.0000e+000,20.00000,    -0.46742,1.03537
184.97400, 29.38333, 4.4708e-002,89.98629,50.00000,0.0000e+000,20.00000,    -0.45550,1.03282
186.98500, 29.56333, 3.1666e-002,89.90129,50.00000,0.0000e+000,20.00000,    -0.43660,1.03026
188.94200, 29.74333, 1.8925e-002,89.81398,50.00000,0.0000e+000,20.00000,    -0.42012,1.02778
190.90401, 29.92333, 6.1433e-003,89.73774,50.00000,0.0000e+000,20.00000,    -0.40805,1.02530
192.84399, 30.10333,-6.6133e-003,89.66985,50.00000,0.0000e+000,20.00000,    -0.39019,1.02285
194.75999, 30.28333,-1.9322e-002,89.60711,50.00000,0.0000e+000,20.00000,    -0.37358,1.02043
196.64999, 30.46333,-3.1741e-002,89.54728,50.00000,0.0000e+000,20.00000,    -0.36153,1.01806
198.52800, 30.64333,-4.3562e-002,89.48485,50.00000,0.0000e+000,20.00000,    -0.35088,1.01570
200.38400, 30.82333,-5.5721e-002,89.42192,50.00000,0.0000e+000,20.00000,    -0.33879,1.01337
202.25900, 31.00333,-6.7345e-002,89.36712,50.00000,0.0000e+000,20.00000,    -0.32703,1.01103
204.09200, 31.18333,-7.8623e-002,89.31393,50.00000,0.0000e+000,20.00000,    -0.31901,1.00874
205.91400, 31.36333,-8.9730e-002,89.25532,50.00000,0.0000e+000,20.00000,    -0.30818,1.00647
207.73000, 31.54333,    -0.10005,89.20217,50.00000,0.0000e+000,20.00000,    -0.29236,1.00421
209.55099, 31.72333,    -0.11030,89.14891,50.00000,0.0000e+000,20.00000,    -0.27959,1.00196
211.35400, 31.90333,    -0.11991,89.10528,50.00000,0.0000e+000,20.00000,    -0.27186,0.99972
213.13100, 32.08333,    -0.12929,89.06466,50.00000,0.0000e+000,20.00000,    -0.26617,0.99753
214.88800, 32.26333,    -0.13848,89.01737,50.00000,0.0000e+000,20.00000,    -0.26006,0.99536
216.66299, 32.44333,    -0.14794,88.96803,50.00000,0.0000e+000,20.00000,    -0.25274,0.99318
218.42400, 32.62333,    -0.15722,88.92501,50.00000,0.0000e+000,20.00000,    -0.24459,0.99102
220.17599, 32.80333,    -0.16722,88.88609,50.00000,0.0000e+000,20.00000,    -0.23803,0.98887
221.92599, 32.98333,    -0.17669,88.83972,50.00000,0.0000e+000,20.00000,    -0.23283,0.98673
223.65401, 33.16333,    -0.18606,88.79413,50.00000,0.0000e+000,20.00000,    -0.22628,0.98462
225.41901, 33.34333,    -0.19511,88.76254,50.00000,0.0000e+000,20.00000,    -0.22068,0.98247
227.15199, 33.52333,    -0.20417,88.73218,50.00000,0.0000e+000,20.00000,    -0.21414,0.98037
228.88600, 33.70333,    -0.21279,88.69283,50.00000,0.0000e+000,20.00000,    -0.21082,0.97826
230.61200, 33.88334,    -0.22140,88.64982,50.00000,0.0000e+000,20.00000,    -0.20961,0.97617
232.33501, 34.06333,    -0.22996,88.61140,50.00000,0.0000e+000,20.00000,    -0.20584,0.97409
234.06799, 34.24333,    -0.23805,88.57617,50.00000,0.0000e+000,20.00000,    -0.19982,0.97201
235.80099, 34.42333,    -0.24666,88.54212,50.00000,0.0000e+000,20.00000,    -0.19516,0.96992
237.52699, 34.60333,    -0.25461,88.51006,50.00000,0.0000e+000,20.00000,    -0.19352,0.96785
239.25500, 34.78333,    -0.26294,88.47666,50.00000,0.0000e+000,20.00000,    -0.18978,0.96578
240.97301, 34.96333,    -0.27068,88.44238,50.00000,0.0000e+000,20.00000,    -0.18512,0.96373
242.71899, 35.14333,    -0.27830,88.40839,50.00000,0.0000e+000,20.00000,    -0.18327,0.96165
244.45300, 35.32333,    -0.28511,88.37857,50.00000,0.0000e+000,20.00000,    -0.18241,0.95959
246.17101, 35.50333,    -0.29267,88.34634,50.00000,0.0000e+000,20.00000,    -0.17969,0.95755
247.89400, 35.68333,    -0.29972,88.31024,50.00000,0.0000e+000,20.00000,    -0.17702,0.95551
249.62601, 35.86333,    -0.30693,88.27749,50.00000,0.0000e+000,20.00000,    -0.17450,0.95347
251.35300, 36.04333,    -0.31360,88.24875,50.00000,0.0000e+000,20.00000,    -0.17152,0.95144
253.08299, 36.22333,    -0.32046,88.22249,50.00000,0.0000e+000,20.00000,    -0.17036,0.94940
254.81700, 36.40333,    -0.32765,88.18991,50.00000,0.0000e+000,20.00000,    -0.16917,0.94737
256.53699, 36.58333,    -0.33492,88.15849,50.00000,0.0000e+000,20.00000,    -0.16534,0.94536
258.26999, 36.76333,    -0.34123,88.12780,50.00000,0.0000e+000,20.00000,    -0.16323,0.94334
259.99301, 36.94333,    -0.34816,88.10119,50.00000,0.0000e+000,20.00000,    -0.16247,0.94133
261.73499, 37.12333,    -0.35519,88.07442,50.00000,0.0000e+000,20.00000,    -0.16057,0.93931
263.47501, 37.30333,    -0.36187,88.04742,50.00000,0.0000e+000,20.00000,    -0.15857,0.93729
265.20401, 37.48333,    -0.36888,88.01430,50.00000,0.0000e+000,20.00000,    -0.15562,0.93529
266.94800, 37.66333,    -0.37476,87.98319,50.00000,0.0000e+000,20.00000,    -0.15364,0.93328
268.68100, 37.84333,    -0.38128,87.95856,50.00000,0.0000e+000,20.00000,    -0.15217,0.93129
270.40799, 38.02333,    -0.38688,87.92932,50.00000,0.0000e+000,20.00000,    -0.15342,0.92931
272.14401, 38.20333,    -0.39305,87.90026,50.00000,0.0000e+000,20.00000,    -0.15164,0.92732
273.88800, 38.38334,    -0.39976,87.88041,50.00000,0.0000e+000,20.00000,    -0.14958,0.92533
275.61499, 38.56333,    -0.40638,87.85600,50.00000,0.0000e+000,20.00000,    -0.14857,0.92337
277.35599, 38.74333,    -0.41349,87.82378,50.00000,0.0000e+000,20.00000,    -0.14674,0.92139
279.10699, 38.92333,    -0.42079,87.79955,50.00000,0.0000e+000,20.00000,    -0.14580,0.91941
280.84299, 39.10333,    -0.42786,87.77594,50.00000,0.0000e+000,20.00000,    -0.14638,0.91745
282.57999, 39.28333,    -0.43403,87.75074,50.00000,0.0000e+000,20.00000,    -0.14384,0.91549
284.34698, 39.46333,    -0.44034,87.72464,50.00000,0.0000e+000,20.00000,    -0.14171,0.91350
286.09500, 39.64333,    -0.44613,87.70050,50.00000,0.0000e+000,20.00000,    -0.14354,0.91154
287.85199, 39.82333,    -0.45231,87.67088,50.00000,0.0000e+000,20.00000,    -0.14218,0.90958
289.57901, 40.00333,    -0.45884,87.64406,50.00000,0.0000e+000,20.00000,    -0.13894,0.90766
291.34100, 40.18333,    -0.46534,87.62071,50.00000,0.0000e+000,20.00000,    -0.13833,0.90570
293.10001, 40.36333,    -0.47238,87.59297,50.00000,0.0000e+000,20.00000,    -0.13806,0.90375
294.86401, 40.54333,    -0.47906,87.57178,50.00000,0.0000e+000,20.00000,    -0.13658,0.90180
296.63501, 40.72333,    -0.48500,87.54975,50.00000,0.0000e+000,20.00000,    -0.13667,0.89984
298.40601, 40.90333,    -0.49082,87.52099,50.00000,0.0000e+000,20.00000,    -0.13708,0.89790
300.15302, 41.08333,    -0.49563,87.49705,50.00000,0.0000e+000,20.00000,    -0.13592,0.89598
301.91299, 41.26333,    -0.50136,87.47383,50.00000,0.0000e+000,20.00000,    -0.13442,0.89406
303.67499, 41.44333,    -0.50734,87.44245,50.00000,0.0000e+000,20.00000,    -0.13405,0.89214
305.45099, 41.62333,    -0.51425,87.41726,50.00000,0.0000e+000,20.00000,    -0.13307,0.89021
307.21701, 41.80333,    -0.52127,87.39923,50.00000,0.0000e+000,20.00000,    -0.13086,0.88829
308.99301, 41.98333,    -0.52658,87.38040,50.00000,0.0000e+000,20.00000,    -0.13102,0.88637
310.74799, 42.16333,    -0.53079,87.35981,50.00000,0.0000e+000,20.00000,    -0.12992,0.88448
312.52100, 42.34333,    -0.53563,87.33320,50.00000,0.0000e+000,20.00000,    -0.13033,0.88258
314.27899, 42.52333,    -0.54151,87.30740,50.00000,0.0000e+000,20.00000,    -0.13099,0.88069
316.02200, 42.70333,    -0.54740,87.28212,50.00000,0.0000e+000,20.00000,    -0.12904,0.87883
317.80301, 42.88334,    -0.55428,87.26101,50.00000,0.0000e+000,20.00000,    -0.12722,0.87693
319.57001, 43.06333,    -0.56091,87.24042,50.00000,0.0000e+000,20.00000,    -0.12707,0.87506
321.35101, 43.24333,    -0.56723,87.21815,50.00000,0.0000e+000,20.00000,    -0.12606,0.87317
323.11401, 43.42333,    -0.57333,87.19282,50.00000,0.0000e+000,20.00000,    -0.12495,0.87131
324.87900, 43.60333,    -0.57876,87.17236,50.00000,0.0000e+000,20.00000,    -0.12633,0.86945
326.65399, 43.78333,    -0.58471,87.14959,50.00000,0.0000e+000,20.00000,    -0.12748,0.86759
328.44299, 43.96333,    -0.59066,87.12562,50.00000,0.0000e+000,20.00000,    -0.12828,0.86572
330.22198, 44.14333,    -0.59706,87.10204,50.00000,0.0000e+000,20.00000,    -0.12720,0.86387
331.99500, 44.32333,    -0.60297,87.07839,50.00000,0.0000e+000,20.00000,    -0.12583,0.86202
333.77499, 44.50333,    -0.60865,87.05674,50.00000,0.0000e+000,20.00000,    -0.12595,0.86018
335.55200, 44.68333,    -0.61437,87.03803,50.00000,0.0000e+000,20.00000,    -0.12677,0.85834
337.32401, 44.86333,    -0.61920,87.01739,50.00000,0.0000e+000,20.00000,    -0.12825,0.85652
339.10400, 45.04333,    -0.62340,86.99052,50.00000,0.0000e+000,20.00000,    -0.13007,0.85469
340.85501, 45.22333,    -0.62755,86.96695,50.00000,0.0000e+000,20.00000,    -0.13054,0.85290
342.64099, 45.40333,    -0.63233,86.94405,50.00000,0.0000e+000,20.00000,    -0.13141,0.85108
344.39401, 45.58333,    -0.63731,86.92068,50.00000,0.0000e+000,20.00000,    -0.13279,0.84929
346.16299, 45.76333,    -0.64303,86.89805,50.00000,0.0000e+000,20.00000,    -0.13281,0.84750
347.94299, 45.94333,    -0.64894,86.87565,50.00000,0.0000e+000,20.00000,    -0.13372,0.84570
349.72198, 46.12333,    -0.65444,86.85481,50.00000,0.0000e+000,20.00000,    -0.13701,0.84391
351.49100, 46.30333,    -0.65969,86.82968,50.00000,0.0000e+000,20.00000,    -0.13872,0.84214
353.28400, 46.48333,    -0.66437,86.80414,50.00000,0.0000e+000,20.00000,    -0.13912,0.84034
355.05499, 46.66333,    -0.66968,86.77936,50.00000,0.0000e+000,20.00000,    -0.14106,0.83858
356.82599, 46.84333,    -0.67467,86.75050,50.00000,0.0000e+000,20.00000,    -0.14235,0.83682
358.60501, 47.02333,    -0.67936,86.72348,50.00000,0.0000e+000,20.00000,    -0.14399,0.83505
360.38901, 47.20333,    -0.68367,86.69868,50.00000,0.0000e+000,20.00000,    -0.14582,0.83329
362.16400, 47.38334,    -0.68855,86.67234,50.00000,0.0000e+000,20.00000,    -0.14656,0.83155
363.94501, 47.56333,    -0.69382,86.64707,50.00000,0.0000e+000,20.00000,    -0.14572,0.82980
365.76300, 47.74333,    -0.70187,86.62189,50.00000,0.0000e+000,20.00000,    -0.14582,0.82802
367.58200, 47.92333,    -0.71124,86.58669,50.00000,0.0000e+000,20.00000,    -0.14809,0.82625
369.41901, 48.10333,    -0.71846,86.55610,50.00000,0.0000e+000,20.00000,    -0.14779,0.82447
371.24301, 48.28333,    -0.72304,86.53576,50.00000,0.0000e+000,20.00000,    -0.14674,0.82270
373.05499, 48.46333,    -0.72566,86.50998,50.00000,0.0000e+000,20.00000,    -0.14741,0.82096
374.84601, 48.64333,    -0.72724,86.47915,50.00000,0.0000e+000,20.00000,    -0.14645,0.81924
376.64999, 48.82333,    -0.72981,86.44849,50.00000,0.0000e+000,20.00000,    -0.14568,0.81751
378.41501, 49.00333,    -0.73237,86.41920,50.00000,0.0000e+000,20.00000,    -0.14463,0.81583
380.19000, 49.18333,    -0.73746,86.39199,50.00000,0.0000e+000,20.00000,    -0.14365,0.81414
381.95599, 49.36333,    -0.74266,86.37173,50.00000,0.0000e+000,20.00000,    -0.14313,0.81247
383.73999, 49.54333,    -0.74847,86.35026,50.00000,0.0000e+000,20.00000,    -0.14372,0.81078
385.52100, 49.72333,    -0.75495,86.32092,50.00000,0.0000e+000,20.00000,    -0.14022,0.80911
387.30301, 49.90333,    -0.76176,86.29693,50.00000,0.0000e+000,20.00000,    -0.13620,0.80744
389.08600, 50.08333,    -0.76917,86.27513,50.00000,0.0000e+000,20.00000,    -0.13569,0.80577
390.86899, 50.26333,    -0.77696,86.24877,50.00000,0.0000e+000,20.00000,    -0.13421,0.80411
392.64401, 50.44333,    -0.78469,86.22350,50.00000,0.0000e+000,20.00000,    -0.13178,0.80247
394.43100, 50.62333,    -0.79113,86.19840,50.00000,0.0000e+000,20.00000,    -0.13026,0.80082
396.21399, 50.80333,    -0.79689,86.17710,50.00000,0.0000e+000,20.00000,    -0.12770,0.79918
397.98700, 50.98333,    -0.80138,86.15493,50.00000,0.0000e+000,20.00000,    -0.12376,0.79755
399.76501, 51.16333,    -0.80611,86.13141,50.00000,0.0000e+000,20.00000,    -0.12384,0.79592
401.51700, 51.34333,    -0.81180,86.10482,50.00000,0.0000e+000,20.00000,    -0.12486,0.79433
403.28601, 51.52333,    -0.81767,86.08283,50.00000,0.0000e+000,20.00000,    -0.12274,0.79272
405.06799, 51.70333,    -0.82452,86.06461,50.00000,0.0000e+000,20.00000,    -0.12242,0.79111
406.85001, 51.88334,    -0.83086,86.04610,50.00000,0.0000e+000,20.00000,    -0.12440,0.78951
408.62299, 52.06333,    -0.83803,86.02668,50.00000,0.0000e+000,20.00000,    -0.12402,0.78792
410.40601, 52.24333,    -0.84421,86.00599,50.00000,0.0000e+000,20.00000,    -0.12354,0.78632
412.19000, 52.42333,    -0.85002,85.98071,50.00000,0.0000e+000,20.00000,    -0.12357,0.78473
413.94699, 52.60333,    -0.85398,85.95928,50.00000,0.0000e+000,20.00000,    -0.12389,0.78317
415.70700, 52.78333,    -0.85792,85.94579,50.00000,0.0000e+000,20.00000,    -0.12363,0.78162
417.46600, 52.96333,    -0.86366,85.92563,50.00000,0.0000e+000,20.00000,    -0.12601,0.78007
419.23499, 53.14333,    -0.87034,85.90136,50.00000,0.0000e+000,20.00000,    -0.12632,0.77852
421.00000, 53.32333,    -0.87695,85.87984,50.00000,0.0000e+000,20.00000,    -0.12806,0.77697
422.79001, 53.50333,    -0.88406,85.85695,50.00000,0.0000e+000,20.00000,    -0.13448,0.77541
424.59100, 53.68333,    -0.89264,85.82827,50.00000,0.0000e+000,20.00000,    -0.14228,0.77385
426.42599, 53.86333,    -0.90332,85.80309,50.00000,0.0000e+000,20.00000,    -0.15136,0.77226
428.25800, 54.04333,    -0.91251,85.77957,50.00000,0.0000e+000,20.00000,    -0.16010,0.77069
430.09698, 54.22333,    -0.91657,85.75423,50.00000,0.0000e+000,20.00000,    -0.16938,0.76911
431.89700, 54.40333,    -0.91612,85.73054,50.00000,0.0000e+000,20.00000,    -0.18475,0.76757
433.70901, 54.58333,    -0.91247,85.71041,50.00000,0.0000e+000,20.00000,    -0.20265,0.76603
435.48499, 54.76333,    -0.90713,85.67968,50.00000,0.0000e+000,20.00000,    -0.22128,0.76453
437.27701, 54.94333,    -0.90003,85.65088,50.00000,0.0000e+000,20.00000,    -0.24190,0.76301
439.02701, 55.12333,    -0.89108,85.62313,50.00000,0.0000e+000,20.00000,    -0.26497,0.76154
440.81400, 55.30333,    -0.88192,85.58271,50.00000,0.0000e+000,20.00000,    -0.28567,0.76004
442.59201, 55.48333,    -0.86999,85.53642,50.00000,0.0000e+000,20.00000,    -0.30750,0.75856
444.38300, 55.66333,    -0.85404,85.48478,50.00000,0.0000e+000,20.00000,    -0.33631,0.75707
446.14001, 55.84333,    -0.83628,85.43190,50.00000,0.0000e+000,20.00000,    -0.36288,0.75562
447.92001, 56.02333,    -0.81594,85.37630,50.00000,0.0000e+000,20.00000,    -0.38971,0.75415
449.69000, 56.20333,    -0.79571,85.29884,50.00000,0.0000e+000,20.00000,    -0.42186,0.75269
451.44601, 56.38334,    -0.77267,85.21978,50.00000,0.0000e+000,20.00000,    -0.45321,0.75126
453.23099, 56.56333,    -0.74956,85.13430,50.00000,0.0000e+000,20.00000,    -0.48009,0.74980
455.00000, 56.74333,    -0.72703,85.03706,50.00000,0.0000e+000,20.00000,    -0.50788,0.74837
456.79501, 56.92333,    -0.70605,84.93020,50.00000,0.0000e+000,20.00000,    -0.52971,0.74692
458.57800, 57.10333,    -0.68352,84.83169,50.00000,0.0000e+000,20.00000,    -0.54336,0.74548
460.37799, 57.28333,    -0.66485,84.72687,50.00000,0.0000e+000,20.00000,    -0.54910,0.74404
462.20001, 57.46333,    -0.64638,84.59804,50.00000,0.0000e+000,20.00000,    -0.54536,0.74258
463.99899, 57.64333,    -0.62473,84.47388,50.00000,0.0000e+000,20.00000,    -0.53985,0.74115
465.78799, 57.82333,    -0.60404,84.35476,50.00000,0.0000e+000,20.00000,    -0.53378,0.73973
467.56799, 58.00333,    -0.58687,84.21311,50.00000,0.0000e+000,20.00000,    -0.52006,0.73833
469.35400, 58.18333,    -0.57381,84.07743,50.00000,0.0000e+000,20.00000,    -0.50419,0.73692
471.12299, 58.36333,    -0.56759,83.94981,50.00000,0.0000e+000,20.00000,    -0.48598,0.73554
472.89499, 58.54333,    -0.57488,83.81763,50.00000,0.0000e+000,20.00000,    -0.46420,0.73416
474.67300, 58.72333,    -0.60454,83.70641,50.00000,0.0000e+000,20.00000,    -0.43848,0.73278
476.47800, 58.90333,    -0.66325,83.61635,50.00000,0.0000e+000,20.00000,    -0.41578,0.73138
478.26099, 59.08333,    -0.74589,83.54451,50.00000,0.0000e+000,20.00000,    -0.39227,0.73001
480.07700, 59.26333,    -0.83059,83.50470,50.00000,0.0000e+000,20.00000,    -0.36098,0.72862
481.89099, 59.44333,    -0.89927,83.47160,50.00000,0.0000e+000,20.00000,    -0.32987,0.72723
483.69699, 59.62333,    -0.94897,83.43957,50.00000,0.0000e+000,20.00000,    -0.30214,0.72586
485.51901, 59.80333,    -0.98525,83.41390,50.00000,0.0000e+000,20.00000,    -0.26759,0.72448
487.34698, 59.98333,    -1.01258,83.39222,50.00000,0.0000e+000,20.00000,    -0.23467,0.72310
489.15601, 60.16333,    -1.03228,83.37409,50.00000,0.0000e+000,20.00000,    -0.20385,0.72174
490.95499, 60.34333,    -1.04809,83.35843,50.00000,0.0000e+000,20.00000,    -0.17003,0.72040
492.75000, 60.52333,    -1.06133,83.34571,50.00000,0.0000e+000,20.00000,    -0.13984,0.71906
494.56400, 60.70333,    -1.07293,83.32942,50.00000,0.0000e+000,20.00000,    -0.11714,0.71772
496.39301, 60.88334,    -1.08653,83.31269,50.00000,0.0000e+000,20.00000,    -0.10014,0.71637
498.22601, 61.06333,    -1.09990,83.30105,50.00000,0.0000e+000,20.00000,-9.1057e-002,0.71502
500.07199, 61.24333,    -1.10869,83.28789,50.00000,0.0000e+000,20.00000,-8.4661e-002,0.71367
501.88000, 61.42333,    -1.11323,83.27260,50.00000,0.0000e+000,20.00000,-7.7606e-002,0.71235
503.68600, 61.60333,    -1.11647,83.25899,50.00000,0.0000e+000,20.00000,-7.3402e-002,0.71104
505.48999, 61.78333,    -1.11967,83.24260,50.00000,0.0000e+000,20.00000,-7.0338e-002,0.70974
507.29001, 61.96333,    -1.12303,83.22612,50.00000,0.0000e+000,20.00000,-6.7449e-002,0.70845
509.08401, 62.14333,    -1.12586,83.21699,50.00000,0.0000e+000,20.00000,-6.5290e-002,0.70716
510.84601, 62.32333,    -1.12906,83.21118,50.00000,0.0000e+000,20.00000,-6.3891e-002,0.70590
512.63202, 62.50333,    -1.13213,83.20330,50.00000,0.0000e+000,20.00000,-6.1728e-002,0.70464
514.40601, 62.68333,    -1.13598,83.18924,50.00000,0.0000e+000,20.00000,-6.0029e-002,0.70338
516.20599, 62.86333,    -1.14182,83.17837,50.00000,0.0000e+000,20.00000,-5.9980e-002,0.70211
518.00201, 63.04333,    -1.14944,83.16859,50.00000,0.0000e+000,20.00000,-6.0158e-002,0.70085
519.76898, 63.22333,    -1.15096,83.16163,50.00000,0.0000e+000,20.00000,-5.8343e-002,0.69962
521.53998, 63.40333,    -1.15137,83.15118,50.00000,0.0000e+000,20.00000,-5.6570e-002,0.69839
523.30298, 63.58333,    -1.15313,83.13961,50.00000,0.0000e+000,20.00000,-5.4130e-002,0.69717
525.07098, 63.76333,    -1.15731,83.13136,50.00000,0.0000e+000,20.00000,-5.2037e-002,0.69595
526.83301, 63.94333,    -1.16252,83.12326,50.00000,0.0000e+000,20.00000,-5.2283e-002,0.69474
528.63599, 64.12334,    -1.16897,83.11527,50.00000,0.0000e+000,20.00000,-5.3823e-002,0.69351
530.42297, 64.30334,    -1.17544,83.10793,50.00000,0.0000e+000,20.00000,-5.4788e-002,0.69229
532.20801, 64.48333,    -1.18231,83.09730,50.00000,0.0000e+000,20.00000,-5.4277e-002,0.69109
534.00098, 64.66333,    -1.18737,83.08547,50.00000,0.0000e+000,20.00000,-5.4164e-002,0.68988
535.80200, 64.84333,    -1.19155,83.07210,50.00000,0.0000e+000,20.00000,-5.3023e-002,0.68867
537.59802, 65.02333,    -1.19576,83.06268,50.00000,0.0000e+000,20.00000,-5.2947e-002,0.68747
539.39600, 65.20333,    -1.20105,83.05544,50.00000,0.0000e+000,20.00000,-5.2773e-002,0.68627
541.19299, 65.38333,    -1.20641,83.04861,50.00000,0.0000e+000,20.00000,-5.2910e-002,0.68508
542.98798, 65.56333,    -1.21106,83.03968,50.00000,0.0000e+000,20.00000,-5.4648e-002,0.68389
544.78998, 65.74333,    -1.21485,83.02869,50.00000,0.0000e+000,20.00000,-5.4190e-002,0.68271
546.61499, 65.92333,    -1.22052,83.01701,50.00000,0.0000e+000,20.00000,-5.4360e-002,0.68151
548.40900, 66.10333,    -1.22542,83.00633,50.00000,0.0000e+000,20.00000,-5.5702e-002,0.68035
550.20801, 66.28333,    -1.23017,82.99492,50.00000,0.0000e+000,20.00000,-5.5289e-002,0.67918
552.01202, 66.46333,    -1.23304,82.98321,50.00000,0.0000e+000,20.00000,-5.5354e-002,0.67802
553.81201, 66.64333,    -1.23668,82.97690,50.00000,0.0000e+000,20.00000,-5.4156e-002,0.67686
555.61798, 66.82333,    -1.24067,82.97050,50.00000,0.0000e+000,20.00000,-5.4608e-002,0.67570
557.40601, 67.00333,    -1.24355,82.96161,50.00000,0.0000e+000,20.00000,-5.6252e-002,0.67456
559.18402, 67.18333,    -1.24695,82.95015,50.00000,0.0000e+000,20.00000,-5.6600e-002,0.67344
560.97998, 67.36333,    -1.25051,82.93457,50.00000,0.0000e+000,20.00000,-5.7128e-002,0.67230
562.77502, 67.54333,    -1.25539,82.92717,50.00000,0.0000e+000,20.00000,-5.9428e-002,0.67117
564.56702, 67.72334,    -1.25934,82.91963,50.00000,0.0000e+000,20.00000,-5.8800e-002,0.67005
566.35498, 67.90334,    -1.26409,82.90709,50.00000,0.0000e+000,20.00000,-5.6774e-002,0.66894
568.16901, 68.08334,    -1.27008,82.89853,50.00000,0.0000e+000,20.00000,-5.6925e-002,0.66781
569.97900, 68.26334,    -1.27460,82.88673,50.00000,0.0000e+000,20.00000,-5.7040e-002,0.66669
571.76300, 68.44334,    -1.27800,82.87755,50.00000,0.0000e+000,20.00000,-5.9043e-002,0.66560
573.57098, 68.62334,    -1.28227,82.86625,50.00000,0.0000e+000,20.00000,-6.1105e-002,0.66449
575.37201, 68.80334,    -1.28717,82.85279,50.00000,0.0000e+000,20.00000,-6.0947e-002,0.66339
577.17297, 68.98333,    -1.29140,82.84374,50.00000,0.0000e+000,20.00000,-6.1782e-002,0.66230
578.96503, 69.16333,    -1.29623,82.83485,50.00000,0.0000e+000,20.00000,-6.1346e-002,0.66121
580.77802, 69.34333,    -1.30022,82.81601,50.00000,0.0000e+000,20.00000,-6.2090e-002,0.66012
582.60498, 69.52333,    -1.30319,82.80427,50.00000,0.0000e+000,20.00000,-6.3616e-002,0.65903
584.38702, 69.70333,    -1.30664,82.80148,50.00000,0.0000e+000,20.00000,-6.4377e-002,0.65797
586.21399, 69.88333,    -1.31072,82.79083,50.00000,0.0000e+000,20.00000,-6.5609e-002,0.65688
588.01599, 70.06333,    -1.31437,82.77804,50.00000,0.0000e+000,20.00000,-6.6846e-002,0.65582
589.81702, 70.24333,    -1.31894,82.76433,50.00000,0.0000e+000,20.00000,-6.9571e-002,0.65476
591.63800, 70.42333,    -1.32201,82.74990,50.00000,0.0000e+000,20.00000,-7.2120e-002,0.65369
593.43701, 70.60333,    -1.32709,82.74165,50.00000,0.0000e+000,20.00000,-7.4695e-002,0.65264
595.26898, 70.78333,    -1.33368,82.72894,50.00000,0.0000e+000,20.00000,-7.5089e-002,0.65158
597.08600, 70.96333,    -1.33689,82.71434,50.00000,0.0000e+000,20.00000,-7.6738e-002,0.65053
598.90002, 71.14333,    -1.33955,82.70263,50.00000,0.0000e+000,20.00000,-7.6912e-002,0.64948
600.70599, 71.32333,    -1.34039,82.69082,50.00000,0.0000e+000,20.00000,-7.8607e-002,0.64845
602.49799, 71.50333,    -1.34162,82.67595,50.00000,0.0000e+000,20.00000,-8.3640e-002,0.64743
604.28497, 71.68333,    -1.34345,82.66196,50.00000,0.0000e+000,20.00000,-8.7176e-002,0.64641
606.08398, 71.86333,    -1.34608,82.64712,50.00000,0.0000e+000,20.00000,-8.8355e-002,0.64539
607.86200, 72.04333,    -1.34858,82.62754,50.00000,0.0000e+000,20.00000,-8.9241e-002,0.64439
609.66101, 72.22334,    -1.35173,82.60801,50.00000,0.0000e+000,20.00000,-9.1114e-002,0.64339
611.46198, 72.40334,    -1.35585,82.58472,50.00000,0.0000e+000,20.00000,-9.5031e-002,0.64238
613.27197, 72.58334,    -1.35894,82.57161,50.00000,0.0000e+000,20.00000,-9.8631e-002,0.64137
615.07501, 72.76334,    -1.36085,82.55911,50.00000,0.0000e+000,20.00000,    -0.10069,0.64038
616.84998, 72.94334,    -1.36269,82.54076,50.00000,0.0000e+000,20.00000,    -0.10279,0.63940
618.64697, 73.12334,    -1.36532,82.52092,50.00000,0.0000e+000,20.00000,    -0.10711,0.63841
620.44702, 73.30334,    -1.36801,82.49990,50.00000,0.0000e+000,20.00000,    -0.11049,0.63743
622.23798, 73.48333,    -1.36983,82.47747,50.00000,0.0000e+000,20.00000,    -0.11305,0.63646
624.04199, 73.66333,    -1.37263,82.45917,50.00000,0.0000e+000,20.00000,    -0.11581,0.63548
625.83899, 73.84333,    -1.37567,82.44349,50.00000,0.0000e+000,20.00000,    -0.11839,0.63451
627.63800, 74.02333,    -1.37917,82.42213,50.00000,0.0000e+000,20.00000,    -0.12100,0.63355
629.45599, 74.20333,    -1.38405,82.39917,50.00000,0.0000e+000,20.00000,    -0.12207,0.63257
631.30103, 74.38333,    -1.39182,82.37463,50.00000,0.0000e+000,20.00000,    -0.12586,0.63159
633.13702, 74.56333,    -1.39590,82.35134,50.00000,0.0000e+000,20.00000,    -0.13104,0.63062
634.95599, 74.74333,    -1.39645,82.33207,50.00000,0.0000e+000,20.00000,    -0.13442,0.62966
636.75500, 74.92333,    -1.39375,82.30568,50.00000,0.0000e+000,20.00000,    -0.13716,0.62872
638.55103, 75.10333,    -1.39060,82.27839,50.00000,0.0000e+000,20.00000,    -0.13974,0.62778
640.32599, 75.28333,    -1.39049,82.25424,50.00000,0.0000e+000,20.00000,    -0.14308,0.62685
642.09802, 75.46333,    -1.38867,82.23043,50.00000,0.0000e+000,20.00000,    -0.14697,0.62593
643.84802, 75.64333,    -1.38635,82.20247,50.00000,0.0000e+000,20.00000,    -0.15045,0.62503
645.63702, 75.82333,    -1.39028,82.17307,50.00000,0.0000e+000,20.00000,    -0.15429,0.62411
647.50702, 76.00333,    -1.40345,82.14616,50.00000,0.0000e+000,20.00000,    -0.16052,0.62315
649.36102, 76.18333,    -1.41060,82.11745,50.00000,0.0000e+000,20.00000,    -0.16386,0.62221
651.20697, 76.36333,    -1.41305,82.08732,50.00000,0.0000e+000,20.00000,    -0.16652,0.62127
653.02502, 76.54333,    -1.41103,82.05695,50.00000,0.0000e+000,20.00000,    -0.17152,0.62035
654.81500, 76.72334,    -1.40754,82.02718,50.00000,0.0000e+000,20.00000,    -0.17841,0.61945
656.60101, 76.90334,    -1.40441,81.99739,50.00000,0.0000e+000,20.00000,    -0.18389,0.61856
658.38202, 77.08334,    -1.40054,81.96330,50.00000,0.0000e+000,20.00000,    -0.18761,0.61767
660.15198, 77.26334,    -1.39945,81.92914,50.00000,0.0000e+000,20.00000,    -0.19422,0.61679
661.93201, 77.44334,    -1.39835,81.90048,50.00000,0.0000e+000,20.00000,    -0.20110,0.61591
663.71100, 77.62334,    -1.39793,81.86820,50.00000,0.0000e+000,20.00000,    -0.20787,0.61503
665.48499, 77.80334,    -1.39821,81.82254,50.00000,0.0000e+000,20.00000,    -0.21407,0.61416
667.29498, 77.98333,    -1.40189,81.78472,50.00000,0.0000e+000,20.00000,    -0.22002,0.61328
669.10199, 78.16333,    -1.40304,81.75107,50.00000,0.0000e+000,20.00000,    -0.22742,0.61240
670.89899, 78.34333,    -1.40261,81.71483,50.00000,0.0000e+000,20.00000,    -0.23571,0.61153
672.69098, 78.52333,    -1.40031,81.66627,50.00000,0.0000e+000,20.00000,    -0.24410,0.61066
674.48297, 78.70333,    -1.39865,81.61634,50.00000,0.0000e+000,20.00000,    -0.25307,0.60980
676.29199, 78.88333,    -1.39900,81.57847,50.00000,0.0000e+000,20.00000,    -0.26161,0.60893
678.10303, 79.06333,    -1.39876,81.53204,50.00000,0.0000e+000,20.00000,    -0.27107,0.60807
679.89600, 79.24333,    -1.39791,81.48028,50.00000,0.0000e+000,20.00000,    -0.28343,0.60722
681.68903, 79.42333,    -1.39321,81.42569,50.00000,0.0000e+000,20.00000,    -0.29446,0.60637
683.48700, 79.60333,    -1.39073,81.37520,50.00000,0.0000e+000,20.00000,    -0.30068,0.60552
685.30200, 79.78333,    -1.38924,81.32591,50.00000,0.0000e+000,20.00000,    -0.31017,0.60467
687.10400, 79.96333,    -1.38652,81.26978,50.00000,0.0000e+000,20.00000,    -0.32375,0.60383
688.89099, 80.14333,    -1.38225,81.20946,50.00000,0.0000e+000,20.00000,    -0.33563,0.60299
690.70001, 80.32333,    -1.37976,81.14872,50.00000,0.0000e+000,20.00000,    -0.34358,0.60216
692.49701, 80.50333,    -1.37550,81.08686,50.00000,0.0000e+000,20.00000,    -0.35487,0.60132
694.30298, 80.68333,    -1.37453,81.02262,50.00000,0.0000e+000,20.00000,    -0.36658,0.60049
696.08600, 80.86333,    -1.36867,80.95427,50.00000,0.0000e+000,20.00000,    -0.37710,0.59968
697.86902, 81.04333,    -1.36286,80.88020,50.00000,0.0000e+000,20.00000,    -0.38901,0.59886
699.65002, 81.22334,    -1.35874,80.80806,50.00000,0.0000e+000,20.00000,    -0.40015,0.59805
701.45300, 81.40334,    -1.35848,80.74123,50.00000,0.0000e+000,20.00000,    -0.41266,0.59723
703.27698, 81.58334,    -1.35709,80.66814,50.00000,0.0000e+000,20.00000,    -0.42416,0.59641
705.07202, 81.76334,    -1.35405,80.58591,50.00000,0.0000e+000,20.00000,    -0.43385,0.59560
706.89301, 81.94334,    -1.35128,80.50538,50.00000,0.0000e+000,20.00000,    -0.44651,0.59479
708.71002, 82.12334,    -1.34816,80.43136,50.00000,0.0000e+000,20.00000,    -0.46012,0.59398
710.53101, 82.30334,    -1.34428,80.34021,50.00000,0.0000e+000,20.00000,    -0.47279,0.59317
712.34003, 82.48333,    -1.34067,80.25603,50.00000,0.0000e+000,20.00000,    -0.48274,0.59237
714.15002, 82.66333,    -1.33716,80.17535,50.00000,0.0000e+000,20.00000,    -0.49115,0.59157
715.96002, 82.84333,    -1.33513,80.08104,50.00000,0.0000e+000,20.00000,    -0.49821,0.59077
717.78400, 83.02333,    -1.33329,79.98616,50.00000,0.0000e+000,20.00000,    -0.50617,0.58997
719.60303, 83.20333,    -1.33042,79.88900,50.00000,0.0000e+000,20.00000,    -0.51541,0.58918
721.42603, 83.38333,    -1.33048,79.79674,50.00000,0.0000e+000,20.00000,    -0.52223,0.58839
723.22699, 83.56333,    -1.32975,79.70788,50.00000,0.0000e+000,20.00000,    -0.52562,0.58761
725.02899, 83.74333,    -1.32993,79.60369,50.00000,0.0000e+000,20.00000,    -0.52650,0.58683
726.82898, 83.92333,    -1.32937,79.49300,50.00000,0.0000e+000,20.00000,    -0.52966,0.58605
728.61798, 84.10333,    -1.32945,79.38451,50.00000,0.0000e+000,20.00000,    -0.52853,0.58529
730.43903, 84.28333,    -1.33190,79.28311,50.00000,0.0000e+000,20.00000,    -0.53157,0.58451
732.25299, 84.46333,    -1.33537,79.18500,50.00000,0.0000e+000,20.00000,    -0.53738,0.58374
734.05103, 84.64333,    -1.33853,79.08618,50.00000,0.0000e+000,20.00000,    -0.53743,0.58298
735.84601, 84.82333,    -1.34286,78.98411,50.00000,0.0000e+000,20.00000,    -0.53663,0.58222
737.68298, 85.00333,    -1.35300,78.88298,50.00000,0.0000e+000,20.00000,    -0.53657,0.58144
739.48602, 85.18333,    -1.36282,78.78574,50.00000,0.0000e+000,20.00000,    -0.53542,0.58069
741.31500, 85.36333,    -1.37391,78.69140,50.00000,0.0000e+000,20.00000,    -0.53738,0.57992
743.11401, 85.54333,    -1.38259,78.60548,50.00000,0.0000e+000,20.00000,    -0.53742,0.57917
744.91998, 85.72334,    -1.38664,78.52021,50.00000,0.0000e+000,20.00000,    -0.53262,0.57842
746.71301, 85.90334,    -1.38839,78.43665,50.00000,0.0000e+000,20.00000,    -0.52389,0.57768
748.50098, 86.08334,    -1.38624,78.34036,50.00000,0.0000e+000,20.00000,    -0.51515,0.57694
750.28802, 86.26334,    -1.38274,78.23964,50.00000,0.0000e+000,20.00000,    -0.50969,0.57621
752.08002, 86.44334,    -1.38300,78.14501,50.00000,0.0000e+000,20.00000,    -0.49680,0.57547
753.86902, 86.62334,    -1.38453,78.05405,50.00000,0.0000e+000,20.00000,    -0.47727,0.57474
755.66803, 86.80334,    -1.38803,77.95709,50.00000,0.0000e+000,20.00000,    -0.45611,0.57401
757.46198, 86.98333,    -1.39301,77.86665,50.00000,0.0000e+000,20.00000,    -0.43603,0.57328
759.28497, 87.16333,    -1.39577,77.77363,50.00000,0.0000e+000,20.00000,    -0.41418,0.57254
761.10797, 87.34333,    -1.40133,77.67122,50.00000,0.0000e+000,20.00000,    -0.39399,0.57180
762.94000, 87.52333,    -1.40706,77.57663,50.00000,0.0000e+000,20.00000,    -0.37518,0.57107
764.73700, 87.70333,    -1.41475,77.49657,50.00000,0.0000e+000,20.00000,    -0.35795,0.57035
766.52197, 87.88333,    -1.42836,77.42687,50.00000,0.0000e+000,20.00000,    -0.33722,0.56963
768.28601, 88.06333,    -1.45433,77.34814,50.00000,0.0000e+000,20.00000,    -0.31387,0.56893
770.08301, 88.24333,    -1.49921,77.29140,50.00000,0.0000e+000,20.00000,    -0.29251,0.56822
771.90302, 88.42333,    -1.54532,77.25936,50.00000,0.0000e+000,20.00000,    -0.27124,0.56749
773.71698, 88.60333,    -1.57627,77.23483,50.00000,0.0000e+000,20.00000,    -0.24787,0.56678
775.59302, 88.78333,    -1.60376,77.21008,50.00000,0.0000e+000,20.00000,    -0.22629,0.56604
777.39398, 88.96333,    -1.61094,77.19337,50.00000,0.0000e+000,20.00000,    -0.20542,0.56533
779.16199, 89.14333,    -1.60899,77.18051,50.00000,0.0000e+000,20.00000,    -0.18195,0.56464
780.94299, 89.32333,    -1.61196,77.16469,50.00000,0.0000e+000,20.00000,    -0.16069,0.56394
782.72900, 89.50333,    -1.61678,77.14469,50.00000,0.0000e+000,20.00000,    -0.14308,0.56325
784.53699, 89.68333,    -1.62405,77.12579,50.00000,0.0000e+000,20.00000,    -0.13000,0.56254
786.33301, 89.86333,    -1.62929,77.11007,50.00000,0.0000e+000,20.00000,    -0.11418,0.56185
788.15698, 90.04333,    -1.63332,77.09245,50.00000,0.0000e+000,20.00000,    -0.10194,0.56114
789.96802, 90.22334,    -1.63808,77.07855,50.00000,0.0000e+000,20.00000,-9.7629e-002,0.56045
791.76300, 90.40334,    -1.64259,77.06778,50.00000,0.0000e+000,20.00000,-9.5525e-002,0.55976
793.60101, 90.58334,    -1.64530,77.05488,50.00000,0.0000e+000,20.00000,-9.2981e-002,0.55905
795.40399, 90.76334,    -1.64729,77.04057,50.00000,0.0000e+000,20.00000,-9.3185e-002,0.55836
797.21399, 90.94334,    -1.64969,77.02404,50.00000,0.0000e+000,20.00000,-9.5325e-002,0.55767
799.02399, 91.12334,    -1.65172,77.00611,50.00000,0.0000e+000,20.00000,-9.6263e-002,0.55698
800.81598, 91.30334,    -1.65414,76.98744,50.00000,0.0000e+000,20.00000,-9.6494e-002,0.55630
802.63202, 91.48333,    -1.65527,76.96641,50.00000,0.0000e+000,20.00000,-9.6247e-002,0.55562
804.44299, 91.66333,    -1.65611,76.94529,50.00000,0.0000e+000,20.00000,-9.6377e-002,0.55493
806.24103, 91.84333,    -1.65837,76.92799,50.00000,0.0000e+000,20.00000,-9.8098e-002,0.55426
808.02899, 92.02333,    -1.65986,76.90944,50.00000,0.0000e+000,20.00000,    -0.10045,0.55359
809.83801, 92.20333,    -1.66254,76.89201,50.00000,0.0000e+000,20.00000,    -0.10177,0.55291
811.64697, 92.38333,    -1.66402,76.87611,50.00000,0.0000e+000,20.00000,    -0.10312,0.55223
813.45203, 92.56333,    -1.66617,76.85810,50.00000,0.0000e+000,20.00000,    -0.10536,0.55156
815.26202, 92.74333,    -1.66885,76.83701,50.00000,0.0000e+000,20.00000,    -0.10657,0.55088
817.05103, 92.92333,    -1.66889,76.81861,50.00000,0.0000e+000,20.00000,    -0.10725,0.55022
818.85797, 93.10333,    -1.67068,76.79822,50.00000,0.0000e+000,20.00000,    -0.10750,0.54955
820.66602, 93.28333,    -1.67171,76.77920,50.00000,0.0000e+000,20.00000,    -0.10744,0.54888
822.45898, 93.46333,    -1.67324,76.76294,50.00000,0.0000e+000,20.00000,    -0.10682,0.54822
824.29797, 93.64333,    -1.67867,76.74086,50.00000,0.0000e+000,20.00000,    -0.10751,0.54754
826.13098, 93.82333,    -1.68345,76.71579,50.00000,0.0000e+000,20.00000,    -0.10883,0.54687
827.94299, 94.00333,    -1.68481,76.70012,50.00000,0.0000e+000,20.00000,    -0.10965,0.54620
829.71698, 94.18333,    -1.68035,76.68279,50.00000,0.0000e+000,20.00000,    -0.10969,0.54556
831.47198, 94.36333,    -1.67464,76.66152,50.00000,0.0000e+000,20.00000,    -0.10951,0.54491
833.23297, 94.54333,    -1.67441,76.64000,50.00000,0.0000e+000,20.00000,    -0.11019,0.54427
835.06500, 94.72334,    -1.68152,76.62011,50.00000,0.0000e+000,20.00000,    -0.11034,0.54361
836.90399, 94.90334,    -1.69033,76.60038,50.00000,0.0000e+000,20.00000,    -0.10828,0.54294
838.67999, 95.08334,    -1.68931,76.58026,50.00000,0.0000e+000,20.00000,    -0.10794,0.54229
840.50000, 95.26334,    -1.69104,76.56065,50.00000,0.0000e+000,20.00000,    -0.10906,0.54164
842.38300, 95.44334,    -1.70149,76.54110,50.00000,0.0000e+000,20.00000,    -0.10871,0.54096
844.25702, 95.62334,    -1.70850,76.51791,50.00000,0.0000e+000,20.00000,    -0.10587,0.54028
846.07501, 95.80334,    -1.70864,76.49682,50.00000,0.0000e+000,20.00000,    -0.10661,0.53963
847.86499, 95.98333,    -1.70397,76.47968,50.00000,0.0000e+000,20.00000,    -0.10755,0.53898
849.66101, 96.16333,    -1.69971,76.46414,50.00000,0.0000e+000,20.00000,    -0.10461,0.53834
851.42902, 96.34333,    -1.69643,76.44092,50.00000,0.0000e+000,20.00000,    -0.10015,0.53771
853.20398, 96.52333,    -1.69567,76.42046,50.00000,0.0000e+000,20.00000,-9.7458e-002,0.53707
854.98798, 96.70333,    -1.69768,76.40772,50.00000,0.0000e+000,20.00000,-9.5090e-002,0.53643
856.77698, 96.88333,    -1.70024,76.39046,50.00000,0.0000e+000,20.00000,-9.4884e-002,0.53580
858.57098, 97.06333,    -1.70372,76.37003,50.00000,0.0000e+000,20.00000,-9.4281e-002,0.53516
860.38702, 97.24333,    -1.70482,76.35022,50.00000,0.0000e+000,20.00000,-9.1409e-002,0.53451
862.16998, 97.42333,    -1.70394,76.33445,50.00000,0.0000e+000,20.00000,-8.7439e-002,0.53388
863.94800, 97.60333,    -1.70587,76.31599,50.00000,0.0000e+000,20.00000,-8.5681e-002,0.53325
865.73999, 97.78333,    -1.70811,76.29517,50.00000,0.0000e+000,20.00000,-8.4204e-002,0.53261
867.55103, 97.96333,    -1.71216,76.28344,50.00000,0.0000e+000,20.00000,-8.3506e-002,0.53197
869.37097, 98.14333,    -1.71916,76.27827,50.00000,0.0000e+000,20.00000,-7.9634e-002,0.53133
871.19800, 98.32333,    -1.72317,76.26846,50.00000,0.0000e+000,20.00000,-7.4908e-002,0.53069
873.01300, 98.50333,    -1.72596,76.25806,50.00000,0.0000e+000,20.00000,-7.3113e-002,0.53005
874.83301, 98.68333,    -1.72620,76.23966,50.00000,0.0000e+000,20.00000,-7.0929e-002,0.52941
876.65100, 98.86333,    -1.72741,76.22118,50.00000,0.0000e+000,20.00000,-6.7469e-002,0.52877
878.45502, 99.04333,    -1.72834,76.21105,50.00000,0.0000e+000,20.00000,-6.4315e-002,0.52814
880.26300, 99.22334,    -1.73059,76.20379,50.00000,0.0000e+000,20.00000,-6.2882e-002,0.52750
882.07202, 99.40334,    -1.73204,76.18889,50.00000,0.0000e+000,20.00000,-6.1091e-002,0.52687
883.86700, 99.58334,    -1.73394,76.17606,50.00000,0.0000e+000,20.00000,-5.7702e-002,0.52624
885.67401, 99.76334,    -1.73594,76.16351,50.00000,0.0000e+000,20.00000,-5.5207e-002,0.52561
887.45398, 99.94334,    -1.73580,76.15449,50.00000,0.0000e+000,20.00000,-5.5327e-002,0.52499
889.25000,100.12334,    -1.73842,76.14981,50.00000,0.0000e+000,20.00000,-5.4476e-002,0.52436
891.04602,100.30334,    -1.73978,76.14377,50.00000,0.0000e+000,20.00000,-5.3990e-002,0.52373
892.85303,100.48333,    -1.74229,76.13534,50.00000,0.0000e+000,20.00000,-5.1398e-002,0.52310
894.64502,100.66333,    -1.74467,76.12789,50.00000,0.0000e+000,20.00000,-4.6971e-002,0.52248
896.44202,100.84333,    -1.74727,76.11926,50.00000,0.0000e+000,20.00000,-4.5139e-002,0.52186
898.23602,101.02333,    -1.75204,76.10887,50.00000,0.0000e+000,20.00000,-4.5279e-002,0.52123
900.04901,101.20333,    -1.75701,76.09742,50.00000,0.0000e+000,20.00000,-4.1990e-002,0.52060
901.86603,101.38333,    -1.76102,76.08812,50.00000,0.0000e+000,20.00000,-3.8854e-002,0.51997
903.68500,101.56333,    -1.76734,76.08344,50.00000,0.0000e+000,20.00000,-3.6377e-002,0.51934
905.50800,101.74333,    -1.77061,76.07786,50.00000,0.0000e+000,20.00000,-3.5620e-002,0.51871
907.35999,101.92333,    -1.77969,76.07209,50.00000,0.0000e+000,20.00000,-3.7160e-002,0.51807
909.18500,102.10333,    -1.78405,76.06393,50.00000,0.0000e+000,20.00000,-3.7209e-002,0.51744
910.97400,102.28333,    -1.78262,76.05588,50.00000,0.0000e+000,20.00000,-3.4730e-002,0.51682
912.79199,102.46333,    -1.78411,76.05226,50.00000,0.0000e+000,20.00000,-3.3989e-002,0.51619
914.57800,102.64333,    -1.78607,76.04815,50.00000,0.0000e+000,20.00000,-3.2866e-002,0.51557
916.36902,102.82333,    -1.78615,76.04072,50.00000,0.0000e+000,20.00000,-3.1026e-002,0.51496
918.16101,103.00333,    -1.78730,76.03787,50.00000,0.0000e+000,20.00000,-2.8346e-002,0.51434
919.97198,103.18333,    -1.79241,76.03635,50.00000,0.0000e+000,20.00000,-2.6671e-002,0.51371
921.80902,103.36333,    -1.80362,76.03308,50.00000,0.0000e+000,20.00000,-2.6044e-002,0.51308
923.63898,103.54333,    -1.81012,76.02668,50.00000,0.0000e+000,20.00000,-2.3906e-002,0.51245
925.47101,103.72334,    -1.81630,76.01628,50.00000,0.0000e+000,20.00000,-2.3179e-002,0.51182
927.29199,103.90334,    -1.81836,76.00907,50.00000,0.0000e+000,20.00000,-2.2360e-002,0.51119
929.09003,104.08334,    -1.81943,76.00984,50.00000,0.0000e+000,20.00000,-2.0363e-002,0.51057
930.88898,104.26334,    -1.82217,76.00572,50.00000,0.0000e+000,20.00000,-1.9521e-002,0.50995
932.69897,104.44334,    -1.82584,76.00100,50.00000,0.0000e+000,20.00000,-1.9808e-002,0.50933
934.51501,104.62334,    -1.83004,75.99774,50.00000,0.0000e+000,20.00000,-1.8994e-002,0.50870
936.31799,104.80334,    -1.83490,75.99569,50.00000,0.0000e+000,20.00000,-1.7459e-002,0.50808
938.11798,104.98333,    -1.83832,75.99250,50.00000,0.0000e+000,20.00000,-1.7843e-002,0.50746
939.91803,105.16333,    -1.84271,75.98896,50.00000,0.0000e+000,20.00000,-1.8387e-002,0.50684
941.75201,105.34333,    -1.85026,75.99097,50.00000,0.0000e+000,20.00000,-1.6340e-002,0.50621
943.56403,105.52333,    -1.85483,75.98938,50.00000,0.0000e+000,20.00000,-1.2989e-002,0.50558
945.33099,105.70333,    -1.85337,75.98394,50.00000,0.0000e+000,20.00000,-1.0757e-002,0.50498
947.12402,105.88333,    -1.85239,75.98256,50.00000,0.0000e+000,20.00000,-1.1318e-002,0.50436
948.90698,106.06333,    -1.85425,75.98159,50.00000,0.0000e+000,20.00000,-1.2402e-002,0.50375
950.68500,106.24333,    -1.85509,75.97766,50.00000,0.0000e+000,20.00000,-1.2721e-002,0.50313
952.46399,106.42333,    -1.85700,75.97247,50.00000,0.0000e+000,20.00000,-1.2794e-002,0.50252
954.25598,106.60333,    -1.86242,75.97390,50.00000,0.0000e+000,20.00000,-1.1819e-002,0.50190
956.04700,106.78333,    -1.86679,75.97246,50.00000,0.0000e+000,20.00000,-1.1174e-002,0.50129
957.83099,106.96333,    -1.87134,75.96679,50.00000,0.0000e+000,20.00000,-1.1541e-002,0.50067
959.62903,107.14333,    -1.87526,75.96770,50.00000,0.0000e+000,20.00000,-1.3247e-002,0.50005
961.42200,107.32333,    -1.88007,75.97040,50.00000,0.0000e+000,20.00000,-1.4004e-002,0.49943
963.22803,107.50333,    -1.88504,75.97023,50.00000,0.0000e+000,20.00000,-1.4732e-002,0.49881
965.05402,107.68333,    -1.88876,75.96908,50.00000,0.0000e+000,20.00000,-1.5024e-002,0.49818
966.85797,107.86333,    -1.89259,75.96249,50.00000,0.0000e+000,20.00000,-1.2911e-002,0.49756
968.67401,108.04333,    -1.89480,75.95585,50.00000,0.0000e+000,20.00000,-1.0344e-002,0.49693
970.48102,108.22334,    -1.89722,75.95169,50.00000,0.0000e+000,20.00000,-9.3842e-003,0.49631
972.28601,108.40334,    -1.89988,75.95242,50.00000,0.0000e+000,20.00000,-1.0794e-002,0.49569
974.07501,108.58334,    -1.90086,75.95275,50.00000,0.0000e+000,20.00000,-1.2838e-002,0.49507
975.89001,108.76334,    -1.90498,75.94802,50.00000,0.0000e+000,20.00000,-1.2188e-002,0.49444
977.71802,108.94334,    -1.90625,75.94255,50.00000,0.0000e+000,20.00000,-1.0641e-002,0.49381
979.51898,109.12334,    -1.90708,75.93978,50.00000,0.0000e+000,20.00000,-9.9462e-003,0.49319
981.30603,109.30334,    -1.90763,75.93202,50.00000,0.0000e+000,20.00000,-9.9636e-003,0.49257
983.10602,109.48333,    -1.90906,75.92734,50.00000,0.0000e+000,20.00000,-7.4276e-003,0.49194
984.92297,109.66333,    -1.91083,75.93337,50.00000,0.0000e+000,20.00000,-5.7919e-003,0.49131
986.72101,109.84333,    -1.91194,75.94028,50.00000,0.0000e+000,20.00000,-6.4417e-003,0.49069
988.54602,110.02333,    -1.91351,75.93935,50.00000,0.0000e+000,20.00000,-2.7167e-003,0.49006
990.35999,110.20333,    -1.91656,75.93473,50.00000,0.0000e+000,20.00000, 4.8138e-003,0.48943
992.17700,110.38333,    -1.91699,75.92774,50.00000,0.0000e+000,20.00000,-1.3012e-003,0.48880
993.96503,110.56333,    -1.91525,75.92245,50.00000,0.0000e+000,20.00000,-1.0330e-003,0.48818
995.75897,110.74333,    -1.91479,75.92744,50.00000,0.0000e+000,20.00000, 2.3330e-002,0.48755
997.56702,110.92333,    -1.91749,75.93278,50.00000,0.0000e+000,20.00000, 3.3669e-002,0.48692
998.37402,111.00333,    -1.91828,75.93605,50.00000,0.0000e+000,20.00000,-7.6657e-003,0.48664