File: book/some_content/TG_ExpDat_CEM_I_DC14; 30-1-2025-2.csv
#FILE:                       ,CEM_I_DC14; 30-1-2025.ngb-ds3
#FORMAT:                     ,NETZSCH5
#IDENTITY:                   ,OPC PASTE
#DECIMAL:                    ,POINT
#SEPARATOR:                  ,COMMA
#MTYPE:                      ,DSC
#INSTRUMENT:                 ,Microlab TU Delft
#PROJECT:                    ,
#DATE/TIME:                  ,1/02/2025 12:18:42 PM
#CORR. FILE:                 ,Blank with cover; 13-1-2025.ngb-bs3
#LABORATORY:                 ,TU Delft Micro Lab
#OPERATOR:                   ,Ahmed
#REMARK:                     ,under Argon atmosphere, 10K/min
#SAMPLE:                     ,CEM_I_DC14
#SAMPLE MASS /mg:            ,46.8
#MATERIAL:                   ,Geopolymer paste
#REFERENCE:                  ,blank
#REFERENCE MASS /mg:         ,0
#TYPE OF CRUCIBLE:           ,DSC/TG pan Al2O3
#SAMPLE CRUCIBLE MASS /mg:   ,0
#REFERENCE CRUCIBLE MASS /mg:,0
#CORR. CODE:                 ,020
#EXO:                        ,-1
#RANGE:                      ,40/10.0(K/min)/1000
#SEGMENT:                    ,S2/2

##Temp./øC,Time/min,DSC/(mW/mg),Mass/%,Gas Flow(purge1)/(ml/min),Gas Flow(purge2)/(ml/min),Gas Flow(protective)/(ml/min),DTG/(%/min),Sensit./(uV/mW)
 40.39900, 15.01917, 3.0999e-002,98.11917,50.00000,0.0000e+000,20.00000,    -0.10995,1.22639
 40.43700, 15.19917, 3.0814e-002,98.10546,50.00000,0.0000e+000,20.00000,-7.4550e-002,1.22634
 40.46800, 15.37917, 3.0815e-002,98.09314,50.00000,0.0000e+000,20.00000,-7.3251e-002,1.22630
 40.54600, 15.55917, 3.0858e-002,98.08093,50.00000,0.0000e+000,20.00000,-7.4952e-002,1.22619
 40.66500, 15.73917, 3.1500e-002,98.06750,50.00000,0.0000e+000,20.00000,-7.4727e-002,1.22603
 40.82600, 15.91917, 3.2344e-002,98.05278,50.00000,0.0000e+000,20.00000,-7.3734e-002,1.22580
 41.07000, 16.09917, 3.3816e-002,98.03908,50.00000,0.0000e+000,20.00000,-7.2692e-002,1.22547
 41.38500, 16.27917, 3.5917e-002,98.02599,50.00000,0.0000e+000,20.00000,-7.2875e-002,1.22503
 41.76200, 16.45917, 3.8515e-002,98.01247,50.00000,0.0000e+000,20.00000,-7.3466e-002,1.22451
 42.22100, 16.63917, 4.1385e-002,97.99937,50.00000,0.0000e+000,20.00000,-7.5014e-002,1.22388
 42.77000, 16.81917, 4.5156e-002,97.98723,50.00000,0.0000e+000,20.00000,-7.8442e-002,1.22312
 43.38000, 16.99917, 4.8962e-002,97.97546,50.00000,0.0000e+000,20.00000,-8.0320e-002,1.22228
 44.08800, 17.17917, 5.3366e-002,97.96307,50.00000,0.0000e+000,20.00000,-8.2897e-002,1.22131
 44.90500, 17.35917, 5.8251e-002,97.95019,50.00000,0.0000e+000,20.00000,-8.6446e-002,1.22018
 45.74900, 17.53917, 6.2988e-002,97.93654,50.00000,0.0000e+000,20.00000,-9.0552e-002,1.21902
 46.72100, 17.71917, 6.8466e-002,97.92283,50.00000,0.0000e+000,20.00000,-9.4917e-002,1.21768
 47.75600, 17.89917, 7.3907e-002,97.90867,50.00000,0.0000e+000,20.00000,-9.9977e-002,1.21625
 48.88200, 18.07917, 7.9638e-002,97.89371,50.00000,0.0000e+000,20.00000,    -0.10584,1.21470
 50.07500, 18.25917, 8.5592e-002,97.87740,50.00000,0.0000e+000,20.00000,    -0.11282,1.21306
 51.37400, 18.43917, 9.1869e-002,97.85918,50.00000,0.0000e+000,20.00000,    -0.12133,1.21127
 52.71700, 18.61917, 9.8453e-002,97.83834,50.00000,0.0000e+000,20.00000,    -0.13109,1.20942
 54.18200, 18.79917,     0.10503,97.81705,50.00000,0.0000e+000,20.00000,    -0.14234,1.20740
 55.69600, 18.97917,     0.11187,97.79552,50.00000,0.0000e+000,20.00000,    -0.15598,1.20532
 57.28000, 19.15917,     0.11907,97.77093,50.00000,0.0000e+000,20.00000,    -0.17252,1.20314
 58.96000, 19.33917,     0.12655,97.74316,50.00000,0.0000e+000,20.00000,    -0.19119,1.20083
 60.70700, 19.51917,     0.13408,97.71294,50.00000,0.0000e+000,20.00000,    -0.21074,1.19843
 62.49800, 19.69917,     0.14220,97.68070,50.00000,0.0000e+000,20.00000,    -0.23153,1.19597
 64.38000, 19.87917,     0.15076,97.64669,50.00000,0.0000e+000,20.00000,    -0.25470,1.19338
 66.29800, 20.05917,     0.15976,97.60852,50.00000,0.0000e+000,20.00000,    -0.28191,1.19075
 68.29100, 20.23917,     0.16948,97.56491,50.00000,0.0000e+000,20.00000,    -0.31193,1.18802
 70.32000, 20.41917,     0.17929,97.51748,50.00000,0.0000e+000,20.00000,    -0.34302,1.18524
 72.40500, 20.59917,     0.19042,97.46560,50.00000,0.0000e+000,20.00000,    -0.37732,1.18238
 74.53300, 20.77917,     0.20195,97.40514,50.00000,0.0000e+000,20.00000,    -0.41359,1.17947
 76.72800, 20.95917,     0.21420,97.33354,50.00000,0.0000e+000,20.00000,    -0.45157,1.17646
 78.94200, 21.13917,     0.22790,97.25265,50.00000,0.0000e+000,20.00000,    -0.49093,1.17343
 81.19000, 21.31917,     0.24167,97.16787,50.00000,0.0000e+000,20.00000,    -0.53205,1.17036
 83.49000, 21.49917,     0.25699,97.07895,50.00000,0.0000e+000,20.00000,    -0.57512,1.16722
 85.82500, 21.67917,     0.27279,96.98113,50.00000,0.0000e+000,20.00000,    -0.62071,1.16404
 88.18700, 21.85917,     0.28999,96.86860,50.00000,0.0000e+000,20.00000,    -0.66820,1.16082
 90.56300, 22.03917,     0.30816,96.74156,50.00000,0.0000e+000,20.00000,    -0.71752,1.15759
 92.95000, 22.21917,     0.32694,96.60947,50.00000,0.0000e+000,20.00000,    -0.77007,1.15434
 95.38300, 22.39917,     0.34671,96.46399,50.00000,0.0000e+000,20.00000,    -0.82621,1.15103
 97.84000, 22.57917,     0.36723,96.31142,50.00000,0.0000e+000,20.00000,    -0.88521,1.14770
100.28300, 22.75917,     0.38796,96.14984,50.00000,0.0000e+000,20.00000,    -0.94579,1.14439
102.73900, 22.93917,     0.40953,95.97995,50.00000,0.0000e+000,20.00000,    -1.00726,1.14107
105.20700, 23.11917,     0.43071,95.80121,50.00000,0.0000e+000,20.00000,    -1.07010,1.13773
107.66400, 23.29917,     0.45230,95.61326,50.00000,0.0000e+000,20.00000,    -1.13404,1.13441
110.12200, 23.47917,     0.47468,95.41472,50.00000,0.0000e+000,20.00000,    -1.19542,1.13110
112.57700, 23.65917,     0.49842,95.20539,50.00000,0.0000e+000,20.00000,    -1.25037,1.12779
115.03200, 23.83917,     0.52488,94.98438,50.00000,0.0000e+000,20.00000,    -1.29548,1.12449
117.47900, 24.01917,     0.55438,94.74795,50.00000,0.0000e+000,20.00000,    -1.33125,1.12120
119.91400, 24.19917,     0.58681,94.49455,50.00000,0.0000e+000,20.00000,    -1.35401,1.11794
122.34700, 24.37917,     0.62090,94.22273,50.00000,0.0000e+000,20.00000,    -1.36826,1.11468
124.76500, 24.55917,     0.65590,93.93383,50.00000,0.0000e+000,20.00000,    -1.37587,1.11145
127.18900, 24.73917,     0.69006,93.63101,50.00000,0.0000e+000,20.00000,    -1.37762,1.10821
129.59900, 24.91917,     0.72230,93.31839,50.00000,0.0000e+000,20.00000,    -1.37398,1.10500
131.97301, 25.09917,     0.75007,92.99737,50.00000,0.0000e+000,20.00000,    -1.36556,1.10184
134.36000, 25.27917,     0.77108,92.67608,50.00000,0.0000e+000,20.00000,    -1.35249,1.09867
136.73199, 25.45917,     0.78098,92.36332,50.00000,0.0000e+000,20.00000,    -1.33470,1.09552
139.07700, 25.63917,     0.77558,92.06886,50.00000,0.0000e+000,20.00000,    -1.31187,1.09242
141.44299, 25.81917,     0.75476,91.80244,50.00000,0.0000e+000,20.00000,    -1.28321,1.08929
143.79601, 25.99917,     0.71923,91.57056,50.00000,0.0000e+000,20.00000,    -1.24768,1.08619
146.11000, 26.17917,     0.67738,91.36423,50.00000,0.0000e+000,20.00000,    -1.20663,1.08314
148.45000, 26.35917,     0.63543,91.17410,50.00000,0.0000e+000,20.00000,    -1.15997,1.08006
150.77299, 26.53917,     0.59497,90.99712,50.00000,0.0000e+000,20.00000,    -1.10838,1.07701
153.10001, 26.71917,     0.55714,90.83170,50.00000,0.0000e+000,20.00000,    -1.05320,1.07396
155.40100, 26.89917,     0.52221,90.67473,50.00000,0.0000e+000,20.00000,    -0.99343,1.07095
157.68500, 27.07917,     0.48921,90.52484,50.00000,0.0000e+000,20.00000,    -0.93214,1.06797
159.93700, 27.25917,     0.45872,90.38097,50.00000,0.0000e+000,20.00000,    -0.87270,1.06504
162.18600, 27.43917,     0.43053,90.24452,50.00000,0.0000e+000,20.00000,    -0.81702,1.06212
164.40601, 27.61917,     0.40442,90.11408,50.00000,0.0000e+000,20.00000,    -0.76787,1.05924
166.60600, 27.79917,     0.38015,89.99238,50.00000,0.0000e+000,20.00000,    -0.72754,1.05639
168.79500, 27.97917,     0.35758,89.87320,50.00000,0.0000e+000,20.00000,    -0.69415,1.05356
170.94600, 28.15917,     0.33651,89.75674,50.00000,0.0000e+000,20.00000,    -0.66504,1.05078
173.06300, 28.33917,     0.31643,89.64380,50.00000,0.0000e+000,20.00000,    -0.63851,1.04806
175.17400, 28.51917,     0.29730,89.53370,50.00000,0.0000e+000,20.00000,    -0.61439,1.04534
177.26801, 28.69917,     0.27934,89.43068,50.00000,0.0000e+000,20.00000,    -0.59216,1.04266
179.32001, 28.87917,     0.26174,89.33288,50.00000,0.0000e+000,20.00000,    -0.57166,1.04003
181.37900, 29.05917,     0.24502,89.23515,50.00000,0.0000e+000,20.00000,    -0.55179,1.03740
183.42101, 29.23917,     0.22936,89.14037,50.00000,0.0000e+000,20.00000,    -0.53207,1.03480
185.40199, 29.41917,     0.21478,89.04826,50.00000,0.0000e+000,20.00000,    -0.51337,1.03227
187.41100, 29.59917,     0.20101,88.95841,50.00000,0.0000e+000,20.00000,    -0.49665,1.02972
189.36900, 29.77917,     0.18849,88.87074,50.00000,0.0000e+000,20.00000,    -0.47990,1.02724
191.33000, 29.95917,     0.17628,88.78448,50.00000,0.0000e+000,20.00000,    -0.46313,1.02476
193.24899, 30.13917,     0.16373,88.70183,50.00000,0.0000e+000,20.00000,    -0.44747,1.02234
195.19600, 30.31917,     0.15091,88.62274,50.00000,0.0000e+000,20.00000,    -0.43225,1.01988
197.11301, 30.49917,     0.13795,88.54550,50.00000,0.0000e+000,20.00000,    -0.41845,1.01747
198.97000, 30.67917,     0.12499,88.46950,50.00000,0.0000e+000,20.00000,    -0.40606,1.01514
200.86600, 30.85917,     0.11264,88.39620,50.00000,0.0000e+000,20.00000,    -0.39252,1.01277
202.72000, 31.03917,     0.10001,88.33005,50.00000,0.0000e+000,20.00000,    -0.37959,1.01045
204.57100, 31.21917, 8.8388e-002,88.26668,50.00000,0.0000e+000,20.00000,    -0.36719,1.00814
206.41800, 31.39917, 7.6872e-002,88.20464,50.00000,0.0000e+000,20.00000,    -0.35534,1.00584
208.24500, 31.57917, 6.5610e-002,88.14589,50.00000,0.0000e+000,20.00000,    -0.34385,1.00357
210.06000, 31.75917, 5.5224e-002,88.09011,50.00000,0.0000e+000,20.00000,    -0.33241,1.00132
211.87100, 31.93917, 4.5100e-002,88.03390,50.00000,0.0000e+000,20.00000,    -0.32182,0.99908
213.67700, 32.11917, 3.5095e-002,87.97870,50.00000,0.0000e+000,20.00000,    -0.31162,0.99685
215.46001, 32.29917, 2.5797e-002,87.92465,50.00000,0.0000e+000,20.00000,    -0.30144,0.99466
217.24100, 32.47917, 1.7099e-002,87.87148,50.00000,0.0000e+000,20.00000,    -0.29154,0.99247
219.01100, 32.65917, 8.2145e-003,87.82257,50.00000,0.0000e+000,20.00000,    -0.28231,0.99030
220.78000, 32.83917,-1.3198e-004,87.77454,50.00000,0.0000e+000,20.00000,    -0.27509,0.98813
222.55200, 33.01917,-8.1679e-003,87.72728,50.00000,0.0000e+000,20.00000,    -0.26840,0.98596
224.30200, 33.19917,-1.5874e-002,87.68035,50.00000,0.0000e+000,20.00000,    -0.26204,0.98383
226.05000, 33.37917,-2.3846e-002,87.63422,50.00000,0.0000e+000,20.00000,    -0.25588,0.98170
227.79100, 33.55917,-3.1336e-002,87.58932,50.00000,0.0000e+000,20.00000,    -0.25038,0.97959
229.53200, 33.73917,-3.8826e-002,87.54467,50.00000,0.0000e+000,20.00000,    -0.24450,0.97748
231.25800, 33.91917,-4.5878e-002,87.50195,50.00000,0.0000e+000,20.00000,    -0.23890,0.97539
232.98801, 34.09917,-5.3112e-002,87.46158,50.00000,0.0000e+000,20.00000,    -0.23400,0.97331
234.72800, 34.27917,-5.9756e-002,87.42157,50.00000,0.0000e+000,20.00000,    -0.22895,0.97121
236.44501, 34.45917,-6.6225e-002,87.38133,50.00000,0.0000e+000,20.00000,    -0.22505,0.96915
238.17799, 34.63917,-7.2890e-002,87.34055,50.00000,0.0000e+000,20.00000,    -0.22128,0.96707
239.88200, 34.81917,-7.9210e-002,87.30120,50.00000,0.0000e+000,20.00000,    -0.21785,0.96504
241.60300, 34.99917,-8.5118e-002,87.26214,50.00000,0.0000e+000,20.00000,    -0.21451,0.96298
243.34200, 35.17916,-9.1579e-002,87.22484,50.00000,0.0000e+000,20.00000,    -0.21095,0.96091
245.04100, 35.35917,-9.7739e-002,87.18892,50.00000,0.0000e+000,20.00000,    -0.20717,0.95889
246.78200, 35.53917,    -0.10349,87.15407,50.00000,0.0000e+000,20.00000,    -0.20322,0.95683
248.49001, 35.71917,    -0.10937,87.11933,50.00000,0.0000e+000,20.00000,    -0.19992,0.95481
250.20799, 35.89917,    -0.11484,87.08313,50.00000,0.0000e+000,20.00000,    -0.19729,0.95278
251.93600, 36.07917,    -0.12013,87.04789,50.00000,0.0000e+000,20.00000,    -0.19512,0.95075
253.64500, 36.25917,    -0.12569,87.01265,50.00000,0.0000e+000,20.00000,    -0.19279,0.94874
255.36000, 36.43917,    -0.13109,86.97828,50.00000,0.0000e+000,20.00000,    -0.19017,0.94673
257.09201, 36.61917,    -0.13695,86.94360,50.00000,0.0000e+000,20.00000,    -0.18787,0.94471
258.79901, 36.79917,    -0.14251,86.90871,50.00000,0.0000e+000,20.00000,    -0.18576,0.94272
260.51099, 36.97917,    -0.14867,86.87512,50.00000,0.0000e+000,20.00000,    -0.18404,0.94073
262.24500, 37.15917,    -0.15411,86.84355,50.00000,0.0000e+000,20.00000,    -0.18255,0.93872
263.97501, 37.33917,    -0.16022,86.81339,50.00000,0.0000e+000,20.00000,    -0.18117,0.93671
265.70099, 37.51917,    -0.16626,86.78232,50.00000,0.0000e+000,20.00000,    -0.17961,0.93472
267.42599, 37.69917,    -0.17203,86.75139,50.00000,0.0000e+000,20.00000,    -0.17732,0.93273
269.15201, 37.87917,    -0.17783,86.71947,50.00000,0.0000e+000,20.00000,    -0.17535,0.93075
270.88199, 38.05917,    -0.18360,86.68763,50.00000,0.0000e+000,20.00000,    -0.17359,0.92877
272.61899, 38.23917,    -0.18967,86.65646,50.00000,0.0000e+000,20.00000,    -0.17188,0.92678
274.36301, 38.41917,    -0.19518,86.62523,50.00000,0.0000e+000,20.00000,    -0.17043,0.92479
276.09698, 38.59917,    -0.20072,86.59395,50.00000,0.0000e+000,20.00000,    -0.16913,0.92282
277.83301, 38.77917,    -0.20628,86.56247,50.00000,0.0000e+000,20.00000,    -0.16816,0.92085
279.55499, 38.95917,    -0.21179,86.53180,50.00000,0.0000e+000,20.00000,    -0.16728,0.91890
281.32101, 39.13917,    -0.21778,86.50167,50.00000,0.0000e+000,20.00000,    -0.16655,0.91691
283.04901, 39.31917,    -0.22291,86.47257,50.00000,0.0000e+000,20.00000,    -0.16588,0.91496
284.80600, 39.49917,    -0.22784,86.44477,50.00000,0.0000e+000,20.00000,    -0.16543,0.91299
286.54501, 39.67916,    -0.23323,86.41668,50.00000,0.0000e+000,20.00000,    -0.16429,0.91104
288.27899, 39.85917,    -0.23837,86.38794,50.00000,0.0000e+000,20.00000,    -0.16302,0.90910
290.01199, 40.03917,    -0.24364,86.35958,50.00000,0.0000e+000,20.00000,    -0.16198,0.90717
291.76401, 40.21917,    -0.24877,86.33062,50.00000,0.0000e+000,20.00000,    -0.16045,0.90523
293.50000, 40.39917,    -0.25396,86.30042,50.00000,0.0000e+000,20.00000,    -0.15867,0.90330
295.25800, 40.57917,    -0.25921,86.27008,50.00000,0.0000e+000,20.00000,    -0.15715,0.90136
296.99500, 40.75917,    -0.26442,86.24109,50.00000,0.0000e+000,20.00000,    -0.15595,0.89945
298.74701, 40.93917,    -0.27002,86.21353,50.00000,0.0000e+000,20.00000,    -0.15487,0.89752
300.50500, 41.11917,    -0.27557,86.18526,50.00000,0.0000e+000,20.00000,    -0.15404,0.89560
302.25299, 41.29917,    -0.28110,86.15586,50.00000,0.0000e+000,20.00000,    -0.15334,0.89369
304.01700, 41.47917,    -0.28653,86.12805,50.00000,0.0000e+000,20.00000,    -0.15274,0.89177
305.77899, 41.65917,    -0.29162,86.10084,50.00000,0.0000e+000,20.00000,    -0.15204,0.88985
307.55099, 41.83917,    -0.29689,86.07328,50.00000,0.0000e+000,20.00000,    -0.15127,0.88793
309.30899, 42.01917,    -0.30141,86.04734,50.00000,0.0000e+000,20.00000,    -0.15041,0.88603
311.07101, 42.19917,    -0.30678,86.02263,50.00000,0.0000e+000,20.00000,    -0.14919,0.88413
312.83801, 42.37917,    -0.31160,85.99690,50.00000,0.0000e+000,20.00000,    -0.14780,0.88224
314.60300, 42.55917,    -0.31664,85.97042,50.00000,0.0000e+000,20.00000,    -0.14678,0.88035
316.37201, 42.73917,    -0.32144,85.94423,50.00000,0.0000e+000,20.00000,    -0.14634,0.87846
318.14301, 42.91917,    -0.32605,85.91785,50.00000,0.0000e+000,20.00000,    -0.14594,0.87657
319.90302, 43.09917,    -0.33033,85.89241,50.00000,0.0000e+000,20.00000,    -0.14517,0.87470
321.67999, 43.27917,    -0.33500,85.86676,50.00000,0.0000e+000,20.00000,    -0.14470,0.87282
323.43500, 43.45917,    -0.33927,85.84059,50.00000,0.0000e+000,20.00000,    -0.14450,0.87097
325.19699, 43.63917,    -0.34361,85.81488,50.00000,0.0000e+000,20.00000,    -0.14420,0.86912
326.95001, 43.81917,    -0.34774,85.78935,50.00000,0.0000e+000,20.00000,    -0.14429,0.86728
328.70599, 43.99917,    -0.35174,85.76366,50.00000,0.0000e+000,20.00000,    -0.14481,0.86545
330.48801, 44.17916,    -0.35642,85.73836,50.00000,0.0000e+000,20.00000,    -0.14530,0.86359
332.26001, 44.35917,    -0.36237,85.71284,50.00000,0.0000e+000,20.00000,    -0.14556,0.86175
334.03799, 44.53917,    -0.36815,85.68686,50.00000,0.0000e+000,20.00000,    -0.14590,0.85991
335.82101, 44.71917,    -0.37353,85.66039,50.00000,0.0000e+000,20.00000,    -0.14650,0.85807
337.61301, 44.89917,    -0.37832,85.63373,50.00000,0.0000e+000,20.00000,    -0.14750,0.85622
339.41699, 45.07917,    -0.38234,85.60733,50.00000,0.0000e+000,20.00000,    -0.14856,0.85437
341.20801, 45.25917,    -0.38609,85.58096,50.00000,0.0000e+000,20.00000,    -0.14980,0.85254
342.97800, 45.43917,    -0.38934,85.55442,50.00000,0.0000e+000,20.00000,    -0.15155,0.85073
344.76599, 45.61917,    -0.39277,85.52785,50.00000,0.0000e+000,20.00000,    -0.15296,0.84892
346.56000, 45.79917,    -0.39625,85.50126,50.00000,0.0000e+000,20.00000,    -0.15409,0.84710
348.34399, 45.97917,    -0.39898,85.47403,50.00000,0.0000e+000,20.00000,    -0.15555,0.84530
350.13199, 46.15917,    -0.40298,85.44660,50.00000,0.0000e+000,20.00000,    -0.15754,0.84350
351.92099, 46.33917,    -0.40727,85.41924,50.00000,0.0000e+000,20.00000,    -0.15907,0.84171
353.69000, 46.51917,    -0.41013,85.39086,50.00000,0.0000e+000,20.00000,    -0.16040,0.83994
355.47299, 46.69917,    -0.41261,85.36161,50.00000,0.0000e+000,20.00000,    -0.16171,0.83816
357.23999, 46.87917,    -0.41517,85.33229,50.00000,0.0000e+000,20.00000,    -0.16307,0.83641
359.02100, 47.05917,    -0.41796,85.30188,50.00000,0.0000e+000,20.00000,    -0.16434,0.83464
360.79800, 47.23917,    -0.42045,85.26974,50.00000,0.0000e+000,20.00000,    -0.16533,0.83289
362.56699, 47.41917,    -0.42394,85.23876,50.00000,0.0000e+000,20.00000,    -0.16625,0.83115
364.34100, 47.59917,    -0.42707,85.20892,50.00000,0.0000e+000,20.00000,    -0.16702,0.82941
366.11700, 47.77917,    -0.43101,85.17852,50.00000,0.0000e+000,20.00000,    -0.16777,0.82768
367.89499, 47.95917,    -0.43428,85.14592,50.00000,0.0000e+000,20.00000,    -0.16849,0.82595
369.67599, 48.13917,    -0.43771,85.11419,50.00000,0.0000e+000,20.00000,    -0.16899,0.82422
371.45401, 48.31917,    -0.44116,85.08301,50.00000,0.0000e+000,20.00000,    -0.16915,0.82250
373.24399, 48.49917,    -0.44477,85.05154,50.00000,0.0000e+000,20.00000,    -0.16891,0.82077
375.03299, 48.67916,    -0.44845,85.02012,50.00000,0.0000e+000,20.00000,    -0.16864,0.81906
376.80600, 48.85917,    -0.45215,84.98898,50.00000,0.0000e+000,20.00000,    -0.16813,0.81736
378.57501, 49.03917,    -0.45600,84.95878,50.00000,0.0000e+000,20.00000,    -0.16692,0.81567
380.35901, 49.21917,    -0.46026,84.92877,50.00000,0.0000e+000,20.00000,    -0.16570,0.81398
382.14001, 49.39917,    -0.46440,84.89941,50.00000,0.0000e+000,20.00000,    -0.16481,0.81229
383.93600, 49.57917,    -0.46956,84.86962,50.00000,0.0000e+000,20.00000,    -0.16369,0.81060
385.71301, 49.75917,    -0.47440,84.83950,50.00000,0.0000e+000,20.00000,    -0.16174,0.80893
387.50500, 49.93917,    -0.48009,84.81018,50.00000,0.0000e+000,20.00000,    -0.16011,0.80725
389.27200, 50.11917,    -0.48512,84.78141,50.00000,0.0000e+000,20.00000,    -0.15858,0.80560
391.04401, 50.29917,    -0.49076,84.75303,50.00000,0.0000e+000,20.00000,    -0.15663,0.80395
392.84201, 50.47917,    -0.49716,84.72474,50.00000,0.0000e+000,20.00000,    -0.15506,0.80228
394.61899, 50.65917,    -0.50244,84.69644,50.00000,0.0000e+000,20.00000,    -0.15356,0.80064
396.39001, 50.83917,    -0.50768,84.66872,50.00000,0.0000e+000,20.00000,    -0.15209,0.79901
398.18399, 51.01917,    -0.51274,84.64182,50.00000,0.0000e+000,20.00000,    -0.15072,0.79737
399.97198, 51.19917,    -0.51772,84.61515,50.00000,0.0000e+000,20.00000,    -0.14944,0.79573
401.76001, 51.37917,    -0.52314,84.58890,50.00000,0.0000e+000,20.00000,    -0.14797,0.79411
403.53400, 51.55917,    -0.52866,84.56370,50.00000,0.0000e+000,20.00000,    -0.14626,0.79250
405.33200, 51.73917,    -0.53397,84.53772,50.00000,0.0000e+000,20.00000,    -0.14536,0.79087
407.11200, 51.91917,    -0.53890,84.51198,50.00000,0.0000e+000,20.00000,    -0.14479,0.78927
408.90100, 52.09917,    -0.54414,84.48761,50.00000,0.0000e+000,20.00000,    -0.14387,0.78767
410.67899, 52.27917,    -0.54829,84.46221,50.00000,0.0000e+000,20.00000,    -0.14347,0.78608
412.47299, 52.45917,    -0.55377,84.43627,50.00000,0.0000e+000,20.00000,    -0.14327,0.78448
414.26999, 52.63917,    -0.55893,84.41128,50.00000,0.0000e+000,20.00000,    -0.14332,0.78289
416.07501, 52.81917,    -0.56454,84.38627,50.00000,0.0000e+000,20.00000,    -0.14426,0.78129
417.88101, 52.99917,    -0.57002,84.36144,50.00000,0.0000e+000,20.00000,    -0.14656,0.77970
419.67200, 53.17916,    -0.57442,84.33704,50.00000,0.0000e+000,20.00000,    -0.15101,0.77813
421.45401, 53.35917,    -0.57895,84.31323,50.00000,0.0000e+000,20.00000,    -0.15786,0.77658
423.24500, 53.53917,    -0.58270,84.28749,50.00000,0.0000e+000,20.00000,    -0.16598,0.77502
425.03601, 53.71917,    -0.58648,84.26050,50.00000,0.0000e+000,20.00000,    -0.17518,0.77346
426.81201, 53.89917,    -0.59008,84.23539,50.00000,0.0000e+000,20.00000,    -0.18629,0.77193
428.59201, 54.07917,    -0.59300,84.20892,50.00000,0.0000e+000,20.00000,    -0.19824,0.77040
430.38101, 54.25917,    -0.59461,84.18128,50.00000,0.0000e+000,20.00000,    -0.21086,0.76887
432.16199, 54.43917,    -0.59407,84.15348,50.00000,0.0000e+000,20.00000,    -0.22518,0.76735
433.94400, 54.61917,    -0.58969,84.12348,50.00000,0.0000e+000,20.00000,    -0.24117,0.76583
435.72101, 54.79917,    -0.58102,84.08935,50.00000,0.0000e+000,20.00000,    -0.25850,0.76433
437.49399, 54.97917,    -0.56852,84.04794,50.00000,0.0000e+000,20.00000,    -0.27721,0.76283
439.27600, 55.15917,    -0.55360,83.99873,50.00000,0.0000e+000,20.00000,    -0.29922,0.76133
441.05301, 55.33917,    -0.53737,83.94375,50.00000,0.0000e+000,20.00000,    -0.32382,0.75984
442.83600, 55.51917,    -0.51957,83.88501,50.00000,0.0000e+000,20.00000,    -0.34614,0.75836
444.61499, 55.69917,    -0.50179,83.82064,50.00000,0.0000e+000,20.00000,    -0.37130,0.75688
446.39200, 55.87917,    -0.48338,83.75237,50.00000,0.0000e+000,20.00000,    -0.39693,0.75541
448.17300, 56.05917,    -0.46508,83.68076,50.00000,0.0000e+000,20.00000,    -0.42404,0.75394
449.93900, 56.23917,    -0.44665,83.60429,50.00000,0.0000e+000,20.00000,    -0.45258,0.75249
451.72501, 56.41917,    -0.42790,83.52172,50.00000,0.0000e+000,20.00000,    -0.48162,0.75103
453.50900, 56.59917,    -0.40831,83.43412,50.00000,0.0000e+000,20.00000,    -0.51011,0.74958
455.29501, 56.77917,    -0.38988,83.34220,50.00000,0.0000e+000,20.00000,    -0.53749,0.74813
457.10901, 56.95917,    -0.37335,83.24029,50.00000,0.0000e+000,20.00000,    -0.56348,0.74666
458.91599, 57.13917,    -0.35422,83.12534,50.00000,0.0000e+000,20.00000,    -0.58805,0.74521
460.70401, 57.31917,    -0.33403,83.01612,50.00000,0.0000e+000,20.00000,    -0.61149,0.74378
462.50000, 57.49917,    -0.31320,82.90050,50.00000,0.0000e+000,20.00000,    -0.63345,0.74234
464.26501, 57.67916,    -0.29175,82.78091,50.00000,0.0000e+000,20.00000,    -0.65414,0.74094
466.04001, 57.85917,    -0.27092,82.65538,50.00000,0.0000e+000,20.00000,    -0.67211,0.73953
467.81500, 58.03917,    -0.25047,82.52415,50.00000,0.0000e+000,20.00000,    -0.68467,0.73813
469.57101, 58.21917,    -0.23233,82.38875,50.00000,0.0000e+000,20.00000,    -0.68852,0.73675
471.34399, 58.39917,    -0.21626,82.25170,50.00000,0.0000e+000,20.00000,    -0.68365,0.73537
473.12601, 58.57917,    -0.20316,82.11186,50.00000,0.0000e+000,20.00000,    -0.67136,0.73398
474.90100, 58.75917,    -0.19322,81.96918,50.00000,0.0000e+000,20.00000,    -0.65327,0.73260
476.69299, 58.93917,    -0.18661,81.82507,50.00000,0.0000e+000,20.00000,    -0.62965,0.73122
478.48401, 59.11917,    -0.18258,81.68124,50.00000,0.0000e+000,20.00000,    -0.60647,0.72984
480.29099, 59.29917,    -0.18120,81.53759,50.00000,0.0000e+000,20.00000,    -0.58192,0.72845
482.08701, 59.47917,    -0.18305,81.39375,50.00000,0.0000e+000,20.00000,    -0.55536,0.72708
483.90701, 59.65917,    -0.19362,81.25557,50.00000,0.0000e+000,20.00000,    -0.52719,0.72570
485.69901, 59.83917,    -0.22349,81.13089,50.00000,0.0000e+000,20.00000,    -0.49652,0.72434
487.51099, 60.01917,    -0.28758,81.03100,50.00000,0.0000e+000,20.00000,    -0.46443,0.72298
489.32199, 60.19917,    -0.38475,80.95785,50.00000,0.0000e+000,20.00000,    -0.43178,0.72162
491.15399, 60.37917,    -0.48025,80.90878,50.00000,0.0000e+000,20.00000,    -0.39817,0.72025
492.98901, 60.55917,    -0.55509,80.87383,50.00000,0.0000e+000,20.00000,    -0.36302,0.71889
494.82700, 60.73917,    -0.61121,80.84555,50.00000,0.0000e+000,20.00000,    -0.32708,0.71752
496.64899, 60.91917,    -0.65263,80.81980,50.00000,0.0000e+000,20.00000,    -0.29160,0.71618
498.48099, 61.09917,    -0.68355,80.79548,50.00000,0.0000e+000,20.00000,    -0.25628,0.71483
500.30301, 61.27917,    -0.70747,80.77283,50.00000,0.0000e+000,20.00000,    -0.22051,0.71350
502.11700, 61.45917,    -0.72524,80.75121,50.00000,0.0000e+000,20.00000,    -0.18572,0.71218
503.92099, 61.63917,    -0.73898,80.73244,50.00000,0.0000e+000,20.00000,    -0.15407,0.71087
505.72800, 61.81917,    -0.74950,80.71477,50.00000,0.0000e+000,20.00000,    -0.12853,0.70957
507.52600, 61.99917,    -0.75879,80.69725,50.00000,0.0000e+000,20.00000,    -0.10982,0.70828
509.32501, 62.17916,    -0.76686,80.68052,50.00000,0.0000e+000,20.00000,-9.8158e-002,0.70699
511.10501, 62.35917,    -0.77489,80.66618,50.00000,0.0000e+000,20.00000,-9.1361e-002,0.70572
512.89801, 62.53917,    -0.78196,80.65368,50.00000,0.0000e+000,20.00000,-8.6883e-002,0.70445
514.69000, 62.71917,    -0.78812,80.63954,50.00000,0.0000e+000,20.00000,-8.2985e-002,0.70318
516.46399, 62.89917,    -0.79289,80.62509,50.00000,0.0000e+000,20.00000,-7.9262e-002,0.70193
518.24902, 63.07917,    -0.79868,80.61149,50.00000,0.0000e+000,20.00000,-7.6101e-002,0.70068
520.04102, 63.25917,    -0.80409,80.59914,50.00000,0.0000e+000,20.00000,-7.2903e-002,0.69943
521.84399, 63.43917,    -0.81023,80.58720,50.00000,0.0000e+000,20.00000,-7.0271e-002,0.69818
523.64600, 63.61917,    -0.81530,80.57629,50.00000,0.0000e+000,20.00000,-6.8058e-002,0.69693
525.44397, 63.79917,    -0.81982,80.56728,50.00000,0.0000e+000,20.00000,-6.5807e-002,0.69570
527.21100, 63.97917,    -0.82374,80.55796,50.00000,0.0000e+000,20.00000,-6.3823e-002,0.69448
529.01703, 64.15916,    -0.82732,80.54659,50.00000,0.0000e+000,20.00000,-6.2411e-002,0.69325
530.79602, 64.33916,    -0.83086,80.53398,50.00000,0.0000e+000,20.00000,-6.1780e-002,0.69204
532.56201, 64.51917,    -0.83535,80.52205,50.00000,0.0000e+000,20.00000,-6.0753e-002,0.69085
534.37598, 64.69917,    -0.84042,80.51108,50.00000,0.0000e+000,20.00000,-5.9578e-002,0.68962
536.17798, 64.87917,    -0.84658,80.49977,50.00000,0.0000e+000,20.00000,-5.8414e-002,0.68841
537.99402, 65.05917,    -0.85230,80.48937,50.00000,0.0000e+000,20.00000,-5.7497e-002,0.68720
539.78601, 65.23917,    -0.85635,80.47980,50.00000,0.0000e+000,20.00000,-5.6746e-002,0.68601
541.59003, 65.41917,    -0.85989,80.47017,50.00000,0.0000e+000,20.00000,-5.6289e-002,0.68481
543.37598, 65.59917,    -0.86256,80.46080,50.00000,0.0000e+000,20.00000,-5.6585e-002,0.68364
545.16699, 65.77917,    -0.86520,80.45120,50.00000,0.0000e+000,20.00000,-5.6805e-002,0.68246
546.95001, 65.95917,    -0.86857,80.44153,50.00000,0.0000e+000,20.00000,-5.6183e-002,0.68130
548.73798, 66.13917,    -0.87207,80.43144,50.00000,0.0000e+000,20.00000,-5.5075e-002,0.68013
550.54999, 66.31917,    -0.87629,80.42127,50.00000,0.0000e+000,20.00000,-5.4043e-002,0.67896
552.36499, 66.49917,    -0.88066,80.41104,50.00000,0.0000e+000,20.00000,-5.3274e-002,0.67779
554.15002, 66.67917,    -0.88444,80.40138,50.00000,0.0000e+000,20.00000,-5.2358e-002,0.67664
555.96698, 66.85917,    -0.88860,80.39225,50.00000,0.0000e+000,20.00000,-5.1557e-002,0.67548
557.77802, 67.03917,    -0.89253,80.38297,50.00000,0.0000e+000,20.00000,-5.1248e-002,0.67433
559.58899, 67.21917,    -0.89522,80.37364,50.00000,0.0000e+000,20.00000,-5.1162e-002,0.67318
561.37799, 67.39917,    -0.89711,80.36333,50.00000,0.0000e+000,20.00000,-5.1003e-002,0.67205
563.16998, 67.57917,    -0.89866,80.35335,50.00000,0.0000e+000,20.00000,-5.0572e-002,0.67093
564.96698, 67.75916,    -0.90134,80.34437,50.00000,0.0000e+000,20.00000,-4.9798e-002,0.66980
566.76599, 67.93916,    -0.90560,80.33593,50.00000,0.0000e+000,20.00000,-4.9230e-002,0.66868
568.55701, 68.11916,    -0.90852,80.32750,50.00000,0.0000e+000,20.00000,-4.8978e-002,0.66757
570.36298, 68.29916,    -0.91222,80.31932,50.00000,0.0000e+000,20.00000,-4.8410e-002,0.66646
572.16101, 68.47916,    -0.91616,80.31127,50.00000,0.0000e+000,20.00000,-4.7631e-002,0.66535
573.97900, 68.65916,    -0.91885,80.30365,50.00000,0.0000e+000,20.00000,-4.7370e-002,0.66424
575.77301, 68.83916,    -0.92255,80.29531,50.00000,0.0000e+000,20.00000,-4.7333e-002,0.66315
577.57300, 69.01917,    -0.92552,80.28607,50.00000,0.0000e+000,20.00000,-4.6977e-002,0.66206
579.38898, 69.19917,    -0.92847,80.27709,50.00000,0.0000e+000,20.00000,-4.6148e-002,0.66096
581.21899, 69.37917,    -0.93285,80.26900,50.00000,0.0000e+000,20.00000,-4.5972e-002,0.65986
583.00897, 69.55917,    -0.93586,80.26202,50.00000,0.0000e+000,20.00000,-4.6218e-002,0.65879
584.84198, 69.73917,    -0.93818,80.25445,50.00000,0.0000e+000,20.00000,-4.6586e-002,0.65770
586.64203, 69.91917,    -0.93926,80.24519,50.00000,0.0000e+000,20.00000,-4.7011e-002,0.65663
588.41998, 70.09917,    -0.93971,80.23679,50.00000,0.0000e+000,20.00000,-4.7603e-002,0.65558
590.20502, 70.27917,    -0.94095,80.22979,50.00000,0.0000e+000,20.00000,-4.8350e-002,0.65453
591.99298, 70.45917,    -0.94228,80.22189,50.00000,0.0000e+000,20.00000,-4.9237e-002,0.65348
593.78497, 70.63917,    -0.94694,80.21274,50.00000,0.0000e+000,20.00000,-4.9735e-002,0.65244
595.60699, 70.81917,    -0.95193,80.20451,50.00000,0.0000e+000,20.00000,-4.9951e-002,0.65138
597.40997, 70.99917,    -0.95593,80.19747,50.00000,0.0000e+000,20.00000,-5.0312e-002,0.65034
599.21399, 71.17917,    -0.95864,80.18835,50.00000,0.0000e+000,20.00000,-5.1209e-002,0.64930
601.01300, 71.35917,    -0.95974,80.17824,50.00000,0.0000e+000,20.00000,-5.2598e-002,0.64827
602.80798, 71.53917,    -0.96115,80.16848,50.00000,0.0000e+000,20.00000,-5.3945e-002,0.64725
604.59198, 71.71917,    -0.96311,80.15846,50.00000,0.0000e+000,20.00000,-5.4631e-002,0.64624
606.37500, 71.89917,    -0.96451,80.14821,50.00000,0.0000e+000,20.00000,-5.5178e-002,0.64523
608.17499, 72.07917,    -0.96742,80.13743,50.00000,0.0000e+000,20.00000,-5.6083e-002,0.64422
609.95099, 72.25916,    -0.96950,80.12648,50.00000,0.0000e+000,20.00000,-5.7218e-002,0.64322
611.75598, 72.43916,    -0.97209,80.11636,50.00000,0.0000e+000,20.00000,-5.8310e-002,0.64222
613.54199, 72.61916,    -0.97423,80.10649,50.00000,0.0000e+000,20.00000,-5.9794e-002,0.64122
615.34302, 72.79916,    -0.97724,80.09615,50.00000,0.0000e+000,20.00000,-6.1637e-002,0.64023
617.16498, 72.97916,    -0.98112,80.08485,50.00000,0.0000e+000,20.00000,-6.3151e-002,0.63923
618.98602, 73.15916,    -0.98547,80.07265,50.00000,0.0000e+000,20.00000,-6.4526e-002,0.63823
620.79999, 73.33916,    -0.98810,80.06045,50.00000,0.0000e+000,20.00000,-6.6117e-002,0.63724
622.59998, 73.51917,    -0.98980,80.04863,50.00000,0.0000e+000,20.00000,-6.7147e-002,0.63626
624.40997, 73.69917,    -0.99088,80.03787,50.00000,0.0000e+000,20.00000,-6.8062e-002,0.63528
626.18903, 73.87917,    -0.99140,80.02749,50.00000,0.0000e+000,20.00000,-6.9366e-002,0.63432
627.97498, 74.05917,    -0.99203,80.01602,50.00000,0.0000e+000,20.00000,-7.0713e-002,0.63337
629.77002, 74.23917,    -0.99418,80.00306,50.00000,0.0000e+000,20.00000,-7.2289e-002,0.63241
631.59100, 74.41917,    -0.99779,79.98924,50.00000,0.0000e+000,20.00000,-7.3981e-002,0.63144
633.39697, 74.59917,    -1.00210,79.97542,50.00000,0.0000e+000,20.00000,-7.5865e-002,0.63048
635.22803, 74.77917,    -1.00521,79.96133,50.00000,0.0000e+000,20.00000,-7.7659e-002,0.62952
637.04303, 74.95917,    -1.00679,79.94626,50.00000,0.0000e+000,20.00000,-7.9012e-002,0.62857
638.83398, 75.13917,    -1.00683,79.93066,50.00000,0.0000e+000,20.00000,-8.0774e-002,0.62763
640.62097, 75.31917,    -1.00755,79.91653,50.00000,0.0000e+000,20.00000,-8.2539e-002,0.62670
642.39801, 75.49917,    -1.00754,79.90326,50.00000,0.0000e+000,20.00000,-8.4355e-002,0.62578
644.20502, 75.67917,    -1.01106,79.88800,50.00000,0.0000e+000,20.00000,-8.6467e-002,0.62485
646.04199, 75.85917,    -1.01630,79.87210,50.00000,0.0000e+000,20.00000,-8.8971e-002,0.62390
647.87097, 76.03917,    -1.01950,79.85608,50.00000,0.0000e+000,20.00000,-9.1298e-002,0.62297
649.67102, 76.21917,    -1.02027,79.84011,50.00000,0.0000e+000,20.00000,-9.2965e-002,0.62205
651.47699, 76.39917,    -1.02035,79.82320,50.00000,0.0000e+000,20.00000,-9.4720e-002,0.62114
653.27100, 76.57917,    -1.02095,79.80543,50.00000,0.0000e+000,20.00000,-9.6886e-002,0.62023
655.06598, 76.75916,    -1.02204,79.78843,50.00000,0.0000e+000,20.00000,-9.8846e-002,0.61933
656.86298, 76.93916,    -1.02416,79.76997,50.00000,0.0000e+000,20.00000,    -0.10040,0.61843
658.65002, 77.11916,    -1.02590,79.75143,50.00000,0.0000e+000,20.00000,    -0.10213,0.61754
660.45001, 77.29916,    -1.02792,79.73382,50.00000,0.0000e+000,20.00000,    -0.10425,0.61664
662.23700, 77.47916,    -1.03022,79.71593,50.00000,0.0000e+000,20.00000,    -0.10544,0.61576
664.04700, 77.65916,    -1.03296,79.69598,50.00000,0.0000e+000,20.00000,    -0.10635,0.61487
665.84998, 77.83916,    -1.03593,79.67455,50.00000,0.0000e+000,20.00000,    -0.10773,0.61398
667.66699, 78.01917,    -1.04043,79.65457,50.00000,0.0000e+000,20.00000,    -0.10929,0.61310
669.48199, 78.19917,    -1.04476,79.63454,50.00000,0.0000e+000,20.00000,    -0.11049,0.61221
671.29700, 78.37917,    -1.04714,79.61281,50.00000,0.0000e+000,20.00000,    -0.11115,0.61133
673.10303, 78.55917,    -1.04936,79.59068,50.00000,0.0000e+000,20.00000,    -0.11219,0.61046
674.89001, 78.73917,    -1.05099,79.56925,50.00000,0.0000e+000,20.00000,    -0.11314,0.60960
676.68903, 78.91917,    -1.05414,79.54847,50.00000,0.0000e+000,20.00000,    -0.11416,0.60874
678.49200, 79.09917,    -1.05743,79.52750,50.00000,0.0000e+000,20.00000,    -0.11547,0.60788
680.30402, 79.27917,    -1.06172,79.50788,50.00000,0.0000e+000,20.00000,    -0.11658,0.60702
682.12903, 79.45917,    -1.06864,79.48890,50.00000,0.0000e+000,20.00000,    -0.11727,0.60616
683.91199, 79.63917,    -1.07058,79.46805,50.00000,0.0000e+000,20.00000,    -0.11738,0.60532
685.68103, 79.81917,    -1.07118,79.44641,50.00000,0.0000e+000,20.00000,    -0.11800,0.60449
687.47803, 79.99917,    -1.07308,79.42519,50.00000,0.0000e+000,20.00000,    -0.11898,0.60365
689.27600, 80.17917,    -1.07827,79.40493,50.00000,0.0000e+000,20.00000,    -0.11966,0.60282
691.07703, 80.35917,    -1.08310,79.38427,50.00000,0.0000e+000,20.00000,    -0.11998,0.60198
692.89398, 80.53917,    -1.08678,79.36269,50.00000,0.0000e+000,20.00000,    -0.12018,0.60114
694.70203, 80.71917,    -1.09138,79.34038,50.00000,0.0000e+000,20.00000,    -0.12061,0.60031
696.50299, 80.89917,    -1.09342,79.31787,50.00000,0.0000e+000,20.00000,    -0.12080,0.59949
698.29498, 81.07917,    -1.09516,79.29593,50.00000,0.0000e+000,20.00000,    -0.12080,0.59867
700.08801, 81.25916,    -1.09851,79.27401,50.00000,0.0000e+000,20.00000,    -0.12077,0.59785
701.90002, 81.43916,    -1.10220,79.25203,50.00000,0.0000e+000,20.00000,    -0.12004,0.59703
703.70502, 81.61916,    -1.10691,79.22982,50.00000,0.0000e+000,20.00000,    -0.11844,0.59622
705.52899, 81.79916,    -1.11172,79.20648,50.00000,0.0000e+000,20.00000,    -0.11672,0.59540
707.35602, 81.97916,    -1.11656,79.18246,50.00000,0.0000e+000,20.00000,    -0.11501,0.59458
709.16101, 82.15916,    -1.12066,79.15902,50.00000,0.0000e+000,20.00000,    -0.11289,0.59378
710.95801, 82.33916,    -1.12368,79.13658,50.00000,0.0000e+000,20.00000,    -0.11005,0.59298
712.72803, 82.51917,    -1.12723,79.11424,50.00000,0.0000e+000,20.00000,    -0.10677,0.59219
714.54901, 82.69917,    -1.13188,79.09237,50.00000,0.0000e+000,20.00000,    -0.10305,0.59139
716.34698, 82.87917,    -1.13833,79.07213,50.00000,0.0000e+000,20.00000,-9.9300e-002,0.59060
718.17798, 83.05917,    -1.14610,79.05337,50.00000,0.0000e+000,20.00000,-9.6121e-002,0.58980
720.00702, 83.23917,    -1.15584,79.03515,50.00000,0.0000e+000,20.00000,-9.2718e-002,0.58900
721.81598, 83.41917,    -1.16401,79.01919,50.00000,0.0000e+000,20.00000,-8.9047e-002,0.58822
723.60498, 83.59917,    -1.17165,79.00399,50.00000,0.0000e+000,20.00000,-8.5010e-002,0.58744
725.44202, 83.77917,    -1.18123,78.98975,50.00000,0.0000e+000,20.00000,-8.0390e-002,0.58665
727.26898, 83.95917,    -1.19183,78.97671,50.00000,0.0000e+000,20.00000,-7.5302e-002,0.58587
729.12500, 84.13917,    -1.20122,78.96541,50.00000,0.0000e+000,20.00000,-7.0954e-002,0.58507
731.03302, 84.31917,    -1.21445,78.95507,50.00000,0.0000e+000,20.00000,-6.6931e-002,0.58426
732.92499, 84.49917,    -1.22512,78.94588,50.00000,0.0000e+000,20.00000,-6.2976e-002,0.58345
734.78198, 84.67917,    -1.22661,78.93770,50.00000,0.0000e+000,20.00000,-5.8926e-002,0.58267
736.57300, 84.85917,    -1.22176,78.92767,50.00000,0.0000e+000,20.00000,-5.5070e-002,0.58191
738.31897, 85.03917,    -1.21472,78.91785,50.00000,0.0000e+000,20.00000,-5.1739e-002,0.58118
740.02698, 85.21917,    -1.20740,78.90912,50.00000,0.0000e+000,20.00000,-4.9263e-002,0.58046
741.74200, 85.39917,    -1.20189,78.90068,50.00000,0.0000e+000,20.00000,-4.7062e-002,0.57974
743.44397, 85.57917,    -1.19866,78.89313,50.00000,0.0000e+000,20.00000,-4.5177e-002,0.57903
745.17102, 85.75916,    -1.19907,78.88817,50.00000,0.0000e+000,20.00000,-4.3043e-002,0.57832
746.95001, 85.93916,    -1.20455,78.88174,50.00000,0.0000e+000,20.00000,-4.0854e-002,0.57758
748.78101, 86.11916,    -1.21435,78.87419,50.00000,0.0000e+000,20.00000,-3.9515e-002,0.57683
750.59302, 86.29916,    -1.21963,78.86658,50.00000,0.0000e+000,20.00000,-3.8637e-002,0.57608
752.40698, 86.47916,    -1.22098,78.86040,50.00000,0.0000e+000,20.00000,-3.7756e-002,0.57534
754.23499, 86.65916,    -1.22265,78.85579,50.00000,0.0000e+000,20.00000,-3.6153e-002,0.57459
756.05402, 86.83916,    -1.22574,78.84975,50.00000,0.0000e+000,20.00000,-3.4892e-002,0.57385
757.89099, 87.01917,    -1.22730,78.84259,50.00000,0.0000e+000,20.00000,-3.3724e-002,0.57310
759.70502, 87.19917,    -1.22836,78.83537,50.00000,0.0000e+000,20.00000,-3.2298e-002,0.57237
761.50897, 87.37917,    -1.22767,78.82786,50.00000,0.0000e+000,20.00000,-3.1725e-002,0.57164
763.31299, 87.55917,    -1.22649,78.82185,50.00000,0.0000e+000,20.00000,-3.2150e-002,0.57092
765.12000, 87.73917,    -1.22679,78.81838,50.00000,0.0000e+000,20.00000,-3.2079e-002,0.57019
766.91101, 87.91917,    -1.22802,78.81314,50.00000,0.0000e+000,20.00000,-3.1656e-002,0.56948
768.70697, 88.09917,    -1.22773,78.80685,50.00000,0.0000e+000,20.00000,-3.1261e-002,0.56876
770.49799, 88.27917,    -1.22671,78.80166,50.00000,0.0000e+000,20.00000,-3.0992e-002,0.56805
772.27698, 88.45917,    -1.22683,78.79781,50.00000,0.0000e+000,20.00000,-3.1570e-002,0.56735
774.02502, 88.63917,    -1.22599,78.79260,50.00000,0.0000e+000,20.00000,-3.1935e-002,0.56666
775.79401, 88.81917,    -1.22451,78.78767,50.00000,0.0000e+000,20.00000,-3.1637e-002,0.56596
777.57098, 88.99917,    -1.22625,78.78456,50.00000,0.0000e+000,20.00000,-3.1272e-002,0.56526
779.36298, 89.17917,    -1.23037,78.77915,50.00000,0.0000e+000,20.00000,-3.0929e-002,0.56456
781.18597, 89.35917,    -1.23534,78.77242,50.00000,0.0000e+000,20.00000,-3.0700e-002,0.56385
782.99799, 89.53917,    -1.24128,78.76644,50.00000,0.0000e+000,20.00000,-3.1319e-002,0.56314
784.80902, 89.71917,    -1.24536,78.76060,50.00000,0.0000e+000,20.00000,-3.1689e-002,0.56244
786.62299, 89.89917,    -1.24703,78.75440,50.00000,0.0000e+000,20.00000,-3.1536e-002,0.56174
788.44598, 90.07917,    -1.25008,78.74872,50.00000,0.0000e+000,20.00000,-3.2063e-002,0.56103
790.26001, 90.25916,    -1.25260,78.74232,50.00000,0.0000e+000,20.00000,-3.3176e-002,0.56033
792.07703, 90.43916,    -1.25491,78.73504,50.00000,0.0000e+000,20.00000,-3.3974e-002,0.55964
793.89099, 90.61916,    -1.25779,78.72894,50.00000,0.0000e+000,20.00000,-3.4809e-002,0.55894
795.71698, 90.79916,    -1.26140,78.72311,50.00000,0.0000e+000,20.00000,-3.5629e-002,0.55824
797.54700, 90.97916,    -1.26485,78.71692,50.00000,0.0000e+000,20.00000,-3.5981e-002,0.55755
799.37299, 91.15916,    -1.26816,78.71111,50.00000,0.0000e+000,20.00000,-3.6038e-002,0.55685
801.17603, 91.33916,    -1.26910,78.70549,50.00000,0.0000e+000,20.00000,-3.6345e-002,0.55617
802.98798, 91.51917,    -1.26879,78.69911,50.00000,0.0000e+000,20.00000,-3.6706e-002,0.55548
804.77802, 91.69917,    -1.26916,78.69347,50.00000,0.0000e+000,20.00000,-3.6733e-002,0.55481
806.59497, 91.87917,    -1.27305,78.68637,50.00000,0.0000e+000,20.00000,-3.7044e-002,0.55412
808.40997, 92.05917,    -1.27635,78.67836,50.00000,0.0000e+000,20.00000,-3.7286e-002,0.55344
810.21600, 92.23917,    -1.27730,78.67054,50.00000,0.0000e+000,20.00000,-3.7183e-002,0.55277
811.99402, 92.41917,    -1.27603,78.66223,50.00000,0.0000e+000,20.00000,-3.7425e-002,0.55210
813.79797, 92.59917,    -1.27859,78.65570,50.00000,0.0000e+000,20.00000,-3.7920e-002,0.55143
815.59302, 92.77917,    -1.28073,78.64967,50.00000,0.0000e+000,20.00000,-3.8557e-002,0.55076
817.43903, 92.95917,    -1.28633,78.64276,50.00000,0.0000e+000,20.00000,-3.9026e-002,0.55008
819.28003, 93.13917,    -1.29172,78.63561,50.00000,0.0000e+000,20.00000,-3.9409e-002,0.54939
821.10498, 93.31917,    -1.29316,78.62838,50.00000,0.0000e+000,20.00000,-3.9465e-002,0.54872
823.00299, 93.49917,    -1.30264,78.62202,50.00000,0.0000e+000,20.00000,-3.9853e-002,0.54802
824.90100, 93.67917,    -1.31035,78.61529,50.00000,0.0000e+000,20.00000,-3.9830e-002,0.54732
826.75403, 93.85917,    -1.31239,78.60817,50.00000,0.0000e+000,20.00000,-3.9480e-002,0.54664
828.54700, 94.03917,    -1.30687,78.60127,50.00000,0.0000e+000,20.00000,-3.8966e-002,0.54598
830.32703, 94.21917,    -1.30311,78.59413,50.00000,0.0000e+000,20.00000,-3.8079e-002,0.54533
832.09698, 94.39917,    -1.30019,78.58666,50.00000,0.0000e+000,20.00000,-3.7917e-002,0.54469
833.88599, 94.57917,    -1.29776,78.57825,50.00000,0.0000e+000,20.00000,-3.8247e-002,0.54403
835.65698, 94.75916,    -1.29768,78.57038,50.00000,0.0000e+000,20.00000,-3.8165e-002,0.54339
837.41199, 94.93916,    -1.29836,78.56343,50.00000,0.0000e+000,20.00000,-3.7855e-002,0.54275
839.18597, 95.11916,    -1.29879,78.55681,50.00000,0.0000e+000,20.00000,-3.7636e-002,0.54211
840.93298, 95.29916,    -1.29841,78.54977,50.00000,0.0000e+000,20.00000,-3.7992e-002,0.54148
842.69501, 95.47916,    -1.29744,78.54304,50.00000,0.0000e+000,20.00000,-3.8325e-002,0.54084
844.46600, 95.65916,    -1.30054,78.53625,50.00000,0.0000e+000,20.00000,-3.8259e-002,0.54020
846.26398, 95.83916,    -1.30557,78.53017,50.00000,0.0000e+000,20.00000,-3.8202e-002,0.53956
848.04199, 96.01917,    -1.30954,78.52509,50.00000,0.0000e+000,20.00000,-3.7520e-002,0.53892
849.82501, 96.19917,    -1.31228,78.51903,50.00000,0.0000e+000,20.00000,-3.6977e-002,0.53828
851.62701, 96.37917,    -1.31531,78.51196,50.00000,0.0000e+000,20.00000,-3.6424e-002,0.53763
853.44299, 96.55917,    -1.31908,78.50526,50.00000,0.0000e+000,20.00000,-3.5781e-002,0.53698
855.25897, 96.73917,    -1.32232,78.49932,50.00000,0.0000e+000,20.00000,-3.5099e-002,0.53634
857.05402, 96.91917,    -1.32487,78.49293,50.00000,0.0000e+000,20.00000,-3.4850e-002,0.53570
858.87000, 97.09917,    -1.32653,78.48535,50.00000,0.0000e+000,20.00000,-3.4172e-002,0.53505
860.68402, 97.27917,    -1.32868,78.47744,50.00000,0.0000e+000,20.00000,-3.3157e-002,0.53441
862.49200, 97.45917,    -1.33049,78.47044,50.00000,0.0000e+000,20.00000,-3.2580e-002,0.53376
864.30701, 97.63917,    -1.33250,78.46363,50.00000,0.0000e+000,20.00000,-3.2426e-002,0.53312
866.12799, 97.81917,    -1.33518,78.45874,50.00000,0.0000e+000,20.00000,-3.2128e-002,0.53248
867.94800, 97.99917,    -1.33771,78.45364,50.00000,0.0000e+000,20.00000,-3.1656e-002,0.53183
869.75000, 98.17917,    -1.33775,78.44738,50.00000,0.0000e+000,20.00000,-3.1353e-002,0.53120
871.56598, 98.35917,    -1.33890,78.44150,50.00000,0.0000e+000,20.00000,-3.0515e-002,0.53056
873.37299, 98.53917,    -1.33916,78.43690,50.00000,0.0000e+000,20.00000,-2.9635e-002,0.52992
875.17902, 98.71917,    -1.33920,78.43135,50.00000,0.0000e+000,20.00000,-2.8730e-002,0.52929
876.99500, 98.89917,    -1.33930,78.42645,50.00000,0.0000e+000,20.00000,-2.7391e-002,0.52865
878.75702, 99.07917,    -1.33760,78.42342,50.00000,0.0000e+000,20.00000,-2.6357e-002,0.52803
880.55499, 99.25916,    -1.33935,78.41902,50.00000,0.0000e+000,20.00000,-2.5561e-002,0.52740
882.35797, 99.43916,    -1.34170,78.41332,50.00000,0.0000e+000,20.00000,-2.4333e-002,0.52677
884.19598, 99.61916,    -1.34585,78.40894,50.00000,0.0000e+000,20.00000,-2.3767e-002,0.52612
886.02802, 99.79916,    -1.34811,78.40517,50.00000,0.0000e+000,20.00000,-2.3577e-002,0.52548
887.83002, 99.97916,    -1.34929,78.39929,50.00000,0.0000e+000,20.00000,-2.3012e-002,0.52486
889.64301,100.15916,    -1.34911,78.39508,50.00000,0.0000e+000,20.00000,-2.2411e-002,0.52422
891.46600,100.33916,    -1.34938,78.39239,50.00000,0.0000e+000,20.00000,-2.2238e-002,0.52359
893.27399,100.51917,    -1.35029,78.38935,50.00000,0.0000e+000,20.00000,-2.1816e-002,0.52296
895.09399,100.69917,    -1.35092,78.38691,50.00000,0.0000e+000,20.00000,-2.1407e-002,0.52232
896.89600,100.87917,    -1.35089,78.38302,50.00000,0.0000e+000,20.00000,-2.1692e-002,0.52170
898.69397,101.05917,    -1.35088,78.37854,50.00000,0.0000e+000,20.00000,-2.1750e-002,0.52107
900.48999,101.23917,    -1.35084,78.37601,50.00000,0.0000e+000,20.00000,-2.1493e-002,0.52045
902.31299,101.41917,    -1.35205,78.37309,50.00000,0.0000e+000,20.00000,-2.1294e-002,0.51982
904.12000,101.59917,    -1.35374,78.36904,50.00000,0.0000e+000,20.00000,-2.1102e-002,0.51919
905.93402,101.77917,    -1.35538,78.36481,50.00000,0.0000e+000,20.00000,-2.0346e-002,0.51856
907.74298,101.95917,    -1.35453,78.36102,50.00000,0.0000e+000,20.00000,-1.9672e-002,0.51794
909.54199,102.13917,    -1.35459,78.35693,50.00000,0.0000e+000,20.00000,-1.9242e-002,0.51731
911.35901,102.31917,    -1.35522,78.35307,50.00000,0.0000e+000,20.00000,-1.9103e-002,0.51669
913.20300,102.49917,    -1.35911,78.34941,50.00000,0.0000e+000,20.00000,-1.9663e-002,0.51605
915.00702,102.67917,    -1.35965,78.34524,50.00000,0.0000e+000,20.00000,-1.9970e-002,0.51543
916.79602,102.85917,    -1.35802,78.34103,50.00000,0.0000e+000,20.00000,-1.9726e-002,0.51481
918.58600,103.03917,    -1.35264,78.33630,50.00000,0.0000e+000,20.00000,-1.9567e-002,0.51419
920.35699,103.21917,    -1.34968,78.33217,50.00000,0.0000e+000,20.00000,-1.9559e-002,0.51358
922.13300,103.39917,    -1.34881,78.32918,50.00000,0.0000e+000,20.00000,-1.8862e-002,0.51297
923.93500,103.57917,    -1.34984,78.32625,50.00000,0.0000e+000,20.00000,-1.7574e-002,0.51234
925.77197,103.75916,    -1.35158,78.32392,50.00000,0.0000e+000,20.00000,-1.6316e-002,0.51171
927.69501,103.93916,    -1.36513,78.32265,50.00000,0.0000e+000,20.00000,-1.5770e-002,0.51105
929.54102,104.11916,    -1.36802,78.32057,50.00000,0.0000e+000,20.00000,-1.5134e-002,0.51041
931.35199,104.29916,    -1.36313,78.31614,50.00000,0.0000e+000,20.00000,-1.4925e-002,0.50979
933.13202,104.47916,    -1.35706,78.31147,50.00000,0.0000e+000,20.00000,-1.4470e-002,0.50918
934.91498,104.65916,    -1.35245,78.30743,50.00000,0.0000e+000,20.00000,-1.3190e-002,0.50856
936.69299,104.83916,    -1.34923,78.30517,50.00000,0.0000e+000,20.00000,-1.2195e-002,0.50795
938.48602,105.01917,    -1.34955,78.30254,50.00000,0.0000e+000,20.00000,-1.1910e-002,0.50733
940.29303,105.19917,    -1.34957,78.30085,50.00000,0.0000e+000,20.00000,-1.1957e-002,0.50671
942.09302,105.37917,    -1.35032,78.30096,50.00000,0.0000e+000,20.00000,-1.1440e-002,0.50609
943.90198,105.55917,    -1.35160,78.30209,50.00000,0.0000e+000,20.00000,-1.1005e-002,0.50547
945.71198,105.73917,    -1.35078,78.30023,50.00000,0.0000e+000,20.00000,-1.0624e-002,0.50485
947.48602,105.91917,    -1.34769,78.29860,50.00000,0.0000e+000,20.00000,-1.0421e-002,0.50423
949.26703,106.09917,    -1.34490,78.29594,50.00000,0.0000e+000,20.00000,-9.9576e-003,0.50362
951.03699,106.27917,    -1.34222,78.29321,50.00000,0.0000e+000,20.00000,-9.1010e-003,0.50301
952.85498,106.45917,    -1.34315,78.29335,50.00000,0.0000e+000,20.00000,-7.7655e-003,0.50239
954.66803,106.63917,    -1.34608,78.29284,50.00000,0.0000e+000,20.00000,-6.7610e-003,0.50176
956.44702,106.81917,    -1.34409,78.28974,50.00000,0.0000e+000,20.00000,-6.5265e-003,0.50115
958.22998,106.99917,    -1.34160,78.28628,50.00000,0.0000e+000,20.00000,-6.6155e-003,0.50053
960.03497,107.17917,    -1.34086,78.28495,50.00000,0.0000e+000,20.00000,-7.4345e-003,0.49991
961.84399,107.35917,    -1.34374,78.28416,50.00000,0.0000e+000,20.00000,-8.6711e-003,0.49929
963.65100,107.53917,    -1.34457,78.28385,50.00000,0.0000e+000,20.00000,-9.0319e-003,0.49867
965.46503,107.71917,    -1.34442,78.28337,50.00000,0.0000e+000,20.00000,-8.2783e-003,0.49804
967.27502,107.89917,    -1.34356,78.28078,50.00000,0.0000e+000,20.00000,-7.1312e-003,0.49742
969.07898,108.07917,    -1.34199,78.27907,50.00000,0.0000e+000,20.00000,-6.5404e-003,0.49679
970.87299,108.25916,    -1.34087,78.27926,50.00000,0.0000e+000,20.00000,-7.0136e-003,0.49617
972.65802,108.43916,    -1.33932,78.28081,50.00000,0.0000e+000,20.00000,-7.2879e-003,0.49556
974.46198,108.61916,    -1.33952,78.27944,50.00000,0.0000e+000,20.00000,-6.7815e-003,0.49493
976.27100,108.79916,    -1.33967,78.27719,50.00000,0.0000e+000,20.00000,-6.1530e-003,0.49431
978.08197,108.97916,    -1.33991,78.27417,50.00000,0.0000e+000,20.00000,-5.7124e-003,0.49368
979.87097,109.15916,    -1.33958,78.27087,50.00000,0.0000e+000,20.00000,-5.8887e-003,0.49306
981.67102,109.33916,    -1.33813,78.26782,50.00000,0.0000e+000,20.00000,-6.3019e-003,0.49244
983.46997,109.51917,    -1.33949,78.26824,50.00000,0.0000e+000,20.00000,-5.5947e-003,0.49182
985.26202,109.69917,    -1.33936,78.27022,50.00000,0.0000e+000,20.00000,-6.8280e-003,0.49120
987.06598,109.87917,    -1.33818,78.26987,50.00000,0.0000e+000,20.00000,-6.6669e-003,0.49057
988.85199,110.05917,    -1.33638,78.26785,50.00000,0.0000e+000,20.00000,-4.7072e-003,0.48995
990.68903,110.23917,    -1.33778,78.26656,50.00000,0.0000e+000,20.00000,-3.2052e-003,0.48931
992.54901,110.41917,    -1.34359,78.26578,50.00000,0.0000e+000,20.00000,-6.3274e-003,0.48867
994.34003,110.59917,    -1.34246,78.26425,50.00000,0.0000e+000,20.00000,-4.7538e-003,0.48804
996.15503,110.77917,    -1.34039,78.26428,50.00000,0.0000e+000,20.00000,-3.5507e-003,0.48741
997.97302,110.95917,    -1.34106,78.26282,50.00000,0.0000e+000,20.00000,-3.6822e-003,0.48678
998.37000,110.99917,    -1.34164,78.26282,50.00000,0.0000e+000,20.00000, 4.2118e-008,0.48664