File: book/some_content/TG_ExpDat_B50B50D28.csv
#FILE:                       ,B50B50D28; 13-1-2025.ngb-ds3
#FORMAT:                     ,NETZSCH5
#IDENTITY:                   ,Geopolymer paste
#DECIMAL:                    ,POINT
#SEPARATOR:                  ,COMMA
#MTYPE:                      ,DSC
#INSTRUMENT:                 ,Microlab TU Delft
#PROJECT:                    ,
#DATE/TIME:                  ,13/01/2025 4:23:45 PM
#CORR. FILE:                 ,Blank with cover; 13-1-2025.ngb-bs3
#LABORATORY:                 ,TU Delft Micro Lab
#OPERATOR:                   ,Ahmed
#REMARK:                     ,under Argon atmosphere, 10K/min
#SAMPLE:                     ,R50B50D28;13-1-2025
#SAMPLE MASS /mg:            ,39.2
#MATERIAL:                   ,Geopolymer paste
#REFERENCE:                  ,blank
#REFERENCE MASS /mg:         ,0
#TYPE OF CRUCIBLE:           ,DSC/TG pan Al2O3
#SAMPLE CRUCIBLE MASS /mg:   ,0
#REFERENCE CRUCIBLE MASS /mg:,0
#CORR. CODE:                 ,020
#EXO:                        ,-1
#RANGE:                      ,40/10.0(K/min)/1000
#SEGMENT:                    ,S2/2

##Temp./øC,Time/min,DSC/(mW/mg),Mass/%,Gas Flow(purge1)/(ml/min),Gas Flow(purge2)/(ml/min),Gas Flow(protective)/(ml/min),DTG/(%/min),Sensit./(uV/mW)
 40.97000, 15.53167, 6.7490e-002,96.38887,50.00000,0.0000e+000,20.00000,    -0.21514,1.22560
 41.00700, 15.71167, 6.7446e-002,96.34942,50.00000,0.0000e+000,20.00000,    -0.21483,1.22555
 41.07600, 15.89167, 6.8070e-002,96.31005,50.00000,0.0000e+000,20.00000,    -0.21513,1.22546
 41.24100, 16.07167, 6.9481e-002,96.27114,50.00000,0.0000e+000,20.00000,    -0.21539,1.22523
 41.46200, 16.25167, 7.1437e-002,96.23317,50.00000,0.0000e+000,20.00000,    -0.21742,1.22493
 41.76000, 16.43167, 7.3972e-002,96.19403,50.00000,0.0000e+000,20.00000,    -0.22129,1.22452
 42.14800, 16.61167, 7.6930e-002,96.15485,50.00000,0.0000e+000,20.00000,    -0.22665,1.22398
 42.60300, 16.79167, 8.0692e-002,96.11630,50.00000,0.0000e+000,20.00000,    -0.23475,1.22335
 43.16300, 16.97167, 8.5344e-002,96.07809,50.00000,0.0000e+000,20.00000,    -0.24264,1.22258
 43.80100, 17.15167, 9.0424e-002,96.03806,50.00000,0.0000e+000,20.00000,    -0.25153,1.22170
 44.52800, 17.33167, 9.6158e-002,95.99744,50.00000,0.0000e+000,20.00000,    -0.26256,1.22070
 45.34400, 17.51167,     0.10228,95.95517,50.00000,0.0000e+000,20.00000,    -0.27510,1.21957
 46.24000, 17.69167,     0.10882,95.91087,50.00000,0.0000e+000,20.00000,    -0.29021,1.21834
 47.21700, 17.87167,     0.11598,95.86564,50.00000,0.0000e+000,20.00000,    -0.30732,1.21699
 48.29300, 18.05167,     0.12384,95.81817,50.00000,0.0000e+000,20.00000,    -0.32630,1.21551
 49.43700, 18.23167,     0.13179,95.76827,50.00000,0.0000e+000,20.00000,    -0.34701,1.21394
 50.68200, 18.41167,     0.14061,95.71453,50.00000,0.0000e+000,20.00000,    -0.37065,1.21222
 51.95800, 18.59167,     0.15019,95.65699,50.00000,0.0000e+000,20.00000,    -0.40014,1.21046
 53.36200, 18.77167,     0.16053,95.59394,50.00000,0.0000e+000,20.00000,    -0.43486,1.20853
 54.85500, 18.95167,     0.17127,95.52462,50.00000,0.0000e+000,20.00000,    -0.47065,1.20648
 56.42200, 19.13167,     0.18292,95.44749,50.00000,0.0000e+000,20.00000,    -0.51119,1.20432
 58.02500, 19.31167,     0.19535,95.36365,50.00000,0.0000e+000,20.00000,    -0.55619,1.20212
 59.73000, 19.49167,     0.20887,95.27034,50.00000,0.0000e+000,20.00000,    -0.60515,1.19977
 61.48800, 19.67167,     0.22357,95.16966,50.00000,0.0000e+000,20.00000,    -0.65875,1.19736
 63.32400, 19.85167,     0.23964,95.06318,50.00000,0.0000e+000,20.00000,    -0.71855,1.19483
 65.21300, 20.03167,     0.25626,94.94991,50.00000,0.0000e+000,20.00000,    -0.78483,1.19224
 67.17700, 20.21167,     0.27531,94.82623,50.00000,0.0000e+000,20.00000,    -0.85582,1.18955
 69.18300, 20.39167,     0.29524,94.68385,50.00000,0.0000e+000,20.00000,    -0.93305,1.18679
 71.26300, 20.57167,     0.31727,94.51989,50.00000,0.0000e+000,20.00000,    -1.01786,1.18394
 73.37900, 20.75167,     0.34127,94.35125,50.00000,0.0000e+000,20.00000,    -1.10917,1.18105
 75.53900, 20.93167,     0.36739,94.16524,50.00000,0.0000e+000,20.00000,    -1.20703,1.17809
 77.73900, 21.11167,     0.39579,93.96166,50.00000,0.0000e+000,20.00000,    -1.31038,1.17508
 79.96400, 21.29167,     0.42697,93.74100,50.00000,0.0000e+000,20.00000,    -1.41854,1.17204
 82.26600, 21.47167,     0.46045,93.50323,50.00000,0.0000e+000,20.00000,    -1.53247,1.16889
 84.56500, 21.65167,     0.49660,93.24168,50.00000,0.0000e+000,20.00000,    -1.65163,1.16576
 86.93100, 21.83167,     0.53594,92.95359,50.00000,0.0000e+000,20.00000,    -1.77459,1.16253
 89.29700, 22.01167,     0.57783,92.64415,50.00000,0.0000e+000,20.00000,    -1.89929,1.15931
 91.71700, 22.19167,     0.62261,92.30985,50.00000,0.0000e+000,20.00000,    -2.02232,1.15602
 94.12700, 22.37167,     0.66987,91.94252,50.00000,0.0000e+000,20.00000,    -2.13963,1.15274
 96.55600, 22.55167,     0.71923,91.54515,50.00000,0.0000e+000,20.00000,    -2.25609,1.14944
 99.00400, 22.73167,     0.77068,91.11626,50.00000,0.0000e+000,20.00000,    -2.36644,1.14612
101.44700, 22.91167,     0.82596,90.65951,50.00000,0.0000e+000,20.00000,    -2.46816,1.14281
103.91000, 23.09167,     0.87955,90.17683,50.00000,0.0000e+000,20.00000,    -2.56117,1.13948
106.36900, 23.27167,     0.93273,89.66485,50.00000,0.0000e+000,20.00000,    -2.64281,1.13616
108.82300, 23.45167,     0.98445,89.12722,50.00000,0.0000e+000,20.00000,    -2.70596,1.13285
111.28700, 23.63167,     1.03341,88.56864,50.00000,0.0000e+000,20.00000,    -2.74683,1.12953
113.74500, 23.81167,     1.07821,87.99314,50.00000,0.0000e+000,20.00000,    -2.76596,1.12622
116.20500, 23.99167,     1.11766,87.40601,50.00000,0.0000e+000,20.00000,    -2.76359,1.12291
118.67200, 24.17167,     1.14981,86.81525,50.00000,0.0000e+000,20.00000,    -2.73734,1.11960
121.10300, 24.35167,     1.17338,86.22249,50.00000,0.0000e+000,20.00000,    -2.68939,1.11634
123.55800, 24.53167,     1.19178,85.63405,50.00000,0.0000e+000,20.00000,    -2.62287,1.11306
126.00500, 24.71167,     1.20636,85.05942,50.00000,0.0000e+000,20.00000,    -2.54027,1.10979
128.45399, 24.89167,     1.20707,84.49868,50.00000,0.0000e+000,20.00000,    -2.44345,1.10652
130.89799, 25.07167,     1.18838,83.96036,50.00000,0.0000e+000,20.00000,    -2.33556,1.10327
133.35300, 25.25167,     1.15022,83.46419,50.00000,0.0000e+000,20.00000,    -2.21899,1.10001
135.78400, 25.43167,     1.09214,83.02189,50.00000,0.0000e+000,20.00000,    -2.09527,1.09678
138.22800, 25.61167,     1.01724,82.63691,50.00000,0.0000e+000,20.00000,    -1.96397,1.09354
140.65700, 25.79167,     0.93022,82.30745,50.00000,0.0000e+000,20.00000,    -1.82652,1.09033
143.08800, 25.97167,     0.83613,82.03283,50.00000,0.0000e+000,20.00000,    -1.68562,1.08712
145.52400, 26.15167,     0.74063,81.80854,50.00000,0.0000e+000,20.00000,    -1.54275,1.08391
147.94299, 26.33167,     0.64920,81.62281,50.00000,0.0000e+000,20.00000,    -1.40045,1.08073
150.35899, 26.51167,     0.56500,81.46722,50.00000,0.0000e+000,20.00000,    -1.26054,1.07756
152.73100, 26.69167,     0.48972,81.33949,50.00000,0.0000e+000,20.00000,    -1.12378,1.07445
155.12500, 26.87167,     0.42231,81.22526,50.00000,0.0000e+000,20.00000,    -0.99200,1.07132
157.47800, 27.05167,     0.36353,81.11663,50.00000,0.0000e+000,20.00000,    -0.86972,1.06824
159.82300, 27.23167,     0.31159,81.01222,50.00000,0.0000e+000,20.00000,    -0.76020,1.06519
162.12801, 27.41167,     0.26609,80.91712,50.00000,0.0000e+000,20.00000,    -0.66481,1.06219
164.39900, 27.59167,     0.22652,80.83245,50.00000,0.0000e+000,20.00000,    -0.58412,1.05924
166.65500, 27.77167,     0.19140,80.75565,50.00000,0.0000e+000,20.00000,    -0.51766,1.05632
168.87700, 27.95167,     0.16064,80.68507,50.00000,0.0000e+000,20.00000,    -0.46504,1.05345
171.08501, 28.13167,     0.13253,80.61495,50.00000,0.0000e+000,20.00000,    -0.42332,1.05060
173.24100, 28.31167,     0.10747,80.54879,50.00000,0.0000e+000,20.00000,    -0.38975,1.04783
175.37700, 28.49167, 8.3786e-002,80.48551,50.00000,0.0000e+000,20.00000,    -0.36358,1.04508
177.48700, 28.67167, 6.3054e-002,80.42377,50.00000,0.0000e+000,20.00000,    -0.34167,1.04238
179.56300, 28.85167, 4.3897e-002,80.36624,50.00000,0.0000e+000,20.00000,    -0.32132,1.03972
181.63300, 29.03167, 2.6311e-002,80.31459,50.00000,0.0000e+000,20.00000,    -0.30214,1.03707
183.65601, 29.21167, 9.7267e-003,80.26899,50.00000,0.0000e+000,20.00000,    -0.28416,1.03450
185.68300, 29.39167,-5.4319e-003,80.22571,50.00000,0.0000e+000,20.00000,    -0.26818,1.03192
187.67500, 29.57167,-1.9285e-002,80.18537,50.00000,0.0000e+000,20.00000,    -0.25393,1.02939
189.64400, 29.75167,-3.2125e-002,80.14626,50.00000,0.0000e+000,20.00000,    -0.24120,1.02689
191.59100, 29.93167,-4.3906e-002,80.10777,50.00000,0.0000e+000,20.00000,    -0.22858,1.02443
193.52699, 30.11167,-5.4961e-002,80.07020,50.00000,0.0000e+000,20.00000,    -0.21670,1.02199
195.40700, 30.29167,-6.5415e-002,80.03421,50.00000,0.0000e+000,20.00000,    -0.20550,1.01962
197.29800, 30.47167,-7.5403e-002,79.99890,50.00000,0.0000e+000,20.00000,    -0.19435,1.01724
199.17101, 30.65167,-8.4974e-002,79.96395,50.00000,0.0000e+000,20.00000,    -0.18452,1.01489
201.02800, 30.83167,-9.4222e-002,79.92861,50.00000,0.0000e+000,20.00000,    -0.17600,1.01257
202.85800, 31.01167,    -0.10280,79.89673,50.00000,0.0000e+000,20.00000,    -0.16849,1.01028
204.66600, 31.19167,    -0.11075,79.86880,50.00000,0.0000e+000,20.00000,    -0.16165,1.00803
206.49100, 31.37167,    -0.11944,79.84261,50.00000,0.0000e+000,20.00000,    -0.15524,1.00575
208.28799, 31.55167,    -0.12729,79.81787,50.00000,0.0000e+000,20.00000,    -0.14938,1.00352
210.07201, 31.73167,    -0.13515,79.79379,50.00000,0.0000e+000,20.00000,    -0.14393,1.00131
211.85500, 31.91167,    -0.14258,79.77005,50.00000,0.0000e+000,20.00000,    -0.13934,0.99910
213.62500, 32.09167,    -0.14960,79.74743,50.00000,0.0000e+000,20.00000,    -0.13469,0.99692
215.37900, 32.27167,    -0.15666,79.72588,50.00000,0.0000e+000,20.00000,    -0.12910,0.99476
217.13800, 32.45167,    -0.16371,79.70382,50.00000,0.0000e+000,20.00000,    -0.12407,0.99259
218.87601, 32.63167,    -0.17031,79.68179,50.00000,0.0000e+000,20.00000,    -0.11941,0.99046
220.62700, 32.81167,    -0.17668,79.66278,50.00000,0.0000e+000,20.00000,    -0.11590,0.98832
222.36400, 32.99166,    -0.18273,79.64408,50.00000,0.0000e+000,20.00000,    -0.11308,0.98619
224.08701, 33.17167,    -0.18921,79.62661,50.00000,0.0000e+000,20.00000,    -0.11089,0.98409
225.81100, 33.35167,    -0.19526,79.60900,50.00000,0.0000e+000,20.00000,    -0.10938,0.98199
227.53900, 33.53167,    -0.20174,79.59046,50.00000,0.0000e+000,20.00000,    -0.10770,0.97990
229.24300, 33.71167,    -0.20784,79.56989,50.00000,0.0000e+000,20.00000,    -0.10575,0.97783
230.95200, 33.89167,    -0.21408,79.54987,50.00000,0.0000e+000,20.00000,    -0.10391,0.97576
232.67400, 34.07167,    -0.22038,79.53471,50.00000,0.0000e+000,20.00000,    -0.10283,0.97369
234.38100, 34.25167,    -0.22635,79.51852,50.00000,0.0000e+000,20.00000,    -0.10178,0.97163
236.09700, 34.43167,    -0.23245,79.50039,50.00000,0.0000e+000,20.00000,    -0.10064,0.96957
237.81100, 34.61167,    -0.23904,79.48068,50.00000,0.0000e+000,20.00000,    -0.10023,0.96751
239.54100, 34.79167,    -0.24582,79.46224,50.00000,0.0000e+000,20.00000,    -0.10009,0.96544
241.24699, 34.97167,    -0.25212,79.44418,50.00000,0.0000e+000,20.00000,    -0.10031,0.96341
242.97000, 35.15167,    -0.25782,79.42468,50.00000,0.0000e+000,20.00000,    -0.10031,0.96135
244.68201, 35.33167,    -0.26322,79.40649,50.00000,0.0000e+000,20.00000,-9.9885e-002,0.95932
246.41200, 35.51167,    -0.26856,79.38956,50.00000,0.0000e+000,20.00000,-9.9003e-002,0.95727
248.11700, 35.69167,    -0.27351,79.37355,50.00000,0.0000e+000,20.00000,-9.8266e-002,0.95525
249.84100, 35.87167,    -0.27815,79.35607,50.00000,0.0000e+000,20.00000,-9.8988e-002,0.95322
251.55200, 36.05167,    -0.28312,79.33803,50.00000,0.0000e+000,20.00000,-9.9670e-002,0.95120
253.26401, 36.23167,    -0.28819,79.31991,50.00000,0.0000e+000,20.00000,-9.9379e-002,0.94919
254.96899, 36.41167,    -0.29348,79.30195,50.00000,0.0000e+000,20.00000,-9.8640e-002,0.94719
256.69000, 36.59167,    -0.29878,79.28395,50.00000,0.0000e+000,20.00000,-9.8446e-002,0.94518
258.41101, 36.77167,    -0.30396,79.26532,50.00000,0.0000e+000,20.00000,-9.8676e-002,0.94317
260.12399, 36.95167,    -0.30944,79.24776,50.00000,0.0000e+000,20.00000,-9.8220e-002,0.94118
261.87399, 37.13167,    -0.31527,79.23082,50.00000,0.0000e+000,20.00000,-9.8214e-002,0.93915
263.56900, 37.31167,    -0.31982,79.21400,50.00000,0.0000e+000,20.00000,-9.8877e-002,0.93718
265.30200, 37.49166,    -0.32466,79.19619,50.00000,0.0000e+000,20.00000,    -0.10004,0.93518
267.02399, 37.67167,    -0.32907,79.17794,50.00000,0.0000e+000,20.00000,    -0.10123,0.93319
268.75900, 37.85167,    -0.33358,79.15962,50.00000,0.0000e+000,20.00000,    -0.10161,0.93120
270.47501, 38.03167,    -0.33784,79.14251,50.00000,0.0000e+000,20.00000,    -0.10204,0.92923
272.21500, 38.21167,    -0.34220,79.12586,50.00000,0.0000e+000,20.00000,    -0.10248,0.92724
273.94000, 38.39167,    -0.34684,79.10791,50.00000,0.0000e+000,20.00000,    -0.10326,0.92527
275.67899, 38.57167,    -0.35148,79.08923,50.00000,0.0000e+000,20.00000,    -0.10409,0.92329
277.42200, 38.75167,    -0.35625,79.07133,50.00000,0.0000e+000,20.00000,    -0.10557,0.92131
279.13101, 38.93167,    -0.36166,79.05312,50.00000,0.0000e+000,20.00000,    -0.10748,0.91938
280.89200, 39.11167,    -0.36683,79.03367,50.00000,0.0000e+000,20.00000,    -0.10909,0.91739
282.64200, 39.29167,    -0.37166,79.01360,50.00000,0.0000e+000,20.00000,    -0.11074,0.91542
284.37601, 39.47167,    -0.37638,78.99206,50.00000,0.0000e+000,20.00000,    -0.11244,0.91347
286.13400, 39.65167,    -0.38123,78.97228,50.00000,0.0000e+000,20.00000,    -0.11380,0.91150
287.88101, 39.83167,    -0.38532,78.95279,50.00000,0.0000e+000,20.00000,    -0.11555,0.90955
289.62601, 40.01167,    -0.39003,78.93309,50.00000,0.0000e+000,20.00000,    -0.11779,0.90760
291.38199, 40.19167,    -0.39454,78.91263,50.00000,0.0000e+000,20.00000,    -0.11948,0.90565
293.12500, 40.37167,    -0.39900,78.89099,50.00000,0.0000e+000,20.00000,    -0.12135,0.90372
294.88400, 40.55167,    -0.40325,78.86823,50.00000,0.0000e+000,20.00000,    -0.12386,0.90177
296.65500, 40.73167,    -0.40770,78.84409,50.00000,0.0000e+000,20.00000,    -0.12667,0.89982
298.41400, 40.91167,    -0.41139,78.82137,50.00000,0.0000e+000,20.00000,    -0.12944,0.89789
300.18600, 41.09167,    -0.41517,78.79796,50.00000,0.0000e+000,20.00000,    -0.13237,0.89595
301.92700, 41.27167,    -0.41865,78.77342,50.00000,0.0000e+000,20.00000,    -0.13523,0.89404
303.69199, 41.45167,    -0.42197,78.74997,50.00000,0.0000e+000,20.00000,    -0.13771,0.89212
305.44800, 41.63167,    -0.42530,78.72643,50.00000,0.0000e+000,20.00000,    -0.14039,0.89021
307.20801, 41.81167,    -0.42830,78.70165,50.00000,0.0000e+000,20.00000,    -0.14356,0.88830
308.96500, 41.99166,    -0.43071,78.67773,50.00000,0.0000e+000,20.00000,    -0.14676,0.88640
310.72000, 42.17167,    -0.43390,78.65256,50.00000,0.0000e+000,20.00000,    -0.14958,0.88451
312.48099, 42.35167,    -0.43663,78.62553,50.00000,0.0000e+000,20.00000,    -0.15228,0.88262
314.23599, 42.53167,    -0.43936,78.59745,50.00000,0.0000e+000,20.00000,    -0.15455,0.88074
315.98999, 42.71167,    -0.44231,78.56809,50.00000,0.0000e+000,20.00000,    -0.15685,0.87887
317.74600, 42.89167,    -0.44507,78.53779,50.00000,0.0000e+000,20.00000,    -0.15899,0.87700
319.51700, 43.07167,    -0.44770,78.50586,50.00000,0.0000e+000,20.00000,    -0.16058,0.87511
321.28400, 43.25167,    -0.45064,78.47613,50.00000,0.0000e+000,20.00000,    -0.16197,0.87324
323.06299, 43.43167,    -0.45458,78.44733,50.00000,0.0000e+000,20.00000,    -0.16304,0.87137
324.85400, 43.61167,    -0.45866,78.41623,50.00000,0.0000e+000,20.00000,    -0.16351,0.86948
326.63800, 43.79167,    -0.46274,78.38433,50.00000,0.0000e+000,20.00000,    -0.16426,0.86761
328.41699, 43.97167,    -0.46623,78.35247,50.00000,0.0000e+000,20.00000,    -0.16445,0.86575
330.20700, 44.15167,    -0.47012,78.32030,50.00000,0.0000e+000,20.00000,    -0.16373,0.86388
331.97400, 44.33167,    -0.47386,78.28768,50.00000,0.0000e+000,20.00000,    -0.16245,0.86204
333.74200, 44.51167,    -0.47848,78.25630,50.00000,0.0000e+000,20.00000,    -0.16067,0.86021
335.52600, 44.69167,    -0.48439,78.22525,50.00000,0.0000e+000,20.00000,    -0.15894,0.85837
337.29501, 44.87167,    -0.49123,78.19478,50.00000,0.0000e+000,20.00000,    -0.15651,0.85655
339.08801, 45.05167,    -0.49869,78.16576,50.00000,0.0000e+000,20.00000,    -0.15371,0.85471
340.87500, 45.23167,    -0.50613,78.13831,50.00000,0.0000e+000,20.00000,    -0.15146,0.85288
342.65500, 45.41167,    -0.51299,78.11185,50.00000,0.0000e+000,20.00000,    -0.14903,0.85106
344.44699, 45.59167,    -0.51950,78.08505,50.00000,0.0000e+000,20.00000,    -0.14588,0.84924
346.20599, 45.77167,    -0.52684,78.05928,50.00000,0.0000e+000,20.00000,    -0.14201,0.84746
347.98499, 45.95167,    -0.53417,78.03490,50.00000,0.0000e+000,20.00000,    -0.13820,0.84566
349.74701, 46.13167,    -0.54171,78.01159,50.00000,0.0000e+000,20.00000,    -0.13459,0.84389
351.52200, 46.31167,    -0.54944,77.98882,50.00000,0.0000e+000,20.00000,    -0.13082,0.84210
353.29401, 46.49166,    -0.55692,77.96535,50.00000,0.0000e+000,20.00000,    -0.12691,0.84033
355.06299, 46.67167,    -0.56510,77.94193,50.00000,0.0000e+000,20.00000,    -0.12299,0.83857
356.83600, 46.85167,    -0.57334,77.92167,50.00000,0.0000e+000,20.00000,    -0.11922,0.83681
358.61401, 47.03167,    -0.58119,77.90151,50.00000,0.0000e+000,20.00000,    -0.11566,0.83504
360.39001, 47.21167,    -0.58966,77.87972,50.00000,0.0000e+000,20.00000,    -0.11227,0.83329
362.20300, 47.39167,    -0.59787,77.85890,50.00000,0.0000e+000,20.00000,    -0.10864,0.83151
363.99100, 47.57167,    -0.60561,77.84097,50.00000,0.0000e+000,20.00000,    -0.10470,0.82975
365.78900, 47.75167,    -0.61277,77.82301,50.00000,0.0000e+000,20.00000,    -0.10167,0.82800
367.58701, 47.93167,    -0.61850,77.80364,50.00000,0.0000e+000,20.00000,-9.9164e-002,0.82625
369.36801, 48.11167,    -0.62471,77.78547,50.00000,0.0000e+000,20.00000,-9.6685e-002,0.82452
371.14401, 48.29167,    -0.63029,77.76870,50.00000,0.0000e+000,20.00000,-9.4041e-002,0.82280
372.94101, 48.47167,    -0.63726,77.75224,50.00000,0.0000e+000,20.00000,-9.1373e-002,0.82107
374.74500, 48.65167,    -0.64541,77.73667,50.00000,0.0000e+000,20.00000,-8.9301e-002,0.81933
376.57300, 48.83167,    -0.65564,77.72183,50.00000,0.0000e+000,20.00000,-8.7315e-002,0.81758
378.41501, 49.01167,    -0.66450,77.70775,50.00000,0.0000e+000,20.00000,-8.4917e-002,0.81583
380.24301, 49.19167,    -0.67149,77.69393,50.00000,0.0000e+000,20.00000,-8.2613e-002,0.81409
382.05200, 49.37167,    -0.67592,77.68224,50.00000,0.0000e+000,20.00000,-8.1004e-002,0.81238
383.85599, 49.55167,    -0.67864,77.66915,50.00000,0.0000e+000,20.00000,-7.9046e-002,0.81067
385.65201, 49.73167,    -0.68046,77.65481,50.00000,0.0000e+000,20.00000,-7.6432e-002,0.80898
387.43201, 49.91167,    -0.68341,77.64097,50.00000,0.0000e+000,20.00000,-7.4135e-002,0.80732
389.20300, 50.09167,    -0.68771,77.62744,50.00000,0.0000e+000,20.00000,-7.2239e-002,0.80566
390.97699, 50.27167,    -0.69278,77.61344,50.00000,0.0000e+000,20.00000,-7.0108e-002,0.80401
392.74301, 50.45167,    -0.69766,77.60021,50.00000,0.0000e+000,20.00000,-6.8448e-002,0.80238
394.51599, 50.63167,    -0.70254,77.58750,50.00000,0.0000e+000,20.00000,-6.7609e-002,0.80074
396.28299, 50.81167,    -0.70823,77.57472,50.00000,0.0000e+000,20.00000,-6.7196e-002,0.79911
398.05600, 50.99166,    -0.71322,77.56184,50.00000,0.0000e+000,20.00000,-6.6728e-002,0.79749
399.80301, 51.17167,    -0.71809,77.54939,50.00000,0.0000e+000,20.00000,-6.6716e-002,0.79589
401.56299, 51.35167,    -0.72253,77.53841,50.00000,0.0000e+000,20.00000,-6.6383e-002,0.79429
403.33401, 51.53167,    -0.72739,77.52879,50.00000,0.0000e+000,20.00000,-6.5553e-002,0.79268
405.09601, 51.71167,    -0.73298,77.51866,50.00000,0.0000e+000,20.00000,-6.5572e-002,0.79109
406.86899, 51.89167,    -0.73898,77.50871,50.00000,0.0000e+000,20.00000,-6.5953e-002,0.78949
408.65100, 52.07167,    -0.74517,77.49971,50.00000,0.0000e+000,20.00000,-6.5396e-002,0.78789
410.42700, 52.25167,    -0.75106,77.49052,50.00000,0.0000e+000,20.00000,-6.5430e-002,0.78630
412.22601, 52.43167,    -0.75636,77.47879,50.00000,0.0000e+000,20.00000,-6.5080e-002,0.78470
414.02701, 52.61167,    -0.76079,77.46627,50.00000,0.0000e+000,20.00000,-6.3646e-002,0.78310
415.81299, 52.79167,    -0.76379,77.45385,50.00000,0.0000e+000,20.00000,-6.2489e-002,0.78152
417.59299, 52.97167,    -0.76750,77.44196,50.00000,0.0000e+000,20.00000,-6.1559e-002,0.77996
419.36499, 53.15167,    -0.77178,77.43038,50.00000,0.0000e+000,20.00000,-6.1042e-002,0.77840
421.16599, 53.33167,    -0.77640,77.41920,50.00000,0.0000e+000,20.00000,-6.0658e-002,0.77683
422.95001, 53.51167,    -0.78145,77.40576,50.00000,0.0000e+000,20.00000,-6.0099e-002,0.77527
424.73901, 53.69167,    -0.78654,77.39053,50.00000,0.0000e+000,20.00000,-5.9723e-002,0.77372
426.52301, 53.87167,    -0.79239,77.37833,50.00000,0.0000e+000,20.00000,-5.9491e-002,0.77218
428.31900, 54.05167,    -0.79843,77.36523,50.00000,0.0000e+000,20.00000,-5.9012e-002,0.77063
430.08899, 54.23167,    -0.80453,77.35287,50.00000,0.0000e+000,20.00000,-5.7743e-002,0.76912
431.87799, 54.41167,    -0.80991,77.34526,50.00000,0.0000e+000,20.00000,-5.6297e-002,0.76759
433.67401, 54.59167,    -0.81653,77.33676,50.00000,0.0000e+000,20.00000,-5.4929e-002,0.76606
435.47000, 54.77167,    -0.82307,77.32767,50.00000,0.0000e+000,20.00000,-5.3916e-002,0.76454
437.26700, 54.95167,    -0.82940,77.31824,50.00000,0.0000e+000,20.00000,-5.3013e-002,0.76302
439.06799, 55.13167,    -0.83491,77.30975,50.00000,0.0000e+000,20.00000,-5.1943e-002,0.76151
440.85101, 55.31167,    -0.83929,77.30183,50.00000,0.0000e+000,20.00000,-4.9930e-002,0.76001
442.63101, 55.49166,    -0.84322,77.29327,50.00000,0.0000e+000,20.00000,-4.7498e-002,0.75853
444.41501, 55.67167,    -0.84778,77.28472,50.00000,0.0000e+000,20.00000,-4.6152e-002,0.75704
446.21799, 55.85167,    -0.85337,77.27747,50.00000,0.0000e+000,20.00000,-4.4683e-002,0.75555
448.01501, 56.03167,    -0.85946,77.27068,50.00000,0.0000e+000,20.00000,-4.2857e-002,0.75407
449.82501, 56.21167,    -0.86625,77.26355,50.00000,0.0000e+000,20.00000,-4.2607e-002,0.75258
451.62701, 56.39167,    -0.87038,77.25612,50.00000,0.0000e+000,20.00000,-4.2260e-002,0.75111
453.43100, 56.57167,    -0.87401,77.24799,50.00000,0.0000e+000,20.00000,-4.1713e-002,0.74964
455.21899, 56.75167,    -0.87729,77.23959,50.00000,0.0000e+000,20.00000,-4.0969e-002,0.74819
456.99600, 56.93167,    -0.88073,77.23208,50.00000,0.0000e+000,20.00000,-4.0062e-002,0.74675
458.78900, 57.11167,    -0.88463,77.22638,50.00000,0.0000e+000,20.00000,-3.9697e-002,0.74531
460.57999, 57.29167,    -0.88848,77.22022,50.00000,0.0000e+000,20.00000,-3.9298e-002,0.74387
462.36200, 57.47167,    -0.89299,77.21257,50.00000,0.0000e+000,20.00000,-3.8287e-002,0.74245
464.14899, 57.65167,    -0.89790,77.20517,50.00000,0.0000e+000,20.00000,-3.8189e-002,0.74103
465.94800, 57.83167,    -0.90258,77.19869,50.00000,0.0000e+000,20.00000,-3.8218e-002,0.73961
467.74301, 58.01167,    -0.90763,77.19177,50.00000,0.0000e+000,20.00000,-3.8439e-002,0.73819
469.55399, 58.19167,    -0.91248,77.18472,50.00000,0.0000e+000,20.00000,-3.8522e-002,0.73677
471.34698, 58.37167,    -0.91533,77.17772,50.00000,0.0000e+000,20.00000,-3.8212e-002,0.73536
473.13699, 58.55167,    -0.91709,77.17085,50.00000,0.0000e+000,20.00000,-3.8001e-002,0.73397
474.91199, 58.73167,    -0.91914,77.16535,50.00000,0.0000e+000,20.00000,-3.7908e-002,0.73259
476.68701, 58.91167,    -0.92129,77.15913,50.00000,0.0000e+000,20.00000,-3.7908e-002,0.73122
478.46201, 59.09167,    -0.92421,77.15187,50.00000,0.0000e+000,20.00000,-3.7969e-002,0.72986
480.22601, 59.27167,    -0.92718,77.14686,50.00000,0.0000e+000,20.00000,-3.7783e-002,0.72850
482.01099, 59.45167,    -0.93213,77.14007,50.00000,0.0000e+000,20.00000,-3.8547e-002,0.72714
483.81000, 59.63167,    -0.93751,77.13309,50.00000,0.0000e+000,20.00000,-3.9914e-002,0.72577
485.62500, 59.81167,    -0.94270,77.12546,50.00000,0.0000e+000,20.00000,-4.0627e-002,0.72440
487.40500, 59.99166,    -0.94700,77.11755,50.00000,0.0000e+000,20.00000,-4.1013e-002,0.72306
489.19000, 60.17167,    -0.94933,77.11070,50.00000,0.0000e+000,20.00000,-4.1459e-002,0.72172
490.97299, 60.35167,    -0.95143,77.10318,50.00000,0.0000e+000,20.00000,-4.2303e-002,0.72039
492.75900, 60.53167,    -0.95379,77.09558,50.00000,0.0000e+000,20.00000,-4.3306e-002,0.71906
494.54800, 60.71167,    -0.95674,77.08952,50.00000,0.0000e+000,20.00000,-4.3713e-002,0.71773
496.34299, 60.89167,    -0.96069,77.08349,50.00000,0.0000e+000,20.00000,-4.4240e-002,0.71641
498.12601, 61.07167,    -0.96522,77.07685,50.00000,0.0000e+000,20.00000,-4.5529e-002,0.71509
499.92999, 61.25167,    -0.96957,77.06718,50.00000,0.0000e+000,20.00000,-4.6588e-002,0.71377
501.74701, 61.43167,    -0.97534,77.05539,50.00000,0.0000e+000,20.00000,-4.8313e-002,0.71245
503.55899, 61.61167,    -0.98133,77.04575,50.00000,0.0000e+000,20.00000,-4.9911e-002,0.71114
505.39401, 61.79167,    -0.98719,77.03713,50.00000,0.0000e+000,20.00000,-5.0448e-002,0.70981
507.22299, 61.97167,    -0.99128,77.02868,50.00000,0.0000e+000,20.00000,-5.0346e-002,0.70849
509.00800, 62.15167,    -0.99131,77.01880,50.00000,0.0000e+000,20.00000,-5.0441e-002,0.70721
510.82300, 62.33167,    -0.98998,77.00908,50.00000,0.0000e+000,20.00000,-5.1694e-002,0.70592
512.59003, 62.51167,    -0.98898,77.00167,50.00000,0.0000e+000,20.00000,-5.3502e-002,0.70467
514.37500, 62.69167,    -0.99007,76.99269,50.00000,0.0000e+000,20.00000,-5.5378e-002,0.70340
516.14801, 62.87167,    -0.99285,76.98270,50.00000,0.0000e+000,20.00000,-5.6994e-002,0.70215
517.94800, 63.05167,    -0.99756,76.97271,50.00000,0.0000e+000,20.00000,-5.7556e-002,0.70089
519.76703, 63.23167,    -1.00237,76.95968,50.00000,0.0000e+000,20.00000,-5.7178e-002,0.69962
521.59698, 63.41167,    -1.00827,76.94618,50.00000,0.0000e+000,20.00000,-5.7628e-002,0.69835
523.41101, 63.59167,    -1.01301,76.93553,50.00000,0.0000e+000,20.00000,-5.8486e-002,0.69710
525.22101, 63.77167,    -1.01525,76.92862,50.00000,0.0000e+000,20.00000,-5.9346e-002,0.69585
527.02301, 63.95167,    -1.01591,76.92158,50.00000,0.0000e+000,20.00000,-6.0020e-002,0.69461
528.81403, 64.13167,    -1.01551,76.90969,50.00000,0.0000e+000,20.00000,-6.1329e-002,0.69339
530.59302, 64.31167,    -1.01450,76.89681,50.00000,0.0000e+000,20.00000,-6.3937e-002,0.69218
532.35797, 64.49167,    -1.01479,76.88396,50.00000,0.0000e+000,20.00000,-6.5676e-002,0.69098
534.11902, 64.67167,    -1.01479,76.87150,50.00000,0.0000e+000,20.00000,-6.6244e-002,0.68980
535.88397, 64.85167,    -1.01611,76.86014,50.00000,0.0000e+000,20.00000,-6.7144e-002,0.68861
537.65503, 65.03167,    -1.01803,76.84975,50.00000,0.0000e+000,20.00000,-6.7345e-002,0.68743
539.43298, 65.21167,    -1.02064,76.83834,50.00000,0.0000e+000,20.00000,-6.7327e-002,0.68624
541.20398, 65.39167,    -1.02440,76.82640,50.00000,0.0000e+000,20.00000,-6.8380e-002,0.68507
542.98901, 65.57166,    -1.02927,76.81490,50.00000,0.0000e+000,20.00000,-7.0875e-002,0.68389
544.78900, 65.75166,    -1.03373,76.80297,50.00000,0.0000e+000,20.00000,-7.3871e-002,0.68271
546.56897, 65.93166,    -1.03738,76.78875,50.00000,0.0000e+000,20.00000,-7.5027e-002,0.68154
548.37299, 66.11166,    -1.04103,76.77169,50.00000,0.0000e+000,20.00000,-7.5529e-002,0.68037
550.15997, 66.29166,    -1.04367,76.75619,50.00000,0.0000e+000,20.00000,-7.6323e-002,0.67921
551.95697, 66.47166,    -1.04583,76.74390,50.00000,0.0000e+000,20.00000,-7.7193e-002,0.67805
553.77100, 66.65166,    -1.05053,76.73104,50.00000,0.0000e+000,20.00000,-7.8207e-002,0.67688
555.56799, 66.83167,    -1.05440,76.71768,50.00000,0.0000e+000,20.00000,-8.0005e-002,0.67573
557.39203, 67.01167,    -1.05728,76.70420,50.00000,0.0000e+000,20.00000,-8.1937e-002,0.67457
559.19098, 67.19167,    -1.05835,76.68939,50.00000,0.0000e+000,20.00000,-8.3682e-002,0.67343
560.99402, 67.37167,    -1.06049,76.67306,50.00000,0.0000e+000,20.00000,-8.5346e-002,0.67229
562.79700, 67.55167,    -1.06298,76.65561,50.00000,0.0000e+000,20.00000,-8.6811e-002,0.67116
564.58197, 67.73167,    -1.06463,76.63964,50.00000,0.0000e+000,20.00000,-8.7470e-002,0.67004
566.39502, 67.91167,    -1.06716,76.62505,50.00000,0.0000e+000,20.00000,-8.7284e-002,0.66891
568.19598, 68.09167,    -1.06950,76.60939,50.00000,0.0000e+000,20.00000,-8.8081e-002,0.66779
570.00897, 68.27167,    -1.07162,76.59357,50.00000,0.0000e+000,20.00000,-8.9664e-002,0.66667
571.81799, 68.45167,    -1.07250,76.57832,50.00000,0.0000e+000,20.00000,-9.0590e-002,0.66556
573.61700, 68.63167,    -1.07419,76.56169,50.00000,0.0000e+000,20.00000,-9.1655e-002,0.66446
575.40900, 68.81167,    -1.07746,76.54348,50.00000,0.0000e+000,20.00000,-9.3004e-002,0.66337
577.22601, 68.99167,    -1.08072,76.52511,50.00000,0.0000e+000,20.00000,-9.3812e-002,0.66227
579.00800, 69.17167,    -1.08366,76.50735,50.00000,0.0000e+000,20.00000,-9.3582e-002,0.66119
580.80902, 69.35167,    -1.08670,76.49018,50.00000,0.0000e+000,20.00000,-9.3835e-002,0.66011
582.61200, 69.53167,    -1.08972,76.47381,50.00000,0.0000e+000,20.00000,-9.5044e-002,0.65903
584.43103, 69.71167,    -1.09380,76.45795,50.00000,0.0000e+000,20.00000,-9.6773e-002,0.65794
586.24402, 69.89167,    -1.09769,76.43935,50.00000,0.0000e+000,20.00000,-9.8243e-002,0.65686
588.03699, 70.07166,    -1.09893,76.42062,50.00000,0.0000e+000,20.00000,-9.9534e-002,0.65580
589.82098, 70.25166,    -1.09921,76.40439,50.00000,0.0000e+000,20.00000,    -0.10105,0.65476
591.62299, 70.43166,    -1.10087,76.38752,50.00000,0.0000e+000,20.00000,    -0.10248,0.65370
593.42902, 70.61166,    -1.10527,76.36915,50.00000,0.0000e+000,20.00000,    -0.10319,0.65265
595.21899, 70.79166,    -1.10778,76.35136,50.00000,0.0000e+000,20.00000,    -0.10363,0.65161
597.00897, 70.97166,    -1.11085,76.33601,50.00000,0.0000e+000,20.00000,    -0.10413,0.65057
598.80701, 71.15166,    -1.11289,76.31838,50.00000,0.0000e+000,20.00000,    -0.10490,0.64954
600.61700, 71.33167,    -1.11473,76.29771,50.00000,0.0000e+000,20.00000,    -0.10598,0.64850
602.40900, 71.51167,    -1.11755,76.27681,50.00000,0.0000e+000,20.00000,    -0.10751,0.64748
604.22900, 71.69167,    -1.12105,76.25597,50.00000,0.0000e+000,20.00000,    -0.10867,0.64644
606.05603, 71.87167,    -1.12689,76.23522,50.00000,0.0000e+000,20.00000,    -0.10992,0.64541
607.87097, 72.05167,    -1.13030,76.21464,50.00000,0.0000e+000,20.00000,    -0.11137,0.64439
609.67603, 72.23167,    -1.13205,76.19303,50.00000,0.0000e+000,20.00000,    -0.11297,0.64338
611.47900, 72.41167,    -1.13252,76.17224,50.00000,0.0000e+000,20.00000,    -0.11442,0.64237
613.26801, 72.59167,    -1.13151,76.15216,50.00000,0.0000e+000,20.00000,    -0.11617,0.64138
615.06403, 72.77167,    -1.13212,76.13244,50.00000,0.0000e+000,20.00000,    -0.11858,0.64038
616.86700, 72.95167,    -1.13442,76.11249,50.00000,0.0000e+000,20.00000,    -0.12064,0.63939
618.67603, 73.13167,    -1.13771,76.09202,50.00000,0.0000e+000,20.00000,    -0.12194,0.63840
620.46399, 73.31167,    -1.13979,76.07087,50.00000,0.0000e+000,20.00000,    -0.12320,0.63742
622.26801, 73.49167,    -1.14026,76.04869,50.00000,0.0000e+000,20.00000,    -0.12410,0.63644
624.05798, 73.67167,    -1.14157,76.02506,50.00000,0.0000e+000,20.00000,    -0.12491,0.63547
625.83099, 73.85167,    -1.14252,76.00302,50.00000,0.0000e+000,20.00000,    -0.12627,0.63452
627.61401, 74.03167,    -1.14314,75.98088,50.00000,0.0000e+000,20.00000,    -0.12777,0.63356
629.39502, 74.21167,    -1.14489,75.95740,50.00000,0.0000e+000,20.00000,    -0.13014,0.63261
631.21002, 74.39167,    -1.14895,75.93310,50.00000,0.0000e+000,20.00000,    -0.13294,0.63164
633.01398, 74.57166,    -1.15144,75.90868,50.00000,0.0000e+000,20.00000,    -0.13573,0.63069
634.82300, 74.75166,    -1.15417,75.88413,50.00000,0.0000e+000,20.00000,    -0.13838,0.62973
636.63000, 74.93166,    -1.15789,75.85917,50.00000,0.0000e+000,20.00000,    -0.14052,0.62878
638.48700, 75.11166,    -1.16446,75.83350,50.00000,0.0000e+000,20.00000,    -0.14293,0.62781
640.34900, 75.29166,    -1.17250,75.80916,50.00000,0.0000e+000,20.00000,    -0.14552,0.62684
642.18799, 75.47166,    -1.17450,75.78553,50.00000,0.0000e+000,20.00000,    -0.14733,0.62589
644.00702, 75.65166,    -1.17315,75.76031,50.00000,0.0000e+000,20.00000,    -0.14934,0.62495
645.81598, 75.83167,    -1.17010,75.73361,50.00000,0.0000e+000,20.00000,    -0.15167,0.62402
647.61902, 76.01167,    -1.16640,75.70436,50.00000,0.0000e+000,20.00000,    -0.15436,0.62310
649.40002, 76.19167,    -1.16197,75.67390,50.00000,0.0000e+000,20.00000,    -0.15665,0.62219
651.18402, 76.37167,    -1.16090,75.64393,50.00000,0.0000e+000,20.00000,    -0.15841,0.62128
652.97400, 76.55167,    -1.16090,75.61422,50.00000,0.0000e+000,20.00000,    -0.16016,0.62038
654.75403, 76.73167,    -1.16192,75.58591,50.00000,0.0000e+000,20.00000,    -0.16185,0.61948
656.55603, 76.91167,    -1.16270,75.55649,50.00000,0.0000e+000,20.00000,    -0.16368,0.61858
658.34802, 77.09167,    -1.16281,75.52510,50.00000,0.0000e+000,20.00000,    -0.16586,0.61769
660.13898, 77.27167,    -1.16342,75.49467,50.00000,0.0000e+000,20.00000,    -0.16831,0.61680
661.93402, 77.45167,    -1.16440,75.46500,50.00000,0.0000e+000,20.00000,    -0.16994,0.61591
663.73999, 77.63167,    -1.16419,75.43487,50.00000,0.0000e+000,20.00000,    -0.17041,0.61502
665.52600, 77.81167,    -1.16328,75.40199,50.00000,0.0000e+000,20.00000,    -0.17050,0.61414
667.30499, 77.99167,    -1.16239,75.36910,50.00000,0.0000e+000,20.00000,    -0.17081,0.61327
669.09497, 78.17167,    -1.16153,75.33818,50.00000,0.0000e+000,20.00000,    -0.17159,0.61240
670.90100, 78.35167,    -1.16078,75.30718,50.00000,0.0000e+000,20.00000,    -0.17253,0.61153
672.68799, 78.53167,    -1.16092,75.27634,50.00000,0.0000e+000,20.00000,    -0.17374,0.61066
674.48901, 78.71167,    -1.16120,75.24412,50.00000,0.0000e+000,20.00000,    -0.17470,0.60980
676.28998, 78.89167,    -1.16211,75.21147,50.00000,0.0000e+000,20.00000,    -0.17494,0.60893
678.10699, 79.07166,    -1.16312,75.17902,50.00000,0.0000e+000,20.00000,    -0.17547,0.60807
679.90302, 79.25166,    -1.16255,75.14760,50.00000,0.0000e+000,20.00000,    -0.17608,0.60721
681.70203, 79.43166,    -1.16135,75.11925,50.00000,0.0000e+000,20.00000,    -0.17625,0.60636
683.50897, 79.61166,    -1.16025,75.09043,50.00000,0.0000e+000,20.00000,    -0.17531,0.60551
685.29303, 79.79166,    -1.15938,75.05917,50.00000,0.0000e+000,20.00000,    -0.17359,0.60467
687.11200, 79.97166,    -1.15663,75.02639,50.00000,0.0000e+000,20.00000,    -0.17223,0.60382
688.90198, 80.15166,    -1.15355,74.99315,50.00000,0.0000e+000,20.00000,    -0.17104,0.60299
690.71198, 80.33167,    -1.15228,74.96020,50.00000,0.0000e+000,20.00000,    -0.16978,0.60215
692.51703, 80.51167,    -1.15094,74.92756,50.00000,0.0000e+000,20.00000,    -0.16778,0.60132
694.33002, 80.69167,    -1.14984,74.89542,50.00000,0.0000e+000,20.00000,    -0.16558,0.60048
696.13000, 80.87167,    -1.14756,74.86290,50.00000,0.0000e+000,20.00000,    -0.16332,0.59966
697.92700, 81.05167,    -1.14540,74.83072,50.00000,0.0000e+000,20.00000,    -0.16059,0.59884
699.74500, 81.23167,    -1.14539,74.80003,50.00000,0.0000e+000,20.00000,    -0.15854,0.59801
701.56097, 81.41167,    -1.14951,74.77064,50.00000,0.0000e+000,20.00000,    -0.15673,0.59719
703.38098, 81.59167,    -1.15132,74.74351,50.00000,0.0000e+000,20.00000,    -0.15358,0.59636
705.18402, 81.77167,    -1.14821,74.71740,50.00000,0.0000e+000,20.00000,    -0.14965,0.59555
706.96899, 81.95167,    -1.14482,74.69085,50.00000,0.0000e+000,20.00000,    -0.14583,0.59475
708.78302, 82.13167,    -1.14461,74.66444,50.00000,0.0000e+000,20.00000,    -0.14220,0.59394
710.58698, 82.31167,    -1.14501,74.63962,50.00000,0.0000e+000,20.00000,    -0.13841,0.59314
712.39801, 82.49167,    -1.14478,74.61503,50.00000,0.0000e+000,20.00000,    -0.13430,0.59234
714.19397, 82.67167,    -1.14329,74.59061,50.00000,0.0000e+000,20.00000,    -0.12965,0.59155
716.00500, 82.85167,    -1.14348,74.56842,50.00000,0.0000e+000,20.00000,    -0.12429,0.59075
717.82800, 83.03167,    -1.14206,74.54734,50.00000,0.0000e+000,20.00000,    -0.11961,0.58995
719.63898, 83.21167,    -1.14002,74.52540,50.00000,0.0000e+000,20.00000,    -0.11539,0.58916
721.44702, 83.39167,    -1.13854,74.50553,50.00000,0.0000e+000,20.00000,    -0.11186,0.58838
723.24103, 83.57166,    -1.13643,74.48732,50.00000,0.0000e+000,20.00000,    -0.10881,0.58760
725.03601, 83.75166,    -1.13359,74.46821,50.00000,0.0000e+000,20.00000,    -0.10575,0.58683
726.82397, 83.93166,    -1.12986,74.44847,50.00000,0.0000e+000,20.00000,    -0.10166,0.58606
728.61200, 84.11166,    -1.12625,74.42937,50.00000,0.0000e+000,20.00000,-9.7995e-002,0.58529
730.40198, 84.29166,    -1.12323,74.41201,50.00000,0.0000e+000,20.00000,-9.4846e-002,0.58453
732.20099, 84.47166,    -1.12014,74.39614,50.00000,0.0000e+000,20.00000,-9.2034e-002,0.58376
734.00299, 84.65166,    -1.11750,74.38322,50.00000,0.0000e+000,20.00000,-8.9019e-002,0.58300
735.81097, 84.83167,    -1.11432,74.36964,50.00000,0.0000e+000,20.00000,-8.5953e-002,0.58223
737.63000, 85.01167,    -1.11311,74.35541,50.00000,0.0000e+000,20.00000,-8.3208e-002,0.58147
739.46301, 85.19167,    -1.11277,74.34096,50.00000,0.0000e+000,20.00000,-8.1286e-002,0.58070
741.26801, 85.37167,    -1.10989,74.32607,50.00000,0.0000e+000,20.00000,-7.9717e-002,0.57994
743.05798, 85.55167,    -1.10554,74.31053,50.00000,0.0000e+000,20.00000,-7.7853e-002,0.57919
744.85498, 85.73167,    -1.10027,74.29851,50.00000,0.0000e+000,20.00000,-7.5367e-002,0.57845
746.65698, 85.91167,    -1.09742,74.28703,50.00000,0.0000e+000,20.00000,-7.2542e-002,0.57770
748.44299, 86.09167,    -1.09484,74.27429,50.00000,0.0000e+000,20.00000,-7.0669e-002,0.57696
750.25000, 86.27167,    -1.08997,74.25996,50.00000,0.0000e+000,20.00000,-6.9581e-002,0.57622
752.03998, 86.45167,    -1.08639,74.24781,50.00000,0.0000e+000,20.00000,-6.8877e-002,0.57549
753.86603, 86.63167,    -1.08394,74.23807,50.00000,0.0000e+000,20.00000,-6.7439e-002,0.57474
755.66803, 86.81167,    -1.08254,74.22656,50.00000,0.0000e+000,20.00000,-6.6368e-002,0.57401
757.48798, 86.99167,    -1.08224,74.21328,50.00000,0.0000e+000,20.00000,-6.5070e-002,0.57327
759.27100, 87.17167,    -1.07997,74.20062,50.00000,0.0000e+000,20.00000,-6.3068e-002,0.57255
761.09698, 87.35167,    -1.07809,74.18848,50.00000,0.0000e+000,20.00000,-6.1400e-002,0.57181
762.92200, 87.53167,    -1.07668,74.17744,50.00000,0.0000e+000,20.00000,-6.1017e-002,0.57107
764.78400, 87.71167,    -1.07915,74.16851,50.00000,0.0000e+000,20.00000,-6.0745e-002,0.57033
766.59497, 87.89167,    -1.07851,74.15804,50.00000,0.0000e+000,20.00000,-5.9905e-002,0.56960
768.41199, 88.07166,    -1.07547,74.14596,50.00000,0.0000e+000,20.00000,-5.8808e-002,0.56888
770.20203, 88.25166,    -1.07185,74.13476,50.00000,0.0000e+000,20.00000,-5.8003e-002,0.56817
771.98901, 88.43166,    -1.06818,74.12662,50.00000,0.0000e+000,20.00000,-5.7885e-002,0.56746
773.78601, 88.61166,    -1.06797,74.11670,50.00000,0.0000e+000,20.00000,-5.7620e-002,0.56675
775.59302, 88.79166,    -1.06835,74.10661,50.00000,0.0000e+000,20.00000,-5.6950e-002,0.56604
777.39203, 88.97166,    -1.06772,74.09911,50.00000,0.0000e+000,20.00000,-5.6542e-002,0.56533
779.19000, 89.15166,    -1.06775,74.08998,50.00000,0.0000e+000,20.00000,-5.6140e-002,0.56463
780.96399, 89.33167,    -1.06802,74.07886,50.00000,0.0000e+000,20.00000,-5.5602e-002,0.56393
782.73798, 89.51167,    -1.06978,74.06831,50.00000,0.0000e+000,20.00000,-5.5306e-002,0.56324
784.52802, 89.69167,    -1.07065,74.05885,50.00000,0.0000e+000,20.00000,-5.4912e-002,0.56255
786.28998, 89.87167,    -1.06870,74.04881,50.00000,0.0000e+000,20.00000,-5.4201e-002,0.56187
788.08099, 90.05167,    -1.06915,74.03880,50.00000,0.0000e+000,20.00000,-5.4033e-002,0.56117
789.87201, 90.23167,    -1.07376,74.02955,50.00000,0.0000e+000,20.00000,-5.4779e-002,0.56048
791.67700, 90.41167,    -1.07749,74.01943,50.00000,0.0000e+000,20.00000,-5.5420e-002,0.55979
793.46301, 90.59167,    -1.07627,74.00889,50.00000,0.0000e+000,20.00000,-5.5605e-002,0.55911
795.27802, 90.77167,    -1.07740,73.99750,50.00000,0.0000e+000,20.00000,-5.6303e-002,0.55841
797.09003, 90.95167,    -1.08031,73.98677,50.00000,0.0000e+000,20.00000,-5.6703e-002,0.55772
798.89001, 91.13167,    -1.08160,73.97696,50.00000,0.0000e+000,20.00000,-5.6508e-002,0.55704
800.72498, 91.31167,    -1.08617,73.96907,50.00000,0.0000e+000,20.00000,-5.6659e-002,0.55634
802.57703, 91.49167,    -1.09164,73.96035,50.00000,0.0000e+000,20.00000,-5.7046e-002,0.55564
804.45300, 91.67167,    -1.09714,73.95135,50.00000,0.0000e+000,20.00000,-5.7310e-002,0.55493
806.28802, 91.85167,    -1.09966,73.94042,50.00000,0.0000e+000,20.00000,-5.8002e-002,0.55424
808.10498, 92.03167,    -1.09754,73.92940,50.00000,0.0000e+000,20.00000,-5.9204e-002,0.55356
809.88501, 92.21167,    -1.09622,73.91760,50.00000,0.0000e+000,20.00000,-6.0159e-002,0.55289
811.69202, 92.39167,    -1.09534,73.90636,50.00000,0.0000e+000,20.00000,-6.1022e-002,0.55221
813.51501, 92.57166,    -1.09782,73.89599,50.00000,0.0000e+000,20.00000,-6.1855e-002,0.55153
815.32202, 92.75166,    -1.09867,73.88585,50.00000,0.0000e+000,20.00000,-6.3062e-002,0.55086
817.10602, 92.93166,    -1.09787,73.87571,50.00000,0.0000e+000,20.00000,-6.4321e-002,0.55020
818.88599, 93.11166,    -1.09749,73.86447,50.00000,0.0000e+000,20.00000,-6.5873e-002,0.54954
820.66998, 93.29166,    -1.09774,73.85341,50.00000,0.0000e+000,20.00000,-6.7401e-002,0.54888
822.47803, 93.47166,    -1.09993,73.84268,50.00000,0.0000e+000,20.00000,-6.9832e-002,0.54821
824.24902, 93.65166,    -1.10028,73.83032,50.00000,0.0000e+000,20.00000,-7.1674e-002,0.54756
826.04602, 93.83167,    -1.09976,73.81665,50.00000,0.0000e+000,20.00000,-7.3556e-002,0.54690
827.86102, 94.01167,    -1.10323,73.80322,50.00000,0.0000e+000,20.00000,-7.5395e-002,0.54623
829.63599, 94.19167,    -1.10451,73.78960,50.00000,0.0000e+000,20.00000,-7.6795e-002,0.54559
831.42200, 94.37167,    -1.10362,73.77545,50.00000,0.0000e+000,20.00000,-7.9037e-002,0.54493
833.23199, 94.55167,    -1.10460,73.76019,50.00000,0.0000e+000,20.00000,-8.1486e-002,0.54427
835.05902, 94.73167,    -1.10975,73.74540,50.00000,0.0000e+000,20.00000,-8.3636e-002,0.54361
836.88098, 94.91167,    -1.11325,73.73156,50.00000,0.0000e+000,20.00000,-8.5977e-002,0.54295
838.72803, 95.09167,    -1.11746,73.71773,50.00000,0.0000e+000,20.00000,-8.8916e-002,0.54228
840.54700, 95.27167,    -1.11745,73.70040,50.00000,0.0000e+000,20.00000,-9.2219e-002,0.54162
842.36102, 95.45167,    -1.11416,73.68278,50.00000,0.0000e+000,20.00000,-9.5228e-002,0.54096
844.16498, 95.63167,    -1.11309,73.66510,50.00000,0.0000e+000,20.00000,-9.7629e-002,0.54031
845.94800, 95.81167,    -1.11276,73.64653,50.00000,0.0000e+000,20.00000,    -0.10001,0.53967
847.76099, 95.99167,    -1.11284,73.62988,50.00000,0.0000e+000,20.00000,    -0.10194,0.53902
849.56403, 96.17167,    -1.11175,73.61167,50.00000,0.0000e+000,20.00000,    -0.10396,0.53837
851.35699, 96.35167,    -1.11051,73.59235,50.00000,0.0000e+000,20.00000,    -0.10607,0.53773
853.15302, 96.53167,    -1.11115,73.57442,50.00000,0.0000e+000,20.00000,    -0.10810,0.53709
854.96899, 96.71167,    -1.11304,73.55515,50.00000,0.0000e+000,20.00000,    -0.10978,0.53644
856.78802, 96.89167,    -1.11424,73.53349,50.00000,0.0000e+000,20.00000,    -0.11209,0.53579
858.59802, 97.07166,    -1.11573,73.51081,50.00000,0.0000e+000,20.00000,    -0.11395,0.53515
860.41998, 97.25166,    -1.11427,73.48781,50.00000,0.0000e+000,20.00000,    -0.11520,0.53450
862.21802, 97.43166,    -1.11225,73.46525,50.00000,0.0000e+000,20.00000,    -0.11737,0.53386
864.01300, 97.61166,    -1.10978,73.44311,50.00000,0.0000e+000,20.00000,    -0.11969,0.53323
865.79401, 97.79166,    -1.10945,73.42214,50.00000,0.0000e+000,20.00000,    -0.12218,0.53259
867.59302, 97.97166,    -1.10888,73.40118,50.00000,0.0000e+000,20.00000,    -0.12390,0.53196
869.40198, 98.15166,    -1.11069,73.37833,50.00000,0.0000e+000,20.00000,    -0.12557,0.53132
871.21198, 98.33167,    -1.11177,73.35579,50.00000,0.0000e+000,20.00000,    -0.12769,0.53068
873.00201, 98.51167,    -1.10901,73.33540,50.00000,0.0000e+000,20.00000,    -0.12926,0.53005
874.81097, 98.69167,    -1.10858,73.31393,50.00000,0.0000e+000,20.00000,    -0.13054,0.52941
876.67603, 98.87167,    -1.11467,73.29020,50.00000,0.0000e+000,20.00000,    -0.13174,0.52876
878.51099, 99.05167,    -1.11503,73.26788,50.00000,0.0000e+000,20.00000,    -0.13288,0.52812
880.30103, 99.23167,    -1.11219,73.24298,50.00000,0.0000e+000,20.00000,    -0.13425,0.52749
882.06000, 99.41167,    -1.10499,73.21598,50.00000,0.0000e+000,20.00000,    -0.13547,0.52687
883.82397, 99.59167,    -1.10048,73.18957,50.00000,0.0000e+000,20.00000,    -0.13673,0.52625
885.61401, 99.77167,    -1.10009,73.16553,50.00000,0.0000e+000,20.00000,    -0.13848,0.52563
887.41302, 99.95167,    -1.10174,73.14022,50.00000,0.0000e+000,20.00000,    -0.14013,0.52500
889.22803,100.13167,    -1.10485,73.11428,50.00000,0.0000e+000,20.00000,    -0.14160,0.52437
891.08502,100.31167,    -1.10911,73.08963,50.00000,0.0000e+000,20.00000,    -0.14388,0.52372
892.94897,100.49167,    -1.11555,73.06384,50.00000,0.0000e+000,20.00000,    -0.14613,0.52307
894.77698,100.67167,    -1.11501,73.03694,50.00000,0.0000e+000,20.00000,    -0.14771,0.52244
896.58600,100.85167,    -1.11393,73.00983,50.00000,0.0000e+000,20.00000,    -0.14963,0.52181
898.41101,101.03167,    -1.11338,72.98218,50.00000,0.0000e+000,20.00000,    -0.15117,0.52117
900.21997,101.21167,    -1.11184,72.95531,50.00000,0.0000e+000,20.00000,    -0.15228,0.52054
902.00500,101.39167,    -1.10920,72.92944,50.00000,0.0000e+000,20.00000,    -0.15335,0.51992
903.79901,101.57166,    -1.10805,72.90272,50.00000,0.0000e+000,20.00000,    -0.15491,0.51930
905.58301,101.75166,    -1.10716,72.87403,50.00000,0.0000e+000,20.00000,    -0.15650,0.51868
907.37201,101.93166,    -1.10631,72.84591,50.00000,0.0000e+000,20.00000,    -0.15756,0.51807
909.15802,102.11166,    -1.10684,72.81703,50.00000,0.0000e+000,20.00000,    -0.15840,0.51745
910.94299,102.29166,    -1.10628,72.78779,50.00000,0.0000e+000,20.00000,    -0.15896,0.51683
912.74799,102.47166,    -1.10731,72.75840,50.00000,0.0000e+000,20.00000,    -0.15963,0.51621
914.55902,102.65166,    -1.10824,72.72889,50.00000,0.0000e+000,20.00000,    -0.16073,0.51558
916.38098,102.83167,    -1.10986,72.69915,50.00000,0.0000e+000,20.00000,    -0.16179,0.51495
918.21399,103.01167,    -1.11210,72.66828,50.00000,0.0000e+000,20.00000,    -0.16246,0.51432
920.03101,103.19167,    -1.11209,72.63755,50.00000,0.0000e+000,20.00000,    -0.16359,0.51369
921.84302,103.37167,    -1.11231,72.60759,50.00000,0.0000e+000,20.00000,    -0.16485,0.51307
923.63898,103.55167,    -1.10924,72.57692,50.00000,0.0000e+000,20.00000,    -0.16533,0.51245
925.42401,103.73167,    -1.10564,72.54668,50.00000,0.0000e+000,20.00000,    -0.16576,0.51183
927.19800,103.91167,    -1.10136,72.51860,50.00000,0.0000e+000,20.00000,    -0.16684,0.51122
929.00403,104.09167,    -1.09973,72.49121,50.00000,0.0000e+000,20.00000,    -0.16806,0.51060
930.81000,104.27167,    -1.09886,72.46222,50.00000,0.0000e+000,20.00000,    -0.16949,0.50998
932.63000,104.45167,    -1.09349,72.43135,50.00000,0.0000e+000,20.00000,    -0.17090,0.50935
934.41901,104.63167,    -1.08712,72.39979,50.00000,0.0000e+000,20.00000,    -0.17245,0.50873
936.22498,104.81167,    -1.08156,72.36995,50.00000,0.0000e+000,20.00000,    -0.17413,0.50811
937.99799,104.99167,    -1.07427,72.34019,50.00000,0.0000e+000,20.00000,    -0.17537,0.50750
939.78802,105.17167,    -1.06620,72.30919,50.00000,0.0000e+000,20.00000,    -0.17706,0.50688
941.59998,105.35167,    -1.05998,72.27863,50.00000,0.0000e+000,20.00000,    -0.17889,0.50626
943.50598,105.53167,    -1.06713,72.24906,50.00000,0.0000e+000,20.00000,    -0.18120,0.50560
945.42798,105.71167,    -1.07254,72.21683,50.00000,0.0000e+000,20.00000,    -0.18443,0.50494
947.26898,105.89167,    -1.06644,72.18316,50.00000,0.0000e+000,20.00000,    -0.18841,0.50431
949.08197,106.07166,    -1.05702,72.14878,50.00000,0.0000e+000,20.00000,    -0.19171,0.50369
950.88898,106.25166,    -1.05144,72.11398,50.00000,0.0000e+000,20.00000,    -0.19379,0.50306
952.68701,106.43166,    -1.04572,72.07905,50.00000,0.0000e+000,20.00000,    -0.19602,0.50244
954.45398,106.61166,    -1.03881,72.04212,50.00000,0.0000e+000,20.00000,    -0.19902,0.50184
956.20001,106.79166,    -1.03268,72.00661,50.00000,0.0000e+000,20.00000,    -0.20316,0.50123
957.97400,106.97166,    -1.03016,71.97065,50.00000,0.0000e+000,20.00000,    -0.20737,0.50062
959.80200,107.15166,    -1.03427,71.93356,50.00000,0.0000e+000,20.00000,    -0.21150,0.49999
961.56000,107.33167,    -1.03478,71.89497,50.00000,0.0000e+000,20.00000,    -0.21557,0.49939
963.29901,107.51167,    -1.02943,71.85490,50.00000,0.0000e+000,20.00000,    -0.21849,0.49879
965.08899,107.69167,    -1.03024,71.81329,50.00000,0.0000e+000,20.00000,    -0.22043,0.49817
966.86603,107.87167,    -1.03014,71.77204,50.00000,0.0000e+000,20.00000,    -0.22162,0.49756
968.64301,108.05167,    -1.03137,71.73372,50.00000,0.0000e+000,20.00000,    -0.22200,0.49694
970.47400,108.23167,    -1.03735,71.69427,50.00000,0.0000e+000,20.00000,    -0.22196,0.49631
972.32703,108.41167,    -1.04646,71.65347,50.00000,0.0000e+000,20.00000,    -0.22106,0.49567
974.15900,108.59167,    -1.05138,71.60931,50.00000,0.0000e+000,20.00000,    -0.21995,0.49504
975.96600,108.77167,    -1.05239,71.56307,50.00000,0.0000e+000,20.00000,    -0.21772,0.49441
977.77197,108.95167,    -1.05037,71.51708,50.00000,0.0000e+000,20.00000,    -0.21346,0.49379
979.57202,109.13167,    -1.05146,71.47240,50.00000,0.0000e+000,20.00000,    -0.20849,0.49317
981.34497,109.31167,    -1.05178,71.42971,50.00000,0.0000e+000,20.00000,    -0.20514,0.49255
983.15399,109.49167,    -1.05744,71.38876,50.00000,0.0000e+000,20.00000,    -0.20263,0.49193
984.91699,109.67167,    -1.05871,71.34981,50.00000,0.0000e+000,20.00000,    -0.20046,0.49132
986.71899,109.85167,    -1.06355,71.31324,50.00000,0.0000e+000,20.00000,    -0.19361,0.49069
988.50702,110.03167,    -1.06835,71.27851,50.00000,0.0000e+000,20.00000,    -0.18238,0.49007
990.32501,110.21167,    -1.07828,71.24474,50.00000,0.0000e+000,20.00000,    -0.17007,0.48944
992.16998,110.39167,    -1.09084,71.21276,50.00000,0.0000e+000,20.00000,    -0.15692,0.48880
994.00800,110.57166,    -1.10423,71.18424,50.00000,0.0000e+000,20.00000,    -0.14186,0.48816
995.84497,110.75166,    -1.11162,71.16214,50.00000,0.0000e+000,20.00000,    -0.11805,0.48752
997.65100,110.93166,    -1.11878,71.14205,50.00000,0.0000e+000,20.00000,    -0.10084,0.48689
998.40698,111.00667,    -1.12170,71.13520,50.00000,0.0000e+000,20.00000,-2.4837e-002,0.48663