File: book/some_content/TG_ExpDat_OPC9%DC28; 13-2-2025-2.csv
#FILE:                       ,OPC9%DC28; 13-2-2025.ngb-ds3
#FORMAT:                     ,NETZSCH5
#IDENTITY:                   ,GEOPOLYMER PASTE
#DECIMAL:                    ,POINT
#SEPARATOR:                  ,COMMA
#MTYPE:                      ,DSC
#INSTRUMENT:                 ,Microlab TU Delft
#PROJECT:                    ,
#DATE/TIME:                  ,13/02/2025 4:53:50 PM
#CORR. FILE:                 ,Blank with cover; 13-1-2025.ngb-bs3
#LABORATORY:                 ,TU Delft Micro Lab
#OPERATOR:                   ,Ahmed
#REMARK:                     ,under Argon atmosphere, 10K/min
#SAMPLE:                     ,OPC9%DC28
#SAMPLE MASS /mg:            ,37
#MATERIAL:                   ,Geopolymer paste
#REFERENCE:                  ,blank
#REFERENCE MASS /mg:         ,0
#TYPE OF CRUCIBLE:           ,DSC/TG pan Al2O3
#SAMPLE CRUCIBLE MASS /mg:   ,0
#REFERENCE CRUCIBLE MASS /mg:,0
#CORR. CODE:                 ,020
#EXO:                        ,-1
#RANGE:                      ,40/10.0(K/min)/1000
#SEGMENT:                    ,S2/2

##Temp./øC,Time/min,DSC/(mW/mg),Mass/%,Gas Flow(purge1)/(ml/min),Gas Flow(purge2)/(ml/min),Gas Flow(protective)/(ml/min),DTG/(%/min),Sensit./(uV/mW)
 40.74900, 15.47750, 1.3170e-002,98.70262,50.00000,0.0000e+000,20.00000,-5.4903e-002,1.22591
 40.78300, 15.65750, 1.3087e-002,98.69175,50.00000,0.0000e+000,20.00000,-5.1883e-002,1.22586
 40.84100, 15.83750, 1.3138e-002,98.67936,50.00000,0.0000e+000,20.00000,-5.0688e-002,1.22578
 40.95400, 16.01750, 1.3863e-002,98.66927,50.00000,0.0000e+000,20.00000,-4.7524e-002,1.22563
 41.16300, 16.19750, 1.4556e-002,98.66167,50.00000,0.0000e+000,20.00000,-4.6509e-002,1.22534
 41.42700, 16.37750, 1.5907e-002,98.65371,50.00000,0.0000e+000,20.00000,-4.6302e-002,1.22497
 41.76400, 16.55750, 1.7496e-002,98.64515,50.00000,0.0000e+000,20.00000,-4.6093e-002,1.22451
 42.19300, 16.73750, 1.9762e-002,98.63748,50.00000,0.0000e+000,20.00000,-4.6516e-002,1.22392
 42.72400, 16.91750, 2.1729e-002,98.63165,50.00000,0.0000e+000,20.00000,-4.8314e-002,1.22319
 43.30500, 17.09750, 2.4358e-002,98.62601,50.00000,0.0000e+000,20.00000,-4.9784e-002,1.22239
 44.01700, 17.27750, 2.7045e-002,98.61857,50.00000,0.0000e+000,20.00000,-5.1429e-002,1.22140
 44.78800, 17.45750, 2.9823e-002,98.61058,50.00000,0.0000e+000,20.00000,-5.2977e-002,1.22034
 45.65100, 17.63750, 3.3032e-002,98.60245,50.00000,0.0000e+000,20.00000,-5.4501e-002,1.21915
 46.61300, 17.81750, 3.6065e-002,98.59431,50.00000,0.0000e+000,20.00000,-5.6706e-002,1.21783
 47.67100, 17.99750, 3.9227e-002,98.58609,50.00000,0.0000e+000,20.00000,-5.9572e-002,1.21637
 48.80300, 18.17750, 4.2367e-002,98.57845,50.00000,0.0000e+000,20.00000,-6.3439e-002,1.21481
 50.01500, 18.35750, 4.5773e-002,98.56951,50.00000,0.0000e+000,20.00000,-6.8495e-002,1.21314
 51.30600, 18.53750, 4.8939e-002,98.55922,50.00000,0.0000e+000,20.00000,-7.4574e-002,1.21136
 52.68600, 18.71750, 5.1795e-002,98.54652,50.00000,0.0000e+000,20.00000,-8.1390e-002,1.20946
 54.17800, 18.89750, 5.5162e-002,98.53317,50.00000,0.0000e+000,20.00000,-8.9074e-002,1.20741
 55.69800, 19.07750, 5.8645e-002,98.51844,50.00000,0.0000e+000,20.00000,-9.7199e-002,1.20532
 57.34100, 19.25750, 6.1343e-002,98.50254,50.00000,0.0000e+000,20.00000,    -0.10724,1.20306
 59.02600, 19.43750, 6.4295e-002,98.48485,50.00000,0.0000e+000,20.00000,    -0.11911,1.20074
 60.82000, 19.61750, 6.7645e-002,98.46608,50.00000,0.0000e+000,20.00000,    -0.13150,1.19827
 62.66500, 19.79750, 7.0961e-002,98.44802,50.00000,0.0000e+000,20.00000,    -0.14516,1.19574
 64.56400, 19.97750, 7.3726e-002,98.42681,50.00000,0.0000e+000,20.00000,    -0.16140,1.19313
 66.52400, 20.15750, 7.7340e-002,98.40051,50.00000,0.0000e+000,20.00000,    -0.17866,1.19044
 68.53500, 20.33750, 8.0905e-002,98.37064,50.00000,0.0000e+000,20.00000,    -0.19697,1.18768
 70.62300, 20.51750, 8.4442e-002,98.33981,50.00000,0.0000e+000,20.00000,    -0.21650,1.18482
 72.77300, 20.69750, 8.8194e-002,98.30676,50.00000,0.0000e+000,20.00000,    -0.23752,1.18188
 74.92300, 20.87750, 9.2979e-002,98.27049,50.00000,0.0000e+000,20.00000,    -0.25971,1.17893
 77.15200, 21.05750, 9.7885e-002,98.22732,50.00000,0.0000e+000,20.00000,    -0.28233,1.17588
 79.40300, 21.23750,     0.10285,98.17640,50.00000,0.0000e+000,20.00000,    -0.30486,1.17280
 81.72300, 21.41750,     0.10837,98.12327,50.00000,0.0000e+000,20.00000,    -0.32699,1.16964
 84.05600, 21.59750,     0.11466,98.06619,50.00000,0.0000e+000,20.00000,    -0.34985,1.16645
 86.42000, 21.77750,     0.12059,98.00046,50.00000,0.0000e+000,20.00000,    -0.37321,1.16323
 88.85500, 21.95750,     0.12762,97.92912,50.00000,0.0000e+000,20.00000,    -0.39603,1.15991
 91.28500, 22.13750,     0.13455,97.85328,50.00000,0.0000e+000,20.00000,    -0.41778,1.15660
 93.72100, 22.31750,     0.14184,97.77039,50.00000,0.0000e+000,20.00000,    -0.43896,1.15329
 96.20400, 22.49750,     0.14905,97.68137,50.00000,0.0000e+000,20.00000,    -0.45978,1.14992
 98.67600, 22.67750,     0.15578,97.58634,50.00000,0.0000e+000,20.00000,    -0.48043,1.14657
101.16400, 22.85750,     0.16244,97.48829,50.00000,0.0000e+000,20.00000,    -0.49880,1.14320
103.65300, 23.03750,     0.16862,97.38870,50.00000,0.0000e+000,20.00000,    -0.51401,1.13983
106.16000, 23.21750,     0.17433,97.28897,50.00000,0.0000e+000,20.00000,    -0.52881,1.13644
108.65900, 23.39750,     0.17938,97.18799,50.00000,0.0000e+000,20.00000,    -0.54268,1.13307
111.14000, 23.57750,     0.18336,97.08270,50.00000,0.0000e+000,20.00000,    -0.55311,1.12972
113.64100, 23.75750,     0.18667,96.97408,50.00000,0.0000e+000,20.00000,    -0.56119,1.12636
116.13400, 23.93750,     0.18877,96.86494,50.00000,0.0000e+000,20.00000,    -0.56831,1.12301
118.63500, 24.11750,     0.19000,96.75663,50.00000,0.0000e+000,20.00000,    -0.57365,1.11965
121.11000, 24.29750,     0.18996,96.64836,50.00000,0.0000e+000,20.00000,    -0.57614,1.11634
123.59100, 24.47750,     0.18880,96.53731,50.00000,0.0000e+000,20.00000,    -0.57624,1.11302
126.05900, 24.65750,     0.18641,96.42777,50.00000,0.0000e+000,20.00000,    -0.57493,1.10972
128.50800, 24.83750,     0.18301,96.32182,50.00000,0.0000e+000,20.00000,    -0.57237,1.10645
130.98300, 25.01750,     0.17873,96.21519,50.00000,0.0000e+000,20.00000,    -0.56865,1.10316
133.41901, 25.19750,     0.17348,96.10790,50.00000,0.0000e+000,20.00000,    -0.56426,1.09992
135.84500, 25.37750,     0.16775,96.00485,50.00000,0.0000e+000,20.00000,    -0.55793,1.09670
138.26100, 25.55750,     0.16064,95.90432,50.00000,0.0000e+000,20.00000,    -0.54958,1.09350
140.66000, 25.73750,     0.15351,95.80372,50.00000,0.0000e+000,20.00000,    -0.54131,1.09032
143.05499, 25.91750,     0.14616,95.70199,50.00000,0.0000e+000,20.00000,    -0.53100,1.08716
145.41000, 26.09750,     0.13825,95.60422,50.00000,0.0000e+000,20.00000,    -0.51917,1.08406
147.74899, 26.27750,     0.13040,95.50931,50.00000,0.0000e+000,20.00000,    -0.50779,1.08098
150.06700, 26.45750,     0.12183,95.41609,50.00000,0.0000e+000,20.00000,    -0.49513,1.07794
152.36900, 26.63750,     0.11268,95.32545,50.00000,0.0000e+000,20.00000,    -0.48206,1.07492
154.65199, 26.81750,     0.10261,95.23876,50.00000,0.0000e+000,20.00000,    -0.46969,1.07193
156.90800, 26.99750, 9.1643e-002,95.15410,50.00000,0.0000e+000,20.00000,    -0.45634,1.06899
159.14999, 27.17750, 8.0270e-002,95.07187,50.00000,0.0000e+000,20.00000,    -0.44322,1.06606
161.36501, 27.35750, 6.8909e-002,94.99401,50.00000,0.0000e+000,20.00000,    -0.43023,1.06318
163.54601, 27.53750, 5.6803e-002,94.91495,50.00000,0.0000e+000,20.00000,    -0.41692,1.06035
165.71001, 27.71750, 4.4514e-002,94.84233,50.00000,0.0000e+000,20.00000,    -0.40263,1.05755
167.85100, 27.89750, 3.2276e-002,94.77764,50.00000,0.0000e+000,20.00000,    -0.38863,1.05478
169.98399, 28.07750, 2.0639e-002,94.70894,50.00000,0.0000e+000,20.00000,    -0.37528,1.05202
172.08000, 28.25750, 8.4498e-003,94.64360,50.00000,0.0000e+000,20.00000,    -0.36193,1.04932
174.16400, 28.43750,-3.3492e-003,94.58511,50.00000,0.0000e+000,20.00000,    -0.34914,1.04664
176.21400, 28.61750,-1.5386e-002,94.52424,50.00000,0.0000e+000,20.00000,    -0.33672,1.04401
178.24699, 28.79750,-2.6433e-002,94.46488,50.00000,0.0000e+000,20.00000,    -0.32423,1.04140
180.27699, 28.97750,-3.7734e-002,94.40873,50.00000,0.0000e+000,20.00000,    -0.31254,1.03881
182.29800, 29.15750,-4.8514e-002,94.35515,50.00000,0.0000e+000,20.00000,    -0.30192,1.03623
184.27600, 29.33750,-5.9604e-002,94.30317,50.00000,0.0000e+000,20.00000,    -0.29061,1.03371
186.25700, 29.51750,-6.9987e-002,94.25317,50.00000,0.0000e+000,20.00000,    -0.28030,1.03119
188.22900, 29.69750,-8.0521e-002,94.20561,50.00000,0.0000e+000,20.00000,    -0.27186,1.02869
190.18201, 29.87750,-9.0822e-002,94.15904,50.00000,0.0000e+000,20.00000,    -0.26184,1.02621
192.12601, 30.05750,    -0.10028,94.11416,50.00000,0.0000e+000,20.00000,    -0.25226,1.02375
194.03900, 30.23750,    -0.11011,94.06962,50.00000,0.0000e+000,20.00000,    -0.24467,1.02134
195.92500, 30.41750,    -0.11966,94.02727,50.00000,0.0000e+000,20.00000,    -0.23623,1.01897
197.83400, 30.59750,    -0.12899,93.98787,50.00000,0.0000e+000,20.00000,    -0.22760,1.01657
199.70200, 30.77750,    -0.13819,93.94802,50.00000,0.0000e+000,20.00000,    -0.21964,1.01423
201.56200, 30.95750,    -0.14774,93.90819,50.00000,0.0000e+000,20.00000,    -0.21225,1.01190
203.42599, 31.13750,    -0.15692,93.87049,50.00000,0.0000e+000,20.00000,    -0.20516,1.00957
205.27299, 31.31750,    -0.16629,93.83363,50.00000,0.0000e+000,20.00000,    -0.19850,1.00727
207.09000, 31.49750,    -0.17493,93.79897,50.00000,0.0000e+000,20.00000,    -0.19222,1.00501
208.90700, 31.67750,    -0.18406,93.76737,50.00000,0.0000e+000,20.00000,    -0.18590,1.00275
210.71899, 31.85750,    -0.19286,93.73574,50.00000,0.0000e+000,20.00000,    -0.18025,1.00051
212.51401, 32.03750,    -0.20166,93.70452,50.00000,0.0000e+000,20.00000,    -0.17507,0.99829
214.31100, 32.21750,    -0.21095,93.67459,50.00000,0.0000e+000,20.00000,    -0.16973,0.99607
216.08701, 32.39750,    -0.21934,93.64614,50.00000,0.0000e+000,20.00000,    -0.16546,0.99389
217.85600, 32.57750,    -0.22836,93.61850,50.00000,0.0000e+000,20.00000,    -0.16114,0.99171
219.63699, 32.75750,    -0.23776,93.59154,50.00000,0.0000e+000,20.00000,    -0.15628,0.98953
221.39000, 32.93750,    -0.24628,93.56512,50.00000,0.0000e+000,20.00000,    -0.15197,0.98738
223.15300, 33.11750,    -0.25504,93.53911,50.00000,0.0000e+000,20.00000,    -0.14776,0.98523
224.89301, 33.29750,    -0.26373,93.51387,50.00000,0.0000e+000,20.00000,    -0.14398,0.98311
226.64900, 33.47750,    -0.27271,93.49019,50.00000,0.0000e+000,20.00000,    -0.14070,0.98098
228.38000, 33.65750,    -0.28130,93.46604,50.00000,0.0000e+000,20.00000,    -0.13778,0.97888
230.13200, 33.83750,    -0.28977,93.44024,50.00000,0.0000e+000,20.00000,    -0.13456,0.97675
231.86501, 34.01750,    -0.29855,93.41669,50.00000,0.0000e+000,20.00000,    -0.13158,0.97466
233.59900, 34.19750,    -0.30746,93.39279,50.00000,0.0000e+000,20.00000,    -0.12890,0.97257
235.31799, 34.37750,    -0.31560,93.36875,50.00000,0.0000e+000,20.00000,    -0.12642,0.97050
237.04601, 34.55750,    -0.32486,93.34638,50.00000,0.0000e+000,20.00000,    -0.12434,0.96843
238.77600, 34.73750,    -0.33317,93.32397,50.00000,0.0000e+000,20.00000,    -0.12250,0.96636
240.50400, 34.91750,    -0.34254,93.30255,50.00000,0.0000e+000,20.00000,    -0.12084,0.96429
242.22400, 35.09750,    -0.35075,93.28086,50.00000,0.0000e+000,20.00000,    -0.11886,0.96224
243.94701, 35.27750,    -0.35970,93.26096,50.00000,0.0000e+000,20.00000,    -0.11667,0.96019
245.69299, 35.45750,    -0.36799,93.24021,50.00000,0.0000e+000,20.00000,    -0.11421,0.95812
247.42101, 35.63750,    -0.37601,93.22030,50.00000,0.0000e+000,20.00000,    -0.11199,0.95607
249.13901, 35.81750,    -0.38409,93.20112,50.00000,0.0000e+000,20.00000,    -0.11080,0.95404
250.86301, 35.99750,    -0.39234,93.18209,50.00000,0.0000e+000,20.00000,    -0.10950,0.95201
252.61200, 36.17750,    -0.40035,93.16356,50.00000,0.0000e+000,20.00000,    -0.10801,0.94996
254.33400, 36.35750,    -0.40803,93.14412,50.00000,0.0000e+000,20.00000,    -0.10675,0.94793
256.06500, 36.53750,    -0.41580,93.12448,50.00000,0.0000e+000,20.00000,    -0.10523,0.94591
257.79501, 36.71750,    -0.42394,93.10436,50.00000,0.0000e+000,20.00000,    -0.10402,0.94389
259.53400, 36.89750,    -0.43102,93.08583,50.00000,0.0000e+000,20.00000,    -0.10259,0.94186
261.27600, 37.07750,    -0.43810,93.06962,50.00000,0.0000e+000,20.00000,    -0.10186,0.93984
263.00299, 37.25750,    -0.44488,93.05481,50.00000,0.0000e+000,20.00000,    -0.10133,0.93784
264.74701, 37.43750,    -0.45183,93.03770,50.00000,0.0000e+000,20.00000,    -0.10066,0.93582
266.48099, 37.61750,    -0.45801,93.01818,50.00000,0.0000e+000,20.00000,    -0.10027,0.93382
268.20599, 37.79750,    -0.46501,92.99921,50.00000,0.0000e+000,20.00000,-9.9842e-002,0.93184
269.95901, 37.97750,    -0.47184,92.98031,50.00000,0.0000e+000,20.00000,-9.9579e-002,0.92982
271.68301, 38.15750,    -0.47883,92.96234,50.00000,0.0000e+000,20.00000,-9.9144e-002,0.92785
273.42499, 38.33750,    -0.48609,92.94520,50.00000,0.0000e+000,20.00000,-9.8584e-002,0.92586
275.17300, 38.51750,    -0.49312,92.92835,50.00000,0.0000e+000,20.00000,-9.7724e-002,0.92387
276.90500, 38.69750,    -0.50037,92.91158,50.00000,0.0000e+000,20.00000,-9.7413e-002,0.92190
278.66599, 38.87750,    -0.50753,92.89447,50.00000,0.0000e+000,20.00000,-9.8540e-002,0.91991
280.40500, 39.05750,    -0.51412,92.87592,50.00000,0.0000e+000,20.00000,-9.9979e-002,0.91794
282.16101, 39.23750,    -0.52111,92.85791,50.00000,0.0000e+000,20.00000,    -0.10093,0.91596
283.92200, 39.41750,    -0.52774,92.84035,50.00000,0.0000e+000,20.00000,    -0.10171,0.91398
285.66800, 39.59750,    -0.53371,92.82263,50.00000,0.0000e+000,20.00000,    -0.10242,0.91202
287.40399, 39.77750,    -0.53990,92.80519,50.00000,0.0000e+000,20.00000,    -0.10302,0.91008
289.17499, 39.95750,    -0.54598,92.78744,50.00000,0.0000e+000,20.00000,    -0.10383,0.90811
290.93301, 40.13750,    -0.55219,92.76984,50.00000,0.0000e+000,20.00000,    -0.10486,0.90615
292.68500, 40.31750,    -0.55805,92.75279,50.00000,0.0000e+000,20.00000,    -0.10617,0.90421
294.43500, 40.49750,    -0.56389,92.73537,50.00000,0.0000e+000,20.00000,    -0.10743,0.90227
296.20999, 40.67750,    -0.56994,92.71502,50.00000,0.0000e+000,20.00000,    -0.10864,0.90031
297.97699, 40.85750,    -0.57556,92.69466,50.00000,0.0000e+000,20.00000,    -0.10927,0.89837
299.72198, 41.03750,    -0.58162,92.67489,50.00000,0.0000e+000,20.00000,    -0.11011,0.89645
301.49899, 41.21750,    -0.58667,92.65280,50.00000,0.0000e+000,20.00000,    -0.11146,0.89451
303.25101, 41.39750,    -0.59220,92.63099,50.00000,0.0000e+000,20.00000,    -0.11321,0.89260
305.01001, 41.57750,    -0.59729,92.60985,50.00000,0.0000e+000,20.00000,    -0.11551,0.89069
306.79300, 41.75750,    -0.60309,92.58876,50.00000,0.0000e+000,20.00000,    -0.11758,0.88875
308.55899, 41.93750,    -0.60785,92.56773,50.00000,0.0000e+000,20.00000,    -0.11918,0.88684
310.31201, 42.11750,    -0.61313,92.54622,50.00000,0.0000e+000,20.00000,    -0.12107,0.88495
312.07700, 42.29750,    -0.61779,92.52472,50.00000,0.0000e+000,20.00000,    -0.12306,0.88305
313.84399, 42.47750,    -0.62263,92.50335,50.00000,0.0000e+000,20.00000,    -0.12467,0.88116
315.62000, 42.65750,    -0.62709,92.48255,50.00000,0.0000e+000,20.00000,    -0.12670,0.87926
317.36600, 42.83750,    -0.63209,92.46144,50.00000,0.0000e+000,20.00000,    -0.12893,0.87740
319.13599, 43.01750,    -0.63748,92.43923,50.00000,0.0000e+000,20.00000,    -0.13049,0.87552
320.89700, 43.19750,    -0.64242,92.41535,50.00000,0.0000e+000,20.00000,    -0.13234,0.87365
322.66400, 43.37750,    -0.64822,92.38968,50.00000,0.0000e+000,20.00000,    -0.13486,0.87179
324.45200, 43.55750,    -0.65347,92.36415,50.00000,0.0000e+000,20.00000,    -0.13755,0.86990
326.21301, 43.73750,    -0.65875,92.34043,50.00000,0.0000e+000,20.00000,    -0.14075,0.86805
327.97601, 43.91750,    -0.66278,92.31661,50.00000,0.0000e+000,20.00000,    -0.14444,0.86621
329.74799, 44.09750,    -0.66768,92.29212,50.00000,0.0000e+000,20.00000,    -0.14851,0.86436
331.50000, 44.27750,    -0.67174,92.26672,50.00000,0.0000e+000,20.00000,    -0.15268,0.86254
333.27499, 44.45750,    -0.67612,92.23888,50.00000,0.0000e+000,20.00000,    -0.15712,0.86070
335.05600, 44.63750,    -0.68106,92.21102,50.00000,0.0000e+000,20.00000,    -0.16224,0.85885
336.81500, 44.81750,    -0.68519,92.18352,50.00000,0.0000e+000,20.00000,    -0.16748,0.85704
338.59000, 44.99750,    -0.68928,92.15510,50.00000,0.0000e+000,20.00000,    -0.17193,0.85522
340.37601, 45.17750,    -0.69373,92.12484,50.00000,0.0000e+000,20.00000,    -0.17638,0.85339
342.16101, 45.35750,    -0.69768,92.09405,50.00000,0.0000e+000,20.00000,    -0.18214,0.85157
343.94400, 45.53750,    -0.70165,92.06166,50.00000,0.0000e+000,20.00000,    -0.18853,0.84975
345.73300, 45.71750,    -0.70488,92.02706,50.00000,0.0000e+000,20.00000,    -0.19466,0.84794
347.52899, 45.89750,    -0.70732,91.99081,50.00000,0.0000e+000,20.00000,    -0.20039,0.84612
349.28900, 46.07750,    -0.70956,91.95411,50.00000,0.0000e+000,20.00000,    -0.20601,0.84435
351.08600, 46.25750,    -0.71191,91.91722,50.00000,0.0000e+000,20.00000,    -0.21106,0.84254
352.86801, 46.43750,    -0.71450,91.87802,50.00000,0.0000e+000,20.00000,    -0.21574,0.84076
354.64899, 46.61750,    -0.71680,91.83677,50.00000,0.0000e+000,20.00000,    -0.22052,0.83898
356.42599, 46.79750,    -0.72006,91.79681,50.00000,0.0000e+000,20.00000,    -0.22461,0.83721
358.21201, 46.97750,    -0.72448,91.75568,50.00000,0.0000e+000,20.00000,    -0.22828,0.83544
359.99399, 47.15750,    -0.72875,91.70957,50.00000,0.0000e+000,20.00000,    -0.23219,0.83368
361.79501, 47.33750,    -0.73400,91.66200,50.00000,0.0000e+000,20.00000,    -0.23585,0.83191
363.57300, 47.51750,    -0.73862,91.61588,50.00000,0.0000e+000,20.00000,    -0.23837,0.83016
365.36099, 47.69750,    -0.74349,91.57030,50.00000,0.0000e+000,20.00000,    -0.24000,0.82841
367.13800, 47.87750,    -0.74869,91.52490,50.00000,0.0000e+000,20.00000,    -0.24151,0.82668
368.92001, 48.05750,    -0.75399,91.47867,50.00000,0.0000e+000,20.00000,    -0.24349,0.82495
370.69299, 48.23750,    -0.75892,91.43364,50.00000,0.0000e+000,20.00000,    -0.24492,0.82323
372.49899, 48.41750,    -0.76474,91.38844,50.00000,0.0000e+000,20.00000,    -0.24511,0.82149
374.27802, 48.59750,    -0.77004,91.34519,50.00000,0.0000e+000,20.00000,    -0.24549,0.81978
376.05801, 48.77750,    -0.77633,91.30189,50.00000,0.0000e+000,20.00000,    -0.24598,0.81808
377.83099, 48.95750,    -0.78279,91.25709,50.00000,0.0000e+000,20.00000,    -0.24519,0.81638
379.60400, 49.13750,    -0.78914,91.21161,50.00000,0.0000e+000,20.00000,    -0.24307,0.81470
381.40302, 49.31750,    -0.79564,91.16773,50.00000,0.0000e+000,20.00000,    -0.24110,0.81299
383.17401, 49.49750,    -0.80176,91.12562,50.00000,0.0000e+000,20.00000,    -0.23960,0.81132
384.93399, 49.67750,    -0.80852,91.08350,50.00000,0.0000e+000,20.00000,    -0.23768,0.80966
386.72400, 49.85750,    -0.81614,91.03983,50.00000,0.0000e+000,20.00000,    -0.23508,0.80798
388.49399, 50.03750,    -0.82483,90.99559,50.00000,0.0000e+000,20.00000,    -0.23308,0.80632
390.26199, 50.21750,    -0.83341,90.95345,50.00000,0.0000e+000,20.00000,    -0.23040,0.80468
392.04599, 50.39750,    -0.84283,90.91201,50.00000,0.0000e+000,20.00000,    -0.22815,0.80302
393.82901, 50.57750,    -0.85210,90.86970,50.00000,0.0000e+000,20.00000,    -0.22699,0.80137
395.60101, 50.75750,    -0.86106,90.82705,50.00000,0.0000e+000,20.00000,    -0.22570,0.79974
397.38699, 50.93750,    -0.86991,90.78670,50.00000,0.0000e+000,20.00000,    -0.22377,0.79810
399.19101, 51.11750,    -0.87826,90.74770,50.00000,0.0000e+000,20.00000,    -0.22208,0.79645
400.95901, 51.29750,    -0.88661,90.70762,50.00000,0.0000e+000,20.00000,    -0.22110,0.79484
402.76300, 51.47750,    -0.89528,90.66880,50.00000,0.0000e+000,20.00000,    -0.22048,0.79320
404.54599, 51.65750,    -0.90283,90.63214,50.00000,0.0000e+000,20.00000,    -0.21989,0.79158
406.32901, 51.83750,    -0.90994,90.59432,50.00000,0.0000e+000,20.00000,    -0.21999,0.78998
408.10199, 52.01750,    -0.91725,90.55841,50.00000,0.0000e+000,20.00000,    -0.22009,0.78838
409.89301, 52.19750,    -0.92528,90.52349,50.00000,0.0000e+000,20.00000,    -0.21979,0.78678
411.69299, 52.37750,    -0.93339,90.48505,50.00000,0.0000e+000,20.00000,    -0.22032,0.78517
413.48901, 52.55750,    -0.94087,90.44511,50.00000,0.0000e+000,20.00000,    -0.22079,0.78358
415.29199, 52.73750,    -0.94764,90.40646,50.00000,0.0000e+000,20.00000,    -0.22164,0.78198
417.08499, 52.91750,    -0.95453,90.36841,50.00000,0.0000e+000,20.00000,    -0.22282,0.78040
418.88300, 53.09750,    -0.96060,90.32987,50.00000,0.0000e+000,20.00000,    -0.22334,0.77882
420.67599, 53.27750,    -0.96633,90.29029,50.00000,0.0000e+000,20.00000,    -0.22406,0.77725
422.46701, 53.45750,    -0.97128,90.24942,50.00000,0.0000e+000,20.00000,    -0.22664,0.77569
424.23499, 53.63750,    -0.97555,90.20510,50.00000,0.0000e+000,20.00000,    -0.22927,0.77416
426.01401, 53.81750,    -0.98037,90.16153,50.00000,0.0000e+000,20.00000,    -0.23156,0.77262
427.80801, 53.99750,    -0.98704,90.12140,50.00000,0.0000e+000,20.00000,    -0.23428,0.77107
429.57101, 54.17750,    -0.99137,90.07784,50.00000,0.0000e+000,20.00000,    -0.23675,0.76956
431.33899, 54.35750,    -0.99434,90.03321,50.00000,0.0000e+000,20.00000,    -0.23894,0.76805
433.09799, 54.53750,    -0.99734,89.98931,50.00000,0.0000e+000,20.00000,    -0.24146,0.76655
434.84100, 54.71750,    -1.00204,89.94579,50.00000,0.0000e+000,20.00000,    -0.24458,0.76507
436.62299, 54.89750,    -1.00863,89.90380,50.00000,0.0000e+000,20.00000,    -0.24784,0.76356
438.39700, 55.07750,    -1.01551,89.86214,50.00000,0.0000e+000,20.00000,    -0.25062,0.76207
440.18500, 55.25750,    -1.02470,89.81680,50.00000,0.0000e+000,20.00000,    -0.25296,0.76057
441.99399, 55.43750,    -1.03500,89.76913,50.00000,0.0000e+000,20.00000,    -0.25493,0.75906
443.81100, 55.61750,    -1.04403,89.72411,50.00000,0.0000e+000,20.00000,    -0.25692,0.75755
445.63501, 55.79750,    -1.05122,89.67967,50.00000,0.0000e+000,20.00000,    -0.26019,0.75603
447.44101, 55.97750,    -1.05570,89.63309,50.00000,0.0000e+000,20.00000,    -0.26249,0.75454
449.23001, 56.15750,    -1.05815,89.58515,50.00000,0.0000e+000,20.00000,    -0.26438,0.75307
451.04300, 56.33750,    -1.06065,89.53715,50.00000,0.0000e+000,20.00000,    -0.26773,0.75159
452.82001, 56.51750,    -1.06341,89.48800,50.00000,0.0000e+000,20.00000,    -0.27116,0.75014
454.61099, 56.69750,    -1.06708,89.43757,50.00000,0.0000e+000,20.00000,    -0.27443,0.74868
456.39099, 56.87750,    -1.07217,89.38795,50.00000,0.0000e+000,20.00000,    -0.27790,0.74724
458.17300, 57.05750,    -1.07714,89.33880,50.00000,0.0000e+000,20.00000,    -0.28109,0.74581
459.96201, 57.23750,    -1.08204,89.28817,50.00000,0.0000e+000,20.00000,    -0.28304,0.74437
461.74899, 57.41750,    -1.08656,89.23672,50.00000,0.0000e+000,20.00000,    -0.28523,0.74294
463.53601, 57.59750,    -1.09179,89.18464,50.00000,0.0000e+000,20.00000,    -0.28884,0.74152
465.33701, 57.77750,    -1.09902,89.13302,50.00000,0.0000e+000,20.00000,    -0.29220,0.74009
467.13901, 57.95750,    -1.10633,89.08185,50.00000,0.0000e+000,20.00000,    -0.29469,0.73867
468.95001, 58.13750,    -1.11303,89.02619,50.00000,0.0000e+000,20.00000,    -0.29807,0.73724
470.77301, 58.31750,    -1.11816,88.96970,50.00000,0.0000e+000,20.00000,    -0.30111,0.73581
472.55499, 58.49750,    -1.12250,88.91527,50.00000,0.0000e+000,20.00000,    -0.30331,0.73442
474.34000, 58.67750,    -1.12400,88.86136,50.00000,0.0000e+000,20.00000,    -0.30650,0.73304
476.11600, 58.85750,    -1.12572,88.80525,50.00000,0.0000e+000,20.00000,    -0.31023,0.73166
477.89401, 59.03750,    -1.12752,88.75000,50.00000,0.0000e+000,20.00000,    -0.31319,0.73029
479.64999, 59.21750,    -1.13136,88.69662,50.00000,0.0000e+000,20.00000,    -0.31650,0.72894
481.44299, 59.39750,    -1.13564,88.63992,50.00000,0.0000e+000,20.00000,    -0.31982,0.72757
483.23599, 59.57750,    -1.14530,88.58108,50.00000,0.0000e+000,20.00000,    -0.32288,0.72621
485.05801, 59.75750,    -1.15624,88.52427,50.00000,0.0000e+000,20.00000,    -0.32606,0.72483
486.88199, 59.93750,    -1.16548,88.46439,50.00000,0.0000e+000,20.00000,    -0.32869,0.72345
488.71301, 60.11750,    -1.17133,88.40411,50.00000,0.0000e+000,20.00000,    -0.33137,0.72208
490.51001, 60.29750,    -1.17549,88.34563,50.00000,0.0000e+000,20.00000,    -0.33373,0.72073
492.31400, 60.47750,    -1.17823,88.28491,50.00000,0.0000e+000,20.00000,    -0.33578,0.71939
494.11099, 60.65750,    -1.18054,88.22183,50.00000,0.0000e+000,20.00000,    -0.33729,0.71805
495.90601, 60.83750,    -1.18364,88.16078,50.00000,0.0000e+000,20.00000,    -0.33945,0.71673
497.68799, 61.01750,    -1.18693,88.09760,50.00000,0.0000e+000,20.00000,    -0.34325,0.71542
499.46701, 61.19750,    -1.19104,88.03342,50.00000,0.0000e+000,20.00000,    -0.34685,0.71411
501.26700, 61.37750,    -1.19595,87.97021,50.00000,0.0000e+000,20.00000,    -0.34969,0.71280
503.03900, 61.55750,    -1.20087,87.90775,50.00000,0.0000e+000,20.00000,    -0.35316,0.71151
504.81601, 61.73750,    -1.20539,87.84361,50.00000,0.0000e+000,20.00000,    -0.35493,0.71023
506.61700, 61.91750,    -1.21027,87.77710,50.00000,0.0000e+000,20.00000,    -0.35566,0.70893
508.39301, 62.09750,    -1.21577,87.71312,50.00000,0.0000e+000,20.00000,    -0.35737,0.70765
510.19699, 62.27750,    -1.22234,87.65180,50.00000,0.0000e+000,20.00000,    -0.35893,0.70637
512.00403, 62.45750,    -1.22963,87.59052,50.00000,0.0000e+000,20.00000,    -0.35991,0.70508
513.78802, 62.63750,    -1.23632,87.52751,50.00000,0.0000e+000,20.00000,    -0.36185,0.70382
515.60602, 62.81750,    -1.24186,87.46072,50.00000,0.0000e+000,20.00000,    -0.36360,0.70254
517.41302, 62.99750,    -1.24661,87.39172,50.00000,0.0000e+000,20.00000,    -0.36612,0.70127
519.19702, 63.17750,    -1.25024,87.32243,50.00000,0.0000e+000,20.00000,    -0.36854,0.70002
520.98999, 63.35750,    -1.25442,87.25272,50.00000,0.0000e+000,20.00000,    -0.36935,0.69877
522.78497, 63.53750,    -1.25802,87.18617,50.00000,0.0000e+000,20.00000,    -0.37130,0.69753
524.58002, 63.71750,    -1.26254,87.12296,50.00000,0.0000e+000,20.00000,    -0.37419,0.69629
526.36902, 63.89750,    -1.26771,87.05840,50.00000,0.0000e+000,20.00000,    -0.37626,0.69506
528.16901, 64.07750,    -1.27204,86.99263,50.00000,0.0000e+000,20.00000,    -0.37851,0.69383
529.96600, 64.25750,    -1.27631,86.92624,50.00000,0.0000e+000,20.00000,    -0.38072,0.69260
531.75403, 64.43750,    -1.28111,86.85799,50.00000,0.0000e+000,20.00000,    -0.38332,0.69139
533.53302, 64.61750,    -1.28558,86.78924,50.00000,0.0000e+000,20.00000,    -0.38669,0.69019
535.33002, 64.79750,    -1.29044,86.71646,50.00000,0.0000e+000,20.00000,    -0.38842,0.68898
537.12299, 64.97750,    -1.29593,86.64328,50.00000,0.0000e+000,20.00000,    -0.38857,0.68778
538.90900, 65.15750,    -1.30184,86.57732,50.00000,0.0000e+000,20.00000,    -0.38967,0.68659
540.71002, 65.33750,    -1.30673,86.50807,50.00000,0.0000e+000,20.00000,    -0.39164,0.68540
542.49500, 65.51750,    -1.31203,86.43112,50.00000,0.0000e+000,20.00000,    -0.39416,0.68422
544.29303, 65.69750,    -1.31690,86.35813,50.00000,0.0000e+000,20.00000,    -0.39707,0.68303
546.09601, 65.87750,    -1.32308,86.28832,50.00000,0.0000e+000,20.00000,    -0.39983,0.68185
547.89801, 66.05750,    -1.32885,86.21901,50.00000,0.0000e+000,20.00000,    -0.40271,0.68068
549.70203, 66.23750,    -1.33378,86.14774,50.00000,0.0000e+000,20.00000,    -0.40457,0.67951
551.47900, 66.41750,    -1.33801,86.06997,50.00000,0.0000e+000,20.00000,    -0.40487,0.67836
553.29303, 66.59750,    -1.34199,85.99346,50.00000,0.0000e+000,20.00000,    -0.40475,0.67719
555.08301, 66.77750,    -1.34665,85.92365,50.00000,0.0000e+000,20.00000,    -0.40493,0.67604
556.88300, 66.95750,    -1.35120,85.85058,50.00000,0.0000e+000,20.00000,    -0.40761,0.67490
558.68298, 67.13750,    -1.35603,85.77575,50.00000,0.0000e+000,20.00000,    -0.41079,0.67375
560.47198, 67.31750,    -1.35972,85.70314,50.00000,0.0000e+000,20.00000,    -0.41100,0.67262
562.24298, 67.49750,    -1.36284,85.62871,50.00000,0.0000e+000,20.00000,    -0.41168,0.67151
564.01898, 67.67750,    -1.36458,85.55283,50.00000,0.0000e+000,20.00000,    -0.41335,0.67039
565.80902, 67.85750,    -1.36834,85.47643,50.00000,0.0000e+000,20.00000,    -0.41527,0.66928
567.59497, 68.03750,    -1.37323,85.40069,50.00000,0.0000e+000,20.00000,    -0.41678,0.66817
569.39001, 68.21750,    -1.37864,85.33071,50.00000,0.0000e+000,20.00000,    -0.41660,0.66706
571.20898, 68.39750,    -1.38709,85.25975,50.00000,0.0000e+000,20.00000,    -0.41565,0.66594
573.02100, 68.57750,    -1.39384,85.18545,50.00000,0.0000e+000,20.00000,    -0.41641,0.66482
574.86298, 68.75750,    -1.40556,85.10936,50.00000,0.0000e+000,20.00000,    -0.41683,0.66370
576.71802, 68.93750,    -1.41791,85.03001,50.00000,0.0000e+000,20.00000,    -0.41615,0.66257
578.55798, 69.11750,    -1.42528,84.95227,50.00000,0.0000e+000,20.00000,    -0.41701,0.66146
580.39099, 69.29750,    -1.42963,84.87595,50.00000,0.0000e+000,20.00000,    -0.41838,0.66036
582.18597, 69.47750,    -1.43071,84.79973,50.00000,0.0000e+000,20.00000,    -0.41938,0.65928
583.99298, 69.65750,    -1.43061,84.72352,50.00000,0.0000e+000,20.00000,    -0.42026,0.65820
585.79303, 69.83750,    -1.43087,84.64723,50.00000,0.0000e+000,20.00000,    -0.42078,0.65713
587.57001, 70.01750,    -1.43279,84.57106,50.00000,0.0000e+000,20.00000,    -0.42320,0.65608
589.36499, 70.19750,    -1.43431,84.49652,50.00000,0.0000e+000,20.00000,    -0.42639,0.65502
591.12299, 70.37750,    -1.43768,84.42360,50.00000,0.0000e+000,20.00000,    -0.42835,0.65399
592.92999, 70.55750,    -1.44379,84.34965,50.00000,0.0000e+000,20.00000,    -0.42941,0.65294
594.70001, 70.73750,    -1.45009,84.27720,50.00000,0.0000e+000,20.00000,    -0.42962,0.65191
596.51599, 70.91750,    -1.45880,84.20195,50.00000,0.0000e+000,20.00000,    -0.43058,0.65086
598.32300, 71.09750,    -1.46726,84.12322,50.00000,0.0000e+000,20.00000,    -0.43265,0.64982
600.15100, 71.27750,    -1.47415,84.04373,50.00000,0.0000e+000,20.00000,    -0.43508,0.64877
601.94299, 71.45750,    -1.47797,83.96421,50.00000,0.0000e+000,20.00000,    -0.43759,0.64774
603.71399, 71.63750,    -1.47823,83.88595,50.00000,0.0000e+000,20.00000,    -0.44021,0.64674
605.49597, 71.81750,    -1.47933,83.80675,50.00000,0.0000e+000,20.00000,    -0.44256,0.64573
607.28198, 71.99750,    -1.48385,83.72501,50.00000,0.0000e+000,20.00000,    -0.44492,0.64472
609.08002, 72.17750,    -1.49328,83.64350,50.00000,0.0000e+000,20.00000,    -0.44825,0.64371
610.91498, 72.35750,    -1.50333,83.56384,50.00000,0.0000e+000,20.00000,    -0.45183,0.64268
612.73901, 72.53750,    -1.51127,83.48422,50.00000,0.0000e+000,20.00000,    -0.45583,0.64167
614.58502, 72.71750,    -1.52041,83.40281,50.00000,0.0000e+000,20.00000,    -0.45991,0.64065
616.44299, 72.89750,    -1.53142,83.31923,50.00000,0.0000e+000,20.00000,    -0.46401,0.63962
618.30402, 73.07750,    -1.53733,83.23417,50.00000,0.0000e+000,20.00000,    -0.46726,0.63860
620.08600, 73.25750,    -1.53427,83.14889,50.00000,0.0000e+000,20.00000,    -0.47051,0.63763
621.85199, 73.43750,    -1.52823,83.06299,50.00000,0.0000e+000,20.00000,    -0.47501,0.63667
623.61603, 73.61750,    -1.52466,82.97797,50.00000,0.0000e+000,20.00000,    -0.47862,0.63571
625.39801, 73.79750,    -1.52635,82.89433,50.00000,0.0000e+000,20.00000,    -0.48165,0.63475
627.16602, 73.97750,    -1.53036,82.80965,50.00000,0.0000e+000,20.00000,    -0.48544,0.63380
628.96503, 74.15750,    -1.53409,82.72278,50.00000,0.0000e+000,20.00000,    -0.49057,0.63284
630.79303, 74.33750,    -1.54559,82.63557,50.00000,0.0000e+000,20.00000,    -0.49664,0.63186
632.64600, 74.51750,    -1.55964,82.54678,50.00000,0.0000e+000,20.00000,    -0.50239,0.63088
634.47803, 74.69750,    -1.56724,82.45366,50.00000,0.0000e+000,20.00000,    -0.50706,0.62991
636.31201, 74.87750,    -1.56967,82.36176,50.00000,0.0000e+000,20.00000,    -0.51103,0.62895
638.11499, 75.05750,    -1.56642,82.27087,50.00000,0.0000e+000,20.00000,    -0.51485,0.62801
639.89398, 75.23750,    -1.56482,82.17616,50.00000,0.0000e+000,20.00000,    -0.51821,0.62708
641.67902, 75.41750,    -1.56384,82.08353,50.00000,0.0000e+000,20.00000,    -0.52194,0.62615
643.48401, 75.59750,    -1.56486,81.99154,50.00000,0.0000e+000,20.00000,    -0.52554,0.62522
645.25800, 75.77750,    -1.56767,81.89633,50.00000,0.0000e+000,20.00000,    -0.52860,0.62431
647.06500, 75.95750,    -1.57023,81.79818,50.00000,0.0000e+000,20.00000,    -0.53198,0.62338
648.86798, 76.13750,    -1.57156,81.69695,50.00000,0.0000e+000,20.00000,    -0.53483,0.62246
650.65997, 76.31750,    -1.57509,81.59462,50.00000,0.0000e+000,20.00000,    -0.53671,0.62155
652.44800, 76.49750,    -1.57848,81.49407,50.00000,0.0000e+000,20.00000,    -0.53739,0.62065
654.24799, 76.67750,    -1.58152,81.39454,50.00000,0.0000e+000,20.00000,    -0.53826,0.61974
656.03101, 76.85750,    -1.58394,81.29527,50.00000,0.0000e+000,20.00000,    -0.53966,0.61884
657.83197, 77.03750,    -1.58648,81.19708,50.00000,0.0000e+000,20.00000,    -0.53948,0.61794
659.60999, 77.21750,    -1.59033,81.09824,50.00000,0.0000e+000,20.00000,    -0.53886,0.61706
661.41199, 77.39750,    -1.59491,81.00082,50.00000,0.0000e+000,20.00000,    -0.53742,0.61617
663.19897, 77.57750,    -1.59749,80.90551,50.00000,0.0000e+000,20.00000,    -0.53460,0.61528
665.00598, 77.75750,    -1.60081,80.80699,50.00000,0.0000e+000,20.00000,    -0.53127,0.61440
666.80103, 77.93750,    -1.60394,80.70869,50.00000,0.0000e+000,20.00000,    -0.52659,0.61352
668.59100, 78.11750,    -1.60784,80.61350,50.00000,0.0000e+000,20.00000,    -0.52135,0.61265
670.39203, 78.29750,    -1.61199,80.51841,50.00000,0.0000e+000,20.00000,    -0.51566,0.61177
672.19000, 78.47750,    -1.61574,80.42281,50.00000,0.0000e+000,20.00000,    -0.50948,0.61090
673.98499, 78.65750,    -1.61992,80.32712,50.00000,0.0000e+000,20.00000,    -0.50419,0.61004
675.78601, 78.83750,    -1.62614,80.23298,50.00000,0.0000e+000,20.00000,    -0.49909,0.60917
677.60303, 79.01750,    -1.63287,80.14161,50.00000,0.0000e+000,20.00000,    -0.49210,0.60831
679.40601, 79.19750,    -1.63697,80.05439,50.00000,0.0000e+000,20.00000,    -0.48484,0.60745
681.21899, 79.37750,    -1.64099,79.97010,50.00000,0.0000e+000,20.00000,    -0.47902,0.60659
683.00201, 79.55750,    -1.64174,79.88458,50.00000,0.0000e+000,20.00000,    -0.47215,0.60575
684.79102, 79.73750,    -1.64211,79.80061,50.00000,0.0000e+000,20.00000,    -0.46366,0.60491
686.58698, 79.91750,    -1.64607,79.71723,50.00000,0.0000e+000,20.00000,    -0.45526,0.60407
688.38202, 80.09750,    -1.65174,79.63650,50.00000,0.0000e+000,20.00000,    -0.44657,0.60323
690.19202, 80.27750,    -1.65740,79.55943,50.00000,0.0000e+000,20.00000,    -0.43853,0.60239
692.00403, 80.45750,    -1.66090,79.48001,50.00000,0.0000e+000,20.00000,    -0.43033,0.60155
693.81598, 80.63750,    -1.66369,79.39968,50.00000,0.0000e+000,20.00000,    -0.42112,0.60072
695.62201, 80.81750,    -1.66771,79.32558,50.00000,0.0000e+000,20.00000,    -0.41242,0.59989
697.41400, 80.99750,    -1.66992,79.25449,50.00000,0.0000e+000,20.00000,    -0.40507,0.59907
699.21899, 81.17750,    -1.67225,79.18069,50.00000,0.0000e+000,20.00000,    -0.39767,0.59825
701.02197, 81.35750,    -1.67675,79.10736,50.00000,0.0000e+000,20.00000,    -0.39041,0.59743
702.82898, 81.53750,    -1.68074,79.03881,50.00000,0.0000e+000,20.00000,    -0.38371,0.59661
704.62097, 81.71750,    -1.68301,78.97381,50.00000,0.0000e+000,20.00000,    -0.37662,0.59581
706.42297, 81.89750,    -1.68516,78.91047,50.00000,0.0000e+000,20.00000,    -0.37034,0.59500
708.22198, 82.07750,    -1.68768,78.84489,50.00000,0.0000e+000,20.00000,    -0.36619,0.59419
710.01703, 82.25750,    -1.69134,78.77860,50.00000,0.0000e+000,20.00000,    -0.36197,0.59340
711.84100, 82.43750,    -1.69595,78.71702,50.00000,0.0000e+000,20.00000,    -0.35679,0.59259
713.64801, 82.61750,    -1.69925,78.65735,50.00000,0.0000e+000,20.00000,    -0.35237,0.59179
715.45099, 82.79750,    -1.70115,78.59598,50.00000,0.0000e+000,20.00000,    -0.34878,0.59100
717.29102, 82.97750,    -1.70546,78.53822,50.00000,0.0000e+000,20.00000,    -0.34478,0.59019
719.12201, 83.15750,    -1.71009,78.47988,50.00000,0.0000e+000,20.00000,    -0.34039,0.58939
720.95001, 83.33750,    -1.71131,78.41988,50.00000,0.0000e+000,20.00000,    -0.33532,0.58859
722.75500, 83.51750,    -1.70847,78.36208,50.00000,0.0000e+000,20.00000,    -0.32930,0.58781
724.56598, 83.69750,    -1.70657,78.30413,50.00000,0.0000e+000,20.00000,    -0.32192,0.58703
726.43597, 83.87750,    -1.71327,78.24244,50.00000,0.0000e+000,20.00000,    -0.31251,0.58622
728.28198, 84.05750,    -1.71774,78.17902,50.00000,0.0000e+000,20.00000,    -0.30196,0.58543
730.11700, 84.23750,    -1.71662,78.11686,50.00000,0.0000e+000,20.00000,    -0.29244,0.58465
731.91400, 84.41750,    -1.71159,78.05752,50.00000,0.0000e+000,20.00000,    -0.28358,0.58388
733.69897, 84.59750,    -1.70381,77.99955,50.00000,0.0000e+000,20.00000,    -0.27349,0.58312
735.46899, 84.77750,    -1.69952,77.94096,50.00000,0.0000e+000,20.00000,    -0.26331,0.58238
737.21600, 84.95750,    -1.69894,77.88266,50.00000,0.0000e+000,20.00000,    -0.25335,0.58164
738.97601, 85.13750,    -1.70263,77.83061,50.00000,0.0000e+000,20.00000,    -0.24296,0.58090
740.76001, 85.31750,    -1.71776,77.78619,50.00000,0.0000e+000,20.00000,    -0.23324,0.58015
742.55402, 85.49750,    -1.73884,77.74866,50.00000,0.0000e+000,20.00000,    -0.22317,0.57940
744.36298, 85.67750,    -1.75486,77.71732,50.00000,0.0000e+000,20.00000,    -0.21189,0.57865
746.17603, 85.85750,    -1.76620,77.68904,50.00000,0.0000e+000,20.00000,    -0.19963,0.57790
747.97998, 86.03750,    -1.77345,77.66148,50.00000,0.0000e+000,20.00000,    -0.18788,0.57716
749.77802, 86.21750,    -1.77626,77.63417,50.00000,0.0000e+000,20.00000,    -0.17661,0.57642
751.58502, 86.39750,    -1.77719,77.60909,50.00000,0.0000e+000,20.00000,    -0.16516,0.57567
753.38000, 86.57750,    -1.77720,77.58768,50.00000,0.0000e+000,20.00000,    -0.15340,0.57494
755.22900, 86.75750,    -1.78675,77.56630,50.00000,0.0000e+000,20.00000,    -0.14183,0.57419
757.09802, 86.93750,    -1.79671,77.54440,50.00000,0.0000e+000,20.00000,    -0.13214,0.57343
758.92200, 87.11750,    -1.80000,77.52163,50.00000,0.0000e+000,20.00000,    -0.12383,0.57269
760.72900, 87.29750,    -1.79811,77.50061,50.00000,0.0000e+000,20.00000,    -0.11706,0.57196
762.53998, 87.47750,    -1.79348,77.48055,50.00000,0.0000e+000,20.00000,    -0.11230,0.57123
764.34497, 87.65750,    -1.79340,77.46190,50.00000,0.0000e+000,20.00000,    -0.10866,0.57050
766.15802, 87.83750,    -1.79279,77.44252,50.00000,0.0000e+000,20.00000,    -0.10514,0.56978
767.95398, 88.01750,    -1.79157,77.42360,50.00000,0.0000e+000,20.00000,    -0.10200,0.56906
769.75098, 88.19750,    -1.79023,77.40714,50.00000,0.0000e+000,20.00000,-9.9437e-002,0.56835
771.54401, 88.37750,    -1.79084,77.39166,50.00000,0.0000e+000,20.00000,-9.7124e-002,0.56764
773.33398, 88.55750,    -1.79195,77.37562,50.00000,0.0000e+000,20.00000,-9.4887e-002,0.56693
775.11902, 88.73750,    -1.79195,77.35774,50.00000,0.0000e+000,20.00000,-9.3155e-002,0.56622
776.90198, 88.91750,    -1.79184,77.34202,50.00000,0.0000e+000,20.00000,-9.1349e-002,0.56552
778.68597, 89.09750,    -1.79176,77.32834,50.00000,0.0000e+000,20.00000,-8.9629e-002,0.56482
780.47400, 89.27750,    -1.79281,77.31364,50.00000,0.0000e+000,20.00000,-8.7912e-002,0.56413
782.25098, 89.45750,    -1.79410,77.29844,50.00000,0.0000e+000,20.00000,-8.6386e-002,0.56343
784.04303, 89.63750,    -1.79533,77.28370,50.00000,0.0000e+000,20.00000,-8.4584e-002,0.56274
785.81702, 89.81750,    -1.79723,77.26802,50.00000,0.0000e+000,20.00000,-8.2443e-002,0.56205
787.62000, 89.99750,    -1.80064,77.25152,50.00000,0.0000e+000,20.00000,-8.1930e-002,0.56135
789.41302, 90.17750,    -1.80518,77.23782,50.00000,0.0000e+000,20.00000,-8.1437e-002,0.56066
791.22998, 90.35750,    -1.81093,77.22488,50.00000,0.0000e+000,20.00000,-8.0505e-002,0.55996
793.04102, 90.53750,    -1.81639,77.20987,50.00000,0.0000e+000,20.00000,-7.9337e-002,0.55927
794.85797, 90.71750,    -1.82108,77.19354,50.00000,0.0000e+000,20.00000,-7.8472e-002,0.55857
796.66400, 90.89750,    -1.82337,77.17837,50.00000,0.0000e+000,20.00000,-7.8207e-002,0.55788
798.45801, 91.07750,    -1.82586,77.16429,50.00000,0.0000e+000,20.00000,-7.8395e-002,0.55720
800.25500, 91.25750,    -1.83010,77.15097,50.00000,0.0000e+000,20.00000,-7.8701e-002,0.55652
802.05798, 91.43750,    -1.83239,77.13819,50.00000,0.0000e+000,20.00000,-7.9065e-002,0.55583
803.84302, 91.61750,    -1.83376,77.12690,50.00000,0.0000e+000,20.00000,-7.8895e-002,0.55516
805.62201, 91.79750,    -1.83702,77.11252,50.00000,0.0000e+000,20.00000,-7.8573e-002,0.55449
807.41901, 91.97750,    -1.84130,77.09818,50.00000,0.0000e+000,20.00000,-7.9318e-002,0.55381
809.21997, 92.15750,    -1.84501,77.08599,50.00000,0.0000e+000,20.00000,-8.0727e-002,0.55314
811.04199, 92.33750,    -1.85415,77.07256,50.00000,0.0000e+000,20.00000,-8.1789e-002,0.55246
812.88599, 92.51750,    -1.86289,77.05925,50.00000,0.0000e+000,20.00000,-8.2267e-002,0.55177
814.72803, 92.69750,    -1.87157,77.04674,50.00000,0.0000e+000,20.00000,-8.3592e-002,0.55108
816.56097, 92.87750,    -1.87779,77.03186,50.00000,0.0000e+000,20.00000,-8.5611e-002,0.55040
818.42499, 93.05750,    -1.88210,77.01560,50.00000,0.0000e+000,20.00000,-8.7925e-002,0.54971
820.27802, 93.23750,    -1.88689,76.99932,50.00000,0.0000e+000,20.00000,-8.9992e-002,0.54902
822.07202, 93.41750,    -1.88450,76.98445,50.00000,0.0000e+000,20.00000,-9.2464e-002,0.54836
823.86700, 93.59750,    -1.87914,76.96917,50.00000,0.0000e+000,20.00000,-9.4641e-002,0.54770
825.65399, 93.77750,    -1.87521,76.95253,50.00000,0.0000e+000,20.00000,-9.6815e-002,0.54704
827.43597, 93.95750,    -1.87353,76.93471,50.00000,0.0000e+000,20.00000,-9.9869e-002,0.54639
829.23999, 94.13750,    -1.87444,76.91616,50.00000,0.0000e+000,20.00000,    -0.10258,0.54573
831.03198, 94.31750,    -1.87506,76.89816,50.00000,0.0000e+000,20.00000,    -0.10570,0.54508
832.83801, 94.49750,    -1.87646,76.87831,50.00000,0.0000e+000,20.00000,    -0.10946,0.54442
834.62598, 94.67750,    -1.87658,76.85682,50.00000,0.0000e+000,20.00000,    -0.11270,0.54377
836.44098, 94.85750,    -1.87905,76.83490,50.00000,0.0000e+000,20.00000,    -0.11561,0.54311
838.23401, 95.03750,    -1.88035,76.81414,50.00000,0.0000e+000,20.00000,    -0.11914,0.54246
840.05402, 95.21750,    -1.88169,76.79397,50.00000,0.0000e+000,20.00000,    -0.12295,0.54180
841.85400, 95.39750,    -1.88022,76.77238,50.00000,0.0000e+000,20.00000,    -0.12664,0.54115
843.65198, 95.57750,    -1.88037,76.74983,50.00000,0.0000e+000,20.00000,    -0.13054,0.54050
845.45599, 95.75750,    -1.88119,76.72644,50.00000,0.0000e+000,20.00000,    -0.13420,0.53985
847.25897, 95.93750,    -1.88372,76.70332,50.00000,0.0000e+000,20.00000,    -0.13689,0.53920
849.06799, 96.11750,    -1.88434,76.67879,50.00000,0.0000e+000,20.00000,    -0.14019,0.53855
850.85999, 96.29750,    -1.88479,76.65268,50.00000,0.0000e+000,20.00000,    -0.14429,0.53791
852.68201, 96.47750,    -1.88677,76.62638,50.00000,0.0000e+000,20.00000,    -0.14736,0.53726
854.48199, 96.65750,    -1.88638,76.59977,50.00000,0.0000e+000,20.00000,    -0.14937,0.53661
856.27502, 96.83750,    -1.88678,76.57087,50.00000,0.0000e+000,20.00000,    -0.15191,0.53597
858.07300, 97.01750,    -1.88696,76.54161,50.00000,0.0000e+000,20.00000,    -0.15564,0.53533
859.87201, 97.19750,    -1.88671,76.51321,50.00000,0.0000e+000,20.00000,    -0.15869,0.53469
861.68903, 97.37750,    -1.88899,76.48283,50.00000,0.0000e+000,20.00000,    -0.16174,0.53405
863.49799, 97.55750,    -1.89242,76.45165,50.00000,0.0000e+000,20.00000,    -0.16478,0.53341
865.31702, 97.73750,    -1.89575,76.42283,50.00000,0.0000e+000,20.00000,    -0.16750,0.53276
867.12402, 97.91750,    -1.89768,76.39357,50.00000,0.0000e+000,20.00000,    -0.16960,0.53212
868.94098, 98.09750,    -1.89889,76.35936,50.00000,0.0000e+000,20.00000,    -0.17181,0.53148
870.78101, 98.27750,    -1.90552,76.32629,50.00000,0.0000e+000,20.00000,    -0.17411,0.53083
872.60797, 98.45750,    -1.90989,76.29660,50.00000,0.0000e+000,20.00000,    -0.17559,0.53019
874.42499, 98.63750,    -1.90784,76.26699,50.00000,0.0000e+000,20.00000,    -0.17688,0.52955
876.20801, 98.81750,    -1.90398,76.23338,50.00000,0.0000e+000,20.00000,    -0.17841,0.52892
877.99298, 98.99750,    -1.90144,76.20068,50.00000,0.0000e+000,20.00000,    -0.18025,0.52830
879.78998, 99.17750,    -1.90175,76.16746,50.00000,0.0000e+000,20.00000,    -0.18162,0.52767
881.57202, 99.35750,    -1.90299,76.13293,50.00000,0.0000e+000,20.00000,    -0.18278,0.52704
883.38300, 99.53750,    -1.90497,76.09960,50.00000,0.0000e+000,20.00000,    -0.18417,0.52641
885.16602, 99.71750,    -1.90770,76.06772,50.00000,0.0000e+000,20.00000,    -0.18539,0.52579
886.96802, 99.89750,    -1.90924,76.03412,50.00000,0.0000e+000,20.00000,    -0.18562,0.52516
888.80298,100.07750,    -1.91349,75.99914,50.00000,0.0000e+000,20.00000,    -0.18636,0.52452
890.59601,100.25750,    -1.91503,75.96695,50.00000,0.0000e+000,20.00000,    -0.18811,0.52389
892.41498,100.43750,    -1.91703,75.93420,50.00000,0.0000e+000,20.00000,    -0.19044,0.52326
894.22498,100.61750,    -1.91946,75.89924,50.00000,0.0000e+000,20.00000,    -0.19171,0.52263
896.02502,100.79750,    -1.92085,75.86417,50.00000,0.0000e+000,20.00000,    -0.19338,0.52200
897.80603,100.97750,    -1.92080,75.82919,50.00000,0.0000e+000,20.00000,    -0.19495,0.52138
899.62598,101.15750,    -1.92301,75.79362,50.00000,0.0000e+000,20.00000,    -0.19569,0.52075
901.41602,101.33750,    -1.92460,75.75908,50.00000,0.0000e+000,20.00000,    -0.19664,0.52013
903.21802,101.51750,    -1.92608,75.72588,50.00000,0.0000e+000,20.00000,    -0.19771,0.51950
905.00500,101.69750,    -1.92754,75.69167,50.00000,0.0000e+000,20.00000,    -0.19879,0.51889
906.80603,101.87750,    -1.92720,75.65555,50.00000,0.0000e+000,20.00000,    -0.20009,0.51826
908.64001,102.05750,    -1.93569,75.61904,50.00000,0.0000e+000,20.00000,    -0.20150,0.51763
910.46100,102.23750,    -1.94021,75.58154,50.00000,0.0000e+000,20.00000,    -0.20235,0.51700
912.26801,102.41750,    -1.94080,75.54370,50.00000,0.0000e+000,20.00000,    -0.20298,0.51637
914.07898,102.59750,    -1.94207,75.50480,50.00000,0.0000e+000,20.00000,    -0.20363,0.51575
915.89301,102.77750,    -1.94407,75.46595,50.00000,0.0000e+000,20.00000,    -0.20461,0.51512
917.69098,102.95750,    -1.94313,75.42853,50.00000,0.0000e+000,20.00000,    -0.20510,0.51450
919.49103,103.13750,    -1.94320,75.39152,50.00000,0.0000e+000,20.00000,    -0.20554,0.51388
921.32202,103.31750,    -1.94968,75.35533,50.00000,0.0000e+000,20.00000,    -0.20633,0.51325
923.11401,103.49750,    -1.94922,75.31885,50.00000,0.0000e+000,20.00000,    -0.20616,0.51263
924.89099,103.67750,    -1.94765,75.27908,50.00000,0.0000e+000,20.00000,    -0.20433,0.51202
926.71399,103.85750,    -1.94923,75.24080,50.00000,0.0000e+000,20.00000,    -0.20260,0.51139
928.50403,104.03750,    -1.95179,75.20530,50.00000,0.0000e+000,20.00000,    -0.20080,0.51077
930.30103,104.21750,    -1.95424,75.16848,50.00000,0.0000e+000,20.00000,    -0.19874,0.51015
932.11200,104.39750,    -1.95351,75.13101,50.00000,0.0000e+000,20.00000,    -0.19578,0.50953
933.93201,104.57750,    -1.95462,75.09261,50.00000,0.0000e+000,20.00000,    -0.19140,0.50890
935.72699,104.75750,    -1.95736,75.05499,50.00000,0.0000e+000,20.00000,    -0.18685,0.50828
937.54303,104.93750,    -1.95791,75.01858,50.00000,0.0000e+000,20.00000,    -0.18281,0.50766
939.34497,105.11750,    -1.95554,74.98221,50.00000,0.0000e+000,20.00000,    -0.17846,0.50704
941.14502,105.29750,    -1.95435,74.94829,50.00000,0.0000e+000,20.00000,    -0.17338,0.50642
942.95697,105.47750,    -1.95293,74.91871,50.00000,0.0000e+000,20.00000,    -0.16671,0.50579
944.76300,105.65750,    -1.95080,74.88888,50.00000,0.0000e+000,20.00000,    -0.16014,0.50517
946.55798,105.83750,    -1.94637,74.85803,50.00000,0.0000e+000,20.00000,    -0.15351,0.50455
948.36798,106.01750,    -1.94452,74.82771,50.00000,0.0000e+000,20.00000,    -0.14703,0.50393
950.18903,106.19750,    -1.94399,74.79921,50.00000,0.0000e+000,20.00000,    -0.14078,0.50330
951.99500,106.37750,    -1.94229,74.77540,50.00000,0.0000e+000,20.00000,    -0.13413,0.50268
953.80603,106.55750,    -1.94035,74.75461,50.00000,0.0000e+000,20.00000,    -0.12664,0.50206
955.59003,106.73750,    -1.93702,74.73234,50.00000,0.0000e+000,20.00000,    -0.11972,0.50144
957.41498,106.91750,    -1.94072,74.71143,50.00000,0.0000e+000,20.00000,    -0.11333,0.50082
959.21600,107.09750,    -1.94148,74.69337,50.00000,0.0000e+000,20.00000,    -0.10729,0.50019
961.03699,107.27750,    -1.94210,74.67819,50.00000,0.0000e+000,20.00000,    -0.10220,0.49957
962.83698,107.45750,    -1.94336,74.66315,50.00000,0.0000e+000,20.00000,-9.7090e-002,0.49895
964.63599,107.63750,    -1.94226,74.65137,50.00000,0.0000e+000,20.00000,-9.0854e-002,0.49833
966.51202,107.81750,    -1.94989,74.63896,50.00000,0.0000e+000,20.00000,-8.4351e-002,0.49768
968.36102,107.99750,    -1.95484,74.62448,50.00000,0.0000e+000,20.00000,-7.8581e-002,0.49704
970.14203,108.17750,    -1.94903,74.61017,50.00000,0.0000e+000,20.00000,-7.3928e-002,0.49643
971.92200,108.35750,    -1.94255,74.59921,50.00000,0.0000e+000,20.00000,-7.0384e-002,0.49581
973.70300,108.53750,    -1.94034,74.58848,50.00000,0.0000e+000,20.00000,-6.6528e-002,0.49520
975.48901,108.71750,    -1.93788,74.57550,50.00000,0.0000e+000,20.00000,-6.2896e-002,0.49458
977.27502,108.89750,    -1.93797,74.56284,50.00000,0.0000e+000,20.00000,-5.9994e-002,0.49396
979.04102,109.07750,    -1.93832,74.55132,50.00000,0.0000e+000,20.00000,-5.8259e-002,0.49335
980.82098,109.25750,    -1.94037,74.54023,50.00000,0.0000e+000,20.00000,-5.6506e-002,0.49273
982.62903,109.43750,    -1.94372,74.53166,50.00000,0.0000e+000,20.00000,-5.5186e-002,0.49211
984.42401,109.61750,    -1.94718,74.52509,50.00000,0.0000e+000,20.00000,-5.2136e-002,0.49149
986.22498,109.79750,    -1.95000,74.51736,50.00000,0.0000e+000,20.00000,-5.0917e-002,0.49086
988.01599,109.97750,    -1.95108,74.50960,50.00000,0.0000e+000,20.00000,-4.7488e-002,0.49024
989.82397,110.15750,    -1.95522,74.50187,50.00000,0.0000e+000,20.00000,-4.4535e-002,0.48961
991.64203,110.33750,    -1.96175,74.49380,50.00000,0.0000e+000,20.00000,-4.5706e-002,0.48898
993.47198,110.51750,    -1.96823,74.48581,50.00000,0.0000e+000,20.00000,-4.6613e-002,0.48835
995.28198,110.69750,    -1.96951,74.47786,50.00000,0.0000e+000,20.00000,-4.7908e-002,0.48772
997.08099,110.87750,    -1.96865,74.46904,50.00000,0.0000e+000,20.00000,-5.2665e-002,0.48709
998.33698,111.00250,    -1.96928,74.46216,50.00000,0.0000e+000,20.00000,-5.2050e-002,0.48665