File: book/some_content/TG_ExpDat_A8%DC14; 30-1-2025-2.csv
#FILE:                       ,A8%DC14; 30-1-2025.ngb-ds3
#FORMAT:                     ,NETZSCH5
#IDENTITY:                   ,GEOPOLYMER PASTE
#DECIMAL:                    ,POINT
#SEPARATOR:                  ,COMMA
#MTYPE:                      ,DSC
#INSTRUMENT:                 ,Microlab TU Delft
#PROJECT:                    ,
#DATE/TIME:                  ,31/01/2025 4:40:42 PM
#CORR. FILE:                 ,Blank with cover; 13-1-2025.ngb-bs3
#LABORATORY:                 ,TU Delft Micro Lab
#OPERATOR:                   ,Ahmed
#REMARK:                     ,under Argon atmosphere, 10K/min
#SAMPLE:                     ,A8%DC14
#SAMPLE MASS /mg:            ,32.8
#MATERIAL:                   ,Geopolymer paste
#REFERENCE:                  ,blank
#REFERENCE MASS /mg:         ,0
#TYPE OF CRUCIBLE:           ,DSC/TG pan Al2O3
#SAMPLE CRUCIBLE MASS /mg:   ,0
#REFERENCE CRUCIBLE MASS /mg:,0
#CORR. CODE:                 ,020
#EXO:                        ,-1
#RANGE:                      ,40/10.0(K/min)/1000
#SEGMENT:                    ,S2/2

##Temp./øC,Time/min,DSC/(mW/mg),Mass/%,Gas Flow(purge1)/(ml/min),Gas Flow(purge2)/(ml/min),Gas Flow(protective)/(ml/min),DTG/(%/min),Sensit./(uV/mW)
 50.40700, 18.32583,-4.5941e-002,92.69467,50.00000,0.0000e+000,20.00000,    -0.11835,1.21260
 50.47000, 18.50083,-4.7710e-002,92.67836,50.00000,0.0000e+000,20.00000,    -0.10265,1.21251
 50.59000, 18.67583,-4.8100e-002,92.66574,50.00000,0.0000e+000,20.00000,-8.7276e-002,1.21235
 50.81700, 18.85083,-4.7978e-002,92.65773,50.00000,0.0000e+000,20.00000,-7.2160e-002,1.21204
 51.10800, 19.02583,-4.6842e-002,92.65490,50.00000,0.0000e+000,20.00000,-5.7804e-002,1.21163
 51.51500, 19.20083,-4.4885e-002,92.65334,50.00000,0.0000e+000,20.00000,-4.5274e-002,1.21107
 52.04200, 19.37583,-4.1953e-002,92.65508,50.00000,0.0000e+000,20.00000,-3.5352e-002,1.21035
 52.67800, 19.55083,-3.8329e-002,92.65933,50.00000,0.0000e+000,20.00000,-2.6503e-002,1.20947
 53.42400, 19.72583,-3.3761e-002,92.66466,50.00000,0.0000e+000,20.00000,-1.8874e-002,1.20845
 54.27500, 19.90083,-2.8688e-002,92.67164,50.00000,0.0000e+000,20.00000,-1.3863e-002,1.20728
 55.26900, 20.07583,-2.2973e-002,92.67865,50.00000,0.0000e+000,20.00000,-1.0769e-002,1.20591
 56.38100, 20.25083,-1.6551e-002,92.68481,50.00000,0.0000e+000,20.00000,-9.9088e-003,1.20438
 57.59700, 20.42583,-9.7474e-003,92.69042,50.00000,0.0000e+000,20.00000,-1.2053e-002,1.20271
 58.95200, 20.60083,-2.7118e-003,92.69778,50.00000,0.0000e+000,20.00000,-1.7450e-002,1.20084
 60.39400, 20.77583, 4.8505e-003,92.70371,50.00000,0.0000e+000,20.00000,-2.6235e-002,1.19886
 61.94300, 20.95083, 1.2342e-002,92.70669,50.00000,0.0000e+000,20.00000,-3.7748e-002,1.19673
 63.60300, 21.12583, 2.0136e-002,92.70395,50.00000,0.0000e+000,20.00000,-5.1879e-002,1.19445
 65.37700, 21.30083, 2.7826e-002,92.69732,50.00000,0.0000e+000,20.00000,-6.9564e-002,1.19202
 67.22700, 21.47583, 3.6373e-002,92.69206,50.00000,0.0000e+000,20.00000,-9.0863e-002,1.18948
 69.16600, 21.65083, 4.5117e-002,92.68300,50.00000,0.0000e+000,20.00000,    -0.11718,1.18682
 71.19800, 21.82583, 5.4260e-002,92.67011,50.00000,0.0000e+000,20.00000,    -0.14680,1.18403
 73.30100, 22.00083, 6.3884e-002,92.65616,50.00000,0.0000e+000,20.00000,    -0.17764,1.18115
 75.47600, 22.17583, 7.4410e-002,92.63768,50.00000,0.0000e+000,20.00000,    -0.21056,1.17817
 77.71600, 22.35083, 8.4976e-002,92.61096,50.00000,0.0000e+000,20.00000,    -0.24774,1.17511
 80.05200, 22.52583, 9.6640e-002,92.57710,50.00000,0.0000e+000,20.00000,    -0.29188,1.17192
 82.44000, 22.70083,     0.10947,92.53629,50.00000,0.0000e+000,20.00000,    -0.33890,1.16866
 84.90000, 22.87583,     0.12270,92.48813,50.00000,0.0000e+000,20.00000,    -0.38305,1.16530
 87.40700, 23.05083,     0.13836,92.43144,50.00000,0.0000e+000,20.00000,    -0.42994,1.16188
 89.94800, 23.22583,     0.15477,92.36418,50.00000,0.0000e+000,20.00000,    -0.47864,1.15842
 92.54400, 23.40083,     0.17220,92.28201,50.00000,0.0000e+000,20.00000,    -0.52923,1.15489
 95.17600, 23.57583,     0.19153,92.18456,50.00000,0.0000e+000,20.00000,    -0.57902,1.15132
 97.83600, 23.75083,     0.21191,92.08066,50.00000,0.0000e+000,20.00000,    -0.62937,1.14771
100.51900, 23.92583,     0.23352,91.97046,50.00000,0.0000e+000,20.00000,    -0.68047,1.14407
103.23500, 24.10083,     0.25649,91.84856,50.00000,0.0000e+000,20.00000,    -0.73008,1.14039
105.94300, 24.27583,     0.27989,91.70654,50.00000,0.0000e+000,20.00000,    -0.77667,1.13673
108.65300, 24.45083,     0.30372,91.54036,50.00000,0.0000e+000,20.00000,    -0.82025,1.13308
111.39800, 24.62583,     0.32712,91.37815,50.00000,0.0000e+000,20.00000,    -0.86134,1.12938
114.13200, 24.80083,     0.34970,91.20915,50.00000,0.0000e+000,20.00000,    -0.89992,1.12570
116.88100, 24.97583,     0.37131,91.02686,50.00000,0.0000e+000,20.00000,    -0.93476,1.12200
119.64000, 25.15083,     0.39095,90.83921,50.00000,0.0000e+000,20.00000,    -0.96505,1.11830
122.34600, 25.32583,     0.40808,90.64539,50.00000,0.0000e+000,20.00000,    -0.99007,1.11468
125.10300, 25.50083,     0.42315,90.45048,50.00000,0.0000e+000,20.00000,    -1.01003,1.11100
127.86500, 25.67583,     0.43506,90.24986,50.00000,0.0000e+000,20.00000,    -1.02741,1.10731
130.57500, 25.85083,     0.44432,90.04567,50.00000,0.0000e+000,20.00000,    -1.04079,1.10370
133.29500, 26.02583,     0.45041,89.84268,50.00000,0.0000e+000,20.00000,    -1.04838,1.10008
136.01100, 26.20083,     0.45323,89.64408,50.00000,0.0000e+000,20.00000,    -1.04704,1.09648
138.69299, 26.37583,     0.45330,89.44846,50.00000,0.0000e+000,20.00000,    -1.04239,1.09293
141.38300, 26.55083,     0.45032,89.25397,50.00000,0.0000e+000,20.00000,    -1.03726,1.08937
144.04900, 26.72583,     0.44475,89.06222,50.00000,0.0000e+000,20.00000,    -1.02853,1.08585
146.67101, 26.90083,     0.43658,88.87514,50.00000,0.0000e+000,20.00000,    -1.01785,1.08240
149.30200, 27.07583,     0.42647,88.69086,50.00000,0.0000e+000,20.00000,    -1.00170,1.07894
151.90900, 27.25083,     0.41455,88.51161,50.00000,0.0000e+000,20.00000,    -0.98264,1.07552
154.47000, 27.42583,     0.40083,88.34054,50.00000,0.0000e+000,20.00000,    -0.96192,1.07217
157.00301, 27.60083,     0.38577,88.17232,50.00000,0.0000e+000,20.00000,    -0.93931,1.06886
159.49899, 27.77583,     0.36992,88.01079,50.00000,0.0000e+000,20.00000,    -0.91497,1.06561
161.98801, 27.95083,     0.35323,87.85527,50.00000,0.0000e+000,20.00000,    -0.89062,1.06237
164.43700, 28.12583,     0.33562,87.70461,50.00000,0.0000e+000,20.00000,    -0.86716,1.05920
166.86200, 28.30083,     0.31748,87.55841,50.00000,0.0000e+000,20.00000,    -0.84302,1.05605
169.26900, 28.47583,     0.29860,87.41455,50.00000,0.0000e+000,20.00000,    -0.81823,1.05294
171.62500, 28.65083,     0.28015,87.26639,50.00000,0.0000e+000,20.00000,    -0.79310,1.04991
173.97000, 28.82583,     0.26096,87.12742,50.00000,0.0000e+000,20.00000,    -0.76770,1.04689
176.26801, 29.00083,     0.24202,87.00036,50.00000,0.0000e+000,20.00000,    -0.74343,1.04394
178.54900, 29.17583,     0.22380,86.87756,50.00000,0.0000e+000,20.00000,    -0.72055,1.04102
180.80499, 29.35083,     0.20515,86.75594,50.00000,0.0000e+000,20.00000,    -0.69687,1.03813
183.02200, 29.52583,     0.18690,86.63818,50.00000,0.0000e+000,20.00000,    -0.67441,1.03530
185.23199, 29.70083,     0.16923,86.52564,50.00000,0.0000e+000,20.00000,    -0.65251,1.03249
187.39200, 29.87583,     0.15186,86.41422,50.00000,0.0000e+000,20.00000,    -0.63175,1.02975
189.53200, 30.05083,     0.13485,86.30540,50.00000,0.0000e+000,20.00000,    -0.61110,1.02703
191.65500, 30.22583,     0.11799,86.20094,50.00000,0.0000e+000,20.00000,    -0.59147,1.02435
193.74200, 30.40083,     0.10236,86.10089,50.00000,0.0000e+000,20.00000,    -0.57045,1.02172
195.79100, 30.57583, 8.6684e-002,86.00716,50.00000,0.0000e+000,20.00000,    -0.54991,1.01914
197.83501, 30.75083, 7.1824e-002,85.91415,50.00000,0.0000e+000,20.00000,    -0.53200,1.01657
199.85899, 30.92583, 5.7346e-002,85.82135,50.00000,0.0000e+000,20.00000,    -0.51571,1.01403
201.82899, 31.10083, 4.3275e-002,85.73549,50.00000,0.0000e+000,20.00000,    -0.49964,1.01157
203.80099, 31.27583, 2.9436e-002,85.65291,50.00000,0.0000e+000,20.00000,    -0.48304,1.00910
205.74500, 31.45083, 1.6036e-002,85.57252,50.00000,0.0000e+000,20.00000,    -0.46691,1.00668
207.65700, 31.62583, 2.8719e-003,85.49570,50.00000,0.0000e+000,20.00000,    -0.45116,1.00430
209.56100, 31.80083,-9.7040e-003,85.42078,50.00000,0.0000e+000,20.00000,    -0.43538,1.00194
211.46201, 31.97583,-2.1944e-002,85.34859,50.00000,0.0000e+000,20.00000,    -0.42094,0.99959
213.31500, 32.15083,-3.4309e-002,85.27792,50.00000,0.0000e+000,20.00000,    -0.40653,0.99730
215.15800, 32.32583,-4.6402e-002,85.20773,50.00000,0.0000e+000,20.00000,    -0.39247,0.99503
217.00101, 32.50083,-5.8692e-002,85.14011,50.00000,0.0000e+000,20.00000,    -0.37880,0.99276
218.81700, 32.67583,-7.1998e-002,85.07526,50.00000,0.0000e+000,20.00000,    -0.36496,0.99053
220.62300, 32.85083,-8.4774e-002,85.01125,50.00000,0.0000e+000,20.00000,    -0.35331,0.98832
222.41299, 33.02583,-9.8595e-002,84.94968,50.00000,0.0000e+000,20.00000,    -0.34247,0.98613
224.18800, 33.20083,    -0.11264,84.89293,50.00000,0.0000e+000,20.00000,    -0.33162,0.98397
225.94299, 33.37583,    -0.12701,84.83821,50.00000,0.0000e+000,20.00000,    -0.32092,0.98183
227.71201, 33.55083,    -0.14129,84.78512,50.00000,0.0000e+000,20.00000,    -0.31065,0.97969
229.45799, 33.72583,    -0.15545,84.73183,50.00000,0.0000e+000,20.00000,    -0.30106,0.97757
231.19000, 33.90083,    -0.16906,84.67986,50.00000,0.0000e+000,20.00000,    -0.29170,0.97548
232.92000, 34.07583,    -0.18266,84.63310,50.00000,0.0000e+000,20.00000,    -0.28286,0.97339
234.63699, 34.25083,    -0.19606,84.58973,50.00000,0.0000e+000,20.00000,    -0.27454,0.97132
236.36800, 34.42583,    -0.20886,84.54756,50.00000,0.0000e+000,20.00000,    -0.26683,0.96924
238.05600, 34.60083,    -0.22144,84.50204,50.00000,0.0000e+000,20.00000,    -0.25916,0.96722
239.77400, 34.77583,    -0.23353,84.45652,50.00000,0.0000e+000,20.00000,    -0.25132,0.96516
241.46700, 34.95083,    -0.24578,84.41411,50.00000,0.0000e+000,20.00000,    -0.24458,0.96314
243.14200, 35.12583,    -0.25650,84.37333,50.00000,0.0000e+000,20.00000,    -0.23860,0.96115
244.83099, 35.30083,    -0.26761,84.33538,50.00000,0.0000e+000,20.00000,    -0.23318,0.95914
246.52100, 35.47583,    -0.27811,84.29664,50.00000,0.0000e+000,20.00000,    -0.22834,0.95714
248.18500, 35.65083,    -0.28772,84.25930,50.00000,0.0000e+000,20.00000,    -0.22378,0.95517
249.85800, 35.82583,    -0.29703,84.22200,50.00000,0.0000e+000,20.00000,    -0.22025,0.95320
251.52800, 36.00083,    -0.30671,84.18308,50.00000,0.0000e+000,20.00000,    -0.21774,0.95123
253.17400, 36.17583,    -0.31587,84.14519,50.00000,0.0000e+000,20.00000,    -0.21596,0.94930
254.85500, 36.35083,    -0.32477,84.10793,50.00000,0.0000e+000,20.00000,    -0.21385,0.94732
256.53799, 36.52583,    -0.33406,84.07309,50.00000,0.0000e+000,20.00000,    -0.21092,0.94536
258.17899, 36.70083,    -0.34268,84.03863,50.00000,0.0000e+000,20.00000,    -0.20870,0.94344
259.85199, 36.87583,    -0.35164,84.00506,50.00000,0.0000e+000,20.00000,    -0.20621,0.94149
261.52802, 37.05083,    -0.35982,83.97137,50.00000,0.0000e+000,20.00000,    -0.20473,0.93955
263.19299, 37.22583,    -0.36726,83.93679,50.00000,0.0000e+000,20.00000,    -0.20362,0.93762
264.86301, 37.40083,    -0.37495,83.90073,50.00000,0.0000e+000,20.00000,    -0.20245,0.93569
266.53699, 37.57583,    -0.38193,83.86400,50.00000,0.0000e+000,20.00000,    -0.20208,0.93376
268.21201, 37.75083,    -0.38891,83.82861,50.00000,0.0000e+000,20.00000,    -0.20162,0.93183
269.89099, 37.92583,    -0.39614,83.79282,50.00000,0.0000e+000,20.00000,    -0.20107,0.92990
271.55099, 38.10083,    -0.40254,83.75712,50.00000,0.0000e+000,20.00000,    -0.20066,0.92800
273.21799, 38.27583,    -0.40847,83.72102,50.00000,0.0000e+000,20.00000,    -0.20060,0.92610
274.89499, 38.45083,    -0.41453,83.68541,50.00000,0.0000e+000,20.00000,    -0.20090,0.92419
276.56500, 38.62583,    -0.42057,83.65155,50.00000,0.0000e+000,20.00000,    -0.20196,0.92229
278.24600, 38.80083,    -0.42675,83.61885,50.00000,0.0000e+000,20.00000,    -0.20377,0.92038
279.93301, 38.97583,    -0.43275,83.58476,50.00000,0.0000e+000,20.00000,    -0.20527,0.91847
281.59698, 39.15083,    -0.43912,83.55067,50.00000,0.0000e+000,20.00000,    -0.20615,0.91660
283.28299, 39.32583,    -0.44520,83.51619,50.00000,0.0000e+000,20.00000,    -0.20697,0.91470
284.98499, 39.50083,    -0.45120,83.47967,50.00000,0.0000e+000,20.00000,    -0.20822,0.91279
286.65500, 39.67583,    -0.45672,83.44303,50.00000,0.0000e+000,20.00000,    -0.20928,0.91092
288.33401, 39.85083,    -0.46145,83.40683,50.00000,0.0000e+000,20.00000,    -0.21104,0.90904
290.02499, 40.02583,    -0.46648,83.37079,50.00000,0.0000e+000,20.00000,    -0.21330,0.90716
291.72400, 40.20083,    -0.47098,83.33551,50.00000,0.0000e+000,20.00000,    -0.21531,0.90527
293.40302, 40.37583,    -0.47540,83.29882,50.00000,0.0000e+000,20.00000,    -0.21765,0.90341
295.08401, 40.55083,    -0.48017,83.25949,50.00000,0.0000e+000,20.00000,    -0.22109,0.90155
296.77899, 40.72583,    -0.48497,83.21934,50.00000,0.0000e+000,20.00000,    -0.22405,0.89969
298.46701, 40.90083,    -0.49032,83.18049,50.00000,0.0000e+000,20.00000,    -0.22652,0.89783
300.16901, 41.07583,    -0.49612,83.14154,50.00000,0.0000e+000,20.00000,    -0.22922,0.89596
301.86899, 41.25083,    -0.50131,83.10095,50.00000,0.0000e+000,20.00000,    -0.23220,0.89411
303.55600, 41.42583,    -0.50660,83.06132,50.00000,0.0000e+000,20.00000,    -0.23566,0.89227
305.26999, 41.60083,    -0.51058,83.02081,50.00000,0.0000e+000,20.00000,    -0.23900,0.89040
306.97601, 41.77583,    -0.51468,82.97691,50.00000,0.0000e+000,20.00000,    -0.24158,0.88855
308.67001, 41.95083,    -0.51860,82.93317,50.00000,0.0000e+000,20.00000,    -0.24432,0.88672
310.38000, 42.12583,    -0.52287,82.89019,50.00000,0.0000e+000,20.00000,    -0.24760,0.88488
312.09399, 42.30083,    -0.52778,82.84548,50.00000,0.0000e+000,20.00000,    -0.25100,0.88304
313.81799, 42.47583,    -0.53303,82.80048,50.00000,0.0000e+000,20.00000,    -0.25458,0.88119
315.54300, 42.65083,    -0.53750,82.75694,50.00000,0.0000e+000,20.00000,    -0.25819,0.87934
317.24500, 42.82583,    -0.54182,82.71347,50.00000,0.0000e+000,20.00000,    -0.26195,0.87753
318.96201, 43.00083,    -0.54561,82.66849,50.00000,0.0000e+000,20.00000,    -0.26653,0.87570
320.67300, 43.17583,    -0.54946,82.61984,50.00000,0.0000e+000,20.00000,    -0.27130,0.87389
322.39600, 43.35083,    -0.55314,82.57049,50.00000,0.0000e+000,20.00000,    -0.27495,0.87207
324.11700, 43.52583,    -0.55747,82.52362,50.00000,0.0000e+000,20.00000,    -0.27771,0.87026
325.83899, 43.70083,    -0.56072,82.47850,50.00000,0.0000e+000,20.00000,    -0.28124,0.86845
327.54901, 43.87583,    -0.56435,82.43187,50.00000,0.0000e+000,20.00000,    -0.28584,0.86666
329.28000, 44.05083,    -0.56784,82.38257,50.00000,0.0000e+000,20.00000,    -0.29039,0.86485
330.98801, 44.22583,    -0.57181,82.33031,50.00000,0.0000e+000,20.00000,    -0.29466,0.86307
332.70300, 44.40083,    -0.57556,82.27685,50.00000,0.0000e+000,20.00000,    -0.29963,0.86129
334.41199, 44.57583,    -0.58005,82.22509,50.00000,0.0000e+000,20.00000,    -0.30531,0.85952
336.14700, 44.75083,    -0.58516,82.17053,50.00000,0.0000e+000,20.00000,    -0.31092,0.85773
337.87900, 44.92583,    -0.59103,82.11220,50.00000,0.0000e+000,20.00000,    -0.31567,0.85595
339.60800, 45.10083,    -0.59645,82.05715,50.00000,0.0000e+000,20.00000,    -0.31984,0.85417
341.34299, 45.27583,    -0.60069,82.00531,50.00000,0.0000e+000,20.00000,    -0.32512,0.85240
343.06799, 45.45083,    -0.60407,81.95030,50.00000,0.0000e+000,20.00000,    -0.33172,0.85064
344.80801, 45.62583,    -0.60664,81.89118,50.00000,0.0000e+000,20.00000,    -0.33818,0.84887
346.53900, 45.80083,    -0.60883,81.83093,50.00000,0.0000e+000,20.00000,    -0.34425,0.84712
348.25601, 45.97583,    -0.61046,81.77031,50.00000,0.0000e+000,20.00000,    -0.34987,0.84539
349.98199, 46.15083,    -0.61235,81.70879,50.00000,0.0000e+000,20.00000,    -0.35493,0.84365
351.70200, 46.32583,    -0.61668,81.64542,50.00000,0.0000e+000,20.00000,    -0.35984,0.84192
353.45099, 46.50083,    -0.62131,81.58092,50.00000,0.0000e+000,20.00000,    -0.36425,0.84018
355.19299, 46.67583,    -0.62604,81.51644,50.00000,0.0000e+000,20.00000,    -0.36714,0.83844
356.94101, 46.85083,    -0.62873,81.45208,50.00000,0.0000e+000,20.00000,    -0.36999,0.83670
358.67899, 47.02583,    -0.63083,81.38589,50.00000,0.0000e+000,20.00000,    -0.37405,0.83498
360.42300, 47.20083,    -0.63266,81.31702,50.00000,0.0000e+000,20.00000,    -0.37767,0.83326
362.16400, 47.37583,    -0.63327,81.24742,50.00000,0.0000e+000,20.00000,    -0.37997,0.83155
363.88599, 47.55083,    -0.63470,81.17783,50.00000,0.0000e+000,20.00000,    -0.38146,0.82986
365.57300, 47.72583,    -0.63666,81.10685,50.00000,0.0000e+000,20.00000,    -0.38298,0.82821
367.32401, 47.90083,    -0.64017,81.03483,50.00000,0.0000e+000,20.00000,    -0.38395,0.82650
369.02701, 48.07583,    -0.64287,80.96373,50.00000,0.0000e+000,20.00000,    -0.38431,0.82485
370.73499, 48.25083,    -0.64512,80.89423,50.00000,0.0000e+000,20.00000,    -0.38392,0.82319
372.46899, 48.42583,    -0.65133,80.82622,50.00000,0.0000e+000,20.00000,    -0.38270,0.82152
374.17801, 48.60083,    -0.65925,80.75846,50.00000,0.0000e+000,20.00000,    -0.38159,0.81988
375.92300, 48.77583,    -0.66742,80.69089,50.00000,0.0000e+000,20.00000,    -0.38048,0.81820
377.66400, 48.95083,    -0.67393,80.62415,50.00000,0.0000e+000,20.00000,    -0.37864,0.81654
379.38300, 49.12583,    -0.67808,80.55807,50.00000,0.0000e+000,20.00000,    -0.37600,0.81491
381.08600, 49.30083,    -0.68323,80.49240,50.00000,0.0000e+000,20.00000,    -0.37371,0.81329
382.80200, 49.47583,    -0.68916,80.42661,50.00000,0.0000e+000,20.00000,    -0.37098,0.81167
384.52802, 49.65083,    -0.69740,80.36127,50.00000,0.0000e+000,20.00000,    -0.36734,0.81004
386.26199, 49.82583,    -0.70689,80.29729,50.00000,0.0000e+000,20.00000,    -0.36321,0.80841
387.99600, 50.00083,    -0.71740,80.23380,50.00000,0.0000e+000,20.00000,    -0.35957,0.80679
389.73401, 50.17583,    -0.72629,80.17259,50.00000,0.0000e+000,20.00000,    -0.35576,0.80517
391.47198, 50.35083,    -0.73603,80.11278,50.00000,0.0000e+000,20.00000,    -0.35152,0.80355
393.22501, 50.52583,    -0.74414,80.05202,50.00000,0.0000e+000,20.00000,    -0.34814,0.80193
394.94800, 50.70083,    -0.75169,79.99072,50.00000,0.0000e+000,20.00000,    -0.34553,0.80034
396.68100, 50.87583,    -0.75898,79.93047,50.00000,0.0000e+000,20.00000,    -0.34363,0.79875
398.40900, 51.05083,    -0.76668,79.86999,50.00000,0.0000e+000,20.00000,    -0.34173,0.79716
400.15601, 51.22583,    -0.77476,79.80904,50.00000,0.0000e+000,20.00000,    -0.33981,0.79557
401.89899, 51.40083,    -0.78267,79.74970,50.00000,0.0000e+000,20.00000,    -0.33785,0.79398
403.64801, 51.57583,    -0.79055,79.69254,50.00000,0.0000e+000,20.00000,    -0.33649,0.79240
405.40900, 51.75083,    -0.79887,79.63571,50.00000,0.0000e+000,20.00000,    -0.33624,0.79080
407.16800, 51.92583,    -0.81014,79.57966,50.00000,0.0000e+000,20.00000,    -0.33593,0.78922
408.94101, 52.10083,    -0.82134,79.52693,50.00000,0.0000e+000,20.00000,    -0.33519,0.78763
410.74600, 52.27583,    -0.82886,79.47324,50.00000,0.0000e+000,20.00000,    -0.33452,0.78602
412.50201, 52.45083,    -0.83351,79.41642,50.00000,0.0000e+000,20.00000,    -0.33362,0.78446
414.26901, 52.62583,    -0.83702,79.35773,50.00000,0.0000e+000,20.00000,    -0.33254,0.78289
416.00800, 52.80083,    -0.83979,79.29834,50.00000,0.0000e+000,20.00000,    -0.33228,0.78135
417.73801, 52.97583,    -0.84290,79.23981,50.00000,0.0000e+000,20.00000,    -0.33214,0.77983
419.46600, 53.15083,    -0.84642,79.18113,50.00000,0.0000e+000,20.00000,    -0.33241,0.77831
421.18301, 53.32583,    -0.84976,79.12229,50.00000,0.0000e+000,20.00000,    -0.33335,0.77681
422.92599, 53.50083,    -0.85578,79.06107,50.00000,0.0000e+000,20.00000,    -0.33446,0.77529
424.64600, 53.67583,    -0.86302,78.99793,50.00000,0.0000e+000,20.00000,    -0.33472,0.77380
426.39700, 53.85083,    -0.87031,78.93944,50.00000,0.0000e+000,20.00000,    -0.33609,0.77229
428.12399, 54.02583,    -0.87649,78.88221,50.00000,0.0000e+000,20.00000,    -0.33854,0.77080
429.87399, 54.20083,    -0.88279,78.82383,50.00000,0.0000e+000,20.00000,    -0.33995,0.76930
431.60400, 54.37583,    -0.88837,78.76692,50.00000,0.0000e+000,20.00000,    -0.34080,0.76782
433.33701, 54.55083,    -0.89330,78.70889,50.00000,0.0000e+000,20.00000,    -0.34129,0.76635
435.06601, 54.72583,    -0.89826,78.64891,50.00000,0.0000e+000,20.00000,    -0.34199,0.76488
436.79800, 54.90083,    -0.90373,78.58785,50.00000,0.0000e+000,20.00000,    -0.34284,0.76342
438.53101, 55.07583,    -0.90907,78.52661,50.00000,0.0000e+000,20.00000,    -0.34360,0.76196
440.26700, 55.25083,    -0.91414,78.46502,50.00000,0.0000e+000,20.00000,    -0.34379,0.76050
441.98901, 55.42583,    -0.91842,78.40617,50.00000,0.0000e+000,20.00000,    -0.34298,0.75906
443.72198, 55.60083,    -0.92348,78.34819,50.00000,0.0000e+000,20.00000,    -0.34282,0.75762
445.45401, 55.77583,    -0.92877,78.28739,50.00000,0.0000e+000,20.00000,    -0.34377,0.75618
447.17499, 55.95083,    -0.93296,78.22618,50.00000,0.0000e+000,20.00000,    -0.34441,0.75476
448.88800, 56.12583,    -0.93887,78.16537,50.00000,0.0000e+000,20.00000,    -0.34532,0.75335
450.62100, 56.30083,    -0.94426,78.10424,50.00000,0.0000e+000,20.00000,    -0.34705,0.75193
452.37201, 56.47583,    -0.94981,78.04297,50.00000,0.0000e+000,20.00000,    -0.34855,0.75050
454.09100, 56.65083,    -0.95342,77.98133,50.00000,0.0000e+000,20.00000,    -0.34925,0.74910
455.78500, 56.82583,    -0.95358,77.91977,50.00000,0.0000e+000,20.00000,    -0.34989,0.74773
457.47800, 57.00083,    -0.95555,77.85873,50.00000,0.0000e+000,20.00000,    -0.35089,0.74636
459.17999, 57.17583,    -0.96217,77.79867,50.00000,0.0000e+000,20.00000,    -0.35212,0.74500
460.91299, 57.35083,    -0.97188,77.73844,50.00000,0.0000e+000,20.00000,    -0.35360,0.74361
462.65601, 57.52583,    -0.98126,77.67817,50.00000,0.0000e+000,20.00000,    -0.35421,0.74222
464.41199, 57.70083,    -0.98995,77.61746,50.00000,0.0000e+000,20.00000,    -0.35494,0.74082
466.17001, 57.87583,    -0.99782,77.55710,50.00000,0.0000e+000,20.00000,    -0.35621,0.73943
467.92300, 58.05083,    -1.00407,77.49485,50.00000,0.0000e+000,20.00000,    -0.35766,0.73805
469.66699, 58.22583,    -1.00966,77.43031,50.00000,0.0000e+000,20.00000,    -0.35912,0.73668
471.43100, 58.40083,    -1.01374,77.36623,50.00000,0.0000e+000,20.00000,    -0.36009,0.73530
473.17999, 58.57583,    -1.01774,77.30332,50.00000,0.0000e+000,20.00000,    -0.36086,0.73394
474.92801, 58.75083,    -1.02156,77.23864,50.00000,0.0000e+000,20.00000,    -0.36176,0.73258
476.68600, 58.92583,    -1.02607,77.17341,50.00000,0.0000e+000,20.00000,    -0.36353,0.73122
478.43100, 59.10083,    -1.03217,77.10929,50.00000,0.0000e+000,20.00000,    -0.36547,0.72988
480.19601, 59.27583,    -1.03833,77.04751,50.00000,0.0000e+000,20.00000,    -0.36744,0.72853
481.95401, 59.45083,    -1.04242,76.98450,50.00000,0.0000e+000,20.00000,    -0.37002,0.72718
483.70801, 59.62583,    -1.04677,76.91949,50.00000,0.0000e+000,20.00000,    -0.37301,0.72585
485.45200, 59.80083,    -1.05038,76.85359,50.00000,0.0000e+000,20.00000,    -0.37456,0.72453
487.20001, 59.97583,    -1.05448,76.78685,50.00000,0.0000e+000,20.00000,    -0.37489,0.72321
488.95999, 60.15083,    -1.06176,76.72124,50.00000,0.0000e+000,20.00000,    -0.37519,0.72189
490.72299, 60.32583,    -1.06948,76.65650,50.00000,0.0000e+000,20.00000,    -0.37615,0.72057
492.49100, 60.50083,    -1.07519,76.59226,50.00000,0.0000e+000,20.00000,    -0.37710,0.71926
494.24500, 60.67583,    -1.07889,76.52635,50.00000,0.0000e+000,20.00000,    -0.37708,0.71795
495.99799, 60.85083,    -1.08194,76.45903,50.00000,0.0000e+000,20.00000,    -0.37750,0.71666
497.73199, 61.02583,    -1.08501,76.39195,50.00000,0.0000e+000,20.00000,    -0.37899,0.71538
499.46399, 61.20083,    -1.08765,76.32340,50.00000,0.0000e+000,20.00000,    -0.38099,0.71411
501.21301, 61.37583,    -1.09211,76.25178,50.00000,0.0000e+000,20.00000,    -0.38224,0.71284
502.94101, 61.55083,    -1.09708,76.18281,50.00000,0.0000e+000,20.00000,    -0.38338,0.71158
504.67899, 61.72583,    -1.10223,76.11762,50.00000,0.0000e+000,20.00000,    -0.38464,0.71033
506.41400, 61.90083,    -1.10824,76.05227,50.00000,0.0000e+000,20.00000,    -0.38547,0.70907
508.15399, 62.07583,    -1.11375,75.98609,50.00000,0.0000e+000,20.00000,    -0.38596,0.70783
509.91400, 62.25083,    -1.11853,75.91887,50.00000,0.0000e+000,20.00000,    -0.38665,0.70657
511.65201, 62.42583,    -1.12326,75.85267,50.00000,0.0000e+000,20.00000,    -0.38777,0.70533
513.40002, 62.60083,    -1.12831,75.78739,50.00000,0.0000e+000,20.00000,    -0.38926,0.70409
515.14099, 62.77583,    -1.13329,75.71985,50.00000,0.0000e+000,20.00000,    -0.39130,0.70286
516.87799, 62.95083,    -1.13798,75.65096,50.00000,0.0000e+000,20.00000,    -0.39220,0.70164
518.63098, 63.12583,    -1.14376,75.58175,50.00000,0.0000e+000,20.00000,    -0.39107,0.70042
520.38800, 63.30083,    -1.14873,75.51282,50.00000,0.0000e+000,20.00000,    -0.39009,0.69919
522.13702, 63.47583,    -1.15256,75.44198,50.00000,0.0000e+000,20.00000,    -0.39029,0.69798
523.88702, 63.65083,    -1.15676,75.37156,50.00000,0.0000e+000,20.00000,    -0.39091,0.69677
525.63000, 63.82583,    -1.16177,75.30385,50.00000,0.0000e+000,20.00000,    -0.39110,0.69557
527.37201, 64.00083,    -1.16544,75.23729,50.00000,0.0000e+000,20.00000,    -0.39144,0.69437
529.11499, 64.17583,    -1.16828,75.16949,50.00000,0.0000e+000,20.00000,    -0.39159,0.69318
530.83197, 64.35083,    -1.17146,75.09861,50.00000,0.0000e+000,20.00000,    -0.39188,0.69202
532.56500, 64.52583,    -1.17476,75.02460,50.00000,0.0000e+000,20.00000,    -0.39142,0.69084
534.30402, 64.70084,    -1.17956,74.95104,50.00000,0.0000e+000,20.00000,    -0.39042,0.68967
536.04102, 64.87583,    -1.18524,74.88376,50.00000,0.0000e+000,20.00000,    -0.38895,0.68851
537.77802, 65.05083,    -1.19184,74.81670,50.00000,0.0000e+000,20.00000,    -0.38706,0.68735
539.54700, 65.22583,    -1.19833,74.74958,50.00000,0.0000e+000,20.00000,    -0.38490,0.68617
541.29797, 65.40083,    -1.20613,74.68227,50.00000,0.0000e+000,20.00000,    -0.38227,0.68501
543.04797, 65.57584,    -1.21126,74.61554,50.00000,0.0000e+000,20.00000,    -0.37976,0.68385
544.78198, 65.75083,    -1.21597,74.54831,50.00000,0.0000e+000,20.00000,    -0.37780,0.68271
546.54498, 65.92583,    -1.22342,74.48013,50.00000,0.0000e+000,20.00000,    -0.37566,0.68156
548.30200, 66.10083,    -1.23023,74.41336,50.00000,0.0000e+000,20.00000,    -0.37207,0.68042
550.04901, 66.27583,    -1.23581,74.34793,50.00000,0.0000e+000,20.00000,    -0.36757,0.67928
551.80701, 66.45084,    -1.23997,74.28333,50.00000,0.0000e+000,20.00000,    -0.36290,0.67815
553.54401, 66.62583,    -1.24326,74.21872,50.00000,0.0000e+000,20.00000,    -0.35913,0.67703
555.27802, 66.80083,    -1.24719,74.15609,50.00000,0.0000e+000,20.00000,    -0.35536,0.67592
557.02301, 66.97583,    -1.25252,74.09424,50.00000,0.0000e+000,20.00000,    -0.35106,0.67481
558.78198, 67.15083,    -1.25943,74.03229,50.00000,0.0000e+000,20.00000,    -0.34698,0.67369
560.51898, 67.32584,    -1.26526,73.97183,50.00000,0.0000e+000,20.00000,    -0.34228,0.67259
562.26898, 67.50083,    -1.27201,73.91240,50.00000,0.0000e+000,20.00000,    -0.33755,0.67149
564.00897, 67.67583,    -1.27883,73.85269,50.00000,0.0000e+000,20.00000,    -0.33208,0.67040
565.76599, 67.85083,    -1.28545,73.79517,50.00000,0.0000e+000,20.00000,    -0.32610,0.66930
567.51703, 68.02583,    -1.29234,73.73934,50.00000,0.0000e+000,20.00000,    -0.32064,0.66821
569.27802, 68.20084,    -1.29892,73.68219,50.00000,0.0000e+000,20.00000,    -0.31534,0.66713
571.02899, 68.37583,    -1.30462,73.62489,50.00000,0.0000e+000,20.00000,    -0.30909,0.66605
572.81097, 68.55083,    -1.31376,73.57070,50.00000,0.0000e+000,20.00000,    -0.30228,0.66495
574.58301, 68.72583,    -1.32224,73.51910,50.00000,0.0000e+000,20.00000,    -0.29683,0.66387
576.31403, 68.90083,    -1.32652,73.46687,50.00000,0.0000e+000,20.00000,    -0.29142,0.66282
578.05298, 69.07584,    -1.32888,73.41578,50.00000,0.0000e+000,20.00000,    -0.28514,0.66176
579.79700, 69.25083,    -1.33476,73.36653,50.00000,0.0000e+000,20.00000,    -0.27902,0.66071
581.55402, 69.42583,    -1.34268,73.31736,50.00000,0.0000e+000,20.00000,    -0.27347,0.65966
583.32898, 69.60083,    -1.35021,73.27099,50.00000,0.0000e+000,20.00000,    -0.26803,0.65860
585.07599, 69.77583,    -1.35524,73.22529,50.00000,0.0000e+000,20.00000,    -0.26312,0.65756
586.81799, 69.95084,    -1.35787,73.17922,50.00000,0.0000e+000,20.00000,    -0.25820,0.65652
588.54303, 70.12583,    -1.35828,73.13540,50.00000,0.0000e+000,20.00000,    -0.25284,0.65551
590.26599, 70.30083,    -1.36066,73.09604,50.00000,0.0000e+000,20.00000,    -0.24771,0.65449
592.03998, 70.47583,    -1.37183,73.05572,50.00000,0.0000e+000,20.00000,    -0.24322,0.65346
593.84802, 70.65083,    -1.38927,73.01292,50.00000,0.0000e+000,20.00000,    -0.23862,0.65240
595.65002, 70.82584,    -1.40221,72.97260,50.00000,0.0000e+000,20.00000,    -0.23410,0.65136
597.44598, 71.00083,    -1.40853,72.93572,50.00000,0.0000e+000,20.00000,    -0.23017,0.65032
599.21100, 71.17583,    -1.41001,72.89707,50.00000,0.0000e+000,20.00000,    -0.22605,0.64931
600.96100, 71.35083,    -1.41284,72.85773,50.00000,0.0000e+000,20.00000,    -0.22217,0.64830
602.73901, 71.52583,    -1.41602,72.81926,50.00000,0.0000e+000,20.00000,    -0.21856,0.64729
604.49500, 71.70084,    -1.41838,72.78108,50.00000,0.0000e+000,20.00000,    -0.21448,0.64629
606.22601, 71.87583,    -1.42071,72.74259,50.00000,0.0000e+000,20.00000,    -0.21055,0.64531
607.96997, 72.05083,    -1.42522,72.70520,50.00000,0.0000e+000,20.00000,    -0.20769,0.64433
609.72302, 72.22583,    -1.42982,72.66860,50.00000,0.0000e+000,20.00000,    -0.20564,0.64335
611.46698, 72.40083,    -1.43340,72.63343,50.00000,0.0000e+000,20.00000,    -0.20278,0.64238
613.19897, 72.57584,    -1.43508,72.59823,50.00000,0.0000e+000,20.00000,    -0.19996,0.64141
614.91199, 72.75083,    -1.43659,72.56260,50.00000,0.0000e+000,20.00000,    -0.19844,0.64047
616.65302, 72.92583,    -1.44042,72.52782,50.00000,0.0000e+000,20.00000,    -0.19660,0.63951
618.38098, 73.10083,    -1.44580,72.49392,50.00000,0.0000e+000,20.00000,    -0.19411,0.63856
620.11603, 73.27583,    -1.45178,72.46098,50.00000,0.0000e+000,20.00000,    -0.19183,0.63761
621.84802, 73.45084,    -1.45612,72.42933,50.00000,0.0000e+000,20.00000,    -0.18976,0.63667
623.57898, 73.62583,    -1.46065,72.39840,50.00000,0.0000e+000,20.00000,    -0.18699,0.63573
625.31500, 73.80083,    -1.46559,72.36765,50.00000,0.0000e+000,20.00000,    -0.18448,0.63479
627.05603, 73.97583,    -1.47131,72.33653,50.00000,0.0000e+000,20.00000,    -0.18249,0.63386
628.82898, 74.15083,    -1.47947,72.30472,50.00000,0.0000e+000,20.00000,    -0.18086,0.63291
630.62201, 74.32584,    -1.49455,72.27311,50.00000,0.0000e+000,20.00000,    -0.17967,0.63195
632.44098, 74.50083,    -1.50436,72.24098,50.00000,0.0000e+000,20.00000,    -0.17850,0.63099
634.20203, 74.67583,    -1.50684,72.20936,50.00000,0.0000e+000,20.00000,    -0.17785,0.63006
635.96600, 74.85083,    -1.50525,72.17901,50.00000,0.0000e+000,20.00000,    -0.17759,0.62913
637.69702, 75.02583,    -1.50046,72.14869,50.00000,0.0000e+000,20.00000,    -0.17786,0.62822
639.42297, 75.20084,    -1.49728,72.11781,50.00000,0.0000e+000,20.00000,    -0.17909,0.62732
641.12598, 75.37583,    -1.49698,72.08853,50.00000,0.0000e+000,20.00000,    -0.18083,0.62644
642.86798, 75.55083,    -1.49791,72.06024,50.00000,0.0000e+000,20.00000,    -0.18238,0.62554
644.58502, 75.72583,    -1.50055,72.03085,50.00000,0.0000e+000,20.00000,    -0.18390,0.62465
646.30499, 75.90083,    -1.50372,72.00111,50.00000,0.0000e+000,20.00000,    -0.18619,0.62377
648.07001, 76.07584,    -1.50780,71.97087,50.00000,0.0000e+000,20.00000,    -0.18917,0.62287
649.83301, 76.25083,    -1.51346,71.93995,50.00000,0.0000e+000,20.00000,    -0.19226,0.62197
651.59497, 76.42583,    -1.51717,71.90777,50.00000,0.0000e+000,20.00000,    -0.19591,0.62108
653.33398, 76.60083,    -1.51812,71.87449,50.00000,0.0000e+000,20.00000,    -0.20082,0.62020
655.07501, 76.77583,    -1.51647,71.84086,50.00000,0.0000e+000,20.00000,    -0.20598,0.61932
656.81201, 76.95084,    -1.51473,71.80515,50.00000,0.0000e+000,20.00000,    -0.21020,0.61845
658.56403, 77.12583,    -1.51491,71.76764,50.00000,0.0000e+000,20.00000,    -0.21375,0.61758
660.33301, 77.30083,    -1.51726,71.73070,50.00000,0.0000e+000,20.00000,    -0.21744,0.61670
662.15900, 77.47583,    -1.53036,71.69460,50.00000,0.0000e+000,20.00000,    -0.22019,0.61580
663.98700, 77.65083,    -1.53922,71.65651,50.00000,0.0000e+000,20.00000,    -0.22212,0.61490
665.79700, 77.82584,    -1.53868,71.61470,50.00000,0.0000e+000,20.00000,    -0.22396,0.61401
667.55298, 78.00083,    -1.53279,71.57177,50.00000,0.0000e+000,20.00000,    -0.22548,0.61315
669.32397, 78.17583,    -1.52545,71.52772,50.00000,0.0000e+000,20.00000,    -0.22649,0.61229
671.07300, 78.35083,    -1.52156,71.48023,50.00000,0.0000e+000,20.00000,    -0.22655,0.61144
672.82599, 78.52583,    -1.51925,71.43085,50.00000,0.0000e+000,20.00000,    -0.22606,0.61060
674.57599, 78.70084,    -1.51806,71.38317,50.00000,0.0000e+000,20.00000,    -0.22492,0.60975
676.32300, 78.87583,    -1.52076,71.33889,50.00000,0.0000e+000,20.00000,    -0.22272,0.60892
678.09399, 79.05083,    -1.52670,71.29637,50.00000,0.0000e+000,20.00000,    -0.22003,0.60807
679.87299, 79.22583,    -1.53480,71.25603,50.00000,0.0000e+000,20.00000,    -0.21749,0.60723
681.64001, 79.40083,    -1.53914,71.21862,50.00000,0.0000e+000,20.00000,    -0.21447,0.60639
683.38702, 79.57584,    -1.53805,71.18202,50.00000,0.0000e+000,20.00000,    -0.20987,0.60557
685.10498, 79.75083,    -1.53329,71.14556,50.00000,0.0000e+000,20.00000,    -0.20410,0.60476
686.81299, 79.92583,    -1.52900,71.10980,50.00000,0.0000e+000,20.00000,    -0.19840,0.60396
688.51300, 80.10083,    -1.52557,71.07562,50.00000,0.0000e+000,20.00000,    -0.19240,0.60317
690.21100, 80.27583,    -1.52568,71.04351,50.00000,0.0000e+000,20.00000,    -0.18560,0.60238
691.93201, 80.45084,    -1.52889,71.01253,50.00000,0.0000e+000,20.00000,    -0.17815,0.60159
693.67102, 80.62583,    -1.53453,70.98284,50.00000,0.0000e+000,20.00000,    -0.17099,0.60078
695.39600, 80.80083,    -1.53970,70.95487,50.00000,0.0000e+000,20.00000,    -0.16484,0.59999
697.13501, 80.97583,    -1.54431,70.92749,50.00000,0.0000e+000,20.00000,    -0.15907,0.59920
698.88202, 81.15083,    -1.54624,70.90114,50.00000,0.0000e+000,20.00000,    -0.15367,0.59840
700.61499, 81.32584,    -1.54875,70.87656,50.00000,0.0000e+000,20.00000,    -0.14894,0.59761
702.37097, 81.50083,    -1.55303,70.85430,50.00000,0.0000e+000,20.00000,    -0.14388,0.59682
704.10602, 81.67583,    -1.55639,70.83252,50.00000,0.0000e+000,20.00000,    -0.13855,0.59604
705.86102, 81.85083,    -1.55939,70.80926,50.00000,0.0000e+000,20.00000,    -0.13360,0.59525
707.66803, 82.02583,    -1.56914,70.78483,50.00000,0.0000e+000,20.00000,    -0.12927,0.59444
709.48999, 82.20084,    -1.58312,70.76190,50.00000,0.0000e+000,20.00000,    -0.12534,0.59363
711.30103, 82.37583,    -1.58809,70.74183,50.00000,0.0000e+000,20.00000,    -0.12165,0.59283
713.07397, 82.55083,    -1.58544,70.72187,50.00000,0.0000e+000,20.00000,    -0.11850,0.59204
714.83197, 82.72583,    -1.58028,70.70094,50.00000,0.0000e+000,20.00000,    -0.11496,0.59127
716.57501, 82.90083,    -1.57815,70.68157,50.00000,0.0000e+000,20.00000,    -0.11107,0.59050
718.34100, 83.07584,    -1.57569,70.66254,50.00000,0.0000e+000,20.00000,    -0.10817,0.58973
720.09198, 83.25083,    -1.57694,70.64345,50.00000,0.0000e+000,20.00000,    -0.10597,0.58897
721.84302, 83.42583,    -1.57878,70.62652,50.00000,0.0000e+000,20.00000,    -0.10435,0.58821
723.60498, 83.60083,    -1.58166,70.60968,50.00000,0.0000e+000,20.00000,    -0.10245,0.58744
725.33899, 83.77583,    -1.58304,70.59269,50.00000,0.0000e+000,20.00000,-9.9187e-002,0.58669
727.09100, 83.95084,    -1.58357,70.57548,50.00000,0.0000e+000,20.00000,-9.5512e-002,0.58594
728.83099, 84.12583,    -1.58459,70.55868,50.00000,0.0000e+000,20.00000,-9.2967e-002,0.58520
730.58301, 84.30083,    -1.58638,70.54150,50.00000,0.0000e+000,20.00000,-9.0989e-002,0.58445
732.36700, 84.47583,    -1.59422,70.52534,50.00000,0.0000e+000,20.00000,-8.8741e-002,0.58369
734.13800, 84.65083,    -1.59895,70.51245,50.00000,0.0000e+000,20.00000,-8.5985e-002,0.58294
735.90100, 84.82584,    -1.60012,70.49860,50.00000,0.0000e+000,20.00000,-8.3023e-002,0.58219
737.64600, 85.00083,    -1.59846,70.48333,50.00000,0.0000e+000,20.00000,-8.0591e-002,0.58146
739.37598, 85.17583,    -1.59653,70.46792,50.00000,0.0000e+000,20.00000,-7.8943e-002,0.58073
741.11603, 85.35083,    -1.59581,70.45204,50.00000,0.0000e+000,20.00000,-7.7396e-002,0.58000
742.83801, 85.52583,    -1.59634,70.43796,50.00000,0.0000e+000,20.00000,-7.5735e-002,0.57929
744.53003, 85.70084,    -1.59004,70.42747,50.00000,0.0000e+000,20.00000,-7.3673e-002,0.57858
746.24500, 85.87583,    -1.58974,70.41601,50.00000,0.0000e+000,20.00000,-7.1139e-002,0.57787
747.97699, 86.05083,    -1.59498,70.40388,50.00000,0.0000e+000,20.00000,-6.8943e-002,0.57716
749.73401, 86.22583,    -1.60279,70.39129,50.00000,0.0000e+000,20.00000,-6.7015e-002,0.57643
751.53198, 86.40083,    -1.61284,70.37959,50.00000,0.0000e+000,20.00000,-6.5947e-002,0.57570
753.30103, 86.57584,    -1.62013,70.37139,50.00000,0.0000e+000,20.00000,-6.4474e-002,0.57497
755.09698, 86.75083,    -1.62645,70.36208,50.00000,0.0000e+000,20.00000,-6.2845e-002,0.57424
756.92603, 86.92583,    -1.63692,70.35055,50.00000,0.0000e+000,20.00000,-6.1458e-002,0.57350
758.71100, 87.10083,    -1.64085,70.33905,50.00000,0.0000e+000,20.00000,-5.9188e-002,0.57277
760.48602, 87.27583,    -1.64010,70.32828,50.00000,0.0000e+000,20.00000,-5.7097e-002,0.57205
762.23700, 87.45084,    -1.63680,70.31775,50.00000,0.0000e+000,20.00000,-5.6466e-002,0.57135
763.99701, 87.62583,    -1.63153,70.30946,50.00000,0.0000e+000,20.00000,-5.6238e-002,0.57064
765.73602, 87.80083,    -1.62789,70.30134,50.00000,0.0000e+000,20.00000,-5.5395e-002,0.56995
767.46002, 87.97583,    -1.62618,70.29174,50.00000,0.0000e+000,20.00000,-5.4366e-002,0.56926
769.20502, 88.15083,    -1.62571,70.28127,50.00000,0.0000e+000,20.00000,-5.3535e-002,0.56856
770.94800, 88.32584,    -1.62785,70.27245,50.00000,0.0000e+000,20.00000,-5.3531e-002,0.56787
772.70203, 88.50083,    -1.62985,70.26488,50.00000,0.0000e+000,20.00000,-5.4066e-002,0.56718
774.44299, 88.67583,    -1.63269,70.25447,50.00000,0.0000e+000,20.00000,-5.4149e-002,0.56649
776.19202, 88.85083,    -1.63504,70.24574,50.00000,0.0000e+000,20.00000,-5.3795e-002,0.56580
777.93103, 89.02583,    -1.63772,70.23874,50.00000,0.0000e+000,20.00000,-5.3556e-002,0.56512
779.68298, 89.20084,    -1.63876,70.22983,50.00000,0.0000e+000,20.00000,-5.3364e-002,0.56443
781.44202, 89.37583,    -1.63997,70.22009,50.00000,0.0000e+000,20.00000,-5.3252e-002,0.56375
783.19000, 89.55083,    -1.64307,70.21064,50.00000,0.0000e+000,20.00000,-5.3714e-002,0.56307
784.94397, 89.72583,    -1.64460,70.20203,50.00000,0.0000e+000,20.00000,-5.3821e-002,0.56239
786.70099, 89.90083,    -1.64535,70.19310,50.00000,0.0000e+000,20.00000,-5.3595e-002,0.56171
788.44397, 90.07584,    -1.64625,70.18331,50.00000,0.0000e+000,20.00000,-5.3563e-002,0.56103
790.20801, 90.25083,    -1.64949,70.17363,50.00000,0.0000e+000,20.00000,-5.4048e-002,0.56035
791.97900, 90.42583,    -1.65270,70.16281,50.00000,0.0000e+000,20.00000,-5.4193e-002,0.55967
793.73297, 90.60083,    -1.65331,70.15194,50.00000,0.0000e+000,20.00000,-5.3871e-002,0.55900
795.49500, 90.77583,    -1.65351,70.14176,50.00000,0.0000e+000,20.00000,-5.3819e-002,0.55833
797.24799, 90.95084,    -1.65512,70.13165,50.00000,0.0000e+000,20.00000,-5.3919e-002,0.55766
798.99103, 91.12583,    -1.65504,70.12199,50.00000,0.0000e+000,20.00000,-5.4084e-002,0.55700
800.75500, 91.30083,    -1.65820,70.11326,50.00000,0.0000e+000,20.00000,-5.3647e-002,0.55633
802.50000, 91.47583,    -1.65704,70.10335,50.00000,0.0000e+000,20.00000,-5.3432e-002,0.55567
804.21503, 91.65083,    -1.64908,70.09438,50.00000,0.0000e+000,20.00000,-5.3457e-002,0.55502
805.98102, 91.82584,    -1.65211,70.08443,50.00000,0.0000e+000,20.00000,-5.3368e-002,0.55435
807.77197, 92.00083,    -1.66226,70.07508,50.00000,0.0000e+000,20.00000,-5.3350e-002,0.55368
809.56097, 92.17583,    -1.66769,70.06557,50.00000,0.0000e+000,20.00000,-5.3097e-002,0.55301
811.31799, 92.35083,    -1.66723,70.05591,50.00000,0.0000e+000,20.00000,-5.2857e-002,0.55235
813.08197, 92.52583,    -1.66483,70.04823,50.00000,0.0000e+000,20.00000,-5.2987e-002,0.55170
814.86499, 92.70084,    -1.67072,70.04106,50.00000,0.0000e+000,20.00000,-5.3357e-002,0.55103
816.60101, 92.87583,    -1.66507,70.03115,50.00000,0.0000e+000,20.00000,-5.3452e-002,0.55039
818.32098, 93.05083,    -1.65842,70.02196,50.00000,0.0000e+000,20.00000,-5.3540e-002,0.54975
820.06097, 93.22583,    -1.65655,70.01429,50.00000,0.0000e+000,20.00000,-5.3762e-002,0.54910
821.78601, 93.40083,    -1.65360,70.00561,50.00000,0.0000e+000,20.00000,-5.4786e-002,0.54847
823.51703, 93.57584,    -1.65246,69.99688,50.00000,0.0000e+000,20.00000,-5.5722e-002,0.54783
825.23901, 93.75083,    -1.65170,69.98706,50.00000,0.0000e+000,20.00000,-5.5810e-002,0.54720
826.99103, 93.92583,    -1.65309,69.97798,50.00000,0.0000e+000,20.00000,-5.5943e-002,0.54655
828.78400, 94.10083,    -1.66049,69.96799,50.00000,0.0000e+000,20.00000,-5.5381e-002,0.54590
830.58600, 94.27583,    -1.67286,69.95752,50.00000,0.0000e+000,20.00000,-5.5759e-002,0.54524
832.38202, 94.45084,    -1.67552,69.94619,50.00000,0.0000e+000,20.00000,-5.7683e-002,0.54458
834.17297, 94.62583,    -1.67611,69.93507,50.00000,0.0000e+000,20.00000,-5.9345e-002,0.54393
835.96997, 94.80083,    -1.67907,69.92563,50.00000,0.0000e+000,20.00000,-6.0360e-002,0.54328
837.73297, 94.97583,    -1.67415,69.91606,50.00000,0.0000e+000,20.00000,-6.2016e-002,0.54264
839.49597, 95.15083,    -1.66767,69.90425,50.00000,0.0000e+000,20.00000,-6.3606e-002,0.54200
841.23700, 95.32584,    -1.66119,69.89054,50.00000,0.0000e+000,20.00000,-6.5132e-002,0.54137
842.98901, 95.50083,    -1.65504,69.87945,50.00000,0.0000e+000,20.00000,-6.6451e-002,0.54074
844.69598, 95.67583,    -1.65034,69.86962,50.00000,0.0000e+000,20.00000,-6.7557e-002,0.54012
846.40698, 95.85083,    -1.64554,69.86089,50.00000,0.0000e+000,20.00000,-6.8414e-002,0.53951
848.13202, 96.02583,    -1.63966,69.85266,50.00000,0.0000e+000,20.00000,-6.8840e-002,0.53889
849.86499, 96.20084,    -1.63844,69.84010,50.00000,0.0000e+000,20.00000,-6.9826e-002,0.53827
851.59399, 96.37583,    -1.63925,69.82534,50.00000,0.0000e+000,20.00000,-7.0958e-002,0.53765
853.33698, 96.55083,    -1.64020,69.81108,50.00000,0.0000e+000,20.00000,-7.2255e-002,0.53702
855.09100, 96.72583,    -1.64042,69.79736,50.00000,0.0000e+000,20.00000,-7.3078e-002,0.53640
856.82202, 96.90083,    -1.63966,69.78324,50.00000,0.0000e+000,20.00000,-7.3691e-002,0.53578
858.58099, 97.07584,    -1.64097,69.76912,50.00000,0.0000e+000,20.00000,-7.4292e-002,0.53515
860.33698, 97.25083,    -1.63919,69.75479,50.00000,0.0000e+000,20.00000,-7.4761e-002,0.53453
862.09198, 97.42583,    -1.63914,69.74095,50.00000,0.0000e+000,20.00000,-7.6252e-002,0.53391
863.86700, 97.60083,    -1.64112,69.72785,50.00000,0.0000e+000,20.00000,-7.8314e-002,0.53328
865.65900, 97.77583,    -1.64783,69.71606,50.00000,0.0000e+000,20.00000,-8.0695e-002,0.53264
867.43597, 97.95084,    -1.64689,69.70283,50.00000,0.0000e+000,20.00000,-8.1985e-002,0.53201
869.18402, 98.12583,    -1.64194,69.68735,50.00000,0.0000e+000,20.00000,-8.2906e-002,0.53140
870.95001, 98.30083,    -1.63891,69.67201,50.00000,0.0000e+000,20.00000,-8.3657e-002,0.53077
872.69098, 98.47583,    -1.63633,69.65841,50.00000,0.0000e+000,20.00000,-8.4095e-002,0.53016
874.44098, 98.65083,    -1.63213,69.64667,50.00000,0.0000e+000,20.00000,-8.4691e-002,0.52955
876.18597, 98.82584,    -1.62997,69.63190,50.00000,0.0000e+000,20.00000,-8.5601e-002,0.52893
877.92798, 99.00083,    -1.62777,69.61692,50.00000,0.0000e+000,20.00000,-8.6655e-002,0.52832
879.68500, 99.17583,    -1.62583,69.60245,50.00000,0.0000e+000,20.00000,-8.8067e-002,0.52770
881.42401, 99.35083,    -1.62198,69.58584,50.00000,0.0000e+000,20.00000,-8.9790e-002,0.52709
883.16101, 99.52583,    -1.62098,69.56875,50.00000,0.0000e+000,20.00000,-9.1706e-002,0.52649
884.93903, 99.70084,    -1.62480,69.55340,50.00000,0.0000e+000,20.00000,-9.3768e-002,0.52586
886.70001, 99.87583,    -1.62431,69.53695,50.00000,0.0000e+000,20.00000,-9.5362e-002,0.52525
888.48999,100.05083,    -1.62912,69.51891,50.00000,0.0000e+000,20.00000,-9.6544e-002,0.52463
890.25897,100.22583,    -1.62869,69.50282,50.00000,0.0000e+000,20.00000,-9.8297e-002,0.52401
892.02197,100.40083,    -1.62527,69.48735,50.00000,0.0000e+000,20.00000,    -0.10115,0.52339
893.77301,100.57584,    -1.62049,69.47033,50.00000,0.0000e+000,20.00000,    -0.10371,0.52278
895.52600,100.75083,    -1.61891,69.45258,50.00000,0.0000e+000,20.00000,    -0.10554,0.52217
897.31598,100.92583,    -1.62351,69.43374,50.00000,0.0000e+000,20.00000,    -0.10797,0.52155
899.09998,101.10083,    -1.62620,69.41410,50.00000,0.0000e+000,20.00000,    -0.11048,0.52093
900.89001,101.27583,    -1.62403,69.39450,50.00000,0.0000e+000,20.00000,    -0.11269,0.52031
902.62402,101.45084,    -1.61848,69.37522,50.00000,0.0000e+000,20.00000,    -0.11446,0.51971
904.36499,101.62583,    -1.61216,69.35484,50.00000,0.0000e+000,20.00000,    -0.11631,0.51911
906.09198,101.80083,    -1.60635,69.33468,50.00000,0.0000e+000,20.00000,    -0.11830,0.51851
907.86499,101.97583,    -1.60457,69.31430,50.00000,0.0000e+000,20.00000,    -0.12043,0.51789
909.62402,102.15083,    -1.60839,69.29235,50.00000,0.0000e+000,20.00000,    -0.12223,0.51729
911.37500,102.32584,    -1.60740,69.26974,50.00000,0.0000e+000,20.00000,    -0.12365,0.51668
913.11499,102.50083,    -1.60287,69.24731,50.00000,0.0000e+000,20.00000,    -0.12550,0.51608
914.86798,102.67583,    -1.59965,69.22494,50.00000,0.0000e+000,20.00000,    -0.12760,0.51547
916.61102,102.85083,    -1.59737,69.20080,50.00000,0.0000e+000,20.00000,    -0.12945,0.51487
918.35602,103.02583,    -1.59458,69.17535,50.00000,0.0000e+000,20.00000,    -0.13118,0.51427
920.11401,103.20084,    -1.59239,69.15137,50.00000,0.0000e+000,20.00000,    -0.13333,0.51366
921.85901,103.37583,    -1.59290,69.12959,50.00000,0.0000e+000,20.00000,    -0.13502,0.51306
923.57501,103.55083,    -1.58625,69.10585,50.00000,0.0000e+000,20.00000,    -0.13570,0.51247
925.31097,103.72583,    -1.58392,69.08018,50.00000,0.0000e+000,20.00000,    -0.13626,0.51187
927.05402,103.90083,    -1.58451,69.05700,50.00000,0.0000e+000,20.00000,    -0.13715,0.51127
928.81500,104.07584,    -1.58548,69.03583,50.00000,0.0000e+000,20.00000,    -0.13825,0.51066
930.59198,104.25083,    -1.58930,69.01288,50.00000,0.0000e+000,20.00000,    -0.13980,0.51005
932.36603,104.42583,    -1.58984,68.98748,50.00000,0.0000e+000,20.00000,    -0.14137,0.50944
934.12500,104.60083,    -1.58780,68.96119,50.00000,0.0000e+000,20.00000,    -0.14146,0.50883
935.86401,104.77583,    -1.58354,68.93535,50.00000,0.0000e+000,20.00000,    -0.14091,0.50824
937.64203,104.95084,    -1.58421,68.90850,50.00000,0.0000e+000,20.00000,    -0.14116,0.50762
939.43701,105.12583,    -1.58981,68.88170,50.00000,0.0000e+000,20.00000,    -0.14212,0.50701
941.21198,105.30083,    -1.59154,68.85732,50.00000,0.0000e+000,20.00000,    -0.14197,0.50639
942.99103,105.47583,    -1.59223,68.83544,50.00000,0.0000e+000,20.00000,    -0.14037,0.50578
944.75299,105.65083,    -1.58912,68.81212,50.00000,0.0000e+000,20.00000,    -0.13894,0.50518
946.48700,105.82584,    -1.58072,68.78640,50.00000,0.0000e+000,20.00000,    -0.13728,0.50458
948.20599,106.00083,    -1.57270,68.75889,50.00000,0.0000e+000,20.00000,    -0.13544,0.50399
949.96899,106.17583,    -1.57363,68.73027,50.00000,0.0000e+000,20.00000,    -0.13303,0.50338
951.67999,106.35083,    -1.56603,68.70457,50.00000,0.0000e+000,20.00000,    -0.12968,0.50279
953.41199,106.52583,    -1.56391,68.68224,50.00000,0.0000e+000,20.00000,    -0.12494,0.50219
955.15900,106.70084,    -1.56917,68.65739,50.00000,0.0000e+000,20.00000,    -0.11997,0.50159
956.91302,106.87583,    -1.57385,68.63097,50.00000,0.0000e+000,20.00000,    -0.11496,0.50099
958.69299,107.05083,    -1.58321,68.60693,50.00000,0.0000e+000,20.00000,    -0.11059,0.50038
960.46301,107.22583,    -1.58929,68.58718,50.00000,0.0000e+000,20.00000,    -0.10697,0.49977
962.23798,107.40083,    -1.59473,68.56723,50.00000,0.0000e+000,20.00000,    -0.10312,0.49915
964.01099,107.57584,    -1.59827,68.54999,50.00000,0.0000e+000,20.00000,-9.7956e-002,0.49854
965.77002,107.75083,    -1.59775,68.53518,50.00000,0.0000e+000,20.00000,-9.1522e-002,0.49794
967.53302,107.92583,    -1.59699,68.51960,50.00000,0.0000e+000,20.00000,-8.5093e-002,0.49733
969.30402,108.10083,    -1.59694,68.50452,50.00000,0.0000e+000,20.00000,-7.8674e-002,0.49672
971.08398,108.27583,    -1.60628,68.49339,50.00000,0.0000e+000,20.00000,-7.3268e-002,0.49610
972.87598,108.45084,    -1.61204,68.48588,50.00000,0.0000e+000,20.00000,-6.7701e-002,0.49548
974.65302,108.62583,    -1.61334,68.47714,50.00000,0.0000e+000,20.00000,-6.1928e-002,0.49487
976.40698,108.80083,    -1.61009,68.46795,50.00000,0.0000e+000,20.00000,-5.6424e-002,0.49426
978.15802,108.97583,    -1.60472,68.45810,50.00000,0.0000e+000,20.00000,-5.1370e-002,0.49366
979.91101,109.15083,    -1.60108,68.44934,50.00000,0.0000e+000,20.00000,-4.7305e-002,0.49305
981.63898,109.32584,    -1.59919,68.44212,50.00000,0.0000e+000,20.00000,-4.2239e-002,0.49245
983.37299,109.50083,    -1.59732,68.43825,50.00000,0.0000e+000,20.00000,-3.6964e-002,0.49185
985.11499,109.67583,    -1.59407,68.43419,50.00000,0.0000e+000,20.00000,-3.3072e-002,0.49125
986.83899,109.85083,    -1.59189,68.42936,50.00000,0.0000e+000,20.00000,-3.0843e-002,0.49065
988.58197,110.02583,    -1.58825,68.42586,50.00000,0.0000e+000,20.00000,-2.6582e-002,0.49004
990.30200,110.20084,    -1.58838,68.42272,50.00000,0.0000e+000,20.00000,-2.3404e-002,0.48945
992.04199,110.37583,    -1.58702,68.41893,50.00000,0.0000e+000,20.00000,-2.3563e-002,0.48884
993.78400,110.55083,    -1.58660,68.41284,50.00000,0.0000e+000,20.00000,-2.4205e-002,0.48824
995.51398,110.72583,    -1.58737,68.40909,50.00000,0.0000e+000,20.00000,-2.5358e-002,0.48764
997.25897,110.90083,    -1.58892,68.40592,50.00000,0.0000e+000,20.00000,-2.6172e-002,0.48703
998.31000,111.00584,    -1.58959,68.40244,50.00000,0.0000e+000,20.00000,-1.0643e-002,0.48666