File: book/some_content/TG_ExpDat_CEM_III_DC28; 14-2-2025-2.csv
#FILE:                       ,CEM_III_DC28; 14-2-2025.ngb-ds3
#FORMAT:                     ,NETZSCH5
#IDENTITY:                   ,OPC PASTE
#DECIMAL:                    ,POINT
#SEPARATOR:                  ,COMMA
#MTYPE:                      ,DSC
#INSTRUMENT:                 ,Microlab TU Delft
#PROJECT:                    ,
#DATE/TIME:                  ,14/02/2025 5:34:26 PM
#CORR. FILE:                 ,Blank with cover; 13-1-2025.ngb-bs3
#LABORATORY:                 ,TU Delft Micro Lab
#OPERATOR:                   ,Ahmed
#REMARK:                     ,under Argon atmosphere, 10K/min
#SAMPLE:                     ,CEM_III_DC28
#SAMPLE MASS /mg:            ,35.2
#MATERIAL:                   ,CEMENT PASTE
#REFERENCE:                  ,blank
#REFERENCE MASS /mg:         ,0
#TYPE OF CRUCIBLE:           ,DSC/TG pan Al2O3
#SAMPLE CRUCIBLE MASS /mg:   ,0
#REFERENCE CRUCIBLE MASS /mg:,0
#CORR. CODE:                 ,020
#EXO:                        ,-1
#RANGE:                      ,40/10.0(K/min)/1000
#SEGMENT:                    ,S2/2

##Temp./øC,Time/min,DSC/(mW/mg),Mass/%,Gas Flow(purge1)/(ml/min),Gas Flow(purge2)/(ml/min),Gas Flow(protective)/(ml/min),DTG/(%/min),Sensit./(uV/mW)
 40.23300, 15.04000, 2.5445e-002,99.02236,50.00000,0.0000e+000,20.00000,-7.3749e-002,1.22662
 40.28400, 15.22000, 2.5058e-002,99.01259,50.00000,0.0000e+000,20.00000,-5.6690e-002,1.22655
 40.35500, 15.40000, 2.4777e-002,99.00318,50.00000,0.0000e+000,20.00000,-5.7639e-002,1.22645
 40.43500, 15.58000, 2.4408e-002,98.99189,50.00000,0.0000e+000,20.00000,-5.3691e-002,1.22634
 40.55200, 15.76000, 2.4199e-002,98.98166,50.00000,0.0000e+000,20.00000,-5.0876e-002,1.22618
 40.76200, 15.94000, 2.4399e-002,98.97277,50.00000,0.0000e+000,20.00000,-5.0769e-002,1.22589
 40.98500, 16.12000, 2.4900e-002,98.96498,50.00000,0.0000e+000,20.00000,-5.0495e-002,1.22558
 41.32900, 16.30000, 2.5476e-002,98.95798,50.00000,0.0000e+000,20.00000,-5.0427e-002,1.22511
 41.72000, 16.48000, 2.6691e-002,98.95019,50.00000,0.0000e+000,20.00000,-5.0961e-002,1.22457
 42.20900, 16.66000, 2.8034e-002,98.94122,50.00000,0.0000e+000,20.00000,-5.1003e-002,1.22390
 42.78200, 16.84000, 2.9895e-002,98.93207,50.00000,0.0000e+000,20.00000,-5.3210e-002,1.22311
 43.40800, 17.02000, 3.2292e-002,98.92355,50.00000,0.0000e+000,20.00000,-5.4614e-002,1.22224
 44.12400, 17.20000, 3.4324e-002,98.91448,50.00000,0.0000e+000,20.00000,-5.6599e-002,1.22126
 44.94100, 17.38000, 3.6789e-002,98.90611,50.00000,0.0000e+000,20.00000,-5.8630e-002,1.22013
 45.84800, 17.56000, 3.9103e-002,98.89683,50.00000,0.0000e+000,20.00000,-6.1433e-002,1.21888
 46.81700, 17.74000, 4.2155e-002,98.88655,50.00000,0.0000e+000,20.00000,-6.5347e-002,1.21755
 47.87600, 17.92000, 4.4718e-002,98.87681,50.00000,0.0000e+000,20.00000,-6.9259e-002,1.21609
 49.03600, 18.10000, 4.7454e-002,98.86846,50.00000,0.0000e+000,20.00000,-7.2988e-002,1.21449
 50.24400, 18.28000, 5.0504e-002,98.85883,50.00000,0.0000e+000,20.00000,-7.7854e-002,1.21282
 51.55300, 18.46000, 5.3245e-002,98.84685,50.00000,0.0000e+000,20.00000,-8.4113e-002,1.21102
 52.93300, 18.64000, 5.6036e-002,98.83255,50.00000,0.0000e+000,20.00000,-9.0898e-002,1.20912
 54.37500, 18.82000, 5.9037e-002,98.81672,50.00000,0.0000e+000,20.00000,-9.8636e-002,1.20714
 55.94400, 19.00000, 6.1823e-002,98.80057,50.00000,0.0000e+000,20.00000,    -0.10700,1.20498
 57.53700, 19.18000, 6.5143e-002,98.78226,50.00000,0.0000e+000,20.00000,    -0.11754,1.20279
 59.23000, 19.36000, 6.7959e-002,98.76195,50.00000,0.0000e+000,20.00000,    -0.13051,1.20046
 60.95300, 19.54000, 7.1024e-002,98.73885,50.00000,0.0000e+000,20.00000,    -0.14398,1.19809
 62.77800, 19.72000, 7.4146e-002,98.71615,50.00000,0.0000e+000,20.00000,    -0.15857,1.19558
 64.68600, 19.90000, 7.7907e-002,98.69558,50.00000,0.0000e+000,20.00000,    -0.17593,1.19296
 66.60400, 20.08000, 8.1338e-002,98.67129,50.00000,0.0000e+000,20.00000,    -0.19554,1.19033
 68.61400, 20.26000, 8.5451e-002,98.64030,50.00000,0.0000e+000,20.00000,    -0.21588,1.18757
 70.66600, 20.44000, 8.9807e-002,98.60650,50.00000,0.0000e+000,20.00000,    -0.23659,1.18476
 72.79600, 20.62000, 9.4430e-002,98.57019,50.00000,0.0000e+000,20.00000,    -0.25871,1.18184
 74.92500, 20.80000, 9.9480e-002,98.53111,50.00000,0.0000e+000,20.00000,    -0.28208,1.17893
 77.09800, 20.98000,     0.10508,98.48567,50.00000,0.0000e+000,20.00000,    -0.30599,1.17596
 79.34500, 21.16000,     0.11128,98.43035,50.00000,0.0000e+000,20.00000,    -0.33024,1.17288
 81.62900, 21.34000,     0.11768,98.37103,50.00000,0.0000e+000,20.00000,    -0.35424,1.16976
 83.91000, 21.52000,     0.12494,98.30881,50.00000,0.0000e+000,20.00000,    -0.37910,1.16665
 86.26600, 21.70000,     0.13257,98.23827,50.00000,0.0000e+000,20.00000,    -0.40540,1.16344
 88.64100, 21.88000,     0.14065,98.15864,50.00000,0.0000e+000,20.00000,    -0.43112,1.16020
 91.04000, 22.06000,     0.14869,98.07303,50.00000,0.0000e+000,20.00000,    -0.45529,1.15694
 93.46900, 22.24000,     0.15680,97.98432,50.00000,0.0000e+000,20.00000,    -0.47911,1.15363
 95.90000, 22.42000,     0.16568,97.88867,50.00000,0.0000e+000,20.00000,    -0.50209,1.15033
 98.37900, 22.60000,     0.17427,97.78788,50.00000,0.0000e+000,20.00000,    -0.52439,1.14697
100.84000, 22.78000,     0.18236,97.68313,50.00000,0.0000e+000,20.00000,    -0.54537,1.14364
103.30700, 22.96000,     0.19032,97.57492,50.00000,0.0000e+000,20.00000,    -0.56242,1.14030
105.76800, 23.14000,     0.19793,97.46476,50.00000,0.0000e+000,20.00000,    -0.57774,1.13697
108.26400, 23.32000,     0.20489,97.35149,50.00000,0.0000e+000,20.00000,    -0.59271,1.13360
110.73500, 23.50000,     0.21081,97.23490,50.00000,0.0000e+000,20.00000,    -0.60453,1.13027
113.19900, 23.68000,     0.21537,97.11772,50.00000,0.0000e+000,20.00000,    -0.61371,1.12695
115.68100, 23.86000,     0.21904,96.99948,50.00000,0.0000e+000,20.00000,    -0.62200,1.12362
118.14100, 24.04000,     0.22067,96.87905,50.00000,0.0000e+000,20.00000,    -0.62997,1.12031
120.58900, 24.22000,     0.22163,96.75903,50.00000,0.0000e+000,20.00000,    -0.63516,1.11703
123.06300, 24.40000,     0.22102,96.63916,50.00000,0.0000e+000,20.00000,    -0.63806,1.11372
125.50300, 24.58000,     0.21913,96.51817,50.00000,0.0000e+000,20.00000,    -0.63905,1.11046
127.95100, 24.76000,     0.21614,96.40110,50.00000,0.0000e+000,20.00000,    -0.63824,1.10719
130.38200, 24.94000,     0.21196,96.28628,50.00000,0.0000e+000,20.00000,    -0.63583,1.10396
132.78700, 25.12000,     0.20710,96.16992,50.00000,0.0000e+000,20.00000,    -0.63156,1.10076
135.21201, 25.30000,     0.20157,96.05708,50.00000,0.0000e+000,20.00000,    -0.62597,1.09754
137.61301, 25.48000,     0.19677,95.94547,50.00000,0.0000e+000,20.00000,    -0.61935,1.09436
140.00600, 25.66000,     0.19196,95.83075,50.00000,0.0000e+000,20.00000,    -0.61082,1.09119
142.37100, 25.84000,     0.18723,95.71338,50.00000,0.0000e+000,20.00000,    -0.60020,1.08807
144.71201, 26.02000,     0.18245,95.59934,50.00000,0.0000e+000,20.00000,    -0.58885,1.08498
147.05499, 26.20000,     0.17682,95.48815,50.00000,0.0000e+000,20.00000,    -0.57668,1.08189
149.35699, 26.38000,     0.16954,95.37990,50.00000,0.0000e+000,20.00000,    -0.56309,1.07887
151.65800, 26.56000,     0.16067,95.27469,50.00000,0.0000e+000,20.00000,    -0.54987,1.07585
153.93800, 26.74000,     0.15041,95.17285,50.00000,0.0000e+000,20.00000,    -0.53790,1.07287
156.17999, 26.92000,     0.13899,95.07543,50.00000,0.0000e+000,20.00000,    -0.52466,1.06994
158.38499, 27.10000,     0.12679,94.97945,50.00000,0.0000e+000,20.00000,    -0.51127,1.06706
160.60500, 27.28000,     0.11402,94.88572,50.00000,0.0000e+000,20.00000,    -0.49797,1.06417
162.77699, 27.46000,     0.10131,94.79799,50.00000,0.0000e+000,20.00000,    -0.48347,1.06135
164.93800, 27.64000, 8.8885e-002,94.71599,50.00000,0.0000e+000,20.00000,    -0.46768,1.05855
167.09599, 27.82000, 7.6022e-002,94.63690,50.00000,0.0000e+000,20.00000,    -0.45203,1.05575
169.20900, 28.00000, 6.3766e-002,94.56106,50.00000,0.0000e+000,20.00000,    -0.43657,1.05302
171.29401, 28.18000, 5.0950e-002,94.48914,50.00000,0.0000e+000,20.00000,    -0.42184,1.05033
173.39799, 28.36000, 3.9040e-002,94.41958,50.00000,0.0000e+000,20.00000,    -0.40757,1.04762
175.43900, 28.54000, 2.7233e-002,94.34876,50.00000,0.0000e+000,20.00000,    -0.39353,1.04500
177.49001, 28.72000, 1.6219e-002,94.27999,50.00000,0.0000e+000,20.00000,    -0.38023,1.04237
179.51401, 28.90000, 5.1488e-003,94.21515,50.00000,0.0000e+000,20.00000,    -0.36786,1.03978
181.52000, 29.08000,-4.9525e-003,94.15206,50.00000,0.0000e+000,20.00000,    -0.35626,1.03722
183.51100, 29.26000,-1.4810e-002,94.09071,50.00000,0.0000e+000,20.00000,    -0.34503,1.03468
185.48900, 29.44000,-2.4611e-002,94.03085,50.00000,0.0000e+000,20.00000,    -0.33498,1.03216
187.45300, 29.62000,-3.4038e-002,93.97293,50.00000,0.0000e+000,20.00000,    -0.32529,1.02967
189.40100, 29.80000,-4.2750e-002,93.91769,50.00000,0.0000e+000,20.00000,    -0.31570,1.02720
191.32401, 29.98000,-5.1565e-002,93.86276,50.00000,0.0000e+000,20.00000,    -0.30717,1.02477
193.24400, 30.16000,-6.0380e-002,93.80894,50.00000,0.0000e+000,20.00000,    -0.29959,1.02234
195.13200, 30.34000,-6.8256e-002,93.75741,50.00000,0.0000e+000,20.00000,    -0.29153,1.01997
197.01300, 30.52000,-7.6061e-002,93.70789,50.00000,0.0000e+000,20.00000,    -0.28366,1.01760
198.87100, 30.70000,-8.3985e-002,93.65759,50.00000,0.0000e+000,20.00000,    -0.27668,1.01527
200.73900, 30.88000,-9.1946e-002,93.60523,50.00000,0.0000e+000,20.00000,    -0.26974,1.01293
202.59300, 31.06000,-9.9235e-002,93.55701,50.00000,0.0000e+000,20.00000,    -0.26291,1.01061
204.42999, 31.24000,    -0.10649,93.51088,50.00000,0.0000e+000,20.00000,    -0.25611,1.00832
206.23801, 31.42000,    -0.11379,93.46641,50.00000,0.0000e+000,20.00000,    -0.24962,1.00607
208.07600, 31.60000,    -0.12103,93.42473,50.00000,0.0000e+000,20.00000,    -0.24363,1.00378
209.88300, 31.78000,    -0.12818,93.38363,50.00000,0.0000e+000,20.00000,    -0.23776,1.00154
211.67700, 31.96000,    -0.13597,93.34155,50.00000,0.0000e+000,20.00000,    -0.23237,0.99932
213.47301, 32.14000,    -0.14373,93.30040,50.00000,0.0000e+000,20.00000,    -0.22692,0.99711
215.25101, 32.32000,    -0.15178,93.25951,50.00000,0.0000e+000,20.00000,    -0.22194,0.99491
217.02299, 32.50000,    -0.15991,93.21966,50.00000,0.0000e+000,20.00000,    -0.21611,0.99274
218.80800, 32.68000,    -0.16873,93.18137,50.00000,0.0000e+000,20.00000,    -0.20923,0.99054
220.55800, 32.86000,    -0.17725,93.14452,50.00000,0.0000e+000,20.00000,    -0.20377,0.98840
222.28400, 33.04000,    -0.18552,93.10917,50.00000,0.0000e+000,20.00000,    -0.19868,0.98629
224.07800, 33.22000,    -0.19388,93.07445,50.00000,0.0000e+000,20.00000,    -0.19445,0.98410
225.81500, 33.40000,    -0.20255,93.04069,50.00000,0.0000e+000,20.00000,    -0.19050,0.98199
227.56400, 33.58000,    -0.21096,93.00733,50.00000,0.0000e+000,20.00000,    -0.18675,0.97987
229.30600, 33.76000,    -0.21930,92.97286,50.00000,0.0000e+000,20.00000,    -0.18263,0.97775
231.05400, 33.94000,    -0.22787,92.94054,50.00000,0.0000e+000,20.00000,    -0.17859,0.97564
232.79500, 34.12000,    -0.23550,92.90891,50.00000,0.0000e+000,20.00000,    -0.17493,0.97354
234.53300, 34.30000,    -0.24391,92.87976,50.00000,0.0000e+000,20.00000,    -0.17096,0.97145
236.25500, 34.48000,    -0.25152,92.85263,50.00000,0.0000e+000,20.00000,    -0.16695,0.96938
237.99899, 34.66000,    -0.25907,92.82370,50.00000,0.0000e+000,20.00000,    -0.16325,0.96729
239.73900, 34.84000,    -0.26677,92.79603,50.00000,0.0000e+000,20.00000,    -0.16045,0.96521
241.46300, 35.02000,    -0.27353,92.76676,50.00000,0.0000e+000,20.00000,    -0.15758,0.96315
243.19299, 35.20000,    -0.28075,92.73881,50.00000,0.0000e+000,20.00000,    -0.15454,0.96109
244.92000, 35.38000,    -0.28734,92.71164,50.00000,0.0000e+000,20.00000,    -0.15162,0.95904
246.62500, 35.56000,    -0.29440,92.68447,50.00000,0.0000e+000,20.00000,    -0.14858,0.95702
248.35001, 35.74000,    -0.30152,92.65805,50.00000,0.0000e+000,20.00000,    -0.14620,0.95498
250.08800, 35.92000,    -0.30847,92.63048,50.00000,0.0000e+000,20.00000,    -0.14385,0.95292
251.80499, 36.10000,    -0.31553,92.60454,50.00000,0.0000e+000,20.00000,    -0.14213,0.95090
253.53400, 36.28000,    -0.32246,92.58048,50.00000,0.0000e+000,20.00000,    -0.14085,0.94887
255.25900, 36.46000,    -0.32991,92.55707,50.00000,0.0000e+000,20.00000,    -0.13897,0.94685
256.98300, 36.64000,    -0.33637,92.53195,50.00000,0.0000e+000,20.00000,    -0.13728,0.94484
258.72101, 36.82000,    -0.34350,92.50733,50.00000,0.0000e+000,20.00000,    -0.13520,0.94281
260.45099, 37.00000,    -0.35039,92.48440,50.00000,0.0000e+000,20.00000,    -0.13332,0.94080
262.19199, 37.18000,    -0.35680,92.46175,50.00000,0.0000e+000,20.00000,    -0.13178,0.93878
263.91800, 37.36000,    -0.36298,92.43871,50.00000,0.0000e+000,20.00000,    -0.13024,0.93678
265.65100, 37.54000,    -0.36974,92.41458,50.00000,0.0000e+000,20.00000,    -0.12885,0.93478
267.38400, 37.72000,    -0.37622,92.39149,50.00000,0.0000e+000,20.00000,    -0.12704,0.93278
269.11499, 37.90000,    -0.38271,92.36801,50.00000,0.0000e+000,20.00000,    -0.12543,0.93079
270.87201, 38.08000,    -0.38951,92.34544,50.00000,0.0000e+000,20.00000,    -0.12433,0.92878
272.62100, 38.26000,    -0.39613,92.32350,50.00000,0.0000e+000,20.00000,    -0.12350,0.92678
274.36600, 38.44000,    -0.40272,92.30179,50.00000,0.0000e+000,20.00000,    -0.12241,0.92479
276.12299, 38.62000,    -0.40921,92.28039,50.00000,0.0000e+000,20.00000,    -0.12141,0.92279
277.88300, 38.80000,    -0.41494,92.25896,50.00000,0.0000e+000,20.00000,    -0.12132,0.92079
279.61801, 38.98000,    -0.42022,92.23747,50.00000,0.0000e+000,20.00000,    -0.12124,0.91883
281.36301, 39.16000,    -0.42514,92.21581,50.00000,0.0000e+000,20.00000,    -0.12094,0.91686
283.10400, 39.34000,    -0.43112,92.19443,50.00000,0.0000e+000,20.00000,    -0.12078,0.91490
284.86499, 39.52000,    -0.43699,92.17351,50.00000,0.0000e+000,20.00000,    -0.12106,0.91292
286.60400, 39.70000,    -0.44333,92.15301,50.00000,0.0000e+000,20.00000,    -0.12082,0.91097
288.36801, 39.88000,    -0.44925,92.13275,50.00000,0.0000e+000,20.00000,    -0.12053,0.90901
290.12000, 40.06000,    -0.45518,92.11246,50.00000,0.0000e+000,20.00000,    -0.12022,0.90705
291.87900, 40.24000,    -0.46072,92.09167,50.00000,0.0000e+000,20.00000,    -0.12000,0.90510
293.63199, 40.42000,    -0.46655,92.07051,50.00000,0.0000e+000,20.00000,    -0.12007,0.90316
295.40201, 40.60000,    -0.47146,92.04797,50.00000,0.0000e+000,20.00000,    -0.11998,0.90120
297.16101, 40.78000,    -0.47624,92.02538,50.00000,0.0000e+000,20.00000,    -0.11985,0.89927
298.91699, 40.96000,    -0.48035,92.00367,50.00000,0.0000e+000,20.00000,    -0.12008,0.89734
300.68600, 41.14000,    -0.48362,91.98050,50.00000,0.0000e+000,20.00000,    -0.12041,0.89540
302.42801, 41.32000,    -0.48688,91.95611,50.00000,0.0000e+000,20.00000,    -0.12059,0.89350
304.19400, 41.50000,    -0.49136,91.93335,50.00000,0.0000e+000,20.00000,    -0.12109,0.89157
305.95700, 41.68000,    -0.49580,91.91157,50.00000,0.0000e+000,20.00000,    -0.12195,0.88966
307.72601, 41.86000,    -0.50081,91.89054,50.00000,0.0000e+000,20.00000,    -0.12287,0.88774
309.47800, 42.04000,    -0.50599,91.86979,50.00000,0.0000e+000,20.00000,    -0.12346,0.88585
311.26300, 42.22000,    -0.51040,91.84806,50.00000,0.0000e+000,20.00000,    -0.12413,0.88393
313.02200, 42.40000,    -0.51493,91.82690,50.00000,0.0000e+000,20.00000,    -0.12491,0.88204
314.80200, 42.58000,    -0.52062,91.80598,50.00000,0.0000e+000,20.00000,    -0.12575,0.88013
316.56500, 42.76000,    -0.52571,91.78376,50.00000,0.0000e+000,20.00000,    -0.12682,0.87825
318.35501, 42.94000,    -0.53027,91.76096,50.00000,0.0000e+000,20.00000,    -0.12743,0.87635
320.11700, 43.12000,    -0.53381,91.73923,50.00000,0.0000e+000,20.00000,    -0.12726,0.87448
321.87500, 43.30000,    -0.53706,91.71704,50.00000,0.0000e+000,20.00000,    -0.12779,0.87262
323.63901, 43.48000,    -0.54059,91.69372,50.00000,0.0000e+000,20.00000,    -0.12909,0.87076
325.39401, 43.66000,    -0.54426,91.67005,50.00000,0.0000e+000,20.00000,    -0.13043,0.86891
327.18301, 43.84000,    -0.54761,91.64714,50.00000,0.0000e+000,20.00000,    -0.13219,0.86704
328.93201, 44.02000,    -0.55190,91.62376,50.00000,0.0000e+000,20.00000,    -0.13383,0.86521
330.69800, 44.20000,    -0.55679,91.59893,50.00000,0.0000e+000,20.00000,    -0.13498,0.86337
332.46500, 44.38000,    -0.56117,91.57303,50.00000,0.0000e+000,20.00000,    -0.13621,0.86154
334.25500, 44.56000,    -0.56634,91.54741,50.00000,0.0000e+000,20.00000,    -0.13792,0.85968
336.01901, 44.74000,    -0.57047,91.52215,50.00000,0.0000e+000,20.00000,    -0.14014,0.85786
337.80399, 44.92000,    -0.57524,91.49827,50.00000,0.0000e+000,20.00000,    -0.14244,0.85602
339.58301, 45.10000,    -0.57934,91.47366,50.00000,0.0000e+000,20.00000,    -0.14437,0.85420
341.38901, 45.28000,    -0.58273,91.44708,50.00000,0.0000e+000,20.00000,    -0.14633,0.85235
343.16000, 45.46000,    -0.58674,91.42096,50.00000,0.0000e+000,20.00000,    -0.14868,0.85055
344.95300, 45.64000,    -0.59005,91.39414,50.00000,0.0000e+000,20.00000,    -0.15078,0.84873
346.73999, 45.82000,    -0.59317,91.36634,50.00000,0.0000e+000,20.00000,    -0.15283,0.84692
348.50800, 46.00000,    -0.59671,91.34053,50.00000,0.0000e+000,20.00000,    -0.15511,0.84513
350.28201, 46.18000,    -0.60085,91.31540,50.00000,0.0000e+000,20.00000,    -0.15742,0.84335
352.07800, 46.36000,    -0.60469,91.28770,50.00000,0.0000e+000,20.00000,    -0.15921,0.84155
353.87799, 46.54000,    -0.60916,91.25695,50.00000,0.0000e+000,20.00000,    -0.16069,0.83975
355.67300, 46.72000,    -0.61436,91.22640,50.00000,0.0000e+000,20.00000,    -0.16246,0.83796
357.44901, 46.90000,    -0.61737,91.19730,50.00000,0.0000e+000,20.00000,    -0.16425,0.83620
359.23901, 47.08000,    -0.62083,91.16730,50.00000,0.0000e+000,20.00000,    -0.16557,0.83443
361.04001, 47.26000,    -0.62323,91.13510,50.00000,0.0000e+000,20.00000,    -0.16690,0.83265
362.81601, 47.44000,    -0.62540,91.10414,50.00000,0.0000e+000,20.00000,    -0.16760,0.83091
364.60400, 47.62000,    -0.62849,91.07361,50.00000,0.0000e+000,20.00000,    -0.16782,0.82915
366.38101, 47.80000,    -0.63070,91.04110,50.00000,0.0000e+000,20.00000,    -0.16879,0.82742
368.15500, 47.98000,    -0.63412,91.00674,50.00000,0.0000e+000,20.00000,    -0.17021,0.82569
369.91699, 48.16000,    -0.63654,90.97419,50.00000,0.0000e+000,20.00000,    -0.17094,0.82398
371.70099, 48.34000,    -0.64004,90.94326,50.00000,0.0000e+000,20.00000,    -0.17064,0.82226
373.48300, 48.52000,    -0.64444,90.91275,50.00000,0.0000e+000,20.00000,    -0.17016,0.82055
375.26501, 48.70000,    -0.64864,90.88201,50.00000,0.0000e+000,20.00000,    -0.17018,0.81883
377.04599, 48.88000,    -0.65252,90.85076,50.00000,0.0000e+000,20.00000,    -0.17027,0.81713
378.82199, 49.06000,    -0.65677,90.81959,50.00000,0.0000e+000,20.00000,    -0.16978,0.81544
380.61700, 49.24000,    -0.66073,90.79005,50.00000,0.0000e+000,20.00000,    -0.16948,0.81373
382.40701, 49.42000,    -0.66472,90.76163,50.00000,0.0000e+000,20.00000,    -0.16939,0.81204
384.19000, 49.60000,    -0.66851,90.73197,50.00000,0.0000e+000,20.00000,    -0.16877,0.81036
385.96399, 49.78000,    -0.67265,90.70188,50.00000,0.0000e+000,20.00000,    -0.16759,0.80869
387.78000, 49.96000,    -0.67887,90.67187,50.00000,0.0000e+000,20.00000,    -0.16657,0.80699
389.58099, 50.14000,    -0.68478,90.64252,50.00000,0.0000e+000,20.00000,    -0.16558,0.80531
391.37201, 50.32000,    -0.69000,90.61341,50.00000,0.0000e+000,20.00000,    -0.16408,0.80365
393.17700, 50.50000,    -0.69482,90.58428,50.00000,0.0000e+000,20.00000,    -0.16296,0.80197
394.96899, 50.68000,    -0.69853,90.55431,50.00000,0.0000e+000,20.00000,    -0.16237,0.80032
396.74701, 50.86000,    -0.70289,90.52410,50.00000,0.0000e+000,20.00000,    -0.16219,0.79869
398.53400, 51.04000,    -0.70695,90.49391,50.00000,0.0000e+000,20.00000,    -0.16240,0.79705
400.30600, 51.22000,    -0.71146,90.46383,50.00000,0.0000e+000,20.00000,    -0.16263,0.79543
402.07800, 51.40000,    -0.71556,90.43395,50.00000,0.0000e+000,20.00000,    -0.16199,0.79382
403.83801, 51.58000,    -0.71935,90.40396,50.00000,0.0000e+000,20.00000,    -0.16168,0.79222
405.61499, 51.76000,    -0.72437,90.37455,50.00000,0.0000e+000,20.00000,    -0.16245,0.79062
407.37500, 51.94000,    -0.73008,90.34679,50.00000,0.0000e+000,20.00000,    -0.16323,0.78904
409.15701, 52.12000,    -0.73735,90.32151,50.00000,0.0000e+000,20.00000,    -0.16369,0.78744
410.94400, 52.30000,    -0.74488,90.29536,50.00000,0.0000e+000,20.00000,    -0.16473,0.78584
412.73099, 52.48000,    -0.75198,90.26664,50.00000,0.0000e+000,20.00000,    -0.16516,0.78425
414.52100, 52.66000,    -0.75746,90.23623,50.00000,0.0000e+000,20.00000,    -0.16521,0.78267
416.29800, 52.84000,    -0.76220,90.20544,50.00000,0.0000e+000,20.00000,    -0.16533,0.78110
418.09299, 53.02000,    -0.76731,90.17595,50.00000,0.0000e+000,20.00000,    -0.16529,0.77952
419.87000, 53.20000,    -0.77202,90.14861,50.00000,0.0000e+000,20.00000,    -0.16558,0.77796
421.63599, 53.38000,    -0.77749,90.12027,50.00000,0.0000e+000,20.00000,    -0.16612,0.77642
423.43701, 53.56000,    -0.78460,90.08781,50.00000,0.0000e+000,20.00000,    -0.16680,0.77485
425.24899, 53.74000,    -0.79174,90.05511,50.00000,0.0000e+000,20.00000,    -0.16787,0.77328
427.04300, 53.92000,    -0.79794,90.02436,50.00000,0.0000e+000,20.00000,    -0.16990,0.77173
428.84299, 54.10000,    -0.80317,89.99176,50.00000,0.0000e+000,20.00000,    -0.17198,0.77018
430.64999, 54.28000,    -0.80772,89.95989,50.00000,0.0000e+000,20.00000,    -0.17344,0.76864
432.44199, 54.46000,    -0.81136,89.92959,50.00000,0.0000e+000,20.00000,    -0.17472,0.76711
434.23401, 54.64000,    -0.81569,89.89887,50.00000,0.0000e+000,20.00000,    -0.17591,0.76558
436.01300, 54.82000,    -0.81957,89.86889,50.00000,0.0000e+000,20.00000,    -0.17747,0.76408
437.80499, 55.00000,    -0.82350,89.83812,50.00000,0.0000e+000,20.00000,    -0.17958,0.76257
439.58200, 55.18000,    -0.82884,89.80627,50.00000,0.0000e+000,20.00000,    -0.18159,0.76107
441.35800, 55.36000,    -0.83426,89.77416,50.00000,0.0000e+000,20.00000,    -0.18235,0.75959
443.16101, 55.54000,    -0.83900,89.74227,50.00000,0.0000e+000,20.00000,    -0.18342,0.75809
444.94699, 55.72000,    -0.84371,89.70940,50.00000,0.0000e+000,20.00000,    -0.18593,0.75660
446.73599, 55.90000,    -0.84795,89.67605,50.00000,0.0000e+000,20.00000,    -0.18795,0.75512
448.52802, 56.08000,    -0.85292,89.64246,50.00000,0.0000e+000,20.00000,    -0.18968,0.75365
450.33701, 56.26000,    -0.85791,89.60770,50.00000,0.0000e+000,20.00000,    -0.19235,0.75216
452.12601, 56.44000,    -0.86169,89.57257,50.00000,0.0000e+000,20.00000,    -0.19537,0.75070
453.90399, 56.62000,    -0.86738,89.53708,50.00000,0.0000e+000,20.00000,    -0.19931,0.74926
455.69800, 56.80000,    -0.87161,89.50179,50.00000,0.0000e+000,20.00000,    -0.20316,0.74780
457.50500, 56.98000,    -0.87677,89.46643,50.00000,0.0000e+000,20.00000,    -0.20671,0.74634
459.29401, 57.16000,    -0.88196,89.43186,50.00000,0.0000e+000,20.00000,    -0.21062,0.74490
461.07599, 57.34000,    -0.88621,89.39539,50.00000,0.0000e+000,20.00000,    -0.21445,0.74348
462.87601, 57.52000,    -0.88992,89.35572,50.00000,0.0000e+000,20.00000,    -0.21774,0.74204
464.66299, 57.70000,    -0.89364,89.31579,50.00000,0.0000e+000,20.00000,    -0.22158,0.74062
466.45700, 57.88000,    -0.89753,89.27725,50.00000,0.0000e+000,20.00000,    -0.22623,0.73920
468.24799, 58.06000,    -0.90156,89.23746,50.00000,0.0000e+000,20.00000,    -0.23157,0.73779
470.03101, 58.24000,    -0.90507,89.19600,50.00000,0.0000e+000,20.00000,    -0.23692,0.73639
471.82401, 58.42000,    -0.90780,89.15187,50.00000,0.0000e+000,20.00000,    -0.24215,0.73499
473.60101, 58.60000,    -0.91152,89.10712,50.00000,0.0000e+000,20.00000,    -0.24770,0.73361
475.38199, 58.78000,    -0.91572,89.06259,50.00000,0.0000e+000,20.00000,    -0.25333,0.73223
477.17599, 58.96000,    -0.92010,89.01640,50.00000,0.0000e+000,20.00000,    -0.25910,0.73084
478.96201, 59.14000,    -0.92471,88.97019,50.00000,0.0000e+000,20.00000,    -0.26489,0.72947
480.76099, 59.32000,    -0.93057,88.92566,50.00000,0.0000e+000,20.00000,    -0.27025,0.72809
482.56500, 59.50000,    -0.93519,88.87867,50.00000,0.0000e+000,20.00000,    -0.27663,0.72672
484.34500, 59.68000,    -0.93980,88.82876,50.00000,0.0000e+000,20.00000,    -0.28370,0.72537
486.13599, 59.86000,    -0.94369,88.77506,50.00000,0.0000e+000,20.00000,    -0.28982,0.72401
487.92801, 60.04000,    -0.94752,88.72031,50.00000,0.0000e+000,20.00000,    -0.29535,0.72267
489.72800, 60.22000,    -0.95263,88.66582,50.00000,0.0000e+000,20.00000,    -0.30062,0.72132
491.51501, 60.40000,    -0.95719,88.61039,50.00000,0.0000e+000,20.00000,    -0.30591,0.71998
493.31699, 60.58000,    -0.96187,88.55439,50.00000,0.0000e+000,20.00000,    -0.31081,0.71864
495.12000, 60.76000,    -0.96668,88.49872,50.00000,0.0000e+000,20.00000,    -0.31571,0.71731
496.91299, 60.94000,    -0.97092,88.44184,50.00000,0.0000e+000,20.00000,    -0.32174,0.71599
498.70300, 61.12000,    -0.97480,88.38338,50.00000,0.0000e+000,20.00000,    -0.32822,0.71467
500.49200, 61.30000,    -0.98005,88.32062,50.00000,0.0000e+000,20.00000,    -0.33392,0.71336
502.30301, 61.48000,    -0.98509,88.25589,50.00000,0.0000e+000,20.00000,    -0.33858,0.71205
504.07901, 61.66000,    -0.99023,88.19369,50.00000,0.0000e+000,20.00000,    -0.34269,0.71076
505.85901, 61.84000,    -0.99455,88.13244,50.00000,0.0000e+000,20.00000,    -0.34661,0.70947
507.66699, 62.02000,    -0.99947,88.06972,50.00000,0.0000e+000,20.00000,    -0.34978,0.70818
509.45801, 62.20000,    -1.00466,88.00558,50.00000,0.0000e+000,20.00000,    -0.35315,0.70689
511.24399, 62.38000,    -1.00923,87.94287,50.00000,0.0000e+000,20.00000,    -0.35710,0.70562
513.03699, 62.56000,    -1.01447,87.87979,50.00000,0.0000e+000,20.00000,    -0.36140,0.70435
514.82800, 62.74000,    -1.01984,87.81169,50.00000,0.0000e+000,20.00000,    -0.36543,0.70308
516.63000, 62.92000,    -1.02693,87.74326,50.00000,0.0000e+000,20.00000,    -0.36811,0.70182
518.44098, 63.10000,    -1.03461,87.67579,50.00000,0.0000e+000,20.00000,    -0.36957,0.70055
520.26599, 63.28000,    -1.04250,87.60928,50.00000,0.0000e+000,20.00000,    -0.37086,0.69928
522.07501, 63.46000,    -1.04832,87.54153,50.00000,0.0000e+000,20.00000,    -0.37219,0.69802
523.88898, 63.64000,    -1.05223,87.47216,50.00000,0.0000e+000,20.00000,    -0.37365,0.69677
525.66901, 63.82000,    -1.05452,87.40576,50.00000,0.0000e+000,20.00000,    -0.37529,0.69554
527.46698, 64.00000,    -1.05817,87.33874,50.00000,0.0000e+000,20.00000,    -0.37604,0.69431
529.25897, 64.18000,    -1.06276,87.26859,50.00000,0.0000e+000,20.00000,    -0.37730,0.69309
531.03699, 64.36000,    -1.06841,87.19729,50.00000,0.0000e+000,20.00000,    -0.37865,0.69188
532.82300, 64.54000,    -1.07545,87.12569,50.00000,0.0000e+000,20.00000,    -0.37864,0.69067
534.62402, 64.72000,    -1.08178,87.05723,50.00000,0.0000e+000,20.00000,    -0.37849,0.68946
536.42401, 64.90000,    -1.08818,86.99020,50.00000,0.0000e+000,20.00000,    -0.37863,0.68825
538.21698, 65.08000,    -1.09458,86.92075,50.00000,0.0000e+000,20.00000,    -0.37907,0.68705
540.01202, 65.26000,    -1.09952,86.85280,50.00000,0.0000e+000,20.00000,    -0.37922,0.68586
541.82001, 65.44000,    -1.10613,86.78649,50.00000,0.0000e+000,20.00000,    -0.37866,0.68466
543.61298, 65.62000,    -1.11435,86.71810,50.00000,0.0000e+000,20.00000,    -0.37891,0.68348
545.41699, 65.80000,    -1.11914,86.65115,50.00000,0.0000e+000,20.00000,    -0.37935,0.68230
547.20599, 65.98000,    -1.12297,86.58363,50.00000,0.0000e+000,20.00000,    -0.37895,0.68113
549.00598, 66.16000,    -1.12924,86.51604,50.00000,0.0000e+000,20.00000,    -0.37852,0.67996
550.79199, 66.34000,    -1.13445,86.44873,50.00000,0.0000e+000,20.00000,    -0.37770,0.67880
552.57898, 66.52000,    -1.13750,86.38060,50.00000,0.0000e+000,20.00000,    -0.37683,0.67765
554.36401, 66.70000,    -1.14193,86.31258,50.00000,0.0000e+000,20.00000,    -0.37720,0.67650
556.17401, 66.88000,    -1.14796,86.24434,50.00000,0.0000e+000,20.00000,    -0.37784,0.67535
557.97998, 67.06000,    -1.15532,86.17634,50.00000,0.0000e+000,20.00000,    -0.37865,0.67420
559.81500, 67.24000,    -1.16185,86.10896,50.00000,0.0000e+000,20.00000,    -0.38001,0.67304
561.62299, 67.42000,    -1.16815,86.04121,50.00000,0.0000e+000,20.00000,    -0.38091,0.67190
563.43500, 67.60000,    -1.17191,85.97313,50.00000,0.0000e+000,20.00000,    -0.38117,0.67076
565.24402, 67.78000,    -1.17534,85.90484,50.00000,0.0000e+000,20.00000,    -0.38022,0.66963
567.03497, 67.96000,    -1.17753,85.83546,50.00000,0.0000e+000,20.00000,    -0.38029,0.66851
568.82202, 68.14000,    -1.18039,85.76626,50.00000,0.0000e+000,20.00000,    -0.38161,0.66741
570.62500, 68.32000,    -1.18223,85.70024,50.00000,0.0000e+000,20.00000,    -0.38167,0.66629
572.40601, 68.50000,    -1.18531,85.63260,50.00000,0.0000e+000,20.00000,    -0.38023,0.66520
574.20398, 68.68000,    -1.18825,85.56143,50.00000,0.0000e+000,20.00000,    -0.37978,0.66410
575.98901, 68.86000,    -1.19272,85.48982,50.00000,0.0000e+000,20.00000,    -0.38048,0.66302
577.78601, 69.04000,    -1.19711,85.41880,50.00000,0.0000e+000,20.00000,    -0.38086,0.66193
579.57098, 69.22000,    -1.20145,85.34710,50.00000,0.0000e+000,20.00000,    -0.38109,0.66085
581.38898, 69.40000,    -1.20781,85.27819,50.00000,0.0000e+000,20.00000,    -0.38245,0.65976
583.20099, 69.58000,    -1.21246,85.21411,50.00000,0.0000e+000,20.00000,    -0.38382,0.65867
585.01099, 69.76000,    -1.21669,85.14720,50.00000,0.0000e+000,20.00000,    -0.38444,0.65760
586.80499, 69.94000,    -1.21906,85.07524,50.00000,0.0000e+000,20.00000,    -0.38480,0.65653
588.59497, 70.12000,    -1.22036,85.00593,50.00000,0.0000e+000,20.00000,    -0.38682,0.65548
590.38000, 70.30000,    -1.22288,84.94288,50.00000,0.0000e+000,20.00000,    -0.38863,0.65443
592.17401, 70.48000,    -1.22693,84.87725,50.00000,0.0000e+000,20.00000,    -0.38796,0.65338
593.97400, 70.66000,    -1.23120,84.80685,50.00000,0.0000e+000,20.00000,    -0.38740,0.65233
595.76801, 70.84000,    -1.23493,84.73744,50.00000,0.0000e+000,20.00000,    -0.38882,0.65129
597.58301, 71.02000,    -1.23982,84.66956,50.00000,0.0000e+000,20.00000,    -0.38977,0.65024
599.40302, 71.20000,    -1.24779,84.59694,50.00000,0.0000e+000,20.00000,    -0.39076,0.64919
601.24103, 71.38000,    -1.25323,84.52353,50.00000,0.0000e+000,20.00000,    -0.39271,0.64814
603.05402, 71.56000,    -1.25633,84.45183,50.00000,0.0000e+000,20.00000,    -0.39483,0.64711
604.86401, 71.74000,    -1.25722,84.38113,50.00000,0.0000e+000,20.00000,    -0.39620,0.64608
606.65900, 71.92000,    -1.25846,84.30788,50.00000,0.0000e+000,20.00000,    -0.39727,0.64507
608.45502, 72.10000,    -1.25912,84.23370,50.00000,0.0000e+000,20.00000,    -0.39953,0.64406
610.26300, 72.28000,    -1.26059,84.16466,50.00000,0.0000e+000,20.00000,    -0.40254,0.64305
612.04700, 72.46000,    -1.26258,84.09593,50.00000,0.0000e+000,20.00000,    -0.40466,0.64205
613.84399, 72.64000,    -1.26414,84.02030,50.00000,0.0000e+000,20.00000,    -0.40646,0.64106
615.64099, 72.82000,    -1.26549,83.94469,50.00000,0.0000e+000,20.00000,    -0.40811,0.64006
617.42200, 73.00000,    -1.26790,83.87128,50.00000,0.0000e+000,20.00000,    -0.40859,0.63908
619.22900, 73.18000,    -1.27154,83.79939,50.00000,0.0000e+000,20.00000,    -0.40858,0.63810
621.03101, 73.36000,    -1.27530,83.72631,50.00000,0.0000e+000,20.00000,    -0.40890,0.63711
622.83698, 73.54000,    -1.27914,83.64981,50.00000,0.0000e+000,20.00000,    -0.41016,0.63613
624.63800, 73.72000,    -1.28117,83.57509,50.00000,0.0000e+000,20.00000,    -0.41094,0.63516
626.44299, 73.90000,    -1.28388,83.50327,50.00000,0.0000e+000,20.00000,    -0.41113,0.63419
628.26501, 74.08000,    -1.28716,83.42822,50.00000,0.0000e+000,20.00000,    -0.41196,0.63321
630.09497, 74.26000,    -1.29388,83.35054,50.00000,0.0000e+000,20.00000,    -0.41290,0.63223
631.97302, 74.44000,    -1.30266,83.27366,50.00000,0.0000e+000,20.00000,    -0.41372,0.63124
633.81500, 74.62000,    -1.30735,83.19973,50.00000,0.0000e+000,20.00000,    -0.41487,0.63026
635.63599, 74.80000,    -1.30704,83.12612,50.00000,0.0000e+000,20.00000,    -0.41604,0.62930
637.46002, 74.98000,    -1.30230,83.05243,50.00000,0.0000e+000,20.00000,    -0.41639,0.62835
639.23297, 75.16000,    -1.29928,82.97945,50.00000,0.0000e+000,20.00000,    -0.41630,0.62742
641.02899, 75.34000,    -1.29942,82.90446,50.00000,0.0000e+000,20.00000,    -0.41528,0.62649
642.79797, 75.52000,    -1.29723,82.82877,50.00000,0.0000e+000,20.00000,    -0.41474,0.62557
644.58899, 75.70000,    -1.29946,82.75359,50.00000,0.0000e+000,20.00000,    -0.41609,0.62465
646.39398, 75.88000,    -1.30309,82.68001,50.00000,0.0000e+000,20.00000,    -0.41671,0.62372
648.18799, 76.06000,    -1.30532,82.60897,50.00000,0.0000e+000,20.00000,    -0.41526,0.62281
649.97498, 76.24000,    -1.30688,82.53212,50.00000,0.0000e+000,20.00000,    -0.41411,0.62190
651.74701, 76.42000,    -1.30752,82.45193,50.00000,0.0000e+000,20.00000,    -0.41441,0.62100
653.53998, 76.60000,    -1.30921,82.37334,50.00000,0.0000e+000,20.00000,    -0.41538,0.62009
655.32703, 76.78000,    -1.31125,82.29948,50.00000,0.0000e+000,20.00000,    -0.41661,0.61920
657.10797, 76.96000,    -1.31349,82.22720,50.00000,0.0000e+000,20.00000,    -0.41800,0.61831
658.90198, 77.14000,    -1.31736,82.15478,50.00000,0.0000e+000,20.00000,    -0.41913,0.61741
660.69397, 77.32000,    -1.32123,82.08174,50.00000,0.0000e+000,20.00000,    -0.41916,0.61652
662.47998, 77.50000,    -1.32453,82.00544,50.00000,0.0000e+000,20.00000,    -0.41869,0.61564
664.28900, 77.68000,    -1.32804,81.92823,50.00000,0.0000e+000,20.00000,    -0.41986,0.61475
666.08502, 77.86000,    -1.33231,81.85561,50.00000,0.0000e+000,20.00000,    -0.42297,0.61387
667.89502, 78.04000,    -1.33667,81.78298,50.00000,0.0000e+000,20.00000,    -0.42393,0.61298
669.70801, 78.22000,    -1.34132,81.70787,50.00000,0.0000e+000,20.00000,    -0.42441,0.61210
671.52802, 78.40000,    -1.34230,81.63114,50.00000,0.0000e+000,20.00000,    -0.42565,0.61122
673.30902, 78.58000,    -1.34167,81.55285,50.00000,0.0000e+000,20.00000,    -0.42857,0.61036
675.09900, 78.76000,    -1.34338,81.47486,50.00000,0.0000e+000,20.00000,    -0.43259,0.60950
676.90002, 78.94000,    -1.34638,81.39608,50.00000,0.0000e+000,20.00000,    -0.43643,0.60864
678.72498, 79.12000,    -1.35345,81.31958,50.00000,0.0000e+000,20.00000,    -0.44078,0.60777
680.54602, 79.30000,    -1.35887,81.24612,50.00000,0.0000e+000,20.00000,    -0.44508,0.60691
682.36499, 79.48000,    -1.36327,81.16884,50.00000,0.0000e+000,20.00000,    -0.44923,0.60605
684.15900, 79.66000,    -1.36241,81.08651,50.00000,0.0000e+000,20.00000,    -0.45503,0.60521
685.92297, 79.84000,    -1.35814,81.00689,50.00000,0.0000e+000,20.00000,    -0.46169,0.60438
687.71301, 80.02000,    -1.35801,80.92576,50.00000,0.0000e+000,20.00000,    -0.46788,0.60354
689.50500, 80.20000,    -1.36115,80.84204,50.00000,0.0000e+000,20.00000,    -0.47411,0.60271
691.31403, 80.38000,    -1.36528,80.75737,50.00000,0.0000e+000,20.00000,    -0.47965,0.60187
693.12299, 80.56000,    -1.36591,80.67037,50.00000,0.0000e+000,20.00000,    -0.48487,0.60104
694.90503, 80.74000,    -1.36543,80.58396,50.00000,0.0000e+000,20.00000,    -0.49091,0.60022
696.69098, 80.92000,    -1.36353,80.49573,50.00000,0.0000e+000,20.00000,    -0.49695,0.59940
698.50500, 81.10000,    -1.36570,80.40468,50.00000,0.0000e+000,20.00000,    -0.50286,0.59857
700.36401, 81.28000,    -1.37438,80.31206,50.00000,0.0000e+000,20.00000,    -0.50837,0.59773
702.25000, 81.46000,    -1.38553,80.21801,50.00000,0.0000e+000,20.00000,    -0.51207,0.59687
704.12299, 81.64000,    -1.38935,80.12160,50.00000,0.0000e+000,20.00000,    -0.51574,0.59603
705.93701, 81.82000,    -1.38528,80.02435,50.00000,0.0000e+000,20.00000,    -0.51890,0.59522
707.75000, 82.00000,    -1.37892,79.92535,50.00000,0.0000e+000,20.00000,    -0.52126,0.59441
709.53302, 82.18000,    -1.37318,79.82653,50.00000,0.0000e+000,20.00000,    -0.52355,0.59361
711.31799, 82.36000,    -1.36865,79.72960,50.00000,0.0000e+000,20.00000,    -0.52443,0.59282
713.10199, 82.54000,    -1.36498,79.62936,50.00000,0.0000e+000,20.00000,    -0.52491,0.59203
714.87201, 82.72000,    -1.36480,79.52939,50.00000,0.0000e+000,20.00000,    -0.52363,0.59125
716.65900, 82.90000,    -1.36614,79.43399,50.00000,0.0000e+000,20.00000,    -0.52081,0.59047
718.44299, 83.08000,    -1.36916,79.33777,50.00000,0.0000e+000,20.00000,    -0.51746,0.58968
720.24103, 83.26000,    -1.37606,79.24189,50.00000,0.0000e+000,20.00000,    -0.51344,0.58890
722.04102, 83.44000,    -1.38320,79.14805,50.00000,0.0000e+000,20.00000,    -0.50895,0.58812
723.81897, 83.62000,    -1.38814,79.05589,50.00000,0.0000e+000,20.00000,    -0.50353,0.58735
725.59698, 83.80000,    -1.39147,78.96379,50.00000,0.0000e+000,20.00000,    -0.49729,0.58658
727.40503, 83.98000,    -1.39772,78.87096,50.00000,0.0000e+000,20.00000,    -0.49071,0.58581
729.21997, 84.16000,    -1.40680,78.78051,50.00000,0.0000e+000,20.00000,    -0.48490,0.58503
731.02802, 84.34000,    -1.41408,78.69192,50.00000,0.0000e+000,20.00000,    -0.47836,0.58426
732.83002, 84.52000,    -1.41849,78.60781,50.00000,0.0000e+000,20.00000,    -0.47226,0.58349
734.62701, 84.70000,    -1.42113,78.52759,50.00000,0.0000e+000,20.00000,    -0.46816,0.58273
736.41498, 84.88000,    -1.42483,78.44700,50.00000,0.0000e+000,20.00000,    -0.46490,0.58198
738.22900, 85.06000,    -1.43219,78.36810,50.00000,0.0000e+000,20.00000,    -0.46281,0.58121
740.04602, 85.24000,    -1.44146,78.28826,50.00000,0.0000e+000,20.00000,    -0.46206,0.58045
741.83398, 85.42000,    -1.44709,78.21058,50.00000,0.0000e+000,20.00000,    -0.46211,0.57970
743.65100, 85.60000,    -1.45108,78.13442,50.00000,0.0000e+000,20.00000,    -0.46239,0.57895
745.44397, 85.78000,    -1.45437,78.05950,50.00000,0.0000e+000,20.00000,    -0.46165,0.57820
747.24902, 85.96000,    -1.45682,77.98371,50.00000,0.0000e+000,20.00000,    -0.46094,0.57746
749.06799, 86.14000,    -1.45717,77.90812,50.00000,0.0000e+000,20.00000,    -0.46037,0.57671
750.87598, 86.32000,    -1.45480,77.83043,50.00000,0.0000e+000,20.00000,    -0.45767,0.57596
752.66699, 86.50000,    -1.44949,77.74983,50.00000,0.0000e+000,20.00000,    -0.45123,0.57523
754.46198, 86.68000,    -1.44184,77.66656,50.00000,0.0000e+000,20.00000,    -0.43832,0.57450
756.26202, 86.86000,    -1.43567,77.57855,50.00000,0.0000e+000,20.00000,    -0.42269,0.57376
758.07599, 87.04000,    -1.43275,77.48758,50.00000,0.0000e+000,20.00000,    -0.40522,0.57303
759.88397, 87.22000,    -1.43143,77.39505,50.00000,0.0000e+000,20.00000,    -0.38730,0.57230
761.69702, 87.40000,    -1.43209,77.30212,50.00000,0.0000e+000,20.00000,    -0.36996,0.57157
763.54498, 87.58000,    -1.43684,77.21119,50.00000,0.0000e+000,20.00000,    -0.35321,0.57082
765.39801, 87.76000,    -1.44825,77.12301,50.00000,0.0000e+000,20.00000,    -0.33628,0.57008
767.22803, 87.94000,    -1.46168,77.03536,50.00000,0.0000e+000,20.00000,    -0.31926,0.56935
769.03699, 88.12000,    -1.47848,76.95792,50.00000,0.0000e+000,20.00000,    -0.30149,0.56863
770.82001, 88.30000,    -1.50971,76.89773,50.00000,0.0000e+000,20.00000,    -0.28245,0.56792
772.60699, 88.48000,    -1.56367,76.86111,50.00000,0.0000e+000,20.00000,    -0.26271,0.56722
774.40802, 88.66000,    -1.59984,76.83821,50.00000,0.0000e+000,20.00000,    -0.24193,0.56650
776.20801, 88.84000,    -1.62054,76.82141,50.00000,0.0000e+000,20.00000,    -0.22035,0.56580
778.00897, 89.02000,    -1.63384,76.80866,50.00000,0.0000e+000,20.00000,    -0.19841,0.56509
779.79102, 89.20000,    -1.64423,76.79573,50.00000,0.0000e+000,20.00000,    -0.17646,0.56439
781.62500, 89.38000,    -1.65489,76.78221,50.00000,0.0000e+000,20.00000,    -0.15476,0.56368
783.42102, 89.56000,    -1.66338,76.76823,50.00000,0.0000e+000,20.00000,    -0.13387,0.56298
785.22498, 89.74000,    -1.67011,76.75484,50.00000,0.0000e+000,20.00000,    -0.11304,0.56228
787.02002, 89.92000,    -1.67306,76.74237,50.00000,0.0000e+000,20.00000,-9.4436e-002,0.56158
788.81403, 90.10000,    -1.67571,76.73142,50.00000,0.0000e+000,20.00000,-8.0418e-002,0.56089
790.61200, 90.28000,    -1.67987,76.72110,50.00000,0.0000e+000,20.00000,-7.3201e-002,0.56020
792.39099, 90.46000,    -1.68223,76.70970,50.00000,0.0000e+000,20.00000,-7.0402e-002,0.55952
794.19598, 90.64000,    -1.68602,76.69812,50.00000,0.0000e+000,20.00000,-6.9448e-002,0.55882
795.99597, 90.82000,    -1.69128,76.68587,50.00000,0.0000e+000,20.00000,-6.9747e-002,0.55814
797.78497, 91.00000,    -1.69575,76.67335,50.00000,0.0000e+000,20.00000,-7.0068e-002,0.55746
799.58801, 91.18000,    -1.69979,76.66088,50.00000,0.0000e+000,20.00000,-7.0186e-002,0.55677
801.38599, 91.36000,    -1.70456,76.64915,50.00000,0.0000e+000,20.00000,-6.9973e-002,0.55609
803.18701, 91.54000,    -1.70708,76.63700,50.00000,0.0000e+000,20.00000,-6.9939e-002,0.55541
804.97498, 91.72000,    -1.70873,76.62543,50.00000,0.0000e+000,20.00000,-7.0322e-002,0.55473
806.77197, 91.90000,    -1.71226,76.61351,50.00000,0.0000e+000,20.00000,-7.1515e-002,0.55406
808.56897, 92.08000,    -1.71505,76.60006,50.00000,0.0000e+000,20.00000,-7.2982e-002,0.55338
810.37500, 92.26000,    -1.71962,76.58609,50.00000,0.0000e+000,20.00000,-7.4395e-002,0.55271
812.17902, 92.44000,    -1.72525,76.57199,50.00000,0.0000e+000,20.00000,-7.5831e-002,0.55203
813.97998, 92.62000,    -1.72979,76.55775,50.00000,0.0000e+000,20.00000,-7.7360e-002,0.55136
815.78900, 92.80000,    -1.73265,76.54380,50.00000,0.0000e+000,20.00000,-7.9155e-002,0.55069
817.57599, 92.98000,    -1.73455,76.52986,50.00000,0.0000e+000,20.00000,-8.0803e-002,0.55002
819.40503, 93.16000,    -1.74110,76.51659,50.00000,0.0000e+000,20.00000,-8.2559e-002,0.54935
821.21503, 93.34000,    -1.74686,76.50331,50.00000,0.0000e+000,20.00000,-8.4427e-002,0.54868
823.02802, 93.52000,    -1.75204,76.48938,50.00000,0.0000e+000,20.00000,-8.6329e-002,0.54801
824.84003, 93.70000,    -1.75766,76.47405,50.00000,0.0000e+000,20.00000,-8.8118e-002,0.54734
826.66400, 93.88000,    -1.76330,76.45837,50.00000,0.0000e+000,20.00000,-8.9889e-002,0.54667
828.47400, 94.06000,    -1.77024,76.44215,50.00000,0.0000e+000,20.00000,-9.1432e-002,0.54601
830.28101, 94.24000,    -1.77684,76.42534,50.00000,0.0000e+000,20.00000,-9.2752e-002,0.54535
832.13098, 94.42000,    -1.78792,76.40782,50.00000,0.0000e+000,20.00000,-9.4700e-002,0.54467
833.96698, 94.60000,    -1.79557,76.38892,50.00000,0.0000e+000,20.00000,-9.6892e-002,0.54401
835.76001, 94.78000,    -1.79789,76.37013,50.00000,0.0000e+000,20.00000,-9.9431e-002,0.54335
837.55902, 94.96000,    -1.80005,76.35206,50.00000,0.0000e+000,20.00000,    -0.10224,0.54270
839.35101, 95.14000,    -1.80145,76.33316,50.00000,0.0000e+000,20.00000,    -0.10556,0.54205
841.14099, 95.32000,    -1.80224,76.31441,50.00000,0.0000e+000,20.00000,    -0.10906,0.54140
842.92102, 95.50000,    -1.80374,76.29623,50.00000,0.0000e+000,20.00000,    -0.11191,0.54076
844.73798, 95.68000,    -1.81090,76.27673,50.00000,0.0000e+000,20.00000,    -0.11428,0.54011
846.54199, 95.86000,    -1.82039,76.25688,50.00000,0.0000e+000,20.00000,    -0.11633,0.53946
848.34399, 96.04000,    -1.82282,76.23824,50.00000,0.0000e+000,20.00000,    -0.11788,0.53881
850.13599, 96.22000,    -1.82524,76.21708,50.00000,0.0000e+000,20.00000,    -0.12006,0.53817
851.93402, 96.40000,    -1.82654,76.19526,50.00000,0.0000e+000,20.00000,    -0.12248,0.53752
853.75403, 96.58000,    -1.83408,76.17211,50.00000,0.0000e+000,20.00000,    -0.12477,0.53687
855.57599, 96.76000,    -1.83994,76.14861,50.00000,0.0000e+000,20.00000,    -0.12675,0.53622
857.38202, 96.94000,    -1.84466,76.12356,50.00000,0.0000e+000,20.00000,    -0.12917,0.53558
859.19397, 97.12000,    -1.84449,76.09696,50.00000,0.0000e+000,20.00000,    -0.13150,0.53494
861.00299, 97.30000,    -1.84606,76.07126,50.00000,0.0000e+000,20.00000,    -0.13410,0.53429
862.80701, 97.48000,    -1.84779,76.04673,50.00000,0.0000e+000,20.00000,    -0.13738,0.53365
864.61499, 97.66000,    -1.84883,76.02304,50.00000,0.0000e+000,20.00000,    -0.14072,0.53301
866.42200, 97.84000,    -1.85191,76.00056,50.00000,0.0000e+000,20.00000,    -0.14359,0.53237
868.21698, 98.02000,    -1.85236,75.97589,50.00000,0.0000e+000,20.00000,    -0.14596,0.53174
870.01202, 98.20000,    -1.85327,75.94843,50.00000,0.0000e+000,20.00000,    -0.14896,0.53110
871.86401, 98.38000,    -1.86388,75.92093,50.00000,0.0000e+000,20.00000,    -0.15140,0.53045
873.71997, 98.56000,    -1.87101,75.89549,50.00000,0.0000e+000,20.00000,    -0.15349,0.52980
875.61902, 98.74000,    -1.88390,75.86830,50.00000,0.0000e+000,20.00000,    -0.15556,0.52913
877.44202, 98.92000,    -1.88470,75.84063,50.00000,0.0000e+000,20.00000,    -0.15730,0.52849
879.17798, 99.10000,    -1.86627,75.81340,50.00000,0.0000e+000,20.00000,    -0.16005,0.52788
880.93298, 99.28000,    -1.85521,75.78261,50.00000,0.0000e+000,20.00000,    -0.16344,0.52727
882.70599, 99.46000,    -1.85373,75.75025,50.00000,0.0000e+000,20.00000,    -0.16663,0.52665
884.48602, 99.64000,    -1.85432,75.72064,50.00000,0.0000e+000,20.00000,    -0.17006,0.52602
886.25897, 99.82000,    -1.85337,75.69169,50.00000,0.0000e+000,20.00000,    -0.17326,0.52540
888.03998,100.00000,    -1.85342,75.65929,50.00000,0.0000e+000,20.00000,    -0.17578,0.52478
889.85999,100.18000,    -1.85744,75.62704,50.00000,0.0000e+000,20.00000,    -0.17835,0.52415
891.65997,100.36000,    -1.86004,75.59609,50.00000,0.0000e+000,20.00000,    -0.18156,0.52352
893.48199,100.54000,    -1.86250,75.56394,50.00000,0.0000e+000,20.00000,    -0.18450,0.52289
895.29602,100.72000,    -1.86450,75.53126,50.00000,0.0000e+000,20.00000,    -0.18729,0.52225
897.09601,100.90000,    -1.86371,75.49578,50.00000,0.0000e+000,20.00000,    -0.19068,0.52163
898.86401,101.08000,    -1.85821,75.45863,50.00000,0.0000e+000,20.00000,    -0.19313,0.52101
900.64600,101.26000,    -1.85363,75.42293,50.00000,0.0000e+000,20.00000,    -0.19492,0.52040
902.44000,101.44000,    -1.85651,75.38776,50.00000,0.0000e+000,20.00000,    -0.19717,0.51977
904.25000,101.62000,    -1.86164,75.35222,50.00000,0.0000e+000,20.00000,    -0.19950,0.51915
906.05298,101.80000,    -1.86162,75.31579,50.00000,0.0000e+000,20.00000,    -0.20140,0.51852
907.85797,101.98000,    -1.86086,75.27884,50.00000,0.0000e+000,20.00000,    -0.20315,0.51790
909.67401,102.16000,    -1.86542,75.24147,50.00000,0.0000e+000,20.00000,    -0.20482,0.51727
911.49799,102.34000,    -1.87000,75.20401,50.00000,0.0000e+000,20.00000,    -0.20607,0.51664
913.31799,102.52000,    -1.87304,75.16609,50.00000,0.0000e+000,20.00000,    -0.20723,0.51601
915.14301,102.70000,    -1.87167,75.12689,50.00000,0.0000e+000,20.00000,    -0.20713,0.51538
916.92200,102.88000,    -1.86603,75.08754,50.00000,0.0000e+000,20.00000,    -0.20571,0.51476
918.71600,103.06000,    -1.85913,75.04864,50.00000,0.0000e+000,20.00000,    -0.20434,0.51414
920.49902,103.24000,    -1.85634,75.01001,50.00000,0.0000e+000,20.00000,    -0.20262,0.51353
922.31897,103.42000,    -1.86169,74.97291,50.00000,0.0000e+000,20.00000,    -0.20009,0.51290
924.11499,103.60000,    -1.86335,74.93431,50.00000,0.0000e+000,20.00000,    -0.19653,0.51228
925.94098,103.78000,    -1.86573,74.89510,50.00000,0.0000e+000,20.00000,    -0.19310,0.51165
927.75598,103.96000,    -1.86627,74.85784,50.00000,0.0000e+000,20.00000,    -0.19028,0.51103
929.56500,104.14000,    -1.86677,74.82135,50.00000,0.0000e+000,20.00000,    -0.18695,0.51040
931.36798,104.32000,    -1.86722,74.78444,50.00000,0.0000e+000,20.00000,    -0.18280,0.50978
933.17999,104.50000,    -1.86512,74.74942,50.00000,0.0000e+000,20.00000,    -0.17770,0.50916
935.01202,104.68000,    -1.87025,74.71719,50.00000,0.0000e+000,20.00000,    -0.17166,0.50853
936.84003,104.86000,    -1.87282,74.68608,50.00000,0.0000e+000,20.00000,    -0.16613,0.50790
938.66803,105.04000,    -1.87121,74.65678,50.00000,0.0000e+000,20.00000,    -0.16062,0.50727
940.50000,105.22000,    -1.86879,74.63023,50.00000,0.0000e+000,20.00000,    -0.15478,0.50664
942.29498,105.40000,    -1.86409,74.60648,50.00000,0.0000e+000,20.00000,    -0.14774,0.50602
944.13501,105.58000,    -1.86300,74.58275,50.00000,0.0000e+000,20.00000,    -0.14060,0.50539
945.94800,105.76000,    -1.85998,74.55586,50.00000,0.0000e+000,20.00000,    -0.13372,0.50476
947.72400,105.94000,    -1.85054,74.53006,50.00000,0.0000e+000,20.00000,    -0.12742,0.50415
949.51300,106.12000,    -1.84045,74.50716,50.00000,0.0000e+000,20.00000,    -0.12109,0.50354
951.28101,106.30000,    -1.83147,74.48630,50.00000,0.0000e+000,20.00000,    -0.11480,0.50293
953.06799,106.48000,    -1.82508,74.46878,50.00000,0.0000e+000,20.00000,    -0.10875,0.50231
954.85602,106.66000,    -1.81903,74.45030,50.00000,0.0000e+000,20.00000,    -0.10295,0.50170
956.63501,106.84000,    -1.81429,74.43148,50.00000,0.0000e+000,20.00000,-9.7920e-002,0.50108
958.41699,107.02000,    -1.80630,74.41502,50.00000,0.0000e+000,20.00000,-9.3424e-002,0.50047
960.19897,107.20000,    -1.80032,74.40222,50.00000,0.0000e+000,20.00000,-8.9388e-002,0.49986
962.00897,107.38000,    -1.79762,74.38916,50.00000,0.0000e+000,20.00000,-8.5706e-002,0.49923
963.82599,107.56000,    -1.79523,74.37650,50.00000,0.0000e+000,20.00000,-8.1072e-002,0.49861
965.63300,107.74000,    -1.79151,74.36347,50.00000,0.0000e+000,20.00000,-7.6121e-002,0.49798
967.50201,107.92000,    -1.79540,74.34944,50.00000,0.0000e+000,20.00000,-7.1762e-002,0.49734
969.33099,108.10000,    -1.79288,74.33680,50.00000,0.0000e+000,20.00000,-6.7908e-002,0.49671
971.10602,108.28000,    -1.78374,74.32599,50.00000,0.0000e+000,20.00000,-6.5326e-002,0.49609
972.85400,108.46000,    -1.77003,74.31612,50.00000,0.0000e+000,20.00000,-6.2379e-002,0.49549
974.64203,108.64000,    -1.76813,74.30491,50.00000,0.0000e+000,20.00000,-5.9534e-002,0.49487
976.45203,108.82000,    -1.76944,74.29416,50.00000,0.0000e+000,20.00000,-5.7008e-002,0.49425
978.30402,109.00000,    -1.77811,74.28467,50.00000,0.0000e+000,20.00000,-5.5124e-002,0.49361
980.10400,109.18000,    -1.77934,74.27490,50.00000,0.0000e+000,20.00000,-5.4318e-002,0.49298
981.92603,109.36000,    -1.77924,74.26508,50.00000,0.0000e+000,20.00000,-5.2470e-002,0.49235
983.75500,109.54000,    -1.78674,74.25673,50.00000,0.0000e+000,20.00000,-4.9701e-002,0.49172
985.56201,109.72000,    -1.78421,74.24936,50.00000,0.0000e+000,20.00000,-4.8522e-002,0.49109
987.32703,109.90000,    -1.77861,74.24221,50.00000,0.0000e+000,20.00000,-4.6471e-002,0.49048
989.10101,110.08000,    -1.77169,74.23393,50.00000,0.0000e+000,20.00000,-4.5094e-002,0.48986
990.84003,110.26000,    -1.76524,74.22634,50.00000,0.0000e+000,20.00000,-4.3556e-002,0.48926
992.62000,110.44000,    -1.76707,74.21808,50.00000,0.0000e+000,20.00000,-4.4537e-002,0.48864
994.44501,110.62000,    -1.77527,74.20992,50.00000,0.0000e+000,20.00000,-4.4696e-002,0.48801
996.25702,110.80000,    -1.78295,74.20365,50.00000,0.0000e+000,20.00000,-4.3792e-002,0.48738
998.07800,110.98000,    -1.78563,74.19430,50.00000,0.0000e+000,20.00000,-6.4988e-002,0.48674
998.26898,111.00000,    -1.78681,74.19318,50.00000,0.0000e+000,20.00000,-3.9640e-002,0.48668