File: book/some_content/TG_ExpDat_CEM_I_DC1; 17-1-2025-2.csv
#FILE:                       ,CEM_I_DC1; 17-1-2025.ngb-ds3
#FORMAT:                     ,NETZSCH5
#IDENTITY:                   ,CEM I
#DECIMAL:                    ,POINT
#SEPARATOR:                  ,COMMA
#MTYPE:                      ,DSC
#INSTRUMENT:                 ,Microlab TU Delft
#PROJECT:                    ,
#DATE/TIME:                  ,18/01/2025 4:55:01 PM
#CORR. FILE:                 ,Blank with cover; 13-1-2025.ngb-bs3
#LABORATORY:                 ,TU Delft Micro Lab
#OPERATOR:                   ,Ahmed
#REMARK:                     ,under Argon atmosphere, 10K/min
#SAMPLE:                     ,CEMIDC1;18-1-2025
#SAMPLE MASS /mg:            ,43.4
#MATERIAL:                   ,Geopolymer paste
#REFERENCE:                  ,blank
#REFERENCE MASS /mg:         ,0
#TYPE OF CRUCIBLE:           ,DSC/TG pan Al2O3
#SAMPLE CRUCIBLE MASS /mg:   ,0
#REFERENCE CRUCIBLE MASS /mg:,0
#CORR. CODE:                 ,020
#EXO:                        ,-1
#RANGE:                      ,40/10.0(K/min)/1000
#SEGMENT:                    ,S2/2

##Temp./øC,Time/min,DSC/(mW/mg),Mass/%,Gas Flow(purge1)/(ml/min),Gas Flow(purge2)/(ml/min),Gas Flow(protective)/(ml/min),DTG/(%/min),Sensit./(uV/mW)
 39.56600, 15.03000, 3.8093e-002,98.17086,50.00000,0.0000e+000,20.00000,-4.0503e-002,1.22754
 39.59800, 15.21000, 3.8137e-002,98.15564,50.00000,0.0000e+000,20.00000,-8.3115e-002,1.22750
 39.63700, 15.39000, 3.8254e-002,98.13931,50.00000,0.0000e+000,20.00000,-8.8388e-002,1.22744
 39.73200, 15.57000, 3.8530e-002,98.12229,50.00000,0.0000e+000,20.00000,-9.1742e-002,1.22731
 39.85400, 15.75000, 3.9194e-002,98.10534,50.00000,0.0000e+000,20.00000,-9.4143e-002,1.22714
 40.01100, 15.93000, 4.0304e-002,98.08817,50.00000,0.0000e+000,20.00000,-9.4807e-002,1.22693
 40.26800, 16.11000, 4.1720e-002,98.06996,50.00000,0.0000e+000,20.00000,-9.5137e-002,1.22657
 40.56900, 16.29000, 4.3914e-002,98.05154,50.00000,0.0000e+000,20.00000,-9.7340e-002,1.22616
 40.95500, 16.47000, 4.6687e-002,98.03334,50.00000,0.0000e+000,20.00000,-9.9923e-002,1.22563
 41.43000, 16.65000, 4.9926e-002,98.01514,50.00000,0.0000e+000,20.00000,    -0.10281,1.22497
 41.98800, 16.83000, 5.3777e-002,97.99800,50.00000,0.0000e+000,20.00000,    -0.10686,1.22420
 42.62300, 17.01000, 5.7954e-002,97.98114,50.00000,0.0000e+000,20.00000,    -0.11211,1.22333
 43.33400, 17.19000, 6.2977e-002,97.96338,50.00000,0.0000e+000,20.00000,    -0.11737,1.22235
 44.17100, 17.37000, 6.7988e-002,97.94414,50.00000,0.0000e+000,20.00000,    -0.12323,1.22119
 45.03700, 17.55000, 7.3242e-002,97.92376,50.00000,0.0000e+000,20.00000,    -0.13005,1.22000
 46.00400, 17.73000, 7.9164e-002,97.90297,50.00000,0.0000e+000,20.00000,    -0.13783,1.21867
 47.06900, 17.91000, 8.5196e-002,97.88140,50.00000,0.0000e+000,20.00000,    -0.14640,1.21720
 48.21400, 18.09000, 9.1713e-002,97.85862,50.00000,0.0000e+000,20.00000,    -0.15632,1.21562
 49.42700, 18.27000, 9.8384e-002,97.83595,50.00000,0.0000e+000,20.00000,    -0.16864,1.21395
 50.72800, 18.45000,     0.10527,97.81257,50.00000,0.0000e+000,20.00000,    -0.18339,1.21216
 52.11800, 18.63000,     0.11263,97.78510,50.00000,0.0000e+000,20.00000,    -0.20101,1.21024
 53.58400, 18.81000,     0.12015,97.75341,50.00000,0.0000e+000,20.00000,    -0.22062,1.20823
 55.11800, 18.99000,     0.12813,97.71850,50.00000,0.0000e+000,20.00000,    -0.24153,1.20612
 56.70400, 19.17000,     0.13645,97.68056,50.00000,0.0000e+000,20.00000,    -0.26500,1.20393
 58.40300, 19.35000,     0.14532,97.63923,50.00000,0.0000e+000,20.00000,    -0.29226,1.20160
 60.13800, 19.53000,     0.15470,97.59429,50.00000,0.0000e+000,20.00000,    -0.32527,1.19921
 61.95200, 19.71000,     0.16435,97.54553,50.00000,0.0000e+000,20.00000,    -0.36116,1.19672
 63.84500, 19.89000,     0.17505,97.49180,50.00000,0.0000e+000,20.00000,    -0.39983,1.19412
 65.79000, 20.07000,     0.18687,97.43005,50.00000,0.0000e+000,20.00000,    -0.44160,1.19145
 67.80900, 20.25000,     0.19928,97.35921,50.00000,0.0000e+000,20.00000,    -0.48728,1.18868
 69.85000, 20.43000,     0.21250,97.27893,50.00000,0.0000e+000,20.00000,    -0.53715,1.18588
 71.95000, 20.61000,     0.22713,97.19118,50.00000,0.0000e+000,20.00000,    -0.59057,1.18300
 74.12000, 20.79000,     0.24292,97.09834,50.00000,0.0000e+000,20.00000,    -0.64797,1.18003
 76.30600, 20.97000,     0.25968,96.99552,50.00000,0.0000e+000,20.00000,    -0.70932,1.17704
 78.53500, 21.15000,     0.27837,96.87829,50.00000,0.0000e+000,20.00000,    -0.77280,1.17399
 80.82000, 21.33000,     0.29812,96.74009,50.00000,0.0000e+000,20.00000,    -0.83785,1.17087
 83.13000, 21.51000,     0.31962,96.58864,50.00000,0.0000e+000,20.00000,    -0.90339,1.16771
 85.47900, 21.69000,     0.34266,96.42656,50.00000,0.0000e+000,20.00000,    -0.96894,1.16451
 87.85700, 21.87000,     0.36731,96.25300,50.00000,0.0000e+000,20.00000,    -1.03323,1.16127
 90.25400, 22.05000,     0.39356,96.06555,50.00000,0.0000e+000,20.00000,    -1.09490,1.15801
 92.68000, 22.23000,     0.42128,95.85947,50.00000,0.0000e+000,20.00000,    -1.15458,1.15471
 95.13000, 22.41000,     0.45073,95.63563,50.00000,0.0000e+000,20.00000,    -1.21400,1.15138
 97.58500, 22.59000,     0.48151,95.39424,50.00000,0.0000e+000,20.00000,    -1.27551,1.14805
100.06200, 22.77000,     0.51327,95.13489,50.00000,0.0000e+000,20.00000,    -1.33876,1.14469
102.53000, 22.95000,     0.54484,94.86349,50.00000,0.0000e+000,20.00000,    -1.40174,1.14135
104.99300, 23.13000,     0.57592,94.58263,50.00000,0.0000e+000,20.00000,    -1.46241,1.13802
107.47000, 23.31000,     0.60459,94.29560,50.00000,0.0000e+000,20.00000,    -1.52078,1.13467
109.94200, 23.49000,     0.62971,94.00392,50.00000,0.0000e+000,20.00000,    -1.57598,1.13134
112.39000, 23.67000,     0.65047,93.70877,50.00000,0.0000e+000,20.00000,    -1.62515,1.12804
114.85800, 23.85000,     0.66750,93.41379,50.00000,0.0000e+000,20.00000,    -1.66440,1.12472
117.30600, 24.03000,     0.68420,93.11751,50.00000,0.0000e+000,20.00000,    -1.68832,1.12143
119.75500, 24.21000,     0.70451,92.81487,50.00000,0.0000e+000,20.00000,    -1.69565,1.11815
122.20900, 24.39000,     0.72771,92.50043,50.00000,0.0000e+000,20.00000,    -1.68884,1.11486
124.66500, 24.57000,     0.75300,92.17057,50.00000,0.0000e+000,20.00000,    -1.67082,1.11158
127.08400, 24.75000,     0.77902,91.82743,50.00000,0.0000e+000,20.00000,    -1.64523,1.10835
129.52000, 24.93000,     0.80462,91.47260,50.00000,0.0000e+000,20.00000,    -1.61353,1.10510
131.94099, 25.11000,     0.82717,91.10938,50.00000,0.0000e+000,20.00000,    -1.57677,1.10188
134.35600, 25.29000,     0.84380,90.74679,50.00000,0.0000e+000,20.00000,    -1.53652,1.09867
136.75000, 25.47000,     0.84976,90.39290,50.00000,0.0000e+000,20.00000,    -1.49272,1.09550
139.12300, 25.65000,     0.83944,90.05987,50.00000,0.0000e+000,20.00000,    -1.44779,1.09236
141.50999, 25.83000,     0.81381,89.76285,50.00000,0.0000e+000,20.00000,    -1.40048,1.08920
143.88800, 26.01000,     0.77391,89.50864,50.00000,0.0000e+000,20.00000,    -1.35047,1.08606
146.25800, 26.19000,     0.72168,89.29042,50.00000,0.0000e+000,20.00000,    -1.29641,1.08294
148.61099, 26.37000,     0.66737,89.09672,50.00000,0.0000e+000,20.00000,    -1.23630,1.07985
150.96800, 26.55000,     0.61556,88.91835,50.00000,0.0000e+000,20.00000,    -1.17258,1.07676
153.30499, 26.73000,     0.56743,88.75275,50.00000,0.0000e+000,20.00000,    -1.10611,1.07370
155.63100, 26.91000,     0.52336,88.59924,50.00000,0.0000e+000,20.00000,    -1.03472,1.07065
157.93300, 27.09000,     0.48344,88.45429,50.00000,0.0000e+000,20.00000,    -0.96113,1.06765
160.21899, 27.27000,     0.44719,88.31809,50.00000,0.0000e+000,20.00000,    -0.88880,1.06467
162.47200, 27.45000,     0.41462,88.18689,50.00000,0.0000e+000,20.00000,    -0.82104,1.06174
164.70100, 27.63000,     0.38510,88.06250,50.00000,0.0000e+000,20.00000,    -0.76181,1.05885
166.91800, 27.81000,     0.35828,87.94380,50.00000,0.0000e+000,20.00000,    -0.71338,1.05598
169.10001, 27.99000,     0.33405,87.82798,50.00000,0.0000e+000,20.00000,    -0.67458,1.05316
171.25900, 28.17000,     0.31149,87.71955,50.00000,0.0000e+000,20.00000,    -0.64230,1.05038
173.39101, 28.35000,     0.29081,87.61162,50.00000,0.0000e+000,20.00000,    -0.61373,1.04763
175.49400, 28.53000,     0.27092,87.50117,50.00000,0.0000e+000,20.00000,    -0.58743,1.04493
177.59900, 28.71000,     0.25211,87.39800,50.00000,0.0000e+000,20.00000,    -0.56329,1.04223
179.67500, 28.89000,     0.23398,87.30307,50.00000,0.0000e+000,20.00000,    -0.54107,1.03958
181.71300, 29.07000,     0.21681,87.21135,50.00000,0.0000e+000,20.00000,    -0.52148,1.03697
183.73199, 29.25000,     0.20060,87.12141,50.00000,0.0000e+000,20.00000,    -0.50228,1.03440
185.74899, 29.43000,     0.18526,87.03418,50.00000,0.0000e+000,20.00000,    -0.48397,1.03183
187.75101, 29.61000,     0.17123,86.95014,50.00000,0.0000e+000,20.00000,    -0.46732,1.02929
189.72600, 29.79000,     0.15809,86.86854,50.00000,0.0000e+000,20.00000,    -0.45034,1.02679
191.67500, 29.97000,     0.14502,86.78948,50.00000,0.0000e+000,20.00000,    -0.43424,1.02432
193.60100, 30.15000,     0.13241,86.71295,50.00000,0.0000e+000,20.00000,    -0.41851,1.02189
195.53000, 30.33000,     0.11971,86.64079,50.00000,0.0000e+000,20.00000,    -0.40192,1.01946
197.42900, 30.51000,     0.10747,86.57315,50.00000,0.0000e+000,20.00000,    -0.38667,1.01708
199.30600, 30.69000, 9.5491e-002,86.50849,50.00000,0.0000e+000,20.00000,    -0.37350,1.01472
201.17799, 30.87000, 8.3852e-002,86.44209,50.00000,0.0000e+000,20.00000,    -0.36098,1.01238
203.03999, 31.05000, 7.2802e-002,86.38013,50.00000,0.0000e+000,20.00000,    -0.34846,1.01005
204.88400, 31.23000, 6.2607e-002,86.32093,50.00000,0.0000e+000,20.00000,    -0.33640,1.00775
206.71899, 31.41000, 5.2154e-002,86.26256,50.00000,0.0000e+000,20.00000,    -0.32504,1.00547
208.53600, 31.59000, 4.2160e-002,86.20721,50.00000,0.0000e+000,20.00000,    -0.31418,1.00321
210.34900, 31.77000, 3.2701e-002,86.15635,50.00000,0.0000e+000,20.00000,    -0.30382,1.00097
212.13600, 31.95000, 2.3410e-002,86.10633,50.00000,0.0000e+000,20.00000,    -0.29375,0.99876
213.91701, 32.13000, 1.4729e-002,86.05643,50.00000,0.0000e+000,20.00000,    -0.28401,0.99656
215.70500, 32.31000, 6.1169e-003,86.00719,50.00000,0.0000e+000,20.00000,    -0.27529,0.99436
217.47200, 32.49000,-1.9667e-003,85.95932,50.00000,0.0000e+000,20.00000,    -0.26791,0.99218
219.23000, 32.67000,-1.0139e-002,85.91284,50.00000,0.0000e+000,20.00000,    -0.26043,0.99003
220.98399, 32.85000,-1.8008e-002,85.86808,50.00000,0.0000e+000,20.00000,    -0.25366,0.98788
222.74200, 33.03000,-2.6091e-002,85.82442,50.00000,0.0000e+000,20.00000,    -0.24703,0.98573
224.46899, 33.21000,-3.3599e-002,85.78128,50.00000,0.0000e+000,20.00000,    -0.24101,0.98363
226.21899, 33.39000,-4.1230e-002,85.73894,50.00000,0.0000e+000,20.00000,    -0.23554,0.98150
227.93300, 33.57000,-4.8838e-002,85.69722,50.00000,0.0000e+000,20.00000,    -0.23080,0.97942
229.67599, 33.75000,-5.6265e-002,85.65675,50.00000,0.0000e+000,20.00000,    -0.22621,0.97731
231.39999, 33.93000,-6.3055e-002,85.61901,50.00000,0.0000e+000,20.00000,    -0.22156,0.97522
233.14101, 34.11000,-7.0290e-002,85.58264,50.00000,0.0000e+000,20.00000,    -0.21723,0.97312
234.85500, 34.29000,-7.6848e-002,85.54516,50.00000,0.0000e+000,20.00000,    -0.21307,0.97106
236.56900, 34.47000,-8.3343e-002,85.50622,50.00000,0.0000e+000,20.00000,    -0.20966,0.96900
238.28000, 34.65000,-8.9391e-002,85.46775,50.00000,0.0000e+000,20.00000,    -0.20646,0.96695
240.00999, 34.83000,-9.5687e-002,85.43240,50.00000,0.0000e+000,20.00000,    -0.20318,0.96488
241.73199, 35.01000,    -0.10140,85.39613,50.00000,0.0000e+000,20.00000,    -0.19978,0.96283
243.43500, 35.19000,    -0.10744,85.35981,50.00000,0.0000e+000,20.00000,    -0.19648,0.96080
245.13600, 35.37000,    -0.11362,85.32549,50.00000,0.0000e+000,20.00000,    -0.19333,0.95878
246.86600, 35.55000,    -0.12002,85.29223,50.00000,0.0000e+000,20.00000,    -0.19038,0.95673
248.56700, 35.73000,    -0.12617,85.25928,50.00000,0.0000e+000,20.00000,    -0.18830,0.95472
250.27400, 35.91000,    -0.13177,85.22575,50.00000,0.0000e+000,20.00000,    -0.18660,0.95271
251.99300, 36.09000,    -0.13789,85.19286,50.00000,0.0000e+000,20.00000,    -0.18449,0.95068
253.70599, 36.27000,    -0.14354,85.15882,50.00000,0.0000e+000,20.00000,    -0.18180,0.94867
255.42599, 36.45000,    -0.14938,85.12514,50.00000,0.0000e+000,20.00000,    -0.17904,0.94666
257.13501, 36.63000,    -0.15535,85.09322,50.00000,0.0000e+000,20.00000,    -0.17691,0.94466
258.86200, 36.81000,    -0.16064,85.06229,50.00000,0.0000e+000,20.00000,    -0.17452,0.94265
260.60101, 36.99000,    -0.16613,85.03189,50.00000,0.0000e+000,20.00000,    -0.17201,0.94062
262.31201, 37.17000,    -0.17084,85.00150,50.00000,0.0000e+000,20.00000,    -0.17036,0.93864
264.04501, 37.35000,    -0.17590,84.97155,50.00000,0.0000e+000,20.00000,    -0.16891,0.93663
265.76199, 37.53000,    -0.18060,84.94107,50.00000,0.0000e+000,20.00000,    -0.16752,0.93465
267.50201, 37.71000,    -0.18553,84.91073,50.00000,0.0000e+000,20.00000,    -0.16604,0.93264
269.22601, 37.89000,    -0.18993,84.88120,50.00000,0.0000e+000,20.00000,    -0.16442,0.93066
270.96301, 38.07000,    -0.19459,84.85210,50.00000,0.0000e+000,20.00000,    -0.16233,0.92867
272.70200, 38.25000,    -0.19972,84.82346,50.00000,0.0000e+000,20.00000,    -0.16007,0.92669
274.42200, 38.43000,    -0.20434,84.79528,50.00000,0.0000e+000,20.00000,    -0.15855,0.92472
276.15302, 38.61000,    -0.20944,84.76808,50.00000,0.0000e+000,20.00000,    -0.15734,0.92275
277.90701, 38.79000,    -0.21417,84.74078,50.00000,0.0000e+000,20.00000,    -0.15664,0.92076
279.62299, 38.97000,    -0.21891,84.71233,50.00000,0.0000e+000,20.00000,    -0.15598,0.91882
281.37399, 39.15000,    -0.22343,84.68412,50.00000,0.0000e+000,20.00000,    -0.15491,0.91685
283.11700, 39.33000,    -0.22814,84.65637,50.00000,0.0000e+000,20.00000,    -0.15356,0.91488
284.85901, 39.51000,    -0.23236,84.62818,50.00000,0.0000e+000,20.00000,    -0.15223,0.91293
286.60199, 39.69000,    -0.23666,84.60102,50.00000,0.0000e+000,20.00000,    -0.15108,0.91098
288.35400, 39.87000,    -0.24094,84.57470,50.00000,0.0000e+000,20.00000,    -0.14985,0.90902
290.09698, 40.05000,    -0.24551,84.54905,50.00000,0.0000e+000,20.00000,    -0.14892,0.90708
291.84698, 40.23000,    -0.24947,84.52261,50.00000,0.0000e+000,20.00000,    -0.14809,0.90514
293.59399, 40.41000,    -0.25380,84.49598,50.00000,0.0000e+000,20.00000,    -0.14729,0.90320
295.35699, 40.59000,    -0.25823,84.46840,50.00000,0.0000e+000,20.00000,    -0.14627,0.90125
297.10101, 40.77000,    -0.26238,84.44017,50.00000,0.0000e+000,20.00000,    -0.14513,0.89933
298.86600, 40.95000,    -0.26696,84.41384,50.00000,0.0000e+000,20.00000,    -0.14426,0.89739
300.61600, 41.13000,    -0.27105,84.38842,50.00000,0.0000e+000,20.00000,    -0.14350,0.89548
302.35901, 41.31000,    -0.27566,84.36284,50.00000,0.0000e+000,20.00000,    -0.14223,0.89357
304.12601, 41.49000,    -0.28002,84.33730,50.00000,0.0000e+000,20.00000,    -0.14102,0.89165
305.89301, 41.67000,    -0.28426,84.31258,50.00000,0.0000e+000,20.00000,    -0.14015,0.88973
307.65701, 41.85000,    -0.28838,84.28743,50.00000,0.0000e+000,20.00000,    -0.13968,0.88782
309.41501, 42.03000,    -0.29241,84.26207,50.00000,0.0000e+000,20.00000,    -0.13925,0.88592
311.17001, 42.21000,    -0.29679,84.23752,50.00000,0.0000e+000,20.00000,    -0.13850,0.88403
312.93799, 42.39000,    -0.30084,84.21397,50.00000,0.0000e+000,20.00000,    -0.13737,0.88213
314.69901, 42.57000,    -0.30563,84.19006,50.00000,0.0000e+000,20.00000,    -0.13617,0.88024
316.46399, 42.75000,    -0.31039,84.16493,50.00000,0.0000e+000,20.00000,    -0.13567,0.87836
318.25000, 42.93000,    -0.31482,84.13988,50.00000,0.0000e+000,20.00000,    -0.13570,0.87646
320.01599, 43.11000,    -0.31822,84.11610,50.00000,0.0000e+000,20.00000,    -0.13572,0.87459
321.78400, 43.29000,    -0.32231,84.09317,50.00000,0.0000e+000,20.00000,    -0.13547,0.87271
323.56100, 43.47000,    -0.32607,84.07000,50.00000,0.0000e+000,20.00000,    -0.13507,0.87084
325.34399, 43.65000,    -0.32933,84.04619,50.00000,0.0000e+000,20.00000,    -0.13448,0.86897
327.10699, 43.83000,    -0.33270,84.02153,50.00000,0.0000e+000,20.00000,    -0.13409,0.86712
328.87900, 44.01000,    -0.33636,83.99737,50.00000,0.0000e+000,20.00000,    -0.13423,0.86527
330.66599, 44.19000,    -0.33996,83.97424,50.00000,0.0000e+000,20.00000,    -0.13480,0.86340
332.43701, 44.37000,    -0.34385,83.95038,50.00000,0.0000e+000,20.00000,    -0.13525,0.86156
334.21500, 44.55000,    -0.34734,83.92575,50.00000,0.0000e+000,20.00000,    -0.13548,0.85972
335.97601, 44.73000,    -0.35097,83.90025,50.00000,0.0000e+000,20.00000,    -0.13603,0.85791
337.76099, 44.91000,    -0.35437,83.87460,50.00000,0.0000e+000,20.00000,    -0.13729,0.85607
339.53699, 45.09000,    -0.35790,83.84970,50.00000,0.0000e+000,20.00000,    -0.13874,0.85425
341.31900, 45.27000,    -0.36077,83.82616,50.00000,0.0000e+000,20.00000,    -0.14034,0.85242
343.09500, 45.45000,    -0.36454,83.80331,50.00000,0.0000e+000,20.00000,    -0.14226,0.85061
344.87601, 45.63000,    -0.36761,83.77957,50.00000,0.0000e+000,20.00000,    -0.14339,0.84881
346.65701, 45.81000,    -0.37076,83.75451,50.00000,0.0000e+000,20.00000,    -0.14428,0.84700
348.43799, 45.99000,    -0.37317,83.72872,50.00000,0.0000e+000,20.00000,    -0.14581,0.84520
350.22400, 46.17000,    -0.37584,83.70336,50.00000,0.0000e+000,20.00000,    -0.14768,0.84341
352.00699, 46.35000,    -0.37850,83.67761,50.00000,0.0000e+000,20.00000,    -0.14910,0.84162
353.78500, 46.53000,    -0.38104,83.65077,50.00000,0.0000e+000,20.00000,    -0.15024,0.83984
355.56500, 46.71000,    -0.38380,83.62223,50.00000,0.0000e+000,20.00000,    -0.15085,0.83807
357.33401, 46.89000,    -0.38614,83.59386,50.00000,0.0000e+000,20.00000,    -0.15130,0.83631
359.12299, 47.07000,    -0.38913,83.56521,50.00000,0.0000e+000,20.00000,    -0.15216,0.83454
360.90601, 47.25000,    -0.39172,83.53456,50.00000,0.0000e+000,20.00000,    -0.15324,0.83278
362.67700, 47.43000,    -0.39468,83.50546,50.00000,0.0000e+000,20.00000,    -0.15401,0.83104
364.47400, 47.61000,    -0.39774,83.47789,50.00000,0.0000e+000,20.00000,    -0.15436,0.82928
366.26401, 47.79000,    -0.40083,83.44938,50.00000,0.0000e+000,20.00000,    -0.15468,0.82753
368.03699, 47.97000,    -0.40371,83.41895,50.00000,0.0000e+000,20.00000,    -0.15493,0.82581
369.81900, 48.15000,    -0.40654,83.38910,50.00000,0.0000e+000,20.00000,    -0.15504,0.82408
371.60001, 48.33000,    -0.40919,83.35952,50.00000,0.0000e+000,20.00000,    -0.15475,0.82236
373.38501, 48.51000,    -0.41249,83.33127,50.00000,0.0000e+000,20.00000,    -0.15386,0.82064
375.16901, 48.69000,    -0.41550,83.30451,50.00000,0.0000e+000,20.00000,    -0.15287,0.81893
376.95700, 48.87000,    -0.41921,83.27762,50.00000,0.0000e+000,20.00000,    -0.15168,0.81722
378.71799, 49.05000,    -0.42337,83.25082,50.00000,0.0000e+000,20.00000,    -0.14977,0.81554
380.51401, 49.23000,    -0.42763,83.22433,50.00000,0.0000e+000,20.00000,    -0.14808,0.81383
382.29599, 49.41000,    -0.43137,83.19831,50.00000,0.0000e+000,20.00000,    -0.14690,0.81215
384.07300, 49.59000,    -0.43580,83.17136,50.00000,0.0000e+000,20.00000,    -0.14564,0.81047
385.86700, 49.77000,    -0.43956,83.14500,50.00000,0.0000e+000,20.00000,    -0.14391,0.80878
387.63800, 49.95000,    -0.44431,83.11887,50.00000,0.0000e+000,20.00000,    -0.14204,0.80712
389.42001, 50.13000,    -0.44894,83.09326,50.00000,0.0000e+000,20.00000,    -0.13982,0.80546
391.18301, 50.31000,    -0.45371,83.06810,50.00000,0.0000e+000,20.00000,    -0.13760,0.80382
392.97501, 50.49000,    -0.45872,83.04317,50.00000,0.0000e+000,20.00000,    -0.13604,0.80216
394.75601, 50.67000,    -0.46353,83.01895,50.00000,0.0000e+000,20.00000,    -0.13468,0.80052
396.54300, 50.85000,    -0.46820,82.99544,50.00000,0.0000e+000,20.00000,    -0.13335,0.79887
398.32901, 51.03000,    -0.47278,82.97205,50.00000,0.0000e+000,20.00000,    -0.13206,0.79724
400.10999, 51.21000,    -0.47719,82.94881,50.00000,0.0000e+000,20.00000,    -0.13098,0.79561
401.91699, 51.39000,    -0.48144,82.92519,50.00000,0.0000e+000,20.00000,    -0.12948,0.79396
403.68900, 51.57000,    -0.48570,82.90131,50.00000,0.0000e+000,20.00000,    -0.12809,0.79236
405.48001, 51.75000,    -0.48994,82.87786,50.00000,0.0000e+000,20.00000,    -0.12739,0.79074
407.28601, 51.93000,    -0.49382,82.85620,50.00000,0.0000e+000,20.00000,    -0.12675,0.78912
409.06500, 52.11000,    -0.49810,82.83560,50.00000,0.0000e+000,20.00000,    -0.12618,0.78752
410.84900, 52.29000,    -0.50197,82.81469,50.00000,0.0000e+000,20.00000,    -0.12687,0.78593
412.63400, 52.47000,    -0.50599,82.79283,50.00000,0.0000e+000,20.00000,    -0.12853,0.78434
414.42700, 52.65000,    -0.50974,82.77087,50.00000,0.0000e+000,20.00000,    -0.13078,0.78275
416.22501, 52.83000,    -0.51320,82.74898,50.00000,0.0000e+000,20.00000,    -0.13430,0.78116
418.00500, 53.01000,    -0.51676,82.72693,50.00000,0.0000e+000,20.00000,    -0.13974,0.77959
419.79199, 53.19000,    -0.51999,82.70546,50.00000,0.0000e+000,20.00000,    -0.14664,0.77803
421.57800, 53.37000,    -0.52326,82.68418,50.00000,0.0000e+000,20.00000,    -0.15461,0.77647
423.36801, 53.55000,    -0.52646,82.66095,50.00000,0.0000e+000,20.00000,    -0.16413,0.77491
425.15500, 53.73000,    -0.52888,82.63729,50.00000,0.0000e+000,20.00000,    -0.17592,0.77336
426.92401, 53.91000,    -0.53038,82.61450,50.00000,0.0000e+000,20.00000,    -0.18827,0.77183
428.72000, 54.09000,    -0.52964,82.58776,50.00000,0.0000e+000,20.00000,    -0.20124,0.77029
430.50400, 54.27000,    -0.52589,82.55750,50.00000,0.0000e+000,20.00000,    -0.21531,0.76876
432.29199, 54.45000,    -0.51924,82.52607,50.00000,0.0000e+000,20.00000,    -0.23079,0.76724
434.07501, 54.63000,    -0.50886,82.49072,50.00000,0.0000e+000,20.00000,    -0.24725,0.76572
435.85901, 54.81000,    -0.49675,82.44864,50.00000,0.0000e+000,20.00000,    -0.26497,0.76421
437.64401, 54.99000,    -0.48305,82.40061,50.00000,0.0000e+000,20.00000,    -0.28402,0.76270
439.42300, 55.17000,    -0.46862,82.34820,50.00000,0.0000e+000,20.00000,    -0.30389,0.76121
441.19601, 55.35000,    -0.45345,82.29090,50.00000,0.0000e+000,20.00000,    -0.32508,0.75972
442.98001, 55.53000,    -0.43784,82.22652,50.00000,0.0000e+000,20.00000,    -0.34974,0.75824
444.75299, 55.71000,    -0.42164,82.16069,50.00000,0.0000e+000,20.00000,    -0.37499,0.75676
446.53000, 55.89000,    -0.40584,82.09312,50.00000,0.0000e+000,20.00000,    -0.39945,0.75529
448.30899, 56.07000,    -0.38954,82.02078,50.00000,0.0000e+000,20.00000,    -0.42553,0.75383
450.08301, 56.25000,    -0.37344,81.94296,50.00000,0.0000e+000,20.00000,    -0.45039,0.75237
451.87500, 56.43000,    -0.35631,81.86144,50.00000,0.0000e+000,20.00000,    -0.47736,0.75091
453.64099, 56.61000,    -0.33905,81.77541,50.00000,0.0000e+000,20.00000,    -0.50174,0.74947
455.42300, 56.79000,    -0.32180,81.68473,50.00000,0.0000e+000,20.00000,    -0.52578,0.74802
457.19800, 56.97000,    -0.30452,81.59134,50.00000,0.0000e+000,20.00000,    -0.54749,0.74659
458.97601, 57.15000,    -0.28673,81.49268,50.00000,0.0000e+000,20.00000,    -0.56787,0.74516
460.76901, 57.33000,    -0.26849,81.38053,50.00000,0.0000e+000,20.00000,    -0.58506,0.74372
462.54401, 57.51000,    -0.24939,81.26457,50.00000,0.0000e+000,20.00000,    -0.59990,0.74231
464.33701, 57.69000,    -0.23032,81.15081,50.00000,0.0000e+000,20.00000,    -0.61159,0.74088
466.11700, 57.87000,    -0.21174,81.02569,50.00000,0.0000e+000,20.00000,    -0.61449,0.73947
467.91299, 58.05000,    -0.19491,80.90408,50.00000,0.0000e+000,20.00000,    -0.60892,0.73806
469.69901, 58.23000,    -0.18027,80.77224,50.00000,0.0000e+000,20.00000,    -0.59709,0.73665
471.49200, 58.41000,    -0.16827,80.64153,50.00000,0.0000e+000,20.00000,    -0.58159,0.73525
473.27301, 58.59000,    -0.15851,80.50734,50.00000,0.0000e+000,20.00000,    -0.56407,0.73386
475.06100, 58.77000,    -0.15230,80.37502,50.00000,0.0000e+000,20.00000,    -0.54530,0.73248
476.85001, 58.95000,    -0.14987,80.24467,50.00000,0.0000e+000,20.00000,    -0.52513,0.73110
478.66000, 59.13000,    -0.15447,80.11680,50.00000,0.0000e+000,20.00000,    -0.50078,0.72970
480.47101, 59.31000,    -0.17099,79.99635,50.00000,0.0000e+000,20.00000,    -0.47386,0.72832
482.28101, 59.49000,    -0.20490,79.88339,50.00000,0.0000e+000,20.00000,    -0.44806,0.72694
484.08701, 59.67000,    -0.26283,79.79696,50.00000,0.0000e+000,20.00000,    -0.41934,0.72556
485.90100, 59.85000,    -0.34484,79.73671,50.00000,0.0000e+000,20.00000,    -0.39034,0.72419
487.70999, 60.03000,    -0.42743,79.69666,50.00000,0.0000e+000,20.00000,    -0.35859,0.72283
489.52100, 60.21000,    -0.48936,79.66730,50.00000,0.0000e+000,20.00000,    -0.32631,0.72147
491.33401, 60.39000,    -0.53425,79.64096,50.00000,0.0000e+000,20.00000,    -0.29376,0.72012
493.13300, 60.57000,    -0.56787,79.61639,50.00000,0.0000e+000,20.00000,    -0.26051,0.71878
494.97601, 60.75000,    -0.59375,79.59257,50.00000,0.0000e+000,20.00000,    -0.22778,0.71741
496.80200, 60.93000,    -0.61419,79.57109,50.00000,0.0000e+000,20.00000,    -0.19568,0.71607
498.62000, 61.11000,    -0.62842,79.55251,50.00000,0.0000e+000,20.00000,    -0.16599,0.71473
500.42899, 61.29000,    -0.63872,79.53426,50.00000,0.0000e+000,20.00000,    -0.13808,0.71341
502.21500, 61.47000,    -0.64693,79.51486,50.00000,0.0000e+000,20.00000,    -0.11678,0.71211
504.02301, 61.65000,    -0.65391,79.49843,50.00000,0.0000e+000,20.00000,    -0.10242,0.71080
505.81100, 61.83000,    -0.65973,79.48434,50.00000,0.0000e+000,20.00000,-9.3523e-002,0.70951
507.60599, 62.01000,    -0.66594,79.47067,50.00000,0.0000e+000,20.00000,-8.7137e-002,0.70822
509.41800, 62.19000,    -0.67102,79.45664,50.00000,0.0000e+000,20.00000,-8.2268e-002,0.70692
511.23499, 62.37000,    -0.67651,79.44416,50.00000,0.0000e+000,20.00000,-7.8460e-002,0.70563
513.04199, 62.55000,    -0.68104,79.43394,50.00000,0.0000e+000,20.00000,-7.4846e-002,0.70435
514.83698, 62.73000,    -0.68354,79.42232,50.00000,0.0000e+000,20.00000,-7.1527e-002,0.70308
516.63397, 62.91000,    -0.68567,79.40993,50.00000,0.0000e+000,20.00000,-6.8966e-002,0.70181
518.41602, 63.09000,    -0.68772,79.39668,50.00000,0.0000e+000,20.00000,-6.6567e-002,0.70057
520.19501, 63.27000,    -0.68899,79.38341,50.00000,0.0000e+000,20.00000,-6.4080e-002,0.69932
521.97198, 63.45000,    -0.69064,79.37178,50.00000,0.0000e+000,20.00000,-6.2198e-002,0.69809
523.74103, 63.63000,    -0.69304,79.36136,50.00000,0.0000e+000,20.00000,-6.1065e-002,0.69687
525.53998, 63.81000,    -0.69654,79.35404,50.00000,0.0000e+000,20.00000,-6.0060e-002,0.69563
527.32098, 63.99000,    -0.70040,79.34574,50.00000,0.0000e+000,20.00000,-5.8713e-002,0.69441
529.10498, 64.17000,    -0.70267,79.33499,50.00000,0.0000e+000,20.00000,-5.7389e-002,0.69319
530.88898, 64.35000,    -0.70489,79.32414,50.00000,0.0000e+000,20.00000,-5.6587e-002,0.69198
532.67700, 64.53000,    -0.70707,79.31421,50.00000,0.0000e+000,20.00000,-5.5979e-002,0.69077
534.45599, 64.71000,    -0.70932,79.30459,50.00000,0.0000e+000,20.00000,-5.5177e-002,0.68957
536.25598, 64.89000,    -0.71130,79.29534,50.00000,0.0000e+000,20.00000,-5.3947e-002,0.68836
538.03802, 65.07000,    -0.71389,79.28513,50.00000,0.0000e+000,20.00000,-5.2527e-002,0.68717
539.82703, 65.25000,    -0.71685,79.27487,50.00000,0.0000e+000,20.00000,-5.1565e-002,0.68598
541.62903, 65.43000,    -0.71961,79.26486,50.00000,0.0000e+000,20.00000,-5.0928e-002,0.68479
543.44397, 65.61000,    -0.72411,79.25469,50.00000,0.0000e+000,20.00000,-5.0887e-002,0.68359
545.25201, 65.79000,    -0.72784,79.24555,50.00000,0.0000e+000,20.00000,-5.1089e-002,0.68241
547.03400, 65.97000,    -0.73058,79.23721,50.00000,0.0000e+000,20.00000,-5.0608e-002,0.68124
548.84900, 66.15000,    -0.73224,79.22994,50.00000,0.0000e+000,20.00000,-5.0131e-002,0.68006
550.62903, 66.33000,    -0.73291,79.22105,50.00000,0.0000e+000,20.00000,-4.9985e-002,0.67891
552.41101, 66.51000,    -0.73312,79.21157,50.00000,0.0000e+000,20.00000,-4.9747e-002,0.67776
554.17798, 66.69000,    -0.73463,79.20286,50.00000,0.0000e+000,20.00000,-4.9667e-002,0.67662
555.97803, 66.87000,    -0.73724,79.19461,50.00000,0.0000e+000,20.00000,-4.9335e-002,0.67547
557.77502, 67.05000,    -0.74120,79.18631,50.00000,0.0000e+000,20.00000,-4.9032e-002,0.67433
559.59399, 67.23000,    -0.74558,79.17787,50.00000,0.0000e+000,20.00000,-4.8765e-002,0.67318
561.41699, 67.41000,    -0.74926,79.17024,50.00000,0.0000e+000,20.00000,-4.8191e-002,0.67203
563.22400, 67.59000,    -0.75186,79.16187,50.00000,0.0000e+000,20.00000,-4.7850e-002,0.67089
565.03101, 67.77000,    -0.75376,79.15303,50.00000,0.0000e+000,20.00000,-4.7159e-002,0.66976
566.85400, 67.95000,    -0.75494,79.14399,50.00000,0.0000e+000,20.00000,-4.7082e-002,0.66863
568.64398, 68.13000,    -0.75659,79.13440,50.00000,0.0000e+000,20.00000,-4.7089e-002,0.66752
570.43103, 68.31000,    -0.75670,79.12555,50.00000,0.0000e+000,20.00000,-4.6800e-002,0.66641
572.23499, 68.49000,    -0.75855,79.11661,50.00000,0.0000e+000,20.00000,-4.6152e-002,0.66531
574.03497, 68.67000,    -0.76097,79.10779,50.00000,0.0000e+000,20.00000,-4.6056e-002,0.66421
575.84601, 68.85000,    -0.76398,79.09863,50.00000,0.0000e+000,20.00000,-4.6422e-002,0.66310
577.65002, 69.03000,    -0.76620,79.08947,50.00000,0.0000e+000,20.00000,-4.6152e-002,0.66201
579.45801, 69.21000,    -0.76763,79.08130,50.00000,0.0000e+000,20.00000,-4.5823e-002,0.66092
581.25299, 69.39000,    -0.76877,79.07313,50.00000,0.0000e+000,20.00000,-4.5995e-002,0.65984
583.03900, 69.57000,    -0.76997,79.06687,50.00000,0.0000e+000,20.00000,-4.6354e-002,0.65877
584.85199, 69.75000,    -0.77110,79.06025,50.00000,0.0000e+000,20.00000,-4.6781e-002,0.65769
586.63501, 69.93000,    -0.77253,79.05176,50.00000,0.0000e+000,20.00000,-4.6909e-002,0.65663
588.42999, 70.11000,    -0.77394,79.04309,50.00000,0.0000e+000,20.00000,-4.7207e-002,0.65557
590.23499, 70.29000,    -0.77538,79.03642,50.00000,0.0000e+000,20.00000,-4.7626e-002,0.65451
592.02399, 70.47000,    -0.77670,79.02894,50.00000,0.0000e+000,20.00000,-4.8140e-002,0.65347
593.82703, 70.65000,    -0.77949,79.01934,50.00000,0.0000e+000,20.00000,-4.8465e-002,0.65241
595.62799, 70.83000,    -0.78187,79.01139,50.00000,0.0000e+000,20.00000,-4.8698e-002,0.65137
597.43500, 71.01000,    -0.78313,79.00506,50.00000,0.0000e+000,20.00000,-4.9372e-002,0.65033
599.22900, 71.19000,    -0.78405,78.99659,50.00000,0.0000e+000,20.00000,-5.0372e-002,0.64929
601.03003, 71.37000,    -0.78505,78.98652,50.00000,0.0000e+000,20.00000,-5.1926e-002,0.64826
602.82800, 71.55000,    -0.78608,78.97607,50.00000,0.0000e+000,20.00000,-5.3557e-002,0.64724
604.63300, 71.73000,    -0.78808,78.96586,50.00000,0.0000e+000,20.00000,-5.4707e-002,0.64621
606.43701, 71.91000,    -0.79031,78.95592,50.00000,0.0000e+000,20.00000,-5.5902e-002,0.64520
608.23602, 72.09000,    -0.79128,78.94552,50.00000,0.0000e+000,20.00000,-5.7656e-002,0.64418
610.03900, 72.27000,    -0.79277,78.93482,50.00000,0.0000e+000,20.00000,-5.9558e-002,0.64317
611.88098, 72.45000,    -0.79729,78.92446,50.00000,0.0000e+000,20.00000,-6.0650e-002,0.64215
613.74701, 72.63000,    -0.80047,78.91437,50.00000,0.0000e+000,20.00000,-6.1820e-002,0.64111
615.56897, 72.81000,    -0.80231,78.90382,50.00000,0.0000e+000,20.00000,-6.3608e-002,0.64010
617.38501, 72.99000,    -0.80175,78.89206,50.00000,0.0000e+000,20.00000,-6.5268e-002,0.63911
619.18597, 73.17000,    -0.80031,78.87982,50.00000,0.0000e+000,20.00000,-6.6710e-002,0.63812
620.96997, 73.35000,    -0.79820,78.86754,50.00000,0.0000e+000,20.00000,-6.7976e-002,0.63715
622.75299, 73.53000,    -0.79673,78.85511,50.00000,0.0000e+000,20.00000,-6.8950e-002,0.63618
624.54199, 73.71000,    -0.79709,78.84203,50.00000,0.0000e+000,20.00000,-7.0214e-002,0.63521
626.31500, 73.89000,    -0.79815,78.82870,50.00000,0.0000e+000,20.00000,-7.2016e-002,0.63426
628.14099, 74.07000,    -0.79927,78.81475,50.00000,0.0000e+000,20.00000,-7.3786e-002,0.63328
629.92102, 74.25000,    -0.79992,78.80110,50.00000,0.0000e+000,20.00000,-7.5392e-002,0.63233
631.71399, 74.43000,    -0.79990,78.78836,50.00000,0.0000e+000,20.00000,-7.7311e-002,0.63137
633.49298, 74.61000,    -0.79917,78.77566,50.00000,0.0000e+000,20.00000,-7.9468e-002,0.63043
635.27502, 74.79000,    -0.79922,78.76174,50.00000,0.0000e+000,20.00000,-8.1369e-002,0.62949
637.06097, 74.97000,    -0.79918,78.74658,50.00000,0.0000e+000,20.00000,-8.3349e-002,0.62856
638.85498, 75.15000,    -0.79956,78.73149,50.00000,0.0000e+000,20.00000,-8.5986e-002,0.62762
640.65302, 75.33000,    -0.80204,78.71740,50.00000,0.0000e+000,20.00000,-8.8683e-002,0.62668
642.44202, 75.51000,    -0.80233,78.70325,50.00000,0.0000e+000,20.00000,-9.0651e-002,0.62576
644.24103, 75.69000,    -0.80372,78.68657,50.00000,0.0000e+000,20.00000,-9.2583e-002,0.62483
646.07001, 75.87000,    -0.80639,78.66932,50.00000,0.0000e+000,20.00000,-9.4781e-002,0.62389
647.89801, 76.05000,    -0.80797,78.65295,50.00000,0.0000e+000,20.00000,-9.7409e-002,0.62295
649.72400, 76.23000,    -0.80768,78.63605,50.00000,0.0000e+000,20.00000,    -0.10040,0.62202
651.53198, 76.41000,    -0.80749,78.61788,50.00000,0.0000e+000,20.00000,    -0.10347,0.62111
653.33502, 76.59000,    -0.80666,78.59932,50.00000,0.0000e+000,20.00000,    -0.10635,0.62020
655.14099, 76.77000,    -0.80588,78.58023,50.00000,0.0000e+000,20.00000,    -0.10896,0.61929
656.94397, 76.95000,    -0.80530,78.55857,50.00000,0.0000e+000,20.00000,    -0.11171,0.61839
658.72699, 77.13000,    -0.80429,78.53619,50.00000,0.0000e+000,20.00000,    -0.11491,0.61750
660.53198, 77.31000,    -0.80466,78.51575,50.00000,0.0000e+000,20.00000,    -0.11811,0.61660
662.33301, 77.49000,    -0.80540,78.49557,50.00000,0.0000e+000,20.00000,    -0.12034,0.61571
664.14301, 77.67000,    -0.80554,78.47395,50.00000,0.0000e+000,20.00000,    -0.12198,0.61482
665.96100, 77.85000,    -0.80505,78.45072,50.00000,0.0000e+000,20.00000,    -0.12425,0.61393
667.74500, 78.03000,    -0.80441,78.42693,50.00000,0.0000e+000,20.00000,    -0.12640,0.61306
669.52399, 78.21000,    -0.80337,78.40314,50.00000,0.0000e+000,20.00000,    -0.12804,0.61219
671.31702, 78.39000,    -0.80247,78.37898,50.00000,0.0000e+000,20.00000,    -0.12970,0.61132
673.09100, 78.57000,    -0.80195,78.35443,50.00000,0.0000e+000,20.00000,    -0.13141,0.61047
674.86603, 78.75000,    -0.80079,78.32941,50.00000,0.0000e+000,20.00000,    -0.13225,0.60962
676.64899, 78.93000,    -0.80183,78.30342,50.00000,0.0000e+000,20.00000,    -0.13268,0.60876
678.41901, 79.11000,    -0.80398,78.27774,50.00000,0.0000e+000,20.00000,    -0.13380,0.60792
680.23999, 79.29000,    -0.80701,78.25301,50.00000,0.0000e+000,20.00000,    -0.13557,0.60705
682.06598, 79.47000,    -0.81161,78.22966,50.00000,0.0000e+000,20.00000,    -0.13723,0.60619
683.87000, 79.65000,    -0.81464,78.20515,50.00000,0.0000e+000,20.00000,    -0.13797,0.60534
685.69501, 79.83000,    -0.81739,78.18040,50.00000,0.0000e+000,20.00000,    -0.13824,0.60449
687.51202, 80.01000,    -0.81970,78.15642,50.00000,0.0000e+000,20.00000,    -0.13903,0.60364
689.34003, 80.19000,    -0.82287,78.13191,50.00000,0.0000e+000,20.00000,    -0.14045,0.60279
691.16998, 80.37000,    -0.82541,78.10681,50.00000,0.0000e+000,20.00000,    -0.14181,0.60194
692.97101, 80.55000,    -0.82462,78.08229,50.00000,0.0000e+000,20.00000,    -0.14283,0.60111
694.76801, 80.73000,    -0.82499,78.05827,50.00000,0.0000e+000,20.00000,    -0.14392,0.60028
696.57098, 80.91000,    -0.82636,78.03363,50.00000,0.0000e+000,20.00000,    -0.14516,0.59945
698.42603, 81.09000,    -0.83088,78.00735,50.00000,0.0000e+000,20.00000,    -0.14654,0.59861
700.25598, 81.27000,    -0.83236,77.97996,50.00000,0.0000e+000,20.00000,    -0.14867,0.59778
702.05200, 81.45000,    -0.82937,77.95384,50.00000,0.0000e+000,20.00000,    -0.15079,0.59696
703.84100, 81.63000,    -0.82583,77.92915,50.00000,0.0000e+000,20.00000,    -0.15250,0.59616
705.63300, 81.81000,    -0.82323,77.90290,50.00000,0.0000e+000,20.00000,    -0.15464,0.59535
707.43298, 81.99000,    -0.82204,77.87393,50.00000,0.0000e+000,20.00000,    -0.15676,0.59455
709.21997, 82.17000,    -0.82136,77.84429,50.00000,0.0000e+000,20.00000,    -0.15885,0.59375
711.02100, 82.35000,    -0.82075,77.81569,50.00000,0.0000e+000,20.00000,    -0.16138,0.59295
712.82501, 82.53000,    -0.81930,77.78601,50.00000,0.0000e+000,20.00000,    -0.16416,0.59215
714.63202, 82.71000,    -0.81963,77.75566,50.00000,0.0000e+000,20.00000,    -0.16634,0.59136
716.42297, 82.89000,    -0.81829,77.72569,50.00000,0.0000e+000,20.00000,    -0.16783,0.59057
718.21399, 83.07000,    -0.81636,77.69473,50.00000,0.0000e+000,20.00000,    -0.16907,0.58978
720.00500, 83.25000,    -0.81568,77.66264,50.00000,0.0000e+000,20.00000,    -0.17006,0.58900
721.82202, 83.43000,    -0.81705,77.63150,50.00000,0.0000e+000,20.00000,    -0.17062,0.58821
723.62097, 83.61000,    -0.81867,77.59979,50.00000,0.0000e+000,20.00000,    -0.16981,0.58744
725.43597, 83.79000,    -0.81907,77.56765,50.00000,0.0000e+000,20.00000,    -0.16672,0.58665
727.31201, 83.97000,    -0.82320,77.53514,50.00000,0.0000e+000,20.00000,    -0.16193,0.58585
729.14697, 84.15000,    -0.82488,77.50137,50.00000,0.0000e+000,20.00000,    -0.15711,0.58506
730.97198, 84.33000,    -0.82282,77.46710,50.00000,0.0000e+000,20.00000,    -0.15162,0.58428
732.74103, 84.51000,    -0.81848,77.43429,50.00000,0.0000e+000,20.00000,    -0.14553,0.58353
734.53101, 84.69000,    -0.81557,77.40295,50.00000,0.0000e+000,20.00000,    -0.13911,0.58277
736.30298, 84.87000,    -0.81456,77.37099,50.00000,0.0000e+000,20.00000,    -0.13225,0.58202
738.05701, 85.05000,    -0.81690,77.34047,50.00000,0.0000e+000,20.00000,    -0.12553,0.58129
739.84698, 85.23000,    -0.82422,77.31321,50.00000,0.0000e+000,20.00000,    -0.11909,0.58053
741.65997, 85.41000,    -0.83591,77.28961,50.00000,0.0000e+000,20.00000,    -0.11255,0.57978
743.47101, 85.59000,    -0.84866,77.27133,50.00000,0.0000e+000,20.00000,    -0.10586,0.57902
745.29199, 85.77000,    -0.85798,77.25864,50.00000,0.0000e+000,20.00000,-9.8416e-002,0.57827
747.09399, 85.95000,    -0.86307,77.24744,50.00000,0.0000e+000,20.00000,-9.0342e-002,0.57752
748.90802, 86.13000,    -0.86529,77.23778,50.00000,0.0000e+000,20.00000,-8.2894e-002,0.57677
750.72601, 86.31000,    -0.86693,77.22955,50.00000,0.0000e+000,20.00000,-7.6042e-002,0.57603
752.55298, 86.49000,    -0.86812,77.22264,50.00000,0.0000e+000,20.00000,-6.9279e-002,0.57528
754.34302, 86.67000,    -0.86668,77.21721,50.00000,0.0000e+000,20.00000,-6.1635e-002,0.57455
756.14398, 86.85000,    -0.86629,77.20989,50.00000,0.0000e+000,20.00000,-5.4769e-002,0.57381
757.94397, 87.03000,    -0.86785,77.20214,50.00000,0.0000e+000,20.00000,-4.8893e-002,0.57308
759.75897, 87.21000,    -0.86955,77.19449,50.00000,0.0000e+000,20.00000,-4.3514e-002,0.57235
761.57001, 87.39000,    -0.86999,77.18677,50.00000,0.0000e+000,20.00000,-4.0205e-002,0.57162
763.35999, 87.57000,    -0.87034,77.18101,50.00000,0.0000e+000,20.00000,-3.8715e-002,0.57090
765.16199, 87.75000,    -0.87064,77.17724,50.00000,0.0000e+000,20.00000,-3.7539e-002,0.57018
766.95898, 87.93000,    -0.87069,77.17050,50.00000,0.0000e+000,20.00000,-3.6685e-002,0.56946
768.74103, 88.11000,    -0.87147,77.16245,50.00000,0.0000e+000,20.00000,-3.6473e-002,0.56875
770.52502, 88.29000,    -0.87302,77.15533,50.00000,0.0000e+000,20.00000,-3.6462e-002,0.56804
772.32397, 88.47000,    -0.87517,77.15122,50.00000,0.0000e+000,20.00000,-3.7159e-002,0.56733
774.13898, 88.65000,    -0.87730,77.14581,50.00000,0.0000e+000,20.00000,-3.7333e-002,0.56661
775.92700, 88.83000,    -0.87964,77.13925,50.00000,0.0000e+000,20.00000,-3.7189e-002,0.56591
777.71399, 89.01000,    -0.88088,77.13470,50.00000,0.0000e+000,20.00000,-3.7289e-002,0.56521
779.48700, 89.19000,    -0.88225,77.12798,50.00000,0.0000e+000,20.00000,-3.7367e-002,0.56451
781.27802, 89.37000,    -0.88281,77.12006,50.00000,0.0000e+000,20.00000,-3.7777e-002,0.56381
783.06702, 89.55000,    -0.88674,77.11292,50.00000,0.0000e+000,20.00000,-3.8974e-002,0.56312
784.88000, 89.73000,    -0.89135,77.10613,50.00000,0.0000e+000,20.00000,-3.9199e-002,0.56241
786.71899, 89.91000,    -0.89533,77.09864,50.00000,0.0000e+000,20.00000,-3.9231e-002,0.56170
788.53302, 90.09000,    -0.89911,77.09135,50.00000,0.0000e+000,20.00000,-3.9603e-002,0.56100
790.36401, 90.27000,    -0.90250,77.08356,50.00000,0.0000e+000,20.00000,-4.0860e-002,0.56029
792.17700, 90.45000,    -0.90561,77.07576,50.00000,0.0000e+000,20.00000,-4.2012e-002,0.55960
793.99200, 90.63000,    -0.90758,77.06850,50.00000,0.0000e+000,20.00000,-4.2787e-002,0.55890
795.79102, 90.81000,    -0.90990,77.06067,50.00000,0.0000e+000,20.00000,-4.3930e-002,0.55822
797.60797, 90.99000,    -0.91279,77.05251,50.00000,0.0000e+000,20.00000,-4.4696e-002,0.55752
799.40503, 91.17000,    -0.91580,77.04479,50.00000,0.0000e+000,20.00000,-4.4887e-002,0.55684
801.21002, 91.35000,    -0.91816,77.03669,50.00000,0.0000e+000,20.00000,-4.4881e-002,0.55616
803.01300, 91.53000,    -0.92030,77.02948,50.00000,0.0000e+000,20.00000,-4.4834e-002,0.55547
804.79797, 91.71000,    -0.92161,77.02164,50.00000,0.0000e+000,20.00000,-4.4732e-002,0.55480
806.58502, 91.89000,    -0.92283,77.01284,50.00000,0.0000e+000,20.00000,-4.4793e-002,0.55413
808.37097, 92.07000,    -0.92531,77.00382,50.00000,0.0000e+000,20.00000,-4.4954e-002,0.55346
810.18298, 92.25000,    -0.92896,76.99471,50.00000,0.0000e+000,20.00000,-4.5016e-002,0.55278
812.02100, 92.43000,    -0.93365,76.98517,50.00000,0.0000e+000,20.00000,-4.5334e-002,0.55209
813.86401, 92.61000,    -0.93988,76.97618,50.00000,0.0000e+000,20.00000,-4.5746e-002,0.55140
815.68597, 92.79000,    -0.94302,76.96722,50.00000,0.0000e+000,20.00000,-4.6138e-002,0.55073
817.50299, 92.97000,    -0.94366,76.95840,50.00000,0.0000e+000,20.00000,-4.6420e-002,0.55005
819.29700, 93.15000,    -0.94528,76.95096,50.00000,0.0000e+000,20.00000,-4.6329e-002,0.54939
821.11902, 93.33000,    -0.94785,76.94434,50.00000,0.0000e+000,20.00000,-4.6557e-002,0.54871
822.94501, 93.51000,    -0.95200,76.93741,50.00000,0.0000e+000,20.00000,-4.7028e-002,0.54804
824.75897, 93.69000,    -0.95371,76.92995,50.00000,0.0000e+000,20.00000,-4.7119e-002,0.54737
826.58197, 93.87000,    -0.95623,76.92173,50.00000,0.0000e+000,20.00000,-4.6922e-002,0.54670
828.39600, 94.05000,    -0.95929,76.91365,50.00000,0.0000e+000,20.00000,-4.6409e-002,0.54604
830.19598, 94.23000,    -0.96167,76.90521,50.00000,0.0000e+000,20.00000,-4.5550e-002,0.54538
831.99103, 94.41000,    -0.96131,76.89623,50.00000,0.0000e+000,20.00000,-4.5435e-002,0.54473
833.77002, 94.59000,    -0.96149,76.88648,50.00000,0.0000e+000,20.00000,-4.5421e-002,0.54408
835.53900, 94.77000,    -0.96266,76.87761,50.00000,0.0000e+000,20.00000,-4.4964e-002,0.54343
837.34399, 94.95000,    -0.96667,76.86972,50.00000,0.0000e+000,20.00000,-4.4795e-002,0.54278
839.18597, 95.13000,    -0.97302,76.86175,50.00000,0.0000e+000,20.00000,-4.5099e-002,0.54211
841.01898, 95.31000,    -0.97681,76.85246,50.00000,0.0000e+000,20.00000,-4.5644e-002,0.54145
842.83099, 95.49000,    -0.97763,76.84334,50.00000,0.0000e+000,20.00000,-4.6076e-002,0.54079
844.63397, 95.67000,    -0.98007,76.83489,50.00000,0.0000e+000,20.00000,-4.6081e-002,0.54014
846.46002, 95.85000,    -0.98453,76.82751,50.00000,0.0000e+000,20.00000,-4.5744e-002,0.53949
848.27698, 96.03000,    -0.98722,76.82122,50.00000,0.0000e+000,20.00000,-4.4854e-002,0.53883
850.05499, 96.21000,    -0.98721,76.81288,50.00000,0.0000e+000,20.00000,-4.4592e-002,0.53820
851.82501, 96.39000,    -0.98619,76.80385,50.00000,0.0000e+000,20.00000,-4.4096e-002,0.53756
853.59198, 96.57000,    -0.98653,76.79638,50.00000,0.0000e+000,20.00000,-4.3444e-002,0.53693
855.36902, 96.75000,    -0.98907,76.78941,50.00000,0.0000e+000,20.00000,-4.2361e-002,0.53630
857.15900, 96.93000,    -0.99238,76.78175,50.00000,0.0000e+000,20.00000,-4.1481e-002,0.53566
858.97198, 97.11000,    -0.99545,76.77309,50.00000,0.0000e+000,20.00000,-4.0271e-002,0.53501
860.77698, 97.29000,    -0.99754,76.76407,50.00000,0.0000e+000,20.00000,-3.9067e-002,0.53437
862.59198, 97.47000,    -1.00065,76.75575,50.00000,0.0000e+000,20.00000,-3.8316e-002,0.53373
864.38300, 97.65000,    -1.00280,76.74859,50.00000,0.0000e+000,20.00000,-3.7852e-002,0.53309
866.16302, 97.83000,    -1.00520,76.74346,50.00000,0.0000e+000,20.00000,-3.7338e-002,0.53246
867.96698, 98.01000,    -1.00658,76.73602,50.00000,0.0000e+000,20.00000,-3.6364e-002,0.53183
869.76501, 98.19000,    -1.00877,76.72789,50.00000,0.0000e+000,20.00000,-3.5423e-002,0.53119
871.60101, 98.37000,    -1.01328,76.72099,50.00000,0.0000e+000,20.00000,-3.4767e-002,0.53054
873.42999, 98.55000,    -1.01630,76.71659,50.00000,0.0000e+000,20.00000,-3.4263e-002,0.52990
875.22198, 98.73000,    -1.01665,76.71225,50.00000,0.0000e+000,20.00000,-3.3320e-002,0.52927
877.04700, 98.91000,    -1.02025,76.70735,50.00000,0.0000e+000,20.00000,-3.1995e-002,0.52863
878.91199, 99.09000,    -1.02541,76.70277,50.00000,0.0000e+000,20.00000,-3.0825e-002,0.52797
880.75598, 99.27000,    -1.03030,76.69698,50.00000,0.0000e+000,20.00000,-3.0164e-002,0.52733
882.55603, 99.45000,    -1.03076,76.69105,50.00000,0.0000e+000,20.00000,-2.9651e-002,0.52670
884.32001, 99.63000,    -1.02786,76.68631,50.00000,0.0000e+000,20.00000,-2.9534e-002,0.52608
886.08002, 99.81000,    -1.02675,76.68220,50.00000,0.0000e+000,20.00000,-2.8919e-002,0.52547
887.87799, 99.99000,    -1.02815,76.67653,50.00000,0.0000e+000,20.00000,-2.7756e-002,0.52484
889.66699,100.17000,    -1.03118,76.67116,50.00000,0.0000e+000,20.00000,-2.6835e-002,0.52421
891.49701,100.35000,    -1.03405,76.66603,50.00000,0.0000e+000,20.00000,-2.6663e-002,0.52358
893.29303,100.53000,    -1.03707,76.66172,50.00000,0.0000e+000,20.00000,-2.6617e-002,0.52295
895.10400,100.71000,    -1.03970,76.65815,50.00000,0.0000e+000,20.00000,-2.6479e-002,0.52232
896.88599,100.89000,    -1.04198,76.65357,50.00000,0.0000e+000,20.00000,-2.6782e-002,0.52170
898.67798,101.07000,    -1.04407,76.64766,50.00000,0.0000e+000,20.00000,-2.6834e-002,0.52108
900.46198,101.25000,    -1.04659,76.64195,50.00000,0.0000e+000,20.00000,-2.6513e-002,0.52046
902.27100,101.43000,    -1.05043,76.63702,50.00000,0.0000e+000,20.00000,-2.5919e-002,0.51983
904.07098,101.61000,    -1.05426,76.63236,50.00000,0.0000e+000,20.00000,-2.5138e-002,0.51921
905.90802,101.79000,    -1.05990,76.62814,50.00000,0.0000e+000,20.00000,-2.4311e-002,0.51857
907.71997,101.97000,    -1.06322,76.62448,50.00000,0.0000e+000,20.00000,-2.3608e-002,0.51794
909.53198,102.15000,    -1.06756,76.62029,50.00000,0.0000e+000,20.00000,-2.3045e-002,0.51732
911.34003,102.33000,    -1.07137,76.61635,50.00000,0.0000e+000,20.00000,-2.2721e-002,0.51669
913.17999,102.51000,    -1.07600,76.61202,50.00000,0.0000e+000,20.00000,-2.2784e-002,0.51606
914.98199,102.69000,    -1.07805,76.60655,50.00000,0.0000e+000,20.00000,-2.2547e-002,0.51543
916.77301,102.87000,    -1.07927,76.60070,50.00000,0.0000e+000,20.00000,-2.1790e-002,0.51482
918.57300,103.05000,    -1.08119,76.59562,50.00000,0.0000e+000,20.00000,-2.0619e-002,0.51419
920.39398,103.23000,    -1.08587,76.59246,50.00000,0.0000e+000,20.00000,-1.9660e-002,0.51357
922.18201,103.41000,    -1.09067,76.59128,50.00000,0.0000e+000,20.00000,-1.8202e-002,0.51295
923.98999,103.59000,    -1.09327,76.58900,50.00000,0.0000e+000,20.00000,-1.6287e-002,0.51233
925.85199,103.77000,    -1.10137,76.58614,50.00000,0.0000e+000,20.00000,-1.5173e-002,0.51168
927.71503,103.95000,    -1.10926,76.58300,50.00000,0.0000e+000,20.00000,-1.4984e-002,0.51104
929.54303,104.13000,    -1.11321,76.57983,50.00000,0.0000e+000,20.00000,-1.4942e-002,0.51041
931.37299,104.31000,    -1.11659,76.57599,50.00000,0.0000e+000,20.00000,-1.4443e-002,0.50978
933.16998,104.49000,    -1.11663,76.57250,50.00000,0.0000e+000,20.00000,-1.3404e-002,0.50916
934.95502,104.67000,    -1.11743,76.56930,50.00000,0.0000e+000,20.00000,-1.1666e-002,0.50855
936.75500,104.85000,    -1.11910,76.56764,50.00000,0.0000e+000,20.00000,-1.0088e-002,0.50793
938.53003,105.03000,    -1.12142,76.56603,50.00000,0.0000e+000,20.00000,-9.7928e-003,0.50732
940.31702,105.21000,    -1.12230,76.56627,50.00000,0.0000e+000,20.00000,-9.8853e-003,0.50670
942.08801,105.39000,    -1.12490,76.56876,50.00000,0.0000e+000,20.00000,-9.6004e-003,0.50609
943.86700,105.57000,    -1.12825,76.56988,50.00000,0.0000e+000,20.00000,-9.1288e-003,0.50548
945.64203,105.75000,    -1.13038,76.56678,50.00000,0.0000e+000,20.00000,-8.3242e-003,0.50487
947.41699,105.93000,    -1.13175,76.56288,50.00000,0.0000e+000,20.00000,-7.8686e-003,0.50426
949.20697,106.11000,    -1.13551,76.56019,50.00000,0.0000e+000,20.00000,-7.4414e-003,0.50364
950.96301,106.29000,    -1.13603,76.55864,50.00000,0.0000e+000,20.00000,-6.6861e-003,0.50304
952.78400,106.47000,    -1.14182,76.55872,50.00000,0.0000e+000,20.00000,-5.4731e-003,0.50241
954.62299,106.65000,    -1.15160,76.55952,50.00000,0.0000e+000,20.00000,-4.9830e-003,0.50178
956.43500,106.83000,    -1.15549,76.55748,50.00000,0.0000e+000,20.00000,-5.3278e-003,0.50115
958.22498,107.01000,    -1.15786,76.55542,50.00000,0.0000e+000,20.00000,-5.9363e-003,0.50054
960.03198,107.19000,    -1.15980,76.55454,50.00000,0.0000e+000,20.00000,-7.0740e-003,0.49991
961.87299,107.37000,    -1.16472,76.55334,50.00000,0.0000e+000,20.00000,-8.1804e-003,0.49928
963.67499,107.55000,    -1.16751,76.55306,50.00000,0.0000e+000,20.00000,-7.8348e-003,0.49866
965.48401,107.73000,    -1.16951,76.55197,50.00000,0.0000e+000,20.00000,-6.7720e-003,0.49803
967.30103,107.91000,    -1.17222,76.54964,50.00000,0.0000e+000,20.00000,-6.1220e-003,0.49741
969.12097,108.09000,    -1.17271,76.54858,50.00000,0.0000e+000,20.00000,-6.1540e-003,0.49678
970.92200,108.27000,    -1.17464,76.54947,50.00000,0.0000e+000,20.00000,-6.4958e-003,0.49616
972.73602,108.45000,    -1.17580,76.54990,50.00000,0.0000e+000,20.00000,-6.9670e-003,0.49553
974.52197,108.63000,    -1.17603,76.54724,50.00000,0.0000e+000,20.00000,-6.3756e-003,0.49491
976.31000,108.81000,    -1.17586,76.54463,50.00000,0.0000e+000,20.00000,-5.5830e-003,0.49430
978.09998,108.99000,    -1.17502,76.54282,50.00000,0.0000e+000,20.00000,-5.4372e-003,0.49368
979.90997,109.17000,    -1.17673,76.54042,50.00000,0.0000e+000,20.00000,-5.9682e-003,0.49305
981.74902,109.35000,    -1.18018,76.53887,50.00000,0.0000e+000,20.00000,-6.8959e-003,0.49241
983.55701,109.53000,    -1.18343,76.53867,50.00000,0.0000e+000,20.00000,-6.4609e-003,0.49179
985.36401,109.71000,    -1.18383,76.53830,50.00000,0.0000e+000,20.00000,-7.9135e-003,0.49116
987.15698,109.89000,    -1.18189,76.53661,50.00000,0.0000e+000,20.00000,-6.9662e-003,0.49054
988.95801,110.07000,    -1.17988,76.53506,50.00000,0.0000e+000,20.00000,-6.0921e-003,0.48991
990.76501,110.25000,    -1.18157,76.53403,50.00000,0.0000e+000,20.00000,-5.9862e-003,0.48929
992.57001,110.43000,    -1.18244,76.53455,50.00000,0.0000e+000,20.00000,-6.4372e-003,0.48866
994.36102,110.61000,    -1.18204,76.53512,50.00000,0.0000e+000,20.00000,-5.6345e-003,0.48804
996.16602,110.79000,    -1.18284,76.53496,50.00000,0.0000e+000,20.00000,-1.2365e-002,0.48741
997.98199,110.97000,    -1.18283,76.53375,50.00000,0.0000e+000,20.00000,-5.8227e-002,0.48678
998.32300,111.00500,    -1.18344,76.52995,50.00000,0.0000e+000,20.00000,    -0.23654,0.48666