File: book/some_content/TG_ExpDat_OPC9%D28; 13-1-2025-2.csv
#FILE:                       ,OPC9%D28; 13-1-2025.ngb-ds3
#FORMAT:                     ,NETZSCH5
#IDENTITY:                   ,Geopolymer paste
#DECIMAL:                    ,POINT
#SEPARATOR:                  ,COMMA
#MTYPE:                      ,DSC
#INSTRUMENT:                 ,Microlab TU Delft
#PROJECT:                    ,
#DATE/TIME:                  ,14/01/2025 11:19:12 AM
#CORR. FILE:                 ,Blank with cover; 13-1-2025.ngb-bs3
#LABORATORY:                 ,TU Delft Micro Lab
#OPERATOR:                   ,Ahmed
#REMARK:                     ,under Argon atmosphere, 10K/min
#SAMPLE:                     ,OPC9%D28;13-1-2025
#SAMPLE MASS /mg:            ,36
#MATERIAL:                   ,Geopolymer paste
#REFERENCE:                  ,blank
#REFERENCE MASS /mg:         ,0
#TYPE OF CRUCIBLE:           ,DSC/TG pan Al2O3
#SAMPLE CRUCIBLE MASS /mg:   ,0
#REFERENCE CRUCIBLE MASS /mg:,0
#CORR. CODE:                 ,020
#EXO:                        ,-1
#RANGE:                      ,40/10.0(K/min)/1000
#SEGMENT:                    ,S2/2

##Temp./øC,Time/min,DSC/(mW/mg),Mass/%,Gas Flow(purge1)/(ml/min),Gas Flow(purge2)/(ml/min),Gas Flow(protective)/(ml/min),DTG/(%/min),Sensit./(uV/mW)
 40.06200, 14.99917, 7.4883e-002,97.34722,50.00000,0.0000e+000,20.00000,    -0.47362,1.22686
 40.10700, 15.17917, 7.4749e-002,97.30961,50.00000,0.0000e+000,20.00000,    -0.18977,1.22679
 40.16600, 15.35917, 7.4805e-002,97.27804,50.00000,0.0000e+000,20.00000,    -0.19122,1.22671
 40.24600, 15.53917, 7.4864e-002,97.24419,50.00000,0.0000e+000,20.00000,    -0.19361,1.22660
 40.36900, 15.71917, 7.5306e-002,97.20864,50.00000,0.0000e+000,20.00000,    -0.19569,1.22643
 40.52500, 15.89917, 7.6650e-002,97.17262,50.00000,0.0000e+000,20.00000,    -0.19705,1.22622
 40.77200, 16.07917, 7.8193e-002,97.13724,50.00000,0.0000e+000,20.00000,    -0.19972,1.22588
 41.07000, 16.25917, 8.0519e-002,97.10123,50.00000,0.0000e+000,20.00000,    -0.20238,1.22547
 41.43400, 16.43917, 8.3424e-002,97.06454,50.00000,0.0000e+000,20.00000,    -0.20776,1.22496
 41.89200, 16.61917, 8.6877e-002,97.02788,50.00000,0.0000e+000,20.00000,    -0.21309,1.22433
 42.43900, 16.79917, 9.1278e-002,96.99167,50.00000,0.0000e+000,20.00000,    -0.22093,1.22358
 43.06900, 16.97917, 9.5988e-002,96.95510,50.00000,0.0000e+000,20.00000,    -0.22873,1.22271
 43.75800, 17.15917,     0.10153,96.91490,50.00000,0.0000e+000,20.00000,    -0.23847,1.22176
 44.54700, 17.33917,     0.10771,96.87625,50.00000,0.0000e+000,20.00000,    -0.24978,1.22067
 45.42600, 17.51917,     0.11411,96.83630,50.00000,0.0000e+000,20.00000,    -0.26251,1.21946
 46.36500, 17.69917,     0.12121,96.79261,50.00000,0.0000e+000,20.00000,    -0.27674,1.21817
 47.38000, 17.87917,     0.12875,96.74794,50.00000,0.0000e+000,20.00000,    -0.29489,1.21677
 48.51200, 18.05917,     0.13687,96.70270,50.00000,0.0000e+000,20.00000,    -0.31649,1.21521
 49.69200, 18.23917,     0.14547,96.65585,50.00000,0.0000e+000,20.00000,    -0.33933,1.21358
 50.96800, 18.41917,     0.15472,96.60703,50.00000,0.0000e+000,20.00000,    -0.36466,1.21183
 52.33800, 18.59917,     0.16500,96.55080,50.00000,0.0000e+000,20.00000,    -0.39601,1.20994
 53.76400, 18.77917,     0.17528,96.48817,50.00000,0.0000e+000,20.00000,    -0.43011,1.20798
 55.28000, 18.95917,     0.18689,96.42211,50.00000,0.0000e+000,20.00000,    -0.46715,1.20589
 56.85400, 19.13917,     0.19916,96.34847,50.00000,0.0000e+000,20.00000,    -0.51073,1.20373
 58.51800, 19.31917,     0.21268,96.26754,50.00000,0.0000e+000,20.00000,    -0.55928,1.20144
 60.23400, 19.49917,     0.22741,96.18070,50.00000,0.0000e+000,20.00000,    -0.61130,1.19908
 62.04700, 19.67917,     0.24271,96.08156,50.00000,0.0000e+000,20.00000,    -0.66814,1.19659
 63.90700, 19.85917,     0.26016,95.96787,50.00000,0.0000e+000,20.00000,    -0.73155,1.19403
 65.79100, 20.03917,     0.27869,95.84876,50.00000,0.0000e+000,20.00000,    -0.80008,1.19145
 67.78400, 20.21917,     0.29912,95.72141,50.00000,0.0000e+000,20.00000,    -0.87453,1.18871
 69.80400, 20.39917,     0.32175,95.57426,50.00000,0.0000e+000,20.00000,    -0.95326,1.18594
 71.88700, 20.57917,     0.34621,95.41346,50.00000,0.0000e+000,20.00000,    -1.03716,1.18309
 74.01000, 20.75917,     0.37265,95.24246,50.00000,0.0000e+000,20.00000,    -1.12820,1.18018
 76.16600, 20.93917,     0.40195,95.04666,50.00000,0.0000e+000,20.00000,    -1.22602,1.17723
 78.36700, 21.11917,     0.43379,94.83293,50.00000,0.0000e+000,20.00000,    -1.32899,1.17422
 80.62400, 21.29917,     0.46715,94.60178,50.00000,0.0000e+000,20.00000,    -1.43670,1.17114
 82.88800, 21.47917,     0.50338,94.35293,50.00000,0.0000e+000,20.00000,    -1.54768,1.16804
 85.21100, 21.65917,     0.54232,94.07960,50.00000,0.0000e+000,20.00000,    -1.66048,1.16488
 87.56900, 21.83917,     0.58284,93.78563,50.00000,0.0000e+000,20.00000,    -1.77626,1.16166
 89.93500, 22.01917,     0.62561,93.46886,50.00000,0.0000e+000,20.00000,    -1.89411,1.15844
 92.33800, 22.19917,     0.66921,93.12967,50.00000,0.0000e+000,20.00000,    -2.01308,1.15517
 94.75300, 22.37917,     0.71371,92.76533,50.00000,0.0000e+000,20.00000,    -2.13013,1.15189
 97.17000, 22.55917,     0.75873,92.37192,50.00000,0.0000e+000,20.00000,    -2.24599,1.14861
 99.59500, 22.73917,     0.80458,91.94676,50.00000,0.0000e+000,20.00000,    -2.35426,1.14532
102.03400, 22.91917,     0.85094,91.49408,50.00000,0.0000e+000,20.00000,    -2.45251,1.14202
104.48400, 23.09917,     0.89721,91.01808,50.00000,0.0000e+000,20.00000,    -2.53725,1.13871
106.93500, 23.27917,     0.94354,90.51944,50.00000,0.0000e+000,20.00000,    -2.60454,1.13539
109.41400, 23.45917,     0.98842,89.99787,50.00000,0.0000e+000,20.00000,    -2.64540,1.13205
111.86900, 23.63917,     1.03234,89.45893,50.00000,0.0000e+000,20.00000,    -2.65979,1.12874
114.31900, 23.81917,     1.07383,88.90490,50.00000,0.0000e+000,20.00000,    -2.65048,1.12545
116.76700, 23.99917,     1.11133,88.33018,50.00000,0.0000e+000,20.00000,    -2.62174,1.12216
119.20300, 24.17917,     1.14380,87.74218,50.00000,0.0000e+000,20.00000,    -2.57638,1.11889
121.65900, 24.35917,     1.17199,87.15190,50.00000,0.0000e+000,20.00000,    -2.51353,1.11560
124.10000, 24.53917,     1.19690,86.56178,50.00000,0.0000e+000,20.00000,    -2.43895,1.11234
126.52300, 24.71917,     1.21126,85.98818,50.00000,0.0000e+000,20.00000,    -2.35156,1.10910
128.97501, 24.89917,     1.20472,85.44411,50.00000,0.0000e+000,20.00000,    -2.25407,1.10583
131.39999, 25.07917,     1.17196,84.94367,50.00000,0.0000e+000,20.00000,    -2.14991,1.10260
133.83600, 25.25917,     1.11049,84.51261,50.00000,0.0000e+000,20.00000,    -2.03886,1.09936
136.26300, 25.43917,     1.02433,84.15820,50.00000,0.0000e+000,20.00000,    -1.92110,1.09614
138.68401, 25.61917,     0.92449,83.87021,50.00000,0.0000e+000,20.00000,    -1.79762,1.09294
141.11600, 25.79917,     0.82280,83.63317,50.00000,0.0000e+000,20.00000,    -1.66810,1.08972
143.56100, 25.97917,     0.72563,83.43336,50.00000,0.0000e+000,20.00000,    -1.53449,1.08650
145.97600, 26.15917,     0.63654,83.26983,50.00000,0.0000e+000,20.00000,    -1.39988,1.08331
148.41400, 26.33917,     0.55747,83.12134,50.00000,0.0000e+000,20.00000,    -1.26456,1.08011
150.82001, 26.51917,     0.48793,82.98806,50.00000,0.0000e+000,20.00000,    -1.13342,1.07695
153.20599, 26.69917,     0.42742,82.87114,50.00000,0.0000e+000,20.00000,    -1.00899,1.07382
155.55400, 26.87917,     0.37512,82.75668,50.00000,0.0000e+000,20.00000,    -0.89278,1.07076
157.89400, 27.05917,     0.33047,82.64354,50.00000,0.0000e+000,20.00000,    -0.79291,1.06770
160.19400, 27.23917,     0.29220,82.53642,50.00000,0.0000e+000,20.00000,    -0.71250,1.06471
162.48300, 27.41917,     0.26029,82.43533,50.00000,0.0000e+000,20.00000,    -0.64984,1.06173
164.74001, 27.59917,     0.23422,82.33748,50.00000,0.0000e+000,20.00000,    -0.60285,1.05880
166.95399, 27.77917,     0.21423,82.23870,50.00000,0.0000e+000,20.00000,    -0.56273,1.05594
169.15500, 27.95917,     0.19895,82.14052,50.00000,0.0000e+000,20.00000,    -0.53204,1.05309
171.32100, 28.13917,     0.18550,82.04418,50.00000,0.0000e+000,20.00000,    -0.50627,1.05030
173.45200, 28.31917,     0.17220,81.94648,50.00000,0.0000e+000,20.00000,    -0.48294,1.04755
175.56500, 28.49917,     0.15663,81.85097,50.00000,0.0000e+000,20.00000,    -0.46471,1.04484
177.66800, 28.67917,     0.13912,81.76542,50.00000,0.0000e+000,20.00000,    -0.44702,1.04214
179.69901, 28.85917,     0.12081,81.68708,50.00000,0.0000e+000,20.00000,    -0.42992,1.03954
181.75700, 29.03917,     0.10258,81.61400,50.00000,0.0000e+000,20.00000,    -0.41294,1.03692
183.75400, 29.21917, 8.4618e-002,81.54627,50.00000,0.0000e+000,20.00000,    -0.39686,1.03437
185.77699, 29.39917, 6.7411e-002,81.47379,50.00000,0.0000e+000,20.00000,    -0.38214,1.03180
187.72900, 29.57917, 5.1246e-002,81.41320,50.00000,0.0000e+000,20.00000,    -0.36614,1.02932
189.68700, 29.75917, 3.5581e-002,81.35717,50.00000,0.0000e+000,20.00000,    -0.34967,1.02684
191.62199, 29.93917, 2.1288e-002,81.30139,50.00000,0.0000e+000,20.00000,    -0.33402,1.02439
193.56500, 30.11917, 8.0877e-003,81.24962,50.00000,0.0000e+000,20.00000,    -0.31797,1.02194
195.45900, 30.29917,-4.5938e-003,81.19791,50.00000,0.0000e+000,20.00000,    -0.30145,1.01955
197.33000, 30.47917,-1.6459e-002,81.14803,50.00000,0.0000e+000,20.00000,    -0.28707,1.01720
199.20500, 30.65917,-2.7690e-002,81.09686,50.00000,0.0000e+000,20.00000,    -0.27446,1.01485
201.06799, 30.83917,-3.8366e-002,81.04962,50.00000,0.0000e+000,20.00000,    -0.26262,1.01252
202.89101, 31.01917,-4.8816e-002,81.00670,50.00000,0.0000e+000,20.00000,    -0.25264,1.01024
204.73100, 31.19917,-5.8409e-002,80.96225,50.00000,0.0000e+000,20.00000,    -0.24032,1.00794
206.55400, 31.37917,-6.7982e-002,80.92152,50.00000,0.0000e+000,20.00000,    -0.23037,1.00568
208.36301, 31.55917,-7.7491e-002,80.88319,50.00000,0.0000e+000,20.00000,    -0.22279,1.00343
210.14799, 31.73917,-8.6954e-002,80.84413,50.00000,0.0000e+000,20.00000,    -0.21519,1.00122
211.91800, 31.91917,-9.5948e-002,80.80501,50.00000,0.0000e+000,20.00000,    -0.20874,0.99903
213.73199, 32.09917,    -0.10497,80.76874,50.00000,0.0000e+000,20.00000,    -0.20139,0.99679
215.46800, 32.27917,    -0.11369,80.73370,50.00000,0.0000e+000,20.00000,    -0.19490,0.99465
217.23300, 32.45917,    -0.12244,80.70062,50.00000,0.0000e+000,20.00000,    -0.18749,0.99248
218.98900, 32.63917,    -0.13120,80.66941,50.00000,0.0000e+000,20.00000,    -0.18074,0.99032
220.73300, 32.81917,    -0.13983,80.63817,50.00000,0.0000e+000,20.00000,    -0.17626,0.98819
222.46700, 32.99917,    -0.14827,80.61013,50.00000,0.0000e+000,20.00000,    -0.17095,0.98607
224.19299, 33.17916,    -0.15671,80.58386,50.00000,0.0000e+000,20.00000,    -0.16676,0.98396
225.92799, 33.35917,    -0.16506,80.55596,50.00000,0.0000e+000,20.00000,    -0.16287,0.98185
227.67000, 33.53917,    -0.17314,80.52744,50.00000,0.0000e+000,20.00000,    -0.15833,0.97974
229.37100, 33.71917,    -0.18078,80.49877,50.00000,0.0000e+000,20.00000,    -0.15441,0.97768
231.11000, 33.89917,    -0.18852,80.47334,50.00000,0.0000e+000,20.00000,    -0.15077,0.97557
232.81700, 34.07917,    -0.19603,80.44741,50.00000,0.0000e+000,20.00000,    -0.14737,0.97351
234.54601, 34.25917,    -0.20322,80.42279,50.00000,0.0000e+000,20.00000,    -0.14395,0.97143
236.25999, 34.43917,    -0.21038,80.39961,50.00000,0.0000e+000,20.00000,    -0.14091,0.96937
237.97200, 34.61917,    -0.21720,80.37321,50.00000,0.0000e+000,20.00000,    -0.13804,0.96732
239.67400, 34.79917,    -0.22425,80.34787,50.00000,0.0000e+000,20.00000,    -0.13631,0.96528
241.40300, 34.97917,    -0.23089,80.32204,50.00000,0.0000e+000,20.00000,    -0.13542,0.96322
243.11000, 35.15917,    -0.23731,80.29714,50.00000,0.0000e+000,20.00000,    -0.13319,0.96119
244.81900, 35.33917,    -0.24367,80.27509,50.00000,0.0000e+000,20.00000,    -0.13037,0.95916
246.53000, 35.51917,    -0.25063,80.25025,50.00000,0.0000e+000,20.00000,    -0.12807,0.95713
248.23500, 35.69917,    -0.25650,80.22662,50.00000,0.0000e+000,20.00000,    -0.12729,0.95511
249.95100, 35.87917,    -0.26301,80.20371,50.00000,0.0000e+000,20.00000,    -0.12634,0.95309
251.65199, 36.05917,    -0.26900,80.18251,50.00000,0.0000e+000,20.00000,    -0.12492,0.95108
253.36900, 36.23917,    -0.27564,80.16221,50.00000,0.0000e+000,20.00000,    -0.12402,0.94907
255.09599, 36.41917,    -0.28140,80.14160,50.00000,0.0000e+000,20.00000,    -0.12257,0.94704
256.81601, 36.59917,    -0.28738,80.11945,50.00000,0.0000e+000,20.00000,    -0.12140,0.94503
258.53799, 36.77917,    -0.29319,80.09640,50.00000,0.0000e+000,20.00000,    -0.12048,0.94302
260.26001, 36.95917,    -0.29885,80.07619,50.00000,0.0000e+000,20.00000,    -0.11961,0.94102
261.99799, 37.13917,    -0.30401,80.05822,50.00000,0.0000e+000,20.00000,    -0.11948,0.93900
263.72699, 37.31917,    -0.30952,80.03826,50.00000,0.0000e+000,20.00000,    -0.11940,0.93700
265.44400, 37.49917,    -0.31508,80.01542,50.00000,0.0000e+000,20.00000,    -0.11947,0.93502
267.17300, 37.67916,    -0.31986,79.99291,50.00000,0.0000e+000,20.00000,    -0.11957,0.93302
268.91199, 37.85917,    -0.32483,79.97269,50.00000,0.0000e+000,20.00000,    -0.11994,0.93102
270.64600, 38.03917,    -0.33015,79.95312,50.00000,0.0000e+000,20.00000,    -0.12022,0.92904
272.38901, 38.21917,    -0.33463,79.93254,50.00000,0.0000e+000,20.00000,    -0.12082,0.92704
274.10501, 38.39917,    -0.33969,79.91116,50.00000,0.0000e+000,20.00000,    -0.12164,0.92508
275.86301, 38.57917,    -0.34445,79.88927,50.00000,0.0000e+000,20.00000,    -0.12159,0.92308
277.58801, 38.75917,    -0.34893,79.86674,50.00000,0.0000e+000,20.00000,    -0.12240,0.92113
279.34601, 38.93917,    -0.35354,79.84531,50.00000,0.0000e+000,20.00000,    -0.12434,0.91914
281.07501, 39.11917,    -0.35849,79.82153,50.00000,0.0000e+000,20.00000,    -0.12588,0.91718
282.80801, 39.29917,    -0.36227,79.79702,50.00000,0.0000e+000,20.00000,    -0.12739,0.91523
284.54001, 39.47917,    -0.36580,79.77370,50.00000,0.0000e+000,20.00000,    -0.12851,0.91329
286.29099, 39.65917,    -0.36982,79.75064,50.00000,0.0000e+000,20.00000,    -0.13021,0.91133
288.02600, 39.83917,    -0.37429,79.72915,50.00000,0.0000e+000,20.00000,    -0.13279,0.90939
289.77100, 40.01917,    -0.37848,79.70689,50.00000,0.0000e+000,20.00000,    -0.13496,0.90744
291.52399, 40.19917,    -0.38274,79.68210,50.00000,0.0000e+000,20.00000,    -0.13637,0.90549
293.27200, 40.37917,    -0.38726,79.65883,50.00000,0.0000e+000,20.00000,    -0.13745,0.90356
295.01801, 40.55917,    -0.39136,79.63550,50.00000,0.0000e+000,20.00000,    -0.13905,0.90163
296.76599, 40.73917,    -0.39516,79.61031,50.00000,0.0000e+000,20.00000,    -0.14122,0.89970
298.51199, 40.91917,    -0.39896,79.58545,50.00000,0.0000e+000,20.00000,    -0.14299,0.89778
300.27600, 41.09917,    -0.40325,79.55773,50.00000,0.0000e+000,20.00000,    -0.14477,0.89585
302.03201, 41.27917,    -0.40779,79.53044,50.00000,0.0000e+000,20.00000,    -0.14645,0.89393
303.80399, 41.45917,    -0.41188,79.50407,50.00000,0.0000e+000,20.00000,    -0.14854,0.89200
305.56601, 41.63917,    -0.41717,79.47524,50.00000,0.0000e+000,20.00000,    -0.15200,0.89008
307.35599, 41.81917,    -0.42119,79.44668,50.00000,0.0000e+000,20.00000,    -0.15555,0.88814
309.12500, 41.99917,    -0.42396,79.41989,50.00000,0.0000e+000,20.00000,    -0.15830,0.88623
310.91101, 42.17916,    -0.42697,79.39441,50.00000,0.0000e+000,20.00000,    -0.16120,0.88431
312.68799, 42.35917,    -0.42952,79.36632,50.00000,0.0000e+000,20.00000,    -0.16526,0.88240
314.46899, 42.53917,    -0.43185,79.33699,50.00000,0.0000e+000,20.00000,    -0.16881,0.88049
316.22198, 42.71917,    -0.43386,79.30736,50.00000,0.0000e+000,20.00000,    -0.17266,0.87862
318.01599, 42.89917,    -0.43623,79.27622,50.00000,0.0000e+000,20.00000,    -0.17602,0.87671
319.76801, 43.07917,    -0.43837,79.24642,50.00000,0.0000e+000,20.00000,    -0.17905,0.87485
321.54300, 43.25917,    -0.44033,79.21615,50.00000,0.0000e+000,20.00000,    -0.18234,0.87297
323.31601, 43.43917,    -0.44259,79.18214,50.00000,0.0000e+000,20.00000,    -0.18534,0.87110
325.09601, 43.61917,    -0.44447,79.14730,50.00000,0.0000e+000,20.00000,    -0.18830,0.86923
326.88400, 43.79917,    -0.44567,79.11247,50.00000,0.0000e+000,20.00000,    -0.19171,0.86735
328.65100, 43.97917,    -0.44743,79.07851,50.00000,0.0000e+000,20.00000,    -0.19534,0.86550
330.41800, 44.15917,    -0.44910,79.04110,50.00000,0.0000e+000,20.00000,    -0.19797,0.86366
332.20499, 44.33917,    -0.45144,79.00292,50.00000,0.0000e+000,20.00000,    -0.19944,0.86180
333.98999, 44.51917,    -0.45345,78.96431,50.00000,0.0000e+000,20.00000,    -0.20053,0.85996
335.76300, 44.69917,    -0.45597,78.92478,50.00000,0.0000e+000,20.00000,    -0.20197,0.85812
337.53201, 44.87917,    -0.45942,78.88580,50.00000,0.0000e+000,20.00000,    -0.20367,0.85630
339.31000, 45.05917,    -0.46298,78.84775,50.00000,0.0000e+000,20.00000,    -0.20416,0.85448
341.07599, 45.23917,    -0.46731,78.80837,50.00000,0.0000e+000,20.00000,    -0.20312,0.85267
342.85300, 45.41917,    -0.47264,78.76876,50.00000,0.0000e+000,20.00000,    -0.20181,0.85086
344.64301, 45.59917,    -0.47815,78.72913,50.00000,0.0000e+000,20.00000,    -0.20050,0.84904
346.41901, 45.77917,    -0.48459,78.69028,50.00000,0.0000e+000,20.00000,    -0.19879,0.84724
348.20901, 45.95917,    -0.49137,78.65273,50.00000,0.0000e+000,20.00000,    -0.19612,0.84543
349.97400, 46.13917,    -0.49899,78.61765,50.00000,0.0000e+000,20.00000,    -0.19352,0.84366
351.76099, 46.31917,    -0.50659,78.58425,50.00000,0.0000e+000,20.00000,    -0.19001,0.84187
353.55301, 46.49917,    -0.51396,78.54858,50.00000,0.0000e+000,20.00000,    -0.18505,0.84007
355.31400, 46.67916,    -0.52236,78.51161,50.00000,0.0000e+000,20.00000,    -0.18028,0.83832
357.09299, 46.85917,    -0.53081,78.47952,50.00000,0.0000e+000,20.00000,    -0.17594,0.83655
358.85599, 47.03917,    -0.53977,78.44949,50.00000,0.0000e+000,20.00000,    -0.17081,0.83481
360.65601, 47.21917,    -0.54883,78.41975,50.00000,0.0000e+000,20.00000,    -0.16475,0.83303
362.43600, 47.39917,    -0.55771,78.38929,50.00000,0.0000e+000,20.00000,    -0.15876,0.83128
364.19901, 47.57917,    -0.56613,78.36133,50.00000,0.0000e+000,20.00000,    -0.15309,0.82955
365.98199, 47.75917,    -0.57523,78.33443,50.00000,0.0000e+000,20.00000,    -0.14791,0.82781
367.75800, 47.93917,    -0.58331,78.30578,50.00000,0.0000e+000,20.00000,    -0.14293,0.82608
369.53601, 48.11917,    -0.59091,78.27928,50.00000,0.0000e+000,20.00000,    -0.13876,0.82435
371.32599, 48.29917,    -0.59885,78.25771,50.00000,0.0000e+000,20.00000,    -0.13432,0.82262
373.09299, 48.47917,    -0.60662,78.23609,50.00000,0.0000e+000,20.00000,    -0.12884,0.82092
374.87100, 48.65917,    -0.61399,78.21390,50.00000,0.0000e+000,20.00000,    -0.12483,0.81921
376.64700, 48.83917,    -0.62193,78.19306,50.00000,0.0000e+000,20.00000,    -0.12083,0.81751
378.43701, 49.01917,    -0.62908,78.17521,50.00000,0.0000e+000,20.00000,    -0.11654,0.81581
380.22800, 49.19917,    -0.63698,78.15769,50.00000,0.0000e+000,20.00000,    -0.11201,0.81410
382.00699, 49.37917,    -0.64461,78.13947,50.00000,0.0000e+000,20.00000,    -0.10804,0.81242
383.80801, 49.55917,    -0.65234,78.12049,50.00000,0.0000e+000,20.00000,    -0.10472,0.81072
385.58899, 49.73917,    -0.65917,78.10303,50.00000,0.0000e+000,20.00000,    -0.10111,0.80904
387.40500, 49.91917,    -0.66494,78.08515,50.00000,0.0000e+000,20.00000,-9.8147e-002,0.80734
389.18201, 50.09917,    -0.67015,78.06608,50.00000,0.0000e+000,20.00000,-9.6010e-002,0.80568
390.95599, 50.27917,    -0.67429,78.04874,50.00000,0.0000e+000,20.00000,-9.2600e-002,0.80403
392.72800, 50.45917,    -0.67927,78.03071,50.00000,0.0000e+000,20.00000,-8.9656e-002,0.80239
394.49799, 50.63917,    -0.68380,78.01450,50.00000,0.0000e+000,20.00000,-8.7963e-002,0.80075
396.27701, 50.81917,    -0.68921,78.00062,50.00000,0.0000e+000,20.00000,-8.7419e-002,0.79912
398.03299, 50.99917,    -0.69445,77.98653,50.00000,0.0000e+000,20.00000,-8.6907e-002,0.79751
399.80200, 51.17916,    -0.70074,77.97271,50.00000,0.0000e+000,20.00000,-8.7001e-002,0.79589
401.58200, 51.35917,    -0.70686,77.95816,50.00000,0.0000e+000,20.00000,-8.6590e-002,0.79427
403.38199, 51.53917,    -0.71316,77.94306,50.00000,0.0000e+000,20.00000,-8.6472e-002,0.79264
405.16101, 51.71917,    -0.71844,77.92674,50.00000,0.0000e+000,20.00000,-8.8086e-002,0.79103
406.95200, 51.89917,    -0.72452,77.91175,50.00000,0.0000e+000,20.00000,-9.0243e-002,0.78942
408.73901, 52.07917,    -0.73003,77.90235,50.00000,0.0000e+000,20.00000,-9.1598e-002,0.78781
410.54800, 52.25917,    -0.73571,77.89159,50.00000,0.0000e+000,20.00000,-9.3494e-002,0.78620
412.33801, 52.43917,    -0.74042,77.87706,50.00000,0.0000e+000,20.00000,-9.6704e-002,0.78460
414.12201, 52.61917,    -0.74379,77.86063,50.00000,0.0000e+000,20.00000,    -0.10003,0.78302
415.91699, 52.79917,    -0.74551,77.84536,50.00000,0.0000e+000,20.00000,    -0.10365,0.78143
417.69400, 52.97917,    -0.74668,77.82718,50.00000,0.0000e+000,20.00000,    -0.10758,0.77987
419.47900, 53.15917,    -0.74737,77.80938,50.00000,0.0000e+000,20.00000,    -0.11109,0.77830
421.26401, 53.33917,    -0.74682,77.79247,50.00000,0.0000e+000,20.00000,    -0.11428,0.77674
423.06000, 53.51917,    -0.74650,77.77018,50.00000,0.0000e+000,20.00000,    -0.11686,0.77518
424.85901, 53.69917,    -0.74526,77.74293,50.00000,0.0000e+000,20.00000,    -0.11862,0.77362
426.61801, 53.87917,    -0.74297,77.71987,50.00000,0.0000e+000,20.00000,    -0.12098,0.77210
428.40302, 54.05917,    -0.74046,77.69603,50.00000,0.0000e+000,20.00000,    -0.12299,0.77056
430.19400, 54.23917,    -0.73839,77.66745,50.00000,0.0000e+000,20.00000,    -0.12409,0.76903
431.94800, 54.41917,    -0.73685,77.64113,50.00000,0.0000e+000,20.00000,    -0.12351,0.76753
433.72198, 54.59917,    -0.73711,77.61411,50.00000,0.0000e+000,20.00000,    -0.12259,0.76602
435.50201, 54.77917,    -0.73948,77.58590,50.00000,0.0000e+000,20.00000,    -0.12055,0.76451
437.27399, 54.95917,    -0.74393,77.55849,50.00000,0.0000e+000,20.00000,    -0.11809,0.76301
439.08301, 55.13917,    -0.75195,77.53182,50.00000,0.0000e+000,20.00000,    -0.11633,0.76149
440.85901, 55.31917,    -0.76316,77.50584,50.00000,0.0000e+000,20.00000,    -0.11308,0.76001
442.67999, 55.49917,    -0.77558,77.48329,50.00000,0.0000e+000,20.00000,    -0.10783,0.75849
444.46399, 55.67916,    -0.78788,77.46407,50.00000,0.0000e+000,20.00000,    -0.10375,0.75700
446.26199, 55.85917,    -0.79967,77.44679,50.00000,0.0000e+000,20.00000,-9.9959e-002,0.75552
448.08099, 56.03917,    -0.81101,77.42848,50.00000,0.0000e+000,20.00000,-9.4573e-002,0.75402
449.87900, 56.21917,    -0.82131,77.41362,50.00000,0.0000e+000,20.00000,-8.9528e-002,0.75254
451.67001, 56.39917,    -0.82940,77.40143,50.00000,0.0000e+000,20.00000,-8.4436e-002,0.75107
453.48801, 56.57917,    -0.83632,77.39094,50.00000,0.0000e+000,20.00000,-7.8633e-002,0.74959
455.26901, 56.75917,    -0.84230,77.38178,50.00000,0.0000e+000,20.00000,-7.2752e-002,0.74815
457.03799, 56.93917,    -0.84911,77.37165,50.00000,0.0000e+000,20.00000,-6.6831e-002,0.74672
458.85400, 57.11917,    -0.85501,77.36205,50.00000,0.0000e+000,20.00000,-6.1657e-002,0.74526
460.64200, 57.29917,    -0.86062,77.35413,50.00000,0.0000e+000,20.00000,-5.7579e-002,0.74382
462.43100, 57.47917,    -0.86618,77.34528,50.00000,0.0000e+000,20.00000,-5.3383e-002,0.74240
464.20401, 57.65917,    -0.87101,77.33624,50.00000,0.0000e+000,20.00000,-5.0666e-002,0.74099
465.99500, 57.83917,    -0.87526,77.32727,50.00000,0.0000e+000,20.00000,-4.8588e-002,0.73957
467.78000, 58.01917,    -0.87974,77.31919,50.00000,0.0000e+000,20.00000,-4.7349e-002,0.73816
469.57599, 58.19917,    -0.88442,77.31089,50.00000,0.0000e+000,20.00000,-4.6466e-002,0.73675
471.34900, 58.37917,    -0.88922,77.30380,50.00000,0.0000e+000,20.00000,-4.5717e-002,0.73536
473.14499, 58.55917,    -0.89418,77.29754,50.00000,0.0000e+000,20.00000,-4.4939e-002,0.73396
474.95599, 58.73917,    -0.89839,77.29244,50.00000,0.0000e+000,20.00000,-4.4023e-002,0.73256
476.74500, 58.91917,    -0.90205,77.28565,50.00000,0.0000e+000,20.00000,-4.3955e-002,0.73118
478.53101, 59.09917,    -0.90535,77.27705,50.00000,0.0000e+000,20.00000,-4.4224e-002,0.72980
480.34299, 59.27917,    -0.91033,77.27235,50.00000,0.0000e+000,20.00000,-4.3866e-002,0.72841
482.13501, 59.45917,    -0.91476,77.26577,50.00000,0.0000e+000,20.00000,-4.3396e-002,0.72705
483.91599, 59.63917,    -0.91816,77.25527,50.00000,0.0000e+000,20.00000,-4.3985e-002,0.72569
485.72299, 59.81917,    -0.92244,77.24423,50.00000,0.0000e+000,20.00000,-4.4166e-002,0.72433
487.52600, 59.99917,    -0.92775,77.23460,50.00000,0.0000e+000,20.00000,-4.3917e-002,0.72297
489.33099, 60.17916,    -0.93190,77.22650,50.00000,0.0000e+000,20.00000,-4.4251e-002,0.72161
491.12201, 60.35917,    -0.93595,77.21981,50.00000,0.0000e+000,20.00000,-4.4243e-002,0.72027
492.93201, 60.53917,    -0.93924,77.21357,50.00000,0.0000e+000,20.00000,-4.3531e-002,0.71893
494.72501, 60.71917,    -0.94213,77.20425,50.00000,0.0000e+000,20.00000,-4.2382e-002,0.71760
496.52301, 60.89917,    -0.94476,77.19497,50.00000,0.0000e+000,20.00000,-4.2028e-002,0.71627
498.29999, 61.07917,    -0.94580,77.18733,50.00000,0.0000e+000,20.00000,-4.2776e-002,0.71497
500.07599, 61.25917,    -0.94925,77.18049,50.00000,0.0000e+000,20.00000,-4.3152e-002,0.71367
501.87201, 61.43917,    -0.95194,77.16943,50.00000,0.0000e+000,20.00000,-4.2356e-002,0.71236
503.65601, 61.61917,    -0.95594,77.16021,50.00000,0.0000e+000,20.00000,-4.0796e-002,0.71106
505.44901, 61.79917,    -0.95990,77.15276,50.00000,0.0000e+000,20.00000,-3.9618e-002,0.70977
507.22501, 61.97917,    -0.96393,77.14438,50.00000,0.0000e+000,20.00000,-3.8312e-002,0.70849
509.00699, 62.15917,    -0.96579,77.13741,50.00000,0.0000e+000,20.00000,-3.7432e-002,0.70722
510.80801, 62.33917,    -0.96944,77.13429,50.00000,0.0000e+000,20.00000,-3.7863e-002,0.70593
512.57800, 62.51917,    -0.97288,77.13266,50.00000,0.0000e+000,20.00000,-3.7400e-002,0.70467
514.34802, 62.69917,    -0.97534,77.12593,50.00000,0.0000e+000,20.00000,-3.6142e-002,0.70342
516.16498, 62.87917,    -0.98052,77.11771,50.00000,0.0000e+000,20.00000,-3.5086e-002,0.70214
517.97699, 63.05917,    -0.98732,77.11049,50.00000,0.0000e+000,20.00000,-3.5084e-002,0.70087
519.79102, 63.23917,    -0.99290,77.10320,50.00000,0.0000e+000,20.00000,-3.3574e-002,0.69961
521.59601, 63.41917,    -0.99729,77.09752,50.00000,0.0000e+000,20.00000,-3.2447e-002,0.69835
523.41803, 63.59917,    -0.99979,77.09200,50.00000,0.0000e+000,20.00000,-3.2466e-002,0.69709
525.21503, 63.77917,    -1.00114,77.08793,50.00000,0.0000e+000,20.00000,-3.2524e-002,0.69585
527.01300, 63.95917,    -1.00341,77.08488,50.00000,0.0000e+000,20.00000,-3.2709e-002,0.69462
528.81097, 64.13917,    -1.00644,77.07742,50.00000,0.0000e+000,20.00000,-3.4050e-002,0.69339
530.61499, 64.31917,    -1.00960,77.07017,50.00000,0.0000e+000,20.00000,-3.6306e-002,0.69216
532.40503, 64.49917,    -1.01177,77.06467,50.00000,0.0000e+000,20.00000,-3.6654e-002,0.69095
534.18799, 64.67917,    -1.01301,77.06100,50.00000,0.0000e+000,20.00000,-3.5665e-002,0.68975
535.97803, 64.85917,    -1.01466,77.05447,50.00000,0.0000e+000,20.00000,-3.5666e-002,0.68855
537.77002, 65.03917,    -1.01729,77.04921,50.00000,0.0000e+000,20.00000,-3.5827e-002,0.68735
539.56097, 65.21917,    -1.02035,77.04381,50.00000,0.0000e+000,20.00000,-3.6513e-002,0.68616
541.37201, 65.39917,    -1.02455,77.03652,50.00000,0.0000e+000,20.00000,-3.7799e-002,0.68496
543.15302, 65.57917,    -1.02734,77.02809,50.00000,0.0000e+000,20.00000,-3.9631e-002,0.68378
544.95398, 65.75916,    -1.03070,77.01992,50.00000,0.0000e+000,20.00000,-4.1983e-002,0.68260
546.74799, 65.93916,    -1.03350,77.01148,50.00000,0.0000e+000,20.00000,-4.2847e-002,0.68143
548.54303, 66.11916,    -1.03602,77.00187,50.00000,0.0000e+000,20.00000,-4.3232e-002,0.68026
550.35101, 66.29916,    -1.03816,76.99407,50.00000,0.0000e+000,20.00000,-4.4252e-002,0.67909
552.13898, 66.47916,    -1.03942,76.98934,50.00000,0.0000e+000,20.00000,-4.5844e-002,0.67793
553.91302, 66.65916,    -1.04114,76.98247,50.00000,0.0000e+000,20.00000,-4.6704e-002,0.67679
555.73199, 66.83916,    -1.04284,76.97453,50.00000,0.0000e+000,20.00000,-4.8425e-002,0.67563
557.51202, 67.01917,    -1.04434,76.96618,50.00000,0.0000e+000,20.00000,-4.9787e-002,0.67450
559.29401, 67.19917,    -1.04503,76.95644,50.00000,0.0000e+000,20.00000,-5.0840e-002,0.67337
561.06799, 67.37917,    -1.04633,76.94515,50.00000,0.0000e+000,20.00000,-5.3090e-002,0.67225
562.86902, 67.55917,    -1.04809,76.93392,50.00000,0.0000e+000,20.00000,-5.4477e-002,0.67111
564.65900, 67.73917,    -1.05032,76.92341,50.00000,0.0000e+000,20.00000,-5.4588e-002,0.66999
566.46198, 67.91917,    -1.05566,76.91463,50.00000,0.0000e+000,20.00000,-5.4307e-002,0.66887
568.28900, 68.09917,    -1.06279,76.90502,50.00000,0.0000e+000,20.00000,-5.4562e-002,0.66774
570.10999, 68.27917,    -1.06754,76.89554,50.00000,0.0000e+000,20.00000,-5.6647e-002,0.66661
571.95300, 68.45917,    -1.06945,76.88638,50.00000,0.0000e+000,20.00000,-5.8406e-002,0.66548
573.76801, 68.63917,    -1.07076,76.87477,50.00000,0.0000e+000,20.00000,-5.9532e-002,0.66437
575.57703, 68.81917,    -1.07187,76.86412,50.00000,0.0000e+000,20.00000,-6.0766e-002,0.66327
577.38397, 68.99917,    -1.07259,76.85407,50.00000,0.0000e+000,20.00000,-6.1780e-002,0.66217
579.19202, 69.17917,    -1.07503,76.83784,50.00000,0.0000e+000,20.00000,-6.1837e-002,0.66108
581.00299, 69.35917,    -1.07754,76.82375,50.00000,0.0000e+000,20.00000,-6.2190e-002,0.65999
582.80499, 69.53917,    -1.08014,76.81447,50.00000,0.0000e+000,20.00000,-6.2823e-002,0.65891
584.59003, 69.71917,    -1.08118,76.80625,50.00000,0.0000e+000,20.00000,-6.4048e-002,0.65785
586.39502, 69.89917,    -1.08298,76.79710,50.00000,0.0000e+000,20.00000,-6.5886e-002,0.65677
588.18298, 70.07917,    -1.08385,76.78514,50.00000,0.0000e+000,20.00000,-6.9098e-002,0.65572
589.96997, 70.25916,    -1.08517,76.77208,50.00000,0.0000e+000,20.00000,-7.2840e-002,0.65467
591.76599, 70.43916,    -1.08578,76.75997,50.00000,0.0000e+000,20.00000,-7.4957e-002,0.65362
593.55200, 70.61916,    -1.08826,76.74752,50.00000,0.0000e+000,20.00000,-7.6321e-002,0.65257
595.37201, 70.79916,    -1.08983,76.73407,50.00000,0.0000e+000,20.00000,-7.8854e-002,0.65152
597.14203, 70.97916,    -1.08981,76.72270,50.00000,0.0000e+000,20.00000,-8.0260e-002,0.65050
598.93903, 71.15916,    -1.09246,76.71026,50.00000,0.0000e+000,20.00000,-8.1187e-002,0.64946
600.75000, 71.33916,    -1.09575,76.69730,50.00000,0.0000e+000,20.00000,-8.3384e-002,0.64842
602.54999, 71.51917,    -1.09781,76.68399,50.00000,0.0000e+000,20.00000,-8.5651e-002,0.64740
604.35400, 71.69917,    -1.09788,76.66855,50.00000,0.0000e+000,20.00000,-8.7980e-002,0.64637
606.12701, 71.87917,    -1.09791,76.64788,50.00000,0.0000e+000,20.00000,-8.9774e-002,0.64537
607.94299, 72.05917,    -1.09955,76.62494,50.00000,0.0000e+000,20.00000,-9.1415e-002,0.64435
609.74500, 72.23917,    -1.09986,76.60531,50.00000,0.0000e+000,20.00000,-9.3963e-002,0.64334
611.52399, 72.41917,    -1.09981,76.58903,50.00000,0.0000e+000,20.00000,-9.6354e-002,0.64235
613.33801, 72.59917,    -1.10012,76.57095,50.00000,0.0000e+000,20.00000,-9.8000e-002,0.64134
615.14502, 72.77917,    -1.10114,76.55008,50.00000,0.0000e+000,20.00000,    -0.10069,0.64034
616.96198, 72.95917,    -1.10187,76.53157,50.00000,0.0000e+000,20.00000,    -0.10339,0.63934
618.78601, 73.13917,    -1.10380,76.51355,50.00000,0.0000e+000,20.00000,    -0.10579,0.63834
620.61401, 73.31917,    -1.10406,76.49702,50.00000,0.0000e+000,20.00000,    -0.10873,0.63734
622.42297, 73.49917,    -1.10144,76.47980,50.00000,0.0000e+000,20.00000,    -0.11085,0.63636
624.22998, 73.67917,    -1.09756,76.46181,50.00000,0.0000e+000,20.00000,    -0.11152,0.63538
626.03101, 73.85917,    -1.09644,76.44296,50.00000,0.0000e+000,20.00000,    -0.11247,0.63441
627.84601, 74.03917,    -1.09551,76.42171,50.00000,0.0000e+000,20.00000,    -0.11487,0.63343
629.64801, 74.21917,    -1.09353,76.40042,50.00000,0.0000e+000,20.00000,    -0.11797,0.63247
631.46198, 74.39917,    -1.09174,76.38088,50.00000,0.0000e+000,20.00000,    -0.12067,0.63151
633.27698, 74.57917,    -1.08998,76.35978,50.00000,0.0000e+000,20.00000,    -0.12235,0.63055
635.04498, 74.75916,    -1.08402,76.33765,50.00000,0.0000e+000,20.00000,    -0.12471,0.62961
636.81000, 74.93916,    -1.07860,76.31607,50.00000,0.0000e+000,20.00000,    -0.12829,0.62869
638.58801, 75.11916,    -1.07645,76.29237,50.00000,0.0000e+000,20.00000,    -0.13237,0.62776
640.38800, 75.29916,    -1.08006,76.26931,50.00000,0.0000e+000,20.00000,    -0.13650,0.62682
642.20203, 75.47916,    -1.08033,76.24736,50.00000,0.0000e+000,20.00000,    -0.13901,0.62588
643.99200, 75.65916,    -1.08040,76.22155,50.00000,0.0000e+000,20.00000,    -0.14104,0.62496
645.78802, 75.83916,    -1.07992,76.19262,50.00000,0.0000e+000,20.00000,    -0.14337,0.62403
647.58502, 76.01917,    -1.07917,76.16444,50.00000,0.0000e+000,20.00000,    -0.14660,0.62311
649.38898, 76.19917,    -1.07821,76.13720,50.00000,0.0000e+000,20.00000,    -0.14981,0.62220
651.20001, 76.37917,    -1.07766,76.11001,50.00000,0.0000e+000,20.00000,    -0.15373,0.62128
653.01501, 76.55917,    -1.07768,76.08292,50.00000,0.0000e+000,20.00000,    -0.15763,0.62036
654.79303, 76.73917,    -1.07677,76.05225,50.00000,0.0000e+000,20.00000,    -0.16114,0.61946
656.60602, 76.91917,    -1.07530,76.02052,50.00000,0.0000e+000,20.00000,    -0.16420,0.61856
658.42200, 77.09917,    -1.07393,75.98834,50.00000,0.0000e+000,20.00000,    -0.16800,0.61765
660.23199, 77.27917,    -1.07440,75.96037,50.00000,0.0000e+000,20.00000,    -0.17324,0.61675
662.06097, 77.45917,    -1.07828,75.93456,50.00000,0.0000e+000,20.00000,    -0.17597,0.61585
663.89398, 77.63917,    -1.07935,75.90593,50.00000,0.0000e+000,20.00000,    -0.17655,0.61494
665.70203, 77.81917,    -1.07777,75.87273,50.00000,0.0000e+000,20.00000,    -0.17847,0.61406
667.51898, 77.99917,    -1.07615,75.84115,50.00000,0.0000e+000,20.00000,    -0.18307,0.61317
669.36499, 78.17917,    -1.07482,75.80694,50.00000,0.0000e+000,20.00000,    -0.18816,0.61227
671.16199, 78.35917,    -1.07347,75.77025,50.00000,0.0000e+000,20.00000,    -0.19211,0.61140
672.99298, 78.53917,    -1.07121,75.73563,50.00000,0.0000e+000,20.00000,    -0.19491,0.61052
674.83502, 78.71917,    -1.07141,75.70138,50.00000,0.0000e+000,20.00000,    -0.19690,0.60963
676.66199, 78.89917,    -1.07068,75.66458,50.00000,0.0000e+000,20.00000,    -0.19915,0.60876
678.45099, 79.07917,    -1.06476,75.62385,50.00000,0.0000e+000,20.00000,    -0.20280,0.60790
680.24902, 79.25916,    -1.05837,75.58737,50.00000,0.0000e+000,20.00000,    -0.20749,0.60705
682.02698, 79.43916,    -1.05295,75.55668,50.00000,0.0000e+000,20.00000,    -0.21139,0.60621
683.80499, 79.61916,    -1.04915,75.52222,50.00000,0.0000e+000,20.00000,    -0.21282,0.60537
685.61499, 79.79916,    -1.05034,75.47953,50.00000,0.0000e+000,20.00000,    -0.21365,0.60452
687.41602, 79.97916,    -1.04879,75.43294,50.00000,0.0000e+000,20.00000,    -0.21391,0.60368
689.21100, 80.15916,    -1.04701,75.39132,50.00000,0.0000e+000,20.00000,    -0.21290,0.60285
691.00098, 80.33916,    -1.04345,75.35072,50.00000,0.0000e+000,20.00000,    -0.21199,0.60202
692.77399, 80.51917,    -1.04015,75.31176,50.00000,0.0000e+000,20.00000,    -0.21037,0.60120
694.54498, 80.69917,    -1.03817,75.27150,50.00000,0.0000e+000,20.00000,    -0.20813,0.60038
696.33002, 80.87917,    -1.03771,75.22968,50.00000,0.0000e+000,20.00000,    -0.20519,0.59956
698.11102, 81.05917,    -1.03923,75.18672,50.00000,0.0000e+000,20.00000,    -0.20142,0.59875
699.92499, 81.23917,    -1.04314,75.14429,50.00000,0.0000e+000,20.00000,    -0.19883,0.59793
701.70599, 81.41917,    -1.04754,75.10546,50.00000,0.0000e+000,20.00000,    -0.19591,0.59712
703.50403, 81.59917,    -1.05202,75.07031,50.00000,0.0000e+000,20.00000,    -0.18947,0.59631
705.29901, 81.77917,    -1.05547,75.03584,50.00000,0.0000e+000,20.00000,    -0.18172,0.59550
707.09900, 81.95917,    -1.05858,75.00259,50.00000,0.0000e+000,20.00000,    -0.17607,0.59470
708.90802, 82.13917,    -1.06233,74.97059,50.00000,0.0000e+000,20.00000,    -0.16986,0.59389
710.71698, 82.31917,    -1.06631,74.94198,50.00000,0.0000e+000,20.00000,    -0.16419,0.59309
712.50598, 82.49917,    -1.07103,74.91415,50.00000,0.0000e+000,20.00000,    -0.15784,0.59229
714.34198, 82.67917,    -1.07475,74.88454,50.00000,0.0000e+000,20.00000,    -0.15090,0.59148
716.13599, 82.85917,    -1.07902,74.85932,50.00000,0.0000e+000,20.00000,    -0.14425,0.59069
717.95398, 83.03917,    -1.07980,74.83822,50.00000,0.0000e+000,20.00000,    -0.13787,0.58990
719.75098, 83.21917,    -1.08084,74.81506,50.00000,0.0000e+000,20.00000,    -0.13166,0.58911
721.54999, 83.39917,    -1.08346,74.79666,50.00000,0.0000e+000,20.00000,    -0.12633,0.58833
723.35101, 83.57917,    -1.08465,74.77869,50.00000,0.0000e+000,20.00000,    -0.12142,0.58755
725.15503, 83.75916,    -1.08576,74.75719,50.00000,0.0000e+000,20.00000,    -0.11615,0.58677
726.97101, 83.93916,    -1.08424,74.73856,50.00000,0.0000e+000,20.00000,    -0.11067,0.58599
728.75299, 84.11916,    -1.08280,74.72051,50.00000,0.0000e+000,20.00000,    -0.10656,0.58523
730.55499, 84.29916,    -1.08216,74.70320,50.00000,0.0000e+000,20.00000,    -0.10245,0.58446
732.37903, 84.47916,    -1.08221,74.68725,50.00000,0.0000e+000,20.00000,-9.8612e-002,0.58368
734.18597, 84.65916,    -1.07971,74.66909,50.00000,0.0000e+000,20.00000,-9.5641e-002,0.58292
736.00500, 84.83916,    -1.07724,74.64950,50.00000,0.0000e+000,20.00000,-9.3141e-002,0.58215
737.83099, 85.01917,    -1.07867,74.63229,50.00000,0.0000e+000,20.00000,-9.1046e-002,0.58138
739.66901, 85.19917,    -1.07838,74.61644,50.00000,0.0000e+000,20.00000,-8.9813e-002,0.58061
741.45099, 85.37917,    -1.07162,74.59965,50.00000,0.0000e+000,20.00000,-8.8220e-002,0.57986
743.24902, 85.55917,    -1.06832,74.58506,50.00000,0.0000e+000,20.00000,-8.5921e-002,0.57912
745.07501, 85.73917,    -1.06752,74.57278,50.00000,0.0000e+000,20.00000,-8.4352e-002,0.57836
746.87701, 85.91917,    -1.06457,74.55885,50.00000,0.0000e+000,20.00000,-8.2627e-002,0.57761
748.66199, 86.09917,    -1.05983,74.54594,50.00000,0.0000e+000,20.00000,-8.0907e-002,0.57687
750.44897, 86.27917,    -1.05236,74.53134,50.00000,0.0000e+000,20.00000,-7.9929e-002,0.57614
752.22601, 86.45917,    -1.04555,74.51499,50.00000,0.0000e+000,20.00000,-7.8793e-002,0.57541
754.00598, 86.63917,    -1.03983,74.50320,50.00000,0.0000e+000,20.00000,-7.5806e-002,0.57468
755.83002, 86.81917,    -1.03811,74.48817,50.00000,0.0000e+000,20.00000,-7.4102e-002,0.57394
757.61401, 86.99917,    -1.03502,74.47292,50.00000,0.0000e+000,20.00000,-7.3392e-002,0.57322
759.42200, 87.17917,    -1.02953,74.46101,50.00000,0.0000e+000,20.00000,-7.1138e-002,0.57248
761.19598, 87.35917,    -1.02393,74.44857,50.00000,0.0000e+000,20.00000,-6.9302e-002,0.57177
763.03998, 87.53917,    -1.02288,74.43475,50.00000,0.0000e+000,20.00000,-6.8049e-002,0.57103
764.88000, 87.71917,    -1.02168,74.42315,50.00000,0.0000e+000,20.00000,-6.6665e-002,0.57029
766.72198, 87.89917,    -1.01775,74.41162,50.00000,0.0000e+000,20.00000,-6.7082e-002,0.56955
768.56799, 88.07917,    -1.01572,74.39974,50.00000,0.0000e+000,20.00000,-6.7161e-002,0.56882
770.40503, 88.25916,    -1.01359,74.38586,50.00000,0.0000e+000,20.00000,-6.5859e-002,0.56809
772.23798, 88.43916,    -1.00943,74.37656,50.00000,0.0000e+000,20.00000,-6.5166e-002,0.56736
774.04797, 88.61916,    -1.00282,74.36602,50.00000,0.0000e+000,20.00000,-6.3698e-002,0.56665
775.82098, 88.79916,    -0.99439,74.35243,50.00000,0.0000e+000,20.00000,-6.2579e-002,0.56595
777.60498, 88.97916,    -0.98786,74.34326,50.00000,0.0000e+000,20.00000,-6.2150e-002,0.56525
779.37903, 89.15916,    -0.98330,74.33520,50.00000,0.0000e+000,20.00000,-6.1188e-002,0.56455
781.16803, 89.33916,    -0.98072,74.32694,50.00000,0.0000e+000,20.00000,-5.9822e-002,0.56385
782.96899, 89.51917,    -0.98126,74.31923,50.00000,0.0000e+000,20.00000,-5.9125e-002,0.56315
784.78003, 89.69917,    -0.98170,74.30489,50.00000,0.0000e+000,20.00000,-5.8496e-002,0.56245
786.60101, 89.87917,    -0.98206,74.29057,50.00000,0.0000e+000,20.00000,-5.7406e-002,0.56175
788.41199, 90.05917,    -0.98178,74.27803,50.00000,0.0000e+000,20.00000,-5.6117e-002,0.56105
790.21002, 90.23917,    -0.98121,74.26821,50.00000,0.0000e+000,20.00000,-5.6260e-002,0.56035
792.01202, 90.41917,    -0.97981,74.25937,50.00000,0.0000e+000,20.00000,-5.6135e-002,0.55966
793.78699, 90.59917,    -0.97638,74.24820,50.00000,0.0000e+000,20.00000,-5.5524e-002,0.55898
795.57599, 90.77917,    -0.97511,74.23693,50.00000,0.0000e+000,20.00000,-5.5760e-002,0.55830
797.35498, 90.95917,    -0.97667,74.22837,50.00000,0.0000e+000,20.00000,-5.5892e-002,0.55762
799.17401, 91.13917,    -0.97823,74.21943,50.00000,0.0000e+000,20.00000,-5.5751e-002,0.55693
800.97900, 91.31917,    -0.97821,74.21028,50.00000,0.0000e+000,20.00000,-5.6571e-002,0.55624
802.77802, 91.49917,    -0.97747,74.20084,50.00000,0.0000e+000,20.00000,-5.5879e-002,0.55556
804.56799, 91.67917,    -0.97770,74.19309,50.00000,0.0000e+000,20.00000,-5.3888e-002,0.55489
806.38397, 91.85917,    -0.97684,74.18431,50.00000,0.0000e+000,20.00000,-5.2593e-002,0.55420
808.19501, 92.03917,    -0.97552,74.17367,50.00000,0.0000e+000,20.00000,-5.3269e-002,0.55352
809.99103, 92.21917,    -0.97425,74.16431,50.00000,0.0000e+000,20.00000,-5.3691e-002,0.55285
811.78003, 92.39917,    -0.97255,74.15324,50.00000,0.0000e+000,20.00000,-5.3555e-002,0.55218
813.59399, 92.57917,    -0.97336,74.14207,50.00000,0.0000e+000,20.00000,-5.4263e-002,0.55150
815.39001, 92.75916,    -0.97054,74.13341,50.00000,0.0000e+000,20.00000,-5.5106e-002,0.55084
817.16699, 92.93916,    -0.96758,74.12563,50.00000,0.0000e+000,20.00000,-5.5909e-002,0.55018
818.96802, 93.11916,    -0.96606,74.11571,50.00000,0.0000e+000,20.00000,-5.6753e-002,0.54951
820.75598, 93.29916,    -0.96460,74.10454,50.00000,0.0000e+000,20.00000,-5.7553e-002,0.54885
822.56403, 93.47916,    -0.96496,74.09659,50.00000,0.0000e+000,20.00000,-5.8986e-002,0.54818
824.38800, 93.65916,    -0.96541,74.08924,50.00000,0.0000e+000,20.00000,-5.9819e-002,0.54751
826.18799, 93.83916,    -0.96549,74.07676,50.00000,0.0000e+000,20.00000,-6.0635e-002,0.54685
828.02301, 94.01917,    -0.96578,74.06594,50.00000,0.0000e+000,20.00000,-6.1693e-002,0.54618
829.84100, 94.19917,    -0.96533,74.05624,50.00000,0.0000e+000,20.00000,-6.2332e-002,0.54551
831.70599, 94.37917,    -0.96576,74.04221,50.00000,0.0000e+000,20.00000,-6.3015e-002,0.54483
833.65302, 94.55917,    -0.97687,74.02991,50.00000,0.0000e+000,20.00000,-6.4367e-002,0.54412
835.55603, 94.73917,    -0.97855,74.01841,50.00000,0.0000e+000,20.00000,-6.7095e-002,0.54343
837.40698, 94.91917,    -0.97398,74.00604,50.00000,0.0000e+000,20.00000,-6.9277e-002,0.54276
839.20502, 95.09917,    -0.96448,73.99396,50.00000,0.0000e+000,20.00000,-7.0762e-002,0.54210
840.96997, 95.27917,    -0.95281,73.98040,50.00000,0.0000e+000,20.00000,-7.3487e-002,0.54147
842.71802, 95.45917,    -0.94386,73.96909,50.00000,0.0000e+000,20.00000,-7.6873e-002,0.54083
844.48102, 95.63917,    -0.93916,73.95575,50.00000,0.0000e+000,20.00000,-7.8940e-002,0.54020
846.22302, 95.81917,    -0.93758,73.94222,50.00000,0.0000e+000,20.00000,-8.0709e-002,0.53957
847.99200, 95.99917,    -0.93574,73.92931,50.00000,0.0000e+000,20.00000,-8.2785e-002,0.53894
849.65503, 96.17917,    -0.92465,73.91542,50.00000,0.0000e+000,20.00000,-8.4208e-002,0.53834
851.35400, 96.35917,    -0.91718,73.90161,50.00000,0.0000e+000,20.00000,-8.5487e-002,0.53773
853.10999, 96.53917,    -0.91983,73.88458,50.00000,0.0000e+000,20.00000,-8.8766e-002,0.53710
854.90100, 96.71917,    -0.92697,73.86666,50.00000,0.0000e+000,20.00000,-9.0733e-002,0.53646
856.73199, 96.89917,    -0.93360,73.85019,50.00000,0.0000e+000,20.00000,-9.2177e-002,0.53581
858.57300, 97.07917,    -0.93934,73.83185,50.00000,0.0000e+000,20.00000,-9.3753e-002,0.53516
860.42200, 97.25916,    -0.94204,73.81273,50.00000,0.0000e+000,20.00000,-9.5680e-002,0.53450
862.28003, 97.43916,    -0.94372,73.79312,50.00000,0.0000e+000,20.00000,-9.8440e-002,0.53384
864.11401, 97.61916,    -0.94427,73.77494,50.00000,0.0000e+000,20.00000,    -0.10082,0.53319
865.93402, 97.79916,    -0.94422,73.75816,50.00000,0.0000e+000,20.00000,    -0.10324,0.53255
867.77698, 97.97916,    -0.94418,73.73940,50.00000,0.0000e+000,20.00000,    -0.10544,0.53189
869.59003, 98.15916,    -0.94289,73.72204,50.00000,0.0000e+000,20.00000,    -0.10853,0.53125
871.38800, 98.33916,    -0.93902,73.69961,50.00000,0.0000e+000,20.00000,    -0.10985,0.53062
873.19397, 98.51917,    -0.93703,73.67865,50.00000,0.0000e+000,20.00000,    -0.11045,0.52998
875.01801, 98.69917,    -0.93572,73.66201,50.00000,0.0000e+000,20.00000,    -0.11317,0.52934
876.81403, 98.87917,    -0.93524,73.64245,50.00000,0.0000e+000,20.00000,    -0.11500,0.52871
878.62097, 99.05917,    -0.93475,73.62424,50.00000,0.0000e+000,20.00000,    -0.11653,0.52808
880.42798, 99.23917,    -0.93463,73.60176,50.00000,0.0000e+000,20.00000,    -0.11792,0.52744
882.24500, 99.41917,    -0.93359,73.57903,50.00000,0.0000e+000,20.00000,    -0.11911,0.52681
884.06403, 99.59917,    -0.93492,73.55725,50.00000,0.0000e+000,20.00000,    -0.12137,0.52617
885.88397, 99.77917,    -0.93561,73.53570,50.00000,0.0000e+000,20.00000,    -0.12346,0.52553
887.70697, 99.95917,    -0.93678,73.51097,50.00000,0.0000e+000,20.00000,    -0.12594,0.52490
889.53302,100.13917,    -0.93440,73.48871,50.00000,0.0000e+000,20.00000,    -0.12742,0.52426
891.33502,100.31917,    -0.93038,73.46915,50.00000,0.0000e+000,20.00000,    -0.12884,0.52363
893.13000,100.49917,    -0.92756,73.44319,50.00000,0.0000e+000,20.00000,    -0.13193,0.52301
894.91602,100.67917,    -0.92636,73.41805,50.00000,0.0000e+000,20.00000,    -0.13443,0.52239
896.75500,100.85917,    -0.92883,73.39365,50.00000,0.0000e+000,20.00000,    -0.13722,0.52175
898.60199,101.03917,    -0.93461,73.36869,50.00000,0.0000e+000,20.00000,    -0.13931,0.52111
900.40698,101.21917,    -0.93411,73.34574,50.00000,0.0000e+000,20.00000,    -0.14154,0.52048
902.20697,101.39917,    -0.93054,73.32120,50.00000,0.0000e+000,20.00000,    -0.14276,0.51985
904.01599,101.57917,    -0.93064,73.29499,50.00000,0.0000e+000,20.00000,    -0.14381,0.51923
905.81897,101.75916,    -0.92825,73.26852,50.00000,0.0000e+000,20.00000,    -0.14493,0.51860
907.65399,101.93916,    -0.93311,73.24177,50.00000,0.0000e+000,20.00000,    -0.14662,0.51797
909.44501,102.11916,    -0.93349,73.21461,50.00000,0.0000e+000,20.00000,    -0.14899,0.51735
911.18903,102.29916,    -0.92392,73.18684,50.00000,0.0000e+000,20.00000,    -0.15022,0.51674
912.93103,102.47916,    -0.91945,73.15846,50.00000,0.0000e+000,20.00000,    -0.15139,0.51614
914.69098,102.65916,    -0.92017,73.12988,50.00000,0.0000e+000,20.00000,    -0.15228,0.51553
916.48102,102.83916,    -0.92313,73.10101,50.00000,0.0000e+000,20.00000,    -0.15341,0.51492
918.31403,103.01917,    -0.92657,73.06957,50.00000,0.0000e+000,20.00000,    -0.15557,0.51428
920.17798,103.19917,    -0.93425,73.04251,50.00000,0.0000e+000,20.00000,    -0.15747,0.51364
922.05603,103.37917,    -0.94340,73.01755,50.00000,0.0000e+000,20.00000,    -0.15876,0.51299
923.83502,103.55917,    -0.93998,72.98967,50.00000,0.0000e+000,20.00000,    -0.15941,0.51238
925.59399,103.73917,    -0.93198,72.96013,50.00000,0.0000e+000,20.00000,    -0.15925,0.51177
927.36298,103.91917,    -0.92800,72.93220,50.00000,0.0000e+000,20.00000,    -0.16052,0.51116
929.15802,104.09917,    -0.92763,72.90302,50.00000,0.0000e+000,20.00000,    -0.16234,0.51054
930.98297,104.27917,    -0.92998,72.87264,50.00000,0.0000e+000,20.00000,    -0.16298,0.50992
932.78003,104.45917,    -0.92778,72.84520,50.00000,0.0000e+000,20.00000,    -0.16332,0.50930
934.57703,104.63917,    -0.92378,72.81627,50.00000,0.0000e+000,20.00000,    -0.16375,0.50868
936.39398,104.81917,    -0.91966,72.78544,50.00000,0.0000e+000,20.00000,    -0.16308,0.50805
938.28998,104.99917,    -0.92414,72.75422,50.00000,0.0000e+000,20.00000,    -0.16411,0.50740
940.12000,105.17917,    -0.91756,72.72359,50.00000,0.0000e+000,20.00000,    -0.16736,0.50677
941.94397,105.35917,    -0.90898,72.69380,50.00000,0.0000e+000,20.00000,    -0.16847,0.50614
943.76202,105.53917,    -0.89937,72.66821,50.00000,0.0000e+000,20.00000,    -0.16883,0.50552
945.55103,105.71917,    -0.88733,72.63724,50.00000,0.0000e+000,20.00000,    -0.17001,0.50490
947.32202,105.89917,    -0.87668,72.60287,50.00000,0.0000e+000,20.00000,    -0.17089,0.50429
949.11102,106.07917,    -0.86875,72.57162,50.00000,0.0000e+000,20.00000,    -0.17167,0.50368
950.88300,106.25916,    -0.86075,72.54192,50.00000,0.0000e+000,20.00000,    -0.17352,0.50306
952.66699,106.43916,    -0.85572,72.51165,50.00000,0.0000e+000,20.00000,    -0.17504,0.50245
954.43701,106.61916,    -0.85233,72.48259,50.00000,0.0000e+000,20.00000,    -0.17543,0.50184
956.21002,106.79916,    -0.84829,72.45180,50.00000,0.0000e+000,20.00000,    -0.17566,0.50123
958.01801,106.97916,    -0.85062,72.41530,50.00000,0.0000e+000,20.00000,    -0.17585,0.50061
959.83099,107.15916,    -0.84948,72.38279,50.00000,0.0000e+000,20.00000,    -0.17686,0.49998
961.63898,107.33916,    -0.85016,72.35252,50.00000,0.0000e+000,20.00000,    -0.17904,0.49936
963.41302,107.51917,    -0.84669,72.31985,50.00000,0.0000e+000,20.00000,    -0.17895,0.49875
965.21698,107.69917,    -0.84231,72.28806,50.00000,0.0000e+000,20.00000,    -0.17696,0.49813
966.97498,107.87917,    -0.83924,72.25481,50.00000,0.0000e+000,20.00000,    -0.17444,0.49752
968.79401,108.05917,    -0.83804,72.22051,50.00000,0.0000e+000,20.00000,    -0.17269,0.49689
970.62402,108.23917,    -0.84103,72.18607,50.00000,0.0000e+000,20.00000,    -0.17054,0.49626
972.43799,108.41917,    -0.84479,72.15397,50.00000,0.0000e+000,20.00000,    -0.16734,0.49563
974.25098,108.59917,    -0.84329,72.12167,50.00000,0.0000e+000,20.00000,    -0.16417,0.49501
976.07898,108.77917,    -0.84432,72.09053,50.00000,0.0000e+000,20.00000,    -0.15958,0.49438
977.89600,108.95917,    -0.84488,72.05683,50.00000,0.0000e+000,20.00000,    -0.15523,0.49375
979.72400,109.13917,    -0.84721,72.02283,50.00000,0.0000e+000,20.00000,    -0.15246,0.49311
981.56097,109.31917,    -0.85098,71.99255,50.00000,0.0000e+000,20.00000,    -0.15014,0.49248
983.32202,109.49917,    -0.84669,71.96516,50.00000,0.0000e+000,20.00000,    -0.14598,0.49187
985.08197,109.67917,    -0.84411,71.94190,50.00000,0.0000e+000,20.00000,    -0.14031,0.49126
986.90302,109.85917,    -0.84797,71.91900,50.00000,0.0000e+000,20.00000,    -0.13452,0.49063
988.69800,110.03917,    -0.85142,71.89604,50.00000,0.0000e+000,20.00000,    -0.12491,0.49000
990.48102,110.21917,    -0.85224,71.87784,50.00000,0.0000e+000,20.00000,    -0.11525,0.48939
992.28003,110.39917,    -0.85376,71.85994,50.00000,0.0000e+000,20.00000,    -0.11052,0.48876
994.10498,110.57917,    -0.85887,71.84042,50.00000,0.0000e+000,20.00000,    -0.10594,0.48813
995.94397,110.75916,    -0.86582,71.82272,50.00000,0.0000e+000,20.00000,    -0.10906,0.48749
997.75702,110.93916,    -0.86468,71.80333,50.00000,0.0000e+000,20.00000,    -0.12928,0.48686
998.34003,110.99917,    -0.86452,71.79444,50.00000,0.0000e+000,20.00000,    -0.26544,0.48665