File: book/some_content/TG_ExpDat_MgO5%DC1.csv
#FILE:                       ,MgO5%DC1; 17-1-2025.ngb-ds3
#FORMAT:                     ,NETZSCH5
#IDENTITY:                   ,GEOPOLYMER PASTE
#DECIMAL:                    ,POINT
#SEPARATOR:                  ,COMMA
#MTYPE:                      ,DSC
#INSTRUMENT:                 ,Microlab TU Delft
#PROJECT:                    ,
#DATE/TIME:                  ,18/01/2025 11:15:56 AM
#CORR. FILE:                 ,Blank with cover; 13-1-2025.ngb-bs3
#LABORATORY:                 ,TU Delft Micro Lab
#OPERATOR:                   ,Ahmed
#REMARK:                     ,under Argon atmosphere, 10K/min
#SAMPLE:                     ,MgO5%DC1;18-1-2025
#SAMPLE MASS /mg:            ,30.6
#MATERIAL:                   ,Geopolymer paste
#REFERENCE:                  ,blank
#REFERENCE MASS /mg:         ,0
#TYPE OF CRUCIBLE:           ,DSC/TG pan Al2O3
#SAMPLE CRUCIBLE MASS /mg:   ,0
#REFERENCE CRUCIBLE MASS /mg:,0
#CORR. CODE:                 ,020
#EXO:                        ,-1
#RANGE:                      ,40/10.0(K/min)/1000
#SEGMENT:                    ,S2/2

##Temp./øC,Time/min,DSC/(mW/mg),Mass/%,Gas Flow(purge1)/(ml/min),Gas Flow(purge2)/(ml/min),Gas Flow(protective)/(ml/min),DTG/(%/min),Sensit./(uV/mW)
 44.98200, 18.14833,-3.0817e-002,91.81255,50.00000,0.0000e+000,20.00000,    -0.15625,1.22007
 45.06200, 18.32333,-3.2740e-002,91.78735,50.00000,0.0000e+000,20.00000,    -0.14008,1.21996
 45.19900, 18.49833,-3.3849e-002,91.77041,50.00000,0.0000e+000,20.00000,    -0.12389,1.21977
 45.46000, 18.67333,-3.3982e-002,91.75760,50.00000,0.0000e+000,20.00000,    -0.10831,1.21942
 45.78000, 18.84833,-3.3176e-002,91.74748,50.00000,0.0000e+000,20.00000,-9.3086e-002,1.21897
 46.22100, 19.02333,-3.1310e-002,91.74159,50.00000,0.0000e+000,20.00000,-7.8713e-002,1.21837
 46.76500, 19.19833,-2.8770e-002,91.73951,50.00000,0.0000e+000,20.00000,-6.7223e-002,1.21762
 47.40000, 19.37333,-2.4836e-002,91.74011,50.00000,0.0000e+000,20.00000,-5.8845e-002,1.21674
 48.18500, 19.54833,-2.0120e-002,91.74154,50.00000,0.0000e+000,20.00000,-5.1775e-002,1.21566
 49.07100, 19.72333,-1.5172e-002,91.74351,50.00000,0.0000e+000,20.00000,-4.6111e-002,1.21444
 50.12400, 19.89833,-9.1469e-003,91.74805,50.00000,0.0000e+000,20.00000,-4.4087e-002,1.21299
 51.25800, 20.07333,-2.5521e-003,91.75247,50.00000,0.0000e+000,20.00000,-4.5165e-002,1.21143
 52.52300, 20.24833, 4.5962e-003,91.75396,50.00000,0.0000e+000,20.00000,-4.9589e-002,1.20969
 53.90600, 20.42333, 1.1602e-002,91.75404,50.00000,0.0000e+000,20.00000,-5.7914e-002,1.20778
 55.41700, 20.59833, 1.9645e-002,91.75336,50.00000,0.0000e+000,20.00000,-6.9022e-002,1.20570
 57.02900, 20.77333, 2.8258e-002,91.75120,50.00000,0.0000e+000,20.00000,-8.3304e-002,1.20349
 58.76200, 20.94833, 3.6472e-002,91.74491,50.00000,0.0000e+000,20.00000,    -0.10220,1.20110
 60.58500, 21.12333, 4.5701e-002,91.73037,50.00000,0.0000e+000,20.00000,    -0.12494,1.19860
 62.51200, 21.29833, 5.4913e-002,91.71206,50.00000,0.0000e+000,20.00000,    -0.15129,1.19595
 64.55300, 21.47333, 6.4424e-002,91.69695,50.00000,0.0000e+000,20.00000,    -0.18125,1.19315
 66.64200, 21.64833, 7.4927e-002,91.67697,50.00000,0.0000e+000,20.00000,    -0.21414,1.19028
 68.84500, 21.82333, 8.5744e-002,91.64716,50.00000,0.0000e+000,20.00000,    -0.24996,1.18726
 71.13500, 21.99833, 9.7489e-002,91.61280,50.00000,0.0000e+000,20.00000,    -0.28807,1.18412
 73.46700, 22.17333,     0.10985,91.57219,50.00000,0.0000e+000,20.00000,    -0.33007,1.18092
 75.89200, 22.34833,     0.12271,91.52305,50.00000,0.0000e+000,20.00000,    -0.37916,1.17761
 78.37100, 22.52333,     0.13696,91.46722,50.00000,0.0000e+000,20.00000,    -0.42669,1.17421
 80.91100, 22.69833,     0.15144,91.40022,50.00000,0.0000e+000,20.00000,    -0.47236,1.17074
 83.50500, 22.87333,     0.16704,91.32122,50.00000,0.0000e+000,20.00000,    -0.51662,1.16720
 86.15000, 23.04833,     0.18479,91.23166,50.00000,0.0000e+000,20.00000,    -0.55331,1.16360
 88.81600, 23.22333,     0.20463,91.12927,50.00000,0.0000e+000,20.00000,    -0.58730,1.15996
 91.55500, 23.39833,     0.22713,91.01564,50.00000,0.0000e+000,20.00000,    -0.61977,1.15624
 94.30800, 23.57333,     0.25125,90.89442,50.00000,0.0000e+000,20.00000,    -0.64669,1.15249
 97.06900, 23.74833,     0.27723,90.76244,50.00000,0.0000e+000,20.00000,    -0.67014,1.14875
 99.86600, 23.92333,     0.30410,90.61868,50.00000,0.0000e+000,20.00000,    -0.69125,1.14495
102.67000, 24.09833,     0.32969,90.44965,50.00000,0.0000e+000,20.00000,    -0.70843,1.14116
105.47400, 24.27333,     0.35361,90.26827,50.00000,0.0000e+000,20.00000,    -0.72132,1.13737
108.30100, 24.44833,     0.37258,90.09860,50.00000,0.0000e+000,20.00000,    -0.73098,1.13355
111.10700, 24.62333,     0.38409,89.92466,50.00000,0.0000e+000,20.00000,    -0.73620,1.12977
113.92900, 24.79833,     0.38518,89.76203,50.00000,0.0000e+000,20.00000,    -0.73762,1.12597
116.76600, 24.97333,     0.37776,89.61899,50.00000,0.0000e+000,20.00000,    -0.73536,1.12216
119.57000, 25.14833,     0.36512,89.48026,50.00000,0.0000e+000,20.00000,    -0.72858,1.11840
122.39900, 25.32333,     0.34929,89.35158,50.00000,0.0000e+000,20.00000,    -0.71988,1.11461
125.21300, 25.49833,     0.33198,89.23098,50.00000,0.0000e+000,20.00000,    -0.70836,1.11085
128.04300, 25.67333,     0.31365,89.11492,50.00000,0.0000e+000,20.00000,    -0.69237,1.10707
130.83600, 25.84833,     0.29559,89.00320,50.00000,0.0000e+000,20.00000,    -0.66955,1.10335
133.63200, 26.02333,     0.27739,88.89998,50.00000,0.0000e+000,20.00000,    -0.63889,1.09964
136.42300, 26.19833,     0.25935,88.80236,50.00000,0.0000e+000,20.00000,    -0.61073,1.09593
139.20500, 26.37333,     0.24240,88.70729,50.00000,0.0000e+000,20.00000,    -0.58222,1.09225
141.93401, 26.54833,     0.22564,88.61637,50.00000,0.0000e+000,20.00000,    -0.55258,1.08864
144.63300, 26.72333,     0.20949,88.52722,50.00000,0.0000e+000,20.00000,    -0.52903,1.08508
147.34399, 26.89833,     0.19393,88.44109,50.00000,0.0000e+000,20.00000,    -0.50771,1.08151
149.99400, 27.07333,     0.17836,88.35660,50.00000,0.0000e+000,20.00000,    -0.48689,1.07803
152.63000, 27.24833,     0.16369,88.27001,50.00000,0.0000e+000,20.00000,    -0.46838,1.07458
155.22701, 27.42333,     0.14936,88.18817,50.00000,0.0000e+000,20.00000,    -0.45090,1.07118
157.79401, 27.59833,     0.13426,88.11239,50.00000,0.0000e+000,20.00000,    -0.43353,1.06783
160.33099, 27.77333,     0.12017,88.04269,50.00000,0.0000e+000,20.00000,    -0.41731,1.06453
162.80701, 27.94833,     0.10644,87.97258,50.00000,0.0000e+000,20.00000,    -0.40300,1.06131
165.28799, 28.12333, 9.2629e-002,87.90319,50.00000,0.0000e+000,20.00000,    -0.38966,1.05809
167.71500, 28.29833, 7.9103e-002,87.83876,50.00000,0.0000e+000,20.00000,    -0.37697,1.05495
170.09500, 28.47333, 6.5515e-002,87.77626,50.00000,0.0000e+000,20.00000,    -0.36459,1.05188
172.46001, 28.64833, 5.2346e-002,87.71223,50.00000,0.0000e+000,20.00000,    -0.35183,1.04883
174.79800, 28.82333, 3.9384e-002,87.65277,50.00000,0.0000e+000,20.00000,    -0.33979,1.04583
177.07800, 28.99833, 2.6824e-002,87.59640,50.00000,0.0000e+000,20.00000,    -0.32800,1.04290
179.35699, 29.17333, 1.4576e-002,87.54139,50.00000,0.0000e+000,20.00000,    -0.31583,1.03998
181.59000, 29.34833, 2.8367e-003,87.48926,50.00000,0.0000e+000,20.00000,    -0.30389,1.03713
183.79300, 29.52333,-9.1841e-003,87.44040,50.00000,0.0000e+000,20.00000,    -0.29347,1.03432
185.96800, 29.69833,-1.9964e-002,87.39317,50.00000,0.0000e+000,20.00000,    -0.28347,1.03156
188.10500, 29.87333,-3.1165e-002,87.34580,50.00000,0.0000e+000,20.00000,    -0.27224,1.02884
190.24100, 30.04833,-4.1695e-002,87.29867,50.00000,0.0000e+000,20.00000,    -0.26180,1.02614
192.32401, 30.22333,-5.2496e-002,87.25335,50.00000,0.0000e+000,20.00000,    -0.25233,1.02350
194.39200, 30.39833,-6.2961e-002,87.21059,50.00000,0.0000e+000,20.00000,    -0.24215,1.02090
196.42799, 30.57333,-7.3182e-002,87.17057,50.00000,0.0000e+000,20.00000,    -0.23210,1.01834
198.44901, 30.74833,-8.3183e-002,87.12850,50.00000,0.0000e+000,20.00000,    -0.22311,1.01580
200.41701, 30.92333,-9.3448e-002,87.08634,50.00000,0.0000e+000,20.00000,    -0.21410,1.01333
202.39500, 31.09833,    -0.10290,87.04943,50.00000,0.0000e+000,20.00000,    -0.20520,1.01086
204.33099, 31.27333,    -0.11289,87.01557,50.00000,0.0000e+000,20.00000,    -0.19699,1.00844
206.24800, 31.44833,    -0.12245,86.98194,50.00000,0.0000e+000,20.00000,    -0.18920,1.00606
208.16100, 31.62333,    -0.13260,86.95109,50.00000,0.0000e+000,20.00000,    -0.18181,1.00368
210.02600, 31.79833,    -0.14195,86.92248,50.00000,0.0000e+000,20.00000,    -0.17452,1.00137
211.89301, 31.97333,    -0.15153,86.89410,50.00000,0.0000e+000,20.00000,    -0.16768,0.99906
213.73700, 32.14833,    -0.16121,86.86690,50.00000,0.0000e+000,20.00000,    -0.16087,0.99678
215.55200, 32.32333,    -0.17090,86.84119,50.00000,0.0000e+000,20.00000,    -0.15453,0.99454
217.36301, 32.49833,    -0.17952,86.81642,50.00000,0.0000e+000,20.00000,    -0.14803,0.99232
219.17500, 32.67333,    -0.18897,86.79278,50.00000,0.0000e+000,20.00000,    -0.14092,0.99009
220.93201, 32.84833,    -0.19761,86.77109,50.00000,0.0000e+000,20.00000,    -0.13543,0.98794
222.72200, 33.02333,    -0.20677,86.75054,50.00000,0.0000e+000,20.00000,    -0.13071,0.98576
224.46201, 33.19833,    -0.21591,86.73097,50.00000,0.0000e+000,20.00000,    -0.12639,0.98364
226.21800, 33.37333,    -0.22466,86.71143,50.00000,0.0000e+000,20.00000,    -0.12208,0.98150
227.96001, 33.54833,    -0.23347,86.69075,50.00000,0.0000e+000,20.00000,    -0.11839,0.97939
229.67300, 33.72333,    -0.24193,86.66961,50.00000,0.0000e+000,20.00000,    -0.11510,0.97731
231.40199, 33.89833,    -0.25011,86.64932,50.00000,0.0000e+000,20.00000,    -0.11160,0.97522
233.10899, 34.07333,    -0.25871,86.63115,50.00000,0.0000e+000,20.00000,    -0.10827,0.97316
234.80901, 34.24833,    -0.26714,86.61395,50.00000,0.0000e+000,20.00000,    -0.10515,0.97112
236.51401, 34.42333,    -0.27566,86.59722,50.00000,0.0000e+000,20.00000,    -0.10264,0.96907
238.19099, 34.59833,    -0.28404,86.57881,50.00000,0.0000e+000,20.00000,    -0.10064,0.96706
239.87801, 34.77333,    -0.29226,86.56016,50.00000,0.0000e+000,20.00000,-9.9247e-002,0.96504
241.57700, 34.94833,    -0.30028,86.54294,50.00000,0.0000e+000,20.00000,-9.8378e-002,0.96301
243.23700, 35.12333,    -0.30790,86.52502,50.00000,0.0000e+000,20.00000,-9.7179e-002,0.96104
244.91299, 35.29833,    -0.31610,86.50955,50.00000,0.0000e+000,20.00000,-9.5224e-002,0.95905
246.60100, 35.47333,    -0.32424,86.49311,50.00000,0.0000e+000,20.00000,-9.3165e-002,0.95704
248.28200, 35.64833,    -0.33222,86.47729,50.00000,0.0000e+000,20.00000,-9.1763e-002,0.95506
249.95100, 35.82333,    -0.34071,86.46296,50.00000,0.0000e+000,20.00000,-9.0909e-002,0.95309
251.64301, 35.99833,    -0.34821,86.44904,50.00000,0.0000e+000,20.00000,-9.0278e-002,0.95109
253.31300, 36.17333,    -0.35526,86.43484,50.00000,0.0000e+000,20.00000,-8.9665e-002,0.94913
254.99001, 36.34833,    -0.36213,86.41922,50.00000,0.0000e+000,20.00000,-8.8743e-002,0.94717
256.65799, 36.52333,    -0.36902,86.40419,50.00000,0.0000e+000,20.00000,-8.7291e-002,0.94522
258.32901, 36.69833,    -0.37592,86.38718,50.00000,0.0000e+000,20.00000,-8.6320e-002,0.94327
259.99500, 36.87333,    -0.38276,86.37143,50.00000,0.0000e+000,20.00000,-8.5273e-002,0.94133
261.65399, 37.04833,    -0.38917,86.35755,50.00000,0.0000e+000,20.00000,-8.4782e-002,0.93940
263.32199, 37.22333,    -0.39593,86.34476,50.00000,0.0000e+000,20.00000,-8.4230e-002,0.93747
265.00400, 37.39833,    -0.40275,86.32985,50.00000,0.0000e+000,20.00000,-8.3245e-002,0.93552
266.67200, 37.57333,    -0.40983,86.31363,50.00000,0.0000e+000,20.00000,-8.2550e-002,0.93360
268.34900, 37.74833,    -0.41606,86.29826,50.00000,0.0000e+000,20.00000,-8.2601e-002,0.93167
270.02600, 37.92333,    -0.42287,86.28319,50.00000,0.0000e+000,20.00000,-8.2933e-002,0.92975
271.69199, 38.09833,    -0.42912,86.26922,50.00000,0.0000e+000,20.00000,-8.2547e-002,0.92784
273.34799, 38.27333,    -0.43562,86.25508,50.00000,0.0000e+000,20.00000,-8.2316e-002,0.92595
275.02499, 38.44833,    -0.44167,86.24142,50.00000,0.0000e+000,20.00000,-8.2185e-002,0.92404
276.70801, 38.62333,    -0.44786,86.22738,50.00000,0.0000e+000,20.00000,-8.1695e-002,0.92212
278.39801, 38.79833,    -0.45373,86.21288,50.00000,0.0000e+000,20.00000,-8.1842e-002,0.92021
280.05899, 38.97333,    -0.45954,86.19864,50.00000,0.0000e+000,20.00000,-8.2679e-002,0.91833
281.74301, 39.14833,    -0.46553,86.18533,50.00000,0.0000e+000,20.00000,-8.3608e-002,0.91643
283.43100, 39.32333,    -0.47118,86.17308,50.00000,0.0000e+000,20.00000,-8.4136e-002,0.91453
285.11200, 39.49833,    -0.47675,86.15981,50.00000,0.0000e+000,20.00000,-8.4784e-002,0.91265
286.79501, 39.67333,    -0.48230,86.14480,50.00000,0.0000e+000,20.00000,-8.5241e-002,0.91076
288.49301, 39.84833,    -0.48729,86.13035,50.00000,0.0000e+000,20.00000,-8.6505e-002,0.90887
290.17599, 40.02333,    -0.49258,86.11670,50.00000,0.0000e+000,20.00000,-8.8056e-002,0.90699
291.87399, 40.19833,    -0.49782,86.10134,50.00000,0.0000e+000,20.00000,-8.9548e-002,0.90511
293.56400, 40.37333,    -0.50264,86.08608,50.00000,0.0000e+000,20.00000,-9.0903e-002,0.90323
295.23801, 40.54833,    -0.50762,86.07116,50.00000,0.0000e+000,20.00000,-9.2032e-002,0.90138
296.95801, 40.72333,    -0.51263,86.05556,50.00000,0.0000e+000,20.00000,-9.3223e-002,0.89949
298.63901, 40.89833,    -0.51771,86.03887,50.00000,0.0000e+000,20.00000,-9.4943e-002,0.89764
300.34000, 41.07333,    -0.52213,86.02133,50.00000,0.0000e+000,20.00000,-9.7279e-002,0.89578
302.04300, 41.24833,    -0.52654,86.00297,50.00000,0.0000e+000,20.00000,    -0.10015,0.89392
303.75101, 41.42333,    -0.53121,85.98576,50.00000,0.0000e+000,20.00000,    -0.10262,0.89205
305.44901, 41.59833,    -0.53567,85.96791,50.00000,0.0000e+000,20.00000,    -0.10504,0.89021
307.14999, 41.77333,    -0.54043,85.94812,50.00000,0.0000e+000,20.00000,    -0.10795,0.88837
308.85901, 41.94833,    -0.54494,85.92869,50.00000,0.0000e+000,20.00000,    -0.11093,0.88652
310.55899, 42.12333,    -0.54869,85.90961,50.00000,0.0000e+000,20.00000,    -0.11408,0.88469
312.26999, 42.29833,    -0.55220,85.89117,50.00000,0.0000e+000,20.00000,    -0.11782,0.88285
313.98599, 42.47333,    -0.55570,85.87254,50.00000,0.0000e+000,20.00000,    -0.12189,0.88101
315.71100, 42.64833,    -0.55877,85.85312,50.00000,0.0000e+000,20.00000,    -0.12601,0.87916
317.41699, 42.82333,    -0.56209,85.83246,50.00000,0.0000e+000,20.00000,    -0.13010,0.87735
319.12500, 42.99833,    -0.56436,85.81027,50.00000,0.0000e+000,20.00000,    -0.13407,0.87553
320.83200, 43.17333,    -0.56710,85.78680,50.00000,0.0000e+000,20.00000,    -0.13825,0.87372
322.56799, 43.34833,    -0.56926,85.76329,50.00000,0.0000e+000,20.00000,    -0.14318,0.87189
324.27100, 43.52333,    -0.57101,85.73912,50.00000,0.0000e+000,20.00000,    -0.14789,0.87009
325.98599, 43.69833,    -0.57165,85.71439,50.00000,0.0000e+000,20.00000,    -0.15251,0.86829
327.70300, 43.87333,    -0.57212,85.68788,50.00000,0.0000e+000,20.00000,    -0.15751,0.86649
329.39499, 44.04833,    -0.57213,85.66007,50.00000,0.0000e+000,20.00000,    -0.16269,0.86473
331.10001, 44.22333,    -0.57244,85.63054,50.00000,0.0000e+000,20.00000,    -0.16770,0.86295
332.80600, 44.39833,    -0.57336,85.59977,50.00000,0.0000e+000,20.00000,    -0.17292,0.86118
334.50299, 44.57333,    -0.57500,85.56803,50.00000,0.0000e+000,20.00000,    -0.17809,0.85943
336.21301, 44.74833,    -0.57679,85.53554,50.00000,0.0000e+000,20.00000,    -0.18297,0.85766
337.94501, 44.92333,    -0.57901,85.50275,50.00000,0.0000e+000,20.00000,    -0.18668,0.85588
339.67401, 45.09833,    -0.58179,85.46862,50.00000,0.0000e+000,20.00000,    -0.19008,0.85411
341.38599, 45.27333,    -0.58444,85.43259,50.00000,0.0000e+000,20.00000,    -0.19421,0.85236
343.09299, 45.44833,    -0.58778,85.39601,50.00000,0.0000e+000,20.00000,    -0.19792,0.85062
344.83200, 45.62333,    -0.59076,85.35907,50.00000,0.0000e+000,20.00000,    -0.19985,0.84885
346.55499, 45.79833,    -0.59463,85.32117,50.00000,0.0000e+000,20.00000,    -0.20098,0.84710
348.28201, 45.97333,    -0.59922,85.28423,50.00000,0.0000e+000,20.00000,    -0.20184,0.84536
350.02600, 46.14833,    -0.60576,85.24691,50.00000,0.0000e+000,20.00000,    -0.20264,0.84361
351.76599, 46.32333,    -0.61326,85.20821,50.00000,0.0000e+000,20.00000,    -0.20269,0.84186
353.50201, 46.49833,    -0.61949,85.16882,50.00000,0.0000e+000,20.00000,    -0.20172,0.84012
355.26300, 46.67333,    -0.62700,85.13077,50.00000,0.0000e+000,20.00000,    -0.19993,0.83837
356.99500, 46.84833,    -0.63413,85.09517,50.00000,0.0000e+000,20.00000,    -0.19746,0.83665
358.73099, 47.02333,    -0.64060,85.05767,50.00000,0.0000e+000,20.00000,    -0.19411,0.83493
360.46100, 47.19833,    -0.64784,85.01825,50.00000,0.0000e+000,20.00000,    -0.19029,0.83322
362.17899, 47.37333,    -0.65431,84.98344,50.00000,0.0000e+000,20.00000,    -0.18615,0.83153
363.90799, 47.54833,    -0.66331,84.95187,50.00000,0.0000e+000,20.00000,    -0.18122,0.82984
365.63400, 47.72333,    -0.67321,84.92040,50.00000,0.0000e+000,20.00000,    -0.17652,0.82815
367.36801, 47.89833,    -0.68340,84.88760,50.00000,0.0000e+000,20.00000,    -0.17225,0.82646
369.10800, 48.07333,    -0.69353,84.85494,50.00000,0.0000e+000,20.00000,    -0.16749,0.82477
370.85300, 48.24833,    -0.70286,84.82508,50.00000,0.0000e+000,20.00000,    -0.16234,0.82308
372.59000, 48.42333,    -0.71240,84.79788,50.00000,0.0000e+000,20.00000,    -0.15721,0.82140
374.31201, 48.59833,    -0.72154,84.77282,50.00000,0.0000e+000,20.00000,    -0.15264,0.81975
376.04501, 48.77333,    -0.72958,84.74936,50.00000,0.0000e+000,20.00000,    -0.14807,0.81809
377.77100, 48.94833,    -0.73762,84.72658,50.00000,0.0000e+000,20.00000,    -0.14279,0.81644
379.49600, 49.12333,    -0.74514,84.70453,50.00000,0.0000e+000,20.00000,    -0.13783,0.81480
381.22699, 49.29833,    -0.75326,84.68411,50.00000,0.0000e+000,20.00000,    -0.13424,0.81316
382.95099, 49.47333,    -0.76098,84.66450,50.00000,0.0000e+000,20.00000,    -0.13069,0.81153
384.67499, 49.64833,    -0.77036,84.64350,50.00000,0.0000e+000,20.00000,    -0.12683,0.80990
386.40900, 49.82333,    -0.77971,84.62238,50.00000,0.0000e+000,20.00000,    -0.12240,0.80827
388.15201, 49.99833,    -0.78889,84.60198,50.00000,0.0000e+000,20.00000,    -0.11792,0.80664
389.89700, 50.17333,    -0.79767,84.58156,50.00000,0.0000e+000,20.00000,    -0.11388,0.80502
391.62900, 50.34833,    -0.80607,84.56160,50.00000,0.0000e+000,20.00000,    -0.11061,0.80341
393.37299, 50.52333,    -0.81341,84.54223,50.00000,0.0000e+000,20.00000,    -0.10849,0.80179
395.12299, 50.69833,    -0.82023,84.52243,50.00000,0.0000e+000,20.00000,    -0.10710,0.80018
396.85101, 50.87333,    -0.82635,84.50281,50.00000,0.0000e+000,20.00000,    -0.10574,0.79859
398.57700, 51.04833,    -0.83140,84.48363,50.00000,0.0000e+000,20.00000,    -0.10488,0.79701
400.29999, 51.22333,    -0.83656,84.46475,50.00000,0.0000e+000,20.00000,    -0.10479,0.79544
402.01901, 51.39833,    -0.84210,84.44668,50.00000,0.0000e+000,20.00000,    -0.10449,0.79387
403.76001, 51.57333,    -0.84828,84.42912,50.00000,0.0000e+000,20.00000,    -0.10417,0.79229
405.48001, 51.74833,    -0.85474,84.41314,50.00000,0.0000e+000,20.00000,    -0.10436,0.79074
407.21701, 51.92333,    -0.86202,84.39945,50.00000,0.0000e+000,20.00000,    -0.10448,0.78918
408.96701, 52.09833,    -0.87112,84.38571,50.00000,0.0000e+000,20.00000,    -0.10408,0.78761
410.72900, 52.27333,    -0.87885,84.37068,50.00000,0.0000e+000,20.00000,    -0.10476,0.78603
412.47900, 52.44833,    -0.88654,84.35307,50.00000,0.0000e+000,20.00000,    -0.10552,0.78448
414.22400, 52.62333,    -0.89167,84.33544,50.00000,0.0000e+000,20.00000,    -0.10568,0.78293
415.97400, 52.79833,    -0.89525,84.31773,50.00000,0.0000e+000,20.00000,    -0.10608,0.78138
417.70700, 52.97333,    -0.89845,84.29892,50.00000,0.0000e+000,20.00000,    -0.10657,0.77986
419.43201, 53.14833,    -0.90202,84.27960,50.00000,0.0000e+000,20.00000,    -0.10742,0.77834
421.15601, 53.32333,    -0.90646,84.25991,50.00000,0.0000e+000,20.00000,    -0.10832,0.77684
422.90500, 53.49833,    -0.91156,84.23921,50.00000,0.0000e+000,20.00000,    -0.10933,0.77531
424.63000, 53.67333,    -0.91606,84.21754,50.00000,0.0000e+000,20.00000,    -0.11082,0.77382
426.35300, 53.84833,    -0.92128,84.19837,50.00000,0.0000e+000,20.00000,    -0.11286,0.77233
428.08301, 54.02333,    -0.92604,84.17812,50.00000,0.0000e+000,20.00000,    -0.11493,0.77084
429.82101, 54.19833,    -0.93146,84.15509,50.00000,0.0000e+000,20.00000,    -0.11593,0.76935
431.54901, 54.37333,    -0.93699,84.13422,50.00000,0.0000e+000,20.00000,    -0.11687,0.76787
433.28699, 54.54833,    -0.94254,84.11357,50.00000,0.0000e+000,20.00000,    -0.11829,0.76639
435.02600, 54.72333,    -0.94840,84.09284,50.00000,0.0000e+000,20.00000,    -0.11959,0.76491
436.76099, 54.89833,    -0.95410,84.07149,50.00000,0.0000e+000,20.00000,    -0.12054,0.76345
438.49799, 55.07333,    -0.95976,84.05022,50.00000,0.0000e+000,20.00000,    -0.12148,0.76198
440.23801, 55.24833,    -0.96469,84.02926,50.00000,0.0000e+000,20.00000,    -0.12233,0.76053
441.97198, 55.42333,    -0.96879,84.00924,50.00000,0.0000e+000,20.00000,    -0.12275,0.75908
443.71600, 55.59833,    -0.97305,83.98884,50.00000,0.0000e+000,20.00000,    -0.12371,0.75762
445.44400, 55.77333,    -0.97763,83.96709,50.00000,0.0000e+000,20.00000,    -0.12502,0.75619
447.18100, 55.94833,    -0.98227,83.94625,50.00000,0.0000e+000,20.00000,    -0.12499,0.75476
448.91501, 56.12333,    -0.98800,83.92568,50.00000,0.0000e+000,20.00000,    -0.12524,0.75333
450.67001, 56.29833,    -0.99301,83.90346,50.00000,0.0000e+000,20.00000,    -0.12621,0.75189
452.40701, 56.47333,    -0.99837,83.88051,50.00000,0.0000e+000,20.00000,    -0.12713,0.75047
454.15900, 56.64833,    -1.00323,83.85751,50.00000,0.0000e+000,20.00000,    -0.12837,0.74905
455.89301, 56.82333,    -1.00772,83.83501,50.00000,0.0000e+000,20.00000,    -0.12993,0.74764
457.63400, 56.99833,    -1.01323,83.81167,50.00000,0.0000e+000,20.00000,    -0.13152,0.74624
459.37500, 57.17333,    -1.01764,83.78866,50.00000,0.0000e+000,20.00000,    -0.13305,0.74484
461.12601, 57.34833,    -1.02238,83.76510,50.00000,0.0000e+000,20.00000,    -0.13411,0.74344
462.87100, 57.52333,    -1.02853,83.74109,50.00000,0.0000e+000,20.00000,    -0.13522,0.74205
464.62900, 57.69833,    -1.03488,83.71805,50.00000,0.0000e+000,20.00000,    -0.13746,0.74065
466.36801, 57.87333,    -1.03916,83.69593,50.00000,0.0000e+000,20.00000,    -0.13978,0.73927
468.09201, 58.04833,    -1.03959,83.67209,50.00000,0.0000e+000,20.00000,    -0.14168,0.73792
469.81699, 58.22333,    -1.04045,83.64815,50.00000,0.0000e+000,20.00000,    -0.14336,0.73656
471.55200, 58.39833,    -1.04407,83.62340,50.00000,0.0000e+000,20.00000,    -0.14453,0.73520
473.28400, 58.57333,    -1.05044,83.59677,50.00000,0.0000e+000,20.00000,    -0.14589,0.73386
475.04099, 58.74833,    -1.05692,83.56961,50.00000,0.0000e+000,20.00000,    -0.14749,0.73249
476.80301, 58.92333,    -1.06339,83.54308,50.00000,0.0000e+000,20.00000,    -0.14932,0.73113
478.57101, 59.09833,    -1.07036,83.51815,50.00000,0.0000e+000,20.00000,    -0.15108,0.72977
480.32700, 59.27333,    -1.07579,83.49449,50.00000,0.0000e+000,20.00000,    -0.15232,0.72843
482.08701, 59.44833,    -1.07891,83.46616,50.00000,0.0000e+000,20.00000,    -0.15413,0.72708
483.82999, 59.62333,    -1.08036,83.43653,50.00000,0.0000e+000,20.00000,    -0.15719,0.72576
485.57901, 59.79833,    -1.08134,83.40845,50.00000,0.0000e+000,20.00000,    -0.15924,0.72443
487.29199, 59.97333,    -1.08262,83.37929,50.00000,0.0000e+000,20.00000,    -0.16107,0.72314
489.01401, 60.14833,    -1.08386,83.35145,50.00000,0.0000e+000,20.00000,    -0.16256,0.72185
490.73999, 60.32333,    -1.08674,83.32408,50.00000,0.0000e+000,20.00000,    -0.16385,0.72056
492.46899, 60.49833,    -1.08934,83.29595,50.00000,0.0000e+000,20.00000,    -0.16457,0.71927
494.18600, 60.67333,    -1.09267,83.26633,50.00000,0.0000e+000,20.00000,    -0.16476,0.71800
495.91199, 60.84833,    -1.09729,83.23646,50.00000,0.0000e+000,20.00000,    -0.16623,0.71672
497.63400, 61.02333,    -1.10209,83.20749,50.00000,0.0000e+000,20.00000,    -0.16825,0.71546
499.38000, 61.19833,    -1.11094,83.17873,50.00000,0.0000e+000,20.00000,    -0.16976,0.71418
501.16299, 61.37333,    -1.12077,83.14590,50.00000,0.0000e+000,20.00000,    -0.17076,0.71288
502.91599, 61.54833,    -1.12838,83.11415,50.00000,0.0000e+000,20.00000,    -0.17163,0.71160
504.69000, 61.72333,    -1.13386,83.08357,50.00000,0.0000e+000,20.00000,    -0.17235,0.71032
506.44901, 61.89833,    -1.13708,83.05348,50.00000,0.0000e+000,20.00000,    -0.17297,0.70905
508.20499, 62.07333,    -1.13886,83.02363,50.00000,0.0000e+000,20.00000,    -0.17350,0.70779
509.94800, 62.24833,    -1.13960,82.99281,50.00000,0.0000e+000,20.00000,    -0.17475,0.70654
511.68701, 62.42333,    -1.14156,82.96498,50.00000,0.0000e+000,20.00000,    -0.17603,0.70531
513.43701, 62.59833,    -1.14333,82.93543,50.00000,0.0000e+000,20.00000,    -0.17686,0.70407
515.17499, 62.77333,    -1.14674,82.90379,50.00000,0.0000e+000,20.00000,    -0.17751,0.70284
516.89899, 62.94833,    -1.15043,82.87312,50.00000,0.0000e+000,20.00000,    -0.17831,0.70163
518.64398, 63.12333,    -1.15329,82.84009,50.00000,0.0000e+000,20.00000,    -0.17856,0.70041
520.38800, 63.29833,    -1.15661,82.80739,50.00000,0.0000e+000,20.00000,    -0.17870,0.69919
522.13098, 63.47333,    -1.16051,82.77627,50.00000,0.0000e+000,20.00000,    -0.17960,0.69798
523.86499, 63.64833,    -1.16519,82.74475,50.00000,0.0000e+000,20.00000,    -0.18059,0.69678
525.59900, 63.82333,    -1.16794,82.71523,50.00000,0.0000e+000,20.00000,    -0.18236,0.69559
527.34399, 63.99833,    -1.17243,82.68447,50.00000,0.0000e+000,20.00000,    -0.18419,0.69439
529.09998, 64.17333,    -1.17676,82.65115,50.00000,0.0000e+000,20.00000,    -0.18637,0.69319
530.84601, 64.34834,    -1.18133,82.61762,50.00000,0.0000e+000,20.00000,    -0.18834,0.69201
532.59198, 64.52333,    -1.18534,82.58537,50.00000,0.0000e+000,20.00000,    -0.18898,0.69083
534.33899, 64.69833,    -1.18805,82.55387,50.00000,0.0000e+000,20.00000,    -0.19014,0.68965
536.08801, 64.87334,    -1.19200,82.52245,50.00000,0.0000e+000,20.00000,    -0.19117,0.68847
537.83600, 65.04833,    -1.19457,82.48970,50.00000,0.0000e+000,20.00000,    -0.19185,0.68731
539.57501, 65.22334,    -1.19614,82.45570,50.00000,0.0000e+000,20.00000,    -0.19337,0.68615
541.30200, 65.39833,    -1.19738,82.42188,50.00000,0.0000e+000,20.00000,    -0.19487,0.68501
543.03302, 65.57333,    -1.19963,82.38674,50.00000,0.0000e+000,20.00000,    -0.19636,0.68386
544.78601, 65.74834,    -1.20341,82.34976,50.00000,0.0000e+000,20.00000,    -0.19826,0.68271
546.52502, 65.92333,    -1.20845,82.31214,50.00000,0.0000e+000,20.00000,    -0.19955,0.68157
548.27301, 66.09834,    -1.21425,82.27592,50.00000,0.0000e+000,20.00000,    -0.20041,0.68043
550.01898, 66.27333,    -1.21896,82.24200,50.00000,0.0000e+000,20.00000,    -0.20108,0.67930
551.77600, 66.44833,    -1.22210,82.20750,50.00000,0.0000e+000,20.00000,    -0.20192,0.67817
553.52698, 66.62334,    -1.22781,82.17201,50.00000,0.0000e+000,20.00000,    -0.20326,0.67704
555.28497, 66.79833,    -1.22971,82.13641,50.00000,0.0000e+000,20.00000,    -0.20479,0.67592
557.01398, 66.97334,    -1.23032,82.09978,50.00000,0.0000e+000,20.00000,    -0.20577,0.67481
558.77502, 67.14833,    -1.23487,82.06265,50.00000,0.0000e+000,20.00000,    -0.20669,0.67369
560.55298, 67.32333,    -1.24061,82.02625,50.00000,0.0000e+000,20.00000,    -0.20776,0.67257
562.32703, 67.49834,    -1.24783,81.99018,50.00000,0.0000e+000,20.00000,    -0.20813,0.67145
564.09998, 67.67333,    -1.25284,81.95321,50.00000,0.0000e+000,20.00000,    -0.20718,0.67034
565.86902, 67.84834,    -1.25524,81.91602,50.00000,0.0000e+000,20.00000,    -0.20557,0.66924
567.59497, 68.02333,    -1.25517,81.88002,50.00000,0.0000e+000,20.00000,    -0.20549,0.66817
569.34601, 68.19833,    -1.25395,81.84525,50.00000,0.0000e+000,20.00000,    -0.20606,0.66708
571.08002, 68.37334,    -1.25248,81.80978,50.00000,0.0000e+000,20.00000,    -0.20584,0.66601
572.82800, 68.54833,    -1.25435,81.77266,50.00000,0.0000e+000,20.00000,    -0.20566,0.66494
574.57202, 68.72334,    -1.26185,81.73508,50.00000,0.0000e+000,20.00000,    -0.20645,0.66388
576.34302, 68.89833,    -1.26909,81.69804,50.00000,0.0000e+000,20.00000,    -0.20696,0.66280
578.09601, 69.07333,    -1.27459,81.66027,50.00000,0.0000e+000,20.00000,    -0.20657,0.66174
579.84100, 69.24834,    -1.27828,81.62189,50.00000,0.0000e+000,20.00000,    -0.20642,0.66069
581.58398, 69.42333,    -1.28001,81.58605,50.00000,0.0000e+000,20.00000,    -0.20642,0.65964
583.34698, 69.59834,    -1.28554,81.55423,50.00000,0.0000e+000,20.00000,    -0.20644,0.65859
585.09998, 69.77333,    -1.29160,81.52155,50.00000,0.0000e+000,20.00000,    -0.20701,0.65754
586.85199, 69.94833,    -1.29482,81.48570,50.00000,0.0000e+000,20.00000,    -0.20839,0.65650
588.60999, 70.12334,    -1.29660,81.45037,50.00000,0.0000e+000,20.00000,    -0.20990,0.65547
590.36499, 70.29833,    -1.30120,81.41646,50.00000,0.0000e+000,20.00000,    -0.21087,0.65444
592.09497, 70.47334,    -1.30031,81.37920,50.00000,0.0000e+000,20.00000,    -0.21161,0.65342
593.81403, 70.64833,    -1.30258,81.33950,50.00000,0.0000e+000,20.00000,    -0.21237,0.65242
595.54498, 70.82333,    -1.30566,81.30254,50.00000,0.0000e+000,20.00000,    -0.21304,0.65142
597.30200, 70.99834,    -1.31011,81.26776,50.00000,0.0000e+000,20.00000,    -0.21364,0.65040
599.03400, 71.17333,    -1.31485,81.23138,50.00000,0.0000e+000,20.00000,    -0.21488,0.64941
600.78601, 71.34834,    -1.31976,81.19465,50.00000,0.0000e+000,20.00000,    -0.21714,0.64840
602.53101, 71.52333,    -1.32545,81.15641,50.00000,0.0000e+000,20.00000,    -0.21999,0.64741
604.29401, 71.69833,    -1.33017,81.11699,50.00000,0.0000e+000,20.00000,    -0.22182,0.64641
606.03400, 71.87334,    -1.33401,81.07624,50.00000,0.0000e+000,20.00000,    -0.22328,0.64542
607.79797, 72.04833,    -1.33827,81.03630,50.00000,0.0000e+000,20.00000,    -0.22553,0.64443
609.56097, 72.22334,    -1.34192,80.99606,50.00000,0.0000e+000,20.00000,    -0.22761,0.64344
611.30603, 72.39833,    -1.34504,80.95593,50.00000,0.0000e+000,20.00000,    -0.22873,0.64247
613.06000, 72.57333,    -1.34852,80.91608,50.00000,0.0000e+000,20.00000,    -0.23009,0.64149
614.82703, 72.74834,    -1.35179,80.87611,50.00000,0.0000e+000,20.00000,    -0.23257,0.64051
616.57098, 72.92333,    -1.35452,80.83464,50.00000,0.0000e+000,20.00000,    -0.23504,0.63955
618.33899, 73.09834,    -1.35767,80.79279,50.00000,0.0000e+000,20.00000,    -0.23733,0.63858
620.08801, 73.27333,    -1.35986,80.75095,50.00000,0.0000e+000,20.00000,    -0.23966,0.63763
621.82397, 73.44833,    -1.36117,80.70927,50.00000,0.0000e+000,20.00000,    -0.24145,0.63668
623.58099, 73.62334,    -1.36302,80.66804,50.00000,0.0000e+000,20.00000,    -0.24206,0.63573
625.31702, 73.79833,    -1.36574,80.62617,50.00000,0.0000e+000,20.00000,    -0.24278,0.63479
627.07898, 73.97334,    -1.36923,80.58337,50.00000,0.0000e+000,20.00000,    -0.24422,0.63385
628.82397, 74.14833,    -1.37314,80.54031,50.00000,0.0000e+000,20.00000,    -0.24586,0.63291
630.60400, 74.32333,    -1.37765,80.49675,50.00000,0.0000e+000,20.00000,    -0.24771,0.63196
632.34198, 74.49834,    -1.38018,80.45292,50.00000,0.0000e+000,20.00000,    -0.24985,0.63104
634.11902, 74.67333,    -1.38223,80.40831,50.00000,0.0000e+000,20.00000,    -0.25171,0.63010
635.85699, 74.84834,    -1.38408,80.36357,50.00000,0.0000e+000,20.00000,    -0.25278,0.62919
637.61298, 75.02333,    -1.38405,80.31807,50.00000,0.0000e+000,20.00000,    -0.25343,0.62827
639.37500, 75.19833,    -1.38707,80.27189,50.00000,0.0000e+000,20.00000,    -0.25413,0.62735
641.12201, 75.37334,    -1.39206,80.22826,50.00000,0.0000e+000,20.00000,    -0.25526,0.62644
642.88300, 75.54833,    -1.39477,80.18584,50.00000,0.0000e+000,20.00000,    -0.25575,0.62553
644.64203, 75.72334,    -1.39835,80.14160,50.00000,0.0000e+000,20.00000,    -0.25519,0.62462
646.38599, 75.89833,    -1.40016,80.09560,50.00000,0.0000e+000,20.00000,    -0.25501,0.62373
648.12903, 76.07333,    -1.39920,80.04907,50.00000,0.0000e+000,20.00000,    -0.25483,0.62284
649.87598, 76.24834,    -1.39919,80.00189,50.00000,0.0000e+000,20.00000,    -0.25447,0.62195
651.62097, 76.42333,    -1.40042,79.95415,50.00000,0.0000e+000,20.00000,    -0.25391,0.62106
653.36700, 76.59834,    -1.40402,79.90731,50.00000,0.0000e+000,20.00000,    -0.25363,0.62018
655.12201, 76.77333,    -1.40820,79.86274,50.00000,0.0000e+000,20.00000,    -0.25380,0.61930
656.92200, 76.94833,    -1.41984,79.81857,50.00000,0.0000e+000,20.00000,    -0.25348,0.61840
658.71503, 77.12334,    -1.42844,79.77353,50.00000,0.0000e+000,20.00000,    -0.25270,0.61750
660.51099, 77.29833,    -1.43156,79.72866,50.00000,0.0000e+000,20.00000,    -0.25212,0.61661
662.25702, 77.47334,    -1.42854,79.68756,50.00000,0.0000e+000,20.00000,    -0.25088,0.61575
663.99298, 77.64833,    -1.42376,79.64634,50.00000,0.0000e+000,20.00000,    -0.24879,0.61489
665.70300, 77.82333,    -1.41795,79.60355,50.00000,0.0000e+000,20.00000,    -0.24692,0.61406
667.39301, 77.99834,    -1.41136,79.56100,50.00000,0.0000e+000,20.00000,    -0.24517,0.61323
669.15997, 78.17333,    -1.41558,79.51887,50.00000,0.0000e+000,20.00000,    -0.24335,0.61237
670.92603, 78.34834,    -1.42572,79.47604,50.00000,0.0000e+000,20.00000,    -0.24118,0.61151
672.70697, 78.52333,    -1.43283,79.43105,50.00000,0.0000e+000,20.00000,    -0.23946,0.61065
674.47302, 78.69833,    -1.43601,79.38540,50.00000,0.0000e+000,20.00000,    -0.23830,0.60980
676.21198, 78.87334,    -1.43671,79.34189,50.00000,0.0000e+000,20.00000,    -0.23688,0.60897
677.97998, 79.04833,    -1.43759,79.30093,50.00000,0.0000e+000,20.00000,    -0.23504,0.60813
679.73602, 79.22334,    -1.43817,79.26145,50.00000,0.0000e+000,20.00000,    -0.23388,0.60729
681.47498, 79.39833,    -1.43716,79.22355,50.00000,0.0000e+000,20.00000,    -0.23387,0.60647
683.21503, 79.57333,    -1.43689,79.18493,50.00000,0.0000e+000,20.00000,    -0.23318,0.60565
684.96002, 79.74834,    -1.43677,79.14485,50.00000,0.0000e+000,20.00000,    -0.23132,0.60483
686.70099, 79.92333,    -1.43888,79.10390,50.00000,0.0000e+000,20.00000,    -0.22977,0.60401
688.45599, 80.09834,    -1.44008,79.06361,50.00000,0.0000e+000,20.00000,    -0.22903,0.60320
690.19501, 80.27333,    -1.44239,79.02457,50.00000,0.0000e+000,20.00000,    -0.22858,0.60239
691.95898, 80.44833,    -1.44293,78.98479,50.00000,0.0000e+000,20.00000,    -0.22687,0.60157
693.69202, 80.62334,    -1.44224,78.94522,50.00000,0.0000e+000,20.00000,    -0.22470,0.60077
695.45502, 80.79833,    -1.44377,78.90617,50.00000,0.0000e+000,20.00000,    -0.22331,0.59997
697.19800, 80.97334,    -1.44432,78.86774,50.00000,0.0000e+000,20.00000,    -0.22189,0.59917
698.93298, 81.14833,    -1.44239,78.82832,50.00000,0.0000e+000,20.00000,    -0.22048,0.59838
700.65900, 81.32333,    -1.43990,78.78738,50.00000,0.0000e+000,20.00000,    -0.21828,0.59759
702.41998, 81.49834,    -1.43819,78.75000,50.00000,0.0000e+000,20.00000,    -0.21399,0.59680
704.16302, 81.67333,    -1.44008,78.71424,50.00000,0.0000e+000,20.00000,    -0.20867,0.59601
705.94000, 81.84834,    -1.44448,78.67610,50.00000,0.0000e+000,20.00000,    -0.20338,0.59521
707.71100, 82.02333,    -1.44788,78.63461,50.00000,0.0000e+000,20.00000,    -0.19842,0.59442
709.45697, 82.19833,    -1.44675,78.59306,50.00000,0.0000e+000,20.00000,    -0.19352,0.59364
711.20898, 82.37334,    -1.44440,78.55589,50.00000,0.0000e+000,20.00000,    -0.18840,0.59287
712.96503, 82.54833,    -1.44849,78.51877,50.00000,0.0000e+000,20.00000,    -0.18325,0.59209
714.72803, 82.72334,    -1.45444,78.48302,50.00000,0.0000e+000,20.00000,    -0.17764,0.59131
716.50098, 82.89833,    -1.46104,78.44888,50.00000,0.0000e+000,20.00000,    -0.17153,0.59053
718.27002, 83.07333,    -1.46774,78.41704,50.00000,0.0000e+000,20.00000,    -0.16544,0.58976
720.00702, 83.24834,    -1.47204,78.39041,50.00000,0.0000e+000,20.00000,    -0.15976,0.58900
721.71600, 83.42333,    -1.46961,78.36882,50.00000,0.0000e+000,20.00000,    -0.15499,0.58826
723.47998, 83.59834,    -1.47942,78.34742,50.00000,0.0000e+000,20.00000,    -0.14966,0.58750
725.27698, 83.77333,    -1.49178,78.32600,50.00000,0.0000e+000,20.00000,    -0.14276,0.58672
727.06403, 83.94833,    -1.49761,78.30471,50.00000,0.0000e+000,20.00000,    -0.13461,0.58595
728.82397, 84.12334,    -1.49805,78.28329,50.00000,0.0000e+000,20.00000,    -0.12843,0.58520
730.58398, 84.29833,    -1.49665,78.26262,50.00000,0.0000e+000,20.00000,    -0.12304,0.58445
732.34302, 84.47334,    -1.49297,78.24297,50.00000,0.0000e+000,20.00000,    -0.11788,0.58370
734.09100, 84.64833,    -1.48833,78.22655,50.00000,0.0000e+000,20.00000,    -0.11272,0.58296
735.80603, 84.82333,    -1.48530,78.20907,50.00000,0.0000e+000,20.00000,    -0.10726,0.58223
737.56500, 84.99834,    -1.48329,78.19027,50.00000,0.0000e+000,20.00000,    -0.10308,0.58149
739.31500, 85.17333,    -1.48293,78.17182,50.00000,0.0000e+000,20.00000,    -0.10064,0.58076
741.05603, 85.34834,    -1.48419,78.15389,50.00000,0.0000e+000,20.00000,-9.8965e-002,0.58003
742.80298, 85.52333,    -1.48395,78.13760,50.00000,0.0000e+000,20.00000,-9.7150e-002,0.57930
744.54401, 85.69833,    -1.48128,78.12482,50.00000,0.0000e+000,20.00000,-9.5150e-002,0.57858
746.28101, 85.87334,    -1.48058,78.11022,50.00000,0.0000e+000,20.00000,-9.2194e-002,0.57786
748.04102, 86.04833,    -1.48193,78.09315,50.00000,0.0000e+000,20.00000,-8.9777e-002,0.57713
749.78497, 86.22334,    -1.47945,78.07564,50.00000,0.0000e+000,20.00000,-8.8181e-002,0.57641
751.54602, 86.39833,    -1.47659,78.05834,50.00000,0.0000e+000,20.00000,-8.7506e-002,0.57569
753.28802, 86.57333,    -1.47356,78.04450,50.00000,0.0000e+000,20.00000,-8.6276e-002,0.57498
755.04602, 86.74834,    -1.47158,78.03095,50.00000,0.0000e+000,20.00000,-8.4464e-002,0.57426
756.78802, 86.92333,    -1.47061,78.01669,50.00000,0.0000e+000,20.00000,-8.2886e-002,0.57355
758.54199, 87.09834,    -1.47109,78.00194,50.00000,0.0000e+000,20.00000,-8.0497e-002,0.57284
760.30902, 87.27333,    -1.47179,77.98696,50.00000,0.0000e+000,20.00000,-7.8312e-002,0.57213
762.06598, 87.44833,    -1.47113,77.97218,50.00000,0.0000e+000,20.00000,-7.7693e-002,0.57142
763.83002, 87.62334,    -1.46994,77.96031,50.00000,0.0000e+000,20.00000,-7.7531e-002,0.57071
765.58502, 87.79833,    -1.46786,77.94933,50.00000,0.0000e+000,20.00000,-7.6659e-002,0.57001
767.33301, 87.97334,    -1.46637,77.93576,50.00000,0.0000e+000,20.00000,-7.5833e-002,0.56931
769.07800, 88.14833,    -1.46536,77.92034,50.00000,0.0000e+000,20.00000,-7.4495e-002,0.56861
770.84900, 88.32333,    -1.46660,77.90668,50.00000,0.0000e+000,20.00000,-7.3231e-002,0.56791
772.62201, 88.49834,    -1.46763,77.89547,50.00000,0.0000e+000,20.00000,-7.2393e-002,0.56721
774.39801, 88.67333,    -1.46984,77.88250,50.00000,0.0000e+000,20.00000,-7.1389e-002,0.56651
776.15997, 88.84834,    -1.47318,77.87124,50.00000,0.0000e+000,20.00000,-7.0124e-002,0.56582
777.92700, 89.02333,    -1.47265,77.86276,50.00000,0.0000e+000,20.00000,-6.9248e-002,0.56512
779.68298, 89.19833,    -1.47188,77.85169,50.00000,0.0000e+000,20.00000,-6.9161e-002,0.56443
781.42102, 89.37334,    -1.47087,77.83935,50.00000,0.0000e+000,20.00000,-6.8838e-002,0.56376
783.19702, 89.54833,    -1.47489,77.82671,50.00000,0.0000e+000,20.00000,-6.8996e-002,0.56306
784.96899, 89.72334,    -1.48121,77.81249,50.00000,0.0000e+000,20.00000,-6.8415e-002,0.56238
786.73102, 89.89833,    -1.48235,77.79897,50.00000,0.0000e+000,20.00000,-6.7494e-002,0.56169
788.48102, 90.07333,    -1.48475,77.78716,50.00000,0.0000e+000,20.00000,-6.6580e-002,0.56102
790.23297, 90.24834,    -1.48930,77.77704,50.00000,0.0000e+000,20.00000,-6.6482e-002,0.56034
791.97498, 90.42333,    -1.49135,77.76669,50.00000,0.0000e+000,20.00000,-6.6715e-002,0.55968
793.74402, 90.59834,    -1.49392,77.75659,50.00000,0.0000e+000,20.00000,-6.6846e-002,0.55900
795.48401, 90.77333,    -1.49842,77.74621,50.00000,0.0000e+000,20.00000,-6.7617e-002,0.55833
797.23901, 90.94833,    -1.50209,77.73232,50.00000,0.0000e+000,20.00000,-6.8759e-002,0.55766
798.96002, 91.12334,    -1.50453,77.71855,50.00000,0.0000e+000,20.00000,-6.9576e-002,0.55701
800.71997, 91.29833,    -1.50907,77.70727,50.00000,0.0000e+000,20.00000,-6.9863e-002,0.55634
802.46301, 91.47334,    -1.51216,77.69645,50.00000,0.0000e+000,20.00000,-6.9717e-002,0.55568
804.22601, 91.64833,    -1.51631,77.68591,50.00000,0.0000e+000,20.00000,-6.9466e-002,0.55502
805.98798, 91.82333,    -1.52330,77.67386,50.00000,0.0000e+000,20.00000,-6.9499e-002,0.55435
807.75702, 91.99834,    -1.52774,77.66271,50.00000,0.0000e+000,20.00000,-7.0314e-002,0.55369
809.51300, 92.17333,    -1.52911,77.65047,50.00000,0.0000e+000,20.00000,-7.1229e-002,0.55303
811.27301, 92.34834,    -1.52953,77.63705,50.00000,0.0000e+000,20.00000,-7.2205e-002,0.55237
813.00598, 92.52333,    -1.52961,77.62468,50.00000,0.0000e+000,20.00000,-7.3759e-002,0.55172
814.74402, 92.69833,    -1.52955,77.61219,50.00000,0.0000e+000,20.00000,-7.5207e-002,0.55108
816.50299, 92.87334,    -1.53064,77.59705,50.00000,0.0000e+000,20.00000,-7.5926e-002,0.55042
818.24902, 93.04833,    -1.53163,77.58286,50.00000,0.0000e+000,20.00000,-7.7082e-002,0.54978
819.99597, 93.22334,    -1.53352,77.56988,50.00000,0.0000e+000,20.00000,-7.8391e-002,0.54913
821.74500, 93.39833,    -1.53383,77.55671,50.00000,0.0000e+000,20.00000,-7.9957e-002,0.54848
823.50702, 93.57333,    -1.53742,77.54377,50.00000,0.0000e+000,20.00000,-8.1540e-002,0.54783
825.31702, 93.74834,    -1.54758,77.53053,50.00000,0.0000e+000,20.00000,-8.3773e-002,0.54717
827.09497, 93.92333,    -1.55048,77.51703,50.00000,0.0000e+000,20.00000,-8.6155e-002,0.54652
828.84198, 94.09834,    -1.54860,77.50322,50.00000,0.0000e+000,20.00000,-8.7236e-002,0.54588
830.59100, 94.27333,    -1.54635,77.48879,50.00000,0.0000e+000,20.00000,-8.8377e-002,0.54524
832.33502, 94.44833,    -1.54573,77.47180,50.00000,0.0000e+000,20.00000,-9.0935e-002,0.54460
834.08197, 94.62334,    -1.54588,77.45423,50.00000,0.0000e+000,20.00000,-9.3326e-002,0.54396
835.83099, 94.79833,    -1.54792,77.43760,50.00000,0.0000e+000,20.00000,-9.5884e-002,0.54333
837.59198, 94.97334,    -1.55085,77.42158,50.00000,0.0000e+000,20.00000,-9.9061e-002,0.54269
839.34198, 95.14833,    -1.55358,77.40571,50.00000,0.0000e+000,20.00000,    -0.10210,0.54205
841.11499, 95.32333,    -1.55381,77.38915,50.00000,0.0000e+000,20.00000,    -0.10503,0.54141
842.87201, 95.49834,    -1.55614,77.37035,50.00000,0.0000e+000,20.00000,    -0.10829,0.54078
844.62097, 95.67333,    -1.55740,77.35004,50.00000,0.0000e+000,20.00000,    -0.11158,0.54015
846.37799, 95.84834,    -1.55835,77.33123,50.00000,0.0000e+000,20.00000,    -0.11468,0.53952
848.12097, 96.02333,    -1.56011,77.31509,50.00000,0.0000e+000,20.00000,    -0.11724,0.53889
849.88202, 96.19833,    -1.56185,77.29542,50.00000,0.0000e+000,20.00000,    -0.11951,0.53826
851.63800, 96.37334,    -1.56433,77.27309,50.00000,0.0000e+000,20.00000,    -0.12163,0.53763
853.39600, 96.54833,    -1.56532,77.24934,50.00000,0.0000e+000,20.00000,    -0.12412,0.53700
855.13599, 96.72334,    -1.56644,77.22457,50.00000,0.0000e+000,20.00000,    -0.12667,0.53638
856.87799, 96.89833,    -1.56825,77.19995,50.00000,0.0000e+000,20.00000,    -0.12972,0.53576
858.62701, 97.07333,    -1.57003,77.17618,50.00000,0.0000e+000,20.00000,    -0.13295,0.53514
860.40198, 97.24834,    -1.57156,77.15186,50.00000,0.0000e+000,20.00000,    -0.13562,0.53451
862.16400, 97.42333,    -1.57545,77.12648,50.00000,0.0000e+000,20.00000,    -0.13816,0.53388
863.94098, 97.59834,    -1.57923,77.10107,50.00000,0.0000e+000,20.00000,    -0.14101,0.53325
865.68500, 97.77333,    -1.58041,77.07714,50.00000,0.0000e+000,20.00000,    -0.14466,0.53263
867.43298, 97.94833,    -1.58013,77.05364,50.00000,0.0000e+000,20.00000,    -0.14771,0.53202
869.16498, 98.12334,    -1.57975,77.02875,50.00000,0.0000e+000,20.00000,    -0.14991,0.53140
870.92902, 98.29833,    -1.58165,77.00280,50.00000,0.0000e+000,20.00000,    -0.15158,0.53078
872.68402, 98.47334,    -1.58452,76.97691,50.00000,0.0000e+000,20.00000,    -0.15252,0.53016
874.45697, 98.64833,    -1.58484,76.95085,50.00000,0.0000e+000,20.00000,    -0.15376,0.52954
876.19702, 98.82333,    -1.58691,76.92307,50.00000,0.0000e+000,20.00000,    -0.15547,0.52893
877.94897, 98.99834,    -1.58729,76.89549,50.00000,0.0000e+000,20.00000,    -0.15710,0.52831
879.69501, 99.17333,    -1.58823,76.86731,50.00000,0.0000e+000,20.00000,    -0.15898,0.52770
881.44299, 99.34834,    -1.58946,76.83719,50.00000,0.0000e+000,20.00000,    -0.16079,0.52709
883.20502, 99.52333,    -1.59275,76.80675,50.00000,0.0000e+000,20.00000,    -0.16255,0.52647
884.96198, 99.69833,    -1.59793,76.77757,50.00000,0.0000e+000,20.00000,    -0.16457,0.52586
886.74103, 99.87334,    -1.60034,76.74837,50.00000,0.0000e+000,20.00000,    -0.16673,0.52524
888.48499,100.04833,    -1.60134,76.71878,50.00000,0.0000e+000,20.00000,    -0.16921,0.52463
890.24298,100.22334,    -1.60098,76.69043,50.00000,0.0000e+000,20.00000,    -0.17163,0.52401
891.99902,100.39833,    -1.60066,76.66209,50.00000,0.0000e+000,20.00000,    -0.17426,0.52340
893.76202,100.57333,    -1.60249,76.63178,50.00000,0.0000e+000,20.00000,    -0.17659,0.52279
895.53802,100.74834,    -1.60696,76.60188,50.00000,0.0000e+000,20.00000,    -0.17868,0.52217
897.36603,100.92333,    -1.62250,76.57110,50.00000,0.0000e+000,20.00000,    -0.18081,0.52154
899.14899,101.09834,    -1.62586,76.53864,50.00000,0.0000e+000,20.00000,    -0.18213,0.52092
900.91699,101.27333,    -1.62122,76.50712,50.00000,0.0000e+000,20.00000,    -0.18347,0.52030
902.65100,101.44833,    -1.61657,76.47624,50.00000,0.0000e+000,20.00000,    -0.18514,0.51970
904.37701,101.62334,    -1.61238,76.44513,50.00000,0.0000e+000,20.00000,    -0.18720,0.51910
906.11200,101.79833,    -1.61026,76.41145,50.00000,0.0000e+000,20.00000,    -0.18943,0.51850
907.85797,101.97334,    -1.61112,76.37637,50.00000,0.0000e+000,20.00000,    -0.19179,0.51790
909.59900,102.14833,    -1.61474,76.34142,50.00000,0.0000e+000,20.00000,    -0.19370,0.51729
911.32800,102.32333,    -1.61381,76.30583,50.00000,0.0000e+000,20.00000,    -0.19515,0.51670
913.04498,102.49834,    -1.61011,76.27026,50.00000,0.0000e+000,20.00000,    -0.19697,0.51610
914.78003,102.67333,    -1.60951,76.23468,50.00000,0.0000e+000,20.00000,    -0.19944,0.51550
916.59497,102.84834,    -1.62663,76.20016,50.00000,0.0000e+000,20.00000,    -0.20099,0.51488
918.41101,103.02333,    -1.63186,76.16542,50.00000,0.0000e+000,20.00000,    -0.20220,0.51425
920.22400,103.19833,    -1.64050,76.12954,50.00000,0.0000e+000,20.00000,    -0.20381,0.51362
922.08301,103.37334,    -1.65363,76.09349,50.00000,0.0000e+000,20.00000,    -0.20551,0.51298
923.85101,103.54833,    -1.65131,76.05633,50.00000,0.0000e+000,20.00000,    -0.20628,0.51237
925.59698,103.72334,    -1.64152,76.01820,50.00000,0.0000e+000,20.00000,    -0.20617,0.51177
927.32599,103.89833,    -1.63255,75.98210,50.00000,0.0000e+000,20.00000,    -0.20669,0.51118
929.03003,104.07333,    -1.62281,75.94771,50.00000,0.0000e+000,20.00000,    -0.20709,0.51059
930.76398,104.24834,    -1.62060,75.91176,50.00000,0.0000e+000,20.00000,    -0.20715,0.50999
932.50098,104.42333,    -1.61903,75.87344,50.00000,0.0000e+000,20.00000,    -0.20664,0.50939
934.22803,104.59834,    -1.61411,75.83482,50.00000,0.0000e+000,20.00000,    -0.20512,0.50880
935.95398,104.77333,    -1.61001,75.79809,50.00000,0.0000e+000,20.00000,    -0.20338,0.50820
937.66998,104.94833,    -1.60403,75.76133,50.00000,0.0000e+000,20.00000,    -0.20135,0.50761
939.39398,105.12334,    -1.59873,75.72429,50.00000,0.0000e+000,20.00000,    -0.19836,0.50702
941.12701,105.29833,    -1.59593,75.68802,50.00000,0.0000e+000,20.00000,    -0.19464,0.50642
942.85400,105.47334,    -1.59421,75.65380,50.00000,0.0000e+000,20.00000,    -0.18949,0.50583
944.60699,105.64833,    -1.59177,75.61799,50.00000,0.0000e+000,20.00000,    -0.18393,0.50523
946.34198,105.82333,    -1.58832,75.58091,50.00000,0.0000e+000,20.00000,    -0.17843,0.50463
948.08398,105.99834,    -1.58675,75.54455,50.00000,0.0000e+000,20.00000,    -0.17316,0.50403
949.84198,106.17333,    -1.58583,75.50970,50.00000,0.0000e+000,20.00000,    -0.16751,0.50342
951.59399,106.34834,    -1.58793,75.47807,50.00000,0.0000e+000,20.00000,    -0.16069,0.50282
953.35602,106.52333,    -1.59208,75.45025,50.00000,0.0000e+000,20.00000,    -0.15328,0.50221
955.11603,106.69833,    -1.59644,75.42163,50.00000,0.0000e+000,20.00000,    -0.14627,0.50161
956.88202,106.87334,    -1.60117,75.39536,50.00000,0.0000e+000,20.00000,    -0.13924,0.50100
958.64301,107.04833,    -1.60640,75.37127,50.00000,0.0000e+000,20.00000,    -0.13217,0.50039
960.39600,107.22334,    -1.60909,75.35061,50.00000,0.0000e+000,20.00000,    -0.12549,0.49979
962.17902,107.39833,    -1.61532,75.33262,50.00000,0.0000e+000,20.00000,    -0.11909,0.49917
963.93500,107.57333,    -1.61848,75.31719,50.00000,0.0000e+000,20.00000,    -0.11184,0.49857
965.71600,107.74834,    -1.62438,75.30230,50.00000,0.0000e+000,20.00000,    -0.10380,0.49795
967.46899,107.92333,    -1.62360,75.28567,50.00000,0.0000e+000,20.00000,-9.6146e-002,0.49735
969.21899,108.09834,    -1.62336,75.27012,50.00000,0.0000e+000,20.00000,-8.9062e-002,0.49675
970.97400,108.27333,    -1.62680,75.25832,50.00000,0.0000e+000,20.00000,-8.2989e-002,0.49614
972.72101,108.44833,    -1.62763,75.24815,50.00000,0.0000e+000,20.00000,-7.6963e-002,0.49554
974.46198,108.62334,    -1.63036,75.23667,50.00000,0.0000e+000,20.00000,-7.1467e-002,0.49493
976.25800,108.79833,    -1.63851,75.22560,50.00000,0.0000e+000,20.00000,-6.6424e-002,0.49431
978.01501,108.97334,    -1.64007,75.21486,50.00000,0.0000e+000,20.00000,-6.1428e-002,0.49371
979.79199,109.14833,    -1.64404,75.20401,50.00000,0.0000e+000,20.00000,-5.8192e-002,0.49309
981.55902,109.32333,    -1.64856,75.19274,50.00000,0.0000e+000,20.00000,-5.4771e-002,0.49248
983.30499,109.49834,    -1.64942,75.18425,50.00000,0.0000e+000,20.00000,-5.0430e-002,0.49187
985.04602,109.67333,    -1.64840,75.17699,50.00000,0.0000e+000,20.00000,-4.7679e-002,0.49127
986.78497,109.84834,    -1.65068,75.16912,50.00000,0.0000e+000,20.00000,-4.5317e-002,0.49067
988.51703,110.02333,    -1.64981,75.16215,50.00000,0.0000e+000,20.00000,-4.2393e-002,0.49007
990.26898,110.19833,    -1.65130,75.15567,50.00000,0.0000e+000,20.00000,-3.8080e-002,0.48946
992.02301,110.37334,    -1.65539,75.14901,50.00000,0.0000e+000,20.00000,-3.6693e-002,0.48885
993.79797,110.54833,    -1.66637,75.14127,50.00000,0.0000e+000,20.00000,-3.4966e-002,0.48823
995.57001,110.72334,    -1.67119,75.13673,50.00000,0.0000e+000,20.00000,-3.2556e-002,0.48762
997.33301,110.89833,    -1.67166,75.13119,50.00000,0.0000e+000,20.00000,-3.4630e-002,0.48700
998.37402,111.00333,    -1.67090,75.12745,50.00000,0.0000e+000,20.00000, 1.1599e-002,0.48664