File: book/some_content/TG_ExpDat_MgO5%DC28; 14-1-2025-2.csv
#FILE:                       ,MgO5%DC28; 14-1-2025.ngb-ds3
#FORMAT:                     ,NETZSCH5
#IDENTITY:                   ,GEOPOLYMER PASTE
#DECIMAL:                    ,POINT
#SEPARATOR:                  ,COMMA
#MTYPE:                      ,DSC
#INSTRUMENT:                 ,Microlab TU Delft
#PROJECT:                    ,
#DATE/TIME:                  ,14/02/2025 8:35:54 AM
#CORR. FILE:                 ,Blank with cover; 13-1-2025.ngb-bs3
#LABORATORY:                 ,TU Delft Micro Lab
#OPERATOR:                   ,Ahmed
#REMARK:                     ,under Argon atmosphere, 10K/min
#SAMPLE:                     ,MgO5%DC28
#SAMPLE MASS /mg:            ,36.2
#MATERIAL:                   ,Geopolymer paste
#REFERENCE:                  ,blank
#REFERENCE MASS /mg:         ,0
#TYPE OF CRUCIBLE:           ,DSC/TG pan Al2O3
#SAMPLE CRUCIBLE MASS /mg:   ,0
#REFERENCE CRUCIBLE MASS /mg:,0
#CORR. CODE:                 ,020
#EXO:                        ,-1
#RANGE:                      ,40/10.0(K/min)/1000
#SEGMENT:                    ,S2/2

##Temp./øC,Time/min,DSC/(mW/mg),Mass/%,Gas Flow(purge1)/(ml/min),Gas Flow(purge2)/(ml/min),Gas Flow(protective)/(ml/min),DTG/(%/min),Sensit./(uV/mW)
 39.38900, 15.43083, 1.0025e-002,98.30820,50.00000,0.0000e+000,20.00000,-2.4963e-002,1.22778
 39.40900, 15.61083, 9.4585e-003,98.30190,50.00000,0.0000e+000,20.00000,-2.3603e-002,1.22776
 39.48400, 15.79083, 8.1889e-003,98.29600,50.00000,0.0000e+000,20.00000,-2.2492e-002,1.22765
 39.58500, 15.97083, 6.7476e-003,98.29080,50.00000,0.0000e+000,20.00000,-2.1123e-002,1.22751
 39.76400, 16.15083, 4.8084e-003,98.28745,50.00000,0.0000e+000,20.00000,-1.9738e-002,1.22727
 40.01400, 16.33083, 3.2122e-003,98.28526,50.00000,0.0000e+000,20.00000,-1.8689e-002,1.22692
 40.37300, 16.51083, 1.7528e-003,98.28161,50.00000,0.0000e+000,20.00000,-1.8891e-002,1.22643
 40.79800, 16.69083, 6.8771e-005,98.27704,50.00000,0.0000e+000,20.00000,-1.9477e-002,1.22584
 41.34700, 16.87083,-1.2903e-003,98.27499,50.00000,0.0000e+000,20.00000,-2.1088e-002,1.22508
 41.94300, 17.05083,-2.5995e-003,98.27312,50.00000,0.0000e+000,20.00000,-2.2682e-002,1.22426
 42.61200, 17.23083,-3.8246e-003,98.27069,50.00000,0.0000e+000,20.00000,-2.4215e-002,1.22334
 43.41500, 17.41083,-4.6903e-003,98.26904,50.00000,0.0000e+000,20.00000,-2.5634e-002,1.22223
 44.29800, 17.59083,-4.8330e-003,98.26672,50.00000,0.0000e+000,20.00000,-2.7531e-002,1.22102
 45.25100, 17.77083,-5.8750e-003,98.26383,50.00000,0.0000e+000,20.00000,-2.9841e-002,1.21970
 46.31400, 17.95083,-6.3837e-003,98.25992,50.00000,0.0000e+000,20.00000,-3.2408e-002,1.21824
 47.45600, 18.13083,-6.8770e-003,98.25562,50.00000,0.0000e+000,20.00000,-3.5568e-002,1.21666
 48.71000, 18.31083,-7.7542e-003,98.25121,50.00000,0.0000e+000,20.00000,-3.9202e-002,1.21494
 50.01400, 18.49083,-8.0957e-003,98.24641,50.00000,0.0000e+000,20.00000,-4.3391e-002,1.21314
 51.41000, 18.67083,-9.1178e-003,98.23930,50.00000,0.0000e+000,20.00000,-4.8658e-002,1.21122
 52.89100, 18.85083,-9.7258e-003,98.23066,50.00000,0.0000e+000,20.00000,-5.4772e-002,1.20918
 54.45100, 19.03083,-1.0215e-002,98.22204,50.00000,0.0000e+000,20.00000,-6.1706e-002,1.20703
 56.09600, 19.21083,-1.1511e-002,98.21103,50.00000,0.0000e+000,20.00000,-7.0694e-002,1.20477
 57.80700, 19.39083,-1.2462e-002,98.19829,50.00000,0.0000e+000,20.00000,-8.1525e-002,1.20242
 59.61300, 19.57083,-1.3068e-002,98.18456,50.00000,0.0000e+000,20.00000,-9.2549e-002,1.19993
 61.47700, 19.75083,-1.4275e-002,98.17131,50.00000,0.0000e+000,20.00000,    -0.10450,1.19737
 63.40200, 19.93083,-1.4977e-002,98.15789,50.00000,0.0000e+000,20.00000,    -0.11857,1.19473
 65.38400, 20.11083,-1.5648e-002,98.14181,50.00000,0.0000e+000,20.00000,    -0.13448,1.19201
 67.45100, 20.29083,-1.6323e-002,98.12223,50.00000,0.0000e+000,20.00000,    -0.15189,1.18917
 69.56600, 20.47083,-1.6718e-002,98.10076,50.00000,0.0000e+000,20.00000,    -0.17098,1.18627
 71.72100, 20.65083,-1.6849e-002,98.07720,50.00000,0.0000e+000,20.00000,    -0.19264,1.18332
 73.93300, 20.83083,-1.6696e-002,98.05004,50.00000,0.0000e+000,20.00000,    -0.21568,1.18029
 76.15900, 21.01083,-1.6202e-002,98.01681,50.00000,0.0000e+000,20.00000,    -0.23689,1.17724
 78.47100, 21.19083,-1.5151e-002,97.97571,50.00000,0.0000e+000,20.00000,    -0.25882,1.17408
 80.78800, 21.37083,-1.3680e-002,97.93273,50.00000,0.0000e+000,20.00000,    -0.28182,1.17091
 83.17200, 21.55083,-1.1840e-002,97.88642,50.00000,0.0000e+000,20.00000,    -0.30484,1.16766
 85.56800, 21.73083,-9.2130e-003,97.83193,50.00000,0.0000e+000,20.00000,    -0.32869,1.16439
 87.98800, 21.91083,-6.5346e-003,97.77032,50.00000,0.0000e+000,20.00000,    -0.35266,1.16109
 90.46700, 22.09083,-3.1130e-003,97.70293,50.00000,0.0000e+000,20.00000,    -0.37610,1.15772
 92.93300, 22.27083, 6.0249e-004,97.62806,50.00000,0.0000e+000,20.00000,    -0.39903,1.15436
 95.44300, 22.45083, 4.3764e-003,97.54187,50.00000,0.0000e+000,20.00000,    -0.42151,1.15095
 97.96400, 22.63083, 8.2280e-003,97.44913,50.00000,0.0000e+000,20.00000,    -0.44349,1.14753
100.48500, 22.81083, 1.2600e-002,97.36039,50.00000,0.0000e+000,20.00000,    -0.46410,1.14412
102.99000, 22.99083, 1.6111e-002,97.26910,50.00000,0.0000e+000,20.00000,    -0.48208,1.14073
105.52600, 23.17083, 1.9217e-002,97.17150,50.00000,0.0000e+000,20.00000,    -0.49929,1.13730
108.04600, 23.35083, 2.2063e-002,97.07412,50.00000,0.0000e+000,20.00000,    -0.51532,1.13390
110.55800, 23.53083, 2.4310e-002,96.97427,50.00000,0.0000e+000,20.00000,    -0.52874,1.13051
113.06500, 23.71083, 2.5823e-002,96.87144,50.00000,0.0000e+000,20.00000,    -0.54011,1.12713
115.57700, 23.89083, 2.6350e-002,96.76681,50.00000,0.0000e+000,20.00000,    -0.54928,1.12376
118.05700, 24.07083, 2.6598e-002,96.66169,50.00000,0.0000e+000,20.00000,    -0.55618,1.12043
120.54600, 24.25083, 2.5809e-002,96.55657,50.00000,0.0000e+000,20.00000,    -0.55895,1.11709
123.05700, 24.43083, 2.4146e-002,96.44990,50.00000,0.0000e+000,20.00000,    -0.55865,1.11373
125.54000, 24.61083, 2.1637e-002,96.34256,50.00000,0.0000e+000,20.00000,    -0.55865,1.11041
127.99700, 24.79083, 1.8237e-002,96.23630,50.00000,0.0000e+000,20.00000,    -0.55832,1.10713
130.46500, 24.97083, 1.4224e-002,96.13069,50.00000,0.0000e+000,20.00000,    -0.55581,1.10385
132.90300, 25.15083, 1.0130e-002,96.02606,50.00000,0.0000e+000,20.00000,    -0.55245,1.10060
135.33099, 25.33083, 4.3980e-003,95.92394,50.00000,0.0000e+000,20.00000,    -0.54777,1.09738
137.76700, 25.51083,-1.6180e-003,95.82148,50.00000,0.0000e+000,20.00000,    -0.54092,1.09415
140.15900, 25.69083,-8.1522e-003,95.72119,50.00000,0.0000e+000,20.00000,    -0.53295,1.09099
142.54800, 25.87083,-1.5480e-002,95.62215,50.00000,0.0000e+000,20.00000,    -0.52388,1.08783
144.91400, 26.05083,-2.3452e-002,95.52691,50.00000,0.0000e+000,20.00000,    -0.51377,1.08471
147.26100, 26.23083,-3.1235e-002,95.43521,50.00000,0.0000e+000,20.00000,    -0.50314,1.08162
149.59900, 26.41083,-3.9765e-002,95.34538,50.00000,0.0000e+000,20.00000,    -0.49189,1.07855
151.89200, 26.59083,-4.8557e-002,95.25662,50.00000,0.0000e+000,20.00000,    -0.48044,1.07555
154.18900, 26.77083,-5.6789e-002,95.16820,50.00000,0.0000e+000,20.00000,    -0.46929,1.07254
156.45399, 26.95083,-6.6286e-002,95.08266,50.00000,0.0000e+000,20.00000,    -0.45672,1.06958
158.68900, 27.13083,-7.5339e-002,94.99995,50.00000,0.0000e+000,20.00000,    -0.44417,1.06667
160.91000, 27.31083,-8.5331e-002,94.92178,50.00000,0.0000e+000,20.00000,    -0.43130,1.06377
163.09000, 27.49083,-9.5074e-002,94.84636,50.00000,0.0000e+000,20.00000,    -0.41827,1.06094
165.25700, 27.67083,    -0.10515,94.77354,50.00000,0.0000e+000,20.00000,    -0.40507,1.05813
167.38400, 27.85083,    -0.11501,94.70526,50.00000,0.0000e+000,20.00000,    -0.39201,1.05538
169.53300, 28.03083,    -0.12598,94.63756,50.00000,0.0000e+000,20.00000,    -0.37892,1.05260
171.62500, 28.21083,    -0.13672,94.57105,50.00000,0.0000e+000,20.00000,    -0.36591,1.04991
173.70399, 28.39083,    -0.14685,94.50630,50.00000,0.0000e+000,20.00000,    -0.35301,1.04723
175.76100, 28.57083,    -0.15757,94.44138,50.00000,0.0000e+000,20.00000,    -0.34007,1.04459
177.81700, 28.75083,    -0.16807,94.38110,50.00000,0.0000e+000,20.00000,    -0.32756,1.04195
179.84700, 28.93083,    -0.17830,94.32475,50.00000,0.0000e+000,20.00000,    -0.31656,1.03936
181.85300, 29.11083,    -0.18887,94.26899,50.00000,0.0000e+000,20.00000,    -0.30660,1.03679
183.83000, 29.29083,    -0.19858,94.21552,50.00000,0.0000e+000,20.00000,    -0.29653,1.03427
185.82800, 29.47083,    -0.20877,94.16434,50.00000,0.0000e+000,20.00000,    -0.28695,1.03173
187.78200, 29.65083,    -0.21845,94.11542,50.00000,0.0000e+000,20.00000,    -0.27795,1.02925
189.72600, 29.83083,    -0.22792,94.07077,50.00000,0.0000e+000,20.00000,    -0.26756,1.02679
191.64400, 30.01083,    -0.23741,94.02798,50.00000,0.0000e+000,20.00000,    -0.25739,1.02436
193.55499, 30.19083,    -0.24690,93.98630,50.00000,0.0000e+000,20.00000,    -0.24773,1.02195
195.44800, 30.37083,    -0.25603,93.94484,50.00000,0.0000e+000,20.00000,    -0.23766,1.01957
197.32800, 30.55083,    -0.26525,93.90451,50.00000,0.0000e+000,20.00000,    -0.22848,1.01720
199.19600, 30.73083,    -0.27440,93.86210,50.00000,0.0000e+000,20.00000,    -0.22055,1.01486
201.05499, 30.91083,    -0.28402,93.81896,50.00000,0.0000e+000,20.00000,    -0.21264,1.01253
202.88499, 31.09083,    -0.29305,93.77987,50.00000,0.0000e+000,20.00000,    -0.20517,1.01025
204.71700, 31.27083,    -0.30249,93.74140,50.00000,0.0000e+000,20.00000,    -0.19801,1.00796
206.55099, 31.45083,    -0.31213,93.70472,50.00000,0.0000e+000,20.00000,    -0.19091,1.00568
208.34900, 31.63083,    -0.32122,93.67431,50.00000,0.0000e+000,20.00000,    -0.18516,1.00345
210.16701, 31.81083,    -0.33062,93.64493,50.00000,0.0000e+000,20.00000,    -0.18015,1.00119
211.95399, 31.99083,    -0.33985,93.61513,50.00000,0.0000e+000,20.00000,    -0.17594,0.99898
213.74699, 32.17083,    -0.34898,93.58679,50.00000,0.0000e+000,20.00000,    -0.17107,0.99677
215.52499, 32.35083,    -0.35812,93.55906,50.00000,0.0000e+000,20.00000,    -0.16631,0.99458
217.29900, 32.53083,    -0.36668,93.53140,50.00000,0.0000e+000,20.00000,    -0.16131,0.99240
219.08099, 32.71083,    -0.37583,93.50430,50.00000,0.0000e+000,20.00000,    -0.15574,0.99021
220.84900, 32.89083,    -0.38506,93.47763,50.00000,0.0000e+000,20.00000,    -0.15136,0.98805
222.62300, 33.07084,    -0.39375,93.45207,50.00000,0.0000e+000,20.00000,    -0.14725,0.98588
224.38400, 33.25083,    -0.40243,93.42845,50.00000,0.0000e+000,20.00000,    -0.14373,0.98373
226.11000, 33.43083,    -0.41064,93.40439,50.00000,0.0000e+000,20.00000,    -0.14160,0.98163
227.86400, 33.61083,    -0.41891,93.37989,50.00000,0.0000e+000,20.00000,    -0.14010,0.97950
229.61301, 33.79083,    -0.42777,93.35354,50.00000,0.0000e+000,20.00000,    -0.13854,0.97738
231.34900, 33.97083,    -0.43628,93.32931,50.00000,0.0000e+000,20.00000,    -0.13748,0.97528
233.09900, 34.15083,    -0.44422,93.30644,50.00000,0.0000e+000,20.00000,    -0.13672,0.97317
234.82300, 34.33083,    -0.45335,93.28278,50.00000,0.0000e+000,20.00000,    -0.13576,0.97110
236.55600, 34.51083,    -0.46133,93.25964,50.00000,0.0000e+000,20.00000,    -0.13503,0.96902
238.28101, 34.69083,    -0.46929,93.23603,50.00000,0.0000e+000,20.00000,    -0.13397,0.96695
240.01300, 34.87083,    -0.47770,93.21278,50.00000,0.0000e+000,20.00000,    -0.13325,0.96488
241.73900, 35.05083,    -0.48533,93.18830,50.00000,0.0000e+000,20.00000,    -0.13248,0.96282
243.46899, 35.23083,    -0.49265,93.16471,50.00000,0.0000e+000,20.00000,    -0.13108,0.96076
245.17799, 35.41083,    -0.50013,93.14114,50.00000,0.0000e+000,20.00000,    -0.12948,0.95873
246.91499, 35.59083,    -0.50808,93.11691,50.00000,0.0000e+000,20.00000,    -0.12749,0.95667
248.62801, 35.77083,    -0.51523,93.09240,50.00000,0.0000e+000,20.00000,    -0.12613,0.95465
250.35300, 35.95083,    -0.52304,93.06730,50.00000,0.0000e+000,20.00000,    -0.12509,0.95261
252.06900, 36.13083,    -0.53124,93.04312,50.00000,0.0000e+000,20.00000,    -0.12362,0.95059
253.80099, 36.31083,    -0.54036,93.01853,50.00000,0.0000e+000,20.00000,    -0.12186,0.94856
255.53000, 36.49083,    -0.55046,92.99550,50.00000,0.0000e+000,20.00000,    -0.11980,0.94653
257.25900, 36.67083,    -0.56095,92.97229,50.00000,0.0000e+000,20.00000,    -0.11761,0.94451
258.99799, 36.85083,    -0.57168,92.95082,50.00000,0.0000e+000,20.00000,    -0.11531,0.94249
260.73499, 37.03083,    -0.58185,92.93184,50.00000,0.0000e+000,20.00000,    -0.11334,0.94047
262.47000, 37.21083,    -0.59210,92.91329,50.00000,0.0000e+000,20.00000,    -0.11166,0.93845
264.21100, 37.39083,    -0.60161,92.89456,50.00000,0.0000e+000,20.00000,    -0.10976,0.93644
265.93500, 37.57084,    -0.61149,92.87480,50.00000,0.0000e+000,20.00000,    -0.10759,0.93445
267.67200, 37.75083,    -0.62182,92.85569,50.00000,0.0000e+000,20.00000,    -0.10513,0.93245
269.43201, 37.93083,    -0.63243,92.83723,50.00000,0.0000e+000,20.00000,    -0.10317,0.93043
271.16400, 38.11083,    -0.64241,92.82030,50.00000,0.0000e+000,20.00000,    -0.10121,0.92844
272.89999, 38.29083,    -0.65291,92.80413,50.00000,0.0000e+000,20.00000,-9.9613e-002,0.92646
274.65701, 38.47083,    -0.66303,92.78888,50.00000,0.0000e+000,20.00000,-9.8018e-002,0.92446
276.39200, 38.65083,    -0.67286,92.77306,50.00000,0.0000e+000,20.00000,-9.6930e-002,0.92248
278.14499, 38.83083,    -0.68253,92.75655,50.00000,0.0000e+000,20.00000,-9.7054e-002,0.92050
279.88901, 39.01083,    -0.69219,92.73936,50.00000,0.0000e+000,20.00000,-9.6607e-002,0.91852
281.62399, 39.19083,    -0.70181,92.72203,50.00000,0.0000e+000,20.00000,-9.5948e-002,0.91657
283.38501, 39.37083,    -0.71070,92.70546,50.00000,0.0000e+000,20.00000,-9.5590e-002,0.91458
285.13101, 39.55083,    -0.71978,92.68932,50.00000,0.0000e+000,20.00000,-9.5783e-002,0.91262
286.88000, 39.73083,    -0.72838,92.67245,50.00000,0.0000e+000,20.00000,-9.6396e-002,0.91067
288.63699, 39.91083,    -0.73768,92.65498,50.00000,0.0000e+000,20.00000,-9.7865e-002,0.90871
290.40900, 40.09083,    -0.74665,92.63751,50.00000,0.0000e+000,20.00000,-9.9188e-002,0.90673
292.14999, 40.27083,    -0.75493,92.62023,50.00000,0.0000e+000,20.00000,    -0.10059,0.90480
293.89899, 40.45083,    -0.76372,92.60251,50.00000,0.0000e+000,20.00000,    -0.10191,0.90286
295.66501, 40.63083,    -0.77377,92.58287,50.00000,0.0000e+000,20.00000,    -0.10326,0.90091
297.42001, 40.81083,    -0.78240,92.56544,50.00000,0.0000e+000,20.00000,    -0.10463,0.89898
299.17499, 40.99083,    -0.79073,92.54936,50.00000,0.0000e+000,20.00000,    -0.10584,0.89705
300.93701, 41.17083,    -0.80018,92.53144,50.00000,0.0000e+000,20.00000,    -0.10737,0.89512
302.69901, 41.35083,    -0.80900,92.51151,50.00000,0.0000e+000,20.00000,    -0.10924,0.89320
304.45300, 41.53083,    -0.81807,92.49098,50.00000,0.0000e+000,20.00000,    -0.11112,0.89129
306.23001, 41.71083,    -0.82714,92.46855,50.00000,0.0000e+000,20.00000,    -0.11314,0.88936
307.98499, 41.89083,    -0.83537,92.44712,50.00000,0.0000e+000,20.00000,    -0.11532,0.88746
309.74799, 42.07084,    -0.84390,92.42668,50.00000,0.0000e+000,20.00000,    -0.11759,0.88556
311.51999, 42.25083,    -0.85128,92.40620,50.00000,0.0000e+000,20.00000,    -0.12003,0.88365
313.29700, 42.43083,    -0.85843,92.38506,50.00000,0.0000e+000,20.00000,    -0.12242,0.88174
315.06201, 42.61083,    -0.86614,92.36295,50.00000,0.0000e+000,20.00000,    -0.12540,0.87986
316.82599, 42.79083,    -0.87344,92.34114,50.00000,0.0000e+000,20.00000,    -0.12919,0.87797
318.58200, 42.97083,    -0.88122,92.31900,50.00000,0.0000e+000,20.00000,    -0.13289,0.87611
320.37701, 43.15083,    -0.88888,92.29607,50.00000,0.0000e+000,20.00000,    -0.13639,0.87420
322.15302, 43.33083,    -0.89707,92.27264,50.00000,0.0000e+000,20.00000,    -0.14033,0.87233
323.92300, 43.51083,    -0.90408,92.24796,50.00000,0.0000e+000,20.00000,    -0.14436,0.87046
325.70200, 43.69083,    -0.91093,92.22257,50.00000,0.0000e+000,20.00000,    -0.14906,0.86859
327.47800, 43.87083,    -0.91794,92.19699,50.00000,0.0000e+000,20.00000,    -0.15442,0.86673
329.24200, 44.05083,    -0.92443,92.17081,50.00000,0.0000e+000,20.00000,    -0.16020,0.86489
331.01599, 44.23083,    -0.93068,92.14276,50.00000,0.0000e+000,20.00000,    -0.16695,0.86304
332.77301, 44.41083,    -0.93603,92.11403,50.00000,0.0000e+000,20.00000,    -0.17472,0.86122
334.55200, 44.59083,    -0.94257,92.08437,50.00000,0.0000e+000,20.00000,    -0.18330,0.85937
336.31601, 44.77083,    -0.94882,92.05347,50.00000,0.0000e+000,20.00000,    -0.19230,0.85756
338.09698, 44.95083,    -0.95512,92.02116,50.00000,0.0000e+000,20.00000,    -0.20138,0.85572
339.86801, 45.13083,    -0.96186,91.98679,50.00000,0.0000e+000,20.00000,    -0.21072,0.85391
341.63800, 45.31083,    -0.96739,91.95016,50.00000,0.0000e+000,20.00000,    -0.22057,0.85210
343.39999, 45.49083,    -0.97327,91.91150,50.00000,0.0000e+000,20.00000,    -0.23112,0.85030
345.17001, 45.67083,    -0.97846,91.87160,50.00000,0.0000e+000,20.00000,    -0.24124,0.84851
346.94901, 45.85083,    -0.98368,91.83037,50.00000,0.0000e+000,20.00000,    -0.25088,0.84671
348.72900, 46.03083,    -0.98839,91.78552,50.00000,0.0000e+000,20.00000,    -0.26051,0.84491
350.50500, 46.21083,    -0.99366,91.73565,50.00000,0.0000e+000,20.00000,    -0.27051,0.84312
352.29599, 46.39083,    -0.99901,91.68275,50.00000,0.0000e+000,20.00000,    -0.28010,0.84133
354.06500, 46.57084,    -1.00448,91.62805,50.00000,0.0000e+000,20.00000,    -0.28965,0.83956
355.84799, 46.75083,    -1.00950,91.57220,50.00000,0.0000e+000,20.00000,    -0.29900,0.83779
357.64499, 46.93083,    -1.01501,91.51502,50.00000,0.0000e+000,20.00000,    -0.30727,0.83600
359.45801, 47.11083,    -1.02651,91.45516,50.00000,0.0000e+000,20.00000,    -0.31526,0.83421
361.26199, 47.29083,    -1.03749,91.39146,50.00000,0.0000e+000,20.00000,    -0.32197,0.83243
363.10800, 47.47083,    -1.04610,91.32863,50.00000,0.0000e+000,20.00000,    -0.32738,0.83062
364.92401, 47.65083,    -1.05246,91.26731,50.00000,0.0000e+000,20.00000,    -0.33241,0.82884
366.74200, 47.83083,    -1.05704,91.20483,50.00000,0.0000e+000,20.00000,    -0.33627,0.82707
368.54599, 48.01083,    -1.06048,91.13963,50.00000,0.0000e+000,20.00000,    -0.33826,0.82531
370.32199, 48.19083,    -1.06380,91.07513,50.00000,0.0000e+000,20.00000,    -0.33926,0.82359
372.10300, 48.37083,    -1.06869,91.00971,50.00000,0.0000e+000,20.00000,    -0.33994,0.82187
373.87201, 48.55083,    -1.07574,90.94336,50.00000,0.0000e+000,20.00000,    -0.33997,0.82017
375.64099, 48.73083,    -1.08400,90.87892,50.00000,0.0000e+000,20.00000,    -0.33915,0.81847
377.40399, 48.91083,    -1.09415,90.81366,50.00000,0.0000e+000,20.00000,    -0.33664,0.81679
379.17599, 49.09083,    -1.10508,90.74998,50.00000,0.0000e+000,20.00000,    -0.33296,0.81510
380.95401, 49.27083,    -1.11766,90.69023,50.00000,0.0000e+000,20.00000,    -0.32912,0.81341
382.73099, 49.45083,    -1.13038,90.63093,50.00000,0.0000e+000,20.00000,    -0.32562,0.81173
384.50101, 49.63083,    -1.14236,90.57236,50.00000,0.0000e+000,20.00000,    -0.32186,0.81007
386.27100, 49.81083,    -1.15340,90.51579,50.00000,0.0000e+000,20.00000,    -0.31731,0.80840
388.03601, 49.99083,    -1.16639,90.45960,50.00000,0.0000e+000,20.00000,    -0.31255,0.80675
389.80200, 50.17083,    -1.17987,90.40268,50.00000,0.0000e+000,20.00000,    -0.30654,0.80511
391.58801, 50.35083,    -1.19412,90.34667,50.00000,0.0000e+000,20.00000,    -0.30009,0.80345
393.34000, 50.53083,    -1.20528,90.29224,50.00000,0.0000e+000,20.00000,    -0.29531,0.80182
395.10400, 50.71083,    -1.21461,90.24172,50.00000,0.0000e+000,20.00000,    -0.29057,0.80020
396.84799, 50.89083,    -1.22478,90.19192,50.00000,0.0000e+000,20.00000,    -0.28580,0.79859
398.60501, 51.07084,    -1.23696,90.14260,50.00000,0.0000e+000,20.00000,    -0.28219,0.79698
400.35599, 51.25083,    -1.25166,90.09397,50.00000,0.0000e+000,20.00000,    -0.27910,0.79538
402.12399, 51.43083,    -1.26649,90.04553,50.00000,0.0000e+000,20.00000,    -0.27591,0.79378
403.90399, 51.61083,    -1.28072,89.99722,50.00000,0.0000e+000,20.00000,    -0.27351,0.79216
405.69000, 51.79083,    -1.29429,89.94960,50.00000,0.0000e+000,20.00000,    -0.27243,0.79055
407.46799, 51.97083,    -1.30779,89.90577,50.00000,0.0000e+000,20.00000,    -0.27066,0.78895
409.27200, 52.15083,    -1.32161,89.86346,50.00000,0.0000e+000,20.00000,    -0.26857,0.78734
411.06900, 52.33083,    -1.33447,89.81667,50.00000,0.0000e+000,20.00000,    -0.26752,0.78573
412.87201, 52.51083,    -1.34626,89.76893,50.00000,0.0000e+000,20.00000,    -0.26721,0.78413
414.67700, 52.69083,    -1.35693,89.72188,50.00000,0.0000e+000,20.00000,    -0.26714,0.78253
416.47501, 52.87083,    -1.36652,89.67511,50.00000,0.0000e+000,20.00000,    -0.26718,0.78094
418.26999, 53.05083,    -1.37569,89.62722,50.00000,0.0000e+000,20.00000,    -0.26711,0.77936
420.08099, 53.23083,    -1.38508,89.57983,50.00000,0.0000e+000,20.00000,    -0.26734,0.77777
421.87100, 53.41083,    -1.39531,89.53233,50.00000,0.0000e+000,20.00000,    -0.26840,0.77621
423.67200, 53.59083,    -1.40526,89.48051,50.00000,0.0000e+000,20.00000,    -0.26963,0.77465
425.47198, 53.77083,    -1.41472,89.42955,50.00000,0.0000e+000,20.00000,    -0.27143,0.77309
427.26801, 53.95083,    -1.42439,89.38110,50.00000,0.0000e+000,20.00000,    -0.27395,0.77154
429.07001, 54.13083,    -1.43448,89.33039,50.00000,0.0000e+000,20.00000,    -0.27580,0.76999
430.87201, 54.31083,    -1.44339,89.28014,50.00000,0.0000e+000,20.00000,    -0.27730,0.76845
432.66699, 54.49083,    -1.45191,89.23081,50.00000,0.0000e+000,20.00000,    -0.27885,0.76692
434.46201, 54.67083,    -1.46097,89.18096,50.00000,0.0000e+000,20.00000,    -0.28044,0.76539
436.24301, 54.85083,    -1.46970,89.13252,50.00000,0.0000e+000,20.00000,    -0.28168,0.76388
438.03601, 55.03083,    -1.47836,89.08349,50.00000,0.0000e+000,20.00000,    -0.28320,0.76237
439.82599, 55.21083,    -1.48702,89.03170,50.00000,0.0000e+000,20.00000,    -0.28470,0.76087
441.60199, 55.39083,    -1.49567,88.97913,50.00000,0.0000e+000,20.00000,    -0.28523,0.75939
443.39600, 55.57084,    -1.50443,88.92785,50.00000,0.0000e+000,20.00000,    -0.28655,0.75789
445.17001, 55.75083,    -1.51340,88.87683,50.00000,0.0000e+000,20.00000,    -0.28879,0.75642
446.95801, 55.93083,    -1.52231,88.82408,50.00000,0.0000e+000,20.00000,    -0.28979,0.75494
448.75299, 56.11083,    -1.53305,88.77081,50.00000,0.0000e+000,20.00000,    -0.29048,0.75346
450.54001, 56.29083,    -1.54158,88.71785,50.00000,0.0000e+000,20.00000,    -0.29240,0.75200
452.31500, 56.47083,    -1.55093,88.66531,50.00000,0.0000e+000,20.00000,    -0.29459,0.75055
454.10800, 56.65083,    -1.56130,88.61305,50.00000,0.0000e+000,20.00000,    -0.29705,0.74909
455.91400, 56.83083,    -1.57089,88.56003,50.00000,0.0000e+000,20.00000,    -0.29933,0.74763
457.71201, 57.01083,    -1.58039,88.50719,50.00000,0.0000e+000,20.00000,    -0.30069,0.74618
459.49100, 57.19083,    -1.59047,88.45445,50.00000,0.0000e+000,20.00000,    -0.30209,0.74475
461.28900, 57.37083,    -1.59919,88.39842,50.00000,0.0000e+000,20.00000,    -0.30344,0.74331
463.08701, 57.55083,    -1.60776,88.34158,50.00000,0.0000e+000,20.00000,    -0.30483,0.74187
464.89001, 57.73083,    -1.62026,88.28713,50.00000,0.0000e+000,20.00000,    -0.30639,0.74044
466.68799, 57.91083,    -1.63059,88.23424,50.00000,0.0000e+000,20.00000,    -0.30778,0.73902
468.50201, 58.09083,    -1.63910,88.17848,50.00000,0.0000e+000,20.00000,    -0.30950,0.73759
470.29199, 58.27083,    -1.64600,88.12061,50.00000,0.0000e+000,20.00000,    -0.31156,0.73619
472.07300, 58.45083,    -1.65173,88.06301,50.00000,0.0000e+000,20.00000,    -0.31363,0.73480
473.84900, 58.63083,    -1.65849,88.00567,50.00000,0.0000e+000,20.00000,    -0.31573,0.73342
475.64301, 58.81083,    -1.66682,87.94942,50.00000,0.0000e+000,20.00000,    -0.31745,0.73203
477.43500, 58.99083,    -1.67724,87.89179,50.00000,0.0000e+000,20.00000,    -0.31911,0.73065
479.21899, 59.17083,    -1.68874,87.83494,50.00000,0.0000e+000,20.00000,    -0.32047,0.72927
481.01199, 59.35083,    -1.69728,87.77937,50.00000,0.0000e+000,20.00000,    -0.32194,0.72790
482.78601, 59.53083,    -1.70557,87.72126,50.00000,0.0000e+000,20.00000,    -0.32390,0.72655
484.59100, 59.71083,    -1.71330,87.66296,50.00000,0.0000e+000,20.00000,    -0.32596,0.72518
486.36801, 59.89083,    -1.72157,87.60380,50.00000,0.0000e+000,20.00000,    -0.32729,0.72384
488.15701, 60.07084,    -1.72965,87.54375,50.00000,0.0000e+000,20.00000,    -0.32780,0.72249
489.93201, 60.25083,    -1.73895,87.48393,50.00000,0.0000e+000,20.00000,    -0.32829,0.72116
491.72400, 60.43083,    -1.74783,87.42343,50.00000,0.0000e+000,20.00000,    -0.32943,0.71983
493.50201, 60.61083,    -1.75644,87.36383,50.00000,0.0000e+000,20.00000,    -0.33045,0.71850
495.28900, 60.79083,    -1.76526,87.30537,50.00000,0.0000e+000,20.00000,    -0.33068,0.71718
497.06201, 60.97083,    -1.77479,87.24522,50.00000,0.0000e+000,20.00000,    -0.33146,0.71588
498.85501, 61.15083,    -1.78675,87.18300,50.00000,0.0000e+000,20.00000,    -0.33286,0.71456
500.65201, 61.33083,    -1.79929,87.12082,50.00000,0.0000e+000,20.00000,    -0.33397,0.71325
502.45599, 61.51083,    -1.81134,87.06016,50.00000,0.0000e+000,20.00000,    -0.33475,0.71193
504.25699, 61.69083,    -1.82018,87.00021,50.00000,0.0000e+000,20.00000,    -0.33544,0.71063
506.06400, 61.87083,    -1.82906,86.94034,50.00000,0.0000e+000,20.00000,    -0.33579,0.70933
507.85101, 62.05083,    -1.83618,86.88117,50.00000,0.0000e+000,20.00000,    -0.33566,0.70804
509.64801, 62.23083,    -1.84319,86.81971,50.00000,0.0000e+000,20.00000,    -0.33584,0.70676
511.42700, 62.41083,    -1.85197,86.75917,50.00000,0.0000e+000,20.00000,    -0.33633,0.70549
513.23499, 62.59083,    -1.86084,86.70107,50.00000,0.0000e+000,20.00000,    -0.33729,0.70421
515.02100, 62.77083,    -1.86805,86.64116,50.00000,0.0000e+000,20.00000,    -0.33751,0.70295
516.81500, 62.95083,    -1.87793,86.58077,50.00000,0.0000e+000,20.00000,    -0.33688,0.70169
518.62299, 63.13083,    -1.88899,86.51897,50.00000,0.0000e+000,20.00000,    -0.33679,0.70042
520.41602, 63.31083,    -1.89858,86.45766,50.00000,0.0000e+000,20.00000,    -0.33756,0.69917
522.20502, 63.49083,    -1.90652,86.39633,50.00000,0.0000e+000,20.00000,    -0.33905,0.69793
524.01202, 63.67083,    -1.91344,86.33482,50.00000,0.0000e+000,20.00000,    -0.34015,0.69668
525.78802, 63.85083,    -1.92056,86.27535,50.00000,0.0000e+000,20.00000,    -0.34106,0.69546
527.58197, 64.03083,    -1.92897,86.21461,50.00000,0.0000e+000,20.00000,    -0.34174,0.69423
529.36700, 64.21083,    -1.93771,86.15295,50.00000,0.0000e+000,20.00000,    -0.34223,0.69301
531.17102, 64.39083,    -1.94882,86.09097,50.00000,0.0000e+000,20.00000,    -0.34328,0.69179
532.96698, 64.57083,    -1.95918,86.03012,50.00000,0.0000e+000,20.00000,    -0.34423,0.69057
534.78400, 64.75083,    -1.96843,85.97051,50.00000,0.0000e+000,20.00000,    -0.34519,0.68935
536.56598, 64.93083,    -1.97816,85.90892,50.00000,0.0000e+000,20.00000,    -0.34559,0.68815
538.37903, 65.11083,    -1.98854,85.84537,50.00000,0.0000e+000,20.00000,    -0.34588,0.68694
540.19098, 65.29083,    -1.99720,85.78019,50.00000,0.0000e+000,20.00000,    -0.34660,0.68574
541.98499, 65.47083,    -2.00389,85.71577,50.00000,0.0000e+000,20.00000,    -0.34711,0.68455
543.76898, 65.65083,    -2.00947,85.65334,50.00000,0.0000e+000,20.00000,    -0.34776,0.68338
545.56097, 65.83083,    -2.01664,85.58986,50.00000,0.0000e+000,20.00000,    -0.34863,0.68220
547.35901, 66.01083,    -2.02516,85.52680,50.00000,0.0000e+000,20.00000,    -0.34908,0.68103
549.14301, 66.19083,    -2.03342,85.46486,50.00000,0.0000e+000,20.00000,    -0.34925,0.67987
550.92902, 66.37083,    -2.04250,85.40195,50.00000,0.0000e+000,20.00000,    -0.34966,0.67871
552.73798, 66.55083,    -2.05398,85.33813,50.00000,0.0000e+000,20.00000,    -0.35072,0.67755
554.54199, 66.73083,    -2.06422,85.27488,50.00000,0.0000e+000,20.00000,    -0.35108,0.67639
556.35797, 66.91084,    -2.07770,85.21239,50.00000,0.0000e+000,20.00000,    -0.35067,0.67523
558.19000, 67.09084,    -2.09214,85.14873,50.00000,0.0000e+000,20.00000,    -0.34938,0.67407
560.01398, 67.27084,    -2.10158,85.08501,50.00000,0.0000e+000,20.00000,    -0.34784,0.67291
561.84698, 67.45084,    -2.10859,85.02286,50.00000,0.0000e+000,20.00000,    -0.34727,0.67176
563.65399, 67.63084,    -2.11507,84.95956,50.00000,0.0000e+000,20.00000,    -0.34695,0.67062
565.45599, 67.81084,    -2.11926,84.89605,50.00000,0.0000e+000,20.00000,    -0.34582,0.66950
567.24298, 67.99084,    -2.12477,84.83349,50.00000,0.0000e+000,20.00000,    -0.34505,0.66838
569.03101, 68.17083,    -2.13070,84.77088,50.00000,0.0000e+000,20.00000,    -0.34462,0.66728
570.82098, 68.35083,    -2.13786,84.70750,50.00000,0.0000e+000,20.00000,    -0.34357,0.66617
572.60199, 68.53083,    -2.14584,84.64472,50.00000,0.0000e+000,20.00000,    -0.34175,0.66508
574.39600, 68.71083,    -2.15469,84.58292,50.00000,0.0000e+000,20.00000,    -0.34100,0.66398
576.19202, 68.89083,    -2.16501,84.52225,50.00000,0.0000e+000,20.00000,    -0.33979,0.66289
577.98700, 69.07083,    -2.17475,84.46314,50.00000,0.0000e+000,20.00000,    -0.33752,0.66180
579.76801, 69.25083,    -2.18326,84.40302,50.00000,0.0000e+000,20.00000,    -0.33633,0.66073
581.53802, 69.43083,    -2.19297,84.34089,50.00000,0.0000e+000,20.00000,    -0.33562,0.65967
583.35101, 69.61083,    -2.20564,84.28127,50.00000,0.0000e+000,20.00000,    -0.33465,0.65858
585.14398, 69.79083,    -2.21736,84.22234,50.00000,0.0000e+000,20.00000,    -0.33423,0.65752
586.95099, 69.97083,    -2.22817,84.16149,50.00000,0.0000e+000,20.00000,    -0.33373,0.65645
588.73798, 70.15083,    -2.23709,84.10096,50.00000,0.0000e+000,20.00000,    -0.33303,0.65539
590.55701, 70.33083,    -2.24693,84.04414,50.00000,0.0000e+000,20.00000,    -0.33259,0.65432
592.36298, 70.51083,    -2.25685,83.98485,50.00000,0.0000e+000,20.00000,    -0.33345,0.65327
594.15503, 70.69083,    -2.26676,83.92538,50.00000,0.0000e+000,20.00000,    -0.33512,0.65222
595.95697, 70.87083,    -2.27697,83.86944,50.00000,0.0000e+000,20.00000,    -0.33709,0.65118
597.77502, 71.05083,    -2.28687,83.81225,50.00000,0.0000e+000,20.00000,    -0.33826,0.65013
599.58600, 71.23083,    -2.29570,83.75183,50.00000,0.0000e+000,20.00000,    -0.33857,0.64909
601.37799, 71.41084,    -2.30154,83.69174,50.00000,0.0000e+000,20.00000,    -0.33969,0.64807
603.16803, 71.59084,    -2.30591,83.63077,50.00000,0.0000e+000,20.00000,    -0.34213,0.64705
604.95099, 71.77084,    -2.31194,83.56998,50.00000,0.0000e+000,20.00000,    -0.34445,0.64603
606.72601, 71.95084,    -2.31984,83.50923,50.00000,0.0000e+000,20.00000,    -0.34614,0.64503
608.48901, 72.13084,    -2.32675,83.44818,50.00000,0.0000e+000,20.00000,    -0.34812,0.64404
610.28302, 72.31084,    -2.33631,83.38370,50.00000,0.0000e+000,20.00000,    -0.35013,0.64304
612.11102, 72.49084,    -2.35624,83.31682,50.00000,0.0000e+000,20.00000,    -0.35180,0.64202
613.94598, 72.67083,    -2.37185,83.25007,50.00000,0.0000e+000,20.00000,    -0.35402,0.64100
615.78699, 72.85083,    -2.38257,83.18573,50.00000,0.0000e+000,20.00000,    -0.35659,0.63998
617.59900, 73.03083,    -2.39080,83.12252,50.00000,0.0000e+000,20.00000,    -0.35845,0.63899
619.42902, 73.21083,    -2.39650,83.05858,50.00000,0.0000e+000,20.00000,    -0.35994,0.63799
621.21899, 73.39083,    -2.39994,82.99155,50.00000,0.0000e+000,20.00000,    -0.36106,0.63701
623.02802, 73.57083,    -2.40961,82.92239,50.00000,0.0000e+000,20.00000,    -0.36151,0.63603
624.86401, 73.75083,    -2.42041,82.85485,50.00000,0.0000e+000,20.00000,    -0.36134,0.63504
626.66803, 73.93083,    -2.42312,82.79027,50.00000,0.0000e+000,20.00000,    -0.36143,0.63407
628.45099, 74.11083,    -2.42488,82.72461,50.00000,0.0000e+000,20.00000,    -0.36079,0.63311
630.24500, 74.29083,    -2.43065,82.65834,50.00000,0.0000e+000,20.00000,    -0.35891,0.63215
632.03302, 74.47083,    -2.44155,82.59383,50.00000,0.0000e+000,20.00000,    -0.35651,0.63120
633.83099, 74.65083,    -2.45072,82.52815,50.00000,0.0000e+000,20.00000,    -0.35490,0.63025
635.63300, 74.83083,    -2.46047,82.46113,50.00000,0.0000e+000,20.00000,    -0.35345,0.62931
637.42499, 75.01083,    -2.46767,82.39529,50.00000,0.0000e+000,20.00000,    -0.35175,0.62837
639.23798, 75.19083,    -2.48080,82.33031,50.00000,0.0000e+000,20.00000,    -0.34936,0.62742
641.09100, 75.37083,    -2.49740,82.26727,50.00000,0.0000e+000,20.00000,    -0.34600,0.62646
642.88300, 75.55083,    -2.50150,82.20695,50.00000,0.0000e+000,20.00000,    -0.34231,0.62553
644.66699, 75.73083,    -2.50451,82.14611,50.00000,0.0000e+000,20.00000,    -0.33930,0.62461
646.45697, 75.91084,    -2.50999,82.08441,50.00000,0.0000e+000,20.00000,    -0.33663,0.62369
648.25098, 76.09084,    -2.51673,82.02429,50.00000,0.0000e+000,20.00000,    -0.33304,0.62277
650.04602, 76.27084,    -2.52480,81.96597,50.00000,0.0000e+000,20.00000,    -0.32960,0.62186
651.83899, 76.45084,    -2.53358,81.90729,50.00000,0.0000e+000,20.00000,    -0.32660,0.62095
653.63098, 76.63084,    -2.54030,81.84908,50.00000,0.0000e+000,20.00000,    -0.32352,0.62005
655.42499, 76.81084,    -2.54924,81.79165,50.00000,0.0000e+000,20.00000,    -0.31994,0.61915
657.22198, 76.99084,    -2.55752,81.73393,50.00000,0.0000e+000,20.00000,    -0.31614,0.61825
659.01703, 77.17083,    -2.56682,81.67679,50.00000,0.0000e+000,20.00000,    -0.31248,0.61735
660.84198, 77.35083,    -2.57873,81.62202,50.00000,0.0000e+000,20.00000,    -0.30997,0.61645
662.64899, 77.53083,    -2.59011,81.56828,50.00000,0.0000e+000,20.00000,    -0.30723,0.61556
664.47900, 77.71083,    -2.59736,81.51285,50.00000,0.0000e+000,20.00000,    -0.30450,0.61466
666.29401, 77.89083,    -2.60319,81.45899,50.00000,0.0000e+000,20.00000,    -0.30252,0.61377
668.10199, 78.07083,    -2.60896,81.40708,50.00000,0.0000e+000,20.00000,    -0.30051,0.61288
669.92102, 78.25083,    -2.61566,81.35303,50.00000,0.0000e+000,20.00000,    -0.29761,0.61200
671.72601, 78.43083,    -2.62160,81.29730,50.00000,0.0000e+000,20.00000,    -0.29479,0.61113
673.53198, 78.61083,    -2.62738,81.24374,50.00000,0.0000e+000,20.00000,    -0.29257,0.61026
675.33197, 78.79083,    -2.63173,81.19247,50.00000,0.0000e+000,20.00000,    -0.29014,0.60939
677.13800, 78.97083,    -2.63584,81.14226,50.00000,0.0000e+000,20.00000,    -0.28772,0.60853
678.92700, 79.15083,    -2.63857,81.09102,50.00000,0.0000e+000,20.00000,    -0.28566,0.60768
680.72498, 79.33083,    -2.64405,81.04027,50.00000,0.0000e+000,20.00000,    -0.28402,0.60682
682.51501, 79.51083,    -2.64780,80.98897,50.00000,0.0000e+000,20.00000,    -0.28205,0.60598
684.32300, 79.69083,    -2.66086,80.93559,50.00000,0.0000e+000,20.00000,    -0.27934,0.60513
686.15900, 79.87083,    -2.67462,80.88411,50.00000,0.0000e+000,20.00000,    -0.27675,0.60427
687.99799, 80.05083,    -2.68360,80.83574,50.00000,0.0000e+000,20.00000,    -0.27396,0.60341
689.80200, 80.23083,    -2.68572,80.78789,50.00000,0.0000e+000,20.00000,    -0.27087,0.60257
691.61298, 80.41084,    -2.68736,80.73864,50.00000,0.0000e+000,20.00000,    -0.26811,0.60173
693.40198, 80.59084,    -2.68961,80.68969,50.00000,0.0000e+000,20.00000,    -0.26616,0.60091
695.21301, 80.77084,    -2.69664,80.64118,50.00000,0.0000e+000,20.00000,    -0.26492,0.60008
697.02301, 80.95084,    -2.70114,80.59334,50.00000,0.0000e+000,20.00000,    -0.26390,0.59925
698.81201, 81.13084,    -2.70662,80.54589,50.00000,0.0000e+000,20.00000,    -0.26299,0.59843
700.62701, 81.31084,    -2.71342,80.49764,50.00000,0.0000e+000,20.00000,    -0.26213,0.59761
702.42603, 81.49084,    -2.71832,80.45256,50.00000,0.0000e+000,20.00000,    -0.26053,0.59680
704.21802, 81.67083,    -2.72197,80.41006,50.00000,0.0000e+000,20.00000,    -0.25932,0.59599
706.02100, 81.85083,    -2.72761,80.36689,50.00000,0.0000e+000,20.00000,    -0.25940,0.59518
707.81897, 82.03083,    -2.73286,80.32252,50.00000,0.0000e+000,20.00000,    -0.26000,0.59437
709.61298, 82.21083,    -2.73356,80.27845,50.00000,0.0000e+000,20.00000,    -0.26015,0.59358
711.40698, 82.39083,    -2.73627,80.23434,50.00000,0.0000e+000,20.00000,    -0.25981,0.59278
713.19299, 82.57083,    -2.73917,80.18867,50.00000,0.0000e+000,20.00000,    -0.25891,0.59199
714.98401, 82.75083,    -2.74176,80.14175,50.00000,0.0000e+000,20.00000,    -0.25653,0.59120
716.75500, 82.93083,    -2.74469,80.09389,50.00000,0.0000e+000,20.00000,    -0.25283,0.59042
718.56500, 83.11083,    -2.74984,80.04630,50.00000,0.0000e+000,20.00000,    -0.24790,0.58963
720.37799, 83.29083,    -2.75643,79.99857,50.00000,0.0000e+000,20.00000,    -0.24256,0.58884
722.19202, 83.47083,    -2.76647,79.95138,50.00000,0.0000e+000,20.00000,    -0.23761,0.58805
724.01599, 83.65083,    -2.77417,79.90240,50.00000,0.0000e+000,20.00000,    -0.23213,0.58727
725.81201, 83.83083,    -2.78052,79.85266,50.00000,0.0000e+000,20.00000,    -0.22548,0.58649
727.61798, 84.01083,    -2.78521,79.80283,50.00000,0.0000e+000,20.00000,    -0.21851,0.58572
729.41498, 84.19083,    -2.78952,79.75469,50.00000,0.0000e+000,20.00000,    -0.21198,0.58495
731.23999, 84.37083,    -2.79865,79.70890,50.00000,0.0000e+000,20.00000,    -0.20525,0.58417
733.04901, 84.55083,    -2.81368,79.66847,50.00000,0.0000e+000,20.00000,    -0.19844,0.58340
734.88898, 84.73083,    -2.83137,79.63408,50.00000,0.0000e+000,20.00000,    -0.19046,0.58262
736.72302, 84.91084,    -2.84205,79.60320,50.00000,0.0000e+000,20.00000,    -0.18255,0.58185
738.53497, 85.09084,    -2.84622,79.57644,50.00000,0.0000e+000,20.00000,    -0.17495,0.58109
740.33099, 85.27084,    -2.84943,79.55177,50.00000,0.0000e+000,20.00000,    -0.16745,0.58033
742.11102, 85.45084,    -2.85262,79.52850,50.00000,0.0000e+000,20.00000,    -0.15898,0.57959
743.91199, 85.63084,    -2.86024,79.50800,50.00000,0.0000e+000,20.00000,    -0.15007,0.57884
745.76099, 85.81084,    -2.88026,79.48946,50.00000,0.0000e+000,20.00000,    -0.14051,0.57807
747.59802, 85.99084,    -2.88620,79.46950,50.00000,0.0000e+000,20.00000,    -0.13146,0.57731
749.40503, 86.17083,    -2.88832,79.44878,50.00000,0.0000e+000,20.00000,    -0.12342,0.57657
751.20398, 86.35083,    -2.88555,79.42700,50.00000,0.0000e+000,20.00000,    -0.11630,0.57583
752.99597, 86.53083,    -2.88619,79.40766,50.00000,0.0000e+000,20.00000,    -0.11032,0.57510
754.78302, 86.71083,    -2.88718,79.38943,50.00000,0.0000e+000,20.00000,    -0.10490,0.57437
756.58002, 86.89083,    -2.89056,79.36937,50.00000,0.0000e+000,20.00000,    -0.10110,0.57364
758.34998, 87.07083,    -2.89451,79.34956,50.00000,0.0000e+000,20.00000,-9.7632e-002,0.57292
760.13000, 87.25083,    -2.89999,79.33151,50.00000,0.0000e+000,20.00000,-9.4345e-002,0.57220
761.92999, 87.43083,    -2.90637,79.31433,50.00000,0.0000e+000,20.00000,-9.2133e-002,0.57147
763.71698, 87.61083,    -2.91368,79.29894,50.00000,0.0000e+000,20.00000,-9.0616e-002,0.57076
765.55902, 87.79083,    -2.93050,79.28397,50.00000,0.0000e+000,20.00000,-8.8735e-002,0.57002
767.40198, 87.97083,    -2.93777,79.26707,50.00000,0.0000e+000,20.00000,-8.6460e-002,0.56928
769.20300, 88.15083,    -2.93855,79.25135,50.00000,0.0000e+000,20.00000,-8.3771e-002,0.56856
771.00500, 88.33083,    -2.94091,79.23770,50.00000,0.0000e+000,20.00000,-8.1303e-002,0.56785
772.80402, 88.51083,    -2.94208,79.22617,50.00000,0.0000e+000,20.00000,-7.9713e-002,0.56714
774.58899, 88.69083,    -2.94276,79.21285,50.00000,0.0000e+000,20.00000,-7.7520e-002,0.56643
776.35303, 88.87083,    -2.94432,79.20034,50.00000,0.0000e+000,20.00000,-7.5242e-002,0.56574
778.12201, 89.05083,    -2.94540,79.18901,50.00000,0.0000e+000,20.00000,-7.3311e-002,0.56505
779.90503, 89.23083,    -2.95199,79.17611,50.00000,0.0000e+000,20.00000,-7.1514e-002,0.56435
781.69098, 89.41084,    -2.96327,79.16318,50.00000,0.0000e+000,20.00000,-7.0156e-002,0.56365
783.49799, 89.59084,    -2.97022,79.15022,50.00000,0.0000e+000,20.00000,-6.9091e-002,0.56295
785.27899, 89.77084,    -2.97807,79.13783,50.00000,0.0000e+000,20.00000,-6.7352e-002,0.56226
787.09100, 89.95084,    -2.98903,79.12591,50.00000,0.0000e+000,20.00000,-6.6594e-002,0.56156
788.92798, 90.13084,    -3.00258,79.11485,50.00000,0.0000e+000,20.00000,-6.6640e-002,0.56085
790.75201, 90.31084,    -3.01165,79.10300,50.00000,0.0000e+000,20.00000,-6.7161e-002,0.56014
792.57599, 90.49084,    -3.01915,79.09082,50.00000,0.0000e+000,20.00000,-6.7337e-002,0.55944
794.39600, 90.67083,    -3.02239,79.07936,50.00000,0.0000e+000,20.00000,-6.7605e-002,0.55875
796.18103, 90.85083,    -3.02377,79.06778,50.00000,0.0000e+000,20.00000,-6.8715e-002,0.55807
797.96503, 91.03083,    -3.02878,79.05726,50.00000,0.0000e+000,20.00000,-6.9957e-002,0.55739
799.77197, 91.21083,    -3.03914,79.04628,50.00000,0.0000e+000,20.00000,-7.1204e-002,0.55670
801.58600, 91.39083,    -3.04646,79.03558,50.00000,0.0000e+000,20.00000,-7.2250e-002,0.55601
803.39301, 91.57083,    -3.05271,79.02510,50.00000,0.0000e+000,20.00000,-7.3632e-002,0.55533
805.19397, 91.75083,    -3.06170,79.01248,50.00000,0.0000e+000,20.00000,-7.5239e-002,0.55465
807.03400, 91.93083,    -3.07245,78.99809,50.00000,0.0000e+000,20.00000,-7.7103e-002,0.55396
808.84497, 92.11083,    -3.07957,78.98464,50.00000,0.0000e+000,20.00000,-7.9269e-002,0.55328
810.68402, 92.29083,    -3.08970,78.97087,50.00000,0.0000e+000,20.00000,-8.2148e-002,0.55259
812.49701, 92.47083,    -3.09575,78.95718,50.00000,0.0000e+000,20.00000,-8.5470e-002,0.55191
814.31097, 92.65083,    -3.09992,78.94219,50.00000,0.0000e+000,20.00000,-8.8886e-002,0.55124
816.09399, 92.83083,    -3.09857,78.92510,50.00000,0.0000e+000,20.00000,-9.2821e-002,0.55057
817.90802, 93.01083,    -3.10420,78.90753,50.00000,0.0000e+000,20.00000,-9.6662e-002,0.54990
819.74701, 93.19083,    -3.11568,78.89070,50.00000,0.0000e+000,20.00000,    -0.10071,0.54922
821.58600, 93.37083,    -3.12415,78.87328,50.00000,0.0000e+000,20.00000,    -0.10510,0.54854
823.38898, 93.55083,    -3.12113,78.85544,50.00000,0.0000e+000,20.00000,    -0.10931,0.54788
825.18201, 93.73083,    -3.11623,78.83746,50.00000,0.0000e+000,20.00000,    -0.11278,0.54722
826.95599, 93.91084,    -3.11296,78.81843,50.00000,0.0000e+000,20.00000,    -0.11678,0.54657
828.71198, 94.09084,    -3.10787,78.79593,50.00000,0.0000e+000,20.00000,    -0.12076,0.54592
830.52899, 94.27084,    -3.11757,78.77239,50.00000,0.0000e+000,20.00000,    -0.12476,0.54526
832.33197, 94.45084,    -3.12369,78.74832,50.00000,0.0000e+000,20.00000,    -0.12941,0.54460
834.13702, 94.63084,    -3.12859,78.72349,50.00000,0.0000e+000,20.00000,    -0.13375,0.54394
835.95599, 94.81084,    -3.13434,78.69845,50.00000,0.0000e+000,20.00000,    -0.13814,0.54328
837.74902, 94.99084,    -3.13511,78.67310,50.00000,0.0000e+000,20.00000,    -0.14290,0.54263
839.55298, 95.17083,    -3.13686,78.64671,50.00000,0.0000e+000,20.00000,    -0.14740,0.54198
841.38202, 95.35083,    -3.14401,78.61930,50.00000,0.0000e+000,20.00000,    -0.15212,0.54132
843.18903, 95.53083,    -3.14312,78.59214,50.00000,0.0000e+000,20.00000,    -0.15753,0.54066
844.98297, 95.71083,    -3.14200,78.56428,50.00000,0.0000e+000,20.00000,    -0.16290,0.54002
846.75800, 95.89083,    -3.14482,78.53575,50.00000,0.0000e+000,20.00000,    -0.16659,0.53938
848.55402, 96.07083,    -3.14894,78.50790,50.00000,0.0000e+000,20.00000,    -0.16947,0.53874
850.34601, 96.25083,    -3.15286,78.47659,50.00000,0.0000e+000,20.00000,    -0.17353,0.53809
852.15002, 96.43083,    -3.15578,78.44395,50.00000,0.0000e+000,20.00000,    -0.17772,0.53745
853.95898, 96.61083,    -3.15994,78.41054,50.00000,0.0000e+000,20.00000,    -0.18133,0.53680
855.74500, 96.79083,    -3.16515,78.37614,50.00000,0.0000e+000,20.00000,    -0.18428,0.53616
857.55603, 96.97083,    -3.17164,78.34243,50.00000,0.0000e+000,20.00000,    -0.18735,0.53552
859.37000, 97.15083,    -3.17609,78.30772,50.00000,0.0000e+000,20.00000,    -0.18991,0.53487
861.17200, 97.33083,    -3.17950,78.27034,50.00000,0.0000e+000,20.00000,    -0.19284,0.53423
862.98901, 97.51083,    -3.18354,78.23188,50.00000,0.0000e+000,20.00000,    -0.19609,0.53359
864.78699, 97.69083,    -3.18399,78.19579,50.00000,0.0000e+000,20.00000,    -0.19918,0.53295
866.58698, 97.87083,    -3.18720,78.16202,50.00000,0.0000e+000,20.00000,    -0.20199,0.53231
868.37299, 98.05083,    -3.19408,78.12398,50.00000,0.0000e+000,20.00000,    -0.20411,0.53168
870.19299, 98.23083,    -3.19972,78.08375,50.00000,0.0000e+000,20.00000,    -0.20651,0.53104
872.00098, 98.41084,    -3.20544,78.04516,50.00000,0.0000e+000,20.00000,    -0.20838,0.53040
873.81000, 98.59084,    -3.20794,78.00904,50.00000,0.0000e+000,20.00000,    -0.20977,0.52977
875.61700, 98.77084,    -3.21099,77.97181,50.00000,0.0000e+000,20.00000,    -0.21138,0.52913
877.42902, 98.95084,    -3.21558,77.93495,50.00000,0.0000e+000,20.00000,    -0.21293,0.52850
879.22998, 99.13084,    -3.22086,77.89742,50.00000,0.0000e+000,20.00000,    -0.21437,0.52786
881.04303, 99.31084,    -3.22554,77.85801,50.00000,0.0000e+000,20.00000,    -0.21587,0.52723
882.85498, 99.49084,    -3.23003,77.81804,50.00000,0.0000e+000,20.00000,    -0.21729,0.52659
884.65698, 99.67083,    -3.23250,77.77972,50.00000,0.0000e+000,20.00000,    -0.21948,0.52596
886.46899, 99.85083,    -3.23703,77.74166,50.00000,0.0000e+000,20.00000,    -0.22073,0.52533
888.26599,100.03083,    -3.24062,77.70043,50.00000,0.0000e+000,20.00000,    -0.22132,0.52470
890.07599,100.21083,    -3.24424,77.66016,50.00000,0.0000e+000,20.00000,    -0.22308,0.52407
891.88000,100.39083,    -3.24629,77.62069,50.00000,0.0000e+000,20.00000,    -0.22565,0.52344
893.67102,100.57083,    -3.25000,77.58107,50.00000,0.0000e+000,20.00000,    -0.22758,0.52282
895.46600,100.75083,    -3.25461,77.54113,50.00000,0.0000e+000,20.00000,    -0.22934,0.52220
897.28900,100.93083,    -3.26386,77.49931,50.00000,0.0000e+000,20.00000,    -0.23121,0.52156
899.11603,101.11083,    -3.27107,77.45534,50.00000,0.0000e+000,20.00000,    -0.23272,0.52093
900.92102,101.29083,    -3.27558,77.41315,50.00000,0.0000e+000,20.00000,    -0.23439,0.52030
902.73602,101.47083,    -3.28044,77.37151,50.00000,0.0000e+000,20.00000,    -0.23617,0.51967
904.52502,101.65083,    -3.27997,77.32972,50.00000,0.0000e+000,20.00000,    -0.23777,0.51905
906.33002,101.83083,    -3.28453,77.28755,50.00000,0.0000e+000,20.00000,    -0.23893,0.51843
908.14099,102.01083,    -3.28957,77.24259,50.00000,0.0000e+000,20.00000,    -0.24020,0.51780
909.96503,102.19083,    -3.29892,77.19669,50.00000,0.0000e+000,20.00000,    -0.24108,0.51717
911.80701,102.37083,    -3.31197,77.15238,50.00000,0.0000e+000,20.00000,    -0.24193,0.51653
913.65198,102.55083,    -3.31606,77.10898,50.00000,0.0000e+000,20.00000,    -0.24288,0.51589
915.43903,102.73083,    -3.31553,77.06499,50.00000,0.0000e+000,20.00000,    -0.24340,0.51528
917.23602,102.91084,    -3.31134,77.02043,50.00000,0.0000e+000,20.00000,    -0.24319,0.51466
919.02502,103.09084,    -3.31278,76.97448,50.00000,0.0000e+000,20.00000,    -0.24396,0.51404
920.81097,103.27084,    -3.31343,76.92897,50.00000,0.0000e+000,20.00000,    -0.24459,0.51342
922.60400,103.45084,    -3.31919,76.88538,50.00000,0.0000e+000,20.00000,    -0.24392,0.51280
924.41699,103.63084,    -3.32308,76.84050,50.00000,0.0000e+000,20.00000,    -0.24251,0.51218
926.21997,103.81084,    -3.32987,76.79499,50.00000,0.0000e+000,20.00000,    -0.24113,0.51156
928.01202,103.99084,    -3.33390,76.75204,50.00000,0.0000e+000,20.00000,    -0.23956,0.51094
929.82703,104.17083,    -3.34141,76.70943,50.00000,0.0000e+000,20.00000,    -0.23806,0.51031
931.65698,104.35083,    -3.34633,76.66620,50.00000,0.0000e+000,20.00000,    -0.23694,0.50968
933.46100,104.53083,    -3.34582,76.62283,50.00000,0.0000e+000,20.00000,    -0.23528,0.50906
935.26300,104.71083,    -3.35023,76.57982,50.00000,0.0000e+000,20.00000,    -0.23289,0.50844
937.09302,104.89083,    -3.35472,76.53486,50.00000,0.0000e+000,20.00000,    -0.23037,0.50781
938.89203,105.07083,    -3.35508,76.49026,50.00000,0.0000e+000,20.00000,    -0.22781,0.50719
940.70801,105.25083,    -3.35785,76.45038,50.00000,0.0000e+000,20.00000,    -0.22563,0.50657
942.52899,105.43083,    -3.35755,76.41338,50.00000,0.0000e+000,20.00000,    -0.22280,0.50594
944.35602,105.61083,    -3.36039,76.37458,50.00000,0.0000e+000,20.00000,    -0.22003,0.50531
946.16901,105.79083,    -3.35657,76.33403,50.00000,0.0000e+000,20.00000,    -0.21750,0.50469
947.98798,105.97083,    -3.35397,76.29491,50.00000,0.0000e+000,20.00000,    -0.21508,0.50406
949.82098,106.15083,    -3.35696,76.25562,50.00000,0.0000e+000,20.00000,    -0.21257,0.50343
951.64801,106.33083,    -3.35420,76.21735,50.00000,0.0000e+000,20.00000,    -0.20995,0.50280
953.45099,106.51083,    -3.34660,76.18161,50.00000,0.0000e+000,20.00000,    -0.20709,0.50218
955.24701,106.69083,    -3.34358,76.14514,50.00000,0.0000e+000,20.00000,    -0.20383,0.50156
957.05200,106.87083,    -3.34289,76.10867,50.00000,0.0000e+000,20.00000,    -0.20074,0.50094
958.84198,107.05083,    -3.34036,76.07269,50.00000,0.0000e+000,20.00000,    -0.19860,0.50032
960.63202,107.23083,    -3.33761,76.03841,50.00000,0.0000e+000,20.00000,    -0.19688,0.49971
962.41803,107.41084,    -3.33826,76.00306,50.00000,0.0000e+000,20.00000,    -0.19460,0.49909
964.19299,107.59084,    -3.33843,75.96862,50.00000,0.0000e+000,20.00000,    -0.19084,0.49848
965.98499,107.77084,    -3.34003,75.93507,50.00000,0.0000e+000,20.00000,    -0.18669,0.49786
967.77002,107.95084,    -3.34345,75.90105,50.00000,0.0000e+000,20.00000,    -0.18260,0.49725
969.55902,108.13084,    -3.34476,75.86722,50.00000,0.0000e+000,20.00000,    -0.17856,0.49663
971.33801,108.31084,    -3.34699,75.83436,50.00000,0.0000e+000,20.00000,    -0.17482,0.49601
973.13300,108.49084,    -3.35156,75.80204,50.00000,0.0000e+000,20.00000,    -0.17049,0.49539
974.92902,108.67083,    -3.35602,75.76819,50.00000,0.0000e+000,20.00000,    -0.16583,0.49477
976.71600,108.85083,    -3.35945,75.73527,50.00000,0.0000e+000,20.00000,    -0.16079,0.49416
978.48401,109.03083,    -3.35738,75.70401,50.00000,0.0000e+000,20.00000,    -0.15591,0.49354
980.25800,109.21083,    -3.36306,75.67397,50.00000,0.0000e+000,20.00000,    -0.15148,0.49293
982.06598,109.39083,    -3.37294,75.64642,50.00000,0.0000e+000,20.00000,    -0.14732,0.49230
983.89398,109.57083,    -3.38779,75.62221,50.00000,0.0000e+000,20.00000,    -0.14217,0.49167
985.71698,109.75083,    -3.39390,75.59794,50.00000,0.0000e+000,20.00000,    -0.13662,0.49104
987.53601,109.93083,    -3.39801,75.57390,50.00000,0.0000e+000,20.00000,    -0.12846,0.49041
989.35400,110.11083,    -3.40299,75.55137,50.00000,0.0000e+000,20.00000,    -0.12008,0.48978
991.16998,110.29083,    -3.40932,75.53064,50.00000,0.0000e+000,20.00000,    -0.11410,0.48915
992.99500,110.47083,    -3.41413,75.51102,50.00000,0.0000e+000,20.00000,    -0.10740,0.48851
994.78998,110.65083,    -3.41548,75.49296,50.00000,0.0000e+000,20.00000,    -0.10095,0.48789
996.59802,110.83083,    -3.41677,75.47638,50.00000,0.0000e+000,20.00000,-9.7133e-002,0.48726
998.34302,111.00584,    -3.41943,75.45856,50.00000,0.0000e+000,20.00000,-8.1238e-002,0.48665