File: book/some_content/TG_ExpDat_B30S70DC14; 30-1-2025-2.csv
#FILE:                       ,B30S70DC14; 30-1-2025.ngb-ds3
#FORMAT:                     ,NETZSCH5
#IDENTITY:                   ,geopolymer paste
#DECIMAL:                    ,POINT
#SEPARATOR:                  ,COMMA
#MTYPE:                      ,DSC
#INSTRUMENT:                 ,Microlab TU Delft
#PROJECT:                    ,
#DATE/TIME:                  ,30/01/2025 1:23:42 PM
#CORR. FILE:                 ,Blank with cover; 13-1-2025.ngb-bs3
#LABORATORY:                 ,TU Delft Micro Lab
#OPERATOR:                   ,Farnaz
#REMARK:                     ,under Argon atmosphere, 10K/min
#SAMPLE:                     ,B30S70DC14
#SAMPLE MASS /mg:            ,30.2
#MATERIAL:                   ,Chemical compound
#REFERENCE:                  ,blank
#REFERENCE MASS /mg:         ,0
#TYPE OF CRUCIBLE:           ,DSC/TG pan Al2O3
#SAMPLE CRUCIBLE MASS /mg:   ,0
#REFERENCE CRUCIBLE MASS /mg:,0
#CORR. CODE:                 ,020
#EXO:                        ,-1
#RANGE:                      ,40/10.0(K/min)/1000
#SEGMENT:                    ,S2/2

##Temp./øC,Time/min,DSC/(mW/mg),Mass/%,Gas Flow(purge1)/(ml/min),Gas Flow(purge2)/(ml/min),Gas Flow(protective)/(ml/min),DTG/(%/min),Sensit./(uV/mW)
 40.50700, 15.03167, 3.1356e-002,97.27641,50.00000,0.0000e+000,20.00000,-1.1474e-002,1.22624
 40.55100, 15.21167, 3.0884e-002,97.26614,50.00000,0.0000e+000,20.00000,-5.6683e-002,1.22618
 40.59200, 15.39167, 3.0844e-002,97.25401,50.00000,0.0000e+000,20.00000,-7.4585e-002,1.22613
 40.64800, 15.57167, 3.0496e-002,97.23713,50.00000,0.0000e+000,20.00000,-7.7627e-002,1.22605
 40.76000, 15.75167, 3.0520e-002,97.21974,50.00000,0.0000e+000,20.00000,-7.9204e-002,1.22589
 40.91000, 15.93167, 3.0834e-002,97.20375,50.00000,0.0000e+000,20.00000,-7.8348e-002,1.22569
 41.14700, 16.11167, 3.1564e-002,97.18899,50.00000,0.0000e+000,20.00000,-7.7474e-002,1.22536
 41.45400, 16.29167, 3.2379e-002,97.17441,50.00000,0.0000e+000,20.00000,-7.7162e-002,1.22494
 41.83800, 16.47167, 3.3879e-002,97.15887,50.00000,0.0000e+000,20.00000,-7.7948e-002,1.22441
 42.27100, 16.65167, 3.5526e-002,97.14419,50.00000,0.0000e+000,20.00000,-7.7817e-002,1.22381
 42.82300, 16.83167, 3.7366e-002,97.13145,50.00000,0.0000e+000,20.00000,-7.9675e-002,1.22305
 43.43100, 17.01167, 3.9893e-002,97.11842,50.00000,0.0000e+000,20.00000,-8.2803e-002,1.22221
 44.12700, 17.19167, 4.2386e-002,97.10522,50.00000,0.0000e+000,20.00000,-8.5388e-002,1.22125
 44.91300, 17.37167, 4.5363e-002,97.09264,50.00000,0.0000e+000,20.00000,-8.6604e-002,1.22017
 45.78400, 17.55167, 4.8144e-002,97.07864,50.00000,0.0000e+000,20.00000,-8.8445e-002,1.21897
 46.73500, 17.73167, 5.1515e-002,97.06315,50.00000,0.0000e+000,20.00000,-9.1686e-002,1.21766
 47.77800, 17.91167, 5.4754e-002,97.04828,50.00000,0.0000e+000,20.00000,-9.4853e-002,1.21622
 48.89400, 18.09167, 5.8505e-002,97.03488,50.00000,0.0000e+000,20.00000,-9.8405e-002,1.21468
 50.11200, 18.27167, 6.1980e-002,97.02085,50.00000,0.0000e+000,20.00000,    -0.10376,1.21301
 51.38200, 18.45167, 6.5636e-002,97.00514,50.00000,0.0000e+000,20.00000,    -0.11072,1.21126
 52.76400, 18.63167, 6.9625e-002,96.98760,50.00000,0.0000e+000,20.00000,    -0.11839,1.20935
 54.18300, 18.81167, 7.3378e-002,96.96829,50.00000,0.0000e+000,20.00000,    -0.12595,1.20740
 55.70000, 18.99167, 7.7362e-002,96.94724,50.00000,0.0000e+000,20.00000,    -0.13424,1.20531
 57.30800, 19.17167, 8.1515e-002,96.92664,50.00000,0.0000e+000,20.00000,    -0.14437,1.20310
 58.98400, 19.35167, 8.5732e-002,96.90310,50.00000,0.0000e+000,20.00000,    -0.15622,1.20080
 60.73500, 19.53167, 9.0057e-002,96.87533,50.00000,0.0000e+000,20.00000,    -0.16814,1.19839
 62.55000, 19.71167, 9.4195e-002,96.84839,50.00000,0.0000e+000,20.00000,    -0.18019,1.19590
 64.42300, 19.89167, 9.8780e-002,96.82168,50.00000,0.0000e+000,20.00000,    -0.19436,1.19333
 66.37500, 20.07167,     0.10369,96.78788,50.00000,0.0000e+000,20.00000,    -0.20956,1.19065
 68.37300, 20.25167,     0.10842,96.74793,50.00000,0.0000e+000,20.00000,    -0.22548,1.18791
 70.41500, 20.43167,     0.11364,96.70682,50.00000,0.0000e+000,20.00000,    -0.24237,1.18511
 72.49700, 20.61167,     0.11889,96.66643,50.00000,0.0000e+000,20.00000,    -0.26031,1.18225
 74.68600, 20.79167,     0.12408,96.62352,50.00000,0.0000e+000,20.00000,    -0.27769,1.17926
 76.87000, 20.97167,     0.12951,96.57502,50.00000,0.0000e+000,20.00000,    -0.29588,1.17627
 79.11800, 21.15167,     0.13577,96.51902,50.00000,0.0000e+000,20.00000,    -0.31343,1.17319
 81.37500, 21.33167,     0.14096,96.45983,50.00000,0.0000e+000,20.00000,    -0.32944,1.17011
 83.67300, 21.51167,     0.14716,96.40128,50.00000,0.0000e+000,20.00000,    -0.34589,1.16697
 86.01300, 21.69167,     0.15306,96.33686,50.00000,0.0000e+000,20.00000,    -0.36274,1.16378
 88.41500, 21.87167,     0.15867,96.26802,50.00000,0.0000e+000,20.00000,    -0.37867,1.16051
 90.82000, 22.05167,     0.16403,96.19510,50.00000,0.0000e+000,20.00000,    -0.39286,1.15724
 93.24700, 22.23167,     0.16963,96.11709,50.00000,0.0000e+000,20.00000,    -0.40540,1.15394
 95.70900, 22.41167,     0.17475,96.03296,50.00000,0.0000e+000,20.00000,    -0.41803,1.15059
 98.19200, 22.59167,     0.17954,95.94852,50.00000,0.0000e+000,20.00000,    -0.43054,1.14722
100.68100, 22.77167,     0.18338,95.86190,50.00000,0.0000e+000,20.00000,    -0.44092,1.14385
103.16000, 22.95167,     0.18709,95.77461,50.00000,0.0000e+000,20.00000,    -0.44771,1.14050
105.63600, 23.13167,     0.18935,95.68881,50.00000,0.0000e+000,20.00000,    -0.45305,1.13715
108.11500, 23.31167,     0.19115,95.60154,50.00000,0.0000e+000,20.00000,    -0.45917,1.13380
110.60300, 23.49167,     0.19185,95.51382,50.00000,0.0000e+000,20.00000,    -0.46347,1.13045
113.11200, 23.67167,     0.19176,95.42368,50.00000,0.0000e+000,20.00000,    -0.46586,1.12707
115.58600, 23.85167,     0.19057,95.33202,50.00000,0.0000e+000,20.00000,    -0.46814,1.12374
118.04500, 24.03167,     0.18809,95.24449,50.00000,0.0000e+000,20.00000,    -0.46938,1.12044
120.55000, 24.21167,     0.18544,95.15816,50.00000,0.0000e+000,20.00000,    -0.46813,1.11709
123.00000, 24.39167,     0.18132,95.07019,50.00000,0.0000e+000,20.00000,    -0.46778,1.11381
125.46100, 24.57167,     0.17667,94.98410,50.00000,0.0000e+000,20.00000,    -0.46772,1.11052
127.93400, 24.75167,     0.17103,94.90354,50.00000,0.0000e+000,20.00000,    -0.46624,1.10722
130.35201, 24.93167,     0.16512,94.82513,50.00000,0.0000e+000,20.00000,    -0.46288,1.10400
132.81100, 25.11167,     0.15816,94.74460,50.00000,0.0000e+000,20.00000,    -0.45826,1.10073
135.21800, 25.29167,     0.15038,94.66502,50.00000,0.0000e+000,20.00000,    -0.45331,1.09753
137.62601, 25.47167,     0.14248,94.58798,50.00000,0.0000e+000,20.00000,    -0.44786,1.09434
140.00700, 25.65167,     0.13416,94.50813,50.00000,0.0000e+000,20.00000,    -0.43982,1.09119
142.38699, 25.83167,     0.12715,94.42611,50.00000,0.0000e+000,20.00000,    -0.43118,1.08804
144.74600, 26.01167,     0.12227,94.34718,50.00000,0.0000e+000,20.00000,    -0.42267,1.08493
147.06500, 26.19167,     0.11904,94.26481,50.00000,0.0000e+000,20.00000,    -0.41290,1.08188
149.38100, 26.37167,     0.11633,94.17894,50.00000,0.0000e+000,20.00000,    -0.40250,1.07884
151.66299, 26.55167,     0.11264,94.09573,50.00000,0.0000e+000,20.00000,    -0.39244,1.07585
153.93300, 26.73167,     0.10629,94.02106,50.00000,0.0000e+000,20.00000,    -0.38320,1.07287
156.16800, 26.91167, 9.6688e-002,93.95066,50.00000,0.0000e+000,20.00000,    -0.37298,1.06995
158.39200, 27.09167, 8.4355e-002,93.88122,50.00000,0.0000e+000,20.00000,    -0.36216,1.06705
160.58501, 27.27167, 7.0647e-002,93.81115,50.00000,0.0000e+000,20.00000,    -0.35140,1.06420
162.77600, 27.45167, 5.5960e-002,93.74731,50.00000,0.0000e+000,20.00000,    -0.33948,1.06135
164.92000, 27.63167, 4.1048e-002,93.69026,50.00000,0.0000e+000,20.00000,    -0.32626,1.05857
167.04201, 27.81167, 2.6607e-002,93.63490,50.00000,0.0000e+000,20.00000,    -0.31375,1.05582
169.17599, 27.99167, 1.2211e-002,93.58231,50.00000,0.0000e+000,20.00000,    -0.30037,1.05306
171.26500, 28.17167,-2.4292e-003,93.53301,50.00000,0.0000e+000,20.00000,    -0.28554,1.05037
173.33800, 28.35167,-1.5938e-002,93.48791,50.00000,0.0000e+000,20.00000,    -0.27058,1.04770
175.39500, 28.53167,-2.9589e-002,93.44351,50.00000,0.0000e+000,20.00000,    -0.25746,1.04506
177.42799, 28.71167,-4.2482e-002,93.40011,50.00000,0.0000e+000,20.00000,    -0.24517,1.04245
179.45100, 28.89167,-5.5027e-002,93.35933,50.00000,0.0000e+000,20.00000,    -0.23370,1.03986
181.47200, 29.07167,-6.6586e-002,93.32107,50.00000,0.0000e+000,20.00000,    -0.22218,1.03728
183.46100, 29.25167,-7.7858e-002,93.28515,50.00000,0.0000e+000,20.00000,    -0.21066,1.03474
185.43300, 29.43167,-8.9061e-002,93.25112,50.00000,0.0000e+000,20.00000,    -0.20094,1.03224
187.39101, 29.61167,-9.9702e-002,93.21765,50.00000,0.0000e+000,20.00000,    -0.19216,1.02975
189.33800, 29.79167,    -0.10953,93.18480,50.00000,0.0000e+000,20.00000,    -0.18375,1.02728
191.26801, 29.97167,    -0.11963,93.15317,50.00000,0.0000e+000,20.00000,    -0.17553,1.02484
193.17900, 30.15167,    -0.12871,93.12339,50.00000,0.0000e+000,20.00000,    -0.16835,1.02243
195.07899, 30.33167,    -0.13775,93.09517,50.00000,0.0000e+000,20.00000,    -0.16126,1.02003
196.96400, 30.51167,    -0.14649,93.06917,50.00000,0.0000e+000,20.00000,    -0.15406,1.01766
198.83800, 30.69167,    -0.15501,93.04222,50.00000,0.0000e+000,20.00000,    -0.14766,1.01531
200.69501, 30.87167,    -0.16325,93.01359,50.00000,0.0000e+000,20.00000,    -0.14207,1.01298
202.53600, 31.05167,    -0.17115,92.98988,50.00000,0.0000e+000,20.00000,    -0.13678,1.01068
204.37100, 31.23167,    -0.17880,92.96789,50.00000,0.0000e+000,20.00000,    -0.13195,1.00839
206.18700, 31.41167,    -0.18669,92.94454,50.00000,0.0000e+000,20.00000,    -0.12762,1.00613
207.99100, 31.59167,    -0.19395,92.92177,50.00000,0.0000e+000,20.00000,    -0.12305,1.00389
209.80000, 31.77167,    -0.20180,92.90170,50.00000,0.0000e+000,20.00000,    -0.11880,1.00165
211.59900, 31.95167,    -0.20922,92.88227,50.00000,0.0000e+000,20.00000,    -0.11575,0.99942
213.39000, 32.13167,    -0.21683,92.86368,50.00000,0.0000e+000,20.00000,    -0.11278,0.99721
215.16200, 32.31167,    -0.22396,92.84618,50.00000,0.0000e+000,20.00000,    -0.10943,0.99502
216.93300, 32.49166,    -0.23056,92.82845,50.00000,0.0000e+000,20.00000,    -0.10589,0.99285
218.70000, 32.67167,    -0.23805,92.81030,50.00000,0.0000e+000,20.00000,    -0.10195,0.99068
220.47301, 32.85167,    -0.24460,92.79300,50.00000,0.0000e+000,20.00000,-9.9959e-002,0.98851
222.23100, 33.03167,    -0.25177,92.77666,50.00000,0.0000e+000,20.00000,-9.8509e-002,0.98636
223.98100, 33.21167,    -0.25858,92.75896,50.00000,0.0000e+000,20.00000,-9.7086e-002,0.98422
225.73000, 33.39167,    -0.26544,92.74246,50.00000,0.0000e+000,20.00000,-9.4703e-002,0.98209
227.48000, 33.57167,    -0.27226,92.72633,50.00000,0.0000e+000,20.00000,-9.2840e-002,0.97997
229.23399, 33.75167,    -0.27951,92.70775,50.00000,0.0000e+000,20.00000,-9.1363e-002,0.97784
230.97301, 33.93167,    -0.28625,92.68953,50.00000,0.0000e+000,20.00000,-8.9878e-002,0.97574
232.69600, 34.11167,    -0.29361,92.67517,50.00000,0.0000e+000,20.00000,-8.8810e-002,0.97366
234.44400, 34.29167,    -0.30002,92.66164,50.00000,0.0000e+000,20.00000,-8.7129e-002,0.97155
236.16100, 34.47167,    -0.30717,92.64757,50.00000,0.0000e+000,20.00000,-8.6120e-002,0.96949
237.90100, 34.65167,    -0.31371,92.63051,50.00000,0.0000e+000,20.00000,-8.4698e-002,0.96740
239.63499, 34.83167,    -0.32066,92.61394,50.00000,0.0000e+000,20.00000,-8.3587e-002,0.96533
241.36400, 35.01167,    -0.32733,92.59594,50.00000,0.0000e+000,20.00000,-8.1962e-002,0.96327
243.09100, 35.19167,    -0.33455,92.58091,50.00000,0.0000e+000,20.00000,-8.0425e-002,0.96121
244.82300, 35.37167,    -0.34148,92.56758,50.00000,0.0000e+000,20.00000,-7.9580e-002,0.95915
246.55400, 35.55167,    -0.34879,92.55332,50.00000,0.0000e+000,20.00000,-7.7885e-002,0.95710
248.27000, 35.73167,    -0.35590,92.54011,50.00000,0.0000e+000,20.00000,-7.5958e-002,0.95507
250.00700, 35.91167,    -0.36314,92.52611,50.00000,0.0000e+000,20.00000,-7.5681e-002,0.95302
251.73199, 36.09167,    -0.37095,92.51467,50.00000,0.0000e+000,20.00000,-7.5901e-002,0.95099
253.46700, 36.27167,    -0.37811,92.50053,50.00000,0.0000e+000,20.00000,-7.5450e-002,0.94895
255.20500, 36.45167,    -0.38575,92.48768,50.00000,0.0000e+000,20.00000,-7.3952e-002,0.94691
256.92700, 36.63167,    -0.39294,92.47569,50.00000,0.0000e+000,20.00000,-7.2500e-002,0.94490
258.68201, 36.81167,    -0.40038,92.46372,50.00000,0.0000e+000,20.00000,-7.0796e-002,0.94286
260.40302, 36.99166,    -0.40752,92.45282,50.00000,0.0000e+000,20.00000,-6.9322e-002,0.94085
262.15701, 37.17167,    -0.41435,92.43996,50.00000,0.0000e+000,20.00000,-6.8817e-002,0.93882
263.88000, 37.35167,    -0.42114,92.42785,50.00000,0.0000e+000,20.00000,-6.8280e-002,0.93682
265.62201, 37.53167,    -0.42866,92.41630,50.00000,0.0000e+000,20.00000,-6.7856e-002,0.93481
267.36801, 37.71167,    -0.43528,92.40290,50.00000,0.0000e+000,20.00000,-6.7535e-002,0.93280
269.09299, 37.89167,    -0.44226,92.38833,50.00000,0.0000e+000,20.00000,-6.7926e-002,0.93082
270.83200, 38.07167,    -0.44862,92.37590,50.00000,0.0000e+000,20.00000,-6.7992e-002,0.92882
272.58200, 38.25167,    -0.45577,92.36458,50.00000,0.0000e+000,20.00000,-6.8351e-002,0.92682
274.33499, 38.43167,    -0.46280,92.35330,50.00000,0.0000e+000,20.00000,-6.9121e-002,0.92482
276.07101, 38.61167,    -0.46923,92.34161,50.00000,0.0000e+000,20.00000,-6.9745e-002,0.92285
277.81799, 38.79167,    -0.47576,92.33112,50.00000,0.0000e+000,20.00000,-7.1165e-002,0.92087
279.56000, 38.97167,    -0.48192,92.32012,50.00000,0.0000e+000,20.00000,-7.1809e-002,0.91889
281.28699, 39.15167,    -0.48796,92.30764,50.00000,0.0000e+000,20.00000,-7.2135e-002,0.91694
283.04599, 39.33167,    -0.49412,92.29604,50.00000,0.0000e+000,20.00000,-7.2718e-002,0.91496
284.79001, 39.51167,    -0.50061,92.28328,50.00000,0.0000e+000,20.00000,-7.3194e-002,0.91301
286.53601, 39.69167,    -0.50645,92.27023,50.00000,0.0000e+000,20.00000,-7.2766e-002,0.91105
288.27899, 39.87167,    -0.51295,92.25648,50.00000,0.0000e+000,20.00000,-7.3431e-002,0.90910
290.02701, 40.05167,    -0.51898,92.24191,50.00000,0.0000e+000,20.00000,-7.4715e-002,0.90716
291.79099, 40.23167,    -0.52600,92.22717,50.00000,0.0000e+000,20.00000,-7.6457e-002,0.90520
293.53799, 40.41167,    -0.53235,92.21281,50.00000,0.0000e+000,20.00000,-7.7972e-002,0.90326
295.29199, 40.59167,    -0.53857,92.19695,50.00000,0.0000e+000,20.00000,-7.9416e-002,0.90132
297.04501, 40.77167,    -0.54473,92.18166,50.00000,0.0000e+000,20.00000,-8.1177e-002,0.89939
298.79300, 40.95167,    -0.55090,92.16798,50.00000,0.0000e+000,20.00000,-8.2602e-002,0.89747
300.54999, 41.13167,    -0.55683,92.15456,50.00000,0.0000e+000,20.00000,-8.3929e-002,0.89555
302.32401, 41.31167,    -0.56278,92.13975,50.00000,0.0000e+000,20.00000,-8.5291e-002,0.89361
304.10001, 41.49166,    -0.56834,92.12653,50.00000,0.0000e+000,20.00000,-8.6662e-002,0.89167
305.84601, 41.67167,    -0.57316,92.11178,50.00000,0.0000e+000,20.00000,-8.7893e-002,0.88978
307.60501, 41.85167,    -0.57883,92.09572,50.00000,0.0000e+000,20.00000,-8.9134e-002,0.88787
309.39301, 42.03167,    -0.58399,92.07837,50.00000,0.0000e+000,20.00000,-9.0100e-002,0.88594
311.14499, 42.21167,    -0.58984,92.06090,50.00000,0.0000e+000,20.00000,-9.1063e-002,0.88405
312.91501, 42.39167,    -0.59515,92.04486,50.00000,0.0000e+000,20.00000,-9.1435e-002,0.88215
314.68701, 42.57167,    -0.60102,92.02799,50.00000,0.0000e+000,20.00000,-9.2100e-002,0.88026
316.44901, 42.75167,    -0.60691,92.01021,50.00000,0.0000e+000,20.00000,-9.3609e-002,0.87838
318.22299, 42.93167,    -0.61286,91.99360,50.00000,0.0000e+000,20.00000,-9.5716e-002,0.87649
319.99200, 43.11167,    -0.61787,91.97637,50.00000,0.0000e+000,20.00000,-9.8085e-002,0.87461
321.77399, 43.29167,    -0.62349,91.95819,50.00000,0.0000e+000,20.00000,    -0.10011,0.87273
323.54501, 43.47167,    -0.62930,91.94027,50.00000,0.0000e+000,20.00000,    -0.10157,0.87086
325.30499, 43.65167,    -0.63482,91.92127,50.00000,0.0000e+000,20.00000,    -0.10235,0.86901
327.09399, 43.83167,    -0.63987,91.90285,50.00000,0.0000e+000,20.00000,    -0.10341,0.86713
328.86301, 44.01167,    -0.64532,91.88491,50.00000,0.0000e+000,20.00000,    -0.10467,0.86528
330.63501, 44.19167,    -0.65109,91.86785,50.00000,0.0000e+000,20.00000,    -0.10667,0.86344
332.42300, 44.37167,    -0.65663,91.85015,50.00000,0.0000e+000,20.00000,    -0.10888,0.86158
334.20200, 44.55167,    -0.66162,91.83085,50.00000,0.0000e+000,20.00000,    -0.11159,0.85974
335.96301, 44.73167,    -0.66691,91.81035,50.00000,0.0000e+000,20.00000,    -0.11509,0.85792
337.74799, 44.91167,    -0.67135,91.78693,50.00000,0.0000e+000,20.00000,    -0.11837,0.85608
339.53101, 45.09167,    -0.67598,91.76571,50.00000,0.0000e+000,20.00000,    -0.12159,0.85425
341.29800, 45.27167,    -0.68133,91.74589,50.00000,0.0000e+000,20.00000,    -0.12601,0.85245
343.07999, 45.45167,    -0.68703,91.72713,50.00000,0.0000e+000,20.00000,    -0.13044,0.85063
344.87100, 45.63167,    -0.69261,91.70647,50.00000,0.0000e+000,20.00000,    -0.13409,0.84881
346.64801, 45.81167,    -0.69724,91.68439,50.00000,0.0000e+000,20.00000,    -0.13780,0.84701
348.44199, 45.99166,    -0.70074,91.66106,50.00000,0.0000e+000,20.00000,    -0.14294,0.84520
350.20999, 46.17167,    -0.70482,91.63671,50.00000,0.0000e+000,20.00000,    -0.14911,0.84342
352.00101, 46.35167,    -0.70852,91.60943,50.00000,0.0000e+000,20.00000,    -0.15407,0.84163
353.79001, 46.53167,    -0.71162,91.58001,50.00000,0.0000e+000,20.00000,    -0.15876,0.83984
355.56000, 46.71167,    -0.71553,91.55088,50.00000,0.0000e+000,20.00000,    -0.16246,0.83807
357.33301, 46.89167,    -0.71800,91.52136,50.00000,0.0000e+000,20.00000,    -0.16645,0.83631
359.11499, 47.07167,    -0.72073,91.48794,50.00000,0.0000e+000,20.00000,    -0.17094,0.83455
360.88699, 47.25167,    -0.72358,91.45264,50.00000,0.0000e+000,20.00000,    -0.17583,0.83280
362.66199, 47.43167,    -0.72725,91.42024,50.00000,0.0000e+000,20.00000,    -0.18022,0.83106
364.43399, 47.61167,    -0.73134,91.38899,50.00000,0.0000e+000,20.00000,    -0.18443,0.82932
366.20300, 47.79167,    -0.73640,91.35390,50.00000,0.0000e+000,20.00000,    -0.18953,0.82759
367.98999, 47.97167,    -0.74138,91.31404,50.00000,0.0000e+000,20.00000,    -0.19359,0.82585
369.76401, 48.15167,    -0.74664,91.27628,50.00000,0.0000e+000,20.00000,    -0.19675,0.82413
371.55200, 48.33167,    -0.75125,91.23918,50.00000,0.0000e+000,20.00000,    -0.19890,0.82240
373.32901, 48.51167,    -0.75626,91.20224,50.00000,0.0000e+000,20.00000,    -0.20059,0.82069
375.12399, 48.69167,    -0.76131,91.16603,50.00000,0.0000e+000,20.00000,    -0.20262,0.81897
376.91000, 48.87167,    -0.76649,91.12962,50.00000,0.0000e+000,20.00000,    -0.20400,0.81726
378.68600, 49.05167,    -0.77179,91.09304,50.00000,0.0000e+000,20.00000,    -0.20458,0.81557
380.47601, 49.23167,    -0.77663,91.05653,50.00000,0.0000e+000,20.00000,    -0.20509,0.81387
382.24100, 49.41167,    -0.78162,91.01983,50.00000,0.0000e+000,20.00000,    -0.20603,0.81220
384.05099, 49.59167,    -0.78695,90.97832,50.00000,0.0000e+000,20.00000,    -0.20666,0.81049
385.83499, 49.77167,    -0.79270,90.93881,50.00000,0.0000e+000,20.00000,    -0.20555,0.80881
387.61899, 49.95167,    -0.79951,90.90058,50.00000,0.0000e+000,20.00000,    -0.20429,0.80714
389.39700, 50.13167,    -0.80642,90.86307,50.00000,0.0000e+000,20.00000,    -0.20248,0.80548
391.17801, 50.31167,    -0.81371,90.82763,50.00000,0.0000e+000,20.00000,    -0.20040,0.80383
392.94501, 50.49166,    -0.82221,90.79120,50.00000,0.0000e+000,20.00000,    -0.19897,0.80219
394.73700, 50.67167,    -0.83047,90.75351,50.00000,0.0000e+000,20.00000,    -0.19757,0.80053
396.53799, 50.85167,    -0.83975,90.71585,50.00000,0.0000e+000,20.00000,    -0.19620,0.79888
398.33301, 51.03167,    -0.84893,90.68052,50.00000,0.0000e+000,20.00000,    -0.19490,0.79723
400.11499, 51.21167,    -0.85730,90.64637,50.00000,0.0000e+000,20.00000,    -0.19353,0.79560
401.89899, 51.39167,    -0.86497,90.60987,50.00000,0.0000e+000,20.00000,    -0.19083,0.79398
403.68100, 51.57167,    -0.87248,90.57426,50.00000,0.0000e+000,20.00000,    -0.18867,0.79237
405.45901, 51.75167,    -0.87910,90.54012,50.00000,0.0000e+000,20.00000,    -0.18829,0.79076
407.22601, 51.93167,    -0.88555,90.50942,50.00000,0.0000e+000,20.00000,    -0.18752,0.78917
409.01099, 52.11167,    -0.89283,90.47995,50.00000,0.0000e+000,20.00000,    -0.18618,0.78757
410.79401, 52.29167,    -0.90117,90.44916,50.00000,0.0000e+000,20.00000,    -0.18532,0.78598
412.56400, 52.47167,    -0.91016,90.41789,50.00000,0.0000e+000,20.00000,    -0.18452,0.78440
414.36301, 52.65167,    -0.91876,90.38637,50.00000,0.0000e+000,20.00000,    -0.18323,0.78281
416.14600, 52.83167,    -0.92731,90.35461,50.00000,0.0000e+000,20.00000,    -0.18237,0.78123
417.93100, 53.01167,    -0.93604,90.32308,50.00000,0.0000e+000,20.00000,    -0.18198,0.77966
419.74500, 53.19167,    -0.94403,90.29214,50.00000,0.0000e+000,20.00000,    -0.18104,0.77807
421.54800, 53.37167,    -0.95141,90.26015,50.00000,0.0000e+000,20.00000,    -0.17981,0.77649
423.34799, 53.55167,    -0.95763,90.22416,50.00000,0.0000e+000,20.00000,    -0.17872,0.77493
425.13300, 53.73167,    -0.96465,90.18815,50.00000,0.0000e+000,20.00000,    -0.17913,0.77338
426.92001, 53.91167,    -0.97099,90.15731,50.00000,0.0000e+000,20.00000,    -0.18093,0.77184
428.72900, 54.09167,    -0.97764,90.12487,50.00000,0.0000e+000,20.00000,    -0.18265,0.77028
430.51700, 54.27167,    -0.98344,90.09007,50.00000,0.0000e+000,20.00000,    -0.18387,0.76875
432.31400, 54.45167,    -0.98926,90.05687,50.00000,0.0000e+000,20.00000,    -0.18463,0.76722
434.09500, 54.63167,    -0.99510,90.02412,50.00000,0.0000e+000,20.00000,    -0.18575,0.76570
435.88300, 54.81167,    -1.00111,89.99163,50.00000,0.0000e+000,20.00000,    -0.18713,0.76419
437.67300, 54.99166,    -1.00713,89.95874,50.00000,0.0000e+000,20.00000,    -0.18884,0.76268
439.46201, 55.17167,    -1.01320,89.92710,50.00000,0.0000e+000,20.00000,    -0.19001,0.76118
441.25000, 55.35167,    -1.01932,89.89666,50.00000,0.0000e+000,20.00000,    -0.18990,0.75968
443.03799, 55.53167,    -1.02516,89.86450,50.00000,0.0000e+000,20.00000,    -0.19023,0.75819
444.82501, 55.71167,    -1.03118,89.82885,50.00000,0.0000e+000,20.00000,    -0.19279,0.75670
446.60999, 55.89167,    -1.03654,89.79200,50.00000,0.0000e+000,20.00000,    -0.19486,0.75523
448.40500, 56.07167,    -1.04199,89.75595,50.00000,0.0000e+000,20.00000,    -0.19525,0.75375
450.18701, 56.25167,    -1.04778,89.72167,50.00000,0.0000e+000,20.00000,    -0.19645,0.75229
451.96799, 56.43167,    -1.05253,89.68621,50.00000,0.0000e+000,20.00000,    -0.19810,0.75083
453.74701, 56.61167,    -1.05895,89.64951,50.00000,0.0000e+000,20.00000,    -0.19969,0.74938
455.54800, 56.79167,    -1.06460,89.61240,50.00000,0.0000e+000,20.00000,    -0.20107,0.74792
457.33200, 56.97167,    -1.07142,89.57603,50.00000,0.0000e+000,20.00000,    -0.20308,0.74648
459.11499, 57.15167,    -1.07694,89.54139,50.00000,0.0000e+000,20.00000,    -0.20602,0.74505
460.90500, 57.33167,    -1.08235,89.50396,50.00000,0.0000e+000,20.00000,    -0.20862,0.74361
462.69199, 57.51167,    -1.08722,89.46359,50.00000,0.0000e+000,20.00000,    -0.21011,0.74219
464.47198, 57.69167,    -1.09209,89.42365,50.00000,0.0000e+000,20.00000,    -0.21158,0.74077
466.26999, 57.87167,    -1.09700,89.38723,50.00000,0.0000e+000,20.00000,    -0.21345,0.73935
468.05899, 58.05167,    -1.10159,89.34976,50.00000,0.0000e+000,20.00000,    -0.21656,0.73794
469.85300, 58.23167,    -1.10500,89.31103,50.00000,0.0000e+000,20.00000,    -0.21953,0.73653
471.63501, 58.41167,    -1.10947,89.27256,50.00000,0.0000e+000,20.00000,    -0.22155,0.73514
473.42499, 58.59167,    -1.11409,89.23472,50.00000,0.0000e+000,20.00000,    -0.22338,0.73375
475.22800, 58.77167,    -1.11821,89.19570,50.00000,0.0000e+000,20.00000,    -0.22585,0.73235
477.03500, 58.95167,    -1.12228,89.15479,50.00000,0.0000e+000,20.00000,    -0.22867,0.73095
478.83701, 59.13167,    -1.12670,89.11331,50.00000,0.0000e+000,20.00000,    -0.23067,0.72957
480.63400, 59.31167,    -1.13102,89.07287,50.00000,0.0000e+000,20.00000,    -0.23227,0.72819
482.42899, 59.49166,    -1.13342,89.03083,50.00000,0.0000e+000,20.00000,    -0.23435,0.72682
484.21301, 59.67167,    -1.13599,88.98791,50.00000,0.0000e+000,20.00000,    -0.23755,0.72547
485.99799, 59.85167,    -1.13696,88.94255,50.00000,0.0000e+000,20.00000,    -0.23964,0.72412
487.77200, 60.03167,    -1.13798,88.89631,50.00000,0.0000e+000,20.00000,    -0.24108,0.72278
489.56601, 60.21167,    -1.13961,88.85201,50.00000,0.0000e+000,20.00000,    -0.24290,0.72144
491.34299, 60.39167,    -1.14108,88.80848,50.00000,0.0000e+000,20.00000,    -0.24502,0.72011
493.13000, 60.57167,    -1.14431,88.76300,50.00000,0.0000e+000,20.00000,    -0.24660,0.71878
494.91299, 60.75167,    -1.14853,88.71775,50.00000,0.0000e+000,20.00000,    -0.24773,0.71746
496.71600, 60.93167,    -1.15179,88.67368,50.00000,0.0000e+000,20.00000,    -0.24892,0.71613
498.50201, 61.11167,    -1.15475,88.62808,50.00000,0.0000e+000,20.00000,    -0.25019,0.71482
500.32199, 61.29167,    -1.15956,88.58049,50.00000,0.0000e+000,20.00000,    -0.25145,0.71349
502.16101, 61.47167,    -1.16667,88.53172,50.00000,0.0000e+000,20.00000,    -0.25332,0.71215
504.00601, 61.65167,    -1.17292,88.48642,50.00000,0.0000e+000,20.00000,    -0.25533,0.71081
505.83801, 61.83167,    -1.17586,88.44266,50.00000,0.0000e+000,20.00000,    -0.25594,0.70949
507.66101, 62.01167,    -1.17639,88.39757,50.00000,0.0000e+000,20.00000,    -0.25515,0.70818
509.47601, 62.19167,    -1.17369,88.35193,50.00000,0.0000e+000,20.00000,    -0.25543,0.70688
511.26401, 62.37167,    -1.17115,88.30721,50.00000,0.0000e+000,20.00000,    -0.25619,0.70561
513.05902, 62.55167,    -1.16857,88.26270,50.00000,0.0000e+000,20.00000,    -0.25660,0.70433
514.82001, 62.73167,    -1.16619,88.21672,50.00000,0.0000e+000,20.00000,    -0.25673,0.70309
516.58197, 62.91167,    -1.16468,88.17164,50.00000,0.0000e+000,20.00000,    -0.25702,0.70185
518.33301, 63.09167,    -1.16304,88.12557,50.00000,0.0000e+000,20.00000,    -0.25727,0.70062
520.10101, 63.27167,    -1.16325,88.07654,50.00000,0.0000e+000,20.00000,    -0.25680,0.69939
521.88898, 63.45167,    -1.16655,88.02443,50.00000,0.0000e+000,20.00000,    -0.25731,0.69815
523.67603, 63.63167,    -1.17134,87.97470,50.00000,0.0000e+000,20.00000,    -0.25961,0.69691
525.47400, 63.81167,    -1.17509,87.93241,50.00000,0.0000e+000,20.00000,    -0.26191,0.69567
527.28497, 63.99166,    -1.17814,87.88884,50.00000,0.0000e+000,20.00000,    -0.26287,0.69443
529.08099, 64.17167,    -1.17968,87.84101,50.00000,0.0000e+000,20.00000,    -0.26376,0.69321
530.86700, 64.35167,    -1.18029,87.79370,50.00000,0.0000e+000,20.00000,    -0.26453,0.69199
532.66699, 64.53167,    -1.18054,87.74894,50.00000,0.0000e+000,20.00000,    -0.26520,0.69078
534.46899, 64.71167,    -1.18053,87.70310,50.00000,0.0000e+000,20.00000,    -0.26664,0.68956
536.26599, 64.89167,    -1.18065,87.65496,50.00000,0.0000e+000,20.00000,    -0.26797,0.68836
538.05402, 65.07166,    -1.18116,87.60757,50.00000,0.0000e+000,20.00000,    -0.26869,0.68716
539.84998, 65.25166,    -1.18119,87.56023,50.00000,0.0000e+000,20.00000,    -0.26876,0.68597
541.66199, 65.43166,    -1.18175,87.50880,50.00000,0.0000e+000,20.00000,    -0.26887,0.68477
543.45599, 65.61166,    -1.18183,87.45519,50.00000,0.0000e+000,20.00000,    -0.27138,0.68358
545.25299, 65.79166,    -1.18139,87.40543,50.00000,0.0000e+000,20.00000,    -0.27409,0.68241
547.04303, 65.97166,    -1.18138,87.35730,50.00000,0.0000e+000,20.00000,    -0.27543,0.68124
548.84497, 66.15166,    -1.18034,87.30992,50.00000,0.0000e+000,20.00000,    -0.27636,0.68006
550.62402, 66.33167,    -1.17895,87.26209,50.00000,0.0000e+000,20.00000,    -0.27860,0.67891
552.42798, 66.51167,    -1.17811,87.21170,50.00000,0.0000e+000,20.00000,    -0.28106,0.67775
554.23199, 66.69167,    -1.17856,87.16110,50.00000,0.0000e+000,20.00000,    -0.28221,0.67659
556.03400, 66.87167,    -1.17885,87.11013,50.00000,0.0000e+000,20.00000,    -0.28301,0.67544
557.85101, 67.05167,    -1.17888,87.05807,50.00000,0.0000e+000,20.00000,    -0.28365,0.67428
559.64203, 67.23167,    -1.17723,87.00694,50.00000,0.0000e+000,20.00000,    -0.28391,0.67315
561.49200, 67.41167,    -1.18006,86.95488,50.00000,0.0000e+000,20.00000,    -0.28385,0.67198
563.34003, 67.59167,    -1.18568,86.90218,50.00000,0.0000e+000,20.00000,    -0.28433,0.67082
565.18903, 67.77167,    -1.18667,86.84957,50.00000,0.0000e+000,20.00000,    -0.28493,0.66966
566.96198, 67.95167,    -1.17782,86.79860,50.00000,0.0000e+000,20.00000,    -0.28596,0.66856
568.74500, 68.13167,    -1.16883,86.74574,50.00000,0.0000e+000,20.00000,    -0.28730,0.66745
570.49597, 68.31167,    -1.16155,86.69133,50.00000,0.0000e+000,20.00000,    -0.28775,0.66637
572.25897, 68.49167,    -1.15562,86.63869,50.00000,0.0000e+000,20.00000,    -0.28778,0.66529
574.01898, 68.67167,    -1.15286,86.58799,50.00000,0.0000e+000,20.00000,    -0.28855,0.66421
575.80902, 68.85167,    -1.15460,86.53848,50.00000,0.0000e+000,20.00000,    -0.28950,0.66312
577.58698, 69.03167,    -1.15659,86.48749,50.00000,0.0000e+000,20.00000,    -0.28988,0.66205
579.36603, 69.21167,    -1.15786,86.43387,50.00000,0.0000e+000,20.00000,    -0.28991,0.66097
581.16101, 69.39167,    -1.15799,86.38148,50.00000,0.0000e+000,20.00000,    -0.28960,0.65989
582.96301, 69.57166,    -1.15797,86.33092,50.00000,0.0000e+000,20.00000,    -0.28873,0.65882
584.80200, 69.75166,    -1.16040,86.27992,50.00000,0.0000e+000,20.00000,    -0.28835,0.65772
586.64398, 69.93166,    -1.16387,86.22750,50.00000,0.0000e+000,20.00000,    -0.28795,0.65663
588.49597, 70.11166,    -1.16519,86.17562,50.00000,0.0000e+000,20.00000,    -0.28806,0.65553
590.33099, 70.29166,    -1.16287,86.12483,50.00000,0.0000e+000,20.00000,    -0.28898,0.65446
592.14600, 70.47166,    -1.15884,86.07187,50.00000,0.0000e+000,20.00000,    -0.29039,0.65339
593.95502, 70.65166,    -1.15475,86.01624,50.00000,0.0000e+000,20.00000,    -0.29229,0.65234
595.75702, 70.83167,    -1.15086,85.96314,50.00000,0.0000e+000,20.00000,    -0.29351,0.65130
597.55499, 71.01167,    -1.14652,85.91133,50.00000,0.0000e+000,20.00000,    -0.29368,0.65026
599.34497, 71.19167,    -1.14277,85.85949,50.00000,0.0000e+000,20.00000,    -0.29377,0.64923
601.13898, 71.37167,    -1.13882,85.80980,50.00000,0.0000e+000,20.00000,    -0.29413,0.64820
602.92999, 71.55167,    -1.13550,85.76013,50.00000,0.0000e+000,20.00000,    -0.29516,0.64718
604.72198, 71.73167,    -1.13439,85.70956,50.00000,0.0000e+000,20.00000,    -0.29642,0.64616
606.52899, 71.91167,    -1.13352,85.65539,50.00000,0.0000e+000,20.00000,    -0.29809,0.64514
608.32898, 72.09167,    -1.13099,85.59895,50.00000,0.0000e+000,20.00000,    -0.30019,0.64413
610.13098, 72.27167,    -1.12778,85.54292,50.00000,0.0000e+000,20.00000,    -0.30130,0.64312
611.92102, 72.45167,    -1.12445,85.48633,50.00000,0.0000e+000,20.00000,    -0.30062,0.64212
613.71698, 72.63167,    -1.11994,85.43109,50.00000,0.0000e+000,20.00000,    -0.30082,0.64113
615.50098, 72.81167,    -1.11602,85.37689,50.00000,0.0000e+000,20.00000,    -0.30255,0.64014
617.29797, 72.99167,    -1.11320,85.32371,50.00000,0.0000e+000,20.00000,    -0.30397,0.63915
619.09198, 73.17167,    -1.11171,85.27155,50.00000,0.0000e+000,20.00000,    -0.30473,0.63817
620.91302, 73.35167,    -1.10963,85.21767,50.00000,0.0000e+000,20.00000,    -0.30520,0.63718
622.71600, 73.53167,    -1.10773,85.16087,50.00000,0.0000e+000,20.00000,    -0.30551,0.63620
624.50897, 73.71167,    -1.10544,85.10299,50.00000,0.0000e+000,20.00000,    -0.30512,0.63523
626.31500, 73.89167,    -1.10204,85.04432,50.00000,0.0000e+000,20.00000,    -0.30495,0.63426
628.12799, 74.07166,    -1.09779,84.98738,50.00000,0.0000e+000,20.00000,    -0.30457,0.63328
629.93701, 74.25166,    -1.09415,84.93397,50.00000,0.0000e+000,20.00000,    -0.30371,0.63232
631.73199, 74.43166,    -1.08896,84.88020,50.00000,0.0000e+000,20.00000,    -0.30324,0.63136
633.53601, 74.61166,    -1.08468,84.82250,50.00000,0.0000e+000,20.00000,    -0.30279,0.63041
635.35797, 74.79166,    -1.08324,84.76478,50.00000,0.0000e+000,20.00000,    -0.30179,0.62945
637.17902, 74.97166,    -1.07974,84.71140,50.00000,0.0000e+000,20.00000,    -0.30058,0.62849
638.98199, 75.15166,    -1.07714,84.66020,50.00000,0.0000e+000,20.00000,    -0.29923,0.62755
640.78802, 75.33167,    -1.07585,84.60862,50.00000,0.0000e+000,20.00000,    -0.29683,0.62661
642.57202, 75.51167,    -1.07118,84.55697,50.00000,0.0000e+000,20.00000,    -0.29420,0.62569
644.38202, 75.69167,    -1.07011,84.50161,50.00000,0.0000e+000,20.00000,    -0.29136,0.62476
646.22900, 75.87167,    -1.07344,84.44645,50.00000,0.0000e+000,20.00000,    -0.28844,0.62381
648.05103, 76.05167,    -1.07228,84.39316,50.00000,0.0000e+000,20.00000,    -0.28626,0.62288
649.87299, 76.23167,    -1.07234,84.33931,50.00000,0.0000e+000,20.00000,    -0.28388,0.62195
651.72101, 76.41167,    -1.07396,84.28635,50.00000,0.0000e+000,20.00000,    -0.28061,0.62101
653.53998, 76.59167,    -1.07428,84.23613,50.00000,0.0000e+000,20.00000,    -0.27712,0.62009
655.32300, 76.77167,    -1.07070,84.18833,50.00000,0.0000e+000,20.00000,    -0.27458,0.61920
657.13300, 76.95167,    -1.07006,84.13979,50.00000,0.0000e+000,20.00000,    -0.27246,0.61829
658.92700, 77.13167,    -1.07149,84.09209,50.00000,0.0000e+000,20.00000,    -0.27031,0.61740
660.71002, 77.31167,    -1.07192,84.04401,50.00000,0.0000e+000,20.00000,    -0.26788,0.61651
662.50299, 77.49167,    -1.07153,83.99568,50.00000,0.0000e+000,20.00000,    -0.26369,0.61563
664.29901, 77.67167,    -1.07357,83.94866,50.00000,0.0000e+000,20.00000,    -0.25899,0.61474
666.08197, 77.85167,    -1.07522,83.90269,50.00000,0.0000e+000,20.00000,    -0.25574,0.61387
667.86902, 78.03167,    -1.07522,83.85792,50.00000,0.0000e+000,20.00000,    -0.25228,0.61300
669.63098, 78.21167,    -1.07570,83.81282,50.00000,0.0000e+000,20.00000,    -0.24836,0.61214
671.38702, 78.39167,    -1.07604,83.76746,50.00000,0.0000e+000,20.00000,    -0.24487,0.61129
673.16400, 78.57166,    -1.07746,83.72244,50.00000,0.0000e+000,20.00000,    -0.24223,0.61043
674.94098, 78.75166,    -1.08109,83.67892,50.00000,0.0000e+000,20.00000,    -0.23960,0.60958
676.74597, 78.93166,    -1.08810,83.63514,50.00000,0.0000e+000,20.00000,    -0.23703,0.60872
678.55200, 79.11166,    -1.09504,83.59228,50.00000,0.0000e+000,20.00000,    -0.23402,0.60786
680.35797, 79.29166,    -1.10013,83.55235,50.00000,0.0000e+000,20.00000,    -0.23082,0.60700
682.19299, 79.47166,    -1.10591,83.51410,50.00000,0.0000e+000,20.00000,    -0.22755,0.60613
683.99597, 79.65166,    -1.10871,83.47312,50.00000,0.0000e+000,20.00000,    -0.22403,0.60528
685.79498, 79.83167,    -1.10951,83.43159,50.00000,0.0000e+000,20.00000,    -0.22092,0.60444
687.57397, 80.01167,    -1.11145,83.39245,50.00000,0.0000e+000,20.00000,    -0.21794,0.60361
689.37701, 80.19167,    -1.11455,83.35441,50.00000,0.0000e+000,20.00000,    -0.21551,0.60277
691.18903, 80.37167,    -1.11984,83.31624,50.00000,0.0000e+000,20.00000,    -0.21299,0.60193
693.02197, 80.55167,    -1.12646,83.27741,50.00000,0.0000e+000,20.00000,    -0.21034,0.60108
694.83600, 80.73167,    -1.13299,83.23884,50.00000,0.0000e+000,20.00000,    -0.20840,0.60025
696.64600, 80.91167,    -1.13519,83.20169,50.00000,0.0000e+000,20.00000,    -0.20744,0.59942
698.45398, 81.09167,    -1.13773,83.16493,50.00000,0.0000e+000,20.00000,    -0.20707,0.59860
700.25299, 81.27167,    -1.14186,83.12935,50.00000,0.0000e+000,20.00000,    -0.20756,0.59778
702.05701, 81.45167,    -1.14596,83.09584,50.00000,0.0000e+000,20.00000,    -0.20756,0.59696
703.86298, 81.63167,    -1.15036,83.06249,50.00000,0.0000e+000,20.00000,    -0.20732,0.59615
705.67297, 81.81167,    -1.15448,83.02851,50.00000,0.0000e+000,20.00000,    -0.20829,0.59533
707.50000, 81.99167,    -1.15785,82.99245,50.00000,0.0000e+000,20.00000,    -0.20970,0.59452
709.29700, 82.17167,    -1.15844,82.95604,50.00000,0.0000e+000,20.00000,    -0.21162,0.59372
711.09302, 82.35167,    -1.15761,82.92206,50.00000,0.0000e+000,20.00000,    -0.21396,0.59292
712.89099, 82.53167,    -1.15848,82.88604,50.00000,0.0000e+000,20.00000,    -0.21627,0.59212
714.73798, 82.71167,    -1.16345,82.84658,50.00000,0.0000e+000,20.00000,    -0.21801,0.59131
716.56702, 82.89167,    -1.16803,82.80741,50.00000,0.0000e+000,20.00000,    -0.21789,0.59051
718.39697, 83.07166,    -1.16794,82.76763,50.00000,0.0000e+000,20.00000,    -0.21670,0.58971
720.19098, 83.25166,    -1.16774,82.72711,50.00000,0.0000e+000,20.00000,    -0.21409,0.58892
721.99200, 83.43166,    -1.16830,82.68644,50.00000,0.0000e+000,20.00000,    -0.20934,0.58814
723.78802, 83.61166,    -1.17019,82.64367,50.00000,0.0000e+000,20.00000,    -0.20292,0.58736
725.57898, 83.79166,    -1.17001,82.60044,50.00000,0.0000e+000,20.00000,    -0.19568,0.58659
727.38300, 83.97166,    -1.16988,82.55575,50.00000,0.0000e+000,20.00000,    -0.18781,0.58582
729.17798, 84.15166,    -1.17180,82.50866,50.00000,0.0000e+000,20.00000,    -0.18165,0.58505
730.97699, 84.33167,    -1.17507,82.46135,50.00000,0.0000e+000,20.00000,    -0.17442,0.58428
732.76501, 84.51167,    -1.18128,82.41667,50.00000,0.0000e+000,20.00000,    -0.16517,0.58352
734.54199, 84.69167,    -1.19425,82.37938,50.00000,0.0000e+000,20.00000,    -0.15544,0.58277
736.34601, 84.87167,    -1.22320,82.34702,50.00000,0.0000e+000,20.00000,    -0.14562,0.58201
738.12903, 85.05167,    -1.25220,82.32157,50.00000,0.0000e+000,20.00000,    -0.13614,0.58126
739.91901, 85.23167,    -1.27040,82.30446,50.00000,0.0000e+000,20.00000,    -0.12710,0.58050
741.72803, 85.41167,    -1.28470,82.29365,50.00000,0.0000e+000,20.00000,    -0.11746,0.57975
743.53900, 85.59167,    -1.29606,82.28413,50.00000,0.0000e+000,20.00000,    -0.10758,0.57899
745.39001, 85.77167,    -1.30630,82.27645,50.00000,0.0000e+000,20.00000,-9.6523e-002,0.57823
747.23297, 85.95167,    -1.31524,82.26518,50.00000,0.0000e+000,20.00000,-8.4626e-002,0.57746
749.05402, 86.13167,    -1.31980,82.25532,50.00000,0.0000e+000,20.00000,-7.3749e-002,0.57671
750.86798, 86.31167,    -1.32225,82.24978,50.00000,0.0000e+000,20.00000,-6.3051e-002,0.57597
752.66302, 86.49167,    -1.32337,82.24561,50.00000,0.0000e+000,20.00000,-5.3432e-002,0.57523
754.44098, 86.67167,    -1.32302,82.24236,50.00000,0.0000e+000,20.00000,-4.5165e-002,0.57451
756.27100, 86.85167,    -1.32932,82.23671,50.00000,0.0000e+000,20.00000,-3.8971e-002,0.57376
758.10101, 87.03167,    -1.33845,82.22942,50.00000,0.0000e+000,20.00000,-3.4552e-002,0.57302
759.93201, 87.21167,    -1.34504,82.22207,50.00000,0.0000e+000,20.00000,-3.1779e-002,0.57228
761.74701, 87.39167,    -1.34879,82.21486,50.00000,0.0000e+000,20.00000,-3.0533e-002,0.57155
763.55103, 87.57166,    -1.35081,82.21029,50.00000,0.0000e+000,20.00000,-3.0558e-002,0.57082
765.33002, 87.75166,    -1.35202,82.20746,50.00000,0.0000e+000,20.00000,-2.9801e-002,0.57011
767.12299, 87.93166,    -1.35505,82.20028,50.00000,0.0000e+000,20.00000,-2.8350e-002,0.56939
768.89398, 88.11166,    -1.35939,82.19327,50.00000,0.0000e+000,20.00000,-2.7976e-002,0.56869
770.69702, 88.29166,    -1.36609,82.18986,50.00000,0.0000e+000,20.00000,-2.7448e-002,0.56797
772.48901, 88.47166,    -1.37319,82.18706,50.00000,0.0000e+000,20.00000,-2.6651e-002,0.56726
774.28601, 88.65166,    -1.38150,82.18310,50.00000,0.0000e+000,20.00000,-2.5490e-002,0.56655
776.08502, 88.83167,    -1.38899,82.18038,50.00000,0.0000e+000,20.00000,-2.4599e-002,0.56584
777.86798, 89.01167,    -1.39478,82.17945,50.00000,0.0000e+000,20.00000,-2.3451e-002,0.56514
779.65698, 89.19167,    -1.39955,82.17483,50.00000,0.0000e+000,20.00000,-2.2551e-002,0.56444
781.44800, 89.37167,    -1.40591,82.16737,50.00000,0.0000e+000,20.00000,-2.1947e-002,0.56375
783.25500, 89.55167,    -1.41596,82.15914,50.00000,0.0000e+000,20.00000,-2.2438e-002,0.56304
785.06702, 89.73167,    -1.42595,82.15362,50.00000,0.0000e+000,20.00000,-2.1566e-002,0.56234
786.89301, 89.91167,    -1.43454,82.14890,50.00000,0.0000e+000,20.00000,-2.0339e-002,0.56163
788.73602, 90.09167,    -1.44316,82.14592,50.00000,0.0000e+000,20.00000,-2.0339e-002,0.56092
790.54602, 90.27167,    -1.44960,82.14562,50.00000,0.0000e+000,20.00000,-2.0680e-002,0.56022
792.34003, 90.45167,    -1.45391,82.14490,50.00000,0.0000e+000,20.00000,-2.0655e-002,0.55954
794.14301, 90.63167,    -1.45774,82.14127,50.00000,0.0000e+000,20.00000,-2.0401e-002,0.55884
795.93903, 90.81167,    -1.46361,82.13801,50.00000,0.0000e+000,20.00000,-2.0749e-002,0.55816
797.71698, 90.99167,    -1.46811,82.13401,50.00000,0.0000e+000,20.00000,-2.0550e-002,0.55748
799.49500, 91.17167,    -1.47170,82.13104,50.00000,0.0000e+000,20.00000,-1.8736e-002,0.55681
801.28601, 91.35167,    -1.47754,82.12679,50.00000,0.0000e+000,20.00000,-1.6273e-002,0.55613
803.09100, 91.53167,    -1.48413,82.12317,50.00000,0.0000e+000,20.00000,-1.4981e-002,0.55544
804.89398, 91.71167,    -1.49187,82.12024,50.00000,0.0000e+000,20.00000,-1.4215e-002,0.55476
806.69702, 91.89167,    -1.49849,82.11656,50.00000,0.0000e+000,20.00000,-1.3969e-002,0.55409
808.50098, 92.07166,    -1.50498,82.11258,50.00000,0.0000e+000,20.00000,-1.3951e-002,0.55341
810.32703, 92.25166,    -1.51475,82.10872,50.00000,0.0000e+000,20.00000,-1.4377e-002,0.55272
812.19098, 92.43166,    -1.52732,82.10627,50.00000,0.0000e+000,20.00000,-1.3665e-002,0.55203
814.01599, 92.61166,    -1.53796,82.10437,50.00000,0.0000e+000,20.00000,-1.3058e-002,0.55135
815.83002, 92.79166,    -1.54544,82.10106,50.00000,0.0000e+000,20.00000,-1.3310e-002,0.55067
817.64099, 92.97166,    -1.55247,82.10003,50.00000,0.0000e+000,20.00000,-1.3981e-002,0.55000
819.44598, 93.15166,    -1.56186,82.10080,50.00000,0.0000e+000,20.00000,-1.3339e-002,0.54933
821.23602, 93.33167,    -1.57258,82.09994,50.00000,0.0000e+000,20.00000,-1.2291e-002,0.54867
823.01599, 93.51167,    -1.58387,82.09787,50.00000,0.0000e+000,20.00000,-1.1890e-002,0.54801
824.80701, 93.69167,    -1.59639,82.09550,50.00000,0.0000e+000,20.00000,-1.1597e-002,0.54736
826.59302, 93.87167,    -1.61277,82.09462,50.00000,0.0000e+000,20.00000,-1.1910e-002,0.54670
828.38898, 94.05167,    -1.63081,82.09305,50.00000,0.0000e+000,20.00000,-1.1959e-002,0.54604
830.20502, 94.23167,    -1.64827,82.09188,50.00000,0.0000e+000,20.00000,-1.1623e-002,0.54538
832.01599, 94.41167,    -1.66405,82.09127,50.00000,0.0000e+000,20.00000,-1.2429e-002,0.54472
833.82599, 94.59167,    -1.67730,82.08678,50.00000,0.0000e+000,20.00000,-1.2595e-002,0.54406
835.63800, 94.77167,    -1.68942,82.08114,50.00000,0.0000e+000,20.00000,-1.3404e-002,0.54340
837.43903, 94.95167,    -1.70109,82.07873,50.00000,0.0000e+000,20.00000,-1.5202e-002,0.54274
839.25702, 95.13167,    -1.70973,82.07878,50.00000,0.0000e+000,20.00000,-1.6952e-002,0.54209
841.06403, 95.31167,    -1.71497,82.07755,50.00000,0.0000e+000,20.00000,-1.8524e-002,0.54143
842.87097, 95.49167,    -1.71811,82.07531,50.00000,0.0000e+000,20.00000,-1.9554e-002,0.54078
844.66498, 95.67167,    -1.72410,82.07053,50.00000,0.0000e+000,20.00000,-1.9896e-002,0.54013
846.45599, 95.85167,    -1.73117,82.06591,50.00000,0.0000e+000,20.00000,-2.0207e-002,0.53949
848.25702, 96.03167,    -1.73671,82.06442,50.00000,0.0000e+000,20.00000,-1.9770e-002,0.53884
850.07800, 96.21167,    -1.74319,82.06015,50.00000,0.0000e+000,20.00000,-2.0811e-002,0.53819
851.87598, 96.39167,    -1.74852,82.05600,50.00000,0.0000e+000,20.00000,-2.1462e-002,0.53755
853.68597, 96.57166,    -1.75411,82.05177,50.00000,0.0000e+000,20.00000,-2.1151e-002,0.53690
855.49103, 96.75166,    -1.75885,82.04617,50.00000,0.0000e+000,20.00000,-2.1196e-002,0.53625
857.29797, 96.93166,    -1.76304,82.03936,50.00000,0.0000e+000,20.00000,-2.2919e-002,0.53561
859.12201, 97.11166,    -1.76858,82.03165,50.00000,0.0000e+000,20.00000,-2.3874e-002,0.53496
860.95599, 97.29166,    -1.77617,82.02505,50.00000,0.0000e+000,20.00000,-2.4014e-002,0.53431
862.77399, 97.47166,    -1.78092,82.02226,50.00000,0.0000e+000,20.00000,-2.4069e-002,0.53366
864.57703, 97.65166,    -1.78519,82.01979,50.00000,0.0000e+000,20.00000,-2.4181e-002,0.53303
866.37500, 97.83167,    -1.79179,82.01969,50.00000,0.0000e+000,20.00000,-2.4633e-002,0.53239
868.17798, 98.01167,    -1.79683,82.01647,50.00000,0.0000e+000,20.00000,-2.4105e-002,0.53175
869.97803, 98.19167,    -1.80231,82.01007,50.00000,0.0000e+000,20.00000,-2.3863e-002,0.53112
871.77899, 98.37167,    -1.80909,82.00514,50.00000,0.0000e+000,20.00000,-2.3651e-002,0.53048
873.58502, 98.55167,    -1.81474,82.00201,50.00000,0.0000e+000,20.00000,-2.2876e-002,0.52985
875.38599, 98.73167,    -1.82011,81.99607,50.00000,0.0000e+000,20.00000,-2.2229e-002,0.52921
877.19397, 98.91167,    -1.82655,81.99094,50.00000,0.0000e+000,20.00000,-2.1513e-002,0.52858
878.99402, 99.09167,    -1.83323,81.98856,50.00000,0.0000e+000,20.00000,-2.1197e-002,0.52795
880.78003, 99.27167,    -1.83833,81.98416,50.00000,0.0000e+000,20.00000,-2.1894e-002,0.52732
882.58197, 99.45167,    -1.84533,81.97885,50.00000,0.0000e+000,20.00000,-2.2614e-002,0.52669
884.36902, 99.63167,    -1.85160,81.97489,50.00000,0.0000e+000,20.00000,-2.4018e-002,0.52606
886.14697, 99.81167,    -1.85605,81.97327,50.00000,0.0000e+000,20.00000,-2.4521e-002,0.52544
887.93500, 99.99167,    -1.86201,81.96990,50.00000,0.0000e+000,20.00000,-2.4132e-002,0.52482
889.73798,100.17167,    -1.86868,81.96646,50.00000,0.0000e+000,20.00000,-2.4639e-002,0.52419
891.53497,100.35167,    -1.87444,81.96400,50.00000,0.0000e+000,20.00000,-2.5912e-002,0.52356
893.36603,100.53167,    -1.88305,81.95995,50.00000,0.0000e+000,20.00000,-2.6543e-002,0.52293
895.16901,100.71167,    -1.88986,81.95503,50.00000,0.0000e+000,20.00000,-2.6448e-002,0.52230
896.99799,100.89167,    -1.89444,81.94928,50.00000,0.0000e+000,20.00000,-2.7580e-002,0.52166
898.85303,101.07166,    -1.90541,81.94337,50.00000,0.0000e+000,20.00000,-2.8425e-002,0.52102
900.69702,101.25166,    -1.91159,81.93829,50.00000,0.0000e+000,20.00000,-2.8899e-002,0.52038
902.51202,101.43166,    -1.91060,81.93264,50.00000,0.0000e+000,20.00000,-2.9036e-002,0.51975
904.29999,101.61166,    -1.90943,81.92831,50.00000,0.0000e+000,20.00000,-2.9821e-002,0.51913
906.10303,101.79166,    -1.90671,81.92375,50.00000,0.0000e+000,20.00000,-3.0819e-002,0.51850
907.88000,101.97166,    -1.90483,81.91681,50.00000,0.0000e+000,20.00000,-3.1654e-002,0.51789
909.67499,102.15166,    -1.90673,81.90913,50.00000,0.0000e+000,20.00000,-3.2149e-002,0.51727
911.46503,102.33167,    -1.90793,81.90110,50.00000,0.0000e+000,20.00000,-3.2510e-002,0.51665
913.25403,102.51167,    -1.90772,81.89563,50.00000,0.0000e+000,20.00000,-3.3007e-002,0.51603
915.04999,102.69167,    -1.90840,81.88927,50.00000,0.0000e+000,20.00000,-3.3320e-002,0.51541
916.83398,102.87167,    -1.90809,81.88213,50.00000,0.0000e+000,20.00000,-3.3255e-002,0.51479
918.64203,103.05167,    -1.90647,81.87505,50.00000,0.0000e+000,20.00000,-3.3758e-002,0.51417
920.47601,103.23167,    -1.91113,81.86975,50.00000,0.0000e+000,20.00000,-3.4497e-002,0.51354
922.28802,103.41167,    -1.91464,81.86542,50.00000,0.0000e+000,20.00000,-3.4516e-002,0.51291
924.05402,103.59167,    -1.90770,81.85901,50.00000,0.0000e+000,20.00000,-3.4082e-002,0.51230
925.87598,103.77167,    -1.90964,81.85201,50.00000,0.0000e+000,20.00000,-3.4098e-002,0.51168
927.69299,103.95167,    -1.91327,81.84757,50.00000,0.0000e+000,20.00000,-3.4800e-002,0.51105
929.52399,104.13167,    -1.91573,81.84275,50.00000,0.0000e+000,20.00000,-3.5267e-002,0.51042
931.36102,104.31167,    -1.91856,81.83624,50.00000,0.0000e+000,20.00000,-3.5910e-002,0.50979
933.18701,104.49167,    -1.91974,81.82940,50.00000,0.0000e+000,20.00000,-3.5996e-002,0.50916
934.97699,104.67167,    -1.91541,81.82352,50.00000,0.0000e+000,20.00000,-3.5305e-002,0.50854
936.77197,104.85167,    -1.90759,81.81698,50.00000,0.0000e+000,20.00000,-3.5577e-002,0.50792
938.56299,105.03167,    -1.90129,81.80847,50.00000,0.0000e+000,20.00000,-3.6885e-002,0.50731
940.35999,105.21167,    -1.89634,81.80323,50.00000,0.0000e+000,20.00000,-3.8333e-002,0.50669
942.15399,105.39167,    -1.89161,81.80054,50.00000,0.0000e+000,20.00000,-3.8443e-002,0.50607
943.93903,105.57166,    -1.88406,81.79473,50.00000,0.0000e+000,20.00000,-3.8369e-002,0.50546
945.71997,105.75166,    -1.87619,81.78475,50.00000,0.0000e+000,20.00000,-3.8930e-002,0.50484
947.51001,105.93166,    -1.87172,81.77471,50.00000,0.0000e+000,20.00000,-3.9873e-002,0.50423
949.33600,106.11166,    -1.87110,81.76634,50.00000,0.0000e+000,20.00000,-4.0810e-002,0.50360
951.21503,106.29166,    -1.88054,81.75953,50.00000,0.0000e+000,20.00000,-4.1914e-002,0.50295
953.04199,106.47166,    -1.88184,81.75509,50.00000,0.0000e+000,20.00000,-4.2694e-002,0.50232
954.84998,106.65166,    -1.87763,81.74747,50.00000,0.0000e+000,20.00000,-4.2648e-002,0.50170
956.62201,106.83167,    -1.87175,81.73728,50.00000,0.0000e+000,20.00000,-4.2849e-002,0.50109
958.39301,107.01167,    -1.86706,81.72729,50.00000,0.0000e+000,20.00000,-4.4557e-002,0.50048
960.16400,107.19167,    -1.86373,81.72053,50.00000,0.0000e+000,20.00000,-4.7553e-002,0.49987
961.95300,107.37167,    -1.86624,81.71383,50.00000,0.0000e+000,20.00000,-5.0416e-002,0.49925
963.72900,107.55167,    -1.86934,81.70693,50.00000,0.0000e+000,20.00000,-5.1477e-002,0.49864
965.52399,107.73167,    -1.86892,81.69920,50.00000,0.0000e+000,20.00000,-5.1698e-002,0.49802
967.33600,107.91167,    -1.87244,81.68979,50.00000,0.0000e+000,20.00000,-5.2979e-002,0.49739
969.13098,108.09167,    -1.87350,81.67885,50.00000,0.0000e+000,20.00000,-5.3614e-002,0.49678
970.91400,108.27167,    -1.87506,81.66936,50.00000,0.0000e+000,20.00000,-5.4723e-002,0.49616
972.71997,108.45167,    -1.87640,81.66338,50.00000,0.0000e+000,20.00000,-5.5333e-002,0.49554
974.51703,108.63167,    -1.88024,81.65469,50.00000,0.0000e+000,20.00000,-5.5912e-002,0.49492
976.31403,108.81167,    -1.88005,81.64293,50.00000,0.0000e+000,20.00000,-5.6548e-002,0.49429
978.12000,108.99167,    -1.88278,81.62935,50.00000,0.0000e+000,20.00000,-5.7267e-002,0.49367
979.95502,109.17167,    -1.88956,81.61417,50.00000,0.0000e+000,20.00000,-5.9890e-002,0.49303
981.77399,109.35167,    -1.89357,81.59990,50.00000,0.0000e+000,20.00000,-6.2021e-002,0.49240
983.61700,109.53167,    -1.90055,81.58910,50.00000,0.0000e+000,20.00000,-6.2851e-002,0.49177
985.44598,109.71167,    -1.90460,81.57581,50.00000,0.0000e+000,20.00000,-6.5309e-002,0.49113
987.25098,109.89167,    -1.90100,81.56561,50.00000,0.0000e+000,20.00000,-6.7223e-002,0.49051
989.04401,110.07166,    -1.89661,81.55725,50.00000,0.0000e+000,20.00000,-6.5065e-002,0.48988
990.84601,110.25166,    -1.89924,81.54810,50.00000,0.0000e+000,20.00000,-6.3427e-002,0.48926
992.68201,110.43166,    -1.90446,81.53667,50.00000,0.0000e+000,20.00000,-6.2318e-002,0.48862
994.50000,110.61166,    -1.90801,81.52361,50.00000,0.0000e+000,20.00000,-6.8860e-002,0.48799
996.29498,110.79166,    -1.90797,81.51371,50.00000,0.0000e+000,20.00000,-7.0667e-002,0.48736
998.07800,110.97166,    -1.90511,81.50129,50.00000,0.0000e+000,20.00000,    -0.12990,0.48674
998.32202,110.99667,    -1.90513,81.49669,50.00000,0.0000e+000,20.00000,    -0.28618,0.48666