File: book/some_content/TG_ExpDat_CEM_III_DC7.csv
#FILE:                       ,CEM_III_DC7; 23-1-2025.ngb-ds3
#FORMAT:                     ,NETZSCH5
#IDENTITY:                   ,GEOPOLYMER PASTE
#DECIMAL:                    ,POINT
#SEPARATOR:                  ,COMMA
#MTYPE:                      ,DSC
#INSTRUMENT:                 ,Microlab TU Delft
#PROJECT:                    ,
#DATE/TIME:                  ,24/01/2025 4:44:28 PM
#CORR. FILE:                 ,Blank with cover; 13-1-2025.ngb-bs3
#LABORATORY:                 ,TU Delft Micro Lab
#OPERATOR:                   ,Ahmed
#REMARK:                     ,under Argon atmosphere, 10K/min
#SAMPLE:                     ,CEM_III_DC7
#SAMPLE MASS /mg:            ,37.6
#MATERIAL:                   ,Geopolymer paste
#REFERENCE:                  ,blank
#REFERENCE MASS /mg:         ,0
#TYPE OF CRUCIBLE:           ,DSC/TG pan Al2O3
#SAMPLE CRUCIBLE MASS /mg:   ,0
#REFERENCE CRUCIBLE MASS /mg:,0
#CORR. CODE:                 ,020
#EXO:                        ,-1
#RANGE:                      ,40/10.0(K/min)/1000
#SEGMENT:                    ,S2/2

##Temp./øC,Time/min,DSC/(mW/mg),Mass/%,Gas Flow(purge1)/(ml/min),Gas Flow(purge2)/(ml/min),Gas Flow(protective)/(ml/min),DTG/(%/min),Sensit./(uV/mW)
 39.63500, 15.01667, 5.6635e-002,97.41956,50.00000,0.0000e+000,20.00000,    -0.19411,1.22745
 39.65400, 15.19667, 5.6851e-002,97.39343,50.00000,0.0000e+000,20.00000,    -0.14111,1.22742
 39.70800, 15.37667, 5.6508e-002,97.36969,50.00000,0.0000e+000,20.00000,    -0.14645,1.22735
 39.80800, 15.55667, 5.6283e-002,97.34330,50.00000,0.0000e+000,20.00000,    -0.14669,1.22721
 39.91100, 15.73667, 5.6173e-002,97.31515,50.00000,0.0000e+000,20.00000,    -0.14769,1.22707
 40.08600, 15.91667, 5.6515e-002,97.28702,50.00000,0.0000e+000,20.00000,    -0.15089,1.22682
 40.35400, 16.09667, 5.7029e-002,97.26187,50.00000,0.0000e+000,20.00000,    -0.15131,1.22645
 40.68600, 16.27667, 5.8506e-002,97.23643,50.00000,0.0000e+000,20.00000,    -0.15521,1.22600
 41.07800, 16.45667, 6.0271e-002,97.20796,50.00000,0.0000e+000,20.00000,    -0.15809,1.22546
 41.56200, 16.63667, 6.2424e-002,97.17808,50.00000,0.0000e+000,20.00000,    -0.16306,1.22479
 42.13600, 16.81667, 6.5051e-002,97.14885,50.00000,0.0000e+000,20.00000,    -0.17002,1.22400
 42.77300, 16.99667, 6.8399e-002,97.12101,50.00000,0.0000e+000,20.00000,    -0.17583,1.22312
 43.51900, 17.17667, 7.1511e-002,97.09367,50.00000,0.0000e+000,20.00000,    -0.18388,1.22209
 44.32200, 17.35667, 7.5864e-002,97.06187,50.00000,0.0000e+000,20.00000,    -0.19189,1.22098
 45.22200, 17.53667, 7.9833e-002,97.02937,50.00000,0.0000e+000,20.00000,    -0.20063,1.21974
 46.21100, 17.71667, 8.4486e-002,96.99907,50.00000,0.0000e+000,20.00000,    -0.21221,1.21838
 47.25400, 17.89667, 8.9404e-002,96.96553,50.00000,0.0000e+000,20.00000,    -0.22694,1.21694
 48.40900, 18.07667, 9.4981e-002,96.92860,50.00000,0.0000e+000,20.00000,    -0.24294,1.21535
 49.61400, 18.25667,     0.10043,96.89239,50.00000,0.0000e+000,20.00000,    -0.26051,1.21369
 50.92200, 18.43667,     0.10620,96.85369,50.00000,0.0000e+000,20.00000,    -0.28083,1.21189
 52.30600, 18.61667,     0.11254,96.80913,50.00000,0.0000e+000,20.00000,    -0.30410,1.20999
 53.77200, 18.79667,     0.11913,96.76202,50.00000,0.0000e+000,20.00000,    -0.33009,1.20797
 55.30700, 18.97667,     0.12612,96.70972,50.00000,0.0000e+000,20.00000,    -0.36059,1.20586
 56.92000, 19.15667,     0.13392,96.65469,50.00000,0.0000e+000,20.00000,    -0.39424,1.20364
 58.60900, 19.33667,     0.14202,96.59598,50.00000,0.0000e+000,20.00000,    -0.43458,1.20131
 60.36900, 19.51667,     0.15122,96.52715,50.00000,0.0000e+000,20.00000,    -0.47844,1.19889
 62.19500, 19.69667,     0.16071,96.44847,50.00000,0.0000e+000,20.00000,    -0.52601,1.19639
 64.08700, 19.87667,     0.17135,96.36583,50.00000,0.0000e+000,20.00000,    -0.57752,1.19379
 66.02200, 20.05667,     0.18316,96.27507,50.00000,0.0000e+000,20.00000,    -0.63528,1.19113
 68.01600, 20.23667,     0.19627,96.17298,50.00000,0.0000e+000,20.00000,    -0.69837,1.18840
 70.09700, 20.41667,     0.21023,96.05969,50.00000,0.0000e+000,20.00000,    -0.76715,1.18554
 72.18500, 20.59667,     0.22618,95.93839,50.00000,0.0000e+000,20.00000,    -0.84384,1.18268
 74.34500, 20.77667,     0.24384,95.80217,50.00000,0.0000e+000,20.00000,    -0.92743,1.17972
 76.52600, 20.95667,     0.26322,95.65132,50.00000,0.0000e+000,20.00000,    -1.01618,1.17674
 78.76300, 21.13667,     0.28503,95.47416,50.00000,0.0000e+000,20.00000,    -1.11036,1.17368
 81.02200, 21.31667,     0.30854,95.28518,50.00000,0.0000e+000,20.00000,    -1.20324,1.17059
 83.34400, 21.49667,     0.33505,95.08102,50.00000,0.0000e+000,20.00000,    -1.29387,1.16742
 85.67300, 21.67667,     0.36387,94.85931,50.00000,0.0000e+000,20.00000,    -1.38074,1.16425
 88.02900, 21.85667,     0.39602,94.61511,50.00000,0.0000e+000,20.00000,    -1.46086,1.16104
 90.41600, 22.03667,     0.43046,94.35011,50.00000,0.0000e+000,20.00000,    -1.53097,1.15779
 92.83100, 22.21667,     0.46775,94.05938,50.00000,0.0000e+000,20.00000,    -1.58970,1.15450
 95.24000, 22.39667,     0.50747,93.73731,50.00000,0.0000e+000,20.00000,    -1.64545,1.15123
 97.70900, 22.57667,     0.54920,93.38436,50.00000,0.0000e+000,20.00000,    -1.70055,1.14788
100.12600, 22.75667,     0.59189,93.00863,50.00000,0.0000e+000,20.00000,    -1.75501,1.14460
102.59400, 22.93667,     0.63398,92.60922,50.00000,0.0000e+000,20.00000,    -1.80531,1.14126
105.05100, 23.11667,     0.67426,92.20284,50.00000,0.0000e+000,20.00000,    -1.85470,1.13794
107.50900, 23.29667,     0.70969,91.79397,50.00000,0.0000e+000,20.00000,    -1.90151,1.13462
109.97700, 23.47667,     0.73595,91.39220,50.00000,0.0000e+000,20.00000,    -1.93949,1.13129
112.42100, 23.65667,     0.74773,91.00711,50.00000,0.0000e+000,20.00000,    -1.96010,1.12800
114.89100, 23.83667,     0.74620,90.64601,50.00000,0.0000e+000,20.00000,    -1.96047,1.12468
117.33700, 24.01667,     0.73574,90.31596,50.00000,0.0000e+000,20.00000,    -1.94331,1.12139
119.80200, 24.19667,     0.72770,89.99373,50.00000,0.0000e+000,20.00000,    -1.90876,1.11809
122.25000, 24.37667,     0.72765,89.66045,50.00000,0.0000e+000,20.00000,    -1.85823,1.11481
124.69300, 24.55667,     0.73671,89.31492,50.00000,0.0000e+000,20.00000,    -1.79692,1.11154
127.15500, 24.73667,     0.75200,88.95932,50.00000,0.0000e+000,20.00000,    -1.72761,1.10826
129.59500, 24.91667,     0.76957,88.59274,50.00000,0.0000e+000,20.00000,    -1.65437,1.10500
132.02600, 25.09667,     0.78253,88.21974,50.00000,0.0000e+000,20.00000,    -1.57732,1.10177
134.44901, 25.27667,     0.78240,87.85817,50.00000,0.0000e+000,20.00000,    -1.50307,1.09855
136.87399, 25.45667,     0.75919,87.53446,50.00000,0.0000e+000,20.00000,    -1.42902,1.09533
139.24699, 25.63667,     0.71015,87.26345,50.00000,0.0000e+000,20.00000,    -1.35836,1.09219
141.67300, 25.81667,     0.64416,87.03512,50.00000,0.0000e+000,20.00000,    -1.29736,1.08899
144.08099, 25.99667,     0.57766,86.83886,50.00000,0.0000e+000,20.00000,    -1.23949,1.08581
146.46100, 26.17667,     0.51603,86.67220,50.00000,0.0000e+000,20.00000,    -1.17614,1.08268
148.88000, 26.35667,     0.46050,86.52139,50.00000,0.0000e+000,20.00000,    -1.10905,1.07950
151.25301, 26.53667,     0.41163,86.37903,50.00000,0.0000e+000,20.00000,    -1.03893,1.07638
153.58600, 26.71667,     0.36911,86.23809,50.00000,0.0000e+000,20.00000,    -0.96408,1.07333
155.92599, 26.89667,     0.33193,86.11121,50.00000,0.0000e+000,20.00000,    -0.88621,1.07027
158.22400, 27.07667,     0.29853,85.97850,50.00000,0.0000e+000,20.00000,    -0.80939,1.06727
160.51401, 27.25667,     0.26893,85.85852,50.00000,0.0000e+000,20.00000,    -0.74096,1.06429
162.76500, 27.43667,     0.24203,85.75078,50.00000,0.0000e+000,20.00000,    -0.68626,1.06136
164.98700, 27.61667,     0.21767,85.64046,50.00000,0.0000e+000,20.00000,    -0.64289,1.05848
167.15900, 27.79667,     0.19550,85.52930,50.00000,0.0000e+000,20.00000,    -0.60903,1.05567
169.33400, 27.97667,     0.17480,85.42829,50.00000,0.0000e+000,20.00000,    -0.58140,1.05286
171.48100, 28.15667,     0.15511,85.32995,50.00000,0.0000e+000,20.00000,    -0.55697,1.05009
173.59000, 28.33667,     0.13652,85.23169,50.00000,0.0000e+000,20.00000,    -0.53707,1.04738
175.67400, 28.51667,     0.11929,85.13917,50.00000,0.0000e+000,20.00000,    -0.51615,1.04470
177.72301, 28.69667,     0.10299,85.05091,50.00000,0.0000e+000,20.00000,    -0.49727,1.04207
179.81900, 28.87667, 8.7790e-002,84.96572,50.00000,0.0000e+000,20.00000,    -0.47752,1.03939
181.83800, 29.05667, 7.3702e-002,84.88496,50.00000,0.0000e+000,20.00000,    -0.46067,1.03681
183.85400, 29.23667, 6.0702e-002,84.80501,50.00000,0.0000e+000,20.00000,    -0.44585,1.03424
185.83800, 29.41667, 4.8479e-002,84.72988,50.00000,0.0000e+000,20.00000,    -0.43008,1.03172
187.81000, 29.59667, 3.6828e-002,84.65235,50.00000,0.0000e+000,20.00000,    -0.41445,1.02922
189.76900, 29.77667, 2.5118e-002,84.58126,50.00000,0.0000e+000,20.00000,    -0.40173,1.02673
191.67799, 29.95667, 1.3233e-002,84.51782,50.00000,0.0000e+000,20.00000,    -0.38837,1.02432
193.62000, 30.13667, 1.7672e-003,84.44877,50.00000,0.0000e+000,20.00000,    -0.37379,1.02187
195.51199, 30.31667,-9.6928e-003,84.38161,50.00000,0.0000e+000,20.00000,    -0.36105,1.01949
197.38800, 30.49667,-2.0368e-002,84.32189,50.00000,0.0000e+000,20.00000,    -0.35034,1.01713
199.25999, 30.67667,-3.0853e-002,84.26288,50.00000,0.0000e+000,20.00000,    -0.34022,1.01478
201.11900, 30.85667,-4.0724e-002,84.20090,50.00000,0.0000e+000,20.00000,    -0.33113,1.01245
202.95900, 31.03667,-5.0479e-002,84.14547,50.00000,0.0000e+000,20.00000,    -0.32101,1.01015
204.80099, 31.21667,-5.9351e-002,84.09376,50.00000,0.0000e+000,20.00000,    -0.31185,1.00786
206.60400, 31.39667,-6.8140e-002,84.03956,50.00000,0.0000e+000,20.00000,    -0.30248,1.00561
208.39600, 31.57667,-7.6380e-002,83.98323,50.00000,0.0000e+000,20.00000,    -0.29329,1.00339
210.20799, 31.75667,-8.4517e-002,83.93257,50.00000,0.0000e+000,20.00000,    -0.28720,1.00114
211.97400, 31.93667,-9.2055e-002,83.88733,50.00000,0.0000e+000,20.00000,    -0.27968,0.99896
213.75999, 32.11666,-9.9037e-002,83.84052,50.00000,0.0000e+000,20.00000,    -0.27101,0.99675
215.53101, 32.29667,    -0.10633,83.79147,50.00000,0.0000e+000,20.00000,    -0.26364,0.99457
217.26900, 32.47667,    -0.11286,83.74224,50.00000,0.0000e+000,20.00000,    -0.25708,0.99243
219.03400, 32.65667,    -0.11981,83.69411,50.00000,0.0000e+000,20.00000,    -0.24943,0.99027
220.79500, 32.83667,    -0.12609,83.64999,50.00000,0.0000e+000,20.00000,    -0.24252,0.98811
222.52600, 33.01667,    -0.13358,83.60805,50.00000,0.0000e+000,20.00000,    -0.23713,0.98600
224.27400, 33.19667,    -0.14105,83.56507,50.00000,0.0000e+000,20.00000,    -0.23255,0.98386
226.01300, 33.37667,    -0.14968,83.52521,50.00000,0.0000e+000,20.00000,    -0.22554,0.98175
227.71800, 33.55667,    -0.15824,83.48452,50.00000,0.0000e+000,20.00000,    -0.21906,0.97968
229.45100, 33.73667,    -0.16769,83.44321,50.00000,0.0000e+000,20.00000,    -0.21446,0.97758
231.17900, 33.91667,    -0.17699,83.40616,50.00000,0.0000e+000,20.00000,    -0.20939,0.97549
232.90401, 34.09667,    -0.18600,83.37221,50.00000,0.0000e+000,20.00000,    -0.20305,0.97341
234.62100, 34.27667,    -0.19503,83.33794,50.00000,0.0000e+000,20.00000,    -0.19683,0.97134
236.33099, 34.45667,    -0.20425,83.30350,50.00000,0.0000e+000,20.00000,    -0.19111,0.96929
238.04100, 34.63667,    -0.21249,83.27176,50.00000,0.0000e+000,20.00000,    -0.18570,0.96724
239.75400, 34.81667,    -0.22116,83.24028,50.00000,0.0000e+000,20.00000,    -0.18141,0.96519
241.47800, 34.99667,    -0.22858,83.20360,50.00000,0.0000e+000,20.00000,    -0.17661,0.96313
243.20599, 35.17667,    -0.23655,83.17162,50.00000,0.0000e+000,20.00000,    -0.17207,0.96107
244.91600, 35.35667,    -0.24401,83.14352,50.00000,0.0000e+000,20.00000,    -0.16732,0.95904
246.62500, 35.53667,    -0.25112,83.11473,50.00000,0.0000e+000,20.00000,    -0.16272,0.95702
248.33099, 35.71667,    -0.25839,83.08667,50.00000,0.0000e+000,20.00000,    -0.15940,0.95500
250.05000, 35.89667,    -0.26569,83.06073,50.00000,0.0000e+000,20.00000,    -0.15689,0.95297
251.77299, 36.07667,    -0.27223,83.03454,50.00000,0.0000e+000,20.00000,    -0.15423,0.95094
253.48500, 36.25667,    -0.27948,83.00688,50.00000,0.0000e+000,20.00000,    -0.15094,0.94893
255.20399, 36.43667,    -0.28607,82.98144,50.00000,0.0000e+000,20.00000,    -0.14801,0.94692
256.92401, 36.61666,    -0.29319,82.95563,50.00000,0.0000e+000,20.00000,    -0.14571,0.94491
258.64600, 36.79667,    -0.29984,82.92975,50.00000,0.0000e+000,20.00000,    -0.14221,0.94290
260.38101, 36.97667,    -0.30686,82.90576,50.00000,0.0000e+000,20.00000,    -0.13885,0.94088
262.10999, 37.15667,    -0.31394,82.88296,50.00000,0.0000e+000,20.00000,    -0.13690,0.93887
263.86099, 37.33667,    -0.32023,82.85844,50.00000,0.0000e+000,20.00000,    -0.13575,0.93684
265.57300, 37.51667,    -0.32683,82.83287,50.00000,0.0000e+000,20.00000,    -0.13451,0.93487
267.31201, 37.69667,    -0.33329,82.80766,50.00000,0.0000e+000,20.00000,    -0.13307,0.93286
269.05801, 37.87667,    -0.33918,82.78316,50.00000,0.0000e+000,20.00000,    -0.13046,0.93086
270.79099, 38.05667,    -0.34569,82.76029,50.00000,0.0000e+000,20.00000,    -0.12739,0.92887
272.52701, 38.23667,    -0.35169,82.73872,50.00000,0.0000e+000,20.00000,    -0.12603,0.92688
274.25601, 38.41667,    -0.35770,82.71645,50.00000,0.0000e+000,20.00000,    -0.12467,0.92491
276.00500, 38.59667,    -0.36386,82.69287,50.00000,0.0000e+000,20.00000,    -0.12283,0.92292
277.73901, 38.77667,    -0.37010,82.67161,50.00000,0.0000e+000,20.00000,    -0.12245,0.92096
279.48199, 38.95667,    -0.37617,82.65094,50.00000,0.0000e+000,20.00000,    -0.12245,0.91898
281.22601, 39.13667,    -0.38207,82.62680,50.00000,0.0000e+000,20.00000,    -0.12111,0.91701
282.96899, 39.31667,    -0.38826,82.60264,50.00000,0.0000e+000,20.00000,    -0.12004,0.91505
284.71399, 39.49667,    -0.39429,82.58117,50.00000,0.0000e+000,20.00000,    -0.11935,0.91309
286.45700, 39.67667,    -0.40043,82.56411,50.00000,0.0000e+000,20.00000,    -0.11824,0.91114
288.20401, 39.85667,    -0.40636,82.54829,50.00000,0.0000e+000,20.00000,    -0.11752,0.90919
289.95200, 40.03667,    -0.41220,82.52786,50.00000,0.0000e+000,20.00000,    -0.11688,0.90724
291.70499, 40.21667,    -0.41743,82.50704,50.00000,0.0000e+000,20.00000,    -0.11595,0.90529
293.45999, 40.39667,    -0.42332,82.48772,50.00000,0.0000e+000,20.00000,    -0.11498,0.90335
295.21899, 40.57667,    -0.42884,82.46541,50.00000,0.0000e+000,20.00000,    -0.11505,0.90141
296.98099, 40.75667,    -0.43406,82.44216,50.00000,0.0000e+000,20.00000,    -0.11526,0.89946
298.72198, 40.93667,    -0.43993,82.42254,50.00000,0.0000e+000,20.00000,    -0.11415,0.89755
300.49500, 41.11666,    -0.44506,82.40164,50.00000,0.0000e+000,20.00000,    -0.11265,0.89561
302.26001, 41.29667,    -0.45042,82.37847,50.00000,0.0000e+000,20.00000,    -0.11196,0.89368
303.99799, 41.47667,    -0.45572,82.35785,50.00000,0.0000e+000,20.00000,    -0.11259,0.89179
305.75900, 41.65667,    -0.46040,82.33718,50.00000,0.0000e+000,20.00000,    -0.11346,0.88987
307.53799, 41.83667,    -0.46560,82.31768,50.00000,0.0000e+000,20.00000,    -0.11331,0.88795
309.29599, 42.01667,    -0.46999,82.29910,50.00000,0.0000e+000,20.00000,    -0.11367,0.88605
311.06000, 42.19667,    -0.47538,82.27939,50.00000,0.0000e+000,20.00000,    -0.11471,0.88415
312.83899, 42.37667,    -0.48025,82.25756,50.00000,0.0000e+000,20.00000,    -0.11463,0.88224
314.59601, 42.55667,    -0.48575,82.23611,50.00000,0.0000e+000,20.00000,    -0.11364,0.88035
316.36600, 42.73667,    -0.49123,82.21635,50.00000,0.0000e+000,20.00000,    -0.11313,0.87846
318.13901, 42.91667,    -0.49673,82.19732,50.00000,0.0000e+000,20.00000,    -0.11348,0.87658
319.91000, 43.09667,    -0.50179,82.17809,50.00000,0.0000e+000,20.00000,    -0.11352,0.87470
321.69299, 43.27667,    -0.50645,82.15793,50.00000,0.0000e+000,20.00000,    -0.11389,0.87281
323.45499, 43.45667,    -0.51138,82.13907,50.00000,0.0000e+000,20.00000,    -0.11405,0.87095
325.24100, 43.63667,    -0.51594,82.12012,50.00000,0.0000e+000,20.00000,    -0.11457,0.86907
327.00500, 43.81667,    -0.51996,82.09821,50.00000,0.0000e+000,20.00000,    -0.11598,0.86722
328.77899, 43.99667,    -0.52422,82.07493,50.00000,0.0000e+000,20.00000,    -0.11693,0.86537
330.55600, 44.17667,    -0.52922,82.05323,50.00000,0.0000e+000,20.00000,    -0.11666,0.86352
332.33301, 44.35667,    -0.53401,82.03301,50.00000,0.0000e+000,20.00000,    -0.11664,0.86167
334.09900, 44.53667,    -0.53875,82.01483,50.00000,0.0000e+000,20.00000,    -0.11686,0.85984
335.87601, 44.71667,    -0.54376,81.99390,50.00000,0.0000e+000,20.00000,    -0.11783,0.85801
337.63101, 44.89667,    -0.54801,81.97047,50.00000,0.0000e+000,20.00000,    -0.11888,0.85620
339.41101, 45.07667,    -0.55248,81.94799,50.00000,0.0000e+000,20.00000,    -0.12014,0.85438
341.18701, 45.25667,    -0.55668,81.92669,50.00000,0.0000e+000,20.00000,    -0.12205,0.85256
342.95700, 45.43667,    -0.56096,81.90520,50.00000,0.0000e+000,20.00000,    -0.12424,0.85076
344.72198, 45.61666,    -0.56478,81.88184,50.00000,0.0000e+000,20.00000,    -0.12566,0.84896
346.50900, 45.79667,    -0.56874,81.85834,50.00000,0.0000e+000,20.00000,    -0.12624,0.84715
348.27399, 45.97667,    -0.57179,81.83783,50.00000,0.0000e+000,20.00000,    -0.12636,0.84537
350.04300, 46.15667,    -0.57535,81.81615,50.00000,0.0000e+000,20.00000,    -0.12759,0.84359
351.81100, 46.33667,    -0.57878,81.79541,50.00000,0.0000e+000,20.00000,    -0.12986,0.84182
353.57700, 46.51667,    -0.58258,81.77307,50.00000,0.0000e+000,20.00000,    -0.13165,0.84005
355.35699, 46.69667,    -0.58691,81.75013,50.00000,0.0000e+000,20.00000,    -0.13280,0.83828
357.12701, 46.87667,    -0.59108,81.72582,50.00000,0.0000e+000,20.00000,    -0.13348,0.83652
358.91501, 47.05667,    -0.59467,81.69978,50.00000,0.0000e+000,20.00000,    -0.13488,0.83475
360.68799, 47.23667,    -0.59838,81.67318,50.00000,0.0000e+000,20.00000,    -0.13611,0.83300
362.47400, 47.41667,    -0.60177,81.64654,50.00000,0.0000e+000,20.00000,    -0.13653,0.83124
364.24701, 47.59667,    -0.60520,81.62067,50.00000,0.0000e+000,20.00000,    -0.13668,0.82950
366.04099, 47.77667,    -0.60997,81.59803,50.00000,0.0000e+000,20.00000,    -0.13757,0.82775
367.83600, 47.95667,    -0.61501,81.57371,50.00000,0.0000e+000,20.00000,    -0.13802,0.82600
369.65399, 48.13667,    -0.61975,81.54701,50.00000,0.0000e+000,20.00000,    -0.13878,0.82424
371.45499, 48.31667,    -0.62365,81.52043,50.00000,0.0000e+000,20.00000,    -0.13875,0.82250
373.25299, 48.49667,    -0.62707,81.49270,50.00000,0.0000e+000,20.00000,    -0.13852,0.82077
375.05701, 48.67667,    -0.62924,81.46730,50.00000,0.0000e+000,20.00000,    -0.13830,0.81903
376.84000, 48.85667,    -0.63209,81.44106,50.00000,0.0000e+000,20.00000,    -0.13781,0.81733
378.62201, 49.03667,    -0.63299,81.41484,50.00000,0.0000e+000,20.00000,    -0.13740,0.81563
380.37100, 49.21667,    -0.63480,81.39034,50.00000,0.0000e+000,20.00000,    -0.13588,0.81397
382.11600, 49.39667,    -0.63747,81.36579,50.00000,0.0000e+000,20.00000,    -0.13402,0.81232
383.89600, 49.57667,    -0.64319,81.34181,50.00000,0.0000e+000,20.00000,    -0.13271,0.81064
385.67001, 49.75667,    -0.64939,81.31853,50.00000,0.0000e+000,20.00000,    -0.13127,0.80897
387.43500, 49.93667,    -0.65605,81.29493,50.00000,0.0000e+000,20.00000,    -0.12944,0.80731
389.22198, 50.11666,    -0.66226,81.27270,50.00000,0.0000e+000,20.00000,    -0.12784,0.80565
390.98801, 50.29667,    -0.66844,81.25087,50.00000,0.0000e+000,20.00000,    -0.12443,0.80400
392.75800, 50.47667,    -0.67456,81.22774,50.00000,0.0000e+000,20.00000,    -0.12179,0.80236
394.54001, 50.65667,    -0.68041,81.20392,50.00000,0.0000e+000,20.00000,    -0.11977,0.80072
396.32501, 50.83667,    -0.68653,81.17872,50.00000,0.0000e+000,20.00000,    -0.11697,0.79907
398.11200, 51.01667,    -0.69265,81.15698,50.00000,0.0000e+000,20.00000,    -0.11479,0.79743
399.89499, 51.19667,    -0.69904,81.13751,50.00000,0.0000e+000,20.00000,    -0.11244,0.79581
401.70001, 51.37667,    -0.70478,81.11911,50.00000,0.0000e+000,20.00000,    -0.11058,0.79416
403.47101, 51.55667,    -0.71043,81.10078,50.00000,0.0000e+000,20.00000,    -0.10919,0.79256
405.26199, 51.73667,    -0.71604,81.08113,50.00000,0.0000e+000,20.00000,    -0.10793,0.79094
407.04099, 51.91667,    -0.72124,81.06021,50.00000,0.0000e+000,20.00000,    -0.10672,0.78934
408.82800, 52.09667,    -0.72699,81.04417,50.00000,0.0000e+000,20.00000,    -0.10504,0.78773
410.60501, 52.27667,    -0.73217,81.02874,50.00000,0.0000e+000,20.00000,    -0.10387,0.78614
412.40100, 52.45667,    -0.73809,81.01013,50.00000,0.0000e+000,20.00000,    -0.10263,0.78455
414.18201, 52.63667,    -0.74313,80.99364,50.00000,0.0000e+000,20.00000,    -0.10011,0.78297
415.96799, 52.81667,    -0.74850,80.97707,50.00000,0.0000e+000,20.00000,-9.8888e-002,0.78139
417.75299, 52.99667,    -0.75360,80.96098,50.00000,0.0000e+000,20.00000,-9.8677e-002,0.77982
419.52100, 53.17667,    -0.75870,80.94403,50.00000,0.0000e+000,20.00000,-9.8165e-002,0.77826
421.29501, 53.35667,    -0.76374,80.92576,50.00000,0.0000e+000,20.00000,-9.7805e-002,0.77671
423.08801, 53.53667,    -0.76860,80.90705,50.00000,0.0000e+000,20.00000,-9.7959e-002,0.77515
424.87900, 53.71667,    -0.77416,80.88842,50.00000,0.0000e+000,20.00000,-9.8287e-002,0.77360
426.66101, 53.89667,    -0.77980,80.87285,50.00000,0.0000e+000,20.00000,    -0.10031,0.77206
428.45700, 54.07667,    -0.78584,80.85476,50.00000,0.0000e+000,20.00000,    -0.10382,0.77052
430.24701, 54.25667,    -0.79097,80.83521,50.00000,0.0000e+000,20.00000,    -0.10735,0.76898
432.04300, 54.43667,    -0.79586,80.81901,50.00000,0.0000e+000,20.00000,    -0.11240,0.76745
433.84399, 54.61666,    -0.79970,80.80157,50.00000,0.0000e+000,20.00000,    -0.11866,0.76592
435.63199, 54.79667,    -0.80354,80.78249,50.00000,0.0000e+000,20.00000,    -0.12593,0.76440
437.42899, 54.97667,    -0.80697,80.76558,50.00000,0.0000e+000,20.00000,    -0.13463,0.76288
439.21399, 55.15667,    -0.80958,80.74888,50.00000,0.0000e+000,20.00000,    -0.14216,0.76138
441.01199, 55.33667,    -0.81099,80.72948,50.00000,0.0000e+000,20.00000,    -0.14721,0.75988
442.80399, 55.51667,    -0.81115,80.70754,50.00000,0.0000e+000,20.00000,    -0.15185,0.75838
444.60599, 55.69667,    -0.81007,80.68355,50.00000,0.0000e+000,20.00000,    -0.15833,0.75689
446.40302, 55.87667,    -0.80597,80.65643,50.00000,0.0000e+000,20.00000,    -0.16289,0.75540
448.20801, 56.05667,    -0.79873,80.62555,50.00000,0.0000e+000,20.00000,    -0.16441,0.75391
449.98199, 56.23667,    -0.78850,80.59097,50.00000,0.0000e+000,20.00000,    -0.16580,0.75246
451.77301, 56.41667,    -0.77728,80.55212,50.00000,0.0000e+000,20.00000,    -0.16740,0.75099
453.55701, 56.59667,    -0.76850,80.51006,50.00000,0.0000e+000,20.00000,    -0.16870,0.74954
455.34000, 56.77667,    -0.76440,80.46224,50.00000,0.0000e+000,20.00000,    -0.16965,0.74809
457.12299, 56.95667,    -0.76617,80.41531,50.00000,0.0000e+000,20.00000,    -0.16984,0.74665
458.89999, 57.13667,    -0.77347,80.37728,50.00000,0.0000e+000,20.00000,    -0.16870,0.74522
460.69501, 57.31667,    -0.78378,80.34183,50.00000,0.0000e+000,20.00000,    -0.16613,0.74378
462.47400, 57.49667,    -0.79637,80.30246,50.00000,0.0000e+000,20.00000,    -0.16219,0.74236
464.26501, 57.67667,    -0.80990,80.26704,50.00000,0.0000e+000,20.00000,    -0.15777,0.74094
466.02802, 57.85667,    -0.82589,80.24054,50.00000,0.0000e+000,20.00000,    -0.15264,0.73954
467.80899, 58.03667,    -0.84304,80.21870,50.00000,0.0000e+000,20.00000,    -0.14727,0.73814
469.62299, 58.21667,    -0.85985,80.19625,50.00000,0.0000e+000,20.00000,    -0.14076,0.73671
471.41599, 58.39667,    -0.87501,80.17227,50.00000,0.0000e+000,20.00000,    -0.13338,0.73531
473.20599, 58.57667,    -0.88829,80.15082,50.00000,0.0000e+000,20.00000,    -0.12417,0.73392
475.01501, 58.75667,    -0.89918,80.13330,50.00000,0.0000e+000,20.00000,    -0.11465,0.73251
476.80200, 58.93667,    -0.90946,80.11812,50.00000,0.0000e+000,20.00000,    -0.10748,0.73113
478.61801, 59.11666,    -0.91804,80.10541,50.00000,0.0000e+000,20.00000,    -0.10091,0.72974
480.41400, 59.29667,    -0.92582,80.09602,50.00000,0.0000e+000,20.00000,-9.3060e-002,0.72836
482.21500, 59.47667,    -0.93251,80.08580,50.00000,0.0000e+000,20.00000,-8.6789e-002,0.72699
484.00800, 59.65667,    -0.93876,80.07454,50.00000,0.0000e+000,20.00000,-8.3336e-002,0.72562
485.78400, 59.83667,    -0.94423,80.06053,50.00000,0.0000e+000,20.00000,-8.0639e-002,0.72428
487.58301, 60.01667,    -0.94940,80.04596,50.00000,0.0000e+000,20.00000,-7.7867e-002,0.72292
489.38000, 60.19667,    -0.95522,80.03148,50.00000,0.0000e+000,20.00000,-7.4465e-002,0.72158
491.17499, 60.37667,    -0.96094,80.01794,50.00000,0.0000e+000,20.00000,-7.2367e-002,0.72024
492.97000, 60.55667,    -0.96707,80.00492,50.00000,0.0000e+000,20.00000,-7.0655e-002,0.71890
494.77301, 60.73667,    -0.97300,79.99177,50.00000,0.0000e+000,20.00000,-6.8754e-002,0.71756
496.58301, 60.91667,    -0.97796,79.98014,50.00000,0.0000e+000,20.00000,-6.7973e-002,0.71623
498.37399, 61.09667,    -0.98183,79.97011,50.00000,0.0000e+000,20.00000,-6.8496e-002,0.71491
500.16599, 61.27667,    -0.98517,79.95703,50.00000,0.0000e+000,20.00000,-6.9487e-002,0.71360
501.93600, 61.45667,    -0.98818,79.94159,50.00000,0.0000e+000,20.00000,-7.0435e-002,0.71231
503.72900, 61.63667,    -0.99244,79.92914,50.00000,0.0000e+000,20.00000,-6.9756e-002,0.71101
505.51599, 61.81667,    -0.99765,79.91690,50.00000,0.0000e+000,20.00000,-6.8386e-002,0.70972
507.32101, 61.99667,    -1.00314,79.90573,50.00000,0.0000e+000,20.00000,-6.7136e-002,0.70842
509.11801, 62.17667,    -1.00795,79.89147,50.00000,0.0000e+000,20.00000,-6.6608e-002,0.70714
510.90399, 62.35667,    -1.01267,79.87902,50.00000,0.0000e+000,20.00000,-6.7649e-002,0.70586
512.70697, 62.53667,    -1.01673,79.87039,50.00000,0.0000e+000,20.00000,-6.8447e-002,0.70458
514.50800, 62.71667,    -1.02074,79.86035,50.00000,0.0000e+000,20.00000,-6.8940e-002,0.70331
516.30402, 62.89667,    -1.02521,79.84897,50.00000,0.0000e+000,20.00000,-7.0495e-002,0.70205
518.10797, 63.07667,    -1.02923,79.83565,50.00000,0.0000e+000,20.00000,-7.1915e-002,0.70078
519.91400, 63.25667,    -1.03244,79.82106,50.00000,0.0000e+000,20.00000,-7.2043e-002,0.69952
521.70203, 63.43667,    -1.03559,79.80928,50.00000,0.0000e+000,20.00000,-7.2600e-002,0.69828
523.49799, 63.61666,    -1.03831,79.79974,50.00000,0.0000e+000,20.00000,-7.3463e-002,0.69704
525.29303, 63.79667,    -1.04077,79.78982,50.00000,0.0000e+000,20.00000,-7.5015e-002,0.69580
527.05902, 63.97667,    -1.04436,79.77860,50.00000,0.0000e+000,20.00000,-7.6461e-002,0.69459
528.86102, 64.15667,    -1.04791,79.76242,50.00000,0.0000e+000,20.00000,-7.9110e-002,0.69336
530.64502, 64.33667,    -1.05324,79.74575,50.00000,0.0000e+000,20.00000,-8.1941e-002,0.69214
532.45502, 64.51667,    -1.05731,79.73196,50.00000,0.0000e+000,20.00000,-8.3404e-002,0.69092
534.25098, 64.69666,    -1.06117,79.71662,50.00000,0.0000e+000,20.00000,-8.4857e-002,0.68971
536.04102, 64.87666,    -1.06476,79.69918,50.00000,0.0000e+000,20.00000,-8.7044e-002,0.68851
537.83398, 65.05666,    -1.06906,79.68274,50.00000,0.0000e+000,20.00000,-8.9651e-002,0.68731
539.63501, 65.23666,    -1.07321,79.66794,50.00000,0.0000e+000,20.00000,-9.2148e-002,0.68611
541.43597, 65.41666,    -1.07647,79.65261,50.00000,0.0000e+000,20.00000,-9.4692e-002,0.68492
543.22302, 65.59666,    -1.08073,79.63603,50.00000,0.0000e+000,20.00000,-9.7560e-002,0.68374
545.01703, 65.77666,    -1.08459,79.61754,50.00000,0.0000e+000,20.00000,-9.9798e-002,0.68256
546.83197, 65.95667,    -1.08907,79.59484,50.00000,0.0000e+000,20.00000,    -0.10073,0.68137
548.63501, 66.13667,    -1.09285,79.57477,50.00000,0.0000e+000,20.00000,    -0.10215,0.68020
550.42902, 66.31667,    -1.09694,79.55942,50.00000,0.0000e+000,20.00000,    -0.10480,0.67904
552.21899, 66.49667,    -1.10105,79.54344,50.00000,0.0000e+000,20.00000,    -0.10710,0.67788
554.02399, 66.67667,    -1.10483,79.52318,50.00000,0.0000e+000,20.00000,    -0.10830,0.67672
555.83301, 66.85667,    -1.10894,79.49920,50.00000,0.0000e+000,20.00000,    -0.11009,0.67557
557.62402, 67.03667,    -1.11392,79.47704,50.00000,0.0000e+000,20.00000,    -0.11225,0.67442
559.43402, 67.21667,    -1.11898,79.45805,50.00000,0.0000e+000,20.00000,    -0.11379,0.67328
561.24402, 67.39667,    -1.12348,79.43790,50.00000,0.0000e+000,20.00000,    -0.11547,0.67214
563.04700, 67.57667,    -1.12713,79.41852,50.00000,0.0000e+000,20.00000,    -0.11697,0.67100
564.84399, 67.75667,    -1.13168,79.40013,50.00000,0.0000e+000,20.00000,    -0.11682,0.66988
566.64099, 67.93667,    -1.13610,79.37823,50.00000,0.0000e+000,20.00000,    -0.11734,0.66876
568.43500, 68.11667,    -1.14042,79.35469,50.00000,0.0000e+000,20.00000,    -0.11946,0.66765
570.23999, 68.29667,    -1.14303,79.33110,50.00000,0.0000e+000,20.00000,    -0.12201,0.66653
572.04199, 68.47667,    -1.14706,79.30938,50.00000,0.0000e+000,20.00000,    -0.12277,0.66542
573.82397, 68.65667,    -1.15087,79.28639,50.00000,0.0000e+000,20.00000,    -0.12274,0.66433
575.63000, 68.83667,    -1.15630,79.26316,50.00000,0.0000e+000,20.00000,    -0.12298,0.66323
577.43298, 69.01667,    -1.16106,79.24238,50.00000,0.0000e+000,20.00000,    -0.12418,0.66214
579.21600, 69.19666,    -1.16614,79.22019,50.00000,0.0000e+000,20.00000,    -0.12539,0.66106
581.00702, 69.37666,    -1.17026,79.19658,50.00000,0.0000e+000,20.00000,    -0.12679,0.65999
582.82001, 69.55666,    -1.17490,79.17476,50.00000,0.0000e+000,20.00000,    -0.12927,0.65890
584.60699, 69.73666,    -1.17853,79.15207,50.00000,0.0000e+000,20.00000,    -0.13064,0.65784
586.42102, 69.91666,    -1.18342,79.12883,50.00000,0.0000e+000,20.00000,    -0.13101,0.65676
588.21100, 70.09666,    -1.18747,79.10379,50.00000,0.0000e+000,20.00000,    -0.13212,0.65570
590.00299, 70.27666,    -1.19229,79.08124,50.00000,0.0000e+000,20.00000,    -0.13378,0.65465
591.81500, 70.45667,    -1.19755,79.05797,50.00000,0.0000e+000,20.00000,    -0.13507,0.65359
593.61798, 70.63667,    -1.20324,79.03429,50.00000,0.0000e+000,20.00000,    -0.13648,0.65254
595.44000, 70.81667,    -1.20899,79.01059,50.00000,0.0000e+000,20.00000,    -0.13892,0.65148
597.24597, 70.99667,    -1.21330,78.98664,50.00000,0.0000e+000,20.00000,    -0.14026,0.65044
599.05603, 71.17667,    -1.21678,78.96169,50.00000,0.0000e+000,20.00000,    -0.14019,0.64939
600.86499, 71.35667,    -1.22101,78.93496,50.00000,0.0000e+000,20.00000,    -0.14229,0.64836
602.66699, 71.53667,    -1.22508,78.90804,50.00000,0.0000e+000,20.00000,    -0.14501,0.64733
604.47498, 71.71667,    -1.23023,78.88344,50.00000,0.0000e+000,20.00000,    -0.14684,0.64630
606.29901, 71.89667,    -1.23792,78.85611,50.00000,0.0000e+000,20.00000,    -0.14805,0.64527
608.11700, 72.07667,    -1.24369,78.82786,50.00000,0.0000e+000,20.00000,    -0.15008,0.64425
609.91998, 72.25667,    -1.24549,78.80065,50.00000,0.0000e+000,20.00000,    -0.15171,0.64324
611.72601, 72.43667,    -1.24690,78.77215,50.00000,0.0000e+000,20.00000,    -0.15252,0.64223
613.50897, 72.61667,    -1.24851,78.74234,50.00000,0.0000e+000,20.00000,    -0.15358,0.64124
615.29199, 72.79667,    -1.25208,78.71473,50.00000,0.0000e+000,20.00000,    -0.15593,0.64026
617.11499, 72.97667,    -1.25964,78.69160,50.00000,0.0000e+000,20.00000,    -0.15788,0.63925
618.94098, 73.15667,    -1.26819,78.66290,50.00000,0.0000e+000,20.00000,    -0.15984,0.63825
620.76898, 73.33667,    -1.27355,78.63044,50.00000,0.0000e+000,20.00000,    -0.16109,0.63726
622.56500, 73.51667,    -1.27605,78.60018,50.00000,0.0000e+000,20.00000,    -0.16218,0.63628
624.37701, 73.69666,    -1.27776,78.57103,50.00000,0.0000e+000,20.00000,    -0.16192,0.63530
626.15399, 73.87666,    -1.27953,78.54062,50.00000,0.0000e+000,20.00000,    -0.16173,0.63434
627.94800, 74.05666,    -1.28118,78.51137,50.00000,0.0000e+000,20.00000,    -0.16278,0.63338
629.72101, 74.23666,    -1.28406,78.48442,50.00000,0.0000e+000,20.00000,    -0.16459,0.63243
631.51202, 74.41666,    -1.28960,78.45740,50.00000,0.0000e+000,20.00000,    -0.16581,0.63148
633.29303, 74.59666,    -1.29439,78.42553,50.00000,0.0000e+000,20.00000,    -0.16600,0.63054
635.10101, 74.77666,    -1.29983,78.39334,50.00000,0.0000e+000,20.00000,    -0.16782,0.62959
636.90503, 74.95667,    -1.30466,78.36019,50.00000,0.0000e+000,20.00000,    -0.16783,0.62864
638.71899, 75.13667,    -1.30970,78.32772,50.00000,0.0000e+000,20.00000,    -0.16749,0.62769
640.53601, 75.31667,    -1.31602,78.29869,50.00000,0.0000e+000,20.00000,    -0.16822,0.62674
642.33301, 75.49667,    -1.32063,78.27255,50.00000,0.0000e+000,20.00000,    -0.16838,0.62581
644.14099, 75.67667,    -1.32494,78.24546,50.00000,0.0000e+000,20.00000,    -0.16787,0.62488
645.94598, 75.85667,    -1.32873,78.21481,50.00000,0.0000e+000,20.00000,    -0.16840,0.62395
647.75098, 76.03667,    -1.33168,78.18062,50.00000,0.0000e+000,20.00000,    -0.17036,0.62303
649.56598, 76.21667,    -1.33529,78.14556,50.00000,0.0000e+000,20.00000,    -0.17242,0.62211
651.40100, 76.39667,    -1.34177,78.11633,50.00000,0.0000e+000,20.00000,    -0.17267,0.62117
653.21002, 76.57667,    -1.34502,78.08629,50.00000,0.0000e+000,20.00000,    -0.17163,0.62026
654.98700, 76.75667,    -1.34627,78.05857,50.00000,0.0000e+000,20.00000,    -0.17047,0.61937
656.78699, 76.93667,    -1.34863,78.02831,50.00000,0.0000e+000,20.00000,    -0.17085,0.61847
658.57300, 77.11667,    -1.35130,77.99467,50.00000,0.0000e+000,20.00000,    -0.17242,0.61757
660.38599, 77.29667,    -1.35630,77.96452,50.00000,0.0000e+000,20.00000,    -0.17406,0.61667
662.19098, 77.47667,    -1.36126,77.93610,50.00000,0.0000e+000,20.00000,    -0.17576,0.61578
663.97803, 77.65667,    -1.36407,77.90531,50.00000,0.0000e+000,20.00000,    -0.17638,0.61490
665.79498, 77.83667,    -1.36753,77.87107,50.00000,0.0000e+000,20.00000,    -0.17645,0.61401
667.59998, 78.01667,    -1.37152,77.83671,50.00000,0.0000e+000,20.00000,    -0.17667,0.61313
669.40698, 78.19666,    -1.37458,77.80418,50.00000,0.0000e+000,20.00000,    -0.17884,0.61225
671.21002, 78.37666,    -1.37781,77.77507,50.00000,0.0000e+000,20.00000,    -0.18091,0.61138
673.01300, 78.55666,    -1.38060,77.74703,50.00000,0.0000e+000,20.00000,    -0.18387,0.61051
674.82599, 78.73666,    -1.38431,77.71350,50.00000,0.0000e+000,20.00000,    -0.18670,0.60963
676.63300, 78.91666,    -1.38837,77.67786,50.00000,0.0000e+000,20.00000,    -0.18886,0.60877
678.44800, 79.09666,    -1.39215,77.64526,50.00000,0.0000e+000,20.00000,    -0.19200,0.60790
680.26001, 79.27666,    -1.39402,77.61242,50.00000,0.0000e+000,20.00000,    -0.19563,0.60704
682.03900, 79.45667,    -1.39599,77.57999,50.00000,0.0000e+000,20.00000,    -0.20015,0.60620
683.85797, 79.63667,    -1.39763,77.54653,50.00000,0.0000e+000,20.00000,    -0.20310,0.60535
685.66901, 79.81667,    -1.39953,77.51049,50.00000,0.0000e+000,20.00000,    -0.20551,0.60450
687.45697, 79.99667,    -1.40025,77.47282,50.00000,0.0000e+000,20.00000,    -0.20939,0.60366
689.25098, 80.17667,    -1.40182,77.43536,50.00000,0.0000e+000,20.00000,    -0.21528,0.60283
691.06598, 80.35667,    -1.40429,77.39676,50.00000,0.0000e+000,20.00000,    -0.22308,0.60199
692.89398, 80.53667,    -1.40835,77.35702,50.00000,0.0000e+000,20.00000,    -0.22928,0.60114
694.72803, 80.71667,    -1.41317,77.31595,50.00000,0.0000e+000,20.00000,    -0.23513,0.60030
696.54999, 80.89667,    -1.41368,77.27346,50.00000,0.0000e+000,20.00000,    -0.24209,0.59946
698.34998, 81.07667,    -1.41277,77.23206,50.00000,0.0000e+000,20.00000,    -0.24923,0.59864
700.15900, 81.25667,    -1.41146,77.18609,50.00000,0.0000e+000,20.00000,    -0.25786,0.59782
701.97198, 81.43667,    -1.40980,77.14044,50.00000,0.0000e+000,20.00000,    -0.26641,0.59700
703.75403, 81.61667,    -1.40782,77.09771,50.00000,0.0000e+000,20.00000,    -0.27455,0.59620
705.55200, 81.79667,    -1.40618,77.05096,50.00000,0.0000e+000,20.00000,    -0.28193,0.59539
707.34900, 81.97667,    -1.40542,77.00076,50.00000,0.0000e+000,20.00000,    -0.28983,0.59458
709.16302, 82.15667,    -1.40327,76.94477,50.00000,0.0000e+000,20.00000,    -0.29790,0.59378
710.94299, 82.33667,    -1.39967,76.88947,50.00000,0.0000e+000,20.00000,    -0.30336,0.59298
712.74597, 82.51667,    -1.39679,76.83261,50.00000,0.0000e+000,20.00000,    -0.30542,0.59219
714.54498, 82.69666,    -1.39307,76.77424,50.00000,0.0000e+000,20.00000,    -0.30518,0.59139
716.32898, 82.87666,    -1.39066,76.71573,50.00000,0.0000e+000,20.00000,    -0.30444,0.59061
718.10901, 83.05666,    -1.38761,76.65247,50.00000,0.0000e+000,20.00000,    -0.30423,0.58983
719.90900, 83.23666,    -1.38598,76.58788,50.00000,0.0000e+000,20.00000,    -0.30407,0.58905
721.69397, 83.41666,    -1.38639,76.52269,50.00000,0.0000e+000,20.00000,    -0.30441,0.58827
723.50098, 83.59666,    -1.39142,76.45793,50.00000,0.0000e+000,20.00000,    -0.30168,0.58749
725.30298, 83.77666,    -1.39800,76.39216,50.00000,0.0000e+000,20.00000,    -0.29550,0.58671
727.09998, 83.95667,    -1.40684,76.32405,50.00000,0.0000e+000,20.00000,    -0.28446,0.58594
728.90997, 84.13667,    -1.41990,76.26252,50.00000,0.0000e+000,20.00000,    -0.27278,0.58516
730.69501, 84.31667,    -1.43547,76.21306,50.00000,0.0000e+000,20.00000,    -0.26075,0.58440
732.51398, 84.49667,    -1.45232,76.17029,50.00000,0.0000e+000,20.00000,    -0.24761,0.58363
734.30200, 84.67667,    -1.46319,76.13205,50.00000,0.0000e+000,20.00000,    -0.23361,0.58287
736.12402, 84.85667,    -1.46875,76.08846,50.00000,0.0000e+000,20.00000,    -0.21881,0.58210
737.93500, 85.03667,    -1.47319,76.04256,50.00000,0.0000e+000,20.00000,    -0.20408,0.58134
739.72400, 85.21667,    -1.48184,75.99821,50.00000,0.0000e+000,20.00000,    -0.18936,0.58059
741.53699, 85.39667,    -1.49708,75.96057,50.00000,0.0000e+000,20.00000,    -0.17469,0.57983
743.35199, 85.57667,    -1.52570,75.93207,50.00000,0.0000e+000,20.00000,    -0.16005,0.57907
745.17401, 85.75667,    -1.55373,75.91558,50.00000,0.0000e+000,20.00000,    -0.14367,0.57832
747.01001, 85.93667,    -1.57084,75.90292,50.00000,0.0000e+000,20.00000,    -0.12823,0.57756
748.81299, 86.11667,    -1.57895,75.89019,50.00000,0.0000e+000,20.00000,    -0.11692,0.57681
750.61499, 86.29667,    -1.58310,75.87949,50.00000,0.0000e+000,20.00000,    -0.10775,0.57607
752.40399, 86.47667,    -1.58476,75.87197,50.00000,0.0000e+000,20.00000,-9.9567e-002,0.57534
754.20898, 86.65667,    -1.58997,75.86419,50.00000,0.0000e+000,20.00000,-9.0274e-002,0.57460
756.00299, 86.83667,    -1.59521,75.85351,50.00000,0.0000e+000,20.00000,-8.0523e-002,0.57387
757.76703, 87.01667,    -1.59831,75.84226,50.00000,0.0000e+000,20.00000,-7.0730e-002,0.57315
759.54797, 87.19666,    -1.60372,75.83109,50.00000,0.0000e+000,20.00000,-6.2701e-002,0.57243
761.34601, 87.37666,    -1.60902,75.81914,50.00000,0.0000e+000,20.00000,-5.8210e-002,0.57171
763.15900, 87.55666,    -1.61470,75.81018,50.00000,0.0000e+000,20.00000,-5.6357e-002,0.57098
764.95599, 87.73666,    -1.62108,75.80362,50.00000,0.0000e+000,20.00000,-5.5941e-002,0.57026
766.77600, 87.91666,    -1.62707,75.79440,50.00000,0.0000e+000,20.00000,-5.5022e-002,0.56953
768.58698, 88.09666,    -1.63495,75.78397,50.00000,0.0000e+000,20.00000,-5.4211e-002,0.56881
770.46399, 88.27666,    -1.64803,75.77539,50.00000,0.0000e+000,20.00000,-5.4262e-002,0.56806
772.31799, 88.45667,    -1.65692,75.76693,50.00000,0.0000e+000,20.00000,-5.5492e-002,0.56733
774.15100, 88.63667,    -1.66100,75.75679,50.00000,0.0000e+000,20.00000,-5.6170e-002,0.56661
775.96100, 88.81667,    -1.66317,75.74744,50.00000,0.0000e+000,20.00000,-5.6843e-002,0.56589
777.75201, 88.99667,    -1.66534,75.73841,50.00000,0.0000e+000,20.00000,-5.8004e-002,0.56519
779.55499, 89.17667,    -1.66807,75.72497,50.00000,0.0000e+000,20.00000,-5.8910e-002,0.56448
781.34003, 89.35667,    -1.67211,75.71320,50.00000,0.0000e+000,20.00000,-5.9488e-002,0.56379
783.12299, 89.53667,    -1.67771,75.70214,50.00000,0.0000e+000,20.00000,-5.9753e-002,0.56309
784.93500, 89.71667,    -1.68518,75.69222,50.00000,0.0000e+000,20.00000,-5.9854e-002,0.56239
786.73798, 89.89667,    -1.69110,75.68403,50.00000,0.0000e+000,20.00000,-6.0353e-002,0.56169
788.54102, 90.07667,    -1.69588,75.67603,50.00000,0.0000e+000,20.00000,-6.2088e-002,0.56100
790.33197, 90.25667,    -1.69992,75.66481,50.00000,0.0000e+000,20.00000,-6.3756e-002,0.56031
792.14099, 90.43667,    -1.70417,75.65186,50.00000,0.0000e+000,20.00000,-6.4384e-002,0.55961
793.93103, 90.61667,    -1.70648,75.63843,50.00000,0.0000e+000,20.00000,-6.5258e-002,0.55893
795.73700, 90.79667,    -1.70983,75.62325,50.00000,0.0000e+000,20.00000,-6.6441e-002,0.55824
797.53497, 90.97667,    -1.71298,75.60779,50.00000,0.0000e+000,20.00000,-6.6981e-002,0.55755
799.34601, 91.15667,    -1.71594,75.59524,50.00000,0.0000e+000,20.00000,-6.8241e-002,0.55686
801.14899, 91.33667,    -1.72170,75.58748,50.00000,0.0000e+000,20.00000,-6.9144e-002,0.55618
802.97198, 91.51667,    -1.72551,75.57880,50.00000,0.0000e+000,20.00000,-7.0080e-002,0.55549
804.78601, 91.69666,    -1.72739,75.56703,50.00000,0.0000e+000,20.00000,-7.1883e-002,0.55480
806.58099, 91.87666,    -1.72795,75.55201,50.00000,0.0000e+000,20.00000,-7.3695e-002,0.55413
808.39600, 92.05666,    -1.72975,75.53737,50.00000,0.0000e+000,20.00000,-7.5765e-002,0.55345
810.17999, 92.23666,    -1.73283,75.52488,50.00000,0.0000e+000,20.00000,-7.7357e-002,0.55278
811.98602, 92.41666,    -1.73650,75.51222,50.00000,0.0000e+000,20.00000,-7.8185e-002,0.55210
813.79700, 92.59666,    -1.74087,75.49923,50.00000,0.0000e+000,20.00000,-7.8005e-002,0.55143
815.58801, 92.77666,    -1.74496,75.48480,50.00000,0.0000e+000,20.00000,-7.7923e-002,0.55076
817.39099, 92.95667,    -1.74941,75.46787,50.00000,0.0000e+000,20.00000,-7.9273e-002,0.55009
819.18701, 93.13667,    -1.75670,75.45318,50.00000,0.0000e+000,20.00000,-8.1442e-002,0.54943
820.99402, 93.31667,    -1.76398,75.43965,50.00000,0.0000e+000,20.00000,-8.3666e-002,0.54876
822.78699, 93.49667,    -1.77358,75.42470,50.00000,0.0000e+000,20.00000,-8.6178e-002,0.54810
824.64203, 93.67667,    -1.78910,75.41040,50.00000,0.0000e+000,20.00000,-8.8064e-002,0.54742
826.50800, 93.85667,    -1.80363,75.39279,50.00000,0.0000e+000,20.00000,-8.9474e-002,0.54673
828.34497, 94.03667,    -1.81013,75.37378,50.00000,0.0000e+000,20.00000,-9.0951e-002,0.54606
830.14502, 94.21667,    -1.81350,75.35719,50.00000,0.0000e+000,20.00000,-9.2391e-002,0.54540
831.93402, 94.39667,    -1.81046,75.34262,50.00000,0.0000e+000,20.00000,-9.4137e-002,0.54475
833.72400, 94.57667,    -1.81025,75.32788,50.00000,0.0000e+000,20.00000,-9.6488e-002,0.54409
835.51202, 94.75667,    -1.81125,75.30980,50.00000,0.0000e+000,20.00000,-9.8223e-002,0.54344
837.30603, 94.93667,    -1.81309,75.29323,50.00000,0.0000e+000,20.00000,-9.9734e-002,0.54279
839.09100, 95.11667,    -1.81372,75.27730,50.00000,0.0000e+000,20.00000,    -0.10208,0.54215
840.87201, 95.29667,    -1.81419,75.25735,50.00000,0.0000e+000,20.00000,    -0.10412,0.54150
842.67401, 95.47667,    -1.81547,75.23577,50.00000,0.0000e+000,20.00000,    -0.10645,0.54085
844.47699, 95.65667,    -1.81777,75.21535,50.00000,0.0000e+000,20.00000,    -0.10892,0.54020
846.27301, 95.83667,    -1.81965,75.19700,50.00000,0.0000e+000,20.00000,    -0.10994,0.53955
848.06201, 96.01667,    -1.82099,75.17928,50.00000,0.0000e+000,20.00000,    -0.11069,0.53891
849.85901, 96.19666,    -1.82245,75.16034,50.00000,0.0000e+000,20.00000,    -0.11265,0.53827
851.65399, 96.37666,    -1.82376,75.13815,50.00000,0.0000e+000,20.00000,    -0.11482,0.53762
853.45300, 96.55666,    -1.82719,75.11479,50.00000,0.0000e+000,20.00000,    -0.11670,0.53698
855.26398, 96.73666,    -1.83174,75.09386,50.00000,0.0000e+000,20.00000,    -0.11848,0.53633
857.07800, 96.91666,    -1.83630,75.07222,50.00000,0.0000e+000,20.00000,    -0.12043,0.53569
858.88098, 97.09666,    -1.83960,75.04969,50.00000,0.0000e+000,20.00000,    -0.12130,0.53505
860.70697, 97.27666,    -1.84328,75.02741,50.00000,0.0000e+000,20.00000,    -0.12106,0.53440
862.52002, 97.45667,    -1.84619,75.00148,50.00000,0.0000e+000,20.00000,    -0.12234,0.53375
864.30701, 97.63667,    -1.84792,74.97794,50.00000,0.0000e+000,20.00000,    -0.12390,0.53312
866.10199, 97.81667,    -1.84906,74.95807,50.00000,0.0000e+000,20.00000,    -0.12509,0.53249
867.87201, 97.99667,    -1.85020,74.93643,50.00000,0.0000e+000,20.00000,    -0.12676,0.53186
869.66101, 98.17667,    -1.85225,74.91421,50.00000,0.0000e+000,20.00000,    -0.12786,0.53123
871.44800, 98.35667,    -1.85812,74.88988,50.00000,0.0000e+000,20.00000,    -0.12810,0.53060
873.26898, 98.53667,    -1.86500,74.86597,50.00000,0.0000e+000,20.00000,    -0.12938,0.52996
875.10699, 98.71667,    -1.87150,74.84332,50.00000,0.0000e+000,20.00000,    -0.13057,0.52931
876.91602, 98.89667,    -1.87739,74.82044,50.00000,0.0000e+000,20.00000,    -0.13075,0.52868
878.75000, 99.07667,    -1.88283,74.80000,50.00000,0.0000e+000,20.00000,    -0.13047,0.52803
880.58502, 99.25667,    -1.88890,74.77521,50.00000,0.0000e+000,20.00000,    -0.13000,0.52739
882.39899, 99.43667,    -1.89403,74.75030,50.00000,0.0000e+000,20.00000,    -0.13009,0.52675
884.21399, 99.61667,    -1.89647,74.72824,50.00000,0.0000e+000,20.00000,    -0.13038,0.52612
886.01001, 99.79667,    -1.89673,74.70412,50.00000,0.0000e+000,20.00000,    -0.12991,0.52549
887.81201, 99.97667,    -1.89826,74.67816,50.00000,0.0000e+000,20.00000,    -0.12958,0.52486
889.61902,100.15667,    -1.90082,74.65385,50.00000,0.0000e+000,20.00000,    -0.12977,0.52423
891.43701,100.33667,    -1.90176,74.62811,50.00000,0.0000e+000,20.00000,    -0.13070,0.52360
893.23499,100.51667,    -1.90536,74.60226,50.00000,0.0000e+000,20.00000,    -0.13135,0.52297
895.05298,100.69666,    -1.90906,74.57843,50.00000,0.0000e+000,20.00000,    -0.13104,0.52234
896.86798,100.87666,    -1.91227,74.55743,50.00000,0.0000e+000,20.00000,    -0.13166,0.52171
898.72998,101.05666,    -1.92290,74.53423,50.00000,0.0000e+000,20.00000,    -0.13189,0.52106
900.56598,101.23666,    -1.92720,74.50928,50.00000,0.0000e+000,20.00000,    -0.13141,0.52042
902.39203,101.41666,    -1.92568,74.48755,50.00000,0.0000e+000,20.00000,    -0.13138,0.51979
904.17798,101.59666,    -1.92181,74.46810,50.00000,0.0000e+000,20.00000,    -0.13120,0.51917
905.96301,101.77666,    -1.91705,74.44740,50.00000,0.0000e+000,20.00000,    -0.13043,0.51855
907.73297,101.95667,    -1.91399,74.42349,50.00000,0.0000e+000,20.00000,    -0.12905,0.51794
909.51398,102.13667,    -1.91494,74.39594,50.00000,0.0000e+000,20.00000,    -0.12696,0.51732
911.32001,102.31667,    -1.91804,74.37024,50.00000,0.0000e+000,20.00000,    -0.12545,0.51670
913.11298,102.49667,    -1.92058,74.34818,50.00000,0.0000e+000,20.00000,    -0.12390,0.51608
914.91199,102.67667,    -1.92258,74.32561,50.00000,0.0000e+000,20.00000,    -0.12290,0.51546
916.71399,102.85667,    -1.92416,74.30108,50.00000,0.0000e+000,20.00000,    -0.12224,0.51484
918.48999,103.03667,    -1.92219,74.27693,50.00000,0.0000e+000,20.00000,    -0.12137,0.51422
920.27502,103.21667,    -1.92137,74.25485,50.00000,0.0000e+000,20.00000,    -0.12160,0.51361
922.07300,103.39667,    -1.92338,74.23207,50.00000,0.0000e+000,20.00000,    -0.12109,0.51299
923.88397,103.57667,    -1.92644,74.20867,50.00000,0.0000e+000,20.00000,    -0.11889,0.51236
925.68799,103.75667,    -1.92882,74.18862,50.00000,0.0000e+000,20.00000,    -0.11703,0.51174
927.52899,103.93667,    -1.93228,74.17097,50.00000,0.0000e+000,20.00000,    -0.11534,0.51111
929.34998,104.11667,    -1.93267,74.15075,50.00000,0.0000e+000,20.00000,    -0.11361,0.51048
931.14899,104.29667,    -1.93068,74.13163,50.00000,0.0000e+000,20.00000,    -0.11282,0.50986
932.95300,104.47667,    -1.92487,74.11429,50.00000,0.0000e+000,20.00000,    -0.11150,0.50924
934.74597,104.65667,    -1.91966,74.09449,50.00000,0.0000e+000,20.00000,    -0.10877,0.50862
936.53003,104.83667,    -1.91651,74.07279,50.00000,0.0000e+000,20.00000,    -0.10703,0.50801
938.34802,105.01667,    -1.91348,74.04958,50.00000,0.0000e+000,20.00000,    -0.10705,0.50738
940.14099,105.19666,    -1.90912,74.03065,50.00000,0.0000e+000,20.00000,    -0.10666,0.50676
941.94501,105.37666,    -1.90718,74.01807,50.00000,0.0000e+000,20.00000,    -0.10490,0.50614
943.75702,105.55666,    -1.90491,74.00265,50.00000,0.0000e+000,20.00000,    -0.10329,0.50552
945.56799,105.73666,    -1.90132,73.98188,50.00000,0.0000e+000,20.00000,    -0.10184,0.50489
947.40399,105.91666,    -1.90149,73.96159,50.00000,0.0000e+000,20.00000,    -0.10099,0.50426
949.26398,106.09666,    -1.90499,73.94208,50.00000,0.0000e+000,20.00000,    -0.10137,0.50362
951.10199,106.27666,    -1.90210,73.92406,50.00000,0.0000e+000,20.00000,    -0.10188,0.50299
952.91901,106.45667,    -1.89502,73.90957,50.00000,0.0000e+000,20.00000,    -0.10071,0.50236
954.71399,106.63667,    -1.88587,73.89246,50.00000,0.0000e+000,20.00000,-9.8596e-002,0.50175
956.49799,106.81667,    -1.87701,73.87038,50.00000,0.0000e+000,20.00000,-9.6843e-002,0.50113
958.25897,106.99667,    -1.86769,73.84882,50.00000,0.0000e+000,20.00000,-9.6761e-002,0.50052
960.02100,107.17667,    -1.85575,73.83107,50.00000,0.0000e+000,20.00000,-9.7784e-002,0.49992
961.78302,107.35667,    -1.85053,73.81605,50.00000,0.0000e+000,20.00000,-9.8478e-002,0.49931
963.56097,107.53667,    -1.84825,73.80342,50.00000,0.0000e+000,20.00000,-9.8166e-002,0.49870
965.39398,107.71667,    -1.85292,73.78787,50.00000,0.0000e+000,20.00000,-9.5826e-002,0.49806
967.16699,107.89667,    -1.84777,73.76699,50.00000,0.0000e+000,20.00000,-9.3599e-002,0.49745
968.96399,108.07667,    -1.84603,73.74734,50.00000,0.0000e+000,20.00000,-9.2487e-002,0.49683
970.77698,108.25667,    -1.84873,73.73165,50.00000,0.0000e+000,20.00000,-9.2287e-002,0.49621
972.58698,108.43667,    -1.85106,73.71803,50.00000,0.0000e+000,20.00000,-9.1974e-002,0.49558
974.39301,108.61667,    -1.85118,73.70203,50.00000,0.0000e+000,20.00000,-9.0384e-002,0.49496
976.19702,108.79667,    -1.85138,73.68225,50.00000,0.0000e+000,20.00000,-8.8259e-002,0.49433
978.00201,108.97667,    -1.85303,73.66490,50.00000,0.0000e+000,20.00000,-8.6097e-002,0.49371
979.82397,109.15667,    -1.85651,73.64842,50.00000,0.0000e+000,20.00000,-8.4828e-002,0.49308
981.64697,109.33667,    -1.85901,73.62893,50.00000,0.0000e+000,20.00000,-8.5381e-002,0.49245
983.45001,109.51667,    -1.86067,73.61585,50.00000,0.0000e+000,20.00000,-8.2081e-002,0.49182
985.25800,109.69666,    -1.86135,73.60492,50.00000,0.0000e+000,20.00000,-8.1665e-002,0.49120
987.05298,109.87666,    -1.86114,73.59080,50.00000,0.0000e+000,20.00000,-7.9629e-002,0.49058
988.87500,110.05666,    -1.86471,73.57655,50.00000,0.0000e+000,20.00000,-7.6597e-002,0.48994
990.67999,110.23666,    -1.86801,73.56175,50.00000,0.0000e+000,20.00000,-7.1955e-002,0.48932
992.55499,110.41666,    -1.87756,73.54586,50.00000,0.0000e+000,20.00000,-7.3740e-002,0.48867
994.43201,110.59666,    -1.88817,73.53126,50.00000,0.0000e+000,20.00000,-7.0871e-002,0.48801
996.23102,110.77666,    -1.88481,73.52033,50.00000,0.0000e+000,20.00000,-5.8895e-002,0.48739
998.02197,110.95667,    -1.87851,73.50970,50.00000,0.0000e+000,20.00000,-4.9158e-002,0.48676
998.46198,111.00166,    -1.87769,73.50798,50.00000,0.0000e+000,20.00000, 1.1851e-002,0.48661