File: book/some_content/TG_ExpDat_CEM_I_DC28.csv
#FILE:                       ,CEM_I_DC28; 14-2-2025.ngb-ds3
#FORMAT:                     ,NETZSCH5
#IDENTITY:                   ,OPC PASTE
#DECIMAL:                    ,POINT
#SEPARATOR:                  ,COMMA
#MTYPE:                      ,DSC
#INSTRUMENT:                 ,Microlab TU Delft
#PROJECT:                    ,
#DATE/TIME:                  ,14/02/2025 2:30:12 PM
#CORR. FILE:                 ,Blank with cover; 13-1-2025.ngb-bs3
#LABORATORY:                 ,TU Delft Micro Lab
#OPERATOR:                   ,Ahmed
#REMARK:                     ,under Argon atmosphere, 10K/min
#SAMPLE:                     ,CEM_I_DC28
#SAMPLE MASS /mg:            ,42
#MATERIAL:                   ,Geopolymer paste
#REFERENCE:                  ,blank
#REFERENCE MASS /mg:         ,0
#TYPE OF CRUCIBLE:           ,DSC/TG pan Al2O3
#SAMPLE CRUCIBLE MASS /mg:   ,0
#REFERENCE CRUCIBLE MASS /mg:,0
#CORR. CODE:                 ,020
#EXO:                        ,-1
#RANGE:                      ,40/10.0(K/min)/1000
#SEGMENT:                    ,S2/2

##Temp./øC,Time/min,DSC/(mW/mg),Mass/%,Gas Flow(purge1)/(ml/min),Gas Flow(purge2)/(ml/min),Gas Flow(protective)/(ml/min),DTG/(%/min),Sensit./(uV/mW)
 40.84300, 15.59250, 2.4111e-002,98.37660,50.00000,0.0000e+000,20.00000,-8.2298e-002,1.22578
 40.89200, 15.77250, 2.4186e-002,98.36037,50.00000,0.0000e+000,20.00000,-8.0469e-002,1.22571
 41.01500, 15.95250, 2.4575e-002,98.34388,50.00000,0.0000e+000,20.00000,-7.8956e-002,1.22554
 41.17300, 16.13250, 2.5306e-002,98.32855,50.00000,0.0000e+000,20.00000,-7.6966e-002,1.22532
 41.41600, 16.31250, 2.6484e-002,98.31514,50.00000,0.0000e+000,20.00000,-7.6938e-002,1.22499
 41.72100, 16.49250, 2.8318e-002,98.30178,50.00000,0.0000e+000,20.00000,-7.7975e-002,1.22457
 42.12800, 16.67250, 3.0364e-002,98.28763,50.00000,0.0000e+000,20.00000,-7.9502e-002,1.22401
 42.61400, 16.85250, 3.2623e-002,98.27496,50.00000,0.0000e+000,20.00000,-8.1821e-002,1.22334
 43.19700, 17.03250, 3.5482e-002,98.26368,50.00000,0.0000e+000,20.00000,-8.4264e-002,1.22253
 43.86500, 17.21250, 3.8795e-002,98.25137,50.00000,0.0000e+000,20.00000,-8.6582e-002,1.22161
 44.60500, 17.39250, 4.2355e-002,98.23857,50.00000,0.0000e+000,20.00000,-8.8655e-002,1.22059
 45.42300, 17.57250, 4.5835e-002,98.22435,50.00000,0.0000e+000,20.00000,-9.1505e-002,1.21947
 46.36000, 17.75250, 4.9955e-002,98.20927,50.00000,0.0000e+000,20.00000,-9.5170e-002,1.21817
 47.34700, 17.93250, 5.4086e-002,98.19378,50.00000,0.0000e+000,20.00000,-9.9969e-002,1.21681
 48.44800, 18.11250, 5.8309e-002,98.17795,50.00000,0.0000e+000,20.00000,    -0.10614,1.21530
 49.62900, 18.29250, 6.2593e-002,98.16102,50.00000,0.0000e+000,20.00000,    -0.11375,1.21367
 50.87000, 18.47250, 6.7372e-002,98.14395,50.00000,0.0000e+000,20.00000,    -0.12252,1.21196
 52.24300, 18.65250, 7.2056e-002,98.12525,50.00000,0.0000e+000,20.00000,    -0.13255,1.21007
 53.66200, 18.83250, 7.6999e-002,98.10392,50.00000,0.0000e+000,20.00000,    -0.14456,1.20812
 55.17700, 19.01250, 8.1922e-002,98.08174,50.00000,0.0000e+000,20.00000,    -0.15875,1.20603
 56.76900, 19.19250, 8.7262e-002,98.05884,50.00000,0.0000e+000,20.00000,    -0.17623,1.20384
 58.42500, 19.37250, 9.2537e-002,98.03266,50.00000,0.0000e+000,20.00000,    -0.19659,1.20157
 60.17600, 19.55250, 9.8373e-002,98.00336,50.00000,0.0000e+000,20.00000,    -0.21731,1.19916
 61.97600, 19.73250,     0.10472,97.97060,50.00000,0.0000e+000,20.00000,    -0.23876,1.19669
 63.86300, 19.91250,     0.11133,97.93499,50.00000,0.0000e+000,20.00000,    -0.26302,1.19409
 65.79700, 20.09250,     0.11828,97.89480,50.00000,0.0000e+000,20.00000,    -0.28894,1.19144
 67.80000, 20.27250,     0.12609,97.84925,50.00000,0.0000e+000,20.00000,    -0.31917,1.18869
 69.84300, 20.45250,     0.13438,97.80011,50.00000,0.0000e+000,20.00000,    -0.35508,1.18589
 71.94900, 20.63250,     0.14282,97.74605,50.00000,0.0000e+000,20.00000,    -0.39017,1.18300
 74.11200, 20.81250,     0.15241,97.68355,50.00000,0.0000e+000,20.00000,    -0.42742,1.18004
 76.30100, 20.99250,     0.16308,97.60917,50.00000,0.0000e+000,20.00000,    -0.46680,1.17705
 78.53600, 21.17250,     0.17449,97.52194,50.00000,0.0000e+000,20.00000,    -0.50741,1.17399
 80.83300, 21.35250,     0.18683,97.43120,50.00000,0.0000e+000,20.00000,    -0.54880,1.17085
 83.16900, 21.53250,     0.20031,97.33844,50.00000,0.0000e+000,20.00000,    -0.59145,1.16766
 85.51500, 21.71250,     0.21475,97.23565,50.00000,0.0000e+000,20.00000,    -0.63644,1.16446
 87.90600, 21.89250,     0.23030,97.12509,50.00000,0.0000e+000,20.00000,    -0.68368,1.16120
 90.31200, 22.07250,     0.24661,97.00146,50.00000,0.0000e+000,20.00000,    -0.73250,1.15793
 92.74300, 22.25250,     0.26336,96.85348,50.00000,0.0000e+000,20.00000,    -0.78425,1.15462
 95.21200, 22.43250,     0.28119,96.70433,50.00000,0.0000e+000,20.00000,    -0.83954,1.15127
 97.67800, 22.61250,     0.29911,96.54779,50.00000,0.0000e+000,20.00000,    -0.89626,1.14792
100.17300, 22.79250,     0.31757,96.38225,50.00000,0.0000e+000,20.00000,    -0.95350,1.14454
102.64400, 22.97250,     0.33558,96.20935,50.00000,0.0000e+000,20.00000,    -1.00975,1.14119
105.15200, 23.15250,     0.35398,96.03012,50.00000,0.0000e+000,20.00000,    -1.06642,1.13780
107.61900, 23.33250,     0.37258,95.84351,50.00000,0.0000e+000,20.00000,    -1.12294,1.13447
110.12100, 23.51250,     0.39302,95.64571,50.00000,0.0000e+000,20.00000,    -1.17208,1.13110
112.61200, 23.69250,     0.41488,95.43571,50.00000,0.0000e+000,20.00000,    -1.21013,1.12774
115.09300, 23.87250,     0.43956,95.21399,50.00000,0.0000e+000,20.00000,    -1.23737,1.12441
117.54900, 24.05250,     0.46651,94.97903,50.00000,0.0000e+000,20.00000,    -1.25154,1.12111
120.01600, 24.23250,     0.49529,94.72614,50.00000,0.0000e+000,20.00000,    -1.25901,1.11780
122.47800, 24.41250,     0.52487,94.45979,50.00000,0.0000e+000,20.00000,    -1.26185,1.11450
124.92600, 24.59250,     0.55465,94.18017,50.00000,0.0000e+000,20.00000,    -1.25958,1.11123
127.38000, 24.77250,     0.58308,93.89008,50.00000,0.0000e+000,20.00000,    -1.25235,1.10796
129.80600, 24.95250,     0.60848,93.59311,50.00000,0.0000e+000,20.00000,    -1.24121,1.10472
132.23801, 25.13250,     0.62689,93.29370,50.00000,0.0000e+000,20.00000,    -1.22754,1.10149
134.62601, 25.31250,     0.63094,93.00900,50.00000,0.0000e+000,20.00000,    -1.20960,1.09832
137.02800, 25.49250,     0.61764,92.75514,50.00000,0.0000e+000,20.00000,    -1.18583,1.09513
139.42900, 25.67250,     0.58657,92.53152,50.00000,0.0000e+000,20.00000,    -1.15933,1.09195
141.80800, 25.85250,     0.54812,92.33089,50.00000,0.0000e+000,20.00000,    -1.12616,1.08881
144.19600, 26.03250,     0.50855,92.15154,50.00000,0.0000e+000,20.00000,    -1.08726,1.08566
146.57500, 26.21250,     0.47114,91.98502,50.00000,0.0000e+000,20.00000,    -1.04474,1.08253
148.93800, 26.39250,     0.43633,91.82738,50.00000,0.0000e+000,20.00000,    -0.99781,1.07942
151.26900, 26.57250,     0.40385,91.68036,50.00000,0.0000e+000,20.00000,    -0.94662,1.07636
153.60201, 26.75250,     0.37454,91.54214,50.00000,0.0000e+000,20.00000,    -0.89295,1.07331
155.90900, 26.93250,     0.34729,91.40648,50.00000,0.0000e+000,20.00000,    -0.83750,1.07029
158.18100, 27.11250,     0.32187,91.27475,50.00000,0.0000e+000,20.00000,    -0.78372,1.06733
160.44800, 27.29250,     0.29853,91.15300,50.00000,0.0000e+000,20.00000,    -0.73727,1.06438
162.67700, 27.47250,     0.27662,91.02948,50.00000,0.0000e+000,20.00000,    -0.69864,1.06148
164.89999, 27.65250,     0.25606,90.91640,50.00000,0.0000e+000,20.00000,    -0.66562,1.05860
167.10300, 27.83250,     0.23660,90.80846,50.00000,0.0000e+000,20.00000,    -0.63756,1.05574
169.25301, 28.01250,     0.21823,90.69932,50.00000,0.0000e+000,20.00000,    -0.61294,1.05296
171.38800, 28.19250,     0.20076,90.59260,50.00000,0.0000e+000,20.00000,    -0.59021,1.05021
173.52800, 28.37250,     0.18398,90.49031,50.00000,0.0000e+000,20.00000,    -0.56952,1.04746
175.63100, 28.55250,     0.16752,90.39037,50.00000,0.0000e+000,20.00000,    -0.55036,1.04476
177.71100, 28.73250,     0.15202,90.29240,50.00000,0.0000e+000,20.00000,    -0.53134,1.04209
179.76199, 28.91250,     0.13706,90.20012,50.00000,0.0000e+000,20.00000,    -0.51316,1.03946
181.80701, 29.09250,     0.12302,90.11053,50.00000,0.0000e+000,20.00000,    -0.49651,1.03685
183.84000, 29.27250,     0.10981,90.02364,50.00000,0.0000e+000,20.00000,    -0.47826,1.03426
185.83600, 29.45250, 9.7506e-002,89.93975,50.00000,0.0000e+000,20.00000,    -0.46260,1.03172
187.80701, 29.63250, 8.5706e-002,89.85960,50.00000,0.0000e+000,20.00000,    -0.44895,1.02922
189.77100, 29.81250, 7.3918e-002,89.78143,50.00000,0.0000e+000,20.00000,    -0.43390,1.02673
191.72800, 29.99250, 6.1558e-002,89.70511,50.00000,0.0000e+000,20.00000,    -0.41901,1.02426
193.65300, 30.17250, 4.9172e-002,89.63136,50.00000,0.0000e+000,20.00000,    -0.40519,1.02183
195.57401, 30.35250, 3.7260e-002,89.56185,50.00000,0.0000e+000,20.00000,    -0.39157,1.01941
197.45500, 30.53250, 2.5273e-002,89.49506,50.00000,0.0000e+000,20.00000,    -0.37743,1.01704
199.35699, 30.71250, 1.3481e-002,89.42879,50.00000,0.0000e+000,20.00000,    -0.36450,1.01466
201.22099, 30.89250, 1.9738e-003,89.36558,50.00000,0.0000e+000,20.00000,    -0.35243,1.01233
203.07600, 31.07250,-8.9926e-003,89.30884,50.00000,0.0000e+000,20.00000,    -0.34074,1.01001
204.92999, 31.25250,-1.9793e-002,89.25102,50.00000,0.0000e+000,20.00000,    -0.32891,1.00770
206.75101, 31.43250,-3.0028e-002,89.19283,50.00000,0.0000e+000,20.00000,    -0.31805,1.00543
208.58701, 31.61250,-3.9766e-002,89.13809,50.00000,0.0000e+000,20.00000,    -0.30775,1.00315
210.40601, 31.79250,-4.9238e-002,89.08526,50.00000,0.0000e+000,20.00000,    -0.29766,1.00090
212.19600, 31.97250,-5.8678e-002,89.03262,50.00000,0.0000e+000,20.00000,    -0.28838,0.99868
213.99899, 32.15250,-6.7250e-002,88.98187,50.00000,0.0000e+000,20.00000,    -0.27976,0.99646
215.79100, 32.33250,-7.5876e-002,88.93457,50.00000,0.0000e+000,20.00000,    -0.27160,0.99425
217.55000, 32.51250,-8.3787e-002,88.88866,50.00000,0.0000e+000,20.00000,    -0.26360,0.99209
219.33200, 32.69250,-9.2010e-002,88.84298,50.00000,0.0000e+000,20.00000,    -0.25607,0.98990
221.09200, 32.87250,    -0.10023,88.79790,50.00000,0.0000e+000,20.00000,    -0.25052,0.98775
222.83000, 33.05250,    -0.10785,88.75635,50.00000,0.0000e+000,20.00000,    -0.24431,0.98563
224.58000, 33.23250,    -0.11511,88.71548,50.00000,0.0000e+000,20.00000,    -0.23788,0.98349
226.32500, 33.41250,    -0.12300,88.67457,50.00000,0.0000e+000,20.00000,    -0.23185,0.98137
228.07800, 33.59250,    -0.13045,88.63481,50.00000,0.0000e+000,20.00000,    -0.22647,0.97924
229.80400, 33.77250,    -0.13758,88.59445,50.00000,0.0000e+000,20.00000,    -0.22136,0.97715
231.55000, 33.95250,    -0.14468,88.55547,50.00000,0.0000e+000,20.00000,    -0.21652,0.97504
233.28101, 34.13250,    -0.15160,88.51814,50.00000,0.0000e+000,20.00000,    -0.21271,0.97295
234.99800, 34.31250,    -0.15887,88.48107,50.00000,0.0000e+000,20.00000,    -0.20915,0.97089
236.74600, 34.49250,    -0.16527,88.44443,50.00000,0.0000e+000,20.00000,    -0.20556,0.96879
238.44000, 34.67250,    -0.17221,88.40733,50.00000,0.0000e+000,20.00000,    -0.20132,0.96676
240.16400, 34.85250,    -0.17900,88.37231,50.00000,0.0000e+000,20.00000,    -0.19825,0.96470
241.88100, 35.03250,    -0.18578,88.33739,50.00000,0.0000e+000,20.00000,    -0.19558,0.96265
243.60400, 35.21250,    -0.19247,88.30380,50.00000,0.0000e+000,20.00000,    -0.19256,0.96060
245.30800, 35.39250,    -0.19866,88.27077,50.00000,0.0000e+000,20.00000,    -0.18981,0.95858
247.03400, 35.57250,    -0.20567,88.23668,50.00000,0.0000e+000,20.00000,    -0.18700,0.95653
248.74600, 35.75250,    -0.21181,88.20319,50.00000,0.0000e+000,20.00000,    -0.18458,0.95451
250.47400, 35.93250,    -0.21789,88.16932,50.00000,0.0000e+000,20.00000,    -0.18238,0.95247
252.18800, 36.11250,    -0.22476,88.13623,50.00000,0.0000e+000,20.00000,    -0.18048,0.95045
253.89500, 36.29250,    -0.23098,88.10348,50.00000,0.0000e+000,20.00000,    -0.17857,0.94845
255.62700, 36.47250,    -0.23802,88.07329,50.00000,0.0000e+000,20.00000,    -0.17615,0.94642
257.34299, 36.65250,    -0.24424,88.04273,50.00000,0.0000e+000,20.00000,    -0.17414,0.94442
259.07599, 36.83250,    -0.25110,88.01161,50.00000,0.0000e+000,20.00000,    -0.17235,0.94240
260.79599, 37.01250,    -0.25774,87.98147,50.00000,0.0000e+000,20.00000,    -0.17084,0.94040
262.54401, 37.19250,    -0.26403,87.95167,50.00000,0.0000e+000,20.00000,    -0.16954,0.93837
264.26501, 37.37250,    -0.27018,87.92179,50.00000,0.0000e+000,20.00000,    -0.16774,0.93638
265.97400, 37.55250,    -0.27654,87.89123,50.00000,0.0000e+000,20.00000,    -0.16573,0.93440
267.71600, 37.73250,    -0.28236,87.86170,50.00000,0.0000e+000,20.00000,    -0.16337,0.93240
269.43301, 37.91250,    -0.28813,87.83171,50.00000,0.0000e+000,20.00000,    -0.16132,0.93043
271.17099, 38.09250,    -0.29446,87.80179,50.00000,0.0000e+000,20.00000,    -0.15958,0.92844
272.91699, 38.27250,    -0.30094,87.77336,50.00000,0.0000e+000,20.00000,    -0.15880,0.92644
274.65100, 38.45250,    -0.30702,87.74542,50.00000,0.0000e+000,20.00000,    -0.15780,0.92446
276.37701, 38.63250,    -0.31297,87.71714,50.00000,0.0000e+000,20.00000,    -0.15615,0.92250
278.12701, 38.81250,    -0.31854,87.68872,50.00000,0.0000e+000,20.00000,    -0.15507,0.92052
279.86099, 38.99250,    -0.32446,87.66052,50.00000,0.0000e+000,20.00000,    -0.15429,0.91855
281.61099, 39.17250,    -0.33014,87.63290,50.00000,0.0000e+000,20.00000,    -0.15291,0.91658
283.34900, 39.35250,    -0.33573,87.60650,50.00000,0.0000e+000,20.00000,    -0.15160,0.91462
285.09299, 39.53250,    -0.34168,87.58121,50.00000,0.0000e+000,20.00000,    -0.15087,0.91267
286.83401, 39.71250,    -0.34794,87.55562,50.00000,0.0000e+000,20.00000,    -0.15003,0.91072
288.59299, 39.89250,    -0.35289,87.52923,50.00000,0.0000e+000,20.00000,    -0.14898,0.90875
290.34299, 40.07250,    -0.35892,87.50161,50.00000,0.0000e+000,20.00000,    -0.14789,0.90681
292.08801, 40.25250,    -0.36472,87.47469,50.00000,0.0000e+000,20.00000,    -0.14689,0.90487
293.83600, 40.43250,    -0.37035,87.44939,50.00000,0.0000e+000,20.00000,    -0.14591,0.90293
295.59000, 40.61250,    -0.37579,87.42345,50.00000,0.0000e+000,20.00000,    -0.14492,0.90100
297.34100, 40.79250,    -0.38150,87.39625,50.00000,0.0000e+000,20.00000,    -0.14396,0.89907
299.10101, 40.97250,    -0.38654,87.37128,50.00000,0.0000e+000,20.00000,    -0.14303,0.89713
300.85901, 41.15250,    -0.39242,87.34588,50.00000,0.0000e+000,20.00000,    -0.14209,0.89521
302.60300, 41.33250,    -0.39775,87.31884,50.00000,0.0000e+000,20.00000,    -0.14107,0.89331
304.37000, 41.51250,    -0.40332,87.29208,50.00000,0.0000e+000,20.00000,    -0.14029,0.89138
306.13199, 41.69250,    -0.40866,87.26566,50.00000,0.0000e+000,20.00000,    -0.13975,0.88947
307.89600, 41.87250,    -0.41361,87.24079,50.00000,0.0000e+000,20.00000,    -0.13869,0.88756
309.65500, 42.05250,    -0.41868,87.21657,50.00000,0.0000e+000,20.00000,    -0.13735,0.88566
311.40302, 42.23250,    -0.42434,87.19196,50.00000,0.0000e+000,20.00000,    -0.13661,0.88378
313.18301, 42.41250,    -0.42905,87.16718,50.00000,0.0000e+000,20.00000,    -0.13615,0.88187
314.94299, 42.59250,    -0.43521,87.14240,50.00000,0.0000e+000,20.00000,    -0.13543,0.87998
316.71701, 42.77250,    -0.44070,87.11795,50.00000,0.0000e+000,20.00000,    -0.13515,0.87809
318.50000, 42.95250,    -0.44615,87.09451,50.00000,0.0000e+000,20.00000,    -0.13453,0.87619
320.27701, 43.13250,    -0.45092,87.07278,50.00000,0.0000e+000,20.00000,    -0.13349,0.87431
322.03299, 43.31250,    -0.45533,87.05039,50.00000,0.0000e+000,20.00000,    -0.13291,0.87245
323.81500, 43.49250,    -0.45924,87.02632,50.00000,0.0000e+000,20.00000,    -0.13250,0.87057
325.56699, 43.67250,    -0.46347,87.00241,50.00000,0.0000e+000,20.00000,    -0.13242,0.86873
327.31699, 43.85250,    -0.46822,86.98010,50.00000,0.0000e+000,20.00000,    -0.13258,0.86690
329.09799, 44.03250,    -0.47295,86.95744,50.00000,0.0000e+000,20.00000,    -0.13285,0.86504
330.84799, 44.21250,    -0.47868,86.93364,50.00000,0.0000e+000,20.00000,    -0.13323,0.86321
332.61099, 44.39250,    -0.48354,86.90910,50.00000,0.0000e+000,20.00000,    -0.13373,0.86138
334.39301, 44.57250,    -0.48958,86.88462,50.00000,0.0000e+000,20.00000,    -0.13430,0.85954
336.16901, 44.75250,    -0.49455,86.86165,50.00000,0.0000e+000,20.00000,    -0.13537,0.85771
337.95599, 44.93250,    -0.49962,86.83870,50.00000,0.0000e+000,20.00000,    -0.13701,0.85587
339.70200, 45.11250,    -0.50445,86.81421,50.00000,0.0000e+000,20.00000,    -0.13850,0.85408
341.49899, 45.29250,    -0.50916,86.78915,50.00000,0.0000e+000,20.00000,    -0.14037,0.85224
343.25900, 45.47250,    -0.51374,86.76429,50.00000,0.0000e+000,20.00000,    -0.14267,0.85045
345.05399, 45.65250,    -0.51801,86.73955,50.00000,0.0000e+000,20.00000,    -0.14431,0.84862
346.84000, 45.83250,    -0.52176,86.71413,50.00000,0.0000e+000,20.00000,    -0.14559,0.84682
348.62500, 46.01250,    -0.52564,86.68804,50.00000,0.0000e+000,20.00000,    -0.14710,0.84502
350.38901, 46.19250,    -0.52897,86.66148,50.00000,0.0000e+000,20.00000,    -0.14895,0.84324
352.17200, 46.37250,    -0.53275,86.63487,50.00000,0.0000e+000,20.00000,    -0.15052,0.84145
353.96500, 46.55250,    -0.53646,86.60749,50.00000,0.0000e+000,20.00000,    -0.15242,0.83966
355.73499, 46.73250,    -0.54058,86.57951,50.00000,0.0000e+000,20.00000,    -0.15430,0.83790
357.52499, 46.91250,    -0.54412,86.55205,50.00000,0.0000e+000,20.00000,    -0.15563,0.83612
359.29401, 47.09250,    -0.54767,86.52198,50.00000,0.0000e+000,20.00000,    -0.15702,0.83437
361.07101, 47.27250,    -0.55162,86.48926,50.00000,0.0000e+000,20.00000,    -0.15857,0.83262
362.85999, 47.45250,    -0.55530,86.46017,50.00000,0.0000e+000,20.00000,    -0.15955,0.83086
364.63501, 47.63250,    -0.55977,86.43308,50.00000,0.0000e+000,20.00000,    -0.16003,0.82912
366.43201, 47.81250,    -0.56406,86.40433,50.00000,0.0000e+000,20.00000,    -0.16049,0.82737
368.20801, 47.99250,    -0.56737,86.37322,50.00000,0.0000e+000,20.00000,    -0.16090,0.82564
369.99200, 48.17250,    -0.57101,86.34272,50.00000,0.0000e+000,20.00000,    -0.16115,0.82391
371.76999, 48.35250,    -0.57421,86.31260,50.00000,0.0000e+000,20.00000,    -0.16100,0.82219
373.54901, 48.53250,    -0.57787,86.28281,50.00000,0.0000e+000,20.00000,    -0.16068,0.82048
375.31400, 48.71250,    -0.58162,86.25368,50.00000,0.0000e+000,20.00000,    -0.16085,0.81879
377.09698, 48.89250,    -0.58590,86.22376,50.00000,0.0000e+000,20.00000,    -0.16026,0.81708
378.90100, 49.07250,    -0.59132,86.19308,50.00000,0.0000e+000,20.00000,    -0.15845,0.81536
380.67599, 49.25250,    -0.59578,86.16433,50.00000,0.0000e+000,20.00000,    -0.15761,0.81368
382.45999, 49.43250,    -0.60020,86.13738,50.00000,0.0000e+000,20.00000,    -0.15774,0.81199
384.24899, 49.61250,    -0.60499,86.10970,50.00000,0.0000e+000,20.00000,    -0.15750,0.81030
386.04001, 49.79250,    -0.60987,86.08177,50.00000,0.0000e+000,20.00000,    -0.15639,0.80862
387.81100, 49.97250,    -0.61524,86.05406,50.00000,0.0000e+000,20.00000,    -0.15507,0.80696
389.60001, 50.15250,    -0.62078,86.02736,50.00000,0.0000e+000,20.00000,    -0.15327,0.80529
391.38199, 50.33250,    -0.62619,86.00065,50.00000,0.0000e+000,20.00000,    -0.15095,0.80364
393.14899, 50.51250,    -0.63225,85.97267,50.00000,0.0000e+000,20.00000,    -0.14962,0.80200
394.94800, 50.69250,    -0.63790,85.94517,50.00000,0.0000e+000,20.00000,    -0.14918,0.80034
396.74600, 50.87250,    -0.64397,85.91903,50.00000,0.0000e+000,20.00000,    -0.14810,0.79869
398.51099, 51.05250,    -0.64751,85.89243,50.00000,0.0000e+000,20.00000,    -0.14664,0.79707
400.25601, 51.23250,    -0.65091,85.86497,50.00000,0.0000e+000,20.00000,    -0.14590,0.79548
402.01700, 51.41250,    -0.65494,85.83740,50.00000,0.0000e+000,20.00000,    -0.14506,0.79387
403.78601, 51.59250,    -0.65964,85.81045,50.00000,0.0000e+000,20.00000,    -0.14410,0.79227
405.54901, 51.77250,    -0.66478,85.78438,50.00000,0.0000e+000,20.00000,    -0.14381,0.79068
407.32501, 51.95250,    -0.67108,85.76040,50.00000,0.0000e+000,20.00000,    -0.14363,0.78908
409.09900, 52.13250,    -0.67705,85.73893,50.00000,0.0000e+000,20.00000,    -0.14344,0.78749
410.89600, 52.31250,    -0.68312,85.71530,50.00000,0.0000e+000,20.00000,    -0.14410,0.78588
412.67401, 52.49250,    -0.68862,85.68756,50.00000,0.0000e+000,20.00000,    -0.14508,0.78430
414.46500, 52.67250,    -0.69515,85.66022,50.00000,0.0000e+000,20.00000,    -0.14682,0.78271
416.26099, 52.85250,    -0.70089,85.63618,50.00000,0.0000e+000,20.00000,    -0.14969,0.78113
418.07599, 53.03250,    -0.70598,85.61203,50.00000,0.0000e+000,20.00000,    -0.15409,0.77953
419.86099, 53.21250,    -0.71004,85.58746,50.00000,0.0000e+000,20.00000,    -0.16035,0.77797
421.65799, 53.39250,    -0.71414,85.56322,50.00000,0.0000e+000,20.00000,    -0.16811,0.77640
423.45401, 53.57250,    -0.71804,85.53679,50.00000,0.0000e+000,20.00000,    -0.17695,0.77484
425.25101, 53.75250,    -0.72235,85.51028,50.00000,0.0000e+000,20.00000,    -0.18704,0.77328
427.03799, 53.93250,    -0.72537,85.48473,50.00000,0.0000e+000,20.00000,    -0.19955,0.77174
428.82199, 54.11250,    -0.72682,85.45510,50.00000,0.0000e+000,20.00000,    -0.21340,0.77020
430.61700, 54.29250,    -0.72513,85.42376,50.00000,0.0000e+000,20.00000,    -0.22644,0.76866
432.41901, 54.47250,    -0.71936,85.39160,50.00000,0.0000e+000,20.00000,    -0.23973,0.76713
434.19901, 54.65250,    -0.70909,85.35547,50.00000,0.0000e+000,20.00000,    -0.25467,0.76561
435.99701, 54.83250,    -0.69657,85.31312,50.00000,0.0000e+000,20.00000,    -0.27104,0.76409
437.78799, 55.01250,    -0.68323,85.26359,50.00000,0.0000e+000,20.00000,    -0.28879,0.76258
439.57199, 55.19250,    -0.67073,85.20880,50.00000,0.0000e+000,20.00000,    -0.30772,0.76108
441.38901, 55.37250,    -0.65815,85.15062,50.00000,0.0000e+000,20.00000,    -0.32725,0.75956
443.16000, 55.55250,    -0.64484,85.08991,50.00000,0.0000e+000,20.00000,    -0.34825,0.75809
444.94299, 55.73250,    -0.63114,85.02365,50.00000,0.0000e+000,20.00000,    -0.37204,0.75661
446.74500, 55.91250,    -0.61793,84.95061,50.00000,0.0000e+000,20.00000,    -0.39582,0.75512
448.50699, 56.09250,    -0.60430,84.87581,50.00000,0.0000e+000,20.00000,    -0.41815,0.75367
450.29199, 56.27250,    -0.59028,84.79972,50.00000,0.0000e+000,20.00000,    -0.44242,0.75220
452.05899, 56.45250,    -0.57521,84.72132,50.00000,0.0000e+000,20.00000,    -0.46617,0.75076
453.83301, 56.63250,    -0.56063,84.63830,50.00000,0.0000e+000,20.00000,    -0.48868,0.74931
455.60599, 56.81250,    -0.54580,84.54968,50.00000,0.0000e+000,20.00000,    -0.51054,0.74788
457.37900, 56.99250,    -0.53088,84.45672,50.00000,0.0000e+000,20.00000,    -0.53011,0.74644
459.16699, 57.17250,    -0.51635,84.36014,50.00000,0.0000e+000,20.00000,    -0.54835,0.74501
460.95401, 57.35250,    -0.50173,84.25760,50.00000,0.0000e+000,20.00000,    -0.56417,0.74358
462.74600, 57.53250,    -0.48870,84.14677,50.00000,0.0000e+000,20.00000,    -0.57336,0.74215
464.54401, 57.71250,    -0.47584,84.03045,50.00000,0.0000e+000,20.00000,    -0.57801,0.74072
466.34698, 57.89250,    -0.46412,83.91786,50.00000,0.0000e+000,20.00000,    -0.57767,0.73929
468.15100, 58.07250,    -0.45330,83.79836,50.00000,0.0000e+000,20.00000,    -0.57181,0.73787
469.93100, 58.25250,    -0.44180,83.67610,50.00000,0.0000e+000,20.00000,    -0.56137,0.73647
471.72900, 58.43250,    -0.43019,83.55313,50.00000,0.0000e+000,20.00000,    -0.54744,0.73507
473.51599, 58.61250,    -0.42076,83.42525,50.00000,0.0000e+000,20.00000,    -0.53099,0.73368
475.29901, 58.79250,    -0.41468,83.29864,50.00000,0.0000e+000,20.00000,    -0.51244,0.73229
477.10101, 58.97250,    -0.41537,83.17478,50.00000,0.0000e+000,20.00000,    -0.49229,0.73090
478.90201, 59.15250,    -0.42759,83.05382,50.00000,0.0000e+000,20.00000,    -0.46991,0.72952
480.69299, 59.33250,    -0.45668,82.95312,50.00000,0.0000e+000,20.00000,    -0.44495,0.72815
482.47699, 59.51250,    -0.50115,82.86214,50.00000,0.0000e+000,20.00000,    -0.41828,0.72679
484.25500, 59.69250,    -0.55610,82.78583,50.00000,0.0000e+000,20.00000,    -0.39274,0.72544
486.04599, 59.87250,    -0.61526,82.72868,50.00000,0.0000e+000,20.00000,    -0.36500,0.72408
487.85101, 60.05250,    -0.67700,82.68707,50.00000,0.0000e+000,20.00000,    -0.33550,0.72272
489.66400, 60.23250,    -0.72969,82.65488,50.00000,0.0000e+000,20.00000,    -0.30559,0.72136
491.46701, 60.41250,    -0.77016,82.62683,50.00000,0.0000e+000,20.00000,    -0.27454,0.72002
493.27499, 60.59250,    -0.80095,82.60169,50.00000,0.0000e+000,20.00000,    -0.24302,0.71867
495.07901, 60.77250,    -0.82619,82.57917,50.00000,0.0000e+000,20.00000,    -0.21262,0.71734
496.89401, 60.95250,    -0.84570,82.55904,50.00000,0.0000e+000,20.00000,    -0.18255,0.71600
498.70200, 61.13250,    -0.86066,82.54084,50.00000,0.0000e+000,20.00000,    -0.15777,0.71467
500.49701, 61.31250,    -0.87284,82.52214,50.00000,0.0000e+000,20.00000,    -0.13567,0.71336
502.30899, 61.49250,    -0.88188,82.50266,50.00000,0.0000e+000,20.00000,    -0.11732,0.71204
504.11401, 61.67250,    -0.89069,82.48536,50.00000,0.0000e+000,20.00000,    -0.10420,0.71073
505.91699, 61.85250,    -0.89997,82.47056,50.00000,0.0000e+000,20.00000,-9.5043e-002,0.70943
507.75500, 62.03250,    -0.90907,82.45729,50.00000,0.0000e+000,20.00000,-8.8091e-002,0.70811
509.57501, 62.21250,    -0.91632,82.44364,50.00000,0.0000e+000,20.00000,-8.2846e-002,0.70681
511.40799, 62.39250,    -0.92139,82.43105,50.00000,0.0000e+000,20.00000,-7.8674e-002,0.70550
513.20801, 62.57250,    -0.92499,82.41897,50.00000,0.0000e+000,20.00000,-7.5289e-002,0.70423
514.97803, 62.75250,    -0.92733,82.40571,50.00000,0.0000e+000,20.00000,-7.2604e-002,0.70298
516.76898, 62.93250,    -0.92970,82.39299,50.00000,0.0000e+000,20.00000,-7.0408e-002,0.70172
518.54901, 63.11250,    -0.93247,82.38120,50.00000,0.0000e+000,20.00000,-6.8172e-002,0.70047
520.33099, 63.29250,    -0.93651,82.36934,50.00000,0.0000e+000,20.00000,-6.5560e-002,0.69923
522.11798, 63.47250,    -0.94091,82.35721,50.00000,0.0000e+000,20.00000,-6.3434e-002,0.69799
523.90601, 63.65250,    -0.94610,82.34664,50.00000,0.0000e+000,20.00000,-6.1986e-002,0.69675
525.69897, 63.83250,    -0.95068,82.33867,50.00000,0.0000e+000,20.00000,-6.1025e-002,0.69552
527.49701, 64.01250,    -0.95629,82.32971,50.00000,0.0000e+000,20.00000,-5.9969e-002,0.69429
529.29797, 64.19250,    -0.96139,82.31935,50.00000,0.0000e+000,20.00000,-5.8897e-002,0.69306
531.09302, 64.37250,    -0.96600,82.30894,50.00000,0.0000e+000,20.00000,-5.8273e-002,0.69184
532.88202, 64.55250,    -0.97006,82.29817,50.00000,0.0000e+000,20.00000,-5.7245e-002,0.69063
534.69800, 64.73250,    -0.97410,82.28785,50.00000,0.0000e+000,20.00000,-5.6139e-002,0.68941
536.50299, 64.91250,    -0.98043,82.27746,50.00000,0.0000e+000,20.00000,-5.5402e-002,0.68820
538.33002, 65.09250,    -0.98738,82.26748,50.00000,0.0000e+000,20.00000,-5.4691e-002,0.68698
540.13898, 65.27250,    -0.99115,82.25747,50.00000,0.0000e+000,20.00000,-5.3861e-002,0.68578
541.95001, 65.45250,    -0.99432,82.24764,50.00000,0.0000e+000,20.00000,-5.3305e-002,0.68458
543.74103, 65.63250,    -0.99649,82.23777,50.00000,0.0000e+000,20.00000,-5.3412e-002,0.68340
545.54602, 65.81250,    -1.00016,82.22800,50.00000,0.0000e+000,20.00000,-5.3523e-002,0.68221
547.33698, 65.99250,    -1.00420,82.21892,50.00000,0.0000e+000,20.00000,-5.3282e-002,0.68104
549.13800, 66.17250,    -1.00782,82.20949,50.00000,0.0000e+000,20.00000,-5.2681e-002,0.67987
550.93701, 66.35250,    -1.01151,82.19983,50.00000,0.0000e+000,20.00000,-5.1896e-002,0.67871
552.72400, 66.53250,    -1.01513,82.19107,50.00000,0.0000e+000,20.00000,-5.1420e-002,0.67756
554.51501, 66.71250,    -1.01865,82.18189,50.00000,0.0000e+000,20.00000,-5.0803e-002,0.67641
556.30603, 66.89250,    -1.02162,82.17269,50.00000,0.0000e+000,20.00000,-5.0650e-002,0.67526
558.10400, 67.07250,    -1.02507,82.16355,50.00000,0.0000e+000,20.00000,-5.0807e-002,0.67412
559.90100, 67.25250,    -1.02894,82.15459,50.00000,0.0000e+000,20.00000,-5.0823e-002,0.67298
561.69098, 67.43250,    -1.03205,82.14590,50.00000,0.0000e+000,20.00000,-5.0931e-002,0.67185
563.48499, 67.61250,    -1.03589,82.13706,50.00000,0.0000e+000,20.00000,-5.0744e-002,0.67073
565.27698, 67.79250,    -1.03925,82.12756,50.00000,0.0000e+000,20.00000,-5.0168e-002,0.66961
567.06598, 67.97250,    -1.04264,82.11919,50.00000,0.0000e+000,20.00000,-4.9898e-002,0.66849
568.84497, 68.15250,    -1.04512,82.11139,50.00000,0.0000e+000,20.00000,-4.9778e-002,0.66739
570.62799, 68.33250,    -1.04723,82.10278,50.00000,0.0000e+000,20.00000,-4.9727e-002,0.66629
572.42700, 68.51250,    -1.05238,82.09460,50.00000,0.0000e+000,20.00000,-4.9399e-002,0.66519
574.21600, 68.69250,    -1.05715,82.08548,50.00000,0.0000e+000,20.00000,-4.9368e-002,0.66409
576.03601, 68.87250,    -1.06396,82.07485,50.00000,0.0000e+000,20.00000,-4.9858e-002,0.66299
577.85797, 69.05250,    -1.06911,82.06492,50.00000,0.0000e+000,20.00000,-5.0144e-002,0.66188
579.67297, 69.23250,    -1.07231,82.05467,50.00000,0.0000e+000,20.00000,-5.0210e-002,0.66079
581.46002, 69.41250,    -1.07524,82.04522,50.00000,0.0000e+000,20.00000,-5.0685e-002,0.65971
583.26202, 69.59250,    -1.07683,82.03800,50.00000,0.0000e+000,20.00000,-5.1133e-002,0.65864
585.05402, 69.77250,    -1.07883,82.02999,50.00000,0.0000e+000,20.00000,-5.1918e-002,0.65757
586.89001, 69.95250,    -1.08527,82.02073,50.00000,0.0000e+000,20.00000,-5.3150e-002,0.65648
588.71002, 70.13250,    -1.09145,82.01188,50.00000,0.0000e+000,20.00000,-5.4119e-002,0.65541
590.54102, 70.31250,    -1.09569,82.00403,50.00000,0.0000e+000,20.00000,-5.5024e-002,0.65433
592.35101, 70.49250,    -1.09802,81.99515,50.00000,0.0000e+000,20.00000,-5.5634e-002,0.65327
594.15997, 70.67250,    -1.09968,81.98444,50.00000,0.0000e+000,20.00000,-5.6084e-002,0.65222
595.96600, 70.85250,    -1.10028,81.97404,50.00000,0.0000e+000,20.00000,-5.6898e-002,0.65117
597.71600, 71.03250,    -1.09917,81.96514,50.00000,0.0000e+000,20.00000,-5.7929e-002,0.65016
599.49799, 71.21250,    -1.09942,81.95490,50.00000,0.0000e+000,20.00000,-5.9419e-002,0.64914
601.27002, 71.39250,    -1.10116,81.94380,50.00000,0.0000e+000,20.00000,-6.1884e-002,0.64813
603.05798, 71.57250,    -1.10526,81.93242,50.00000,0.0000e+000,20.00000,-6.4165e-002,0.64711
604.86499, 71.75250,    -1.11072,81.92026,50.00000,0.0000e+000,20.00000,-6.5341e-002,0.64608
606.67102, 71.93250,    -1.11636,81.90811,50.00000,0.0000e+000,20.00000,-6.6663e-002,0.64506
608.49103, 72.11250,    -1.12101,81.89643,50.00000,0.0000e+000,20.00000,-6.8590e-002,0.64404
610.33002, 72.29250,    -1.12662,81.88540,50.00000,0.0000e+000,20.00000,-7.0476e-002,0.64301
612.15601, 72.47250,    -1.13143,81.87344,50.00000,0.0000e+000,20.00000,-7.2242e-002,0.64199
613.97400, 72.65250,    -1.13438,81.86046,50.00000,0.0000e+000,20.00000,-7.3863e-002,0.64099
615.78003, 72.83250,    -1.13390,81.84676,50.00000,0.0000e+000,20.00000,-7.5990e-002,0.63999
617.57599, 73.01250,    -1.13253,81.83174,50.00000,0.0000e+000,20.00000,-7.8093e-002,0.63900
619.34497, 73.19250,    -1.13054,81.81546,50.00000,0.0000e+000,20.00000,-8.0051e-002,0.63803
621.09900, 73.37250,    -1.13036,81.79906,50.00000,0.0000e+000,20.00000,-8.1924e-002,0.63708
622.88202, 73.55250,    -1.13291,81.78536,50.00000,0.0000e+000,20.00000,-8.3285e-002,0.63611
624.68701, 73.73250,    -1.13759,81.77170,50.00000,0.0000e+000,20.00000,-8.4952e-002,0.63513
626.49500, 73.91250,    -1.14329,81.75686,50.00000,0.0000e+000,20.00000,-8.7543e-002,0.63416
628.30298, 74.09250,    -1.14768,81.74149,50.00000,0.0000e+000,20.00000,-9.0660e-002,0.63319
630.12598, 74.27250,    -1.15111,81.72473,50.00000,0.0000e+000,20.00000,-9.3337e-002,0.63222
631.93500, 74.45250,    -1.15166,81.70800,50.00000,0.0000e+000,20.00000,-9.5867e-002,0.63126
633.70898, 74.63250,    -1.15167,81.69143,50.00000,0.0000e+000,20.00000,-9.8576e-002,0.63032
635.49902, 74.81250,    -1.15146,81.67388,50.00000,0.0000e+000,20.00000,    -0.10100,0.62938
637.28900, 74.99250,    -1.15101,81.65571,50.00000,0.0000e+000,20.00000,    -0.10308,0.62844
639.09198, 75.17250,    -1.15656,81.63751,50.00000,0.0000e+000,20.00000,    -0.10565,0.62750
640.93597, 75.35250,    -1.16407,81.62030,50.00000,0.0000e+000,20.00000,    -0.10916,0.62654
642.77600, 75.53250,    -1.16907,81.60245,50.00000,0.0000e+000,20.00000,    -0.11278,0.62558
644.61798, 75.71250,    -1.17244,81.58158,50.00000,0.0000e+000,20.00000,    -0.11634,0.62464
646.42902, 75.89250,    -1.17113,81.55914,50.00000,0.0000e+000,20.00000,    -0.12012,0.62371
648.21399, 76.07250,    -1.16876,81.53748,50.00000,0.0000e+000,20.00000,    -0.12395,0.62279
650.00800, 76.25250,    -1.16610,81.51553,50.00000,0.0000e+000,20.00000,    -0.12768,0.62188
651.80402, 76.43250,    -1.16626,81.49231,50.00000,0.0000e+000,20.00000,    -0.13225,0.62097
653.58698, 76.61250,    -1.16713,81.46852,50.00000,0.0000e+000,20.00000,    -0.13692,0.62007
655.38202, 76.79250,    -1.16766,81.44501,50.00000,0.0000e+000,20.00000,    -0.14127,0.61917
657.19098, 76.97250,    -1.16904,81.41938,50.00000,0.0000e+000,20.00000,    -0.14600,0.61826
659.00000, 77.15250,    -1.17319,81.39245,50.00000,0.0000e+000,20.00000,    -0.15155,0.61736
660.80499, 77.33250,    -1.17519,81.36582,50.00000,0.0000e+000,20.00000,    -0.15790,0.61647
662.60797, 77.51250,    -1.17453,81.33821,50.00000,0.0000e+000,20.00000,    -0.16350,0.61558
664.39398, 77.69250,    -1.17334,81.30946,50.00000,0.0000e+000,20.00000,    -0.16869,0.61470
666.16602, 77.87250,    -1.17116,81.27898,50.00000,0.0000e+000,20.00000,    -0.17444,0.61383
667.92603, 78.05250,    -1.16732,81.24858,50.00000,0.0000e+000,20.00000,    -0.18018,0.61297
669.70001, 78.23250,    -1.16558,81.21591,50.00000,0.0000e+000,20.00000,    -0.18648,0.61211
671.49298, 78.41250,    -1.16904,81.18138,50.00000,0.0000e+000,20.00000,    -0.19411,0.61124
673.32098, 78.59250,    -1.17335,81.14739,50.00000,0.0000e+000,20.00000,    -0.20175,0.61036
675.13599, 78.77250,    -1.17664,81.11220,50.00000,0.0000e+000,20.00000,    -0.20873,0.60949
676.94800, 78.95250,    -1.17700,81.07489,50.00000,0.0000e+000,20.00000,    -0.21596,0.60862
678.73798, 79.13250,    -1.17405,81.03455,50.00000,0.0000e+000,20.00000,    -0.22358,0.60777
680.52698, 79.31250,    -1.17393,80.99353,50.00000,0.0000e+000,20.00000,    -0.23122,0.60692
682.34302, 79.49250,    -1.17391,80.95245,50.00000,0.0000e+000,20.00000,    -0.23899,0.60606
684.17999, 79.67250,    -1.17589,80.90970,50.00000,0.0000e+000,20.00000,    -0.24617,0.60520
686.00897, 79.85250,    -1.17780,80.86704,50.00000,0.0000e+000,20.00000,    -0.25317,0.60434
687.81201, 80.03250,    -1.17607,80.82181,50.00000,0.0000e+000,20.00000,    -0.26056,0.60350
689.61603, 80.21250,    -1.17403,80.77067,50.00000,0.0000e+000,20.00000,    -0.26832,0.60266
691.39301, 80.39250,    -1.16932,80.71898,50.00000,0.0000e+000,20.00000,    -0.27583,0.60183
693.16901, 80.57250,    -1.16502,80.66844,50.00000,0.0000e+000,20.00000,    -0.28294,0.60102
694.99200, 80.75250,    -1.16598,80.61551,50.00000,0.0000e+000,20.00000,    -0.28978,0.60018
696.80103, 80.93250,    -1.16802,80.56110,50.00000,0.0000e+000,20.00000,    -0.29456,0.59935
698.63300, 81.11250,    -1.16965,80.50596,50.00000,0.0000e+000,20.00000,    -0.29770,0.59851
700.43903, 81.29250,    -1.17028,80.44920,50.00000,0.0000e+000,20.00000,    -0.30127,0.59769
702.28601, 81.47250,    -1.17356,80.39247,50.00000,0.0000e+000,20.00000,    -0.30478,0.59686
704.20502, 81.65250,    -1.18450,80.33657,50.00000,0.0000e+000,20.00000,    -0.30784,0.59599
706.18500, 81.83250,    -1.19839,80.27819,50.00000,0.0000e+000,20.00000,    -0.31019,0.59511
708.09497, 82.01250,    -1.20173,80.21550,50.00000,0.0000e+000,20.00000,    -0.31043,0.59425
709.94202, 82.19250,    -1.19583,80.15369,50.00000,0.0000e+000,20.00000,    -0.31017,0.59343
711.70898, 82.37250,    -1.18488,80.09300,50.00000,0.0000e+000,20.00000,    -0.30999,0.59265
713.45599, 82.55250,    -1.17458,80.03091,50.00000,0.0000e+000,20.00000,    -0.30899,0.59187
715.18799, 82.73250,    -1.16958,79.97261,50.00000,0.0000e+000,20.00000,    -0.30729,0.59111
716.91602, 82.91250,    -1.16905,79.91958,50.00000,0.0000e+000,20.00000,    -0.30620,0.59035
718.64697, 83.09250,    -1.17228,79.86618,50.00000,0.0000e+000,20.00000,    -0.30625,0.58960
720.40198, 83.27250,    -1.17975,79.81063,50.00000,0.0000e+000,20.00000,    -0.30551,0.58883
722.18500, 83.45250,    -1.18961,79.75662,50.00000,0.0000e+000,20.00000,    -0.30320,0.58806
723.93701, 83.63250,    -1.19882,79.70331,50.00000,0.0000e+000,20.00000,    -0.30008,0.58730
725.69397, 83.81250,    -1.20709,79.65190,50.00000,0.0000e+000,20.00000,    -0.29583,0.58654
727.47101, 83.99250,    -1.21229,79.60079,50.00000,0.0000e+000,20.00000,    -0.29140,0.58578
729.24500, 84.17250,    -1.21551,79.55075,50.00000,0.0000e+000,20.00000,    -0.28713,0.58502
730.99597, 84.35250,    -1.21644,79.50183,50.00000,0.0000e+000,20.00000,    -0.28160,0.58427
732.76501, 84.53250,    -1.21636,79.45361,50.00000,0.0000e+000,20.00000,    -0.27540,0.58352
734.53699, 84.71250,    -1.21805,79.40360,50.00000,0.0000e+000,20.00000,    -0.26835,0.58277
736.33801, 84.89250,    -1.22205,79.34731,50.00000,0.0000e+000,20.00000,    -0.25960,0.58201
738.14600, 85.07250,    -1.22893,79.29224,50.00000,0.0000e+000,20.00000,    -0.24904,0.58125
739.98102, 85.25250,    -1.23691,79.24393,50.00000,0.0000e+000,20.00000,    -0.23815,0.58048
741.83600, 85.43250,    -1.24536,79.19786,50.00000,0.0000e+000,20.00000,    -0.22668,0.57970
743.69800, 85.61250,    -1.25299,79.15090,50.00000,0.0000e+000,20.00000,    -0.21503,0.57893
745.54797, 85.79250,    -1.25651,79.10495,50.00000,0.0000e+000,20.00000,    -0.20292,0.57816
747.37097, 85.97250,    -1.26114,79.05963,50.00000,0.0000e+000,20.00000,    -0.19098,0.57741
749.20203, 86.15250,    -1.26720,79.01716,50.00000,0.0000e+000,20.00000,    -0.17991,0.57665
751.00598, 86.33250,    -1.27347,78.97965,50.00000,0.0000e+000,20.00000,    -0.16932,0.57591
752.76501, 86.51250,    -1.28409,78.95035,50.00000,0.0000e+000,20.00000,    -0.15813,0.57519
754.52197, 86.69250,    -1.29730,78.92865,50.00000,0.0000e+000,20.00000,    -0.14486,0.57447
756.28601, 86.87250,    -1.30994,78.91120,50.00000,0.0000e+000,20.00000,    -0.13194,0.57376
758.05200, 87.05250,    -1.31925,78.89640,50.00000,0.0000e+000,20.00000,    -0.12058,0.57304
759.84900, 87.23250,    -1.32835,78.88442,50.00000,0.0000e+000,20.00000,    -0.10992,0.57231
761.75000, 87.41250,    -1.34593,78.87502,50.00000,0.0000e+000,20.00000,-9.9530e-002,0.57155
763.65503, 87.59250,    -1.35954,78.86783,50.00000,0.0000e+000,20.00000,-8.9382e-002,0.57078
765.50201, 87.77250,    -1.36399,78.86141,50.00000,0.0000e+000,20.00000,-7.9418e-002,0.57004
767.31598, 87.95250,    -1.36279,78.85311,50.00000,0.0000e+000,20.00000,-7.0008e-002,0.56932
769.10901, 88.13250,    -1.35938,78.84349,50.00000,0.0000e+000,20.00000,-6.1688e-002,0.56860
770.90100, 88.31250,    -1.35821,78.83484,50.00000,0.0000e+000,20.00000,-5.5570e-002,0.56789
772.69000, 88.49250,    -1.35894,78.82775,50.00000,0.0000e+000,20.00000,-5.2197e-002,0.56718
774.46899, 88.67250,    -1.36021,78.81942,50.00000,0.0000e+000,20.00000,-5.0300e-002,0.56648
776.25897, 88.85250,    -1.36309,78.81123,50.00000,0.0000e+000,20.00000,-4.8969e-002,0.56578
778.04901, 89.03250,    -1.36598,78.80454,50.00000,0.0000e+000,20.00000,-4.8370e-002,0.56507
779.89600, 89.21250,    -1.37307,78.79557,50.00000,0.0000e+000,20.00000,-4.8522e-002,0.56435
781.70697, 89.39250,    -1.37911,78.78667,50.00000,0.0000e+000,20.00000,-4.9210e-002,0.56364
783.49402, 89.57250,    -1.38100,78.77751,50.00000,0.0000e+000,20.00000,-5.0223e-002,0.56295
785.26703, 89.75250,    -1.38266,78.76879,50.00000,0.0000e+000,20.00000,-5.0482e-002,0.56226
787.06403, 89.93250,    -1.38593,78.76070,50.00000,0.0000e+000,20.00000,-5.0648e-002,0.56157
788.87701, 90.11250,    -1.39138,78.75249,50.00000,0.0000e+000,20.00000,-5.1498e-002,0.56087
790.67200, 90.29250,    -1.39443,78.74258,50.00000,0.0000e+000,20.00000,-5.2945e-002,0.56018
792.47101, 90.47250,    -1.39686,78.73144,50.00000,0.0000e+000,20.00000,-5.3850e-002,0.55949
794.25598, 90.65250,    -1.39873,78.72109,50.00000,0.0000e+000,20.00000,-5.4488e-002,0.55880
796.09900, 90.83250,    -1.40671,78.71084,50.00000,0.0000e+000,20.00000,-5.5366e-002,0.55810
798.00800, 91.01250,    -1.42315,78.70054,50.00000,0.0000e+000,20.00000,-5.6075e-002,0.55737
799.90100, 91.19250,    -1.43311,78.69046,50.00000,0.0000e+000,20.00000,-5.6822e-002,0.55665
801.74402, 91.37250,    -1.43547,78.68040,50.00000,0.0000e+000,20.00000,-5.7153e-002,0.55595
803.54102, 91.55250,    -1.43163,78.67133,50.00000,0.0000e+000,20.00000,-5.7389e-002,0.55527
805.33398, 91.73250,    -1.42905,78.66157,50.00000,0.0000e+000,20.00000,-5.8015e-002,0.55460
807.12299, 91.91250,    -1.42921,78.64971,50.00000,0.0000e+000,20.00000,-5.8992e-002,0.55393
808.88300, 92.09250,    -1.42872,78.63717,50.00000,0.0000e+000,20.00000,-5.9095e-002,0.55327
810.63397, 92.27250,    -1.42788,78.62570,50.00000,0.0000e+000,20.00000,-5.8520e-002,0.55261
812.37201, 92.45250,    -1.42742,78.61467,50.00000,0.0000e+000,20.00000,-5.8361e-002,0.55196
814.15302, 92.63250,    -1.43270,78.60493,50.00000,0.0000e+000,20.00000,-5.8759e-002,0.55130
815.98297, 92.81250,    -1.44348,78.59383,50.00000,0.0000e+000,20.00000,-5.9013e-002,0.55062
817.75897, 92.99250,    -1.44861,78.58204,50.00000,0.0000e+000,20.00000,-5.9128e-002,0.54996
819.51703, 93.17250,    -1.44775,78.57155,50.00000,0.0000e+000,20.00000,-5.8928e-002,0.54931
821.29199, 93.35250,    -1.44981,78.56180,50.00000,0.0000e+000,20.00000,-5.8934e-002,0.54865
823.07599, 93.53250,    -1.45519,78.55159,50.00000,0.0000e+000,20.00000,-5.8924e-002,0.54799
824.86401, 93.71250,    -1.46016,78.53992,50.00000,0.0000e+000,20.00000,-5.8655e-002,0.54733
826.67401, 93.89250,    -1.46549,78.52965,50.00000,0.0000e+000,20.00000,-5.8234e-002,0.54667
828.45801, 94.07250,    -1.47231,78.52059,50.00000,0.0000e+000,20.00000,-5.7599e-002,0.54602
830.24701, 94.25250,    -1.47707,78.51100,50.00000,0.0000e+000,20.00000,-5.6770e-002,0.54536
832.05701, 94.43250,    -1.48150,78.49944,50.00000,0.0000e+000,20.00000,-5.6878e-002,0.54470
833.89203, 94.61250,    -1.48899,78.48809,50.00000,0.0000e+000,20.00000,-5.6985e-002,0.54403
835.68402, 94.79250,    -1.49402,78.47741,50.00000,0.0000e+000,20.00000,-5.6636e-002,0.54338
837.48102, 94.97250,    -1.49859,78.46792,50.00000,0.0000e+000,20.00000,-5.6501e-002,0.54273
839.28101, 95.15250,    -1.50385,78.45869,50.00000,0.0000e+000,20.00000,-5.6448e-002,0.54208
841.12201, 95.33250,    -1.51036,78.44934,50.00000,0.0000e+000,20.00000,-5.6739e-002,0.54141
842.98102, 95.51250,    -1.51879,78.43892,50.00000,0.0000e+000,20.00000,-5.6337e-002,0.54074
844.81500, 95.69250,    -1.52559,78.42782,50.00000,0.0000e+000,20.00000,-5.5902e-002,0.54008
846.63000, 95.87250,    -1.53010,78.41814,50.00000,0.0000e+000,20.00000,-5.5377e-002,0.53943
848.42603, 96.05250,    -1.52940,78.41012,50.00000,0.0000e+000,20.00000,-5.4330e-002,0.53878
850.21600, 96.23250,    -1.52953,78.40026,50.00000,0.0000e+000,20.00000,-5.3555e-002,0.53814
852.01001, 96.41250,    -1.53268,78.38901,50.00000,0.0000e+000,20.00000,-5.2721e-002,0.53750
853.88397, 96.59250,    -1.54420,78.37836,50.00000,0.0000e+000,20.00000,-5.1853e-002,0.53683
855.76398, 96.77250,    -1.55901,78.36808,50.00000,0.0000e+000,20.00000,-5.0982e-002,0.53616
857.66998, 96.95250,    -1.57076,78.35849,50.00000,0.0000e+000,20.00000,-5.0652e-002,0.53548
859.49701, 97.13250,    -1.56995,78.34760,50.00000,0.0000e+000,20.00000,-4.9772e-002,0.53483
861.29401, 97.31250,    -1.56628,78.33720,50.00000,0.0000e+000,20.00000,-4.8158e-002,0.53419
863.07001, 97.49250,    -1.56227,78.32811,50.00000,0.0000e+000,20.00000,-4.6748e-002,0.53356
864.84198, 97.67250,    -1.56186,78.32043,50.00000,0.0000e+000,20.00000,-4.6063e-002,0.53293
866.60901, 97.85250,    -1.56377,78.31503,50.00000,0.0000e+000,20.00000,-4.5003e-002,0.53231
868.40100, 98.03250,    -1.56744,78.30690,50.00000,0.0000e+000,20.00000,-4.3333e-002,0.53167
870.21503, 98.21250,    -1.57378,78.29831,50.00000,0.0000e+000,20.00000,-4.1825e-002,0.53103
872.05103, 98.39250,    -1.58364,78.29053,50.00000,0.0000e+000,20.00000,-4.0010e-002,0.53039
873.86603, 98.57250,    -1.58679,78.28402,50.00000,0.0000e+000,20.00000,-3.7840e-002,0.52975
875.64203, 98.75250,    -1.58711,78.27622,50.00000,0.0000e+000,20.00000,-3.6109e-002,0.52912
877.43298, 98.93250,    -1.58718,78.26955,50.00000,0.0000e+000,20.00000,-3.4248e-002,0.52849
879.21399, 99.11250,    -1.58865,78.26533,50.00000,0.0000e+000,20.00000,-3.2705e-002,0.52787
880.97302, 99.29250,    -1.58985,78.25967,50.00000,0.0000e+000,20.00000,-3.1670e-002,0.52725
882.74103, 99.47250,    -1.59155,78.25217,50.00000,0.0000e+000,20.00000,-3.0541e-002,0.52663
884.53400, 99.65250,    -1.59527,78.24726,50.00000,0.0000e+000,20.00000,-3.0014e-002,0.52601
886.33502, 99.83250,    -1.60161,78.24428,50.00000,0.0000e+000,20.00000,-2.8741e-002,0.52538
888.15399,100.01250,    -1.60833,78.23870,50.00000,0.0000e+000,20.00000,-2.6987e-002,0.52474
889.93402,100.19250,    -1.60923,78.23415,50.00000,0.0000e+000,20.00000,-2.6097e-002,0.52412
891.69098,100.37250,    -1.60559,78.23172,50.00000,0.0000e+000,20.00000,-2.5737e-002,0.52351
893.45001,100.55250,    -1.60434,78.22855,50.00000,0.0000e+000,20.00000,-2.4908e-002,0.52290
895.24597,100.73250,    -1.60894,78.22479,50.00000,0.0000e+000,20.00000,-2.4175e-002,0.52227
897.04999,100.91250,    -1.61495,78.21997,50.00000,0.0000e+000,20.00000,-2.4193e-002,0.52164
898.86401,101.09250,    -1.62081,78.21447,50.00000,0.0000e+000,20.00000,-2.3935e-002,0.52101
900.67603,101.27250,    -1.62591,78.21030,50.00000,0.0000e+000,20.00000,-2.3303e-002,0.52039
902.51300,101.45250,    -1.63049,78.20676,50.00000,0.0000e+000,20.00000,-2.2832e-002,0.51975
904.32703,101.63250,    -1.63267,78.20360,50.00000,0.0000e+000,20.00000,-2.2696e-002,0.51912
906.11700,101.81250,    -1.63270,78.20137,50.00000,0.0000e+000,20.00000,-2.1918e-002,0.51850
907.92999,101.99250,    -1.63208,78.19713,50.00000,0.0000e+000,20.00000,-2.1115e-002,0.51787
909.75098,102.17250,    -1.63516,78.19166,50.00000,0.0000e+000,20.00000,-2.0653e-002,0.51724
911.55103,102.35250,    -1.63688,78.18714,50.00000,0.0000e+000,20.00000,-2.0490e-002,0.51662
913.37402,102.53250,    -1.63758,78.18264,50.00000,0.0000e+000,20.00000,-2.0394e-002,0.51599
915.20502,102.71250,    -1.64163,78.17826,50.00000,0.0000e+000,20.00000,-1.9898e-002,0.51536
917.00897,102.89250,    -1.64171,78.17389,50.00000,0.0000e+000,20.00000,-1.9386e-002,0.51473
918.78900,103.07250,    -1.63788,78.16894,50.00000,0.0000e+000,20.00000,-1.8997e-002,0.51412
920.63098,103.25250,    -1.64217,78.16465,50.00000,0.0000e+000,20.00000,-1.9088e-002,0.51348
922.46997,103.43250,    -1.64899,78.16237,50.00000,0.0000e+000,20.00000,-1.8762e-002,0.51285
924.26202,103.61250,    -1.64349,78.15981,50.00000,0.0000e+000,20.00000,-1.7942e-002,0.51223
926.06097,103.79250,    -1.64172,78.15774,50.00000,0.0000e+000,20.00000,-1.7032e-002,0.51161
927.87799,103.97250,    -1.64220,78.15674,50.00000,0.0000e+000,20.00000,-1.6164e-002,0.51099
929.70203,104.15250,    -1.64334,78.15473,50.00000,0.0000e+000,20.00000,-1.5841e-002,0.51036
931.52100,104.33250,    -1.64546,78.15127,50.00000,0.0000e+000,20.00000,-1.5489e-002,0.50973
933.33398,104.51250,    -1.64588,78.14861,50.00000,0.0000e+000,20.00000,-1.4936e-002,0.50911
935.14099,104.69250,    -1.64553,78.14488,50.00000,0.0000e+000,20.00000,-1.3956e-002,0.50848
936.94501,104.87250,    -1.64332,78.14195,50.00000,0.0000e+000,20.00000,-1.3302e-002,0.50786
938.75598,105.05250,    -1.64259,78.13810,50.00000,0.0000e+000,20.00000,-1.2584e-002,0.50724
940.56299,105.23250,    -1.64098,78.13553,50.00000,0.0000e+000,20.00000,-1.2156e-002,0.50662
942.37701,105.41250,    -1.64315,78.13603,50.00000,0.0000e+000,20.00000,-1.1408e-002,0.50599
944.16699,105.59250,    -1.64131,78.13594,50.00000,0.0000e+000,20.00000,-1.0703e-002,0.50538
945.94702,105.77250,    -1.63657,78.13379,50.00000,0.0000e+000,20.00000,-1.0454e-002,0.50476
947.74597,105.95250,    -1.63375,78.13046,50.00000,0.0000e+000,20.00000,-1.0397e-002,0.50415
949.54303,106.13250,    -1.63280,78.12720,50.00000,0.0000e+000,20.00000,-1.0078e-002,0.50353
951.33002,106.31250,    -1.63263,78.12452,50.00000,0.0000e+000,20.00000,-9.8237e-003,0.50291
953.13000,106.49250,    -1.63273,78.12374,50.00000,0.0000e+000,20.00000,-8.6126e-003,0.50229
954.94000,106.67250,    -1.63403,78.12157,50.00000,0.0000e+000,20.00000,-7.9352e-003,0.50167
956.76202,106.85250,    -1.63579,78.11930,50.00000,0.0000e+000,20.00000,-7.7150e-003,0.50104
958.56000,107.03250,    -1.63589,78.11843,50.00000,0.0000e+000,20.00000,-7.4012e-003,0.50042
960.37097,107.21250,    -1.63477,78.11833,50.00000,0.0000e+000,20.00000,-8.0926e-003,0.49980
962.17700,107.39250,    -1.63448,78.11892,50.00000,0.0000e+000,20.00000,-8.7033e-003,0.49917
963.98901,107.57250,    -1.63471,78.11872,50.00000,0.0000e+000,20.00000,-8.5463e-003,0.49855
965.78302,107.75250,    -1.63163,78.11752,50.00000,0.0000e+000,20.00000,-7.6528e-003,0.49793
967.57800,107.93250,    -1.63049,78.11525,50.00000,0.0000e+000,20.00000,-6.7359e-003,0.49731
969.39398,108.11250,    -1.62947,78.11332,50.00000,0.0000e+000,20.00000,-5.7369e-003,0.49668
971.18500,108.29250,    -1.62982,78.11369,50.00000,0.0000e+000,20.00000,-5.2097e-003,0.49607
972.98798,108.47250,    -1.62926,78.11380,50.00000,0.0000e+000,20.00000,-4.6963e-003,0.49544
974.78198,108.65250,    -1.62778,78.11088,50.00000,0.0000e+000,20.00000,-4.4224e-003,0.49482
976.59302,108.83250,    -1.62701,78.10896,50.00000,0.0000e+000,20.00000,-4.5552e-003,0.49420
978.43903,109.01250,    -1.63195,78.10664,50.00000,0.0000e+000,20.00000,-4.6764e-003,0.49356
980.23901,109.19250,    -1.63070,78.10458,50.00000,0.0000e+000,20.00000,-5.2084e-003,0.49294
982.03101,109.37250,    -1.62725,78.10307,50.00000,0.0000e+000,20.00000,-5.4139e-003,0.49232
983.84900,109.55250,    -1.62915,78.10300,50.00000,0.0000e+000,20.00000,-4.6244e-003,0.49169
985.68597,109.73250,    -1.63330,78.10307,50.00000,0.0000e+000,20.00000,-5.4825e-003,0.49105
987.50299,109.91250,    -1.63047,78.10362,50.00000,0.0000e+000,20.00000,-4.1660e-003,0.49042
989.29498,110.09250,    -1.62735,78.10473,50.00000,0.0000e+000,20.00000,-2.5965e-003,0.48980
991.09399,110.27250,    -1.62560,78.10494,50.00000,0.0000e+000,20.00000,-2.0196e-003,0.48917
992.87903,110.45250,    -1.62335,78.10368,50.00000,0.0000e+000,20.00000,-3.1563e-003,0.48855
994.67999,110.63250,    -1.62041,78.10197,50.00000,0.0000e+000,20.00000,-6.6255e-003,0.48793
996.49701,110.81250,    -1.62341,78.10137,50.00000,0.0000e+000,20.00000,-5.2204e-003,0.48729
998.29102,110.99250,    -1.62176,78.10000,50.00000,0.0000e+000,20.00000,-5.4797e-006,0.48667
998.40002,111.00250,    -1.62189,78.10000,50.00000,0.0000e+000,20.00000, 1.3311e-009,0.48663