File: book/some_content/TG_ExpDat_CEM_I_D28; 16-1-2025-2.csv
#FILE:                       ,CEM_I_D28; 16-1-2025.ngb-ds3
#FORMAT:                     ,NETZSCH5
#IDENTITY:                   ,geoplolymer paste
#DECIMAL:                    ,POINT
#SEPARATOR:                  ,COMMA
#MTYPE:                      ,DSC
#INSTRUMENT:                 ,Microlab TU Delft
#PROJECT:                    ,
#DATE/TIME:                  ,16/01/2025 5:36:43 PM
#CORR. FILE:                 ,Blank with cover; 13-1-2025.ngb-bs3
#LABORATORY:                 ,TU Delft Micro Lab
#OPERATOR:                   ,Ahmed
#REMARK:                     ,under Argon atmosphere, 10K/min
#SAMPLE:                     ,CEMID28;16-1-2025
#SAMPLE MASS /mg:            ,39
#MATERIAL:                   ,Geopolymer paste
#REFERENCE:                  ,blank
#REFERENCE MASS /mg:         ,0
#TYPE OF CRUCIBLE:           ,DSC/TG pan Al2O3
#SAMPLE CRUCIBLE MASS /mg:   ,0
#REFERENCE CRUCIBLE MASS /mg:,0
#CORR. CODE:                 ,020
#EXO:                        ,-1
#RANGE:                      ,40/10.0(K/min)/1000
#SEGMENT:                    ,S2/2

##Temp./øC,Time/min,DSC/(mW/mg),Mass/%,Gas Flow(purge1)/(ml/min),Gas Flow(purge2)/(ml/min),Gas Flow(protective)/(ml/min),DTG/(%/min),Sensit./(uV/mW)
 43.27700, 17.96500,-3.1030e-002,95.05114,50.00000,0.0000e+000,20.00000,-9.4777e-002,1.22242
 43.31300, 18.14000,-3.2904e-002,95.03634,50.00000,0.0000e+000,20.00000,-8.2489e-002,1.22237
 43.41200, 18.31500,-3.4044e-002,95.02738,50.00000,0.0000e+000,20.00000,-6.9966e-002,1.22224
 43.59300, 18.49000,-3.4403e-002,95.02275,50.00000,0.0000e+000,20.00000,-5.7167e-002,1.22199
 43.86000, 18.66500,-3.4125e-002,95.02056,50.00000,0.0000e+000,20.00000,-4.4760e-002,1.22162
 44.25300, 18.84000,-3.2746e-002,95.02016,50.00000,0.0000e+000,20.00000,-3.2602e-002,1.22108
 44.70600, 19.01500,-3.0792e-002,95.02265,50.00000,0.0000e+000,20.00000,-2.0926e-002,1.22045
 45.30800, 19.19000,-2.7733e-002,95.02759,50.00000,0.0000e+000,20.00000,-1.1265e-002,1.21962
 45.99200, 19.36500,-2.3950e-002,95.03474,50.00000,0.0000e+000,20.00000,-4.4338e-003,1.21868
 46.79400, 19.54000,-1.9441e-002,95.04258,50.00000,0.0000e+000,20.00000, 1.2534e-003,1.21758
 47.74200, 19.71500,-1.4460e-002,95.05060,50.00000,0.0000e+000,20.00000, 5.7818e-003,1.21627
 48.81800, 19.89000,-8.7121e-003,95.06053,50.00000,0.0000e+000,20.00000, 7.6838e-003,1.21479
 50.02000, 20.06500,-2.4188e-003,95.07062,50.00000,0.0000e+000,20.00000, 7.0361e-003,1.21313
 51.33000, 20.24000, 4.4089e-003,95.07907,50.00000,0.0000e+000,20.00000, 4.0863e-003,1.21133
 52.75900, 20.41500, 1.1420e-002,95.08632,50.00000,0.0000e+000,20.00000,-1.8316e-003,1.20936
 54.29900, 20.59000, 1.8295e-002,95.09329,50.00000,0.0000e+000,20.00000,-9.8207e-003,1.20724
 55.95200, 20.76500, 2.5732e-002,95.10017,50.00000,0.0000e+000,20.00000,-2.0123e-002,1.20497
 57.70800, 20.94000, 3.3592e-002,95.10337,50.00000,0.0000e+000,20.00000,-3.3676e-002,1.20255
 59.56200, 21.11500, 4.1391e-002,95.09990,50.00000,0.0000e+000,20.00000,-5.0886e-002,1.20000
 61.54700, 21.29000, 4.9508e-002,95.09334,50.00000,0.0000e+000,20.00000,-7.1932e-002,1.19728
 63.60400, 21.46500, 5.7879e-002,95.08585,50.00000,0.0000e+000,20.00000,-9.6544e-002,1.19445
 65.73700, 21.64000, 6.6822e-002,95.07539,50.00000,0.0000e+000,20.00000,    -0.12404,1.19152
 67.98300, 21.81500, 7.5950e-002,95.06281,50.00000,0.0000e+000,20.00000,    -0.15414,1.18844
 70.25300, 21.99000, 8.5705e-002,95.04761,50.00000,0.0000e+000,20.00000,    -0.18919,1.18533
 72.62300, 22.16500, 9.6797e-002,95.02658,50.00000,0.0000e+000,20.00000,    -0.23176,1.18208
 75.08300, 22.34000,     0.10748,94.99818,50.00000,0.0000e+000,20.00000,    -0.27722,1.17871
 77.56800, 22.51500,     0.11974,94.96485,50.00000,0.0000e+000,20.00000,    -0.32610,1.17531
 80.11200, 22.69000,     0.13340,94.92344,50.00000,0.0000e+000,20.00000,    -0.38034,1.17184
 82.72800, 22.86500,     0.14836,94.87203,50.00000,0.0000e+000,20.00000,    -0.43984,1.16826
 85.36600, 23.04000,     0.16437,94.80841,50.00000,0.0000e+000,20.00000,    -0.50489,1.16466
 88.07700, 23.21500,     0.18213,94.73205,50.00000,0.0000e+000,20.00000,    -0.57636,1.16097
 90.82000, 23.39000,     0.20155,94.64376,50.00000,0.0000e+000,20.00000,    -0.65264,1.15724
 93.59700, 23.56500,     0.22321,94.54865,50.00000,0.0000e+000,20.00000,    -0.73256,1.15346
 96.39800, 23.74000,     0.24738,94.44017,50.00000,0.0000e+000,20.00000,    -0.81491,1.14966
 99.20400, 23.91500,     0.27412,94.30444,50.00000,0.0000e+000,20.00000,    -0.89688,1.14585
102.05200, 24.09000,     0.30469,94.14812,50.00000,0.0000e+000,20.00000,    -0.97524,1.14199
104.88400, 24.26500,     0.34008,93.98374,50.00000,0.0000e+000,20.00000,    -1.04658,1.13816
107.71500, 24.44000,     0.37984,93.80082,50.00000,0.0000e+000,20.00000,    -1.10757,1.13434
110.55400, 24.61500,     0.42444,93.59441,50.00000,0.0000e+000,20.00000,    -1.15789,1.13051
113.38300, 24.79000,     0.47247,93.36195,50.00000,0.0000e+000,20.00000,    -1.19880,1.12671
116.18400, 24.96500,     0.52400,93.10440,50.00000,0.0000e+000,20.00000,    -1.23169,1.12294
119.01000, 25.14000,     0.57631,92.82458,50.00000,0.0000e+000,20.00000,    -1.25752,1.11915
121.82000, 25.31500,     0.62610,92.52750,50.00000,0.0000e+000,20.00000,    -1.27934,1.11538
124.59400, 25.49000,     0.67132,92.21650,50.00000,0.0000e+000,20.00000,    -1.29609,1.11168
127.38900, 25.66500,     0.70904,91.89932,50.00000,0.0000e+000,20.00000,    -1.30295,1.10794
130.15100, 25.84000,     0.73505,91.58347,50.00000,0.0000e+000,20.00000,    -1.30154,1.10426
132.89500, 26.01500,     0.74447,91.28080,50.00000,0.0000e+000,20.00000,    -1.29555,1.10061
135.63901, 26.19000,     0.73163,91.00598,50.00000,0.0000e+000,20.00000,    -1.28472,1.09697
138.37300, 26.36500,     0.70136,90.76292,50.00000,0.0000e+000,20.00000,    -1.26387,1.09335
141.08400, 26.54000,     0.66254,90.54603,50.00000,0.0000e+000,20.00000,    -1.23573,1.08976
143.78000, 26.71500,     0.62230,90.34830,50.00000,0.0000e+000,20.00000,    -1.20262,1.08621
146.47099, 26.89000,     0.58256,90.16532,50.00000,0.0000e+000,20.00000,    -1.16240,1.08266
149.14900, 27.06500,     0.54550,89.99135,50.00000,0.0000e+000,20.00000,    -1.11293,1.07914
151.77901, 27.24000,     0.51006,89.82321,50.00000,0.0000e+000,20.00000,    -1.05835,1.07569
154.42999, 27.41500,     0.47696,89.67043,50.00000,0.0000e+000,20.00000,    -1.00086,1.07222
157.01300, 27.59000,     0.44565,89.52494,50.00000,0.0000e+000,20.00000,    -0.94186,1.06885
159.58400, 27.76500,     0.41657,89.38345,50.00000,0.0000e+000,20.00000,    -0.88336,1.06550
162.11800, 27.94000,     0.38979,89.24704,50.00000,0.0000e+000,20.00000,    -0.83089,1.06220
164.61501, 28.11500,     0.36389,89.12083,50.00000,0.0000e+000,20.00000,    -0.78677,1.05896
167.07300, 28.29000,     0.34014,89.00454,50.00000,0.0000e+000,20.00000,    -0.74947,1.05578
169.53400, 28.46500,     0.31778,88.88240,50.00000,0.0000e+000,20.00000,    -0.71710,1.05260
171.93201, 28.64000,     0.29645,88.75519,50.00000,0.0000e+000,20.00000,    -0.68822,1.04951
174.29700, 28.81500,     0.27590,88.64048,50.00000,0.0000e+000,20.00000,    -0.66143,1.04647
176.66701, 28.99000,     0.25622,88.53411,50.00000,0.0000e+000,20.00000,    -0.63547,1.04343
178.96600, 29.16500,     0.23744,88.42846,50.00000,0.0000e+000,20.00000,    -0.61022,1.04048
181.23199, 29.34000,     0.21999,88.32433,50.00000,0.0000e+000,20.00000,    -0.58784,1.03759
183.48199, 29.51500,     0.20343,88.22612,50.00000,0.0000e+000,20.00000,    -0.56606,1.03472
185.69901, 29.69000,     0.18914,88.12971,50.00000,0.0000e+000,20.00000,    -0.54603,1.03190
187.88901, 29.86500,     0.17589,88.03319,50.00000,0.0000e+000,20.00000,    -0.52615,1.02912
190.03400, 30.04000,     0.16221,87.93988,50.00000,0.0000e+000,20.00000,    -0.50949,1.02640
192.16000, 30.21500,     0.14760,87.85108,50.00000,0.0000e+000,20.00000,    -0.49203,1.02371
194.26900, 30.39000,     0.13216,87.76572,50.00000,0.0000e+000,20.00000,    -0.47222,1.02105
196.33800, 30.56500,     0.11646,87.68506,50.00000,0.0000e+000,20.00000,    -0.45288,1.01845
198.36301, 30.74000,     0.10119,87.60687,50.00000,0.0000e+000,20.00000,    -0.43693,1.01591
200.37500, 30.91500, 8.6483e-002,87.53494,50.00000,0.0000e+000,20.00000,    -0.42137,1.01338
202.36301, 31.09000, 7.2472e-002,87.46961,50.00000,0.0000e+000,20.00000,    -0.40525,1.01090
204.32300, 31.26500, 5.8642e-002,87.40486,50.00000,0.0000e+000,20.00000,    -0.38969,1.00845
206.23900, 31.44000, 4.5617e-002,87.33975,50.00000,0.0000e+000,20.00000,    -0.37514,1.00607
208.15900, 31.61500, 3.3076e-002,87.27745,50.00000,0.0000e+000,20.00000,    -0.36025,1.00368
210.05701, 31.79000, 2.0650e-002,87.21916,50.00000,0.0000e+000,20.00000,    -0.34577,1.00133
211.92999, 31.96500, 9.2231e-003,87.16326,50.00000,0.0000e+000,20.00000,    -0.33284,0.99901
213.78200, 32.14000,-1.6094e-003,87.10889,50.00000,0.0000e+000,20.00000,    -0.32055,0.99672
215.62000, 32.31500,-1.2354e-002,87.05636,50.00000,0.0000e+000,20.00000,    -0.30855,0.99446
217.44701, 32.49000,-2.2043e-002,87.00613,50.00000,0.0000e+000,20.00000,    -0.29692,0.99221
219.25000, 32.66500,-3.1913e-002,86.95659,50.00000,0.0000e+000,20.00000,    -0.28623,0.99000
221.03200, 32.84000,-4.1410e-002,86.90893,50.00000,0.0000e+000,20.00000,    -0.27847,0.98782
222.80701, 33.01500,-5.0432e-002,86.86396,50.00000,0.0000e+000,20.00000,    -0.27124,0.98565
224.57001, 33.19000,-5.9553e-002,86.82050,50.00000,0.0000e+000,20.00000,    -0.26384,0.98350
226.32700, 33.36500,-6.7875e-002,86.77764,50.00000,0.0000e+000,20.00000,    -0.25628,0.98137
228.06300, 33.54000,-7.6192e-002,86.73569,50.00000,0.0000e+000,20.00000,    -0.24968,0.97926
229.79100, 33.71500,-8.3982e-002,86.69271,50.00000,0.0000e+000,20.00000,    -0.24380,0.97717
231.50700, 33.89000,-9.1544e-002,86.64965,50.00000,0.0000e+000,20.00000,    -0.23791,0.97509
233.19299, 34.06500,-9.8752e-002,86.60935,50.00000,0.0000e+000,20.00000,    -0.23238,0.97306
234.90300, 34.24000,    -0.10581,86.57200,50.00000,0.0000e+000,20.00000,    -0.22728,0.97100
236.59599, 34.41500,    -0.11312,86.53585,50.00000,0.0000e+000,20.00000,    -0.22260,0.96897
238.26199, 34.59000,    -0.12015,86.49787,50.00000,0.0000e+000,20.00000,    -0.21831,0.96697
239.94299, 34.76500,    -0.12687,86.45901,50.00000,0.0000e+000,20.00000,    -0.21471,0.96496
241.61400, 34.94000,    -0.13318,86.42103,50.00000,0.0000e+000,20.00000,    -0.21193,0.96297
243.29500, 35.11500,    -0.13959,86.38361,50.00000,0.0000e+000,20.00000,    -0.20888,0.96097
244.96001, 35.29000,    -0.14659,86.34796,50.00000,0.0000e+000,20.00000,    -0.20556,0.95899
246.63200, 35.46500,    -0.15364,86.31211,50.00000,0.0000e+000,20.00000,    -0.20215,0.95701
248.29900, 35.64000,    -0.15971,86.27791,50.00000,0.0000e+000,20.00000,    -0.19836,0.95504
249.98000, 35.81500,    -0.16612,86.24476,50.00000,0.0000e+000,20.00000,    -0.19518,0.95305
251.64200, 35.99000,    -0.17187,86.21166,50.00000,0.0000e+000,20.00000,    -0.19274,0.95110
253.29900, 36.16500,    -0.17725,86.17958,50.00000,0.0000e+000,20.00000,    -0.19089,0.94915
254.95900, 36.34000,    -0.18232,86.14625,50.00000,0.0000e+000,20.00000,    -0.18868,0.94720
256.61499, 36.51500,    -0.18795,86.11358,50.00000,0.0000e+000,20.00000,    -0.18561,0.94527
258.27899, 36.69000,    -0.19309,86.08000,50.00000,0.0000e+000,20.00000,    -0.18269,0.94332
259.93600, 36.86500,    -0.19864,86.04684,50.00000,0.0000e+000,20.00000,    -0.17984,0.94140
261.61099, 37.04000,    -0.20363,86.01618,50.00000,0.0000e+000,20.00000,    -0.17740,0.93945
263.26599, 37.21500,    -0.20924,85.98627,50.00000,0.0000e+000,20.00000,    -0.17503,0.93753
264.91800, 37.39000,    -0.21404,85.95666,50.00000,0.0000e+000,20.00000,    -0.17291,0.93562
266.59299, 37.56500,    -0.21978,85.92670,50.00000,0.0000e+000,20.00000,    -0.17107,0.93369
268.24701, 37.74000,    -0.22483,85.89696,50.00000,0.0000e+000,20.00000,    -0.16904,0.93179
269.91501, 37.91500,    -0.23041,85.86719,50.00000,0.0000e+000,20.00000,    -0.16722,0.92987
271.57800, 38.09000,    -0.23560,85.83808,50.00000,0.0000e+000,20.00000,    -0.16539,0.92797
273.25101, 38.26500,    -0.24059,85.80983,50.00000,0.0000e+000,20.00000,    -0.16377,0.92606
274.91299, 38.44000,    -0.24584,85.78231,50.00000,0.0000e+000,20.00000,    -0.16193,0.92416
276.58099, 38.61500,    -0.25080,85.75482,50.00000,0.0000e+000,20.00000,    -0.15984,0.92227
278.24600, 38.79000,    -0.25591,85.72730,50.00000,0.0000e+000,20.00000,    -0.15858,0.92038
279.94299, 38.96500,    -0.26119,85.70028,50.00000,0.0000e+000,20.00000,    -0.15762,0.91846
281.60101, 39.14000,    -0.26638,85.67290,50.00000,0.0000e+000,20.00000,    -0.15648,0.91659
283.28799, 39.31500,    -0.27106,85.64582,50.00000,0.0000e+000,20.00000,    -0.15556,0.91469
284.97900, 39.49000,    -0.27595,85.61979,50.00000,0.0000e+000,20.00000,    -0.15470,0.91279
286.66299, 39.66500,    -0.28078,85.59396,50.00000,0.0000e+000,20.00000,    -0.15358,0.91091
288.34799, 39.84000,    -0.28512,85.56826,50.00000,0.0000e+000,20.00000,    -0.15260,0.90903
290.02899, 40.01500,    -0.28987,85.54146,50.00000,0.0000e+000,20.00000,    -0.15189,0.90716
291.71600, 40.19000,    -0.29510,85.51467,50.00000,0.0000e+000,20.00000,    -0.15128,0.90528
293.40500, 40.36500,    -0.30019,85.48868,50.00000,0.0000e+000,20.00000,    -0.15067,0.90341
295.09000, 40.54000,    -0.30552,85.46202,50.00000,0.0000e+000,20.00000,    -0.14996,0.90155
296.78101, 40.71500,    -0.31002,85.43495,50.00000,0.0000e+000,20.00000,    -0.14940,0.89968
298.48700, 40.89000,    -0.31553,85.40912,50.00000,0.0000e+000,20.00000,    -0.14880,0.89781
300.19601, 41.06500,    -0.31986,85.38329,50.00000,0.0000e+000,20.00000,    -0.14787,0.89594
301.88699, 41.24000,    -0.32422,85.35640,50.00000,0.0000e+000,20.00000,    -0.14730,0.89409
303.58499, 41.41500,    -0.32849,85.33029,50.00000,0.0000e+000,20.00000,    -0.14685,0.89224
305.28400, 41.59000,    -0.33233,85.30472,50.00000,0.0000e+000,20.00000,    -0.14623,0.89039
306.98300, 41.76500,    -0.33681,85.27850,50.00000,0.0000e+000,20.00000,    -0.14534,0.88855
308.68201, 41.94000,    -0.34070,85.25280,50.00000,0.0000e+000,20.00000,    -0.14466,0.88671
310.37601, 42.11500,    -0.34497,85.22746,50.00000,0.0000e+000,20.00000,    -0.14450,0.88488
312.09299, 42.29000,    -0.34948,85.20240,50.00000,0.0000e+000,20.00000,    -0.14431,0.88304
313.79099, 42.46500,    -0.35455,85.17732,50.00000,0.0000e+000,20.00000,    -0.14381,0.88122
315.50800, 42.64000,    -0.35876,85.15219,50.00000,0.0000e+000,20.00000,    -0.14349,0.87938
317.22299, 42.81500,    -0.36343,85.12779,50.00000,0.0000e+000,20.00000,    -0.14308,0.87755
318.93701, 42.99000,    -0.36783,85.10370,50.00000,0.0000e+000,20.00000,    -0.14243,0.87573
320.64001, 43.16500,    -0.37228,85.07930,50.00000,0.0000e+000,20.00000,    -0.14199,0.87392
322.38300, 43.34000,    -0.37618,85.05542,50.00000,0.0000e+000,20.00000,    -0.14192,0.87208
324.08899, 43.51500,    -0.38024,85.03257,50.00000,0.0000e+000,20.00000,    -0.14181,0.87028
325.82001, 43.69000,    -0.38370,85.00873,50.00000,0.0000e+000,20.00000,    -0.14188,0.86847
327.54599, 43.86500,    -0.38712,84.98347,50.00000,0.0000e+000,20.00000,    -0.14228,0.86666
329.26199, 44.04000,    -0.39050,84.95775,50.00000,0.0000e+000,20.00000,    -0.14271,0.86487
330.98199, 44.21500,    -0.39419,84.93247,50.00000,0.0000e+000,20.00000,    -0.14323,0.86308
332.70001, 44.39000,    -0.39807,84.90702,50.00000,0.0000e+000,20.00000,    -0.14389,0.86129
334.42099, 44.56500,    -0.40140,84.88249,50.00000,0.0000e+000,20.00000,    -0.14460,0.85951
336.13199, 44.74000,    -0.40482,84.85856,50.00000,0.0000e+000,20.00000,    -0.14603,0.85774
337.84299, 44.91500,    -0.40808,84.83390,50.00000,0.0000e+000,20.00000,    -0.14744,0.85598
339.58899, 45.09000,    -0.41145,84.80863,50.00000,0.0000e+000,20.00000,    -0.14880,0.85419
341.28500, 45.26500,    -0.41449,84.78318,50.00000,0.0000e+000,20.00000,    -0.15072,0.85246
343.03299, 45.44000,    -0.41805,84.75728,50.00000,0.0000e+000,20.00000,    -0.15304,0.85068
344.74399, 45.61500,    -0.42128,84.73057,50.00000,0.0000e+000,20.00000,    -0.15444,0.84894
346.46899, 45.79000,    -0.42543,84.70368,50.00000,0.0000e+000,20.00000,    -0.15534,0.84719
348.19901, 45.96500,    -0.42899,84.67701,50.00000,0.0000e+000,20.00000,    -0.15657,0.84544
349.94400, 46.14000,    -0.43306,84.64953,50.00000,0.0000e+000,20.00000,    -0.15838,0.84369
351.69901, 46.31500,    -0.43613,84.62225,50.00000,0.0000e+000,20.00000,    -0.15977,0.84193
353.44199, 46.49000,    -0.43911,84.59382,50.00000,0.0000e+000,20.00000,    -0.16089,0.84018
355.17401, 46.66500,    -0.44155,84.56420,50.00000,0.0000e+000,20.00000,    -0.16200,0.83846
356.89200, 46.84000,    -0.44334,84.53493,50.00000,0.0000e+000,20.00000,    -0.16285,0.83675
358.62000, 47.01500,    -0.44556,84.50544,50.00000,0.0000e+000,20.00000,    -0.16348,0.83504
360.35001, 47.19000,    -0.44854,84.47409,50.00000,0.0000e+000,20.00000,    -0.16397,0.83333
362.06299, 47.36500,    -0.45102,84.44325,50.00000,0.0000e+000,20.00000,    -0.16393,0.83164
363.81100, 47.54000,    -0.45441,84.41418,50.00000,0.0000e+000,20.00000,    -0.16338,0.82993
365.52399, 47.71500,    -0.45788,84.38488,50.00000,0.0000e+000,20.00000,    -0.16292,0.82826
367.24399, 47.89000,    -0.46148,84.35369,50.00000,0.0000e+000,20.00000,    -0.16252,0.82658
368.96399, 48.06500,    -0.46552,84.32214,50.00000,0.0000e+000,20.00000,    -0.16225,0.82491
370.70401, 48.24000,    -0.46999,84.29355,50.00000,0.0000e+000,20.00000,    -0.16185,0.82322
372.44501, 48.41500,    -0.47429,84.26544,50.00000,0.0000e+000,20.00000,    -0.16081,0.82154
374.18100, 48.59000,    -0.47914,84.23705,50.00000,0.0000e+000,20.00000,    -0.15959,0.81987
375.92300, 48.76500,    -0.48411,84.20919,50.00000,0.0000e+000,20.00000,    -0.15814,0.81820
377.65900, 48.94000,    -0.48840,84.18160,50.00000,0.0000e+000,20.00000,    -0.15626,0.81655
379.39899, 49.11500,    -0.49335,84.15473,50.00000,0.0000e+000,20.00000,    -0.15422,0.81489
381.14001, 49.29000,    -0.49818,84.12935,50.00000,0.0000e+000,20.00000,    -0.15261,0.81324
382.86700, 49.46500,    -0.50143,84.10453,50.00000,0.0000e+000,20.00000,    -0.15098,0.81161
384.57199, 49.64000,    -0.50554,84.07923,50.00000,0.0000e+000,20.00000,    -0.14915,0.81000
386.29700, 49.81500,    -0.50977,84.05305,50.00000,0.0000e+000,20.00000,    -0.14672,0.80838
388.02600, 49.99000,    -0.51537,84.02661,50.00000,0.0000e+000,20.00000,    -0.14459,0.80676
389.75101, 50.16500,    -0.52073,84.00083,50.00000,0.0000e+000,20.00000,    -0.14249,0.80515
391.50299, 50.34000,    -0.52726,83.97553,50.00000,0.0000e+000,20.00000,    -0.14003,0.80352
393.24100, 50.51500,    -0.53356,83.95110,50.00000,0.0000e+000,20.00000,    -0.13807,0.80192
394.98901, 50.69000,    -0.53943,83.92755,50.00000,0.0000e+000,20.00000,    -0.13637,0.80030
396.74200, 50.86500,    -0.54520,83.90365,50.00000,0.0000e+000,20.00000,    -0.13468,0.79869
398.47299, 51.04000,    -0.54932,83.87960,50.00000,0.0000e+000,20.00000,    -0.13336,0.79710
400.20300, 51.21500,    -0.55346,83.85632,50.00000,0.0000e+000,20.00000,    -0.13238,0.79552
401.94299, 51.39000,    -0.55728,83.83312,50.00000,0.0000e+000,20.00000,    -0.13164,0.79394
403.66800, 51.56500,    -0.56124,83.80967,50.00000,0.0000e+000,20.00000,    -0.13119,0.79238
405.39899, 51.74000,    -0.56552,83.78705,50.00000,0.0000e+000,20.00000,    -0.13155,0.79081
407.13599, 51.91500,    -0.56956,83.76597,50.00000,0.0000e+000,20.00000,    -0.13283,0.78925
408.85199, 52.09000,    -0.57261,83.74640,50.00000,0.0000e+000,20.00000,    -0.13500,0.78771
410.56799, 52.26500,    -0.57545,83.72633,50.00000,0.0000e+000,20.00000,    -0.13879,0.78618
412.27100, 52.44000,    -0.57920,83.70481,50.00000,0.0000e+000,20.00000,    -0.14392,0.78466
413.98300, 52.61500,    -0.58327,83.68358,50.00000,0.0000e+000,20.00000,    -0.15042,0.78314
415.72501, 52.79000,    -0.58903,83.66238,50.00000,0.0000e+000,20.00000,    -0.15852,0.78160
417.45901, 52.96500,    -0.59397,83.64118,50.00000,0.0000e+000,20.00000,    -0.16836,0.78007
419.19601, 53.14000,    -0.59724,83.61946,50.00000,0.0000e+000,20.00000,    -0.17974,0.77855
420.92899, 53.31500,    -0.59841,83.59624,50.00000,0.0000e+000,20.00000,    -0.19121,0.77703
422.65900, 53.49000,    -0.59682,83.57033,50.00000,0.0000e+000,20.00000,    -0.20296,0.77553
424.40100, 53.66500,    -0.59111,83.54048,50.00000,0.0000e+000,20.00000,    -0.21682,0.77401
426.13199, 53.84000,    -0.58238,83.50862,50.00000,0.0000e+000,20.00000,    -0.23317,0.77252
427.87000, 54.01500,    -0.57138,83.47234,50.00000,0.0000e+000,20.00000,    -0.25004,0.77102
429.59500, 54.19000,    -0.55812,83.43116,50.00000,0.0000e+000,20.00000,    -0.26680,0.76954
431.32599, 54.36500,    -0.54422,83.38635,50.00000,0.0000e+000,20.00000,    -0.28466,0.76806
433.04099, 54.54000,    -0.52875,83.33534,50.00000,0.0000e+000,20.00000,    -0.30361,0.76660
434.75900, 54.71500,    -0.51291,83.27832,50.00000,0.0000e+000,20.00000,    -0.32377,0.76514
436.49399, 54.89000,    -0.49844,83.21556,50.00000,0.0000e+000,20.00000,    -0.34511,0.76367
438.24899, 55.06500,    -0.48429,83.14999,50.00000,0.0000e+000,20.00000,    -0.36699,0.76219
439.98801, 55.24000,    -0.47026,83.08476,50.00000,0.0000e+000,20.00000,    -0.38970,0.76073
441.73901, 55.41500,    -0.45483,83.01589,50.00000,0.0000e+000,20.00000,    -0.41501,0.75927
443.48499, 55.59000,    -0.43900,82.93858,50.00000,0.0000e+000,20.00000,    -0.44089,0.75782
445.22501, 55.76500,    -0.42375,82.85747,50.00000,0.0000e+000,20.00000,    -0.46550,0.75637
446.96301, 55.94000,    -0.40748,82.77612,50.00000,0.0000e+000,20.00000,    -0.49206,0.75494
448.70300, 56.11500,    -0.39242,82.69149,50.00000,0.0000e+000,20.00000,    -0.51751,0.75350
450.44199, 56.29000,    -0.37638,82.60253,50.00000,0.0000e+000,20.00000,    -0.54333,0.75208
452.18301, 56.46500,    -0.36018,82.50987,50.00000,0.0000e+000,20.00000,    -0.56876,0.75066
453.93399, 56.64000,    -0.34431,82.41229,50.00000,0.0000e+000,20.00000,    -0.59248,0.74923
455.67401, 56.81500,    -0.32882,82.31109,50.00000,0.0000e+000,20.00000,    -0.61632,0.74782
457.41400, 56.99000,    -0.31120,82.20660,50.00000,0.0000e+000,20.00000,    -0.64013,0.74642
459.13901, 57.16500,    -0.29217,82.09263,50.00000,0.0000e+000,20.00000,    -0.66176,0.74503
460.87799, 57.34000,    -0.27175,81.96630,50.00000,0.0000e+000,20.00000,    -0.67861,0.74364
462.61200, 57.51500,    -0.25101,81.84381,50.00000,0.0000e+000,20.00000,    -0.69029,0.74225
464.35001, 57.69000,    -0.22869,81.71264,50.00000,0.0000e+000,20.00000,    -0.69409,0.74087
466.08301, 57.86500,    -0.20578,81.57550,50.00000,0.0000e+000,20.00000,    -0.68785,0.73950
467.82001, 58.04000,    -0.18414,81.43692,50.00000,0.0000e+000,20.00000,    -0.67428,0.73813
469.56900, 58.21500,    -0.16229,81.29111,50.00000,0.0000e+000,20.00000,    -0.65757,0.73676
471.30801, 58.39000,    -0.14314,81.14352,50.00000,0.0000e+000,20.00000,    -0.63843,0.73540
473.04599, 58.56500,    -0.12718,80.99448,50.00000,0.0000e+000,20.00000,    -0.61746,0.73404
474.76501, 58.74000,    -0.11585,80.84101,50.00000,0.0000e+000,20.00000,    -0.59503,0.73271
476.50601, 58.91500,    -0.11242,80.69168,50.00000,0.0000e+000,20.00000,    -0.57091,0.73136
478.24301, 59.09000,    -0.11895,80.55214,50.00000,0.0000e+000,20.00000,    -0.54297,0.73002
479.99899, 59.26500,    -0.14546,80.42256,50.00000,0.0000e+000,20.00000,    -0.51395,0.72868
481.75601, 59.44000,    -0.21571,80.31299,50.00000,0.0000e+000,20.00000,    -0.48484,0.72734
483.54001, 59.61500,    -0.34233,80.23811,50.00000,0.0000e+000,20.00000,    -0.45270,0.72598
485.34500, 59.79000,    -0.45979,80.19296,50.00000,0.0000e+000,20.00000,    -0.42020,0.72461
487.14401, 59.96500,    -0.54134,80.16060,50.00000,0.0000e+000,20.00000,    -0.38512,0.72325
488.93301, 60.14000,    -0.59662,80.13354,50.00000,0.0000e+000,20.00000,    -0.34874,0.72191
490.69400, 60.31500,    -0.63558,80.10937,50.00000,0.0000e+000,20.00000,    -0.31236,0.72059
492.45099, 60.49000,    -0.66383,80.08763,50.00000,0.0000e+000,20.00000,    -0.27404,0.71929
494.20499, 60.66500,    -0.68547,80.06739,50.00000,0.0000e+000,20.00000,    -0.23534,0.71798
495.95801, 60.84000,    -0.70188,80.04688,50.00000,0.0000e+000,20.00000,    -0.19898,0.71669
497.70300, 61.01500,    -0.71528,80.02742,50.00000,0.0000e+000,20.00000,    -0.16541,0.71541
499.43201, 61.19000,    -0.72603,80.00899,50.00000,0.0000e+000,20.00000,    -0.13565,0.71414
501.18600, 61.36500,    -0.73644,79.98960,50.00000,0.0000e+000,20.00000,    -0.11408,0.71286
502.90900, 61.54000,    -0.74494,79.97096,50.00000,0.0000e+000,20.00000,    -0.10159,0.71161
504.65500, 61.71500,    -0.75191,79.95511,50.00000,0.0000e+000,20.00000,-9.4647e-002,0.71034
506.39099, 61.89000,    -0.75843,79.94038,50.00000,0.0000e+000,20.00000,-8.9368e-002,0.70909
508.13300, 62.06500,    -0.76480,79.92597,50.00000,0.0000e+000,20.00000,-8.4701e-002,0.70784
509.88699, 62.24000,    -0.77100,79.91240,50.00000,0.0000e+000,20.00000,-8.1202e-002,0.70659
511.63400, 62.41500,    -0.77705,79.90140,50.00000,0.0000e+000,20.00000,-7.8596e-002,0.70534
513.37299, 62.59000,    -0.78088,79.89047,50.00000,0.0000e+000,20.00000,-7.6228e-002,0.70411
515.13000, 62.76500,    -0.78487,79.87904,50.00000,0.0000e+000,20.00000,-7.3677e-002,0.70287
516.87201, 62.94000,    -0.78950,79.86740,50.00000,0.0000e+000,20.00000,-7.1380e-002,0.70165
518.62500, 63.11500,    -0.79376,79.85518,50.00000,0.0000e+000,20.00000,-6.9287e-002,0.70042
520.35400, 63.29000,    -0.79648,79.84378,50.00000,0.0000e+000,20.00000,-6.6772e-002,0.69921
522.10999, 63.46500,    -0.80089,79.83309,50.00000,0.0000e+000,20.00000,-6.4168e-002,0.69800
523.88300, 63.64000,    -0.80766,79.82236,50.00000,0.0000e+000,20.00000,-6.2005e-002,0.69677
525.66302, 63.81500,    -0.81333,79.81398,50.00000,0.0000e+000,20.00000,-6.0169e-002,0.69554
527.44897, 63.99000,    -0.81781,79.80478,50.00000,0.0000e+000,20.00000,-5.8610e-002,0.69432
529.20099, 64.16500,    -0.82043,79.79413,50.00000,0.0000e+000,20.00000,-5.7686e-002,0.69313
530.94397, 64.34000,    -0.82187,79.78249,50.00000,0.0000e+000,20.00000,-5.7412e-002,0.69194
532.68799, 64.51500,    -0.82268,79.77118,50.00000,0.0000e+000,20.00000,-5.6501e-002,0.69076
534.41803, 64.69000,    -0.82378,79.76084,50.00000,0.0000e+000,20.00000,-5.5541e-002,0.68960
536.14502, 64.86500,    -0.82611,79.75018,50.00000,0.0000e+000,20.00000,-5.4703e-002,0.68844
537.86102, 65.04000,    -0.82914,79.73898,50.00000,0.0000e+000,20.00000,-5.3684e-002,0.68729
539.61700, 65.21500,    -0.83254,79.73046,50.00000,0.0000e+000,20.00000,-5.2840e-002,0.68612
541.34100, 65.39000,    -0.83665,79.72344,50.00000,0.0000e+000,20.00000,-5.1723e-002,0.68498
543.08002, 65.56500,    -0.84040,79.71598,50.00000,0.0000e+000,20.00000,-5.0781e-002,0.68383
544.80298, 65.74000,    -0.84374,79.70770,50.00000,0.0000e+000,20.00000,-5.0494e-002,0.68270
546.54901, 65.91500,    -0.84799,79.69921,50.00000,0.0000e+000,20.00000,-4.9954e-002,0.68156
548.28101, 66.09000,    -0.85130,79.68977,50.00000,0.0000e+000,20.00000,-4.8944e-002,0.68043
549.99799, 66.26500,    -0.85330,79.68097,50.00000,0.0000e+000,20.00000,-4.7746e-002,0.67932
551.70099, 66.44000,    -0.85431,79.67326,50.00000,0.0000e+000,20.00000,-4.6778e-002,0.67822
553.41699, 66.61500,    -0.85573,79.66471,50.00000,0.0000e+000,20.00000,-4.5913e-002,0.67711
555.13202, 66.79000,    -0.85900,79.65588,50.00000,0.0000e+000,20.00000,-4.4889e-002,0.67601
556.87500, 66.96500,    -0.86294,79.64815,50.00000,0.0000e+000,20.00000,-4.4218e-002,0.67490
558.62500, 67.14000,    -0.86845,79.64073,50.00000,0.0000e+000,20.00000,-4.4006e-002,0.67379
560.37500, 67.31500,    -0.87369,79.63458,50.00000,0.0000e+000,20.00000,-4.3775e-002,0.67268
562.14398, 67.49000,    -0.87945,79.62802,50.00000,0.0000e+000,20.00000,-4.3559e-002,0.67157
563.92102, 67.66500,    -0.88512,79.62001,50.00000,0.0000e+000,20.00000,-4.3118e-002,0.67045
565.67700, 67.84000,    -0.88779,79.61205,50.00000,0.0000e+000,20.00000,-4.1669e-002,0.66936
567.42603, 68.01500,    -0.88892,79.60481,50.00000,0.0000e+000,20.00000,-4.0541e-002,0.66827
569.15802, 68.19000,    -0.88949,79.59750,50.00000,0.0000e+000,20.00000,-4.0199e-002,0.66720
570.92999, 68.36500,    -0.89436,79.59043,50.00000,0.0000e+000,20.00000,-3.9773e-002,0.66611
572.70398, 68.54000,    -0.89962,79.58312,50.00000,0.0000e+000,20.00000,-3.8750e-002,0.66502
574.48199, 68.71500,    -0.90439,79.57546,50.00000,0.0000e+000,20.00000,-3.8373e-002,0.66393
576.25299, 68.89000,    -0.90822,79.56850,50.00000,0.0000e+000,20.00000,-3.8032e-002,0.66286
578.03302, 69.06500,    -0.91106,79.56220,50.00000,0.0000e+000,20.00000,-3.7333e-002,0.66178
579.78699, 69.24000,    -0.91344,79.55559,50.00000,0.0000e+000,20.00000,-3.7010e-002,0.66072
581.54797, 69.41500,    -0.91359,79.54803,50.00000,0.0000e+000,20.00000,-3.6887e-002,0.65966
583.29199, 69.59000,    -0.91367,79.54328,50.00000,0.0000e+000,20.00000,-3.6395e-002,0.65862
585.01501, 69.76500,    -0.91340,79.53912,50.00000,0.0000e+000,20.00000,-3.5808e-002,0.65759
586.76398, 69.94000,    -0.91592,79.53282,50.00000,0.0000e+000,20.00000,-3.5237e-002,0.65656
588.52002, 70.11500,    -0.92050,79.52595,50.00000,0.0000e+000,20.00000,-3.4801e-002,0.65552
590.27502, 70.29000,    -0.92449,79.52040,50.00000,0.0000e+000,20.00000,-3.4491e-002,0.65449
592.02502, 70.46500,    -0.92651,79.51446,50.00000,0.0000e+000,20.00000,-3.4315e-002,0.65346
593.76501, 70.64000,    -0.92924,79.50747,50.00000,0.0000e+000,20.00000,-3.4293e-002,0.65245
595.50702, 70.81500,    -0.93155,79.50234,50.00000,0.0000e+000,20.00000,-3.4704e-002,0.65144
597.25403, 70.99000,    -0.93309,79.49843,50.00000,0.0000e+000,20.00000,-3.5190e-002,0.65043
598.99597, 71.16500,    -0.93465,79.49200,50.00000,0.0000e+000,20.00000,-3.5185e-002,0.64943
600.75098, 71.34000,    -0.93797,79.48509,50.00000,0.0000e+000,20.00000,-3.5305e-002,0.64842
602.49701, 71.51500,    -0.94095,79.47942,50.00000,0.0000e+000,20.00000,-3.6307e-002,0.64743
604.24799, 71.69000,    -0.94388,79.47425,50.00000,0.0000e+000,20.00000,-3.6809e-002,0.64643
606.00500, 71.86500,    -0.94658,79.46888,50.00000,0.0000e+000,20.00000,-3.6621e-002,0.64544
607.75000, 72.04000,    -0.94920,79.46309,50.00000,0.0000e+000,20.00000,-3.6839e-002,0.64446
609.50299, 72.21500,    -0.95062,79.45661,50.00000,0.0000e+000,20.00000,-3.7775e-002,0.64347
611.25201, 72.39000,    -0.95307,79.44937,50.00000,0.0000e+000,20.00000,-3.8074e-002,0.64250
613.01703, 72.56500,    -0.95606,79.44177,50.00000,0.0000e+000,20.00000,-3.8391e-002,0.64152
614.76599, 72.74000,    -0.95732,79.43354,50.00000,0.0000e+000,20.00000,-3.9608e-002,0.64055
616.51202, 72.91500,    -0.96069,79.42588,50.00000,0.0000e+000,20.00000,-4.0308e-002,0.63958
618.27399, 73.09000,    -0.96294,79.41885,50.00000,0.0000e+000,20.00000,-4.0392e-002,0.63862
620.04199, 73.26500,    -0.96507,79.41197,50.00000,0.0000e+000,20.00000,-4.0991e-002,0.63765
621.78497, 73.44000,    -0.96629,79.40430,50.00000,0.0000e+000,20.00000,-4.1779e-002,0.63670
623.52600, 73.61500,    -0.96684,79.39775,50.00000,0.0000e+000,20.00000,-4.2008e-002,0.63576
625.25598, 73.79000,    -0.96690,79.39144,50.00000,0.0000e+000,20.00000,-4.2314e-002,0.63483
626.98798, 73.96500,    -0.96764,79.38322,50.00000,0.0000e+000,20.00000,-4.2620e-002,0.63389
628.74103, 74.14000,    -0.96889,79.37464,50.00000,0.0000e+000,20.00000,-4.2929e-002,0.63296
630.50403, 74.31500,    -0.97303,79.36731,50.00000,0.0000e+000,20.00000,-4.3442e-002,0.63202
632.27600, 74.49000,    -0.97711,79.35937,50.00000,0.0000e+000,20.00000,-4.4009e-002,0.63108
634.06500, 74.66500,    -0.97976,79.35106,50.00000,0.0000e+000,20.00000,-4.4667e-002,0.63013
635.82501, 74.84000,    -0.98117,79.34373,50.00000,0.0000e+000,20.00000,-4.5060e-002,0.62920
637.58801, 75.01500,    -0.98012,79.33590,50.00000,0.0000e+000,20.00000,-4.5595e-002,0.62828
639.33502, 75.19000,    -0.98101,79.32713,50.00000,0.0000e+000,20.00000,-4.6267e-002,0.62737
641.09302, 75.36500,    -0.98366,79.32041,50.00000,0.0000e+000,20.00000,-4.6896e-002,0.62646
642.83801, 75.54000,    -0.98489,79.31412,50.00000,0.0000e+000,20.00000,-4.7369e-002,0.62555
644.57703, 75.71500,    -0.98484,79.30708,50.00000,0.0000e+000,20.00000,-4.7658e-002,0.62466
646.31598, 75.89000,    -0.98465,79.29949,50.00000,0.0000e+000,20.00000,-4.8129e-002,0.62376
648.04700, 76.06500,    -0.98410,79.29062,50.00000,0.0000e+000,20.00000,-4.9053e-002,0.62288
649.79498, 76.24000,    -0.98557,79.28096,50.00000,0.0000e+000,20.00000,-4.9758e-002,0.62199
651.53101, 76.41500,    -0.98895,79.27041,50.00000,0.0000e+000,20.00000,-5.0248e-002,0.62111
653.29401, 76.59000,    -0.99220,79.26082,50.00000,0.0000e+000,20.00000,-5.1302e-002,0.62022
655.05402, 76.76500,    -0.99551,79.25257,50.00000,0.0000e+000,20.00000,-5.2592e-002,0.61933
656.82300, 76.94000,    -0.99880,79.24297,50.00000,0.0000e+000,20.00000,-5.3335e-002,0.61845
658.59100, 77.11500,    -1.00032,79.23310,50.00000,0.0000e+000,20.00000,-5.4119e-002,0.61757
660.34302, 77.29000,    -1.00189,79.22460,50.00000,0.0000e+000,20.00000,-5.5521e-002,0.61670
662.09198, 77.46500,    -1.00381,79.21684,50.00000,0.0000e+000,20.00000,-5.6339e-002,0.61583
663.84100, 77.64000,    -1.00531,79.20724,50.00000,0.0000e+000,20.00000,-5.6667e-002,0.61497
665.60199, 77.81500,    -1.00647,79.19610,50.00000,0.0000e+000,20.00000,-5.6687e-002,0.61410
667.36200, 77.99000,    -1.00792,79.18545,50.00000,0.0000e+000,20.00000,-5.6675e-002,0.61324
669.10400, 78.16500,    -1.00877,79.17571,50.00000,0.0000e+000,20.00000,-5.6709e-002,0.61240
670.85199, 78.34000,    -1.01125,79.16463,50.00000,0.0000e+000,20.00000,-5.6495e-002,0.61155
672.60400, 78.51500,    -1.01201,79.15267,50.00000,0.0000e+000,20.00000,-5.6697e-002,0.61070
674.35999, 78.69000,    -1.01367,79.14088,50.00000,0.0000e+000,20.00000,-5.6767e-002,0.60986
676.14899, 78.86500,    -1.02062,79.13004,50.00000,0.0000e+000,20.00000,-5.6593e-002,0.60900
677.94702, 79.04000,    -1.02718,79.11907,50.00000,0.0000e+000,20.00000,-5.6308e-002,0.60814
679.68402, 79.21500,    -1.02745,79.10838,50.00000,0.0000e+000,20.00000,-5.6228e-002,0.60732
681.41498, 79.39000,    -1.02664,79.09956,50.00000,0.0000e+000,20.00000,-5.5914e-002,0.60650
683.14899, 79.56500,    -1.02667,79.09120,50.00000,0.0000e+000,20.00000,-5.4771e-002,0.60568
684.88501, 79.74000,    -1.02741,79.08255,50.00000,0.0000e+000,20.00000,-5.3022e-002,0.60486
686.61700, 79.91500,    -1.03025,79.07240,50.00000,0.0000e+000,20.00000,-5.1791e-002,0.60405
688.34302, 80.09000,    -1.03321,79.06245,50.00000,0.0000e+000,20.00000,-5.0580e-002,0.60325
690.09100, 80.26500,    -1.03765,79.05315,50.00000,0.0000e+000,20.00000,-4.9021e-002,0.60244
691.84900, 80.44000,    -1.04234,79.04396,50.00000,0.0000e+000,20.00000,-4.7075e-002,0.60162
693.61902, 80.61500,    -1.04818,79.03465,50.00000,0.0000e+000,20.00000,-4.5099e-002,0.60081
695.37598, 80.79000,    -1.05220,79.02580,50.00000,0.0000e+000,20.00000,-4.3563e-002,0.60000
697.12598, 80.96500,    -1.05514,79.01813,50.00000,0.0000e+000,20.00000,-4.1993e-002,0.59920
698.88098, 81.14000,    -1.05711,79.01072,50.00000,0.0000e+000,20.00000,-4.0541e-002,0.59840
700.63000, 81.31500,    -1.06071,79.00356,50.00000,0.0000e+000,20.00000,-3.9543e-002,0.59761
702.37799, 81.49000,    -1.06427,78.99816,50.00000,0.0000e+000,20.00000,-3.8474e-002,0.59682
704.13397, 81.66500,    -1.06730,78.99336,50.00000,0.0000e+000,20.00000,-3.7123e-002,0.59603
705.89697, 81.84000,    -1.07098,78.98747,50.00000,0.0000e+000,20.00000,-3.5801e-002,0.59523
707.66699, 82.01500,    -1.07504,78.98149,50.00000,0.0000e+000,20.00000,-3.4660e-002,0.59444
709.45502, 82.19000,    -1.07899,78.97587,50.00000,0.0000e+000,20.00000,-3.3636e-002,0.59365
711.20801, 82.36500,    -1.08130,78.97176,50.00000,0.0000e+000,20.00000,-3.2647e-002,0.59287
712.98499, 82.54000,    -1.08326,78.96722,50.00000,0.0000e+000,20.00000,-3.1880e-002,0.59208
714.73102, 82.71500,    -1.08560,78.96169,50.00000,0.0000e+000,20.00000,-3.1062e-002,0.59131
716.49500, 82.89000,    -1.08795,78.95696,50.00000,0.0000e+000,20.00000,-2.9740e-002,0.59054
718.24500, 83.06500,    -1.08750,78.95258,50.00000,0.0000e+000,20.00000,-2.9001e-002,0.58977
719.97101, 83.24000,    -1.08720,78.94773,50.00000,0.0000e+000,20.00000,-2.8524e-002,0.58902
721.75897, 83.41500,    -1.09392,78.94355,50.00000,0.0000e+000,20.00000,-2.8417e-002,0.58824
723.54602, 83.59000,    -1.10202,78.93827,50.00000,0.0000e+000,20.00000,-2.7954e-002,0.58747
725.33899, 83.76500,    -1.10751,78.93294,50.00000,0.0000e+000,20.00000,-2.7195e-002,0.58669
727.09497, 83.94000,    -1.11007,78.92750,50.00000,0.0000e+000,20.00000,-2.6151e-002,0.58594
728.86603, 84.11500,    -1.11061,78.92201,50.00000,0.0000e+000,20.00000,-2.6128e-002,0.58518
730.60498, 84.29000,    -1.10887,78.91600,50.00000,0.0000e+000,20.00000,-2.6346e-002,0.58444
732.31897, 84.46500,    -1.10771,78.90968,50.00000,0.0000e+000,20.00000,-2.6005e-002,0.58371
734.06299, 84.64000,    -1.10640,78.90657,50.00000,0.0000e+000,20.00000,-2.5354e-002,0.58297
735.78497, 84.81500,    -1.10728,78.90287,50.00000,0.0000e+000,20.00000,-2.4760e-002,0.58224
737.53302, 84.99000,    -1.10828,78.89797,50.00000,0.0000e+000,20.00000,-2.4353e-002,0.58151
739.25800, 85.16500,    -1.10868,78.89361,50.00000,0.0000e+000,20.00000,-2.4276e-002,0.58078
741.00201, 85.34000,    -1.10954,78.88965,50.00000,0.0000e+000,20.00000,-2.3984e-002,0.58005
742.72400, 85.51500,    -1.10905,78.88592,50.00000,0.0000e+000,20.00000,-2.3450e-002,0.57933
744.47400, 85.69000,    -1.10974,78.88374,50.00000,0.0000e+000,20.00000,-2.2670e-002,0.57861
746.22699, 85.86500,    -1.11269,78.88030,50.00000,0.0000e+000,20.00000,-2.1363e-002,0.57788
748.00500, 86.04000,    -1.11584,78.87509,50.00000,0.0000e+000,20.00000,-2.0337e-002,0.57715
749.77301, 86.21500,    -1.11446,78.87085,50.00000,0.0000e+000,20.00000,-1.9105e-002,0.57642
751.52600, 86.39000,    -1.11140,78.86725,50.00000,0.0000e+000,20.00000,-1.8631e-002,0.57570
753.26398, 86.56500,    -1.10853,78.86513,50.00000,0.0000e+000,20.00000,-1.8506e-002,0.57499
754.98602, 86.74000,    -1.10542,78.86248,50.00000,0.0000e+000,20.00000,-1.7844e-002,0.57428
756.73297, 86.91500,    -1.10440,78.85851,50.00000,0.0000e+000,20.00000,-1.7596e-002,0.57357
758.49902, 87.09000,    -1.10513,78.85460,50.00000,0.0000e+000,20.00000,-1.7003e-002,0.57286
760.24902, 87.26500,    -1.10592,78.85105,50.00000,0.0000e+000,20.00000,-1.6386e-002,0.57215
762.00897, 87.44000,    -1.10616,78.84801,50.00000,0.0000e+000,20.00000,-1.6619e-002,0.57144
763.77002, 87.61500,    -1.10685,78.84657,50.00000,0.0000e+000,20.00000,-1.6830e-002,0.57073
765.53101, 87.79000,    -1.10629,78.84549,50.00000,0.0000e+000,20.00000,-1.6129e-002,0.57003
767.29700, 87.96500,    -1.10746,78.84336,50.00000,0.0000e+000,20.00000,-1.5676e-002,0.56932
769.09198, 88.14000,    -1.11074,78.84092,50.00000,0.0000e+000,20.00000,-1.5535e-002,0.56861
770.86798, 88.31500,    -1.11212,78.83801,50.00000,0.0000e+000,20.00000,-1.5722e-002,0.56790
772.63397, 88.49000,    -1.11235,78.83616,50.00000,0.0000e+000,20.00000,-1.5910e-002,0.56720
774.38898, 88.66500,    -1.11064,78.83278,50.00000,0.0000e+000,20.00000,-1.5717e-002,0.56651
776.13599, 88.84000,    -1.10908,78.82978,50.00000,0.0000e+000,20.00000,-1.5391e-002,0.56582
777.86499, 89.01500,    -1.10713,78.82857,50.00000,0.0000e+000,20.00000,-1.5686e-002,0.56515
779.62903, 89.19000,    -1.10710,78.82566,50.00000,0.0000e+000,20.00000,-1.5842e-002,0.56446
781.44501, 89.36500,    -1.11550,78.82175,50.00000,0.0000e+000,20.00000,-1.5978e-002,0.56375
783.24597, 89.54000,    -1.12123,78.81964,50.00000,0.0000e+000,20.00000,-1.6596e-002,0.56305
785.00500, 89.71500,    -1.12036,78.81660,50.00000,0.0000e+000,20.00000,-1.6677e-002,0.56236
786.76001, 89.89000,    -1.11827,78.81363,50.00000,0.0000e+000,20.00000,-1.7018e-002,0.56168
788.49799, 90.06500,    -1.11630,78.80981,50.00000,0.0000e+000,20.00000,-1.7614e-002,0.56101
790.22498, 90.24000,    -1.11542,78.80706,50.00000,0.0000e+000,20.00000,-1.8495e-002,0.56035
791.97302, 90.41500,    -1.11508,78.80394,50.00000,0.0000e+000,20.00000,-1.8933e-002,0.55968
793.72900, 90.59000,    -1.11702,78.80159,50.00000,0.0000e+000,20.00000,-1.8870e-002,0.55900
795.46100, 90.76500,    -1.11848,78.79738,50.00000,0.0000e+000,20.00000,-1.9238e-002,0.55834
797.20898, 90.94000,    -1.12080,78.79298,50.00000,0.0000e+000,20.00000,-1.9617e-002,0.55767
798.94897, 91.11500,    -1.12112,78.78961,50.00000,0.0000e+000,20.00000,-1.9814e-002,0.55701
800.66901, 91.29000,    -1.12180,78.78697,50.00000,0.0000e+000,20.00000,-2.0032e-002,0.55636
802.39502, 91.46500,    -1.12030,78.78415,50.00000,0.0000e+000,20.00000,-2.0075e-002,0.55571
804.11200, 91.64000,    -1.11995,78.78179,50.00000,0.0000e+000,20.00000,-1.9833e-002,0.55506
805.83600, 91.81500,    -1.12105,78.77717,50.00000,0.0000e+000,20.00000,-1.9601e-002,0.55441
807.58801, 91.99000,    -1.12567,78.77172,50.00000,0.0000e+000,20.00000,-1.9498e-002,0.55375
809.38098, 92.16500,    -1.13245,78.76692,50.00000,0.0000e+000,20.00000,-1.9498e-002,0.55308
811.13300, 92.34000,    -1.13535,78.76338,50.00000,0.0000e+000,20.00000,-1.9698e-002,0.55242
812.89099, 92.51500,    -1.13614,78.76005,50.00000,0.0000e+000,20.00000,-1.9760e-002,0.55177
814.65503, 92.69000,    -1.13714,78.75714,50.00000,0.0000e+000,20.00000,-1.9754e-002,0.55111
816.39801, 92.86500,    -1.13705,78.75307,50.00000,0.0000e+000,20.00000,-1.9741e-002,0.55046
818.14502, 93.04000,    -1.13679,78.74863,50.00000,0.0000e+000,20.00000,-1.9866e-002,0.54981
819.90802, 93.21500,    -1.13875,78.74576,50.00000,0.0000e+000,20.00000,-1.9830e-002,0.54916
821.66803, 93.39000,    -1.14120,78.74347,50.00000,0.0000e+000,20.00000,-2.0022e-002,0.54851
823.40802, 93.56500,    -1.14190,78.74113,50.00000,0.0000e+000,20.00000,-1.9860e-002,0.54787
825.16998, 93.74000,    -1.14228,78.73814,50.00000,0.0000e+000,20.00000,-1.9539e-002,0.54722
826.92102, 93.91500,    -1.14348,78.73547,50.00000,0.0000e+000,20.00000,-1.9395e-002,0.54658
828.68103, 94.09000,    -1.14462,78.73208,50.00000,0.0000e+000,20.00000,-1.8969e-002,0.54593
830.43799, 94.26500,    -1.14597,78.72896,50.00000,0.0000e+000,20.00000,-1.8380e-002,0.54529
832.18402, 94.44000,    -1.14584,78.72467,50.00000,0.0000e+000,20.00000,-1.8251e-002,0.54465
833.94202, 94.61500,    -1.14593,78.72039,50.00000,0.0000e+000,20.00000,-1.8377e-002,0.54401
835.71399, 94.79000,    -1.14872,78.71687,50.00000,0.0000e+000,20.00000,-1.8301e-002,0.54337
837.48499, 94.96500,    -1.15163,78.71410,50.00000,0.0000e+000,20.00000,-1.8493e-002,0.54273
839.25897, 95.14000,    -1.15246,78.71113,50.00000,0.0000e+000,20.00000,-1.8795e-002,0.54208
840.99103, 95.31500,    -1.14942,78.70822,50.00000,0.0000e+000,20.00000,-1.9080e-002,0.54146
842.76501, 95.49000,    -1.14890,78.70475,50.00000,0.0000e+000,20.00000,-1.9571e-002,0.54082
844.56201, 95.66500,    -1.15415,78.70001,50.00000,0.0000e+000,20.00000,-2.0064e-002,0.54017
846.32397, 95.84000,    -1.15584,78.69619,50.00000,0.0000e+000,20.00000,-2.0246e-002,0.53954
848.08099, 96.01500,    -1.15468,78.69504,50.00000,0.0000e+000,20.00000,-1.9711e-002,0.53890
849.82001, 96.19000,    -1.15213,78.69296,50.00000,0.0000e+000,20.00000,-1.9581e-002,0.53828
851.56097, 96.36500,    -1.15020,78.68984,50.00000,0.0000e+000,20.00000,-1.9334e-002,0.53766
853.30402, 96.54000,    -1.14880,78.68542,50.00000,0.0000e+000,20.00000,-1.8963e-002,0.53703
855.06598, 96.71500,    -1.15033,78.68112,50.00000,0.0000e+000,20.00000,-1.8161e-002,0.53641
856.82202, 96.89000,    -1.15164,78.67726,50.00000,0.0000e+000,20.00000,-1.7722e-002,0.53578
858.60400, 97.06500,    -1.15465,78.67401,50.00000,0.0000e+000,20.00000,-1.7880e-002,0.53515
860.39801, 97.24000,    -1.15705,78.67011,50.00000,0.0000e+000,20.00000,-1.7815e-002,0.53451
862.17499, 97.41500,    -1.15684,78.66528,50.00000,0.0000e+000,20.00000,-1.7573e-002,0.53388
863.93103, 97.59000,    -1.15577,78.66102,50.00000,0.0000e+000,20.00000,-1.7381e-002,0.53325
865.66998, 97.76500,    -1.15361,78.65881,50.00000,0.0000e+000,20.00000,-1.7509e-002,0.53264
867.40002, 97.94000,    -1.15123,78.65685,50.00000,0.0000e+000,20.00000,-1.7171e-002,0.53203
869.13501, 98.11500,    -1.14814,78.65302,50.00000,0.0000e+000,20.00000,-1.7093e-002,0.53141
870.86700, 98.29000,    -1.14607,78.64986,50.00000,0.0000e+000,20.00000,-1.6919e-002,0.53080
872.59497, 98.46500,    -1.14631,78.64878,50.00000,0.0000e+000,20.00000,-1.6146e-002,0.53019
874.33099, 98.64000,    -1.14457,78.64864,50.00000,0.0000e+000,20.00000,-1.5189e-002,0.52958
876.10901, 98.81500,    -1.14600,78.64575,50.00000,0.0000e+000,20.00000,-1.4454e-002,0.52896
877.86298, 98.99000,    -1.14867,78.64253,50.00000,0.0000e+000,20.00000,-1.3969e-002,0.52834
879.63800, 99.16500,    -1.15098,78.63956,50.00000,0.0000e+000,20.00000,-1.3129e-002,0.52772
881.41400, 99.34000,    -1.15223,78.63574,50.00000,0.0000e+000,20.00000,-1.2191e-002,0.52710
883.16803, 99.51500,    -1.15116,78.63225,50.00000,0.0000e+000,20.00000,-1.1534e-002,0.52648
884.91101, 99.69000,    -1.14941,78.63131,50.00000,0.0000e+000,20.00000,-1.1355e-002,0.52587
886.65601, 99.86500,    -1.14720,78.63031,50.00000,0.0000e+000,20.00000,-1.0556e-002,0.52527
888.41400,100.04000,    -1.14728,78.62702,50.00000,0.0000e+000,20.00000,-9.6748e-003,0.52465
890.15601,100.21500,    -1.14349,78.62436,50.00000,0.0000e+000,20.00000,-9.6494e-003,0.52404
891.88000,100.39000,    -1.14017,78.62369,50.00000,0.0000e+000,20.00000,-1.0221e-002,0.52344
893.65198,100.56500,    -1.14166,78.62300,50.00000,0.0000e+000,20.00000,-1.0544e-002,0.52283
895.42102,100.74000,    -1.14417,78.62171,50.00000,0.0000e+000,20.00000,-1.0639e-002,0.52221
897.20801,100.91500,    -1.14662,78.62014,50.00000,0.0000e+000,20.00000,-1.0780e-002,0.52159
898.96600,101.09000,    -1.14560,78.61862,50.00000,0.0000e+000,20.00000,-1.0743e-002,0.52098
900.75299,101.26500,    -1.14527,78.61780,50.00000,0.0000e+000,20.00000,-1.0592e-002,0.52036
902.54401,101.44000,    -1.14751,78.61674,50.00000,0.0000e+000,20.00000,-1.0639e-002,0.51974
904.31897,101.61500,    -1.14755,78.61630,50.00000,0.0000e+000,20.00000,-1.1117e-002,0.51912
906.05298,101.79000,    -1.14262,78.61611,50.00000,0.0000e+000,20.00000,-1.0966e-002,0.51852
907.77002,101.96500,    -1.13588,78.61465,50.00000,0.0000e+000,20.00000,-1.0759e-002,0.51793
909.50702,102.14000,    -1.13387,78.61252,50.00000,0.0000e+000,20.00000,-1.0550e-002,0.51733
911.22198,102.31500,    -1.13128,78.61016,50.00000,0.0000e+000,20.00000,-1.1032e-002,0.51673
912.95599,102.49000,    -1.12899,78.60668,50.00000,0.0000e+000,20.00000,-1.1757e-002,0.51613
914.69098,102.66500,    -1.12757,78.60296,50.00000,0.0000e+000,20.00000,-1.2047e-002,0.51553
916.45697,102.84000,    -1.12818,78.59973,50.00000,0.0000e+000,20.00000,-1.2032e-002,0.51492
918.20599,103.01500,    -1.12692,78.59642,50.00000,0.0000e+000,20.00000,-1.2025e-002,0.51432
919.95898,103.19000,    -1.12585,78.59329,50.00000,0.0000e+000,20.00000,-1.2243e-002,0.51372
921.72400,103.36500,    -1.12696,78.59143,50.00000,0.0000e+000,20.00000,-1.2303e-002,0.51311
923.47302,103.54000,    -1.12538,78.58950,50.00000,0.0000e+000,20.00000,-1.1983e-002,0.51250
925.23798,103.71500,    -1.12496,78.58684,50.00000,0.0000e+000,20.00000,-1.1203e-002,0.51190
927.01300,103.89000,    -1.12455,78.58561,50.00000,0.0000e+000,20.00000,-1.0685e-002,0.51128
928.75403,104.06500,    -1.12116,78.58435,50.00000,0.0000e+000,20.00000,-1.0456e-002,0.51068
930.52301,104.24000,    -1.12035,78.58099,50.00000,0.0000e+000,20.00000,-1.0114e-002,0.51007
932.30603,104.41500,    -1.12108,78.57776,50.00000,0.0000e+000,20.00000,-9.4254e-003,0.50946
934.09302,104.59000,    -1.12033,78.57583,50.00000,0.0000e+000,20.00000,-8.3537e-003,0.50885
935.84497,104.76500,    -1.11823,78.57475,50.00000,0.0000e+000,20.00000,-7.3379e-003,0.50824
937.62500,104.94000,    -1.11715,78.57319,50.00000,0.0000e+000,20.00000,-7.0510e-003,0.50763
939.40698,105.11500,    -1.11684,78.57177,50.00000,0.0000e+000,20.00000,-7.2770e-003,0.50702
941.15399,105.29000,    -1.11354,78.57162,50.00000,0.0000e+000,20.00000,-6.6790e-003,0.50641
942.90399,105.46500,    -1.11018,78.57385,50.00000,0.0000e+000,20.00000,-5.3347e-003,0.50581
944.65900,105.64000,    -1.10818,78.57466,50.00000,0.0000e+000,20.00000,-4.2817e-003,0.50521
946.41901,105.81500,    -1.10373,78.57378,50.00000,0.0000e+000,20.00000,-3.3879e-003,0.50460
948.16803,105.99000,    -1.10067,78.57215,50.00000,0.0000e+000,20.00000,-2.9110e-003,0.50400
949.90302,106.16500,    -1.09820,78.57050,50.00000,0.0000e+000,20.00000,-2.5846e-003,0.50340
951.65503,106.34000,    -1.09672,78.57013,50.00000,0.0000e+000,20.00000,-2.2825e-003,0.50280
953.40198,106.51500,    -1.09383,78.57125,50.00000,0.0000e+000,20.00000,-2.0356e-003,0.50220
955.12598,106.69000,    -1.09106,78.57001,50.00000,0.0000e+000,20.00000,-2.0385e-003,0.50160
956.88599,106.86500,    -1.09059,78.56691,50.00000,0.0000e+000,20.00000,-2.1845e-003,0.50100
958.64398,107.04000,    -1.09023,78.56516,50.00000,0.0000e+000,20.00000,-2.5990e-003,0.50039
960.40399,107.21500,    -1.08952,78.56759,50.00000,0.0000e+000,20.00000,-3.6142e-003,0.49979
962.13702,107.39000,    -1.08757,78.56942,50.00000,0.0000e+000,20.00000,-4.3133e-003,0.49919
963.87799,107.56500,    -1.08405,78.57171,50.00000,0.0000e+000,20.00000,-4.3097e-003,0.49859
965.62402,107.74000,    -1.08002,78.57298,50.00000,0.0000e+000,20.00000,-3.9213e-003,0.49799
967.35699,107.91500,    -1.07723,78.57041,50.00000,0.0000e+000,20.00000,-3.4240e-003,0.49739
969.09900,108.09000,    -1.07365,78.56887,50.00000,0.0000e+000,20.00000,-3.1953e-003,0.49679
970.85400,108.26500,    -1.07354,78.56768,50.00000,0.0000e+000,20.00000,-3.8287e-003,0.49618
972.61200,108.44000,    -1.07331,78.56750,50.00000,0.0000e+000,20.00000,-4.2767e-003,0.49557
974.37201,108.61500,    -1.07250,78.56511,50.00000,0.0000e+000,20.00000,-4.1052e-003,0.49497
976.12799,108.79000,    -1.07093,78.56321,50.00000,0.0000e+000,20.00000,-3.5556e-003,0.49436
977.92499,108.96500,    -1.07124,78.56031,50.00000,0.0000e+000,20.00000,-3.5781e-003,0.49374
979.71802,109.14000,    -1.07212,78.55903,50.00000,0.0000e+000,20.00000,-4.3644e-003,0.49312
981.47302,109.31500,    -1.06998,78.55873,50.00000,0.0000e+000,20.00000,-6.3508e-003,0.49251
983.20898,109.49000,    -1.06509,78.55843,50.00000,0.0000e+000,20.00000,-6.1798e-003,0.49191
984.95203,109.66500,    -1.06114,78.55874,50.00000,0.0000e+000,20.00000,-6.1912e-003,0.49130
986.72900,109.84000,    -1.06064,78.55852,50.00000,0.0000e+000,20.00000,-5.7681e-003,0.49069
988.47400,110.01500,    -1.05756,78.55768,50.00000,0.0000e+000,20.00000,-4.3544e-003,0.49008
990.19800,110.19000,    -1.05393,78.55587,50.00000,0.0000e+000,20.00000,-4.6209e-003,0.48948
991.91199,110.36500,    -1.04846,78.55432,50.00000,0.0000e+000,20.00000,-5.9990e-003,0.48889
993.64099,110.54000,    -1.04502,78.55254,50.00000,0.0000e+000,20.00000,-6.5533e-003,0.48829
995.39600,110.71500,    -1.04412,78.55278,50.00000,0.0000e+000,20.00000,-4.5934e-003,0.48768
997.16602,110.89000,    -1.04532,78.55342,50.00000,0.0000e+000,20.00000,-8.6155e-003,0.48706
998.31201,111.00500,    -1.04356,78.55128,50.00000,0.0000e+000,20.00000,-7.4120e-002,0.48666