File: book/some_content/TG_ExpDat_B30S70DC1; 14-1-2025-2.csv
#FILE:                       ,B30S70DC1; 14-1-2025.ngb-ds3
#FORMAT:                     ,NETZSCH5
#IDENTITY:                   ,Geopolymer paste
#DECIMAL:                    ,POINT
#SEPARATOR:                  ,COMMA
#MTYPE:                      ,DSC
#INSTRUMENT:                 ,Microlab TU Delft
#PROJECT:                    ,
#DATE/TIME:                  ,17/01/2025 12:35:54 PM
#CORR. FILE:                 ,Blank with cover; 13-1-2025.ngb-bs3
#LABORATORY:                 ,TU Delft Micro Lab
#OPERATOR:                   ,Ahmed
#REMARK:                     ,under Argon atmosphere, 10K/min
#SAMPLE:                     ,B30S70DC1;17-1-2025
#SAMPLE MASS /mg:            ,34.6
#MATERIAL:                   ,Geopolymer paste
#REFERENCE:                  ,blank
#REFERENCE MASS /mg:         ,0
#TYPE OF CRUCIBLE:           ,DSC/TG pan Al2O3
#SAMPLE CRUCIBLE MASS /mg:   ,0
#REFERENCE CRUCIBLE MASS /mg:,0
#CORR. CODE:                 ,020
#EXO:                        ,-1
#RANGE:                      ,40/10.0(K/min)/1000
#SEGMENT:                    ,S2/2

##Temp./øC,Time/min,DSC/(mW/mg),Mass/%,Gas Flow(purge1)/(ml/min),Gas Flow(purge2)/(ml/min),Gas Flow(protective)/(ml/min),DTG/(%/min),Sensit./(uV/mW)
 40.62200, 15.00750, 4.1436e-002,97.93390,50.00000,0.0000e+000,20.00000,-7.9265e-003,1.22608
 40.66700, 15.18750, 4.1114e-002,97.91673,50.00000,0.0000e+000,20.00000,-9.3987e-002,1.22602
 40.68800, 15.36750, 4.0989e-002,97.89955,50.00000,0.0000e+000,20.00000,    -0.10087,1.22599
 40.74300, 15.54750, 4.0596e-002,97.88166,50.00000,0.0000e+000,20.00000,    -0.10743,1.22592
 40.85500, 15.72750, 4.0835e-002,97.86079,50.00000,0.0000e+000,20.00000,    -0.10685,1.22576
 41.01400, 15.90750, 4.1526e-002,97.83864,50.00000,0.0000e+000,20.00000,    -0.10650,1.22554
 41.25100, 16.08750, 4.2311e-002,97.81732,50.00000,0.0000e+000,20.00000,    -0.10611,1.22522
 41.51300, 16.26750, 4.3386e-002,97.79818,50.00000,0.0000e+000,20.00000,    -0.10663,1.22486
 41.90200, 16.44750, 4.5386e-002,97.77947,50.00000,0.0000e+000,20.00000,    -0.10873,1.22432
 42.32900, 16.62750, 4.7282e-002,97.76024,50.00000,0.0000e+000,20.00000,    -0.11084,1.22373
 42.85200, 16.80750, 5.0032e-002,97.74162,50.00000,0.0000e+000,20.00000,    -0.11464,1.22301
 43.48300, 16.98750, 5.3225e-002,97.72355,50.00000,0.0000e+000,20.00000,    -0.11826,1.22214
 44.14800, 17.16750, 5.6027e-002,97.70415,50.00000,0.0000e+000,20.00000,    -0.12223,1.22122
 44.90800, 17.34750, 6.0105e-002,97.68496,50.00000,0.0000e+000,20.00000,    -0.12736,1.22018
 45.78500, 17.52750, 6.3801e-002,97.66467,50.00000,0.0000e+000,20.00000,    -0.13261,1.21897
 46.74200, 17.70750, 6.8216e-002,97.64261,50.00000,0.0000e+000,20.00000,    -0.13819,1.21765
 47.76100, 17.88750, 7.2592e-002,97.62025,50.00000,0.0000e+000,20.00000,    -0.14446,1.21624
 48.88000, 18.06750, 7.7131e-002,97.59773,50.00000,0.0000e+000,20.00000,    -0.15220,1.21470
 50.06000, 18.24750, 8.2215e-002,97.57428,50.00000,0.0000e+000,20.00000,    -0.16186,1.21308
 51.33500, 18.42750, 8.7541e-002,97.54873,50.00000,0.0000e+000,20.00000,    -0.17266,1.21132
 52.66900, 18.60750, 9.2687e-002,97.52073,50.00000,0.0000e+000,20.00000,    -0.18490,1.20949
 54.12400, 18.78750, 9.8374e-002,97.49170,50.00000,0.0000e+000,20.00000,    -0.19899,1.20748
 55.63100, 18.96750,     0.10429,97.46060,50.00000,0.0000e+000,20.00000,    -0.21433,1.20541
 57.21500, 19.14750,     0.11029,97.42478,50.00000,0.0000e+000,20.00000,    -0.23111,1.20323
 58.88300, 19.32750,     0.11678,97.38574,50.00000,0.0000e+000,20.00000,    -0.25008,1.20094
 60.62700, 19.50750,     0.12363,97.34357,50.00000,0.0000e+000,20.00000,    -0.27100,1.19854
 62.40600, 19.68750,     0.13069,97.29935,50.00000,0.0000e+000,20.00000,    -0.29260,1.19610
 64.27600, 19.86750,     0.13817,97.25242,50.00000,0.0000e+000,20.00000,    -0.31458,1.19353
 66.21100, 20.04750,     0.14617,97.19936,50.00000,0.0000e+000,20.00000,    -0.33709,1.19087
 68.20900, 20.22750,     0.15478,97.14139,50.00000,0.0000e+000,20.00000,    -0.36030,1.18813
 70.24700, 20.40750,     0.16378,97.07861,50.00000,0.0000e+000,20.00000,    -0.38475,1.18534
 72.32600, 20.58750,     0.17286,97.01012,50.00000,0.0000e+000,20.00000,    -0.41141,1.18249
 74.45400, 20.76750,     0.18258,96.93562,50.00000,0.0000e+000,20.00000,    -0.44045,1.17957
 76.63600, 20.94750,     0.19269,96.85591,50.00000,0.0000e+000,20.00000,    -0.47307,1.17659
 78.86400, 21.12750,     0.20334,96.76825,50.00000,0.0000e+000,20.00000,    -0.50646,1.17354
 81.13500, 21.30750,     0.21362,96.67088,50.00000,0.0000e+000,20.00000,    -0.53751,1.17044
 83.42000, 21.48750,     0.22388,96.56977,50.00000,0.0000e+000,20.00000,    -0.56847,1.16732
 85.75500, 21.66750,     0.23383,96.46723,50.00000,0.0000e+000,20.00000,    -0.59700,1.16413
 88.10000, 21.84750,     0.24422,96.36228,50.00000,0.0000e+000,20.00000,    -0.62224,1.16094
 90.47900, 22.02750,     0.25631,96.25307,50.00000,0.0000e+000,20.00000,    -0.64323,1.15770
 92.90900, 22.20750,     0.26887,96.13735,50.00000,0.0000e+000,20.00000,    -0.66026,1.15440
 95.33200, 22.38750,     0.28282,96.01238,50.00000,0.0000e+000,20.00000,    -0.67351,1.15110
 97.76100, 22.56750,     0.29834,95.87765,50.00000,0.0000e+000,20.00000,    -0.68304,1.14781
100.21000, 22.74750,     0.31374,95.72619,50.00000,0.0000e+000,20.00000,    -0.68908,1.14449
102.66800, 22.92750,     0.32941,95.56466,50.00000,0.0000e+000,20.00000,    -0.69084,1.14116
105.13000, 23.10750,     0.34396,95.40956,50.00000,0.0000e+000,20.00000,    -0.68885,1.13783
107.59400, 23.28750,     0.35554,95.25215,50.00000,0.0000e+000,20.00000,    -0.68515,1.13451
110.06100, 23.46750,     0.36218,95.10045,50.00000,0.0000e+000,20.00000,    -0.67960,1.13118
112.54000, 23.64750,     0.36238,94.95512,50.00000,0.0000e+000,20.00000,    -0.67260,1.12784
114.98300, 23.82750,     0.35465,94.81915,50.00000,0.0000e+000,20.00000,    -0.66450,1.12455
117.46800, 24.00750,     0.34162,94.69379,50.00000,0.0000e+000,20.00000,    -0.65465,1.12122
119.92500, 24.18750,     0.32579,94.57646,50.00000,0.0000e+000,20.00000,    -0.64039,1.11792
122.39000, 24.36750,     0.30837,94.46695,50.00000,0.0000e+000,20.00000,    -0.62215,1.11462
124.85500, 24.54750,     0.29078,94.36474,50.00000,0.0000e+000,20.00000,    -0.60059,1.11133
127.30100, 24.72750,     0.27340,94.27097,50.00000,0.0000e+000,20.00000,    -0.57599,1.10806
129.76500, 24.90750,     0.25647,94.18204,50.00000,0.0000e+000,20.00000,    -0.55298,1.10478
132.20200, 25.08750,     0.24037,94.09405,50.00000,0.0000e+000,20.00000,    -0.52826,1.10154
134.62700, 25.26750,     0.22429,94.01132,50.00000,0.0000e+000,20.00000,    -0.50335,1.09831
137.04201, 25.44750,     0.20971,93.93214,50.00000,0.0000e+000,20.00000,    -0.47998,1.09511
139.45799, 25.62750,     0.19479,93.85348,50.00000,0.0000e+000,20.00000,    -0.45830,1.09191
141.85600, 25.80750,     0.18068,93.77447,50.00000,0.0000e+000,20.00000,    -0.43896,1.08875
144.24400, 25.98750,     0.16761,93.70180,50.00000,0.0000e+000,20.00000,    -0.42131,1.08560
146.60500, 26.16750,     0.15583,93.63529,50.00000,0.0000e+000,20.00000,    -0.40551,1.08249
148.95799, 26.34750,     0.14582,93.56636,50.00000,0.0000e+000,20.00000,    -0.39088,1.07939
151.27200, 26.52750,     0.13668,93.49456,50.00000,0.0000e+000,20.00000,    -0.37723,1.07636
153.57001, 26.70750,     0.12745,93.42300,50.00000,0.0000e+000,20.00000,    -0.36503,1.07335
155.85800, 26.88750,     0.11825,93.35506,50.00000,0.0000e+000,20.00000,    -0.35308,1.07036
158.09500, 27.06750,     0.10777,93.29274,50.00000,0.0000e+000,20.00000,    -0.34199,1.06744
160.32201, 27.24750, 9.7022e-002,93.23176,50.00000,0.0000e+000,20.00000,    -0.33167,1.06454
162.52000, 27.42750, 8.5652e-002,93.17280,50.00000,0.0000e+000,20.00000,    -0.32087,1.06168
164.70000, 27.60750, 7.4177e-002,93.11648,50.00000,0.0000e+000,20.00000,    -0.30933,1.05885
166.83400, 27.78750, 6.2867e-002,93.06213,50.00000,0.0000e+000,20.00000,    -0.29873,1.05609
168.96899, 27.96750, 5.1769e-002,93.00904,50.00000,0.0000e+000,20.00000,    -0.28961,1.05333
171.06100, 28.14750, 4.0548e-002,92.95845,50.00000,0.0000e+000,20.00000,    -0.27969,1.05063
173.14999, 28.32750, 2.9605e-002,92.91274,50.00000,0.0000e+000,20.00000,    -0.26888,1.04794
175.21001, 28.50750, 1.9049e-002,92.86837,50.00000,0.0000e+000,20.00000,    -0.25782,1.04530
177.23300, 28.68750, 8.5858e-003,92.82340,50.00000,0.0000e+000,20.00000,    -0.24748,1.04270
179.26500, 28.86750,-1.2296e-003,92.78019,50.00000,0.0000e+000,20.00000,    -0.23883,1.04010
181.26900, 29.04750,-1.1009e-002,92.73809,50.00000,0.0000e+000,20.00000,    -0.23048,1.03754
183.25900, 29.22750,-2.0729e-002,92.69862,50.00000,0.0000e+000,20.00000,    -0.22142,1.03500
185.23300, 29.40750,-2.9685e-002,92.66127,50.00000,0.0000e+000,20.00000,    -0.21225,1.03249
187.20200, 29.58750,-3.8621e-002,92.62578,50.00000,0.0000e+000,20.00000,    -0.20381,1.02999
189.14500, 29.76750,-4.7597e-002,92.59186,50.00000,0.0000e+000,20.00000,    -0.19528,1.02752
191.08400, 29.94750,-5.6531e-002,92.55979,50.00000,0.0000e+000,20.00000,    -0.18682,1.02507
192.99800, 30.12750,-6.4750e-002,92.52766,50.00000,0.0000e+000,20.00000,    -0.17985,1.02265
194.88300, 30.30750,-7.3373e-002,92.49623,50.00000,0.0000e+000,20.00000,    -0.17322,1.02028
196.77699, 30.48750,-8.1213e-002,92.46523,50.00000,0.0000e+000,20.00000,    -0.16619,1.01790
198.64600, 30.66750,-8.9521e-002,92.43401,50.00000,0.0000e+000,20.00000,    -0.15959,1.01555
200.52200, 30.84750,-9.7455e-002,92.40303,50.00000,0.0000e+000,20.00000,    -0.15298,1.01320
202.35001, 31.02750,    -0.10524,92.37605,50.00000,0.0000e+000,20.00000,    -0.14682,1.01091
204.20000, 31.20750,    -0.11252,92.35271,50.00000,0.0000e+000,20.00000,    -0.14108,1.00861
206.02499, 31.38750,    -0.12027,92.32904,50.00000,0.0000e+000,20.00000,    -0.13572,1.00633
207.83400, 31.56750,    -0.12759,92.30649,50.00000,0.0000e+000,20.00000,    -0.13079,1.00408
209.64301, 31.74750,    -0.13507,92.28621,50.00000,0.0000e+000,20.00000,    -0.12660,1.00184
211.45300, 31.92750,    -0.14228,92.26530,50.00000,0.0000e+000,20.00000,    -0.12256,0.99960
213.23700, 32.10750,    -0.14923,92.24513,50.00000,0.0000e+000,20.00000,    -0.11858,0.99740
215.03999, 32.28750,    -0.15632,92.22570,50.00000,0.0000e+000,20.00000,    -0.11422,0.99517
216.82600, 32.46750,    -0.16313,92.20634,50.00000,0.0000e+000,20.00000,    -0.10912,0.99298
218.58501, 32.64750,    -0.16931,92.18794,50.00000,0.0000e+000,20.00000,    -0.10455,0.99082
220.35699, 32.82750,    -0.17575,92.17048,50.00000,0.0000e+000,20.00000,    -0.10169,0.98865
222.10899, 33.00750,    -0.18217,92.15371,50.00000,0.0000e+000,20.00000,-9.9641e-002,0.98651
223.85100, 33.18750,    -0.18818,92.13747,50.00000,0.0000e+000,20.00000,-9.7782e-002,0.98438
225.61800, 33.36750,    -0.19421,92.12142,50.00000,0.0000e+000,20.00000,-9.5333e-002,0.98223
227.36000, 33.54750,    -0.19991,92.10452,50.00000,0.0000e+000,20.00000,-9.2947e-002,0.98011
229.09399, 33.72750,    -0.20576,92.08731,50.00000,0.0000e+000,20.00000,-9.0708e-002,0.97801
230.82600, 33.90750,    -0.21128,92.07005,50.00000,0.0000e+000,20.00000,-8.8480e-002,0.97592
232.56300, 34.08750,    -0.21733,92.05458,50.00000,0.0000e+000,20.00000,-8.6520e-002,0.97382
234.29300, 34.26750,    -0.22329,92.04190,50.00000,0.0000e+000,20.00000,-8.4746e-002,0.97174
236.03799, 34.44750,    -0.22939,92.02795,50.00000,0.0000e+000,20.00000,-8.3088e-002,0.96964
237.77200, 34.62750,    -0.23519,92.01080,50.00000,0.0000e+000,20.00000,-8.1641e-002,0.96756
239.49800, 34.80750,    -0.24090,91.99453,50.00000,0.0000e+000,20.00000,-8.0955e-002,0.96549
241.21500, 34.98750,    -0.24677,91.97776,50.00000,0.0000e+000,20.00000,-8.0337e-002,0.96344
242.95500, 35.16750,    -0.25271,91.96319,50.00000,0.0000e+000,20.00000,-7.9349e-002,0.96137
244.67799, 35.34750,    -0.25824,91.95140,50.00000,0.0000e+000,20.00000,-7.8196e-002,0.95932
246.40601, 35.52750,    -0.26391,91.93892,50.00000,0.0000e+000,20.00000,-7.6726e-002,0.95728
248.13200, 35.70750,    -0.26973,91.92655,50.00000,0.0000e+000,20.00000,-7.5434e-002,0.95523
249.86400, 35.88750,    -0.27575,91.91439,50.00000,0.0000e+000,20.00000,-7.4522e-002,0.95319
251.58701, 36.06750,    -0.28178,91.90148,50.00000,0.0000e+000,20.00000,-7.4521e-002,0.95116
253.31400, 36.24750,    -0.28764,91.88886,50.00000,0.0000e+000,20.00000,-7.4072e-002,0.94913
255.03500, 36.42750,    -0.29400,91.87667,50.00000,0.0000e+000,20.00000,-7.2550e-002,0.94711
256.77600, 36.60750,    -0.30030,91.86266,50.00000,0.0000e+000,20.00000,-7.1353e-002,0.94508
258.49899, 36.78750,    -0.30658,91.84826,50.00000,0.0000e+000,20.00000,-6.9958e-002,0.94307
260.24200, 36.96750,    -0.31279,91.83579,50.00000,0.0000e+000,20.00000,-6.9083e-002,0.94104
261.97198, 37.14750,    -0.31818,91.82321,50.00000,0.0000e+000,20.00000,-6.9002e-002,0.93903
263.70599, 37.32750,    -0.32451,91.81134,50.00000,0.0000e+000,20.00000,-6.8887e-002,0.93702
265.43201, 37.50750,    -0.33011,91.79889,50.00000,0.0000e+000,20.00000,-6.8509e-002,0.93503
267.17999, 37.68750,    -0.33678,91.78626,50.00000,0.0000e+000,20.00000,-6.8213e-002,0.93302
268.91101, 37.86750,    -0.34273,91.77342,50.00000,0.0000e+000,20.00000,-6.7901e-002,0.93103
270.65701, 38.04750,    -0.34900,91.76125,50.00000,0.0000e+000,20.00000,-6.7787e-002,0.92902
272.38501, 38.22750,    -0.35540,91.75011,50.00000,0.0000e+000,20.00000,-6.7895e-002,0.92705
274.14001, 38.40750,    -0.36235,91.73800,50.00000,0.0000e+000,20.00000,-6.7531e-002,0.92504
275.88000, 38.58750,    -0.36828,91.72639,50.00000,0.0000e+000,20.00000,-6.6761e-002,0.92306
277.63101, 38.76750,    -0.37454,91.71449,50.00000,0.0000e+000,20.00000,-6.6699e-002,0.92108
279.37399, 38.94750,    -0.38011,91.70276,50.00000,0.0000e+000,20.00000,-6.6838e-002,0.91910
281.12299, 39.12750,    -0.38584,91.69090,50.00000,0.0000e+000,20.00000,-6.7061e-002,0.91713
282.86200, 39.30750,    -0.39105,91.67962,50.00000,0.0000e+000,20.00000,-6.7615e-002,0.91517
284.59799, 39.48750,    -0.39635,91.66872,50.00000,0.0000e+000,20.00000,-6.8462e-002,0.91322
286.36499, 39.66750,    -0.40251,91.65710,50.00000,0.0000e+000,20.00000,-6.9134e-002,0.91124
288.11499, 39.84750,    -0.40781,91.64490,50.00000,0.0000e+000,20.00000,-6.9913e-002,0.90929
289.87701, 40.02750,    -0.41402,91.63232,50.00000,0.0000e+000,20.00000,-7.1521e-002,0.90732
291.63199, 40.20750,    -0.41944,91.61998,50.00000,0.0000e+000,20.00000,-7.2484e-002,0.90537
293.38699, 40.38750,    -0.42478,91.60810,50.00000,0.0000e+000,20.00000,-7.3394e-002,0.90343
295.14600, 40.56750,    -0.43001,91.59586,50.00000,0.0000e+000,20.00000,-7.4251e-002,0.90149
296.90500, 40.74750,    -0.43461,91.58282,50.00000,0.0000e+000,20.00000,-7.4917e-002,0.89955
298.64499, 40.92750,    -0.43959,91.56998,50.00000,0.0000e+000,20.00000,-7.5888e-002,0.89764
300.41199, 41.10750,    -0.44438,91.55608,50.00000,0.0000e+000,20.00000,-7.7285e-002,0.89570
302.17099, 41.28750,    -0.44921,91.54036,50.00000,0.0000e+000,20.00000,-7.8718e-002,0.89378
303.94101, 41.46750,    -0.45364,91.52495,50.00000,0.0000e+000,20.00000,-8.0008e-002,0.89185
305.68600, 41.64750,    -0.45790,91.50996,50.00000,0.0000e+000,20.00000,-8.1322e-002,0.88995
307.43399, 41.82750,    -0.46228,91.49300,50.00000,0.0000e+000,20.00000,-8.2769e-002,0.88806
309.18701, 42.00750,    -0.46588,91.47723,50.00000,0.0000e+000,20.00000,-8.4300e-002,0.88616
310.95700, 42.18750,    -0.47118,91.46218,50.00000,0.0000e+000,20.00000,-8.5995e-002,0.88426
312.71899, 42.36750,    -0.47571,91.44719,50.00000,0.0000e+000,20.00000,-8.8193e-002,0.88236
314.47699, 42.54750,    -0.48038,91.43290,50.00000,0.0000e+000,20.00000,-9.0261e-002,0.88048
316.24399, 42.72750,    -0.48460,91.41782,50.00000,0.0000e+000,20.00000,-9.2447e-002,0.87859
318.01099, 42.90750,    -0.48909,91.40131,50.00000,0.0000e+000,20.00000,-9.4580e-002,0.87671
319.77802, 43.08750,    -0.49321,91.38517,50.00000,0.0000e+000,20.00000,-9.6241e-002,0.87484
321.54501, 43.26750,    -0.49669,91.36898,50.00000,0.0000e+000,20.00000,-9.8039e-002,0.87297
323.31900, 43.44750,    -0.50054,91.35224,50.00000,0.0000e+000,20.00000,    -0.10015,0.87110
325.07800, 43.62750,    -0.50405,91.33447,50.00000,0.0000e+000,20.00000,    -0.10196,0.86925
326.86099, 43.80750,    -0.50747,91.31646,50.00000,0.0000e+000,20.00000,    -0.10459,0.86738
328.62900, 43.98750,    -0.51095,91.29845,50.00000,0.0000e+000,20.00000,    -0.10747,0.86553
330.39301, 44.16750,    -0.51398,91.27863,50.00000,0.0000e+000,20.00000,    -0.11024,0.86369
332.17499, 44.34750,    -0.51802,91.25803,50.00000,0.0000e+000,20.00000,    -0.11320,0.86184
333.95901, 44.52750,    -0.52162,91.23730,50.00000,0.0000e+000,20.00000,    -0.11629,0.85999
335.72000, 44.70750,    -0.52486,91.21593,50.00000,0.0000e+000,20.00000,    -0.11923,0.85817
337.50699, 44.88750,    -0.52782,91.19439,50.00000,0.0000e+000,20.00000,    -0.12237,0.85633
339.27701, 45.06750,    -0.53100,91.17229,50.00000,0.0000e+000,20.00000,    -0.12538,0.85451
341.06699, 45.24750,    -0.53367,91.14981,50.00000,0.0000e+000,20.00000,    -0.12861,0.85268
342.81799, 45.42750,    -0.53622,91.12667,50.00000,0.0000e+000,20.00000,    -0.13178,0.85090
344.60800, 45.60750,    -0.53916,91.10124,50.00000,0.0000e+000,20.00000,    -0.13431,0.84908
346.38300, 45.78750,    -0.54293,91.07553,50.00000,0.0000e+000,20.00000,    -0.13671,0.84728
348.15201, 45.96750,    -0.54606,91.05035,50.00000,0.0000e+000,20.00000,    -0.13914,0.84549
349.94101, 46.14750,    -0.54966,91.02522,50.00000,0.0000e+000,20.00000,    -0.14180,0.84369
351.70700, 46.32750,    -0.55393,90.99924,50.00000,0.0000e+000,20.00000,    -0.14371,0.84192
353.48700, 46.50750,    -0.55788,90.97232,50.00000,0.0000e+000,20.00000,    -0.14515,0.84014
355.27600, 46.68750,    -0.56304,90.94450,50.00000,0.0000e+000,20.00000,    -0.14608,0.83836
357.06000, 46.86750,    -0.56800,90.91740,50.00000,0.0000e+000,20.00000,    -0.14649,0.83658
358.83701, 47.04750,    -0.57264,90.88925,50.00000,0.0000e+000,20.00000,    -0.14665,0.83482
360.62500, 47.22750,    -0.57819,90.85994,50.00000,0.0000e+000,20.00000,    -0.14656,0.83306
362.42401, 47.40750,    -0.58422,90.83234,50.00000,0.0000e+000,20.00000,    -0.14575,0.83129
364.20300, 47.58750,    -0.59018,90.80572,50.00000,0.0000e+000,20.00000,    -0.14431,0.82955
365.99799, 47.76750,    -0.59604,90.77777,50.00000,0.0000e+000,20.00000,    -0.14312,0.82779
367.78699, 47.94750,    -0.60197,90.74738,50.00000,0.0000e+000,20.00000,    -0.14230,0.82605
369.56201, 48.12750,    -0.60737,90.71935,50.00000,0.0000e+000,20.00000,    -0.14135,0.82433
371.34601, 48.30750,    -0.61304,90.69267,50.00000,0.0000e+000,20.00000,    -0.13992,0.82260
373.13300, 48.48750,    -0.61897,90.66747,50.00000,0.0000e+000,20.00000,    -0.13806,0.82088
374.90302, 48.66750,    -0.62505,90.64382,50.00000,0.0000e+000,20.00000,    -0.13623,0.81918
376.69400, 48.84750,    -0.63224,90.62073,50.00000,0.0000e+000,20.00000,    -0.13387,0.81747
378.48401, 49.02750,    -0.63897,90.59811,50.00000,0.0000e+000,20.00000,    -0.13096,0.81576
380.25400, 49.20750,    -0.64592,90.57576,50.00000,0.0000e+000,20.00000,    -0.12836,0.81408
382.05200, 49.38750,    -0.65260,90.55506,50.00000,0.0000e+000,20.00000,    -0.12631,0.81238
383.82901, 49.56750,    -0.65961,90.53435,50.00000,0.0000e+000,20.00000,    -0.12398,0.81070
385.61401, 49.74750,    -0.66602,90.51244,50.00000,0.0000e+000,20.00000,    -0.12113,0.80902
387.40601, 49.92750,    -0.67352,90.48998,50.00000,0.0000e+000,20.00000,    -0.11855,0.80734
389.19800, 50.10750,    -0.68045,90.46838,50.00000,0.0000e+000,20.00000,    -0.11570,0.80567
390.97501, 50.28750,    -0.68678,90.44729,50.00000,0.0000e+000,20.00000,    -0.11246,0.80401
392.75900, 50.46750,    -0.69336,90.42669,50.00000,0.0000e+000,20.00000,    -0.11043,0.80236
394.54599, 50.64750,    -0.69989,90.40723,50.00000,0.0000e+000,20.00000,    -0.10929,0.80071
396.33401, 50.82750,    -0.70591,90.38857,50.00000,0.0000e+000,20.00000,    -0.10818,0.79906
398.10800, 51.00750,    -0.71150,90.37013,50.00000,0.0000e+000,20.00000,    -0.10705,0.79744
399.88699, 51.18750,    -0.71741,90.35108,50.00000,0.0000e+000,20.00000,    -0.10666,0.79581
401.66299, 51.36750,    -0.72282,90.33203,50.00000,0.0000e+000,20.00000,    -0.10637,0.79420
403.44199, 51.54750,    -0.72929,90.31231,50.00000,0.0000e+000,20.00000,    -0.10566,0.79258
405.23199, 51.72750,    -0.73525,90.29295,50.00000,0.0000e+000,20.00000,    -0.10536,0.79096
407.02100, 51.90750,    -0.74119,90.27610,50.00000,0.0000e+000,20.00000,    -0.10541,0.78935
408.81601, 52.08750,    -0.74836,90.26226,50.00000,0.0000e+000,20.00000,    -0.10497,0.78774
410.63300, 52.26750,    -0.75484,90.24654,50.00000,0.0000e+000,20.00000,    -0.10511,0.78612
412.41599, 52.44750,    -0.76072,90.22769,50.00000,0.0000e+000,20.00000,    -0.10575,0.78453
414.21500, 52.62750,    -0.76512,90.20894,50.00000,0.0000e+000,20.00000,    -0.10639,0.78294
415.99899, 52.80750,    -0.76864,90.19071,50.00000,0.0000e+000,20.00000,    -0.10698,0.78136
417.76300, 52.98750,    -0.77260,90.17133,50.00000,0.0000e+000,20.00000,    -0.10761,0.77981
419.55301, 53.16750,    -0.77626,90.15172,50.00000,0.0000e+000,20.00000,    -0.10843,0.77824
421.32901, 53.34750,    -0.78025,90.13265,50.00000,0.0000e+000,20.00000,    -0.10909,0.77668
423.11200, 53.52750,    -0.78511,90.11176,50.00000,0.0000e+000,20.00000,    -0.10957,0.77513
424.89200, 53.70750,    -0.79081,90.08948,50.00000,0.0000e+000,20.00000,    -0.11054,0.77359
426.70099, 53.88750,    -0.79741,90.06984,50.00000,0.0000e+000,20.00000,    -0.11262,0.77203
428.48401, 54.06750,    -0.80352,90.04902,50.00000,0.0000e+000,20.00000,    -0.11479,0.77049
430.29001, 54.24750,    -0.80970,90.02686,50.00000,0.0000e+000,20.00000,    -0.11624,0.76894
432.08899, 54.42750,    -0.81387,90.00575,50.00000,0.0000e+000,20.00000,    -0.11772,0.76741
433.88699, 54.60750,    -0.81740,89.98509,50.00000,0.0000e+000,20.00000,    -0.11939,0.76588
435.66901, 54.78750,    -0.82100,89.96404,50.00000,0.0000e+000,20.00000,    -0.12047,0.76437
437.45499, 54.96750,    -0.82482,89.94202,50.00000,0.0000e+000,20.00000,    -0.12111,0.76286
439.25101, 55.14750,    -0.82915,89.91997,50.00000,0.0000e+000,20.00000,    -0.12172,0.76135
441.02499, 55.32750,    -0.83333,89.89851,50.00000,0.0000e+000,20.00000,    -0.12195,0.75987
442.82401, 55.50750,    -0.83716,89.87766,50.00000,0.0000e+000,20.00000,    -0.12215,0.75837
444.60300, 55.68750,    -0.84098,89.85608,50.00000,0.0000e+000,20.00000,    -0.12346,0.75689
446.35599, 55.86750,    -0.84498,89.83328,50.00000,0.0000e+000,20.00000,    -0.12486,0.75544
448.16199, 56.04750,    -0.84958,89.80945,50.00000,0.0000e+000,20.00000,    -0.12551,0.75395
449.93500, 56.22750,    -0.85468,89.78522,50.00000,0.0000e+000,20.00000,    -0.12648,0.75249
451.73199, 56.40750,    -0.85855,89.76082,50.00000,0.0000e+000,20.00000,    -0.12763,0.75102
453.52802, 56.58750,    -0.86373,89.73748,50.00000,0.0000e+000,20.00000,    -0.12894,0.74956
455.32300, 56.76750,    -0.86907,89.71534,50.00000,0.0000e+000,20.00000,    -0.13021,0.74811
457.10800, 56.94750,    -0.87476,89.69392,50.00000,0.0000e+000,20.00000,    -0.13156,0.74666
458.90500, 57.12750,    -0.87995,89.67280,50.00000,0.0000e+000,20.00000,    -0.13319,0.74522
460.72000, 57.30750,    -0.88440,89.64993,50.00000,0.0000e+000,20.00000,    -0.13475,0.74376
462.50400, 57.48750,    -0.88797,89.62540,50.00000,0.0000e+000,20.00000,    -0.13571,0.74234
464.32599, 57.66750,    -0.89420,89.59991,50.00000,0.0000e+000,20.00000,    -0.13692,0.74089
466.16299, 57.84750,    -0.90299,89.57515,50.00000,0.0000e+000,20.00000,    -0.13813,0.73944
467.96799, 58.02750,    -0.90617,89.55050,50.00000,0.0000e+000,20.00000,    -0.13966,0.73801
469.73999, 58.20750,    -0.90453,89.52556,50.00000,0.0000e+000,20.00000,    -0.14101,0.73662
471.49100, 58.38750,    -0.90282,89.50006,50.00000,0.0000e+000,20.00000,    -0.14229,0.73525
473.24100, 58.56750,    -0.90294,89.47361,50.00000,0.0000e+000,20.00000,    -0.14400,0.73389
475.01401, 58.74750,    -0.90550,89.44659,50.00000,0.0000e+000,20.00000,    -0.14622,0.73251
476.77499, 58.92750,    -0.91087,89.41915,50.00000,0.0000e+000,20.00000,    -0.14817,0.73115
478.57401, 59.10750,    -0.91652,89.39222,50.00000,0.0000e+000,20.00000,    -0.14959,0.72977
480.35101, 59.28750,    -0.92266,89.36735,50.00000,0.0000e+000,20.00000,    -0.15124,0.72841
482.13901, 59.46750,    -0.92663,89.34061,50.00000,0.0000e+000,20.00000,    -0.15341,0.72704
483.91199, 59.64750,    -0.93054,89.31263,50.00000,0.0000e+000,20.00000,    -0.15556,0.72570
485.69800, 59.82750,    -0.93371,89.28309,50.00000,0.0000e+000,20.00000,    -0.15714,0.72434
487.50101, 60.00750,    -0.93751,89.25348,50.00000,0.0000e+000,20.00000,    -0.15876,0.72299
489.27899, 60.18750,    -0.94064,89.22519,50.00000,0.0000e+000,20.00000,    -0.16034,0.72165
491.08499, 60.36750,    -0.94440,89.19681,50.00000,0.0000e+000,20.00000,    -0.16162,0.72030
492.88400, 60.54750,    -0.94925,89.16720,50.00000,0.0000e+000,20.00000,    -0.16205,0.71896
494.69000, 60.72750,    -0.95360,89.13870,50.00000,0.0000e+000,20.00000,    -0.16207,0.71763
496.49100, 60.90750,    -0.95657,89.11115,50.00000,0.0000e+000,20.00000,    -0.16310,0.71630
498.29300, 61.08750,    -0.96007,89.08129,50.00000,0.0000e+000,20.00000,    -0.16503,0.71497
500.09100, 61.26750,    -0.96376,89.04830,50.00000,0.0000e+000,20.00000,    -0.16655,0.71366
501.88901, 61.44750,    -0.96798,89.01505,50.00000,0.0000e+000,20.00000,    -0.16760,0.71235
503.68799, 61.62750,    -0.97118,88.98462,50.00000,0.0000e+000,20.00000,    -0.16788,0.71104
505.48300, 61.80750,    -0.97413,88.95384,50.00000,0.0000e+000,20.00000,    -0.16789,0.70975
507.29800, 61.98750,    -0.97767,88.92276,50.00000,0.0000e+000,20.00000,    -0.16776,0.70844
509.08899, 62.16750,    -0.98050,88.89166,50.00000,0.0000e+000,20.00000,    -0.16837,0.70716
510.88599, 62.34750,    -0.98375,88.86254,50.00000,0.0000e+000,20.00000,    -0.16944,0.70588
512.68903, 62.52750,    -0.98648,88.83546,50.00000,0.0000e+000,20.00000,    -0.17063,0.70460
514.47400, 62.70750,    -0.98975,88.80491,50.00000,0.0000e+000,20.00000,    -0.17192,0.70333
516.25800, 62.88750,    -0.99146,88.77289,50.00000,0.0000e+000,20.00000,    -0.17245,0.70208
518.04303, 63.06750,    -0.99204,88.74096,50.00000,0.0000e+000,20.00000,    -0.17207,0.70083
519.82898, 63.24750,    -0.99585,88.70916,50.00000,0.0000e+000,20.00000,    -0.17182,0.69958
521.63702, 63.42750,    -1.00112,88.67868,50.00000,0.0000e+000,20.00000,    -0.17266,0.69832
523.44000, 63.60750,    -1.00525,88.64874,50.00000,0.0000e+000,20.00000,    -0.17347,0.69708
525.25598, 63.78750,    -1.00909,88.62057,50.00000,0.0000e+000,20.00000,    -0.17421,0.69582
527.04303, 63.96750,    -1.01138,88.59079,50.00000,0.0000e+000,20.00000,    -0.17491,0.69460
528.83301, 64.14750,    -1.01306,88.55759,50.00000,0.0000e+000,20.00000,    -0.17615,0.69338
530.63000, 64.32750,    -1.01371,88.52425,50.00000,0.0000e+000,20.00000,    -0.17817,0.69215
532.41400, 64.50750,    -1.01487,88.49192,50.00000,0.0000e+000,20.00000,    -0.17909,0.69095
534.21002, 64.68750,    -1.01870,88.46049,50.00000,0.0000e+000,20.00000,    -0.17948,0.68974
536.03998, 64.86750,    -1.02551,88.42939,50.00000,0.0000e+000,20.00000,    -0.18049,0.68851
537.83099, 65.04750,    -1.02938,88.39701,50.00000,0.0000e+000,20.00000,    -0.18151,0.68731
539.65100, 65.22750,    -1.03078,88.36332,50.00000,0.0000e+000,20.00000,    -0.18238,0.68610
541.44397, 65.40750,    -1.03186,88.32969,50.00000,0.0000e+000,20.00000,    -0.18339,0.68491
543.21997, 65.58750,    -1.03334,88.29597,50.00000,0.0000e+000,20.00000,    -0.18499,0.68374
545.02301, 65.76750,    -1.03533,88.26223,50.00000,0.0000e+000,20.00000,    -0.18650,0.68256
546.81000, 65.94750,    -1.03778,88.22816,50.00000,0.0000e+000,20.00000,    -0.18700,0.68139
548.62701, 66.12750,    -1.04085,88.19377,50.00000,0.0000e+000,20.00000,    -0.18759,0.68020
550.44000, 66.30750,    -1.04694,88.16020,50.00000,0.0000e+000,20.00000,    -0.18830,0.67903
552.28497, 66.48750,    -1.05177,88.12701,50.00000,0.0000e+000,20.00000,    -0.18931,0.67784
554.09302, 66.66750,    -1.05357,88.09169,50.00000,0.0000e+000,20.00000,    -0.19078,0.67668
555.89801, 66.84750,    -1.05328,88.05585,50.00000,0.0000e+000,20.00000,    -0.19226,0.67552
557.67798, 67.02750,    -1.05345,88.02180,50.00000,0.0000e+000,20.00000,    -0.19304,0.67439
559.49597, 67.20750,    -1.05355,87.98818,50.00000,0.0000e+000,20.00000,    -0.19361,0.67324
561.28198, 67.38750,    -1.05450,87.95392,50.00000,0.0000e+000,20.00000,    -0.19432,0.67211
563.06702, 67.56750,    -1.05620,87.91926,50.00000,0.0000e+000,20.00000,    -0.19461,0.67099
564.84698, 67.74750,    -1.05779,87.88460,50.00000,0.0000e+000,20.00000,    -0.19402,0.66988
566.62500, 67.92750,    -1.05878,87.84907,50.00000,0.0000e+000,20.00000,    -0.19350,0.66877
568.41199, 68.10750,    -1.06080,87.81390,50.00000,0.0000e+000,20.00000,    -0.19406,0.66766
570.19299, 68.28750,    -1.06239,87.77874,50.00000,0.0000e+000,20.00000,    -0.19510,0.66656
571.98199, 68.46750,    -1.06388,87.74255,50.00000,0.0000e+000,20.00000,    -0.19476,0.66546
573.79401, 68.64750,    -1.06705,87.70509,50.00000,0.0000e+000,20.00000,    -0.19467,0.66435
575.57898, 68.82750,    -1.07146,87.66838,50.00000,0.0000e+000,20.00000,    -0.19571,0.66326
577.36902, 69.00750,    -1.07471,87.63264,50.00000,0.0000e+000,20.00000,    -0.19615,0.66218
579.16901, 69.18750,    -1.07735,87.59642,50.00000,0.0000e+000,20.00000,    -0.19571,0.66109
580.95898, 69.36750,    -1.07920,87.56119,50.00000,0.0000e+000,20.00000,    -0.19612,0.66002
582.75201, 69.54750,    -1.08150,87.52904,50.00000,0.0000e+000,20.00000,    -0.19707,0.65894
584.53198, 69.72750,    -1.08331,87.49696,50.00000,0.0000e+000,20.00000,    -0.19798,0.65788
586.34399, 69.90750,    -1.08720,87.46162,50.00000,0.0000e+000,20.00000,    -0.19888,0.65681
588.14502, 70.08750,    -1.09131,87.42455,50.00000,0.0000e+000,20.00000,    -0.19972,0.65574
589.96198, 70.26750,    -1.09441,87.39046,50.00000,0.0000e+000,20.00000,    -0.20016,0.65467
591.78198, 70.44750,    -1.09660,87.35543,50.00000,0.0000e+000,20.00000,    -0.20040,0.65361
593.57599, 70.62750,    -1.09853,87.31737,50.00000,0.0000e+000,20.00000,    -0.20101,0.65256
595.36499, 70.80750,    -1.10048,87.28144,50.00000,0.0000e+000,20.00000,    -0.20203,0.65152
597.18402, 70.98750,    -1.10392,87.24902,50.00000,0.0000e+000,20.00000,    -0.20306,0.65047
599.01202, 71.16750,    -1.10869,87.21342,50.00000,0.0000e+000,20.00000,    -0.20432,0.64942
600.83398, 71.34750,    -1.11221,87.17554,50.00000,0.0000e+000,20.00000,    -0.20628,0.64838
602.65198, 71.52750,    -1.11440,87.13681,50.00000,0.0000e+000,20.00000,    -0.20863,0.64734
604.47198, 71.70750,    -1.11608,87.09821,50.00000,0.0000e+000,20.00000,    -0.21033,0.64631
606.28198, 71.88750,    -1.11686,87.05995,50.00000,0.0000e+000,20.00000,    -0.21121,0.64528
608.08899, 72.06750,    -1.11784,87.02236,50.00000,0.0000e+000,20.00000,    -0.21270,0.64427
609.87598, 72.24750,    -1.11893,86.98427,50.00000,0.0000e+000,20.00000,    -0.21434,0.64326
611.66699, 72.42750,    -1.11994,86.94524,50.00000,0.0000e+000,20.00000,    -0.21514,0.64227
613.46503, 72.60750,    -1.12083,86.90571,50.00000,0.0000e+000,20.00000,    -0.21657,0.64127
615.26898, 72.78750,    -1.12330,86.86594,50.00000,0.0000e+000,20.00000,    -0.21929,0.64027
617.06097, 72.96750,    -1.12527,86.82572,50.00000,0.0000e+000,20.00000,    -0.22118,0.63928
618.86499, 73.14750,    -1.12778,86.78591,50.00000,0.0000e+000,20.00000,    -0.22229,0.63829
620.64203, 73.32750,    -1.12877,86.74575,50.00000,0.0000e+000,20.00000,    -0.22326,0.63732
622.41901, 73.50750,    -1.12944,86.70471,50.00000,0.0000e+000,20.00000,    -0.22386,0.63636
624.21002, 73.68750,    -1.13272,86.66423,50.00000,0.0000e+000,20.00000,    -0.22414,0.63539
626.01300, 73.86750,    -1.13654,86.62425,50.00000,0.0000e+000,20.00000,    -0.22473,0.63442
627.81598, 74.04750,    -1.14019,86.58386,50.00000,0.0000e+000,20.00000,    -0.22531,0.63345
629.61902, 74.22750,    -1.14388,86.54315,50.00000,0.0000e+000,20.00000,    -0.22583,0.63249
631.43298, 74.40750,    -1.14678,86.50150,50.00000,0.0000e+000,20.00000,    -0.22643,0.63152
633.22198, 74.58750,    -1.14809,86.45907,50.00000,0.0000e+000,20.00000,    -0.22696,0.63058
635.03699, 74.76750,    -1.14990,86.41703,50.00000,0.0000e+000,20.00000,    -0.22714,0.62962
636.83301, 74.94750,    -1.15177,86.37537,50.00000,0.0000e+000,20.00000,    -0.22696,0.62868
638.64301, 75.12750,    -1.15417,86.33316,50.00000,0.0000e+000,20.00000,    -0.22699,0.62773
640.46100, 75.30750,    -1.15887,86.29196,50.00000,0.0000e+000,20.00000,    -0.22650,0.62678
642.25897, 75.48750,    -1.16197,86.25255,50.00000,0.0000e+000,20.00000,    -0.22564,0.62585
644.08099, 75.66750,    -1.16551,86.21286,50.00000,0.0000e+000,20.00000,    -0.22472,0.62491
645.89099, 75.84750,    -1.16831,86.17277,50.00000,0.0000e+000,20.00000,    -0.22366,0.62398
647.72998, 76.02750,    -1.17117,86.13218,50.00000,0.0000e+000,20.00000,    -0.22274,0.62304
649.55603, 76.20750,    -1.17544,86.09053,50.00000,0.0000e+000,20.00000,    -0.22109,0.62211
651.40198, 76.38750,    -1.17877,86.04887,50.00000,0.0000e+000,20.00000,    -0.21907,0.62117
653.21100, 76.56750,    -1.18030,86.00778,50.00000,0.0000e+000,20.00000,    -0.21719,0.62026
655.02100, 76.74750,    -1.18128,85.96843,50.00000,0.0000e+000,20.00000,    -0.21555,0.61935
656.82001, 76.92750,    -1.18172,85.92848,50.00000,0.0000e+000,20.00000,    -0.21379,0.61845
658.60498, 77.10750,    -1.18257,85.88894,50.00000,0.0000e+000,20.00000,    -0.21224,0.61756
660.39899, 77.28750,    -1.18399,85.85135,50.00000,0.0000e+000,20.00000,    -0.21152,0.61667
662.16699, 77.46750,    -1.18539,85.81452,50.00000,0.0000e+000,20.00000,    -0.21022,0.61579
663.96198, 77.64750,    -1.18698,85.77827,50.00000,0.0000e+000,20.00000,    -0.20819,0.61491
665.75000, 77.82750,    -1.18782,85.74091,50.00000,0.0000e+000,20.00000,    -0.20620,0.61403
667.52600, 78.00750,    -1.19068,85.70515,50.00000,0.0000e+000,20.00000,    -0.20407,0.61316
669.31299, 78.18750,    -1.19291,85.67027,50.00000,0.0000e+000,20.00000,    -0.20188,0.61229
671.12598, 78.36750,    -1.19571,85.63499,50.00000,0.0000e+000,20.00000,    -0.19956,0.61142
672.89697, 78.54750,    -1.19753,85.59941,50.00000,0.0000e+000,20.00000,    -0.19760,0.61056
674.70697, 78.72750,    -1.20130,85.56363,50.00000,0.0000e+000,20.00000,    -0.19568,0.60969
676.50598, 78.90750,    -1.20445,85.52790,50.00000,0.0000e+000,20.00000,    -0.19383,0.60883
678.29700, 79.08750,    -1.20603,85.49108,50.00000,0.0000e+000,20.00000,    -0.19262,0.60798
680.10498, 79.26750,    -1.20864,85.45570,50.00000,0.0000e+000,20.00000,    -0.19197,0.60712
681.92603, 79.44750,    -1.21436,85.42297,50.00000,0.0000e+000,20.00000,    -0.19192,0.60626
683.77002, 79.62750,    -1.21920,85.38990,50.00000,0.0000e+000,20.00000,    -0.19169,0.60539
685.59100, 79.80750,    -1.22121,85.35624,50.00000,0.0000e+000,20.00000,    -0.19151,0.60453
687.39697, 79.98750,    -1.22113,85.32243,50.00000,0.0000e+000,20.00000,    -0.19150,0.60369
689.19800, 80.16750,    -1.22166,85.28955,50.00000,0.0000e+000,20.00000,    -0.19149,0.60285
690.98901, 80.34750,    -1.22140,85.25712,50.00000,0.0000e+000,20.00000,    -0.19140,0.60202
692.76703, 80.52750,    -1.21970,85.22447,50.00000,0.0000e+000,20.00000,    -0.19121,0.60120
694.55103, 80.70750,    -1.21901,85.19142,50.00000,0.0000e+000,20.00000,    -0.19164,0.60038
696.34698, 80.88750,    -1.21991,85.15818,50.00000,0.0000e+000,20.00000,    -0.19217,0.59956
698.17297, 81.06750,    -1.22360,85.12378,50.00000,0.0000e+000,20.00000,    -0.19272,0.59872
699.98499, 81.24750,    -1.22643,85.08804,50.00000,0.0000e+000,20.00000,    -0.19435,0.59790
701.78802, 81.42750,    -1.22619,85.05145,50.00000,0.0000e+000,20.00000,    -0.19622,0.59708
703.61401, 81.60750,    -1.22640,85.01588,50.00000,0.0000e+000,20.00000,    -0.19739,0.59626
705.41699, 81.78750,    -1.22640,84.98102,50.00000,0.0000e+000,20.00000,    -0.19806,0.59545
707.19501, 81.96750,    -1.22656,84.94589,50.00000,0.0000e+000,20.00000,    -0.19817,0.59465
709.01703, 82.14750,    -1.22564,84.91066,50.00000,0.0000e+000,20.00000,    -0.19706,0.59384
710.80200, 82.32750,    -1.22315,84.87565,50.00000,0.0000e+000,20.00000,    -0.19467,0.59305
712.59302, 82.50750,    -1.22088,84.83885,50.00000,0.0000e+000,20.00000,    -0.19097,0.59225
714.40100, 82.68750,    -1.21869,84.80020,50.00000,0.0000e+000,20.00000,    -0.18591,0.59146
716.21198, 82.86750,    -1.21805,84.76226,50.00000,0.0000e+000,20.00000,    -0.17944,0.59066
718.01898, 83.04750,    -1.21707,84.72370,50.00000,0.0000e+000,20.00000,    -0.17309,0.58987
719.82800, 83.22750,    -1.21825,84.68378,50.00000,0.0000e+000,20.00000,    -0.16645,0.58908
721.62701, 83.40750,    -1.22268,84.64566,50.00000,0.0000e+000,20.00000,    -0.15988,0.58830
723.41901, 83.58750,    -1.23090,84.60904,50.00000,0.0000e+000,20.00000,    -0.15349,0.58752
725.21399, 83.76750,    -1.24297,84.57504,50.00000,0.0000e+000,20.00000,    -0.14673,0.58675
727.02698, 83.94750,    -1.25908,84.54583,50.00000,0.0000e+000,20.00000,    -0.13901,0.58597
728.83398, 84.12750,    -1.27401,84.52131,50.00000,0.0000e+000,20.00000,    -0.13194,0.58520
730.62500, 84.30750,    -1.28511,84.50117,50.00000,0.0000e+000,20.00000,    -0.12502,0.58443
732.43201, 84.48750,    -1.29379,84.48565,50.00000,0.0000e+000,20.00000,    -0.11718,0.58366
734.26398, 84.66750,    -1.30039,84.47493,50.00000,0.0000e+000,20.00000,    -0.10905,0.58289
736.10101, 84.84750,    -1.30712,84.46290,50.00000,0.0000e+000,20.00000,    -0.10054,0.58211
737.90100, 85.02750,    -1.30860,84.45043,50.00000,0.0000e+000,20.00000,-9.2219e-002,0.58135
739.67700, 85.20750,    -1.30758,84.43867,50.00000,0.0000e+000,20.00000,-8.4432e-002,0.58061
741.46301, 85.38750,    -1.30763,84.42708,50.00000,0.0000e+000,20.00000,-7.6915e-002,0.57986
743.28198, 85.56750,    -1.30965,84.41634,50.00000,0.0000e+000,20.00000,-7.0027e-002,0.57910
745.09100, 85.74750,    -1.31349,84.40903,50.00000,0.0000e+000,20.00000,-6.4280e-002,0.57835
746.89899, 85.92750,    -1.31561,84.40045,50.00000,0.0000e+000,20.00000,-5.8965e-002,0.57760
748.68799, 86.10750,    -1.31358,84.38931,50.00000,0.0000e+000,20.00000,-5.5154e-002,0.57686
750.44202, 86.28750,    -1.30987,84.37930,50.00000,0.0000e+000,20.00000,-5.3056e-002,0.57614
752.21301, 86.46750,    -1.30635,84.37052,50.00000,0.0000e+000,20.00000,-5.2356e-002,0.57542
754.00403, 86.64750,    -1.30571,84.36349,50.00000,0.0000e+000,20.00000,-5.0934e-002,0.57468
755.80298, 86.82750,    -1.30749,84.35432,50.00000,0.0000e+000,20.00000,-4.9436e-002,0.57395
757.61798, 87.00750,    -1.31221,84.34424,50.00000,0.0000e+000,20.00000,-4.7956e-002,0.57321
759.44800, 87.18750,    -1.31530,84.33479,50.00000,0.0000e+000,20.00000,-4.6352e-002,0.57247
761.25000, 87.36750,    -1.31608,84.32554,50.00000,0.0000e+000,20.00000,-4.5658e-002,0.57175
763.07001, 87.54750,    -1.31468,84.31614,50.00000,0.0000e+000,20.00000,-4.6347e-002,0.57101
764.90900, 87.72750,    -1.31735,84.31013,50.00000,0.0000e+000,20.00000,-4.7237e-002,0.57028
766.75598, 87.90750,    -1.32087,84.30358,50.00000,0.0000e+000,20.00000,-4.7510e-002,0.56954
768.57703, 88.08750,    -1.32140,84.29513,50.00000,0.0000e+000,20.00000,-4.7651e-002,0.56881
770.36798, 88.26750,    -1.32002,84.28629,50.00000,0.0000e+000,20.00000,-4.8001e-002,0.56810
772.15900, 88.44750,    -1.31958,84.27973,50.00000,0.0000e+000,20.00000,-4.8903e-002,0.56739
773.96301, 88.62750,    -1.32147,84.27262,50.00000,0.0000e+000,20.00000,-4.9918e-002,0.56668
775.75299, 88.80750,    -1.32230,84.26610,50.00000,0.0000e+000,20.00000,-5.0717e-002,0.56598
777.52698, 88.98750,    -1.32272,84.26039,50.00000,0.0000e+000,20.00000,-5.1623e-002,0.56528
779.30798, 89.16750,    -1.32283,84.25242,50.00000,0.0000e+000,20.00000,-5.2942e-002,0.56458
781.09497, 89.34750,    -1.32568,84.24226,50.00000,0.0000e+000,20.00000,-5.4046e-002,0.56388
782.93799, 89.52750,    -1.33261,84.23119,50.00000,0.0000e+000,20.00000,-5.5625e-002,0.56317
784.76801, 89.70750,    -1.33849,84.21908,50.00000,0.0000e+000,20.00000,-5.7674e-002,0.56245
786.58197, 89.88750,    -1.34291,84.20824,50.00000,0.0000e+000,20.00000,-5.9561e-002,0.56175
788.40503, 90.06750,    -1.34448,84.19774,50.00000,0.0000e+000,20.00000,-6.1979e-002,0.56105
790.20398, 90.24750,    -1.34539,84.18763,50.00000,0.0000e+000,20.00000,-6.5803e-002,0.56036
792.00403, 90.42750,    -1.34690,84.17539,50.00000,0.0000e+000,20.00000,-6.9642e-002,0.55966
793.81201, 90.60750,    -1.34880,84.16235,50.00000,0.0000e+000,20.00000,-7.3006e-002,0.55897
795.67102, 90.78750,    -1.35803,84.14949,50.00000,0.0000e+000,20.00000,-7.6460e-002,0.55826
797.49298, 90.96750,    -1.36486,84.13576,50.00000,0.0000e+000,20.00000,-7.9900e-002,0.55757
799.29797, 91.14750,    -1.36915,84.12173,50.00000,0.0000e+000,20.00000,-8.2582e-002,0.55688
801.10199, 91.32750,    -1.37329,84.10964,50.00000,0.0000e+000,20.00000,-8.4972e-002,0.55620
802.90198, 91.50750,    -1.37672,84.09607,50.00000,0.0000e+000,20.00000,-8.7569e-002,0.55552
804.68903, 91.68750,    -1.38106,84.08128,50.00000,0.0000e+000,20.00000,-8.9968e-002,0.55484
806.46997, 91.86750,    -1.38568,84.06392,50.00000,0.0000e+000,20.00000,-9.2919e-002,0.55417
808.25800, 92.04750,    -1.39098,84.04351,50.00000,0.0000e+000,20.00000,-9.6578e-002,0.55350
810.03699, 92.22750,    -1.39685,84.02219,50.00000,0.0000e+000,20.00000,    -0.10017,0.55283
811.82599, 92.40750,    -1.40341,84.00305,50.00000,0.0000e+000,20.00000,    -0.10345,0.55216
813.63898, 92.58750,    -1.41357,83.98469,50.00000,0.0000e+000,20.00000,    -0.10682,0.55149
815.46100, 92.76750,    -1.42219,83.96498,50.00000,0.0000e+000,20.00000,    -0.11056,0.55081
817.28699, 92.94750,    -1.42940,83.94489,50.00000,0.0000e+000,20.00000,    -0.11408,0.55013
819.10400, 93.12750,    -1.43564,83.92563,50.00000,0.0000e+000,20.00000,    -0.11781,0.54946
820.86798, 93.30750,    -1.43586,83.90403,50.00000,0.0000e+000,20.00000,    -0.12125,0.54881
822.64697, 93.48750,    -1.43625,83.88400,50.00000,0.0000e+000,20.00000,    -0.12456,0.54815
824.46600, 93.66750,    -1.44051,83.86317,50.00000,0.0000e+000,20.00000,    -0.12745,0.54748
826.29498, 93.84750,    -1.44675,83.83990,50.00000,0.0000e+000,20.00000,    -0.12985,0.54681
828.15601, 94.02750,    -1.45268,83.81520,50.00000,0.0000e+000,20.00000,    -0.13173,0.54613
830.02600, 94.20750,    -1.46170,83.78995,50.00000,0.0000e+000,20.00000,    -0.13405,0.54544
831.86700, 94.38750,    -1.46338,83.76504,50.00000,0.0000e+000,20.00000,    -0.13700,0.54477
833.67902, 94.56750,    -1.46102,83.73808,50.00000,0.0000e+000,20.00000,    -0.13937,0.54411
835.46600, 94.74750,    -1.45843,83.71080,50.00000,0.0000e+000,20.00000,    -0.14175,0.54346
837.24902, 94.92750,    -1.45610,83.68485,50.00000,0.0000e+000,20.00000,    -0.14459,0.54281
839.01398, 95.10750,    -1.45355,83.65904,50.00000,0.0000e+000,20.00000,    -0.14677,0.54217
840.79498, 95.28750,    -1.45239,83.63248,50.00000,0.0000e+000,20.00000,    -0.14928,0.54153
842.59198, 95.46750,    -1.45107,83.60526,50.00000,0.0000e+000,20.00000,    -0.15176,0.54088
844.38000, 95.64750,    -1.45383,83.57658,50.00000,0.0000e+000,20.00000,    -0.15337,0.54024
846.16498, 95.82750,    -1.45772,83.54811,50.00000,0.0000e+000,20.00000,    -0.15463,0.53959
847.96503, 96.00750,    -1.46066,83.52028,50.00000,0.0000e+000,20.00000,    -0.15479,0.53895
849.76898, 96.18750,    -1.46209,83.49120,50.00000,0.0000e+000,20.00000,    -0.15534,0.53830
851.55402, 96.36750,    -1.46436,83.46299,50.00000,0.0000e+000,20.00000,    -0.15561,0.53766
853.36798, 96.54750,    -1.46748,83.43424,50.00000,0.0000e+000,20.00000,    -0.15560,0.53701
855.18201, 96.72750,    -1.47180,83.40477,50.00000,0.0000e+000,20.00000,    -0.15542,0.53636
856.98602, 96.90750,    -1.47567,83.37534,50.00000,0.0000e+000,20.00000,    -0.15573,0.53572
858.77100, 97.08750,    -1.47804,83.34591,50.00000,0.0000e+000,20.00000,    -0.15586,0.53509
860.54602, 97.26750,    -1.47673,83.31634,50.00000,0.0000e+000,20.00000,    -0.15520,0.53445
862.38098, 97.44750,    -1.47981,83.28738,50.00000,0.0000e+000,20.00000,    -0.15474,0.53380
864.32397, 97.62750,    -1.50038,83.25823,50.00000,0.0000e+000,20.00000,    -0.15455,0.53312
866.23297, 97.80750,    -1.51384,83.23182,50.00000,0.0000e+000,20.00000,    -0.15332,0.53244
868.06702, 97.98750,    -1.51547,83.20543,50.00000,0.0000e+000,20.00000,    -0.15105,0.53179
869.84802, 98.16750,    -1.51092,83.17773,50.00000,0.0000e+000,20.00000,    -0.14984,0.53116
871.59497, 98.34750,    -1.50681,83.15023,50.00000,0.0000e+000,20.00000,    -0.14863,0.53055
873.31000, 98.52750,    -1.50154,83.12455,50.00000,0.0000e+000,20.00000,    -0.14643,0.52994
874.95398, 98.70750,    -1.48806,83.09807,50.00000,0.0000e+000,20.00000,    -0.14383,0.52936
876.68597, 98.88750,    -1.48789,83.07080,50.00000,0.0000e+000,20.00000,    -0.14141,0.52876
878.48401, 99.06750,    -1.50090,83.04608,50.00000,0.0000e+000,20.00000,    -0.13944,0.52812
880.31702, 99.24750,    -1.51377,83.01971,50.00000,0.0000e+000,20.00000,    -0.13801,0.52748
882.16602, 99.42750,    -1.52793,82.99160,50.00000,0.0000e+000,20.00000,    -0.13610,0.52683
883.98602, 99.60750,    -1.53820,82.96737,50.00000,0.0000e+000,20.00000,    -0.13441,0.52620
885.82001, 99.78750,    -1.54415,82.94692,50.00000,0.0000e+000,20.00000,    -0.13307,0.52556
887.63300, 99.96750,    -1.55013,82.92341,50.00000,0.0000e+000,20.00000,    -0.13126,0.52492
889.44397,100.14750,    -1.55553,82.89899,50.00000,0.0000e+000,20.00000,    -0.12948,0.52429
891.25403,100.32750,    -1.56069,82.87721,50.00000,0.0000e+000,20.00000,    -0.12863,0.52366
893.08502,100.50750,    -1.56769,82.85718,50.00000,0.0000e+000,20.00000,    -0.12787,0.52302
894.91302,100.68750,    -1.57614,82.83683,50.00000,0.0000e+000,20.00000,    -0.12655,0.52239
896.79498,100.86750,    -1.58830,82.81475,50.00000,0.0000e+000,20.00000,    -0.12576,0.52173
898.66498,101.04750,    -1.59790,82.79100,50.00000,0.0000e+000,20.00000,    -0.12462,0.52108
900.53699,101.22750,    -1.60591,82.76841,50.00000,0.0000e+000,20.00000,    -0.12284,0.52043
902.35602,101.40750,    -1.60897,82.74758,50.00000,0.0000e+000,20.00000,    -0.12167,0.51980
904.11102,101.58750,    -1.60367,82.72654,50.00000,0.0000e+000,20.00000,    -0.12141,0.51919
905.86401,101.76750,    -1.59892,82.70533,50.00000,0.0000e+000,20.00000,    -0.12067,0.51859
907.62201,101.94750,    -1.59599,82.68449,50.00000,0.0000e+000,20.00000,    -0.11946,0.51798
909.38800,102.12750,    -1.59924,82.66182,50.00000,0.0000e+000,20.00000,    -0.11845,0.51737
911.17102,102.30750,    -1.60093,82.63843,50.00000,0.0000e+000,20.00000,    -0.11786,0.51675
912.98199,102.48750,    -1.60236,82.61568,50.00000,0.0000e+000,20.00000,    -0.11771,0.51613
914.74103,102.66750,    -1.60297,82.59351,50.00000,0.0000e+000,20.00000,    -0.11710,0.51552
916.52301,102.84750,    -1.60531,82.57179,50.00000,0.0000e+000,20.00000,    -0.11549,0.51490
918.32397,103.02750,    -1.60545,82.55011,50.00000,0.0000e+000,20.00000,    -0.11367,0.51428
920.14203,103.20750,    -1.60582,82.52901,50.00000,0.0000e+000,20.00000,    -0.11245,0.51365
921.93298,103.38750,    -1.60913,82.50943,50.00000,0.0000e+000,20.00000,    -0.11070,0.51304
923.74402,103.56750,    -1.61053,82.48927,50.00000,0.0000e+000,20.00000,    -0.10801,0.51241
925.54797,103.74750,    -1.61210,82.46898,50.00000,0.0000e+000,20.00000,    -0.10558,0.51179
927.34802,103.92750,    -1.61246,82.45011,50.00000,0.0000e+000,20.00000,    -0.10363,0.51117
929.20898,104.10750,    -1.61708,82.43229,50.00000,0.0000e+000,20.00000,    -0.10131,0.51053
931.06403,104.28750,    -1.62066,82.41281,50.00000,0.0000e+000,20.00000,-9.8752e-002,0.50989
932.87799,104.46750,    -1.61719,82.39317,50.00000,0.0000e+000,20.00000,-9.5898e-002,0.50926
934.70599,104.64750,    -1.61482,82.37510,50.00000,0.0000e+000,20.00000,-9.2570e-002,0.50863
936.52698,104.82750,    -1.61000,82.35872,50.00000,0.0000e+000,20.00000,-8.9391e-002,0.50801
938.32001,105.00750,    -1.60087,82.34222,50.00000,0.0000e+000,20.00000,-8.6739e-002,0.50739
940.08301,105.18750,    -1.58852,82.32720,50.00000,0.0000e+000,20.00000,-8.4489e-002,0.50678
941.88397,105.36750,    -1.57827,82.31535,50.00000,0.0000e+000,20.00000,-8.1595e-002,0.50616
943.67200,105.54750,    -1.56946,82.30397,50.00000,0.0000e+000,20.00000,-7.8642e-002,0.50555
945.45898,105.72750,    -1.55774,82.28899,50.00000,0.0000e+000,20.00000,-7.5401e-002,0.50493
947.26202,105.90750,    -1.55065,82.27389,50.00000,0.0000e+000,20.00000,-7.2436e-002,0.50431
949.07898,106.08750,    -1.54584,82.26016,50.00000,0.0000e+000,20.00000,-6.9647e-002,0.50369
950.90601,106.26750,    -1.54383,82.24799,50.00000,0.0000e+000,20.00000,-6.6945e-002,0.50306
952.73401,106.44750,    -1.54300,82.23818,50.00000,0.0000e+000,20.00000,-6.4157e-002,0.50243
954.55402,106.62750,    -1.54114,82.22833,50.00000,0.0000e+000,20.00000,-6.1436e-002,0.50180
956.37799,106.80750,    -1.53964,82.21694,50.00000,0.0000e+000,20.00000,-5.9102e-002,0.50117
958.17798,106.98750,    -1.53926,82.20523,50.00000,0.0000e+000,20.00000,-5.7308e-002,0.50055
959.97601,107.16750,    -1.53808,82.19556,50.00000,0.0000e+000,20.00000,-5.6543e-002,0.49993
961.77399,107.34750,    -1.53800,82.18602,50.00000,0.0000e+000,20.00000,-5.6021e-002,0.49931
963.56598,107.52750,    -1.53929,82.17819,50.00000,0.0000e+000,20.00000,-5.4305e-002,0.49870
965.37402,107.70750,    -1.53931,82.17158,50.00000,0.0000e+000,20.00000,-5.1768e-002,0.49807
967.17999,107.88750,    -1.54120,82.16277,50.00000,0.0000e+000,20.00000,-4.9398e-002,0.49745
968.97998,108.06750,    -1.54170,82.15290,50.00000,0.0000e+000,20.00000,-4.7557e-002,0.49683
970.76099,108.24750,    -1.54344,82.14426,50.00000,0.0000e+000,20.00000,-4.6546e-002,0.49621
972.57001,108.42750,    -1.54729,82.13774,50.00000,0.0000e+000,20.00000,-4.5704e-002,0.49559
974.44702,108.60750,    -1.55525,82.13001,50.00000,0.0000e+000,20.00000,-4.4385e-002,0.49494
976.32501,108.78750,    -1.56652,82.12124,50.00000,0.0000e+000,20.00000,-4.2858e-002,0.49429
978.17401,108.96750,    -1.56896,82.11179,50.00000,0.0000e+000,20.00000,-4.1834e-002,0.49365
979.97900,109.14750,    -1.56701,82.10253,50.00000,0.0000e+000,20.00000,-4.1408e-002,0.49303
981.71997,109.32750,    -1.56176,82.09406,50.00000,0.0000e+000,20.00000,-4.1564e-002,0.49242
983.47101,109.50750,    -1.55772,82.08767,50.00000,0.0000e+000,20.00000,-4.0634e-002,0.49182
985.25500,109.68750,    -1.55995,82.08249,50.00000,0.0000e+000,20.00000,-3.9991e-002,0.49120
987.05499,109.86750,    -1.56401,82.07677,50.00000,0.0000e+000,20.00000,-3.9439e-002,0.49057
988.82703,110.04750,    -1.56457,82.07051,50.00000,0.0000e+000,20.00000,-3.7090e-002,0.48996
990.59998,110.22750,    -1.56704,82.06383,50.00000,0.0000e+000,20.00000,-3.5339e-002,0.48934
992.36298,110.40750,    -1.56900,82.05754,50.00000,0.0000e+000,20.00000,-3.6956e-002,0.48873
994.16498,110.58750,    -1.57305,82.05117,50.00000,0.0000e+000,20.00000,-3.7619e-002,0.48811
995.95502,110.76750,    -1.57741,82.04508,50.00000,0.0000e+000,20.00000,-3.9221e-002,0.48748
997.79498,110.94750,    -1.58333,82.03754,50.00000,0.0000e+000,20.00000,-4.9373e-002,0.48684
998.33301,111.00250,    -1.58621,82.03468,50.00000,0.0000e+000,20.00000,-5.7760e-002,0.48665