File: book/some_content/TG_ExpDat_MgO5%DC14; 30-1-2025-2.csv
#FILE:                       ,MgO5%DC14; 30-1-2025.ngb-ds3
#FORMAT:                     ,NETZSCH5
#IDENTITY:                   ,GEOPOLYMER PASTE
#DECIMAL:                    ,POINT
#SEPARATOR:                  ,COMMA
#MTYPE:                      ,DSC
#INSTRUMENT:                 ,Microlab TU Delft
#PROJECT:                    ,
#DATE/TIME:                  ,31/01/2025 1:59:28 PM
#CORR. FILE:                 ,Blank with cover; 13-1-2025.ngb-bs3
#LABORATORY:                 ,TU Delft Micro Lab
#OPERATOR:                   ,Ahmed
#REMARK:                     ,under Argon atmosphere, 10K/min
#SAMPLE:                     ,MgO5%DC14
#SAMPLE MASS /mg:            ,39
#MATERIAL:                   ,Geopolymer paste
#REFERENCE:                  ,blank
#REFERENCE MASS /mg:         ,0
#TYPE OF CRUCIBLE:           ,DSC/TG pan Al2O3
#SAMPLE CRUCIBLE MASS /mg:   ,0
#REFERENCE CRUCIBLE MASS /mg:,0
#CORR. CODE:                 ,020
#EXO:                        ,-1
#RANGE:                      ,40/10.0(K/min)/1000
#SEGMENT:                    ,S2/2

##Temp./øC,Time/min,DSC/(mW/mg),Mass/%,Gas Flow(purge1)/(ml/min),Gas Flow(purge2)/(ml/min),Gas Flow(protective)/(ml/min),DTG/(%/min),Sensit./(uV/mW)
 40.61100, 15.02417, 3.4878e-002,97.54270,50.00000,0.0000e+000,20.00000,    -0.12003,1.22610
 40.63300, 15.20417, 3.4560e-002,97.52720,50.00000,0.0000e+000,20.00000,-8.5579e-002,1.22607
 40.67800, 15.38417, 3.4067e-002,97.51298,50.00000,0.0000e+000,20.00000,-8.8510e-002,1.22601
 40.73400, 15.56417, 3.4005e-002,97.49681,50.00000,0.0000e+000,20.00000,-9.0416e-002,1.22593
 40.87000, 15.74417, 3.3899e-002,97.48010,50.00000,0.0000e+000,20.00000,-8.8431e-002,1.22574
 41.04500, 15.92417, 3.4272e-002,97.46250,50.00000,0.0000e+000,20.00000,-8.8402e-002,1.22550
 41.27500, 16.10417, 3.4728e-002,97.44579,50.00000,0.0000e+000,20.00000,-8.8382e-002,1.22518
 41.56300, 16.28417, 3.5650e-002,97.43177,50.00000,0.0000e+000,20.00000,-8.9127e-002,1.22479
 41.93300, 16.46417, 3.7279e-002,97.41640,50.00000,0.0000e+000,20.00000,-9.0636e-002,1.22428
 42.41200, 16.64417, 3.8738e-002,97.39988,50.00000,0.0000e+000,20.00000,-9.1847e-002,1.22362
 42.94600, 16.82417, 4.0889e-002,97.38440,50.00000,0.0000e+000,20.00000,-9.5678e-002,1.22288
 43.57000, 17.00417, 4.3335e-002,97.36942,50.00000,0.0000e+000,20.00000,-9.8064e-002,1.22202
 44.27000, 17.18417, 4.5868e-002,97.35286,50.00000,0.0000e+000,20.00000,    -0.10116,1.22106
 45.06900, 17.36417, 4.9085e-002,97.33663,50.00000,0.0000e+000,20.00000,    -0.10476,1.21995
 45.95600, 17.54417, 5.1798e-002,97.31939,50.00000,0.0000e+000,20.00000,    -0.10907,1.21873
 46.90200, 17.72417, 5.5293e-002,97.30070,50.00000,0.0000e+000,20.00000,    -0.11352,1.21743
 47.94600, 17.90417, 5.8817e-002,97.28275,50.00000,0.0000e+000,20.00000,    -0.11876,1.21599
 49.06500, 18.08417, 6.2564e-002,97.26547,50.00000,0.0000e+000,20.00000,    -0.12579,1.21445
 50.26200, 18.26417, 6.6230e-002,97.24654,50.00000,0.0000e+000,20.00000,    -0.13410,1.21280
 51.54800, 18.44417, 7.0075e-002,97.22477,50.00000,0.0000e+000,20.00000,    -0.14329,1.21103
 52.89800, 18.62417, 7.4389e-002,97.20013,50.00000,0.0000e+000,20.00000,    -0.15335,1.20917
 54.34000, 18.80417, 7.8287e-002,97.17469,50.00000,0.0000e+000,20.00000,    -0.16437,1.20719
 55.87000, 18.98417, 8.2790e-002,97.14961,50.00000,0.0000e+000,20.00000,    -0.17665,1.20508
 57.45400, 19.16417, 8.7266e-002,97.12121,50.00000,0.0000e+000,20.00000,    -0.19150,1.20290
 59.11500, 19.34417, 9.2043e-002,97.08902,50.00000,0.0000e+000,20.00000,    -0.20885,1.20062
 60.83800, 19.52417, 9.7270e-002,97.05565,50.00000,0.0000e+000,20.00000,    -0.22745,1.19825
 62.63400, 19.70417,     0.10221,97.01975,50.00000,0.0000e+000,20.00000,    -0.24699,1.19578
 64.49200, 19.88417,     0.10781,96.98058,50.00000,0.0000e+000,20.00000,    -0.26733,1.19323
 66.41800, 20.06417,     0.11367,96.93605,50.00000,0.0000e+000,20.00000,    -0.28765,1.19059
 68.40100, 20.24417,     0.12048,96.88650,50.00000,0.0000e+000,20.00000,    -0.30784,1.18787
 70.44000, 20.42417,     0.12679,96.83432,50.00000,0.0000e+000,20.00000,    -0.32913,1.18507
 72.52900, 20.60417,     0.13398,96.77977,50.00000,0.0000e+000,20.00000,    -0.35126,1.18221
 74.66800, 20.78417,     0.14153,96.71965,50.00000,0.0000e+000,20.00000,    -0.37420,1.17928
 76.86200, 20.96417,     0.14940,96.65065,50.00000,0.0000e+000,20.00000,    -0.39788,1.17628
 79.08700, 21.14417,     0.15787,96.57162,50.00000,0.0000e+000,20.00000,    -0.42095,1.17324
 81.35300, 21.32417,     0.16579,96.48569,50.00000,0.0000e+000,20.00000,    -0.44414,1.17014
 83.65500, 21.50417,     0.17425,96.39650,50.00000,0.0000e+000,20.00000,    -0.46733,1.16700
 85.98500, 21.68417,     0.18285,96.30515,50.00000,0.0000e+000,20.00000,    -0.48974,1.16382
 88.35800, 21.86417,     0.19136,96.21247,50.00000,0.0000e+000,20.00000,    -0.51028,1.16059
 90.75600, 22.04417,     0.19910,96.11804,50.00000,0.0000e+000,20.00000,    -0.52942,1.15732
 93.18000, 22.22417,     0.20705,96.01706,50.00000,0.0000e+000,20.00000,    -0.54917,1.15403
 95.60900, 22.40417,     0.21435,95.91102,50.00000,0.0000e+000,20.00000,    -0.56717,1.15073
 98.05200, 22.58417,     0.22079,95.80280,50.00000,0.0000e+000,20.00000,    -0.58261,1.14741
100.51200, 22.76417,     0.22709,95.68933,50.00000,0.0000e+000,20.00000,    -0.59565,1.14408
102.97400, 22.94417,     0.23213,95.57325,50.00000,0.0000e+000,20.00000,    -0.60524,1.14075
105.46200, 23.12417,     0.23637,95.45573,50.00000,0.0000e+000,20.00000,    -0.61216,1.13738
107.92700, 23.30417,     0.23948,95.33577,50.00000,0.0000e+000,20.00000,    -0.61847,1.13406
110.41400, 23.48417,     0.24146,95.21515,50.00000,0.0000e+000,20.00000,    -0.62329,1.13070
112.87900, 23.66417,     0.24276,95.09620,50.00000,0.0000e+000,20.00000,    -0.62644,1.12738
115.35400, 23.84417,     0.24280,94.97770,50.00000,0.0000e+000,20.00000,    -0.62893,1.12406
117.81400, 24.02417,     0.24161,94.85422,50.00000,0.0000e+000,20.00000,    -0.62980,1.12075
120.29600, 24.20417,     0.23949,94.73311,50.00000,0.0000e+000,20.00000,    -0.62773,1.11743
122.76400, 24.38417,     0.23652,94.61756,50.00000,0.0000e+000,20.00000,    -0.62481,1.11412
125.23700, 24.56417,     0.23250,94.50224,50.00000,0.0000e+000,20.00000,    -0.61982,1.11082
127.70100, 24.74417,     0.22768,94.38903,50.00000,0.0000e+000,20.00000,    -0.61328,1.10753
130.15800, 24.92417,     0.22244,94.27866,50.00000,0.0000e+000,20.00000,    -0.60614,1.10425
132.60001, 25.10417,     0.21609,94.16676,50.00000,0.0000e+000,20.00000,    -0.59757,1.10101
135.01500, 25.28417,     0.20940,94.05738,50.00000,0.0000e+000,20.00000,    -0.58806,1.09780
137.42300, 25.46417,     0.20183,93.95269,50.00000,0.0000e+000,20.00000,    -0.57841,1.09461
139.82001, 25.64417,     0.19384,93.84991,50.00000,0.0000e+000,20.00000,    -0.56815,1.09144
142.21400, 25.82417,     0.18531,93.74642,50.00000,0.0000e+000,20.00000,    -0.55608,1.08827
144.55299, 26.00417,     0.17656,93.64783,50.00000,0.0000e+000,20.00000,    -0.54286,1.08519
146.89600, 26.18417,     0.16703,93.55069,50.00000,0.0000e+000,20.00000,    -0.53034,1.08210
149.20399, 26.36417,     0.15790,93.45569,50.00000,0.0000e+000,20.00000,    -0.51740,1.07907
151.50600, 26.54417,     0.14798,93.36352,50.00000,0.0000e+000,20.00000,    -0.50436,1.07605
153.77000, 26.72417,     0.13828,93.27217,50.00000,0.0000e+000,20.00000,    -0.49223,1.07309
156.03400, 26.90417,     0.12882,93.18340,50.00000,0.0000e+000,20.00000,    -0.47856,1.07013
158.24200, 27.08417,     0.11909,93.09719,50.00000,0.0000e+000,20.00000,    -0.46404,1.06725
160.47701, 27.26417,     0.10866,93.01276,50.00000,0.0000e+000,20.00000,    -0.45127,1.06434
162.65300, 27.44417, 9.7526e-002,92.93162,50.00000,0.0000e+000,20.00000,    -0.43832,1.06151
164.81400, 27.62417, 8.6347e-002,92.85258,50.00000,0.0000e+000,20.00000,    -0.42386,1.05871
166.98000, 27.80417, 7.4459e-002,92.77785,50.00000,0.0000e+000,20.00000,    -0.41067,1.05590
169.09500, 27.98417, 6.2486e-002,92.70737,50.00000,0.0000e+000,20.00000,    -0.39740,1.05317
171.20200, 28.16417, 5.0450e-002,92.63894,50.00000,0.0000e+000,20.00000,    -0.38347,1.05045
173.28700, 28.34417, 3.8798e-002,92.57269,50.00000,0.0000e+000,20.00000,    -0.37013,1.04777
175.35001, 28.52417, 2.7048e-002,92.50652,50.00000,0.0000e+000,20.00000,    -0.35685,1.04512
177.38600, 28.70417, 1.5425e-002,92.44361,50.00000,0.0000e+000,20.00000,    -0.34406,1.04251
179.42999, 28.88417, 4.0634e-003,92.38651,50.00000,0.0000e+000,20.00000,    -0.33187,1.03989
181.43500, 29.06417,-6.6382e-003,92.32797,50.00000,0.0000e+000,20.00000,    -0.31978,1.03733
183.41400, 29.24417,-1.6825e-002,92.27172,50.00000,0.0000e+000,20.00000,    -0.30781,1.03480
185.40199, 29.42417,-2.7498e-002,92.22052,50.00000,0.0000e+000,20.00000,    -0.29601,1.03227
187.35201, 29.60417,-3.7537e-002,92.16949,50.00000,0.0000e+000,20.00000,    -0.28462,1.02980
189.29100, 29.78417,-4.7510e-002,92.12012,50.00000,0.0000e+000,20.00000,    -0.27367,1.02734
191.21400, 29.96417,-5.7700e-002,92.07503,50.00000,0.0000e+000,20.00000,    -0.26302,1.02491
193.12300, 30.14417,-6.7594e-002,92.03140,50.00000,0.0000e+000,20.00000,    -0.25329,1.02250
195.02600, 30.32417,-7.7514e-002,91.98822,50.00000,0.0000e+000,20.00000,    -0.24375,1.02010
196.89799, 30.50417,-8.7515e-002,91.94569,50.00000,0.0000e+000,20.00000,    -0.23436,1.01774
198.75700, 30.68417,-9.7137e-002,91.90371,50.00000,0.0000e+000,20.00000,    -0.22648,1.01541
200.61900, 30.86417,    -0.10667,91.86263,50.00000,0.0000e+000,20.00000,    -0.21790,1.01308
202.47400, 31.04417,    -0.11642,91.82452,50.00000,0.0000e+000,20.00000,    -0.20906,1.01076
204.32001, 31.22417,    -0.12555,91.78797,50.00000,0.0000e+000,20.00000,    -0.20168,1.00846
206.13400, 31.40417,    -0.13456,91.75363,50.00000,0.0000e+000,20.00000,    -0.19474,1.00620
207.96001, 31.58417,    -0.14344,91.72229,50.00000,0.0000e+000,20.00000,    -0.18786,1.00393
209.78101, 31.76417,    -0.15220,91.69253,50.00000,0.0000e+000,20.00000,    -0.18170,1.00167
211.57201, 31.94417,    -0.16036,91.66174,50.00000,0.0000e+000,20.00000,    -0.17649,0.99945
213.39400, 32.12417,    -0.16859,91.63045,50.00000,0.0000e+000,20.00000,    -0.17110,0.99720
215.17300, 32.30416,    -0.17665,91.60053,50.00000,0.0000e+000,20.00000,    -0.16524,0.99501
216.94701, 32.48417,    -0.18417,91.57178,50.00000,0.0000e+000,20.00000,    -0.15900,0.99283
218.72900, 32.66417,    -0.19177,91.54445,50.00000,0.0000e+000,20.00000,    -0.15338,0.99064
220.47701, 32.84417,    -0.19935,91.51953,50.00000,0.0000e+000,20.00000,    -0.14916,0.98850
222.25301, 33.02417,    -0.20704,91.49491,50.00000,0.0000e+000,20.00000,    -0.14487,0.98633
224.01199, 33.20417,    -0.21439,91.46946,50.00000,0.0000e+000,20.00000,    -0.14122,0.98418
225.73100, 33.38417,    -0.22162,91.44441,50.00000,0.0000e+000,20.00000,    -0.13809,0.98209
227.48700, 33.56417,    -0.22887,91.42118,50.00000,0.0000e+000,20.00000,    -0.13549,0.97996
229.21100, 33.74417,    -0.23636,91.39683,50.00000,0.0000e+000,20.00000,    -0.13286,0.97787
230.96001, 33.92417,    -0.24415,91.37283,50.00000,0.0000e+000,20.00000,    -0.12963,0.97575
232.69800, 34.10417,    -0.25157,91.35126,50.00000,0.0000e+000,20.00000,    -0.12667,0.97366
234.43900, 34.28417,    -0.25918,91.33193,50.00000,0.0000e+000,20.00000,    -0.12393,0.97156
236.17799, 34.46417,    -0.26670,91.31152,50.00000,0.0000e+000,20.00000,    -0.12140,0.96947
237.90300, 34.64417,    -0.27372,91.28849,50.00000,0.0000e+000,20.00000,    -0.11921,0.96740
239.63100, 34.82417,    -0.28083,91.26708,50.00000,0.0000e+000,20.00000,    -0.11739,0.96534
241.34801, 35.00417,    -0.28758,91.24582,50.00000,0.0000e+000,20.00000,    -0.11508,0.96329
243.08900, 35.18417,    -0.29504,91.22516,50.00000,0.0000e+000,20.00000,    -0.11253,0.96121
244.80299, 35.36417,    -0.30217,91.20512,50.00000,0.0000e+000,20.00000,    -0.11036,0.95918
246.55299, 35.54417,    -0.30937,91.18400,50.00000,0.0000e+000,20.00000,    -0.10804,0.95710
248.26601, 35.72417,    -0.31601,91.16432,50.00000,0.0000e+000,20.00000,    -0.10587,0.95507
249.99800, 35.90417,    -0.32245,91.14496,50.00000,0.0000e+000,20.00000,    -0.10431,0.95303
251.72000, 36.08417,    -0.32894,91.12601,50.00000,0.0000e+000,20.00000,    -0.10345,0.95100
253.44600, 36.26417,    -0.33577,91.10747,50.00000,0.0000e+000,20.00000,    -0.10202,0.94898
255.15401, 36.44417,    -0.34265,91.09016,50.00000,0.0000e+000,20.00000,-9.9857e-002,0.94697
256.88000, 36.62417,    -0.34978,91.07240,50.00000,0.0000e+000,20.00000,-9.8404e-002,0.94496
258.59799, 36.80416,    -0.35710,91.05523,50.00000,0.0000e+000,20.00000,-9.7146e-002,0.94295
260.32401, 36.98417,    -0.36470,91.03923,50.00000,0.0000e+000,20.00000,-9.5916e-002,0.94094
262.04901, 37.16417,    -0.37159,91.02366,50.00000,0.0000e+000,20.00000,-9.4852e-002,0.93894
263.77701, 37.34417,    -0.37931,91.00822,50.00000,0.0000e+000,20.00000,-9.3213e-002,0.93694
265.52100, 37.52417,    -0.38618,90.99187,50.00000,0.0000e+000,20.00000,-9.1707e-002,0.93493
267.25000, 37.70417,    -0.39321,90.97565,50.00000,0.0000e+000,20.00000,-9.0295e-002,0.93293
268.98300, 37.88417,    -0.39995,90.95915,50.00000,0.0000e+000,20.00000,-8.9224e-002,0.93094
270.71399, 38.06417,    -0.40649,90.94413,50.00000,0.0000e+000,20.00000,-8.8564e-002,0.92896
272.45001, 38.24417,    -0.41386,90.92944,50.00000,0.0000e+000,20.00000,-8.8105e-002,0.92697
274.20001, 38.42417,    -0.42000,90.91310,50.00000,0.0000e+000,20.00000,-8.7416e-002,0.92498
275.92599, 38.60417,    -0.42687,90.89659,50.00000,0.0000e+000,20.00000,-8.7101e-002,0.92301
277.68799, 38.78417,    -0.43362,90.88011,50.00000,0.0000e+000,20.00000,-8.7919e-002,0.92101
279.43701, 38.96417,    -0.44028,90.86401,50.00000,0.0000e+000,20.00000,-8.8817e-002,0.91903
281.20099, 39.14417,    -0.44683,90.84873,50.00000,0.0000e+000,20.00000,-8.9323e-002,0.91704
282.94800, 39.32417,    -0.45309,90.83423,50.00000,0.0000e+000,20.00000,-8.9669e-002,0.91507
284.69000, 39.50417,    -0.45920,90.82010,50.00000,0.0000e+000,20.00000,-9.0363e-002,0.91312
286.45099, 39.68417,    -0.46442,90.80516,50.00000,0.0000e+000,20.00000,-9.0880e-002,0.91115
288.21500, 39.86417,    -0.46997,90.78902,50.00000,0.0000e+000,20.00000,-9.2128e-002,0.90918
289.95901, 40.04417,    -0.47501,90.77311,50.00000,0.0000e+000,20.00000,-9.3660e-002,0.90723
291.71799, 40.22417,    -0.47986,90.75795,50.00000,0.0000e+000,20.00000,-9.4531e-002,0.90528
293.45801, 40.40417,    -0.48480,90.74208,50.00000,0.0000e+000,20.00000,-9.5339e-002,0.90335
295.20700, 40.58417,    -0.48984,90.72332,50.00000,0.0000e+000,20.00000,-9.6195e-002,0.90142
296.97400, 40.76417,    -0.49575,90.70413,50.00000,0.0000e+000,20.00000,-9.7307e-002,0.89947
298.72501, 40.94417,    -0.50217,90.68673,50.00000,0.0000e+000,20.00000,-9.8932e-002,0.89755
300.49200, 41.12417,    -0.50738,90.66946,50.00000,0.0000e+000,20.00000,    -0.10084,0.89561
302.24600, 41.30416,    -0.51252,90.65069,50.00000,0.0000e+000,20.00000,    -0.10300,0.89369
304.01401, 41.48417,    -0.51639,90.63233,50.00000,0.0000e+000,20.00000,    -0.10527,0.89177
305.76300, 41.66417,    -0.52055,90.61273,50.00000,0.0000e+000,20.00000,    -0.10723,0.88987
307.51999, 41.84417,    -0.52477,90.59245,50.00000,0.0000e+000,20.00000,    -0.10918,0.88796
309.27802, 42.02417,    -0.52868,90.57310,50.00000,0.0000e+000,20.00000,    -0.11156,0.88607
311.04700, 42.20417,    -0.53292,90.55362,50.00000,0.0000e+000,20.00000,    -0.11438,0.88416
312.80301, 42.38417,    -0.53727,90.53404,50.00000,0.0000e+000,20.00000,    -0.11690,0.88227
314.55301, 42.56417,    -0.54186,90.51395,50.00000,0.0000e+000,20.00000,    -0.11937,0.88040
316.32700, 42.74417,    -0.54675,90.49270,50.00000,0.0000e+000,20.00000,    -0.12243,0.87851
318.08301, 42.92417,    -0.55097,90.47114,50.00000,0.0000e+000,20.00000,    -0.12592,0.87664
319.86301, 43.10417,    -0.55469,90.44924,50.00000,0.0000e+000,20.00000,    -0.12939,0.87475
321.62100, 43.28417,    -0.55939,90.42634,50.00000,0.0000e+000,20.00000,    -0.13332,0.87289
323.40500, 43.46417,    -0.56352,90.40309,50.00000,0.0000e+000,20.00000,    -0.13707,0.87100
325.17499, 43.64417,    -0.56805,90.38005,50.00000,0.0000e+000,20.00000,    -0.14097,0.86914
326.95099, 43.82417,    -0.57155,90.35622,50.00000,0.0000e+000,20.00000,    -0.14596,0.86728
328.74799, 44.00417,    -0.57575,90.33071,50.00000,0.0000e+000,20.00000,    -0.15141,0.86540
330.51700, 44.18417,    -0.57861,90.30332,50.00000,0.0000e+000,20.00000,    -0.15764,0.86356
332.30801, 44.36417,    -0.58184,90.27504,50.00000,0.0000e+000,20.00000,    -0.16449,0.86170
334.10001, 44.54417,    -0.58412,90.24627,50.00000,0.0000e+000,20.00000,    -0.17143,0.85984
335.87500, 44.72417,    -0.58678,90.21662,50.00000,0.0000e+000,20.00000,    -0.17942,0.85801
337.65900, 44.90417,    -0.58808,90.18553,50.00000,0.0000e+000,20.00000,    -0.18835,0.85617
339.44199, 45.08417,    -0.58909,90.15293,50.00000,0.0000e+000,20.00000,    -0.19677,0.85434
341.22198, 45.26417,    -0.58994,90.11990,50.00000,0.0000e+000,20.00000,    -0.20564,0.85252
343.00800, 45.44417,    -0.59101,90.08575,50.00000,0.0000e+000,20.00000,    -0.21545,0.85070
344.77301, 45.62417,    -0.59033,90.04843,50.00000,0.0000e+000,20.00000,    -0.22472,0.84891
346.53101, 45.80416,    -0.58926,90.00939,50.00000,0.0000e+000,20.00000,    -0.23325,0.84713
348.32800, 45.98417,    -0.58812,89.96753,50.00000,0.0000e+000,20.00000,    -0.24160,0.84531
350.07199, 46.16417,    -0.58723,89.92289,50.00000,0.0000e+000,20.00000,    -0.25057,0.84356
351.86301, 46.34417,    -0.58679,89.87666,50.00000,0.0000e+000,20.00000,    -0.25870,0.84176
353.63800, 46.52417,    -0.58670,89.82679,50.00000,0.0000e+000,20.00000,    -0.26616,0.83999
355.41501, 46.70417,    -0.58724,89.77250,50.00000,0.0000e+000,20.00000,    -0.27354,0.83822
357.17899, 46.88417,    -0.58777,89.71889,50.00000,0.0000e+000,20.00000,    -0.28074,0.83647
358.96701, 47.06417,    -0.58810,89.66380,50.00000,0.0000e+000,20.00000,    -0.28805,0.83470
360.72601, 47.24417,    -0.58890,89.60511,50.00000,0.0000e+000,20.00000,    -0.29507,0.83296
362.51501, 47.42417,    -0.59095,89.54723,50.00000,0.0000e+000,20.00000,    -0.30052,0.83120
364.29199, 47.60417,    -0.59370,89.49086,50.00000,0.0000e+000,20.00000,    -0.30482,0.82946
366.07101, 47.78417,    -0.59662,89.43357,50.00000,0.0000e+000,20.00000,    -0.30848,0.82772
367.85101, 47.96417,    -0.60031,89.37287,50.00000,0.0000e+000,20.00000,    -0.31075,0.82599
369.64001, 48.14417,    -0.60497,89.31383,50.00000,0.0000e+000,20.00000,    -0.31190,0.82425
371.41400, 48.32417,    -0.60968,89.25717,50.00000,0.0000e+000,20.00000,    -0.31214,0.82254
373.19299, 48.50417,    -0.61548,89.19948,50.00000,0.0000e+000,20.00000,    -0.31088,0.82082
374.97800, 48.68417,    -0.62219,89.14093,50.00000,0.0000e+000,20.00000,    -0.30946,0.81911
376.76801, 48.86417,    -0.62893,89.08127,50.00000,0.0000e+000,20.00000,    -0.30764,0.81740
378.55801, 49.04417,    -0.63650,89.02166,50.00000,0.0000e+000,20.00000,    -0.30454,0.81569
380.34201, 49.22417,    -0.64429,88.96430,50.00000,0.0000e+000,20.00000,    -0.30141,0.81400
382.13400, 49.40417,    -0.65238,88.90971,50.00000,0.0000e+000,20.00000,    -0.29831,0.81230
383.92300, 49.58417,    -0.66159,88.85492,50.00000,0.0000e+000,20.00000,    -0.29461,0.81061
385.70999, 49.76417,    -0.67058,88.80188,50.00000,0.0000e+000,20.00000,    -0.28964,0.80893
387.50000, 49.94417,    -0.68050,88.75147,50.00000,0.0000e+000,20.00000,    -0.28400,0.80725
389.31699, 50.12417,    -0.69094,88.70152,50.00000,0.0000e+000,20.00000,    -0.27867,0.80556
391.09900, 50.30416,    -0.70115,88.65203,50.00000,0.0000e+000,20.00000,    -0.27341,0.80390
392.88699, 50.48417,    -0.71104,88.60336,50.00000,0.0000e+000,20.00000,    -0.26849,0.80224
394.67401, 50.66417,    -0.72005,88.55532,50.00000,0.0000e+000,20.00000,    -0.26341,0.80059
396.47601, 50.84417,    -0.72946,88.50823,50.00000,0.0000e+000,20.00000,    -0.25810,0.79893
398.25900, 51.02417,    -0.73863,88.46135,50.00000,0.0000e+000,20.00000,    -0.25343,0.79730
400.04901, 51.20417,    -0.74785,88.41592,50.00000,0.0000e+000,20.00000,    -0.24940,0.79566
401.84299, 51.38417,    -0.75665,88.37225,50.00000,0.0000e+000,20.00000,    -0.24521,0.79403
403.63101, 51.56417,    -0.76467,88.32988,50.00000,0.0000e+000,20.00000,    -0.24205,0.79241
405.43100, 51.74417,    -0.77257,88.29031,50.00000,0.0000e+000,20.00000,    -0.24037,0.79078
407.20801, 51.92417,    -0.78073,88.25307,50.00000,0.0000e+000,20.00000,    -0.23830,0.78919
409.00900, 52.10417,    -0.78944,88.21500,50.00000,0.0000e+000,20.00000,    -0.23596,0.78757
410.80399, 52.28417,    -0.79739,88.17487,50.00000,0.0000e+000,20.00000,    -0.23473,0.78597
412.60800, 52.46417,    -0.80426,88.13387,50.00000,0.0000e+000,20.00000,    -0.23342,0.78436
414.39200, 52.64417,    -0.81049,88.09348,50.00000,0.0000e+000,20.00000,    -0.23193,0.78278
416.17599, 52.82417,    -0.81583,88.05278,50.00000,0.0000e+000,20.00000,    -0.23082,0.78120
417.95300, 53.00417,    -0.82050,88.01252,50.00000,0.0000e+000,20.00000,    -0.23044,0.77964
419.72601, 53.18417,    -0.82609,87.97312,50.00000,0.0000e+000,20.00000,    -0.23043,0.77809
421.51199, 53.36417,    -0.83206,87.93171,50.00000,0.0000e+000,20.00000,    -0.23049,0.77653
423.29300, 53.54417,    -0.83809,87.88737,50.00000,0.0000e+000,20.00000,    -0.23121,0.77498
425.07700, 53.72417,    -0.84444,87.84436,50.00000,0.0000e+000,20.00000,    -0.23295,0.77343
426.88699, 53.90417,    -0.85084,87.80356,50.00000,0.0000e+000,20.00000,    -0.23421,0.77187
428.67200, 54.08417,    -0.85807,87.75970,50.00000,0.0000e+000,20.00000,    -0.23473,0.77033
430.46701, 54.26417,    -0.86399,87.71587,50.00000,0.0000e+000,20.00000,    -0.23530,0.76879
432.25201, 54.44417,    -0.86907,87.67408,50.00000,0.0000e+000,20.00000,    -0.23679,0.76727
434.03799, 54.62417,    -0.87268,87.63150,50.00000,0.0000e+000,20.00000,    -0.23877,0.76575
435.81100, 54.80416,    -0.87583,87.58726,50.00000,0.0000e+000,20.00000,    -0.24081,0.76425
437.58099, 54.98417,    -0.87983,87.54323,50.00000,0.0000e+000,20.00000,    -0.24358,0.76276
439.35800, 55.16417,    -0.88518,87.50031,50.00000,0.0000e+000,20.00000,    -0.24616,0.76126
441.14200, 55.34417,    -0.89124,87.45765,50.00000,0.0000e+000,20.00000,    -0.24686,0.75977
442.92001, 55.52417,    -0.89693,87.41399,50.00000,0.0000e+000,20.00000,    -0.24772,0.75829
444.72198, 55.70417,    -0.90344,87.37125,50.00000,0.0000e+000,20.00000,    -0.24975,0.75679
446.51300, 55.88417,    -0.90902,87.32960,50.00000,0.0000e+000,20.00000,    -0.25073,0.75531
448.30499, 56.06417,    -0.91446,87.28682,50.00000,0.0000e+000,20.00000,    -0.25182,0.75383
450.08499, 56.24417,    -0.91964,87.24140,50.00000,0.0000e+000,20.00000,    -0.25449,0.75237
451.88101, 56.42417,    -0.92339,87.19364,50.00000,0.0000e+000,20.00000,    -0.25707,0.75090
453.67200, 56.60417,    -0.92808,87.14579,50.00000,0.0000e+000,20.00000,    -0.25854,0.74944
455.46100, 56.78417,    -0.93297,87.09665,50.00000,0.0000e+000,20.00000,    -0.26053,0.74799
457.27200, 56.96417,    -0.93834,87.04599,50.00000,0.0000e+000,20.00000,    -0.26346,0.74653
459.05499, 57.14417,    -0.94358,86.99893,50.00000,0.0000e+000,20.00000,    -0.26631,0.74510
460.85501, 57.32417,    -0.94970,86.95254,50.00000,0.0000e+000,20.00000,    -0.26854,0.74365
462.68600, 57.50417,    -0.95924,86.90439,50.00000,0.0000e+000,20.00000,    -0.27063,0.74219
464.54800, 57.68417,    -0.96823,86.85729,50.00000,0.0000e+000,20.00000,    -0.27380,0.74071
466.37701, 57.86417,    -0.97420,86.80957,50.00000,0.0000e+000,20.00000,    -0.27706,0.73927
468.19199, 58.04417,    -0.97734,86.75833,50.00000,0.0000e+000,20.00000,    -0.27977,0.73784
470.00000, 58.22417,    -0.97773,86.70624,50.00000,0.0000e+000,20.00000,    -0.28187,0.73642
471.79599, 58.40417,    -0.97782,86.65668,50.00000,0.0000e+000,20.00000,    -0.28349,0.73501
473.56900, 58.58417,    -0.97832,86.60572,50.00000,0.0000e+000,20.00000,    -0.28498,0.73363
475.34500, 58.76417,    -0.97973,86.55207,50.00000,0.0000e+000,20.00000,    -0.28577,0.73226
477.11899, 58.94417,    -0.98275,86.49890,50.00000,0.0000e+000,20.00000,    -0.28769,0.73089
478.88501, 59.12417,    -0.98640,86.44689,50.00000,0.0000e+000,20.00000,    -0.29074,0.72953
480.65701, 59.30416,    -0.99127,86.39640,50.00000,0.0000e+000,20.00000,    -0.29330,0.72817
482.44400, 59.48417,    -0.99574,86.34352,50.00000,0.0000e+000,20.00000,    -0.29626,0.72681
484.22198, 59.66417,    -1.00070,86.28914,50.00000,0.0000e+000,20.00000,    -0.29921,0.72546
485.99100, 59.84417,    -1.00600,86.23444,50.00000,0.0000e+000,20.00000,    -0.30059,0.72412
487.76599, 60.02417,    -1.01114,86.17908,50.00000,0.0000e+000,20.00000,    -0.30154,0.72279
489.55499, 60.20417,    -1.01622,86.12518,50.00000,0.0000e+000,20.00000,    -0.30386,0.72145
491.34698, 60.38417,    -1.02082,86.07101,50.00000,0.0000e+000,20.00000,    -0.30645,0.72011
493.11801, 60.56417,    -1.02555,86.01728,50.00000,0.0000e+000,20.00000,    -0.30732,0.71879
494.90799, 60.74417,    -1.03034,85.96295,50.00000,0.0000e+000,20.00000,    -0.30772,0.71746
496.69800, 60.92417,    -1.03516,85.90596,50.00000,0.0000e+000,20.00000,    -0.30876,0.71614
498.48199, 61.10417,    -1.04059,85.84848,50.00000,0.0000e+000,20.00000,    -0.31032,0.71483
500.29599, 61.28417,    -1.04853,85.79058,50.00000,0.0000e+000,20.00000,    -0.31185,0.71351
502.10199, 61.46417,    -1.05642,85.73217,50.00000,0.0000e+000,20.00000,    -0.31308,0.71219
503.89999, 61.64417,    -1.06202,85.67612,50.00000,0.0000e+000,20.00000,    -0.31401,0.71089
505.69699, 61.82417,    -1.06482,85.62059,50.00000,0.0000e+000,20.00000,    -0.31478,0.70959
507.50101, 62.00417,    -1.06826,85.56266,50.00000,0.0000e+000,20.00000,    -0.31540,0.70829
509.28101, 62.18417,    -1.07090,85.50279,50.00000,0.0000e+000,20.00000,    -0.31638,0.70702
511.06799, 62.36417,    -1.07439,85.44534,50.00000,0.0000e+000,20.00000,    -0.31790,0.70575
512.86298, 62.54417,    -1.07864,85.39082,50.00000,0.0000e+000,20.00000,    -0.31901,0.70447
514.65399, 62.72417,    -1.08336,85.33466,50.00000,0.0000e+000,20.00000,    -0.31927,0.70321
516.43701, 62.90417,    -1.08778,85.27868,50.00000,0.0000e+000,20.00000,    -0.31908,0.70195
518.23700, 63.08417,    -1.09353,85.22092,50.00000,0.0000e+000,20.00000,    -0.31895,0.70069
520.03003, 63.26417,    -1.09786,85.16206,50.00000,0.0000e+000,20.00000,    -0.31908,0.69944
521.82898, 63.44417,    -1.10199,85.10403,50.00000,0.0000e+000,20.00000,    -0.32024,0.69819
523.60498, 63.62417,    -1.10586,85.04578,50.00000,0.0000e+000,20.00000,    -0.32190,0.69696
525.40900, 63.80416,    -1.10995,84.98911,50.00000,0.0000e+000,20.00000,    -0.32310,0.69572
527.20898, 63.98417,    -1.11488,84.93200,50.00000,0.0000e+000,20.00000,    -0.32369,0.69448
529.00598, 64.16417,    -1.11942,84.87254,50.00000,0.0000e+000,20.00000,    -0.32472,0.69326
530.81097, 64.34417,    -1.12415,84.81422,50.00000,0.0000e+000,20.00000,    -0.32702,0.69203
532.59698, 64.52417,    -1.12810,84.75664,50.00000,0.0000e+000,20.00000,    -0.32869,0.69082
534.40503, 64.70417,    -1.13190,84.69966,50.00000,0.0000e+000,20.00000,    -0.32957,0.68960
536.19702, 64.88416,    -1.13601,84.64263,50.00000,0.0000e+000,20.00000,    -0.32951,0.68840
538.00299, 65.06416,    -1.14054,84.58388,50.00000,0.0000e+000,20.00000,    -0.32952,0.68720
539.79401, 65.24416,    -1.14500,84.52341,50.00000,0.0000e+000,20.00000,    -0.33062,0.68600
541.59802, 65.42416,    -1.14908,84.46208,50.00000,0.0000e+000,20.00000,    -0.33178,0.68481
543.38501, 65.60416,    -1.15333,84.40019,50.00000,0.0000e+000,20.00000,    -0.33317,0.68363
545.19202, 65.78416,    -1.15714,84.33834,50.00000,0.0000e+000,20.00000,    -0.33463,0.68245
546.99597, 65.96416,    -1.16230,84.27640,50.00000,0.0000e+000,20.00000,    -0.33522,0.68127
548.80200, 66.14417,    -1.16747,84.21370,50.00000,0.0000e+000,20.00000,    -0.33636,0.68009
550.59698, 66.32417,    -1.17163,84.15115,50.00000,0.0000e+000,20.00000,    -0.33792,0.67893
552.40002, 66.50417,    -1.17453,84.09160,50.00000,0.0000e+000,20.00000,    -0.33967,0.67777
554.20898, 66.68417,    -1.17837,84.03427,50.00000,0.0000e+000,20.00000,    -0.34175,0.67660
556.00201, 66.86417,    -1.18185,83.97586,50.00000,0.0000e+000,20.00000,    -0.34330,0.67546
557.80902, 67.04417,    -1.18564,83.91402,50.00000,0.0000e+000,20.00000,    -0.34427,0.67431
559.59998, 67.22417,    -1.18888,83.85155,50.00000,0.0000e+000,20.00000,    -0.34447,0.67317
561.39801, 67.40417,    -1.19249,83.78936,50.00000,0.0000e+000,20.00000,    -0.34458,0.67204
563.20697, 67.58417,    -1.19670,83.72730,50.00000,0.0000e+000,20.00000,    -0.34459,0.67090
565.01001, 67.76417,    -1.20222,83.66584,50.00000,0.0000e+000,20.00000,    -0.34443,0.66977
566.82397, 67.94417,    -1.20913,83.60329,50.00000,0.0000e+000,20.00000,    -0.34476,0.66865
568.66199, 68.12417,    -1.21486,83.53998,50.00000,0.0000e+000,20.00000,    -0.34531,0.66751
570.46198, 68.30417,    -1.21686,83.47662,50.00000,0.0000e+000,20.00000,    -0.34543,0.66640
572.25403, 68.48417,    -1.21846,83.41216,50.00000,0.0000e+000,20.00000,    -0.34599,0.66529
574.05103, 68.66417,    -1.22015,83.34805,50.00000,0.0000e+000,20.00000,    -0.34773,0.66420
575.84802, 68.84417,    -1.22349,83.28400,50.00000,0.0000e+000,20.00000,    -0.34834,0.66310
577.63000, 69.02417,    -1.22717,83.22190,50.00000,0.0000e+000,20.00000,    -0.34724,0.66202
579.42297, 69.20417,    -1.23185,83.15976,50.00000,0.0000e+000,20.00000,    -0.34640,0.66094
581.21503, 69.38416,    -1.23741,83.09770,50.00000,0.0000e+000,20.00000,    -0.34752,0.65986
583.02100, 69.56416,    -1.24333,83.03641,50.00000,0.0000e+000,20.00000,    -0.34845,0.65878
584.83899, 69.74416,    -1.24960,82.97320,50.00000,0.0000e+000,20.00000,    -0.34893,0.65770
586.65198, 69.92416,    -1.25773,82.90813,50.00000,0.0000e+000,20.00000,    -0.34937,0.65662
588.46002, 70.10416,    -1.26413,82.84691,50.00000,0.0000e+000,20.00000,    -0.34950,0.65556
590.27197, 70.28416,    -1.26712,82.78782,50.00000,0.0000e+000,20.00000,    -0.34949,0.65449
592.07202, 70.46416,    -1.26850,82.72405,50.00000,0.0000e+000,20.00000,    -0.35029,0.65344
593.85400, 70.64417,    -1.27082,82.65984,50.00000,0.0000e+000,20.00000,    -0.35112,0.65240
595.62903, 70.82417,    -1.27460,82.60056,50.00000,0.0000e+000,20.00000,    -0.35198,0.65137
597.43903, 71.00417,    -1.27981,82.54239,50.00000,0.0000e+000,20.00000,    -0.35285,0.65032
599.22998, 71.18417,    -1.28385,82.47674,50.00000,0.0000e+000,20.00000,    -0.35332,0.64929
601.04401, 71.36417,    -1.28908,82.41143,50.00000,0.0000e+000,20.00000,    -0.35456,0.64826
602.83398, 71.54417,    -1.29410,82.34745,50.00000,0.0000e+000,20.00000,    -0.35656,0.64724
604.62097, 71.72417,    -1.29716,82.28259,50.00000,0.0000e+000,20.00000,    -0.35809,0.64622
606.43103, 71.90417,    -1.30213,82.21862,50.00000,0.0000e+000,20.00000,    -0.36043,0.64520
608.25098, 72.08417,    -1.30921,82.15464,50.00000,0.0000e+000,20.00000,    -0.36368,0.64418
610.02899, 72.26417,    -1.31322,82.08794,50.00000,0.0000e+000,20.00000,    -0.36491,0.64318
611.83899, 72.44417,    -1.31653,82.02046,50.00000,0.0000e+000,20.00000,    -0.36629,0.64217
613.64099, 72.62417,    -1.31883,81.95482,50.00000,0.0000e+000,20.00000,    -0.36980,0.64117
615.42700, 72.80417,    -1.32159,81.88952,50.00000,0.0000e+000,20.00000,    -0.37492,0.64018
617.21997, 72.98417,    -1.32388,81.82547,50.00000,0.0000e+000,20.00000,    -0.37846,0.63920
619.04199, 73.16417,    -1.33187,81.76027,50.00000,0.0000e+000,20.00000,    -0.38107,0.63820
620.86499, 73.34417,    -1.34058,81.69067,50.00000,0.0000e+000,20.00000,    -0.38324,0.63720
622.70599, 73.52417,    -1.34683,81.61988,50.00000,0.0000e+000,20.00000,    -0.38549,0.63620
624.56201, 73.70417,    -1.35457,81.54944,50.00000,0.0000e+000,20.00000,    -0.38803,0.63520
626.44098, 73.88416,    -1.36447,81.47838,50.00000,0.0000e+000,20.00000,    -0.39032,0.63419
628.28601, 74.06416,    -1.36784,81.41061,50.00000,0.0000e+000,20.00000,    -0.39181,0.63320
630.06299, 74.24416,    -1.36200,81.34148,50.00000,0.0000e+000,20.00000,    -0.39374,0.63225
631.84698, 74.42416,    -1.35574,81.26903,50.00000,0.0000e+000,20.00000,    -0.39694,0.63130
633.61603, 74.60416,    -1.35074,81.19322,50.00000,0.0000e+000,20.00000,    -0.39990,0.63037
635.40698, 74.78416,    -1.35307,81.11551,50.00000,0.0000e+000,20.00000,    -0.40186,0.62942
637.23499, 74.96416,    -1.36096,81.03960,50.00000,0.0000e+000,20.00000,    -0.40372,0.62847
639.05200, 75.14417,    -1.36788,80.96751,50.00000,0.0000e+000,20.00000,    -0.40437,0.62752
640.89697, 75.32417,    -1.37615,80.89479,50.00000,0.0000e+000,20.00000,    -0.40462,0.62656
642.70599, 75.50417,    -1.38050,80.82118,50.00000,0.0000e+000,20.00000,    -0.40471,0.62562
644.50500, 75.68417,    -1.37995,80.74889,50.00000,0.0000e+000,20.00000,    -0.40429,0.62469
646.27502, 75.86417,    -1.37801,80.67729,50.00000,0.0000e+000,20.00000,    -0.40479,0.62378
648.03003, 76.04417,    -1.37512,80.60320,50.00000,0.0000e+000,20.00000,    -0.40469,0.62289
649.80499, 76.22417,    -1.37637,80.52588,50.00000,0.0000e+000,20.00000,    -0.40288,0.62198
651.58398, 76.40417,    -1.38079,80.44911,50.00000,0.0000e+000,20.00000,    -0.40029,0.62108
653.35999, 76.58417,    -1.38471,80.37720,50.00000,0.0000e+000,20.00000,    -0.39729,0.62019
655.14697, 76.76417,    -1.38921,80.30591,50.00000,0.0000e+000,20.00000,    -0.39448,0.61929
656.93298, 76.94417,    -1.39480,80.23439,50.00000,0.0000e+000,20.00000,    -0.39205,0.61839
658.70599, 77.12417,    -1.39977,80.16273,50.00000,0.0000e+000,20.00000,    -0.38893,0.61751
660.50201, 77.30417,    -1.40545,80.09173,50.00000,0.0000e+000,20.00000,    -0.38569,0.61662
662.29602, 77.48417,    -1.41027,80.02208,50.00000,0.0000e+000,20.00000,    -0.38240,0.61573
664.10303, 77.66417,    -1.41533,79.95205,50.00000,0.0000e+000,20.00000,    -0.37901,0.61484
665.90399, 77.84417,    -1.41998,79.88333,50.00000,0.0000e+000,20.00000,    -0.37548,0.61396
667.68298, 78.02417,    -1.42403,79.81768,50.00000,0.0000e+000,20.00000,    -0.37099,0.61309
669.48102, 78.20417,    -1.42751,79.75211,50.00000,0.0000e+000,20.00000,    -0.36636,0.61221
671.27301, 78.38416,    -1.43094,79.68545,50.00000,0.0000e+000,20.00000,    -0.36206,0.61135
673.08801, 78.56416,    -1.43424,79.61912,50.00000,0.0000e+000,20.00000,    -0.35822,0.61047
674.89301, 78.74416,    -1.43882,79.55495,50.00000,0.0000e+000,20.00000,    -0.35463,0.60960
676.68701, 78.92416,    -1.44506,79.49380,50.00000,0.0000e+000,20.00000,    -0.35059,0.60874
678.50403, 79.10416,    -1.44950,79.43214,50.00000,0.0000e+000,20.00000,    -0.34635,0.60788
680.30103, 79.28416,    -1.45153,79.37125,50.00000,0.0000e+000,20.00000,    -0.34235,0.60702
682.11499, 79.46416,    -1.45556,79.31212,50.00000,0.0000e+000,20.00000,    -0.33740,0.60617
683.94098, 79.64417,    -1.45853,79.25168,50.00000,0.0000e+000,20.00000,    -0.33208,0.60531
685.72302, 79.82417,    -1.46103,79.19110,50.00000,0.0000e+000,20.00000,    -0.32748,0.60447
687.51501, 80.00417,    -1.45926,79.13053,50.00000,0.0000e+000,20.00000,    -0.32316,0.60363
689.30402, 80.18417,    -1.46105,79.07321,50.00000,0.0000e+000,20.00000,    -0.31875,0.60280
691.12799, 80.36417,    -1.46671,79.01650,50.00000,0.0000e+000,20.00000,    -0.31435,0.60196
692.98401, 80.54417,    -1.47700,78.95797,50.00000,0.0000e+000,20.00000,    -0.31012,0.60110
694.84198, 80.72417,    -1.48546,78.90085,50.00000,0.0000e+000,20.00000,    -0.30723,0.60025
696.68402, 80.90417,    -1.48928,78.84507,50.00000,0.0000e+000,20.00000,    -0.30405,0.59940
698.52698, 81.08417,    -1.49202,78.78965,50.00000,0.0000e+000,20.00000,    -0.30045,0.59856
700.34100, 81.26417,    -1.49097,78.73726,50.00000,0.0000e+000,20.00000,    -0.29817,0.59774
702.13501, 81.44417,    -1.48720,78.68740,50.00000,0.0000e+000,20.00000,    -0.29610,0.59693
703.90198, 81.62417,    -1.48318,78.63820,50.00000,0.0000e+000,20.00000,    -0.29414,0.59613
705.69000, 81.80417,    -1.48144,78.58872,50.00000,0.0000e+000,20.00000,    -0.29312,0.59533
707.46503, 81.98417,    -1.48009,78.53836,50.00000,0.0000e+000,20.00000,    -0.29286,0.59453
709.24402, 82.16417,    -1.47874,78.48783,50.00000,0.0000e+000,20.00000,    -0.29267,0.59374
711.00201, 82.34417,    -1.47772,78.43860,50.00000,0.0000e+000,20.00000,    -0.29170,0.59296
712.81097, 82.52417,    -1.48160,78.38799,50.00000,0.0000e+000,20.00000,    -0.29062,0.59216
714.63000, 82.70417,    -1.48430,78.33777,50.00000,0.0000e+000,20.00000,    -0.28918,0.59136
716.42798, 82.88416,    -1.48364,78.28960,50.00000,0.0000e+000,20.00000,    -0.28630,0.59057
718.30603, 83.06416,    -1.49125,78.23944,50.00000,0.0000e+000,20.00000,    -0.28252,0.58974
720.17798, 83.24416,    -1.49849,78.18671,50.00000,0.0000e+000,20.00000,    -0.27792,0.58893
722.01202, 83.42416,    -1.49633,78.13372,50.00000,0.0000e+000,20.00000,    -0.27271,0.58813
723.81201, 83.60416,    -1.48962,78.07710,50.00000,0.0000e+000,20.00000,    -0.26655,0.58735
725.60498, 83.78416,    -1.48282,78.01994,50.00000,0.0000e+000,20.00000,    -0.25871,0.58658
727.36902, 83.96416,    -1.47605,77.96412,50.00000,0.0000e+000,20.00000,    -0.25012,0.58582
729.13300, 84.14417,    -1.47201,77.90900,50.00000,0.0000e+000,20.00000,    -0.24260,0.58507
730.90399, 84.32417,    -1.47287,77.85530,50.00000,0.0000e+000,20.00000,    -0.23498,0.58431
732.68103, 84.50417,    -1.47833,77.80399,50.00000,0.0000e+000,20.00000,    -0.22698,0.58356
734.45898, 84.68417,    -1.48726,77.75809,50.00000,0.0000e+000,20.00000,    -0.21853,0.58280
736.22803, 84.86417,    -1.49881,77.71796,50.00000,0.0000e+000,20.00000,    -0.20949,0.58206
738.00403, 85.04417,    -1.51316,77.68397,50.00000,0.0000e+000,20.00000,    -0.20013,0.58131
739.79498, 85.22417,    -1.52755,77.65343,50.00000,0.0000e+000,20.00000,    -0.19079,0.58056
741.59003, 85.40417,    -1.53776,77.62585,50.00000,0.0000e+000,20.00000,    -0.18044,0.57981
743.39502, 85.58417,    -1.54499,77.60348,50.00000,0.0000e+000,20.00000,    -0.16939,0.57905
745.20898, 85.76417,    -1.55042,77.58439,50.00000,0.0000e+000,20.00000,    -0.15788,0.57830
747.00598, 85.94417,    -1.55452,77.56288,50.00000,0.0000e+000,20.00000,    -0.14624,0.57756
748.84698, 86.12417,    -1.55877,77.54038,50.00000,0.0000e+000,20.00000,    -0.13549,0.57680
750.74799, 86.30417,    -1.57202,77.51874,50.00000,0.0000e+000,20.00000,    -0.12554,0.57602
752.63898, 86.48417,    -1.57795,77.50063,50.00000,0.0000e+000,20.00000,    -0.11658,0.57524
754.47601, 86.66417,    -1.57572,77.48439,50.00000,0.0000e+000,20.00000,    -0.10862,0.57449
756.33301, 86.84417,    -1.57500,77.46610,50.00000,0.0000e+000,20.00000,    -0.10302,0.57374
758.15802, 87.02417,    -1.57287,77.44751,50.00000,0.0000e+000,20.00000,-9.8346e-002,0.57300
759.94800, 87.20417,    -1.56522,77.42916,50.00000,0.0000e+000,20.00000,-9.3802e-002,0.57227
761.71002, 87.38416,    -1.55597,77.41187,50.00000,0.0000e+000,20.00000,-9.1018e-002,0.57156
763.49701, 87.56416,    -1.55269,77.39748,50.00000,0.0000e+000,20.00000,-8.9588e-002,0.57084
765.30298, 87.74416,    -1.55311,77.38491,50.00000,0.0000e+000,20.00000,-8.7578e-002,0.57012
767.10797, 87.92416,    -1.55474,77.37052,50.00000,0.0000e+000,20.00000,-8.4935e-002,0.56940
768.90198, 88.10416,    -1.55497,77.35507,50.00000,0.0000e+000,20.00000,-8.2431e-002,0.56868
770.68298, 88.28416,    -1.55284,77.34055,50.00000,0.0000e+000,20.00000,-8.0696e-002,0.56798
772.44702, 88.46416,    -1.54930,77.32862,50.00000,0.0000e+000,20.00000,-7.9568e-002,0.56728
774.21997, 88.64417,    -1.54752,77.31460,50.00000,0.0000e+000,20.00000,-7.7668e-002,0.56658
775.98700, 88.82417,    -1.54832,77.30040,50.00000,0.0000e+000,20.00000,-7.5750e-002,0.56588
777.74597, 89.00417,    -1.54848,77.28875,50.00000,0.0000e+000,20.00000,-7.4091e-002,0.56519
779.51398, 89.18417,    -1.54653,77.27594,50.00000,0.0000e+000,20.00000,-7.2620e-002,0.56450
781.28198, 89.36417,    -1.54797,77.26212,50.00000,0.0000e+000,20.00000,-7.1505e-002,0.56381
783.07202, 89.54417,    -1.55215,77.24822,50.00000,0.0000e+000,20.00000,-7.0937e-002,0.56311
784.87201, 89.72417,    -1.55596,77.23531,50.00000,0.0000e+000,20.00000,-6.9964e-002,0.56241
786.67200, 89.90417,    -1.55924,77.22256,50.00000,0.0000e+000,20.00000,-6.8755e-002,0.56172
788.48602, 90.08417,    -1.56520,77.21004,50.00000,0.0000e+000,20.00000,-6.8127e-002,0.56102
790.31897, 90.26417,    -1.57258,77.19796,50.00000,0.0000e+000,20.00000,-6.8128e-002,0.56031
792.15997, 90.44417,    -1.57782,77.18677,50.00000,0.0000e+000,20.00000,-6.7496e-002,0.55960
793.96503, 90.62417,    -1.57981,77.17529,50.00000,0.0000e+000,20.00000,-6.6904e-002,0.55891
795.77002, 90.80417,    -1.58236,77.16307,50.00000,0.0000e+000,20.00000,-6.6762e-002,0.55822
797.58899, 90.98417,    -1.58590,77.15071,50.00000,0.0000e+000,20.00000,-6.6602e-002,0.55753
799.39099, 91.16417,    -1.58922,77.13971,50.00000,0.0000e+000,20.00000,-6.6298e-002,0.55685
801.20599, 91.34417,    -1.59305,77.12927,50.00000,0.0000e+000,20.00000,-6.5623e-002,0.55616
803.01599, 91.52417,    -1.59664,77.11867,50.00000,0.0000e+000,20.00000,-6.5338e-002,0.55547
804.84302, 91.70417,    -1.59978,77.10797,50.00000,0.0000e+000,20.00000,-6.5194e-002,0.55478
806.64398, 91.88416,    -1.60195,77.09549,50.00000,0.0000e+000,20.00000,-6.5355e-002,0.55411
808.45599, 92.06416,    -1.60389,77.08323,50.00000,0.0000e+000,20.00000,-6.5962e-002,0.55343
810.28802, 92.24416,    -1.60952,77.07195,50.00000,0.0000e+000,20.00000,-6.7250e-002,0.55274
812.10199, 92.42416,    -1.61221,77.05975,50.00000,0.0000e+000,20.00000,-6.8506e-002,0.55206
813.88300, 92.60416,    -1.61188,77.04816,50.00000,0.0000e+000,20.00000,-6.9809e-002,0.55140
815.69000, 92.78416,    -1.61090,77.03654,50.00000,0.0000e+000,20.00000,-7.1478e-002,0.55072
817.48102, 92.96416,    -1.60929,77.02377,50.00000,0.0000e+000,20.00000,-7.3459e-002,0.55006
819.27100, 93.14417,    -1.61109,77.01220,50.00000,0.0000e+000,20.00000,-7.5489e-002,0.54940
821.07599, 93.32417,    -1.61248,77.00031,50.00000,0.0000e+000,20.00000,-7.7240e-002,0.54873
822.87097, 93.50417,    -1.61421,76.98810,50.00000,0.0000e+000,20.00000,-7.9225e-002,0.54807
824.68903, 93.68417,    -1.61525,76.97517,50.00000,0.0000e+000,20.00000,-8.1207e-002,0.54740
826.51599, 93.86417,    -1.61817,76.96094,50.00000,0.0000e+000,20.00000,-8.3614e-002,0.54673
828.31897, 94.04417,    -1.61830,76.94518,50.00000,0.0000e+000,20.00000,-8.6101e-002,0.54607
830.12299, 94.22417,    -1.61821,76.92910,50.00000,0.0000e+000,20.00000,-8.8357e-002,0.54541
831.92999, 94.40417,    -1.61658,76.91258,50.00000,0.0000e+000,20.00000,-9.1432e-002,0.54475
833.74103, 94.58417,    -1.61642,76.89411,50.00000,0.0000e+000,20.00000,-9.4731e-002,0.54409
835.57397, 94.76417,    -1.61981,76.87563,50.00000,0.0000e+000,20.00000,-9.7864e-002,0.54342
837.40503, 94.94417,    -1.62348,76.85761,50.00000,0.0000e+000,20.00000,    -0.10139,0.54276
839.24500, 95.12417,    -1.62552,76.84057,50.00000,0.0000e+000,20.00000,    -0.10505,0.54209
841.07202, 95.30417,    -1.62360,76.82295,50.00000,0.0000e+000,20.00000,    -0.10901,0.54143
842.85699, 95.48417,    -1.61920,76.80378,50.00000,0.0000e+000,20.00000,    -0.11301,0.54078
844.65302, 95.66417,    -1.61709,76.78266,50.00000,0.0000e+000,20.00000,    -0.11680,0.54014
846.44897, 95.84417,    -1.61543,76.76199,50.00000,0.0000e+000,20.00000,    -0.12030,0.53949
848.21198, 96.02417,    -1.61261,76.74204,50.00000,0.0000e+000,20.00000,    -0.12328,0.53886
850.00299, 96.20417,    -1.61159,76.71921,50.00000,0.0000e+000,20.00000,    -0.12695,0.53822
851.79498, 96.38416,    -1.61079,76.69583,50.00000,0.0000e+000,20.00000,    -0.13056,0.53757
853.58600, 96.56416,    -1.61125,76.67171,50.00000,0.0000e+000,20.00000,    -0.13407,0.53693
855.37097, 96.74416,    -1.61265,76.64712,50.00000,0.0000e+000,20.00000,    -0.13700,0.53630
857.18903, 96.92416,    -1.61537,76.62215,50.00000,0.0000e+000,20.00000,    -0.14063,0.53565
858.97900, 97.10416,    -1.61740,76.59566,50.00000,0.0000e+000,20.00000,    -0.14423,0.53501
860.77502, 97.28416,    -1.61681,76.56843,50.00000,0.0000e+000,20.00000,    -0.14710,0.53437
862.56598, 97.46416,    -1.61734,76.54057,50.00000,0.0000e+000,20.00000,    -0.15006,0.53374
864.37000, 97.64417,    -1.61840,76.51220,50.00000,0.0000e+000,20.00000,    -0.15340,0.53310
866.18500, 97.82417,    -1.62171,76.48515,50.00000,0.0000e+000,20.00000,    -0.15680,0.53246
868.03400, 98.00417,    -1.62838,76.45597,50.00000,0.0000e+000,20.00000,    -0.15943,0.53180
869.90302, 98.18417,    -1.63817,76.42462,50.00000,0.0000e+000,20.00000,    -0.16229,0.53114
871.71399, 98.36417,    -1.63937,76.39305,50.00000,0.0000e+000,20.00000,    -0.16509,0.53050
873.48297, 98.54417,    -1.62963,76.36392,50.00000,0.0000e+000,20.00000,    -0.16781,0.52988
875.24597, 98.72417,    -1.62318,76.33396,50.00000,0.0000e+000,20.00000,    -0.17043,0.52926
877.08502, 98.90417,    -1.63101,76.30304,50.00000,0.0000e+000,20.00000,    -0.17247,0.52862
878.94702, 99.08417,    -1.64104,76.27382,50.00000,0.0000e+000,20.00000,    -0.17466,0.52796
880.76703, 99.26417,    -1.64302,76.24243,50.00000,0.0000e+000,20.00000,    -0.17655,0.52732
882.57001, 99.44417,    -1.64046,76.20944,50.00000,0.0000e+000,20.00000,    -0.17798,0.52669
884.34497, 99.62417,    -1.63734,76.17696,50.00000,0.0000e+000,20.00000,    -0.17984,0.52607
886.12201, 99.80417,    -1.63533,76.14511,50.00000,0.0000e+000,20.00000,    -0.18193,0.52545
887.90100, 99.98417,    -1.63458,76.11148,50.00000,0.0000e+000,20.00000,    -0.18347,0.52483
889.68597,100.16417,    -1.63335,76.07730,50.00000,0.0000e+000,20.00000,    -0.18550,0.52421
891.46198,100.34417,    -1.63240,76.04280,50.00000,0.0000e+000,20.00000,    -0.18853,0.52359
893.26501,100.52417,    -1.63466,76.00836,50.00000,0.0000e+000,20.00000,    -0.19134,0.52296
895.06299,100.70417,    -1.63785,75.97457,50.00000,0.0000e+000,20.00000,    -0.19357,0.52234
896.87201,100.88416,    -1.64155,75.93970,50.00000,0.0000e+000,20.00000,    -0.19622,0.52171
898.66400,101.06416,    -1.64449,75.90475,50.00000,0.0000e+000,20.00000,    -0.19831,0.52108
900.49402,101.24416,    -1.64894,75.87111,50.00000,0.0000e+000,20.00000,    -0.19992,0.52045
902.31201,101.42416,    -1.65117,75.83729,50.00000,0.0000e+000,20.00000,    -0.20108,0.51982
904.10602,101.60416,    -1.65201,75.80137,50.00000,0.0000e+000,20.00000,    -0.20270,0.51920
905.91101,101.78416,    -1.65216,75.76455,50.00000,0.0000e+000,20.00000,    -0.20489,0.51857
907.71600,101.96416,    -1.65200,75.72599,50.00000,0.0000e+000,20.00000,    -0.20659,0.51795
909.56097,102.14417,    -1.65695,75.68530,50.00000,0.0000e+000,20.00000,    -0.20758,0.51731
911.40198,102.32417,    -1.66372,75.64542,50.00000,0.0000e+000,20.00000,    -0.20920,0.51667
913.23401,102.50417,    -1.66618,75.60608,50.00000,0.0000e+000,20.00000,    -0.21194,0.51604
915.04102,102.68417,    -1.66308,75.56707,50.00000,0.0000e+000,20.00000,    -0.21419,0.51541
916.82098,102.86417,    -1.65837,75.52848,50.00000,0.0000e+000,20.00000,    -0.21568,0.51480
918.61902,103.04417,    -1.65615,75.48966,50.00000,0.0000e+000,20.00000,    -0.21762,0.51418
920.41302,103.22417,    -1.65754,75.45240,50.00000,0.0000e+000,20.00000,    -0.21973,0.51356
922.21399,103.40417,    -1.66103,75.41526,50.00000,0.0000e+000,20.00000,    -0.22125,0.51294
924.01898,103.58417,    -1.66263,75.37421,50.00000,0.0000e+000,20.00000,    -0.22220,0.51232
925.81201,103.76417,    -1.66281,75.33340,50.00000,0.0000e+000,20.00000,    -0.22363,0.51170
927.61603,103.94417,    -1.66709,75.29522,50.00000,0.0000e+000,20.00000,    -0.22459,0.51108
929.45801,104.12417,    -1.67188,75.25546,50.00000,0.0000e+000,20.00000,    -0.22556,0.51044
931.25800,104.30417,    -1.67430,75.21179,50.00000,0.0000e+000,20.00000,    -0.22723,0.50982
933.06598,104.48417,    -1.67339,75.16865,50.00000,0.0000e+000,20.00000,    -0.22869,0.50920
934.88300,104.66417,    -1.67291,75.12782,50.00000,0.0000e+000,20.00000,    -0.22925,0.50857
936.68402,104.84417,    -1.67125,75.08713,50.00000,0.0000e+000,20.00000,    -0.23002,0.50795
938.49103,105.02417,    -1.66894,75.04577,50.00000,0.0000e+000,20.00000,    -0.23144,0.50733
940.28900,105.20417,    -1.66442,75.00453,50.00000,0.0000e+000,20.00000,    -0.23245,0.50671
942.07599,105.38416,    -1.65898,74.96425,50.00000,0.0000e+000,20.00000,    -0.23167,0.50610
943.88202,105.56416,    -1.65502,74.92161,50.00000,0.0000e+000,20.00000,    -0.23059,0.50548
945.69202,105.74416,    -1.65036,74.87718,50.00000,0.0000e+000,20.00000,    -0.22926,0.50485
947.49500,105.92416,    -1.64456,74.83383,50.00000,0.0000e+000,20.00000,    -0.22706,0.50423
949.30200,106.10416,    -1.63796,74.78855,50.00000,0.0000e+000,20.00000,    -0.22364,0.50361
951.10699,106.28416,    -1.63252,74.74366,50.00000,0.0000e+000,20.00000,    -0.21966,0.50299
952.90100,106.46416,    -1.62662,74.70261,50.00000,0.0000e+000,20.00000,    -0.21528,0.50237
954.68597,106.64417,    -1.62214,74.66137,50.00000,0.0000e+000,20.00000,    -0.21007,0.50176
956.49597,106.82417,    -1.61967,74.61849,50.00000,0.0000e+000,20.00000,    -0.20454,0.50113
958.28900,107.00417,    -1.62120,74.57753,50.00000,0.0000e+000,20.00000,    -0.19878,0.50051
960.11700,107.18417,    -1.62458,74.53957,50.00000,0.0000e+000,20.00000,    -0.19270,0.49988
961.94299,107.36417,    -1.62964,74.50220,50.00000,0.0000e+000,20.00000,    -0.18561,0.49925
963.77802,107.54417,    -1.63351,74.46788,50.00000,0.0000e+000,20.00000,    -0.17744,0.49862
965.59698,107.72417,    -1.63392,74.43670,50.00000,0.0000e+000,20.00000,    -0.16871,0.49799
967.43103,107.90417,    -1.63871,74.40574,50.00000,0.0000e+000,20.00000,    -0.15933,0.49736
969.24597,108.08417,    -1.64035,74.37647,50.00000,0.0000e+000,20.00000,    -0.15003,0.49674
971.02197,108.26417,    -1.63867,74.35059,50.00000,0.0000e+000,20.00000,    -0.14183,0.49612
972.79199,108.44417,    -1.63781,74.32886,50.00000,0.0000e+000,20.00000,    -0.13380,0.49551
974.58502,108.62417,    -1.63757,74.30770,50.00000,0.0000e+000,20.00000,    -0.12529,0.49489
976.37000,108.80417,    -1.63787,74.28722,50.00000,0.0000e+000,20.00000,    -0.11672,0.49427
978.17401,108.98417,    -1.64026,74.26869,50.00000,0.0000e+000,20.00000,    -0.10870,0.49365
979.97101,109.16417,    -1.64459,74.25238,50.00000,0.0000e+000,20.00000,    -0.10105,0.49303
981.77600,109.34417,    -1.64890,74.23732,50.00000,0.0000e+000,20.00000,-9.2011e-002,0.49240
983.57800,109.52417,    -1.65159,74.22551,50.00000,0.0000e+000,20.00000,-8.2643e-002,0.49178
985.37903,109.70417,    -1.65393,74.21491,50.00000,0.0000e+000,20.00000,-7.5122e-002,0.49116
987.18500,109.88416,    -1.65468,74.20367,50.00000,0.0000e+000,20.00000,-6.8480e-002,0.49053
988.98700,110.06416,    -1.65424,74.19216,50.00000,0.0000e+000,20.00000,-6.2542e-002,0.48990
990.78302,110.24416,    -1.65531,74.18057,50.00000,0.0000e+000,20.00000,-5.8863e-002,0.48928
992.59497,110.42416,    -1.65768,74.16885,50.00000,0.0000e+000,20.00000,-5.8405e-002,0.48865
994.37903,110.60416,    -1.65830,74.15835,50.00000,0.0000e+000,20.00000,-5.5858e-002,0.48803
996.17401,110.78416,    -1.65954,74.14939,50.00000,0.0000e+000,20.00000,-5.0033e-002,0.48741
998.00500,110.96416,    -1.66200,74.13935,50.00000,0.0000e+000,20.00000,-4.0988e-002,0.48677
998.34497,110.99917,    -1.66337,74.13846,50.00000,0.0000e+000,20.00000, 1.3171e-002,0.48665