File: book/some_content/TG_ExpDat_OPC7%D28.csv
#FILE:                       ,OPC7%D28; 13-1-2025.ngb-ds3
#FORMAT:                     ,NETZSCH5
#IDENTITY:                   ,Geopolymer paste
#DECIMAL:                    ,POINT
#SEPARATOR:                  ,COMMA
#MTYPE:                      ,DSC
#INSTRUMENT:                 ,Microlab TU Delft
#PROJECT:                    ,
#DATE/TIME:                  ,14/01/2025 8:14:23 AM
#CORR. FILE:                 ,Blank with cover; 13-1-2025.ngb-bs3
#LABORATORY:                 ,TU Delft Micro Lab
#OPERATOR:                   ,Ahmed
#REMARK:                     ,under Argon atmosphere, 10K/min
#SAMPLE:                     ,OPC7%D28;13-1-2025
#SAMPLE MASS /mg:            ,45
#MATERIAL:                   ,Geopolymer paste
#REFERENCE:                  ,blank
#REFERENCE MASS /mg:         ,0
#TYPE OF CRUCIBLE:           ,DSC/TG pan Al2O3
#SAMPLE CRUCIBLE MASS /mg:   ,0
#REFERENCE CRUCIBLE MASS /mg:,0
#CORR. CODE:                 ,020
#EXO:                        ,-1
#RANGE:                      ,40/10.0(K/min)/1000
#SEGMENT:                    ,S2/2

##Temp./øC,Time/min,DSC/(mW/mg),Mass/%,Gas Flow(purge1)/(ml/min),Gas Flow(purge2)/(ml/min),Gas Flow(protective)/(ml/min),DTG/(%/min),Sensit./(uV/mW)
 40.63100, 15.05250, 7.0717e-002,97.39436,50.00000,0.0000e+000,20.00000,    -0.14961,1.22607
 40.66200, 15.23250, 7.0954e-002,97.36182,50.00000,0.0000e+000,20.00000,    -0.17921,1.22603
 40.70600, 15.41250, 7.0930e-002,97.32768,50.00000,0.0000e+000,20.00000,    -0.18233,1.22597
 40.79300, 15.59250, 7.1269e-002,97.29415,50.00000,0.0000e+000,20.00000,    -0.18445,1.22585
 40.91700, 15.77250, 7.2109e-002,97.26059,50.00000,0.0000e+000,20.00000,    -0.18620,1.22568
 41.08900, 15.95250, 7.3617e-002,97.22658,50.00000,0.0000e+000,20.00000,    -0.18993,1.22544
 41.32600, 16.13250, 7.5879e-002,97.19244,50.00000,0.0000e+000,20.00000,    -0.19201,1.22511
 41.63500, 16.31250, 7.8992e-002,97.15863,50.00000,0.0000e+000,20.00000,    -0.19653,1.22469
 42.03200, 16.49250, 8.2545e-002,97.12393,50.00000,0.0000e+000,20.00000,    -0.20188,1.22414
 42.50400, 16.67250, 8.7065e-002,97.08710,50.00000,0.0000e+000,20.00000,    -0.20895,1.22349
 43.07000, 16.85250, 9.2265e-002,97.04991,50.00000,0.0000e+000,20.00000,    -0.21890,1.22271
 43.68800, 17.03250, 9.7810e-002,97.01372,50.00000,0.0000e+000,20.00000,    -0.22719,1.22186
 44.42400, 17.21250,     0.10421,96.97720,50.00000,0.0000e+000,20.00000,    -0.23659,1.22084
 45.22700, 17.39250,     0.11116,96.93844,50.00000,0.0000e+000,20.00000,    -0.24823,1.21974
 46.09200, 17.57250,     0.11858,96.89731,50.00000,0.0000e+000,20.00000,    -0.26121,1.21854
 47.06700, 17.75250,     0.12678,96.85518,50.00000,0.0000e+000,20.00000,    -0.27611,1.21720
 48.12200, 17.93250,     0.13544,96.81146,50.00000,0.0000e+000,20.00000,    -0.29271,1.21575
 49.24400, 18.11250,     0.14466,96.76555,50.00000,0.0000e+000,20.00000,    -0.31097,1.21420
 50.44800, 18.29250,     0.15430,96.71670,50.00000,0.0000e+000,20.00000,    -0.33207,1.21254
 51.74300, 18.47250,     0.16470,96.66456,50.00000,0.0000e+000,20.00000,    -0.35780,1.21076
 53.11700, 18.65250,     0.17584,96.60773,50.00000,0.0000e+000,20.00000,    -0.38751,1.20887
 54.52500, 18.83250,     0.18774,96.54640,50.00000,0.0000e+000,20.00000,    -0.41867,1.20693
 56.06600, 19.01250,     0.20026,96.47920,50.00000,0.0000e+000,20.00000,    -0.45375,1.20481
 57.66200, 19.19250,     0.21378,96.40393,50.00000,0.0000e+000,20.00000,    -0.49223,1.20262
 59.33300, 19.37250,     0.22814,96.32379,50.00000,0.0000e+000,20.00000,    -0.53591,1.20032
 61.06900, 19.55250,     0.24374,96.23665,50.00000,0.0000e+000,20.00000,    -0.58447,1.19793
 62.87500, 19.73250,     0.26012,96.14255,50.00000,0.0000e+000,20.00000,    -0.63756,1.19545
 64.73700, 19.91250,     0.27840,96.04317,50.00000,0.0000e+000,20.00000,    -0.69628,1.19289
 66.64700, 20.09250,     0.29767,95.93365,50.00000,0.0000e+000,20.00000,    -0.75994,1.19027
 68.66000, 20.27250,     0.31871,95.80660,50.00000,0.0000e+000,20.00000,    -0.82931,1.18751
 70.66500, 20.45250,     0.34124,95.66150,50.00000,0.0000e+000,20.00000,    -0.90517,1.18476
 72.74700, 20.63250,     0.36550,95.51288,50.00000,0.0000e+000,20.00000,    -0.98740,1.18191
 74.87900, 20.81250,     0.39188,95.35039,50.00000,0.0000e+000,20.00000,    -1.07589,1.17899
 77.04000, 20.99250,     0.42040,95.17412,50.00000,0.0000e+000,20.00000,    -1.17032,1.17603
 79.24600, 21.17250,     0.45140,94.97692,50.00000,0.0000e+000,20.00000,    -1.27117,1.17302
 81.49600, 21.35250,     0.48497,94.76013,50.00000,0.0000e+000,20.00000,    -1.37859,1.16995
 83.78300, 21.53250,     0.52043,94.52561,50.00000,0.0000e+000,20.00000,    -1.49262,1.16682
 86.06900, 21.71250,     0.55915,94.26916,50.00000,0.0000e+000,20.00000,    -1.61328,1.16371
 88.41600, 21.89250,     0.60025,93.99098,50.00000,0.0000e+000,20.00000,    -1.73916,1.16051
 90.78900, 22.07250,     0.64349,93.69026,50.00000,0.0000e+000,20.00000,    -1.86732,1.15728
 93.19200, 22.25250,     0.68922,93.36103,50.00000,0.0000e+000,20.00000,    -1.99521,1.15401
 95.58800, 22.43250,     0.73671,93.00415,50.00000,0.0000e+000,20.00000,    -2.12570,1.15076
 98.00200, 22.61250,     0.78614,92.61908,50.00000,0.0000e+000,20.00000,    -2.25611,1.14748
100.41800, 22.79250,     0.83683,92.20431,50.00000,0.0000e+000,20.00000,    -2.38417,1.14421
102.87300, 22.97250,     0.88817,91.76060,50.00000,0.0000e+000,20.00000,    -2.50610,1.14088
105.29900, 23.15250,     0.94076,91.28699,50.00000,0.0000e+000,20.00000,    -2.61962,1.13760
107.72000, 23.33250,     0.99398,90.78161,50.00000,0.0000e+000,20.00000,    -2.72267,1.13434
110.16800, 23.51250,     1.04708,90.24667,50.00000,0.0000e+000,20.00000,    -2.80849,1.13103
112.61700, 23.69250,     1.09912,89.68305,50.00000,0.0000e+000,20.00000,    -2.87198,1.12774
115.02300, 23.87250,     1.14885,89.09439,50.00000,0.0000e+000,20.00000,    -2.90864,1.12450
117.43200, 24.05250,     1.19457,88.48569,50.00000,0.0000e+000,20.00000,    -2.91648,1.12127
119.86000, 24.23250,     1.23593,87.86320,50.00000,0.0000e+000,20.00000,    -2.89815,1.11801
122.26000, 24.41250,     1.27157,87.22777,50.00000,0.0000e+000,20.00000,    -2.85731,1.11480
124.66600, 24.59250,     1.30051,86.58623,50.00000,0.0000e+000,20.00000,    -2.79762,1.11158
127.07800, 24.77250,     1.32151,85.94570,50.00000,0.0000e+000,20.00000,    -2.72267,1.10836
129.49500, 24.95250,     1.33497,85.31485,50.00000,0.0000e+000,20.00000,    -2.63363,1.10514
131.87700, 25.13250,     1.33870,84.70193,50.00000,0.0000e+000,20.00000,    -2.53076,1.10197
134.27901, 25.31250,     1.32310,84.12802,50.00000,0.0000e+000,20.00000,    -2.41875,1.09878
136.69400, 25.49250,     1.28184,83.61023,50.00000,0.0000e+000,20.00000,    -2.29501,1.09557
139.09500, 25.67250,     1.21193,83.16748,50.00000,0.0000e+000,20.00000,    -2.16259,1.09239
141.51300, 25.85250,     1.11972,82.80252,50.00000,0.0000e+000,20.00000,    -2.02380,1.08920
143.94800, 26.03250,     1.01563,82.50740,50.00000,0.0000e+000,20.00000,    -1.88071,1.08599
146.36900, 26.21250,     0.90977,82.26865,50.00000,0.0000e+000,20.00000,    -1.73367,1.08280
148.78799, 26.39250,     0.80757,82.07159,50.00000,0.0000e+000,20.00000,    -1.58437,1.07962
151.18401, 26.57250,     0.71263,81.90266,50.00000,0.0000e+000,20.00000,    -1.43563,1.07647
153.58800, 26.75250,     0.62810,81.75581,50.00000,0.0000e+000,20.00000,    -1.28924,1.07333
155.96600, 26.93250,     0.55421,81.62944,50.00000,0.0000e+000,20.00000,    -1.14536,1.07022
158.33299, 27.11250,     0.49020,81.50756,50.00000,0.0000e+000,20.00000,    -1.00982,1.06713
160.66901, 27.29250,     0.43491,81.39815,50.00000,0.0000e+000,20.00000,    -0.88717,1.06409
162.98599, 27.47250,     0.38821,81.29685,50.00000,0.0000e+000,20.00000,    -0.78275,1.06108
165.27299, 27.65250,     0.34857,81.19762,50.00000,0.0000e+000,20.00000,    -0.69769,1.05811
167.52901, 27.83250,     0.31585,81.10002,50.00000,0.0000e+000,20.00000,    -0.63083,1.05519
169.74600, 28.01250,     0.28960,81.00350,50.00000,0.0000e+000,20.00000,    -0.57937,1.05233
171.93100, 28.19250,     0.26926,80.90818,50.00000,0.0000e+000,20.00000,    -0.53950,1.04951
174.09200, 28.37250,     0.25295,80.81095,50.00000,0.0000e+000,20.00000,    -0.50678,1.04673
176.22200, 28.55250,     0.23786,80.71281,50.00000,0.0000e+000,20.00000,    -0.47962,1.04400
178.33400, 28.73250,     0.22070,80.62085,50.00000,0.0000e+000,20.00000,    -0.45817,1.04129
180.39400, 28.91250,     0.20216,80.53440,50.00000,0.0000e+000,20.00000,    -0.43816,1.03866
182.44099, 29.09250,     0.18251,80.45407,50.00000,0.0000e+000,20.00000,    -0.42050,1.03604
184.47701, 29.27250,     0.16314,80.37982,50.00000,0.0000e+000,20.00000,    -0.40476,1.03345
186.48100, 29.45250,     0.14443,80.31312,50.00000,0.0000e+000,20.00000,    -0.38944,1.03090
188.47200, 29.63250,     0.12662,80.25199,50.00000,0.0000e+000,20.00000,    -0.37452,1.02838
190.44200, 29.81250,     0.10987,80.19332,50.00000,0.0000e+000,20.00000,    -0.35861,1.02588
192.37801, 29.99250, 9.3979e-002,80.13627,50.00000,0.0000e+000,20.00000,    -0.34251,1.02344
194.32800, 30.17250, 7.9393e-002,80.08263,50.00000,0.0000e+000,20.00000,    -0.32600,1.02098
196.23199, 30.35250, 6.6164e-002,80.03155,50.00000,0.0000e+000,20.00000,    -0.30825,1.01858
198.11000, 30.53250, 5.3437e-002,79.98103,50.00000,0.0000e+000,20.00000,    -0.29192,1.01622
199.99899, 30.71250, 4.1856e-002,79.93187,50.00000,0.0000e+000,20.00000,    -0.27697,1.01385
201.84599, 30.89250, 3.0974e-002,79.88395,50.00000,0.0000e+000,20.00000,    -0.26284,1.01154
203.68401, 31.07250, 2.0528e-002,79.83949,50.00000,0.0000e+000,20.00000,    -0.25028,1.00925
205.50400, 31.25250, 1.0355e-002,79.79598,50.00000,0.0000e+000,20.00000,    -0.23969,1.00698
207.30600, 31.43250, 7.9309e-004,79.75231,50.00000,0.0000e+000,20.00000,    -0.23044,1.00474
209.11000, 31.61250,-8.6420e-003,79.71306,50.00000,0.0000e+000,20.00000,    -0.22150,1.00250
210.88800, 31.79250,-1.7356e-002,79.67648,50.00000,0.0000e+000,20.00000,    -0.21318,1.00030
212.66400, 31.97250,-2.6550e-002,79.63991,50.00000,0.0000e+000,20.00000,    -0.20593,0.99810
214.43900, 32.15250,-3.5443e-002,79.60588,50.00000,0.0000e+000,20.00000,    -0.19908,0.99591
216.17900, 32.33250,-4.4204e-002,79.57270,50.00000,0.0000e+000,20.00000,    -0.19189,0.99377
217.93600, 32.51250,-5.3071e-002,79.53965,50.00000,0.0000e+000,20.00000,    -0.18453,0.99161
219.68500, 32.69250,-6.1822e-002,79.50974,50.00000,0.0000e+000,20.00000,    -0.17723,0.98947
221.41701, 32.87250,-7.0643e-002,79.48047,50.00000,0.0000e+000,20.00000,    -0.17160,0.98735
223.17999, 33.05250,-7.9178e-002,79.45118,50.00000,0.0000e+000,20.00000,    -0.16653,0.98520
224.89400, 33.23250,-8.7072e-002,79.42299,50.00000,0.0000e+000,20.00000,    -0.16124,0.98311
226.61900, 33.41250,-9.4967e-002,79.39661,50.00000,0.0000e+000,20.00000,    -0.15640,0.98101
228.33000, 33.59250,    -0.10249,79.36986,50.00000,0.0000e+000,20.00000,    -0.15273,0.97894
230.06700, 33.77250,    -0.11013,79.34210,50.00000,0.0000e+000,20.00000,    -0.14915,0.97683
231.77600, 33.95250,    -0.11752,79.31556,50.00000,0.0000e+000,20.00000,    -0.14554,0.97477
233.48100, 34.13250,    -0.12468,79.29092,50.00000,0.0000e+000,20.00000,    -0.14251,0.97271
235.19800, 34.31250,    -0.13167,79.26817,50.00000,0.0000e+000,20.00000,    -0.13895,0.97065
236.89799, 34.49250,    -0.13872,79.24674,50.00000,0.0000e+000,20.00000,    -0.13621,0.96861
238.60201, 34.67250,    -0.14582,79.22272,50.00000,0.0000e+000,20.00000,    -0.13383,0.96657
240.30800, 34.85250,    -0.15238,79.19788,50.00000,0.0000e+000,20.00000,    -0.13158,0.96453
242.00200, 35.03250,    -0.15857,79.17305,50.00000,0.0000e+000,20.00000,    -0.12922,0.96251
243.71001, 35.21250,    -0.16505,79.15053,50.00000,0.0000e+000,20.00000,    -0.12719,0.96047
245.40401, 35.39250,    -0.17057,79.12753,50.00000,0.0000e+000,20.00000,    -0.12522,0.95846
247.09700, 35.57250,    -0.17614,79.10369,50.00000,0.0000e+000,20.00000,    -0.12290,0.95646
248.79900, 35.75250,    -0.18218,79.08221,50.00000,0.0000e+000,20.00000,    -0.12132,0.95445
250.48700, 35.93250,    -0.18762,79.06033,50.00000,0.0000e+000,20.00000,    -0.12004,0.95245
252.18100, 36.11250,    -0.19365,79.03965,50.00000,0.0000e+000,20.00000,    -0.11962,0.95046
253.90500, 36.29250,    -0.19921,79.01949,50.00000,0.0000e+000,20.00000,    -0.11952,0.94844
255.60899, 36.47250,    -0.20497,78.99898,50.00000,0.0000e+000,20.00000,    -0.11816,0.94644
257.32101, 36.65250,    -0.21025,78.97787,50.00000,0.0000e+000,20.00000,    -0.11660,0.94444
259.01999, 36.83250,    -0.21512,78.95782,50.00000,0.0000e+000,20.00000,    -0.11518,0.94246
260.73700, 37.01250,    -0.22012,78.93866,50.00000,0.0000e+000,20.00000,    -0.11437,0.94046
262.44199, 37.19250,    -0.22445,78.91927,50.00000,0.0000e+000,20.00000,    -0.11377,0.93849
264.16000, 37.37250,    -0.22900,78.90018,50.00000,0.0000e+000,20.00000,    -0.11303,0.93650
265.87701, 37.55250,    -0.23356,78.87928,50.00000,0.0000e+000,20.00000,    -0.11302,0.93452
267.59601, 37.73250,    -0.23793,78.85896,50.00000,0.0000e+000,20.00000,    -0.11335,0.93254
269.33301, 37.91250,    -0.24254,78.83767,50.00000,0.0000e+000,20.00000,    -0.11400,0.93054
271.04999, 38.09250,    -0.24698,78.81629,50.00000,0.0000e+000,20.00000,    -0.11469,0.92857
272.77399, 38.27250,    -0.25157,78.79747,50.00000,0.0000e+000,20.00000,    -0.11562,0.92660
274.52200, 38.45250,    -0.25585,78.77853,50.00000,0.0000e+000,20.00000,    -0.11577,0.92461
276.23700, 38.63250,    -0.26060,78.75879,50.00000,0.0000e+000,20.00000,    -0.11615,0.92266
277.95999, 38.81250,    -0.26476,78.73892,50.00000,0.0000e+000,20.00000,    -0.11751,0.92070
279.70901, 38.99250,    -0.26888,78.71854,50.00000,0.0000e+000,20.00000,    -0.11886,0.91873
281.44400, 39.17250,    -0.27267,78.69740,50.00000,0.0000e+000,20.00000,    -0.12070,0.91677
283.18201, 39.35250,    -0.27614,78.67569,50.00000,0.0000e+000,20.00000,    -0.12236,0.91481
284.92599, 39.53250,    -0.27948,78.65300,50.00000,0.0000e+000,20.00000,    -0.12371,0.91285
286.66599, 39.71250,    -0.28308,78.62950,50.00000,0.0000e+000,20.00000,    -0.12459,0.91091
288.40601, 39.89250,    -0.28650,78.60696,50.00000,0.0000e+000,20.00000,    -0.12564,0.90896
290.13800, 40.07250,    -0.28987,78.58313,50.00000,0.0000e+000,20.00000,    -0.12735,0.90703
291.88400, 40.25250,    -0.29329,78.56111,50.00000,0.0000e+000,20.00000,    -0.12892,0.90509
293.61099, 40.43250,    -0.29629,78.53978,50.00000,0.0000e+000,20.00000,    -0.13061,0.90318
295.34601, 40.61250,    -0.29888,78.51581,50.00000,0.0000e+000,20.00000,    -0.13268,0.90127
297.08499, 40.79250,    -0.30198,78.49156,50.00000,0.0000e+000,20.00000,    -0.13421,0.89935
298.82199, 40.97250,    -0.30569,78.46606,50.00000,0.0000e+000,20.00000,    -0.13580,0.89744
300.57401, 41.15250,    -0.31060,78.43936,50.00000,0.0000e+000,20.00000,    -0.13774,0.89552
302.34900, 41.33250,    -0.31602,78.41359,50.00000,0.0000e+000,20.00000,    -0.13994,0.89358
304.11801, 41.51250,    -0.32081,78.38941,50.00000,0.0000e+000,20.00000,    -0.14159,0.89166
305.89600, 41.69250,    -0.32476,78.36418,50.00000,0.0000e+000,20.00000,    -0.14351,0.88972
307.66400, 41.87250,    -0.32766,78.33856,50.00000,0.0000e+000,20.00000,    -0.14594,0.88781
309.45401, 42.05250,    -0.33039,78.31413,50.00000,0.0000e+000,20.00000,    -0.14874,0.88588
311.23199, 42.23250,    -0.33287,78.28853,50.00000,0.0000e+000,20.00000,    -0.15213,0.88396
313.02100, 42.41250,    -0.33536,78.26115,50.00000,0.0000e+000,20.00000,    -0.15453,0.88204
314.81000, 42.59250,    -0.33911,78.23506,50.00000,0.0000e+000,20.00000,    -0.15721,0.88013
316.58200, 42.77250,    -0.34212,78.20858,50.00000,0.0000e+000,20.00000,    -0.16014,0.87823
318.37299, 42.95250,    -0.34474,78.18012,50.00000,0.0000e+000,20.00000,    -0.16279,0.87633
320.16101, 43.13250,    -0.34669,78.14980,50.00000,0.0000e+000,20.00000,    -0.16657,0.87443
321.93900, 43.31250,    -0.34895,78.11990,50.00000,0.0000e+000,20.00000,    -0.17141,0.87255
323.72900, 43.49250,    -0.35055,78.09066,50.00000,0.0000e+000,20.00000,    -0.17543,0.87066
325.48599, 43.67250,    -0.35184,78.05839,50.00000,0.0000e+000,20.00000,    -0.17806,0.86882
327.27100, 43.85250,    -0.35246,78.02568,50.00000,0.0000e+000,20.00000,    -0.18079,0.86695
329.03799, 44.03250,    -0.35318,77.99225,50.00000,0.0000e+000,20.00000,    -0.18403,0.86510
330.82199, 44.21250,    -0.35433,77.95965,50.00000,0.0000e+000,20.00000,    -0.18772,0.86324
332.57800, 44.39250,    -0.35598,77.92613,50.00000,0.0000e+000,20.00000,    -0.18985,0.86142
334.35901, 44.57250,    -0.35838,77.89018,50.00000,0.0000e+000,20.00000,    -0.19111,0.85957
336.14001, 44.75250,    -0.36111,77.85421,50.00000,0.0000e+000,20.00000,    -0.19227,0.85774
337.92599, 44.93250,    -0.36387,77.81485,50.00000,0.0000e+000,20.00000,    -0.19301,0.85590
339.71201, 45.11250,    -0.36687,77.77302,50.00000,0.0000e+000,20.00000,    -0.19352,0.85407
341.48300, 45.29250,    -0.36910,77.73268,50.00000,0.0000e+000,20.00000,    -0.19454,0.85226
343.26001, 45.47250,    -0.37236,77.69682,50.00000,0.0000e+000,20.00000,    -0.19419,0.85045
345.03900, 45.65250,    -0.37589,77.66241,50.00000,0.0000e+000,20.00000,    -0.19281,0.84864
346.79800, 45.83250,    -0.38060,77.62602,50.00000,0.0000e+000,20.00000,    -0.19085,0.84686
348.58701, 46.01250,    -0.38589,77.58517,50.00000,0.0000e+000,20.00000,    -0.18906,0.84505
350.34900, 46.19250,    -0.39213,77.54984,50.00000,0.0000e+000,20.00000,    -0.18725,0.84328
352.13300, 46.37250,    -0.39881,77.51903,50.00000,0.0000e+000,20.00000,    -0.18354,0.84149
353.91501, 46.55250,    -0.40575,77.48690,50.00000,0.0000e+000,20.00000,    -0.17979,0.83971
355.68500, 46.73250,    -0.41338,77.45396,50.00000,0.0000e+000,20.00000,    -0.17506,0.83795
357.45599, 46.91250,    -0.42104,77.42195,50.00000,0.0000e+000,20.00000,    -0.16908,0.83619
359.22601, 47.09250,    -0.42804,77.38922,50.00000,0.0000e+000,20.00000,    -0.16354,0.83444
361.00400, 47.27250,    -0.43652,77.35804,50.00000,0.0000e+000,20.00000,    -0.15932,0.83269
362.78900, 47.45250,    -0.44423,77.33014,50.00000,0.0000e+000,20.00000,    -0.15426,0.83093
364.57599, 47.63250,    -0.45261,77.30371,50.00000,0.0000e+000,20.00000,    -0.14876,0.82918
366.33099, 47.81250,    -0.46066,77.27771,50.00000,0.0000e+000,20.00000,    -0.14225,0.82747
368.12299, 47.99250,    -0.46837,77.25086,50.00000,0.0000e+000,20.00000,    -0.13671,0.82572
369.90302, 48.17250,    -0.47606,77.22808,50.00000,0.0000e+000,20.00000,    -0.13310,0.82400
371.68900, 48.35250,    -0.48339,77.20614,50.00000,0.0000e+000,20.00000,    -0.12986,0.82227
373.49301, 48.53250,    -0.49059,77.18441,50.00000,0.0000e+000,20.00000,    -0.12541,0.82054
375.27600, 48.71250,    -0.49704,77.16440,50.00000,0.0000e+000,20.00000,    -0.12126,0.81882
377.07300, 48.89250,    -0.50371,77.14420,50.00000,0.0000e+000,20.00000,    -0.11668,0.81711
378.88699, 49.07250,    -0.51139,77.12267,50.00000,0.0000e+000,20.00000,    -0.11188,0.81538
380.68301, 49.25250,    -0.51806,77.10612,50.00000,0.0000e+000,20.00000,    -0.10811,0.81367
382.48300, 49.43250,    -0.52328,77.09077,50.00000,0.0000e+000,20.00000,    -0.10494,0.81197
384.26599, 49.61250,    -0.52811,77.07396,50.00000,0.0000e+000,20.00000,    -0.10188,0.81029
386.06799, 49.79250,    -0.53216,77.05755,50.00000,0.0000e+000,20.00000,-9.8075e-002,0.80859
387.83899, 49.97250,    -0.53648,77.04025,50.00000,0.0000e+000,20.00000,-9.5475e-002,0.80694
389.62701, 50.15250,    -0.54090,77.02019,50.00000,0.0000e+000,20.00000,-9.3296e-002,0.80527
391.40302, 50.33250,    -0.54585,77.00298,50.00000,0.0000e+000,20.00000,-9.0171e-002,0.80362
393.19400, 50.51250,    -0.55161,76.98627,50.00000,0.0000e+000,20.00000,-8.7909e-002,0.80196
394.96799, 50.69250,    -0.55702,76.97003,50.00000,0.0000e+000,20.00000,-8.6511e-002,0.80032
396.77600, 50.87250,    -0.56238,76.95580,50.00000,0.0000e+000,20.00000,-8.4057e-002,0.79866
398.55899, 51.05250,    -0.56724,76.94139,50.00000,0.0000e+000,20.00000,-8.3091e-002,0.79703
400.35001, 51.23250,    -0.57139,76.92643,50.00000,0.0000e+000,20.00000,-8.3170e-002,0.79539
402.12799, 51.41250,    -0.57571,76.91153,50.00000,0.0000e+000,20.00000,-8.2739e-002,0.79377
403.91800, 51.59250,    -0.57993,76.89834,50.00000,0.0000e+000,20.00000,-8.2879e-002,0.79215
405.69901, 51.77250,    -0.58418,76.88459,50.00000,0.0000e+000,20.00000,-8.3607e-002,0.79054
407.48300, 51.95250,    -0.58863,76.87049,50.00000,0.0000e+000,20.00000,-8.4169e-002,0.78894
409.28101, 52.13250,    -0.59328,76.85958,50.00000,0.0000e+000,20.00000,-8.5087e-002,0.78733
411.06100, 52.31250,    -0.59718,76.84815,50.00000,0.0000e+000,20.00000,-8.6466e-002,0.78574
412.85001, 52.49250,    -0.60070,76.83351,50.00000,0.0000e+000,20.00000,-8.8375e-002,0.78415
414.62601, 52.67250,    -0.60384,76.82036,50.00000,0.0000e+000,20.00000,-9.0659e-002,0.78257
416.42899, 52.85250,    -0.60687,76.80699,50.00000,0.0000e+000,20.00000,-9.3078e-002,0.78098
418.19800, 53.03250,    -0.60893,76.79161,50.00000,0.0000e+000,20.00000,-9.6007e-002,0.77942
419.97601, 53.21250,    -0.60998,76.77649,50.00000,0.0000e+000,20.00000,-9.9011e-002,0.77787
421.76401, 53.39250,    -0.61042,76.75988,50.00000,0.0000e+000,20.00000,    -0.10224,0.77631
423.55499, 53.57250,    -0.60996,76.74071,50.00000,0.0000e+000,20.00000,    -0.10561,0.77475
425.32001, 53.75250,    -0.60895,76.71898,50.00000,0.0000e+000,20.00000,    -0.10809,0.77322
427.12100, 53.93250,    -0.60671,76.69754,50.00000,0.0000e+000,20.00000,    -0.11095,0.77166
428.88300, 54.11250,    -0.60418,76.67639,50.00000,0.0000e+000,20.00000,    -0.11387,0.77015
430.64499, 54.29250,    -0.60177,76.65289,50.00000,0.0000e+000,20.00000,    -0.11523,0.76864
432.42499, 54.47250,    -0.59971,76.63004,50.00000,0.0000e+000,20.00000,    -0.11621,0.76712
434.19101, 54.65250,    -0.59765,76.60710,50.00000,0.0000e+000,20.00000,    -0.11669,0.76562
435.95001, 54.83250,    -0.59653,76.58190,50.00000,0.0000e+000,20.00000,    -0.11591,0.76413
437.73499, 55.01250,    -0.59747,76.55568,50.00000,0.0000e+000,20.00000,    -0.11476,0.76263
439.51199, 55.19250,    -0.60071,76.53056,50.00000,0.0000e+000,20.00000,    -0.11310,0.76113
441.30801, 55.37250,    -0.60610,76.50464,50.00000,0.0000e+000,20.00000,    -0.11054,0.75963
443.12900, 55.55250,    -0.61201,76.48081,50.00000,0.0000e+000,20.00000,    -0.10719,0.75811
444.94101, 55.73250,    -0.62057,76.45892,50.00000,0.0000e+000,20.00000,    -0.10376,0.75661
446.75699, 55.91250,    -0.63014,76.43715,50.00000,0.0000e+000,20.00000,    -0.10031,0.75511
448.55801, 56.09250,    -0.63993,76.41739,50.00000,0.0000e+000,20.00000,-9.5581e-002,0.75362
450.37000, 56.27250,    -0.65048,76.39998,50.00000,0.0000e+000,20.00000,-9.1621e-002,0.75214
452.18799, 56.45250,    -0.66026,76.38477,50.00000,0.0000e+000,20.00000,-8.8364e-002,0.75065
454.00500, 56.63250,    -0.66900,76.37206,50.00000,0.0000e+000,20.00000,-8.4198e-002,0.74917
455.81699, 56.81250,    -0.67635,76.36101,50.00000,0.0000e+000,20.00000,-7.9261e-002,0.74771
457.61600, 56.99250,    -0.68191,76.35068,50.00000,0.0000e+000,20.00000,-7.4562e-002,0.74625
459.41599, 57.17250,    -0.68649,76.34120,50.00000,0.0000e+000,20.00000,-6.9403e-002,0.74481
461.19601, 57.35250,    -0.69011,76.33200,50.00000,0.0000e+000,20.00000,-6.4128e-002,0.74338
462.96100, 57.53250,    -0.69380,76.32283,50.00000,0.0000e+000,20.00000,-5.9831e-002,0.74197
464.73199, 57.71250,    -0.69649,76.31426,50.00000,0.0000e+000,20.00000,-5.6323e-002,0.74057
466.51001, 57.89250,    -0.69931,76.30810,50.00000,0.0000e+000,20.00000,-5.2665e-002,0.73916
468.28101, 58.07250,    -0.70345,76.30018,50.00000,0.0000e+000,20.00000,-5.0085e-002,0.73777
470.05399, 58.25250,    -0.70716,76.28935,50.00000,0.0000e+000,20.00000,-4.8702e-002,0.73638
471.82001, 58.43250,    -0.71097,76.27950,50.00000,0.0000e+000,20.00000,-4.7474e-002,0.73500
473.60199, 58.61250,    -0.71472,76.27116,50.00000,0.0000e+000,20.00000,-4.6073e-002,0.73361
475.38800, 58.79250,    -0.71802,76.26308,50.00000,0.0000e+000,20.00000,-4.5282e-002,0.73222
477.16299, 58.97250,    -0.72192,76.25587,50.00000,0.0000e+000,20.00000,-4.4620e-002,0.73085
478.95599, 59.15250,    -0.72546,76.25051,50.00000,0.0000e+000,20.00000,-4.3385e-002,0.72948
480.75101, 59.33250,    -0.73014,76.24489,50.00000,0.0000e+000,20.00000,-4.3027e-002,0.72810
482.54199, 59.51250,    -0.73422,76.23580,50.00000,0.0000e+000,20.00000,-4.3213e-002,0.72674
484.35599, 59.69250,    -0.73860,76.22873,50.00000,0.0000e+000,20.00000,-4.3325e-002,0.72536
486.18500, 59.87250,    -0.74261,76.22099,50.00000,0.0000e+000,20.00000,-4.2951e-002,0.72398
487.98300, 60.05250,    -0.74546,76.21046,50.00000,0.0000e+000,20.00000,-4.1909e-002,0.72262
489.79401, 60.23250,    -0.74700,76.20144,50.00000,0.0000e+000,20.00000,-4.1399e-002,0.72127
491.59799, 60.41250,    -0.74927,76.19522,50.00000,0.0000e+000,20.00000,-4.0830e-002,0.71992
493.39700, 60.59250,    -0.75078,76.18793,50.00000,0.0000e+000,20.00000,-3.9814e-002,0.71858
495.18600, 60.77250,    -0.75212,76.18041,50.00000,0.0000e+000,20.00000,-3.9062e-002,0.71726
496.97400, 60.95250,    -0.75348,76.17562,50.00000,0.0000e+000,20.00000,-3.9063e-002,0.71594
498.76501, 61.13250,    -0.75520,76.16844,50.00000,0.0000e+000,20.00000,-3.9521e-002,0.71463
500.55399, 61.31250,    -0.75811,76.15880,50.00000,0.0000e+000,20.00000,-3.8813e-002,0.71332
502.34601, 61.49250,    -0.76088,76.15154,50.00000,0.0000e+000,20.00000,-3.8234e-002,0.71201
504.13800, 61.67250,    -0.76334,76.14562,50.00000,0.0000e+000,20.00000,-3.7697e-002,0.71072
505.94601, 61.85250,    -0.76673,76.13900,50.00000,0.0000e+000,20.00000,-3.6199e-002,0.70941
507.76300, 62.03250,    -0.77082,76.13080,50.00000,0.0000e+000,20.00000,-3.4935e-002,0.70811
509.59299, 62.21250,    -0.77460,76.12397,50.00000,0.0000e+000,20.00000,-3.4949e-002,0.70680
511.41101, 62.39250,    -0.77835,76.11936,50.00000,0.0000e+000,20.00000,-3.4952e-002,0.70550
513.22900, 62.57250,    -0.78067,76.11493,50.00000,0.0000e+000,20.00000,-3.4845e-002,0.70421
515.03998, 62.75250,    -0.78125,76.10931,50.00000,0.0000e+000,20.00000,-3.5494e-002,0.70293
516.83698, 62.93250,    -0.78019,76.10273,50.00000,0.0000e+000,20.00000,-3.5315e-002,0.70167
518.62201, 63.11250,    -0.77930,76.09609,50.00000,0.0000e+000,20.00000,-3.4339e-002,0.70042
520.39099, 63.29250,    -0.77927,76.09081,50.00000,0.0000e+000,20.00000,-3.3805e-002,0.69919
522.17798, 63.47250,    -0.77944,76.08538,50.00000,0.0000e+000,20.00000,-3.3723e-002,0.69795
523.94702, 63.65250,    -0.78103,76.08051,50.00000,0.0000e+000,20.00000,-3.3926e-002,0.69673
525.74597, 63.83250,    -0.78403,76.07572,50.00000,0.0000e+000,20.00000,-3.3524e-002,0.69549
527.54602, 64.01250,    -0.78671,76.06950,50.00000,0.0000e+000,20.00000,-3.3319e-002,0.69425
529.33301, 64.19250,    -0.78827,76.06247,50.00000,0.0000e+000,20.00000,-3.4251e-002,0.69304
531.10101, 64.37250,    -0.78937,76.05519,50.00000,0.0000e+000,20.00000,-3.4921e-002,0.69183
532.88800, 64.55250,    -0.79011,76.04766,50.00000,0.0000e+000,20.00000,-3.4510e-002,0.69063
534.67200, 64.73250,    -0.79112,76.04158,50.00000,0.0000e+000,20.00000,-3.4355e-002,0.68942
536.44897, 64.91250,    -0.79261,76.03565,50.00000,0.0000e+000,20.00000,-3.4704e-002,0.68823
538.24200, 65.09250,    -0.79503,76.02975,50.00000,0.0000e+000,20.00000,-3.5811e-002,0.68704
540.03400, 65.27250,    -0.79725,76.02423,50.00000,0.0000e+000,20.00000,-3.6219e-002,0.68584
541.83002, 65.45250,    -0.79901,76.01725,50.00000,0.0000e+000,20.00000,-3.7197e-002,0.68466
543.63098, 65.63250,    -0.80059,76.01045,50.00000,0.0000e+000,20.00000,-3.8256e-002,0.68347
545.42603, 65.81250,    -0.80255,76.00417,50.00000,0.0000e+000,20.00000,-3.8647e-002,0.68229
547.22900, 65.99250,    -0.80421,75.99609,50.00000,0.0000e+000,20.00000,-3.8808e-002,0.68111
549.01099, 66.17250,    -0.80550,75.98882,50.00000,0.0000e+000,20.00000,-3.9274e-002,0.67996
550.81403, 66.35250,    -0.80649,75.98474,50.00000,0.0000e+000,20.00000,-4.0003e-002,0.67879
552.60498, 66.53250,    -0.80721,75.97928,50.00000,0.0000e+000,20.00000,-4.0973e-002,0.67763
554.40198, 66.71250,    -0.80826,75.97156,50.00000,0.0000e+000,20.00000,-4.1885e-002,0.67648
556.21198, 66.89250,    -0.80950,75.96204,50.00000,0.0000e+000,20.00000,-4.2991e-002,0.67532
558.01703, 67.07250,    -0.81085,75.95482,50.00000,0.0000e+000,20.00000,-4.5089e-002,0.67418
559.79797, 67.25250,    -0.81107,75.94674,50.00000,0.0000e+000,20.00000,-4.6500e-002,0.67305
561.59399, 67.43250,    -0.81100,75.93784,50.00000,0.0000e+000,20.00000,-4.7188e-002,0.67191
563.40198, 67.61250,    -0.81240,75.93044,50.00000,0.0000e+000,20.00000,-4.8039e-002,0.67078
565.23401, 67.79250,    -0.81660,75.92288,50.00000,0.0000e+000,20.00000,-4.8254e-002,0.66963
567.05798, 67.97250,    -0.81979,75.91431,50.00000,0.0000e+000,20.00000,-4.8986e-002,0.66850
568.88501, 68.15250,    -0.82080,75.90411,50.00000,0.0000e+000,20.00000,-5.1255e-002,0.66737
570.69397, 68.33250,    -0.82026,75.89415,50.00000,0.0000e+000,20.00000,-5.3219e-002,0.66625
572.50403, 68.51250,    -0.81817,75.88485,50.00000,0.0000e+000,20.00000,-5.4658e-002,0.66514
574.28497, 68.69250,    -0.81655,75.87527,50.00000,0.0000e+000,20.00000,-5.6045e-002,0.66405
576.08801, 68.87250,    -0.81746,75.86233,50.00000,0.0000e+000,20.00000,-5.7402e-002,0.66296
577.90399, 69.05250,    -0.82131,75.85012,50.00000,0.0000e+000,20.00000,-5.8147e-002,0.66185
579.72302, 69.23250,    -0.82488,75.84025,50.00000,0.0000e+000,20.00000,-5.8976e-002,0.66076
581.55499, 69.41250,    -0.82720,75.83108,50.00000,0.0000e+000,20.00000,-6.1077e-002,0.65966
583.37000, 69.59250,    -0.82792,75.82236,50.00000,0.0000e+000,20.00000,-6.3348e-002,0.65857
585.16302, 69.77250,    -0.82775,75.81243,50.00000,0.0000e+000,20.00000,-6.5326e-002,0.65751
586.96002, 69.95250,    -0.82769,75.79998,50.00000,0.0000e+000,20.00000,-6.6813e-002,0.65644
588.76801, 70.13250,    -0.82661,75.78753,50.00000,0.0000e+000,20.00000,-6.8370e-002,0.65537
590.55402, 70.31250,    -0.82643,75.77527,50.00000,0.0000e+000,20.00000,-7.0350e-002,0.65433
592.33698, 70.49250,    -0.82710,75.76076,50.00000,0.0000e+000,20.00000,-7.2631e-002,0.65328
594.12701, 70.67250,    -0.82835,75.74772,50.00000,0.0000e+000,20.00000,-7.3779e-002,0.65224
595.92798, 70.85250,    -0.82962,75.73722,50.00000,0.0000e+000,20.00000,-7.5144e-002,0.65120
597.70502, 71.03250,    -0.82996,75.72561,50.00000,0.0000e+000,20.00000,-7.7462e-002,0.65017
599.48700, 71.21250,    -0.83036,75.71073,50.00000,0.0000e+000,20.00000,-7.9812e-002,0.64915
601.29303, 71.39250,    -0.83098,75.69492,50.00000,0.0000e+000,20.00000,-8.2757e-002,0.64811
603.07300, 71.57250,    -0.83139,75.67936,50.00000,0.0000e+000,20.00000,-8.5650e-002,0.64710
604.87598, 71.75250,    -0.83344,75.66383,50.00000,0.0000e+000,20.00000,-8.7559e-002,0.64608
606.68103, 71.93250,    -0.83568,75.64824,50.00000,0.0000e+000,20.00000,-8.8966e-002,0.64506
608.48199, 72.11250,    -0.83694,75.63165,50.00000,0.0000e+000,20.00000,-9.0468e-002,0.64405
610.27197, 72.29250,    -0.83721,75.61420,50.00000,0.0000e+000,20.00000,-9.2403e-002,0.64304
612.06097, 72.47250,    -0.83698,75.59721,50.00000,0.0000e+000,20.00000,-9.4477e-002,0.64205
613.86700, 72.65250,    -0.83636,75.58002,50.00000,0.0000e+000,20.00000,-9.7205e-002,0.64104
615.65100, 72.83250,    -0.83606,75.56128,50.00000,0.0000e+000,20.00000,    -0.10005,0.64006
617.44202, 73.01250,    -0.83814,75.54356,50.00000,0.0000e+000,20.00000,    -0.10176,0.63907
619.27100, 73.19250,    -0.84129,75.52432,50.00000,0.0000e+000,20.00000,    -0.10357,0.63807
621.06598, 73.37250,    -0.84256,75.50406,50.00000,0.0000e+000,20.00000,    -0.10643,0.63709
622.89203, 73.55250,    -0.84443,75.48481,50.00000,0.0000e+000,20.00000,    -0.10871,0.63610
624.72998, 73.73250,    -0.84703,75.46678,50.00000,0.0000e+000,20.00000,    -0.11029,0.63511
626.55902, 73.91250,    -0.84843,75.44952,50.00000,0.0000e+000,20.00000,    -0.11201,0.63412
628.37000, 74.09250,    -0.84836,75.42867,50.00000,0.0000e+000,20.00000,    -0.11417,0.63315
630.16699, 74.27250,    -0.84758,75.40728,50.00000,0.0000e+000,20.00000,    -0.11633,0.63220
631.95697, 74.45250,    -0.84628,75.38676,50.00000,0.0000e+000,20.00000,    -0.11877,0.63125
633.74799, 74.63250,    -0.84559,75.36519,50.00000,0.0000e+000,20.00000,    -0.12088,0.63030
635.54901, 74.81250,    -0.84506,75.34437,50.00000,0.0000e+000,20.00000,    -0.12334,0.62935
637.34900, 74.99250,    -0.84538,75.32248,50.00000,0.0000e+000,20.00000,    -0.12604,0.62841
639.15100, 75.17250,    -0.84727,75.29676,50.00000,0.0000e+000,20.00000,    -0.12842,0.62746
640.95697, 75.35250,    -0.84916,75.27219,50.00000,0.0000e+000,20.00000,    -0.13101,0.62653
642.75598, 75.53250,    -0.84869,75.25084,50.00000,0.0000e+000,20.00000,    -0.13393,0.62559
644.57599, 75.71250,    -0.85040,75.22851,50.00000,0.0000e+000,20.00000,    -0.13718,0.62466
646.37701, 75.89250,    -0.85125,75.20350,50.00000,0.0000e+000,20.00000,    -0.14015,0.62373
648.19000, 76.07250,    -0.84955,75.17834,50.00000,0.0000e+000,20.00000,    -0.14303,0.62281
649.97302, 76.25250,    -0.84812,75.15273,50.00000,0.0000e+000,20.00000,    -0.14557,0.62190
651.78601, 76.43250,    -0.84768,75.12631,50.00000,0.0000e+000,20.00000,    -0.14823,0.62098
653.58301, 76.61250,    -0.84843,75.09966,50.00000,0.0000e+000,20.00000,    -0.15156,0.62007
655.38000, 76.79250,    -0.84822,75.07124,50.00000,0.0000e+000,20.00000,    -0.15442,0.61917
657.18701, 76.97250,    -0.84754,75.04209,50.00000,0.0000e+000,20.00000,    -0.15601,0.61827
658.96100, 77.15250,    -0.84738,75.01330,50.00000,0.0000e+000,20.00000,    -0.15806,0.61738
660.75800, 77.33250,    -0.84753,74.98428,50.00000,0.0000e+000,20.00000,    -0.16097,0.61649
662.55701, 77.51250,    -0.84807,74.95543,50.00000,0.0000e+000,20.00000,    -0.16346,0.61560
664.35699, 77.69250,    -0.84780,74.92474,50.00000,0.0000e+000,20.00000,    -0.16570,0.61472
666.16803, 77.87250,    -0.84850,74.89241,50.00000,0.0000e+000,20.00000,    -0.16855,0.61383
667.96899, 78.05250,    -0.84936,74.86237,50.00000,0.0000e+000,20.00000,    -0.17128,0.61295
669.80499, 78.23250,    -0.85049,74.83171,50.00000,0.0000e+000,20.00000,    -0.17419,0.61206
671.60602, 78.41250,    -0.85139,74.79859,50.00000,0.0000e+000,20.00000,    -0.17704,0.61118
673.41302, 78.59250,    -0.85105,74.76638,50.00000,0.0000e+000,20.00000,    -0.17912,0.61031
675.20801, 78.77250,    -0.84945,74.73546,50.00000,0.0000e+000,20.00000,    -0.18192,0.60945
676.99298, 78.95250,    -0.84794,74.70296,50.00000,0.0000e+000,20.00000,    -0.18495,0.60860
678.76599, 79.13250,    -0.84666,74.67054,50.00000,0.0000e+000,20.00000,    -0.18820,0.60775
680.57898, 79.31250,    -0.84688,74.63943,50.00000,0.0000e+000,20.00000,    -0.19159,0.60689
682.39899, 79.49250,    -0.84887,74.60703,50.00000,0.0000e+000,20.00000,    -0.19354,0.60603
684.22998, 79.67250,    -0.84898,74.57161,50.00000,0.0000e+000,20.00000,    -0.19503,0.60517
686.01398, 79.85250,    -0.84539,74.53611,50.00000,0.0000e+000,20.00000,    -0.19718,0.60434
687.80798, 80.03250,    -0.84131,74.49951,50.00000,0.0000e+000,20.00000,    -0.19964,0.60350
689.58502, 80.21250,    -0.83838,74.46215,50.00000,0.0000e+000,20.00000,    -0.20110,0.60267
691.36401, 80.39250,    -0.83649,74.42665,50.00000,0.0000e+000,20.00000,    -0.20194,0.60185
693.16803, 80.57250,    -0.83556,74.38777,50.00000,0.0000e+000,20.00000,    -0.20284,0.60102
694.96997, 80.75250,    -0.83544,74.34775,50.00000,0.0000e+000,20.00000,    -0.20292,0.60019
696.79401, 80.93250,    -0.83488,74.30726,50.00000,0.0000e+000,20.00000,    -0.20212,0.59935
698.61401, 81.11250,    -0.83536,74.26567,50.00000,0.0000e+000,20.00000,    -0.20138,0.59852
700.44202, 81.29250,    -0.83618,74.22785,50.00000,0.0000e+000,20.00000,    -0.20008,0.59769
702.28302, 81.47250,    -0.83703,74.19030,50.00000,0.0000e+000,20.00000,    -0.19716,0.59686
704.10699, 81.65250,    -0.83912,74.15202,50.00000,0.0000e+000,20.00000,    -0.19317,0.59604
705.91101, 81.83250,    -0.83901,74.11297,50.00000,0.0000e+000,20.00000,    -0.18886,0.59523
707.72101, 82.01250,    -0.83816,74.07432,50.00000,0.0000e+000,20.00000,    -0.18366,0.59442
709.50299, 82.19250,    -0.83814,74.03836,50.00000,0.0000e+000,20.00000,    -0.17906,0.59362
711.27502, 82.37250,    -0.83982,74.00409,50.00000,0.0000e+000,20.00000,    -0.17407,0.59284
713.05902, 82.55250,    -0.84214,73.97104,50.00000,0.0000e+000,20.00000,    -0.16784,0.59205
714.85797, 82.73250,    -0.84729,73.94111,50.00000,0.0000e+000,20.00000,    -0.16074,0.59126
716.65900, 82.91250,    -0.85310,73.91242,50.00000,0.0000e+000,20.00000,    -0.15319,0.59047
718.45099, 83.09250,    -0.85769,73.88492,50.00000,0.0000e+000,20.00000,    -0.14707,0.58968
720.24298, 83.27250,    -0.86297,73.85996,50.00000,0.0000e+000,20.00000,    -0.14116,0.58890
722.08099, 83.45250,    -0.87086,73.83856,50.00000,0.0000e+000,20.00000,    -0.13496,0.58810
723.94702, 83.63250,    -0.88109,73.81806,50.00000,0.0000e+000,20.00000,    -0.12876,0.58730
725.82599, 83.81250,    -0.88994,73.79912,50.00000,0.0000e+000,20.00000,    -0.12146,0.58649
727.66998, 83.99250,    -0.89169,73.78072,50.00000,0.0000e+000,20.00000,    -0.11434,0.58569
729.48297, 84.17250,    -0.89099,73.76072,50.00000,0.0000e+000,20.00000,    -0.10870,0.58492
731.30499, 84.35250,    -0.88982,73.74269,50.00000,0.0000e+000,20.00000,    -0.10354,0.58414
733.12299, 84.53250,    -0.88859,73.72822,50.00000,0.0000e+000,20.00000,-9.9028e-002,0.58337
734.91302, 84.71250,    -0.88521,73.71422,50.00000,0.0000e+000,20.00000,-9.4138e-002,0.58261
736.69000, 84.89250,    -0.88160,73.69840,50.00000,0.0000e+000,20.00000,-8.9611e-002,0.58186
738.44501, 85.07250,    -0.87857,73.68254,50.00000,0.0000e+000,20.00000,-8.6130e-002,0.58112
740.22198, 85.25250,    -0.87696,73.66705,50.00000,0.0000e+000,20.00000,-8.3893e-002,0.58038
741.98401, 85.43250,    -0.87567,73.65072,50.00000,0.0000e+000,20.00000,-8.2102e-002,0.57964
743.76703, 85.61250,    -0.87545,73.63770,50.00000,0.0000e+000,20.00000,-7.9948e-002,0.57890
745.52802, 85.79250,    -0.87509,73.62751,50.00000,0.0000e+000,20.00000,-7.7598e-002,0.57817
747.30798, 85.97250,    -0.87376,73.61432,50.00000,0.0000e+000,20.00000,-7.4664e-002,0.57743
749.06403, 86.15250,    -0.87210,73.59961,50.00000,0.0000e+000,20.00000,-7.2447e-002,0.57671
750.86902, 86.33250,    -0.87137,73.58561,50.00000,0.0000e+000,20.00000,-7.1015e-002,0.57597
752.68103, 86.51250,    -0.87134,73.57419,50.00000,0.0000e+000,20.00000,-6.9610e-002,0.57522
754.47198, 86.69250,    -0.87062,73.56338,50.00000,0.0000e+000,20.00000,-6.8080e-002,0.57449
756.27899, 86.87250,    -0.87091,73.55067,50.00000,0.0000e+000,20.00000,-6.7166e-002,0.57376
758.09198, 87.05250,    -0.87025,73.53730,50.00000,0.0000e+000,20.00000,-6.5518e-002,0.57302
759.89398, 87.23250,    -0.86941,73.52302,50.00000,0.0000e+000,20.00000,-6.2977e-002,0.57229
761.70001, 87.41250,    -0.86873,73.51132,50.00000,0.0000e+000,20.00000,-6.1430e-002,0.57157
763.52698, 87.59250,    -0.86825,73.50134,50.00000,0.0000e+000,20.00000,-6.0902e-002,0.57083
765.34497, 87.77250,    -0.86879,73.49243,50.00000,0.0000e+000,20.00000,-5.9630e-002,0.57010
767.15503, 87.95250,    -0.86838,73.48194,50.00000,0.0000e+000,20.00000,-5.7569e-002,0.56938
768.96698, 88.13250,    -0.86617,73.47220,50.00000,0.0000e+000,20.00000,-5.5863e-002,0.56866
770.79303, 88.31250,    -0.86757,73.46326,50.00000,0.0000e+000,20.00000,-5.4525e-002,0.56793
772.59802, 88.49250,    -0.86723,73.45392,50.00000,0.0000e+000,20.00000,-5.3758e-002,0.56722
774.40503, 88.67250,    -0.86623,73.44122,50.00000,0.0000e+000,20.00000,-5.3283e-002,0.56651
776.19897, 88.85250,    -0.86590,73.43114,50.00000,0.0000e+000,20.00000,-5.2190e-002,0.56580
777.98102, 89.03250,    -0.86442,73.42415,50.00000,0.0000e+000,20.00000,-5.0116e-002,0.56510
779.75098, 89.21250,    -0.86254,73.41606,50.00000,0.0000e+000,20.00000,-4.8850e-002,0.56441
781.52301, 89.39250,    -0.86227,73.40786,50.00000,0.0000e+000,20.00000,-4.7741e-002,0.56372
783.33099, 89.57250,    -0.86510,73.39974,50.00000,0.0000e+000,20.00000,-4.7302e-002,0.56301
785.20801, 89.75250,    -0.87336,73.39253,50.00000,0.0000e+000,20.00000,-4.6613e-002,0.56228
787.04602, 89.93250,    -0.87731,73.38469,50.00000,0.0000e+000,20.00000,-4.6118e-002,0.56157
788.82599, 90.11250,    -0.87542,73.37746,50.00000,0.0000e+000,20.00000,-4.6015e-002,0.56089
790.61603, 90.29250,    -0.87420,73.37011,50.00000,0.0000e+000,20.00000,-4.6236e-002,0.56020
792.39899, 90.47250,    -0.87496,73.35957,50.00000,0.0000e+000,20.00000,-4.5103e-002,0.55951
794.21899, 90.65250,    -0.87830,73.34987,50.00000,0.0000e+000,20.00000,-4.4332e-002,0.55882
796.03900, 90.83250,    -0.88097,73.34297,50.00000,0.0000e+000,20.00000,-4.4726e-002,0.55812
797.83197, 91.01250,    -0.88254,73.33554,50.00000,0.0000e+000,20.00000,-4.5164e-002,0.55744
799.62799, 91.19250,    -0.88374,73.32916,50.00000,0.0000e+000,20.00000,-4.5327e-002,0.55676
801.43500, 91.37250,    -0.88590,73.32220,50.00000,0.0000e+000,20.00000,-4.5099e-002,0.55607
803.25702, 91.55250,    -0.88758,73.31438,50.00000,0.0000e+000,20.00000,-4.5270e-002,0.55538
805.08099, 91.73250,    -0.88978,73.30633,50.00000,0.0000e+000,20.00000,-4.5630e-002,0.55469
806.91498, 91.91250,    -0.89190,73.29777,50.00000,0.0000e+000,20.00000,-4.5885e-002,0.55400
808.76202, 92.09250,    -0.89595,73.28809,50.00000,0.0000e+000,20.00000,-4.6384e-002,0.55331
810.59601, 92.27250,    -0.89704,73.27947,50.00000,0.0000e+000,20.00000,-4.6361e-002,0.55262
812.41199, 92.45250,    -0.89633,73.27159,50.00000,0.0000e+000,20.00000,-4.6116e-002,0.55195
814.20697, 92.63250,    -0.89566,73.26317,50.00000,0.0000e+000,20.00000,-4.7057e-002,0.55128
816.01001, 92.81250,    -0.89457,73.25372,50.00000,0.0000e+000,20.00000,-4.8025e-002,0.55061
817.79797, 92.99250,    -0.89278,73.24468,50.00000,0.0000e+000,20.00000,-4.9474e-002,0.54994
819.57300, 93.17250,    -0.89175,73.23719,50.00000,0.0000e+000,20.00000,-5.0317e-002,0.54929
821.34003, 93.35250,    -0.89071,73.22949,50.00000,0.0000e+000,20.00000,-5.1095e-002,0.54863
823.12799, 93.53250,    -0.89029,73.22050,50.00000,0.0000e+000,20.00000,-5.2277e-002,0.54797
824.97101, 93.71250,    -0.89381,73.21201,50.00000,0.0000e+000,20.00000,-5.3441e-002,0.54730
826.82501, 93.89250,    -0.89896,73.20337,50.00000,0.0000e+000,20.00000,-5.4326e-002,0.54661
828.65698, 94.07250,    -0.90137,73.19330,50.00000,0.0000e+000,20.00000,-5.4669e-002,0.54594
830.46399, 94.25250,    -0.90053,73.18407,50.00000,0.0000e+000,20.00000,-5.5705e-002,0.54528
832.21899, 94.43250,    -0.89474,73.17361,50.00000,0.0000e+000,20.00000,-5.7597e-002,0.54464
833.98901, 94.61250,    -0.89129,73.16292,50.00000,0.0000e+000,20.00000,-5.9188e-002,0.54400
835.77399, 94.79250,    -0.89048,73.15099,50.00000,0.0000e+000,20.00000,-6.0712e-002,0.54335
837.53998, 94.97250,    -0.89009,73.14085,50.00000,0.0000e+000,20.00000,-6.2607e-002,0.54271
839.33398, 95.15250,    -0.88925,73.13068,50.00000,0.0000e+000,20.00000,-6.4584e-002,0.54206
841.11603, 95.33250,    -0.88665,73.11833,50.00000,0.0000e+000,20.00000,-6.6778e-002,0.54141
842.96301, 95.51250,    -0.88874,73.10589,50.00000,0.0000e+000,20.00000,-6.9281e-002,0.54075
844.79901, 95.69250,    -0.89203,73.09278,50.00000,0.0000e+000,20.00000,-7.2135e-002,0.54008
846.63300, 95.87250,    -0.89501,73.08235,50.00000,0.0000e+000,20.00000,-7.4162e-002,0.53943
848.44202, 96.05250,    -0.89275,73.07131,50.00000,0.0000e+000,20.00000,-7.5396e-002,0.53878
850.24402, 96.23250,    -0.89048,73.05641,50.00000,0.0000e+000,20.00000,-7.7029e-002,0.53813
852.02502, 96.41250,    -0.88788,73.04109,50.00000,0.0000e+000,20.00000,-7.9195e-002,0.53749
853.86200, 96.59250,    -0.88937,73.02634,50.00000,0.0000e+000,20.00000,-8.0922e-002,0.53684
855.68701, 96.77250,    -0.89042,73.01165,50.00000,0.0000e+000,20.00000,-8.1976e-002,0.53618
857.48401, 96.95250,    -0.88829,72.99708,50.00000,0.0000e+000,20.00000,-8.3902e-002,0.53554
859.27197, 97.13250,    -0.88659,72.98049,50.00000,0.0000e+000,20.00000,-8.5708e-002,0.53491
861.12299, 97.31250,    -0.88714,72.96283,50.00000,0.0000e+000,20.00000,-8.7387e-002,0.53425
862.97998, 97.49250,    -0.89138,72.94404,50.00000,0.0000e+000,20.00000,-8.9196e-002,0.53359
864.83502, 97.67250,    -0.89344,72.92612,50.00000,0.0000e+000,20.00000,-9.1886e-002,0.53293
866.64099, 97.85250,    -0.89135,72.91208,50.00000,0.0000e+000,20.00000,-9.4261e-002,0.53230
868.41498, 98.03250,    -0.88791,72.89639,50.00000,0.0000e+000,20.00000,-9.5911e-002,0.53167
870.18500, 98.21250,    -0.88378,72.87809,50.00000,0.0000e+000,20.00000,-9.7599e-002,0.53104
871.94598, 98.39250,    -0.88203,72.85953,50.00000,0.0000e+000,20.00000,-9.8980e-002,0.53042
873.73700, 98.57250,    -0.87988,72.84479,50.00000,0.0000e+000,20.00000,    -0.10024,0.52979
875.53601, 98.75250,    -0.87997,72.82865,50.00000,0.0000e+000,20.00000,    -0.10191,0.52916
877.33197, 98.93250,    -0.88070,72.80974,50.00000,0.0000e+000,20.00000,    -0.10334,0.52853
879.24103, 99.11250,    -0.88850,72.79140,50.00000,0.0000e+000,20.00000,    -0.10468,0.52786
881.13397, 99.29250,    -0.89454,72.77175,50.00000,0.0000e+000,20.00000,    -0.10606,0.52720
882.95502, 99.47250,    -0.89308,72.75110,50.00000,0.0000e+000,20.00000,    -0.10740,0.52656
884.71698, 99.65250,    -0.88671,72.73159,50.00000,0.0000e+000,20.00000,    -0.10958,0.52594
886.46002, 99.83250,    -0.88025,72.71162,50.00000,0.0000e+000,20.00000,    -0.11165,0.52533
888.17700,100.01250,    -0.87428,72.68980,50.00000,0.0000e+000,20.00000,    -0.11270,0.52473
889.91302,100.19250,    -0.87092,72.66979,50.00000,0.0000e+000,20.00000,    -0.11397,0.52413
891.68500,100.37250,    -0.87049,72.65049,50.00000,0.0000e+000,20.00000,    -0.11668,0.52351
893.45001,100.55250,    -0.87200,72.63010,50.00000,0.0000e+000,20.00000,    -0.11939,0.52290
895.24799,100.73250,    -0.87451,72.60875,50.00000,0.0000e+000,20.00000,    -0.12131,0.52227
897.04199,100.91250,    -0.87640,72.58651,50.00000,0.0000e+000,20.00000,    -0.12353,0.52165
898.82703,101.09250,    -0.87858,72.56293,50.00000,0.0000e+000,20.00000,    -0.12523,0.52103
900.63098,101.27250,    -0.88029,72.53956,50.00000,0.0000e+000,20.00000,    -0.12656,0.52040
902.50000,101.45250,    -0.88546,72.51709,50.00000,0.0000e+000,20.00000,    -0.12794,0.51975
904.38300,101.63250,    -0.89441,72.49436,50.00000,0.0000e+000,20.00000,    -0.12944,0.51910
906.18597,101.81250,    -0.89369,72.47241,50.00000,0.0000e+000,20.00000,    -0.13074,0.51848
907.96899,101.99250,    -0.88978,72.44939,50.00000,0.0000e+000,20.00000,    -0.13186,0.51786
909.75299,102.17250,    -0.88858,72.42431,50.00000,0.0000e+000,20.00000,    -0.13326,0.51724
911.56702,102.35250,    -0.89045,72.39895,50.00000,0.0000e+000,20.00000,    -0.13486,0.51661
913.38202,102.53250,    -0.89311,72.37321,50.00000,0.0000e+000,20.00000,    -0.13684,0.51599
915.20001,102.71250,    -0.89624,72.34679,50.00000,0.0000e+000,20.00000,    -0.13879,0.51536
917.04602,102.89250,    -0.90011,72.32095,50.00000,0.0000e+000,20.00000,    -0.14047,0.51472
918.86499,103.07250,    -0.90243,72.29561,50.00000,0.0000e+000,20.00000,    -0.14083,0.51409
920.66101,103.25250,    -0.90240,72.27049,50.00000,0.0000e+000,20.00000,    -0.14130,0.51347
922.45001,103.43250,    -0.90279,72.24587,50.00000,0.0000e+000,20.00000,    -0.14165,0.51286
924.23297,103.61250,    -0.90301,72.21910,50.00000,0.0000e+000,20.00000,    -0.14223,0.51224
926.01202,103.79250,    -0.90290,72.19447,50.00000,0.0000e+000,20.00000,    -0.14292,0.51163
927.80103,103.97250,    -0.90353,72.17020,50.00000,0.0000e+000,20.00000,    -0.14368,0.51101
929.62000,104.15250,    -0.90590,72.14456,50.00000,0.0000e+000,20.00000,    -0.14438,0.51039
931.44000,104.33250,    -0.90721,72.11631,50.00000,0.0000e+000,20.00000,    -0.14468,0.50976
933.25403,104.51250,    -0.90733,72.08731,50.00000,0.0000e+000,20.00000,    -0.14455,0.50913
935.06500,104.69250,    -0.90511,72.05740,50.00000,0.0000e+000,20.00000,    -0.14458,0.50851
936.88300,104.87250,    -0.90198,72.03197,50.00000,0.0000e+000,20.00000,    -0.14537,0.50788
938.69501,105.05250,    -0.89801,72.00780,50.00000,0.0000e+000,20.00000,    -0.14638,0.50726
940.50403,105.23250,    -0.89112,71.98376,50.00000,0.0000e+000,20.00000,    -0.14762,0.50664
942.31097,105.41250,    -0.88511,71.95955,50.00000,0.0000e+000,20.00000,    -0.14767,0.50602
944.09198,105.59250,    -0.87736,71.93477,50.00000,0.0000e+000,20.00000,    -0.14842,0.50540
945.91803,105.77250,    -0.87096,71.90733,50.00000,0.0000e+000,20.00000,    -0.14923,0.50477
947.74200,105.95250,    -0.86573,71.87929,50.00000,0.0000e+000,20.00000,    -0.15033,0.50415
949.51801,106.13250,    -0.85849,71.85245,50.00000,0.0000e+000,20.00000,    -0.15120,0.50353
951.30402,106.31250,    -0.85287,71.82637,50.00000,0.0000e+000,20.00000,    -0.15131,0.50292
953.13300,106.49250,    -0.85026,71.80053,50.00000,0.0000e+000,20.00000,    -0.15099,0.50229
954.92401,106.67250,    -0.84813,71.77256,50.00000,0.0000e+000,20.00000,    -0.15206,0.50167
956.74799,106.85250,    -0.84689,71.74366,50.00000,0.0000e+000,20.00000,    -0.15381,0.50105
958.56500,107.03250,    -0.84493,71.71456,50.00000,0.0000e+000,20.00000,    -0.15570,0.50042
960.44098,107.21250,    -0.84759,71.68745,50.00000,0.0000e+000,20.00000,    -0.15743,0.49977
962.27399,107.39250,    -0.84886,71.65994,50.00000,0.0000e+000,20.00000,    -0.15929,0.49914
964.09399,107.57250,    -0.84759,71.63265,50.00000,0.0000e+000,20.00000,    -0.16022,0.49851
965.89001,107.75250,    -0.84234,71.60394,50.00000,0.0000e+000,20.00000,    -0.15983,0.49789
967.66101,107.93250,    -0.83778,71.57271,50.00000,0.0000e+000,20.00000,    -0.15992,0.49728
969.44397,108.11250,    -0.83486,71.54320,50.00000,0.0000e+000,20.00000,    -0.16029,0.49667
971.24701,108.29250,    -0.83560,71.51436,50.00000,0.0000e+000,20.00000,    -0.16110,0.49604
973.02399,108.47250,    -0.83397,71.48454,50.00000,0.0000e+000,20.00000,    -0.16091,0.49543
974.79797,108.65250,    -0.83336,71.45402,50.00000,0.0000e+000,20.00000,    -0.15976,0.49482
976.60101,108.83250,    -0.83376,71.42307,50.00000,0.0000e+000,20.00000,    -0.15827,0.49419
978.37903,109.01250,    -0.83380,71.39246,50.00000,0.0000e+000,20.00000,    -0.15683,0.49358
980.14001,109.19250,    -0.83270,71.36141,50.00000,0.0000e+000,20.00000,    -0.15572,0.49297
981.96997,109.37250,    -0.83611,71.33036,50.00000,0.0000e+000,20.00000,    -0.15581,0.49234
983.78302,109.55250,    -0.84014,71.30340,50.00000,0.0000e+000,20.00000,    -0.15415,0.49171
985.57397,109.73250,    -0.84055,71.27618,50.00000,0.0000e+000,20.00000,    -0.15297,0.49109
987.40698,109.91250,    -0.84364,71.24871,50.00000,0.0000e+000,20.00000,    -0.15008,0.49045
989.20898,110.09250,    -0.84476,71.22017,50.00000,0.0000e+000,20.00000,    -0.14594,0.48983
991.05402,110.27250,    -0.84967,71.19268,50.00000,0.0000e+000,20.00000,    -0.14187,0.48919
992.86902,110.45250,    -0.85174,71.16790,50.00000,0.0000e+000,20.00000,    -0.13872,0.48856
994.70300,110.63250,    -0.85414,71.14395,50.00000,0.0000e+000,20.00000,    -0.13039,0.48792
996.50403,110.81250,    -0.85601,71.12166,50.00000,0.0000e+000,20.00000,    -0.12507,0.48729
998.28601,110.99250,    -0.85539,71.09990,50.00000,0.0000e+000,20.00000,    -0.14798,0.48667
998.38000,111.00250,    -0.85552,71.09778,50.00000,0.0000e+000,20.00000,    -0.18719,0.48664