File: book/some_content/TG_ExpDat_B30B70D28; 13-1-2025-2.csv
#FILE:                       ,B30B70D28; 13-1-2025.ngb-ds3
#FORMAT:                     ,NETZSCH5
#IDENTITY:                   ,Geopolymere paste
#DECIMAL:                    ,POINT
#SEPARATOR:                  ,COMMA
#MTYPE:                      ,DSC
#INSTRUMENT:                 ,Microlab TU Delft
#PROJECT:                    ,
#DATE/TIME:                  ,13/01/2025 12:57:40 PM
#CORR. FILE:                 ,Blank with cover; 13-1-2025.ngb-bs3
#LABORATORY:                 ,TU Delft Micro Lab
#OPERATOR:                   ,Ahmed
#REMARK:                     ,under Argon atmosphere, 10K/min
#SAMPLE:                     ,R30B70D28;13-1-2025
#SAMPLE MASS /mg:            ,55.0
#MATERIAL:                   ,Geopolymer paste
#REFERENCE:                  ,blank
#REFERENCE MASS /mg:         ,0
#TYPE OF CRUCIBLE:           ,DSC/TG pan Al2O3
#SAMPLE CRUCIBLE MASS /mg:   ,0
#REFERENCE CRUCIBLE MASS /mg:,0
#CORR. CODE:                 ,020
#EXO:                        ,-1
#RANGE:                      ,40/10.0(K/min)/1000
#SEGMENT:                    ,S2/2

##Temp./øC,Time/min,DSC/(mW/mg),Mass/%,Gas Flow(purge1)/(ml/min),Gas Flow(purge2)/(ml/min),Gas Flow(protective)/(ml/min),DTG/(%/min),Sensit./(uV/mW)
 40.55200, 15.00750, 7.1690e-002,97.92325,50.00000,0.0000e+000,20.00000,    -0.16198,1.22618
 40.60600, 15.18750, 7.1287e-002,97.88991,50.00000,0.0000e+000,20.00000,    -0.18173,1.22611
 40.67800, 15.36750, 7.1066e-002,97.85750,50.00000,0.0000e+000,20.00000,    -0.18111,1.22601
 40.75800, 15.54750, 7.1174e-002,97.82495,50.00000,0.0000e+000,20.00000,    -0.18329,1.22590
 40.90800, 15.72750, 7.1628e-002,97.79253,50.00000,0.0000e+000,20.00000,    -0.18657,1.22569
 41.04400, 15.90750, 7.2522e-002,97.75896,50.00000,0.0000e+000,20.00000,    -0.19026,1.22550
 41.32900, 16.08750, 7.4187e-002,97.72498,50.00000,0.0000e+000,20.00000,    -0.19184,1.22511
 41.67300, 16.26750, 7.6741e-002,97.69073,50.00000,0.0000e+000,20.00000,    -0.19518,1.22464
 42.08400, 16.44750, 7.9735e-002,97.65430,50.00000,0.0000e+000,20.00000,    -0.19997,1.22407
 42.55800, 16.62750, 8.3451e-002,97.61685,50.00000,0.0000e+000,20.00000,    -0.20643,1.22342
 43.10400, 16.80750, 8.7984e-002,97.58046,50.00000,0.0000e+000,20.00000,    -0.21523,1.22266
 43.74800, 16.98750, 9.3043e-002,97.54502,50.00000,0.0000e+000,20.00000,    -0.22372,1.22177
 44.46300, 17.16750, 9.8811e-002,97.50857,50.00000,0.0000e+000,20.00000,    -0.23259,1.22079
 45.25500, 17.34750,     0.10529,97.47096,50.00000,0.0000e+000,20.00000,    -0.24259,1.21970
 46.11600, 17.52750,     0.11200,97.43111,50.00000,0.0000e+000,20.00000,    -0.25407,1.21851
 47.06700, 17.70750,     0.11942,97.38989,50.00000,0.0000e+000,20.00000,    -0.26675,1.21720
 48.12300, 17.88750,     0.12712,97.34708,50.00000,0.0000e+000,20.00000,    -0.28094,1.21575
 49.25700, 18.06750,     0.13544,97.30201,50.00000,0.0000e+000,20.00000,    -0.29719,1.21418
 50.41900, 18.24750,     0.14429,97.25422,50.00000,0.0000e+000,20.00000,    -0.31750,1.21258
 51.68600, 18.42750,     0.15350,97.20350,50.00000,0.0000e+000,20.00000,    -0.33923,1.21084
 53.07000, 18.60750,     0.16321,97.14831,50.00000,0.0000e+000,20.00000,    -0.36248,1.20893
 54.50000, 18.78750,     0.17345,97.08698,50.00000,0.0000e+000,20.00000,    -0.38958,1.20697
 55.97300, 18.96750,     0.18438,97.02241,50.00000,0.0000e+000,20.00000,    -0.41915,1.20494
 57.54600, 19.14750,     0.19582,96.95418,50.00000,0.0000e+000,20.00000,    -0.45210,1.20278
 59.20300, 19.32750,     0.20807,96.88058,50.00000,0.0000e+000,20.00000,    -0.48915,1.20050
 60.90800, 19.50750,     0.22069,96.80176,50.00000,0.0000e+000,20.00000,    -0.53056,1.19815
 62.68200, 19.68750,     0.23442,96.71682,50.00000,0.0000e+000,20.00000,    -0.57659,1.19572
 64.54700, 19.86750,     0.24890,96.62499,50.00000,0.0000e+000,20.00000,    -0.62755,1.19316
 66.44100, 20.04750,     0.26429,96.51743,50.00000,0.0000e+000,20.00000,    -0.68397,1.19056
 68.38800, 20.22750,     0.28095,96.40036,50.00000,0.0000e+000,20.00000,    -0.74636,1.18788
 70.41100, 20.40750,     0.29889,96.28059,50.00000,0.0000e+000,20.00000,    -0.81529,1.18511
 72.45600, 20.58750,     0.31787,96.14770,50.00000,0.0000e+000,20.00000,    -0.89065,1.18231
 74.56300, 20.76750,     0.33848,96.00506,50.00000,0.0000e+000,20.00000,    -0.97377,1.17942
 76.70500, 20.94750,     0.36070,95.84956,50.00000,0.0000e+000,20.00000,    -1.06552,1.17649
 78.88300, 21.12750,     0.38471,95.67741,50.00000,0.0000e+000,20.00000,    -1.16576,1.17351
 81.10500, 21.30750,     0.41078,95.48761,50.00000,0.0000e+000,20.00000,    -1.27385,1.17048
 83.35700, 21.48750,     0.43907,95.27984,50.00000,0.0000e+000,20.00000,    -1.39014,1.16740
 85.64600, 21.66750,     0.46969,95.05206,50.00000,0.0000e+000,20.00000,    -1.51457,1.16428
 87.99700, 21.84750,     0.50313,94.80208,50.00000,0.0000e+000,20.00000,    -1.64480,1.16108
 90.32100, 22.02750,     0.53964,94.52784,50.00000,0.0000e+000,20.00000,    -1.78047,1.15792
 92.68600, 22.20750,     0.57874,94.22596,50.00000,0.0000e+000,20.00000,    -1.92429,1.15470
 95.09400, 22.38750,     0.62164,93.89469,50.00000,0.0000e+000,20.00000,    -2.07287,1.15143
 97.47200, 22.56750,     0.66758,93.53175,50.00000,0.0000e+000,20.00000,    -2.22590,1.14820
 99.88600, 22.74750,     0.71692,93.13445,50.00000,0.0000e+000,20.00000,    -2.38117,1.14493
102.28200, 22.92750,     0.76962,92.70064,50.00000,0.0000e+000,20.00000,    -2.53600,1.14168
104.70900, 23.10750,     0.82552,92.23282,50.00000,0.0000e+000,20.00000,    -2.68867,1.13840
107.13100, 23.28750,     0.88358,91.72944,50.00000,0.0000e+000,20.00000,    -2.83675,1.13513
109.55400, 23.46750,     0.94347,91.18960,50.00000,0.0000e+000,20.00000,    -2.97751,1.13186
111.93500, 23.64750,     1.00408,90.61429,50.00000,0.0000e+000,20.00000,    -3.11072,1.12865
114.33800, 23.82750,     1.06441,90.00605,50.00000,0.0000e+000,20.00000,    -3.23458,1.12542
116.71700, 24.00750,     1.12323,89.36695,50.00000,0.0000e+000,20.00000,    -3.34641,1.12223
119.09000, 24.18750,     1.17996,88.69709,50.00000,0.0000e+000,20.00000,    -3.44372,1.11904
121.46300, 24.36750,     1.23314,88.00047,50.00000,0.0000e+000,20.00000,    -3.52379,1.11586
123.82400, 24.54750,     1.28178,87.28224,50.00000,0.0000e+000,20.00000,    -3.58442,1.11270
126.18900, 24.72750,     1.32502,86.54895,50.00000,0.0000e+000,20.00000,    -3.62223,1.10955
128.50400, 24.90750,     1.36209,85.80476,50.00000,0.0000e+000,20.00000,    -3.63651,1.10646
130.90900, 25.08750,     1.39248,85.05808,50.00000,0.0000e+000,20.00000,    -3.62551,1.10326
133.25800, 25.26750,     1.41546,84.31791,50.00000,0.0000e+000,20.00000,    -3.58790,1.10013
135.59599, 25.44750,     1.43107,83.58360,50.00000,0.0000e+000,20.00000,    -3.52295,1.09703
137.95799, 25.62750,     1.43963,82.85851,50.00000,0.0000e+000,20.00000,    -3.43134,1.09390
140.29601, 25.80750,     1.43988,82.14929,50.00000,0.0000e+000,20.00000,    -3.31691,1.09081
142.63699, 25.98750,     1.42846,81.46270,50.00000,0.0000e+000,20.00000,    -3.18109,1.08771
144.98100, 26.16750,     1.40444,80.80698,50.00000,0.0000e+000,20.00000,    -3.02840,1.08462
147.31400, 26.34750,     1.36812,80.18723,50.00000,0.0000e+000,20.00000,    -2.86309,1.08155
149.66100, 26.52750,     1.32029,79.61307,50.00000,0.0000e+000,20.00000,    -2.68810,1.07847
152.01500, 26.70750,     1.26258,79.09001,50.00000,0.0000e+000,20.00000,    -2.50770,1.07538
154.35600, 26.88750,     1.19497,78.62340,50.00000,0.0000e+000,20.00000,    -2.32494,1.07232
156.69299, 27.06750,     1.11604,78.21706,50.00000,0.0000e+000,20.00000,    -2.14185,1.06927
159.05000, 27.24750,     1.02755,77.87437,50.00000,0.0000e+000,20.00000,    -1.95936,1.06620
161.38300, 27.42750,     0.93012,77.59662,50.00000,0.0000e+000,20.00000,    -1.77648,1.06316
163.72200, 27.60750,     0.82939,77.37309,50.00000,0.0000e+000,20.00000,    -1.59568,1.06012
166.03400, 27.78750,     0.72936,77.19736,50.00000,0.0000e+000,20.00000,    -1.42091,1.05713
168.33600, 27.96750,     0.63111,77.05863,50.00000,0.0000e+000,20.00000,    -1.25290,1.05415
170.61400, 28.14750,     0.54040,76.94388,50.00000,0.0000e+000,20.00000,    -1.09347,1.05121
172.86099, 28.32750,     0.46041,76.84997,50.00000,0.0000e+000,20.00000,    -0.94525,1.04832
175.12300, 28.50750,     0.39109,76.76578,50.00000,0.0000e+000,20.00000,    -0.81035,1.04541
177.34000, 28.68750,     0.33167,76.68579,50.00000,0.0000e+000,20.00000,    -0.69041,1.04256
179.53000, 28.86750,     0.28044,76.61283,50.00000,0.0000e+000,20.00000,    -0.58649,1.03976
181.72200, 29.04750,     0.23628,76.54390,50.00000,0.0000e+000,20.00000,    -0.49889,1.03696
183.87199, 29.22750,     0.19804,76.48357,50.00000,0.0000e+000,20.00000,    -0.42833,1.03422
185.98900, 29.40750,     0.16496,76.43206,50.00000,0.0000e+000,20.00000,    -0.37240,1.03153
188.08600, 29.58750,     0.13604,76.38014,50.00000,0.0000e+000,20.00000,    -0.32911,1.02887
190.15300, 29.76750,     0.11085,76.33245,50.00000,0.0000e+000,20.00000,    -0.29651,1.02625
192.17900, 29.94750, 8.8892e-002,76.28909,50.00000,0.0000e+000,20.00000,    -0.27077,1.02369
194.19000, 30.12750, 6.9321e-002,76.24864,50.00000,0.0000e+000,20.00000,    -0.25105,1.02115
196.15401, 30.30750, 5.1895e-002,76.21043,50.00000,0.0000e+000,20.00000,    -0.23411,1.01868
198.10500, 30.48750, 3.6077e-002,76.17312,50.00000,0.0000e+000,20.00000,    -0.21803,1.01623
200.04201, 30.66750, 2.2166e-002,76.13695,50.00000,0.0000e+000,20.00000,    -0.20362,1.01380
201.94299, 30.84750, 9.5182e-003,76.10376,50.00000,0.0000e+000,20.00000,    -0.19007,1.01142
203.80200, 31.02750,-2.2682e-003,76.07414,50.00000,0.0000e+000,20.00000,    -0.17812,1.00910
205.66499, 31.20750,-1.3296e-002,76.04688,50.00000,0.0000e+000,20.00000,    -0.16846,1.00678
207.50000, 31.38750,-2.3435e-002,76.02226,50.00000,0.0000e+000,20.00000,    -0.15920,1.00450
209.30800, 31.56750,-3.2982e-002,75.99809,50.00000,0.0000e+000,20.00000,    -0.15095,1.00226
211.10300, 31.74750,-4.2043e-002,75.97403,50.00000,0.0000e+000,20.00000,    -0.14308,1.00003
212.89101, 31.92750,-5.0297e-002,75.94942,50.00000,0.0000e+000,20.00000,    -0.13617,0.99782
214.66200, 32.10750,-5.8600e-002,75.92623,50.00000,0.0000e+000,20.00000,    -0.13014,0.99564
216.41701, 32.28750,-6.6155e-002,75.90397,50.00000,0.0000e+000,20.00000,    -0.12387,0.99348
218.16200, 32.46750,-7.3574e-002,75.88258,50.00000,0.0000e+000,20.00000,    -0.11754,0.99134
219.89301, 32.64750,-8.0772e-002,75.86237,50.00000,0.0000e+000,20.00000,    -0.11208,0.98922
221.61501, 32.82750,-8.7591e-002,75.84366,50.00000,0.0000e+000,20.00000,    -0.10822,0.98711
223.33600, 33.00750,-9.4129e-002,75.82667,50.00000,0.0000e+000,20.00000,    -0.10496,0.98501
225.04700, 33.18750,    -0.10050,75.80906,50.00000,0.0000e+000,20.00000,    -0.10235,0.98292
226.75000, 33.36750,    -0.10629,75.79022,50.00000,0.0000e+000,20.00000,-9.9427e-002,0.98085
228.45700, 33.54750,    -0.11257,75.77481,50.00000,0.0000e+000,20.00000,-9.6527e-002,0.97878
230.14400, 33.72750,    -0.11817,75.75948,50.00000,0.0000e+000,20.00000,-9.3555e-002,0.97674
231.83900, 33.90750,    -0.12394,75.74294,50.00000,0.0000e+000,20.00000,-9.1051e-002,0.97469
233.53300, 34.08750,    -0.12974,75.72812,50.00000,0.0000e+000,20.00000,-8.9035e-002,0.97265
235.20399, 34.26750,    -0.13535,75.71474,50.00000,0.0000e+000,20.00000,-8.6879e-002,0.97064
236.90601, 34.44750,    -0.14074,75.70114,50.00000,0.0000e+000,20.00000,-8.4771e-002,0.96860
238.57700, 34.62750,    -0.14588,75.68548,50.00000,0.0000e+000,20.00000,-8.2804e-002,0.96660
240.26500, 34.80750,    -0.15132,75.66956,50.00000,0.0000e+000,20.00000,-8.1541e-002,0.96458
241.94901, 34.98750,    -0.15652,75.65416,50.00000,0.0000e+000,20.00000,-8.0448e-002,0.96257
243.62900, 35.16750,    -0.16175,75.64031,50.00000,0.0000e+000,20.00000,-7.8554e-002,0.96057
245.30901, 35.34750,    -0.16624,75.62708,50.00000,0.0000e+000,20.00000,-7.7241e-002,0.95858
247.00101, 35.52750,    -0.17141,75.61326,50.00000,0.0000e+000,20.00000,-7.6197e-002,0.95657
248.67700, 35.70750,    -0.17574,75.59919,50.00000,0.0000e+000,20.00000,-7.5240e-002,0.95459
250.36700, 35.88750,    -0.18032,75.58413,50.00000,0.0000e+000,20.00000,-7.4684e-002,0.95260
252.05200, 36.06750,    -0.18475,75.57024,50.00000,0.0000e+000,20.00000,-7.4503e-002,0.95061
253.75500, 36.24750,    -0.18921,75.55741,50.00000,0.0000e+000,20.00000,-7.4354e-002,0.94861
255.45000, 36.42750,    -0.19347,75.54555,50.00000,0.0000e+000,20.00000,-7.3832e-002,0.94663
257.15500, 36.60750,    -0.19770,75.53320,50.00000,0.0000e+000,20.00000,-7.2649e-002,0.94464
258.85001, 36.78750,    -0.20182,75.51984,50.00000,0.0000e+000,20.00000,-7.1513e-002,0.94266
260.55099, 36.96750,    -0.20621,75.50761,50.00000,0.0000e+000,20.00000,-7.1027e-002,0.94068
262.24799, 37.14750,    -0.20991,75.49632,50.00000,0.0000e+000,20.00000,-7.1246e-002,0.93871
263.95700, 37.32750,    -0.21376,75.48534,50.00000,0.0000e+000,20.00000,-7.1264e-002,0.93673
265.66400, 37.50750,    -0.21734,75.47243,50.00000,0.0000e+000,20.00000,-7.1310e-002,0.93476
267.36499, 37.68750,    -0.22138,75.45927,50.00000,0.0000e+000,20.00000,-7.1075e-002,0.93280
269.07001, 37.86750,    -0.22492,75.44638,50.00000,0.0000e+000,20.00000,-7.1218e-002,0.93084
270.80301, 38.04750,    -0.22867,75.43359,50.00000,0.0000e+000,20.00000,-7.1918e-002,0.92886
272.52100, 38.22750,    -0.23240,75.42010,50.00000,0.0000e+000,20.00000,-7.2813e-002,0.92689
274.24899, 38.40750,    -0.23639,75.40811,50.00000,0.0000e+000,20.00000,-7.3723e-002,0.92492
275.95200, 38.58750,    -0.23965,75.39685,50.00000,0.0000e+000,20.00000,-7.4083e-002,0.92298
277.69299, 38.76750,    -0.24350,75.38473,50.00000,0.0000e+000,20.00000,-7.4982e-002,0.92101
279.39999, 38.94750,    -0.24682,75.37092,50.00000,0.0000e+000,20.00000,-7.6256e-002,0.91908
281.14801, 39.12750,    -0.25018,75.35698,50.00000,0.0000e+000,20.00000,-7.7656e-002,0.91710
282.88501, 39.30750,    -0.25335,75.34300,50.00000,0.0000e+000,20.00000,-7.8765e-002,0.91515
284.61401, 39.48750,    -0.25636,75.32875,50.00000,0.0000e+000,20.00000,-7.9760e-002,0.91320
286.35400, 39.66750,    -0.25974,75.31431,50.00000,0.0000e+000,20.00000,-8.0898e-002,0.91125
288.08899, 39.84750,    -0.26290,75.29881,50.00000,0.0000e+000,20.00000,-8.2293e-002,0.90932
289.84601, 40.02750,    -0.26612,75.28355,50.00000,0.0000e+000,20.00000,-8.3182e-002,0.90736
291.58099, 40.20750,    -0.26915,75.26805,50.00000,0.0000e+000,20.00000,-8.4218e-002,0.90543
293.31900, 40.38750,    -0.27233,75.25333,50.00000,0.0000e+000,20.00000,-8.5738e-002,0.90350
295.08701, 40.56750,    -0.27554,75.23782,50.00000,0.0000e+000,20.00000,-8.7429e-002,0.90155
296.81799, 40.74750,    -0.27850,75.22170,50.00000,0.0000e+000,20.00000,-8.8614e-002,0.89964
298.57001, 40.92750,    -0.28194,75.20575,50.00000,0.0000e+000,20.00000,-8.9651e-002,0.89772
300.33401, 41.10750,    -0.28503,75.18919,50.00000,0.0000e+000,20.00000,-9.0884e-002,0.89578
302.07199, 41.28750,    -0.28844,75.17229,50.00000,0.0000e+000,20.00000,-9.2347e-002,0.89388
303.83200, 41.46750,    -0.29125,75.15532,50.00000,0.0000e+000,20.00000,-9.3871e-002,0.89197
305.60300, 41.64750,    -0.29447,75.13753,50.00000,0.0000e+000,20.00000,-9.4826e-002,0.89004
307.36200, 41.82750,    -0.29776,75.12054,50.00000,0.0000e+000,20.00000,-9.6105e-002,0.88814
309.13501, 42.00750,    -0.30039,75.10451,50.00000,0.0000e+000,20.00000,-9.7544e-002,0.88622
310.90302, 42.18750,    -0.30345,75.08786,50.00000,0.0000e+000,20.00000,-9.9459e-002,0.88432
312.66199, 42.36750,    -0.30627,75.06995,50.00000,0.0000e+000,20.00000,    -0.10130,0.88243
314.42700, 42.54750,    -0.30953,75.05188,50.00000,0.0000e+000,20.00000,    -0.10301,0.88054
316.19501, 42.72750,    -0.31193,75.03417,50.00000,0.0000e+000,20.00000,    -0.10465,0.87865
317.95099, 42.90750,    -0.31430,75.01586,50.00000,0.0000e+000,20.00000,    -0.10621,0.87678
319.73199, 43.08750,    -0.31630,74.99647,50.00000,0.0000e+000,20.00000,    -0.10802,0.87489
321.48999, 43.26750,    -0.31807,74.97643,50.00000,0.0000e+000,20.00000,    -0.11002,0.87303
323.25400, 43.44750,    -0.32028,74.95752,50.00000,0.0000e+000,20.00000,    -0.11197,0.87116
325.01700, 43.62750,    -0.32241,74.93772,50.00000,0.0000e+000,20.00000,    -0.11389,0.86931
326.79300, 43.80750,    -0.32429,74.91712,50.00000,0.0000e+000,20.00000,    -0.11561,0.86745
328.55801, 43.98750,    -0.32594,74.89540,50.00000,0.0000e+000,20.00000,    -0.11758,0.86560
330.33200, 44.16750,    -0.32807,74.87342,50.00000,0.0000e+000,20.00000,    -0.11933,0.86375
332.11899, 44.34750,    -0.33035,74.85102,50.00000,0.0000e+000,20.00000,    -0.11982,0.86189
333.88501, 44.52750,    -0.33236,74.82903,50.00000,0.0000e+000,20.00000,    -0.12068,0.86006
335.66000, 44.70750,    -0.33487,74.80702,50.00000,0.0000e+000,20.00000,    -0.12122,0.85823
337.44601, 44.88750,    -0.33758,74.78369,50.00000,0.0000e+000,20.00000,    -0.12137,0.85639
339.21799, 45.06750,    -0.34042,74.75959,50.00000,0.0000e+000,20.00000,    -0.12145,0.85457
340.98499, 45.24750,    -0.34334,74.73482,50.00000,0.0000e+000,20.00000,    -0.12169,0.85277
342.76901, 45.42750,    -0.34680,74.71036,50.00000,0.0000e+000,20.00000,    -0.12159,0.85095
344.54099, 45.60750,    -0.35095,74.68779,50.00000,0.0000e+000,20.00000,    -0.12114,0.84915
346.33401, 45.78750,    -0.35597,74.66456,50.00000,0.0000e+000,20.00000,    -0.11950,0.84733
348.11401, 45.96750,    -0.36086,74.63995,50.00000,0.0000e+000,20.00000,    -0.11781,0.84553
349.90500, 46.14750,    -0.36663,74.61966,50.00000,0.0000e+000,20.00000,    -0.11679,0.84373
351.70700, 46.32750,    -0.37258,74.59904,50.00000,0.0000e+000,20.00000,    -0.11480,0.84192
353.51099, 46.50750,    -0.37808,74.57863,50.00000,0.0000e+000,20.00000,    -0.11288,0.84012
355.29800, 46.68750,    -0.38294,74.55901,50.00000,0.0000e+000,20.00000,    -0.11057,0.83833
357.10199, 46.86750,    -0.38757,74.53863,50.00000,0.0000e+000,20.00000,    -0.10750,0.83654
358.88199, 47.04750,    -0.39246,74.51859,50.00000,0.0000e+000,20.00000,    -0.10439,0.83478
360.65399, 47.22750,    -0.39752,74.49941,50.00000,0.0000e+000,20.00000,    -0.10073,0.83303
362.43701, 47.40750,    -0.40279,74.48023,50.00000,0.0000e+000,20.00000,-9.7538e-002,0.83128
364.21301, 47.58750,    -0.40787,74.46423,50.00000,0.0000e+000,20.00000,-9.4056e-002,0.82954
365.98401, 47.76750,    -0.41335,74.44888,50.00000,0.0000e+000,20.00000,-9.0059e-002,0.82781
367.77701, 47.94750,    -0.41891,74.43024,50.00000,0.0000e+000,20.00000,-8.7369e-002,0.82606
369.54901, 48.12750,    -0.42422,74.41488,50.00000,0.0000e+000,20.00000,-8.4322e-002,0.82434
371.32001, 48.30750,    -0.42880,74.40029,50.00000,0.0000e+000,20.00000,-8.1240e-002,0.82263
373.09601, 48.48750,    -0.43410,74.38521,50.00000,0.0000e+000,20.00000,-7.8314e-002,0.82092
374.87701, 48.66750,    -0.43934,74.37245,50.00000,0.0000e+000,20.00000,-7.5464e-002,0.81921
376.67899, 48.84750,    -0.44485,74.35900,50.00000,0.0000e+000,20.00000,-7.2426e-002,0.81748
378.45200, 49.02750,    -0.45008,74.34751,50.00000,0.0000e+000,20.00000,-6.9532e-002,0.81579
380.24399, 49.20750,    -0.45482,74.33634,50.00000,0.0000e+000,20.00000,-6.6799e-002,0.81409
382.01099, 49.38750,    -0.45929,74.32601,50.00000,0.0000e+000,20.00000,-6.4352e-002,0.81241
383.80399, 49.56750,    -0.46382,74.31600,50.00000,0.0000e+000,20.00000,-6.3055e-002,0.81072
385.58099, 49.74750,    -0.46797,74.30490,50.00000,0.0000e+000,20.00000,-6.0067e-002,0.80905
387.37100, 49.92750,    -0.47293,74.29542,50.00000,0.0000e+000,20.00000,-5.7615e-002,0.80737
389.16800, 50.10750,    -0.47763,74.28616,50.00000,0.0000e+000,20.00000,-5.5248e-002,0.80570
390.94699, 50.28750,    -0.48210,74.27715,50.00000,0.0000e+000,20.00000,-5.2816e-002,0.80404
392.74200, 50.46750,    -0.48663,74.26756,50.00000,0.0000e+000,20.00000,-5.1422e-002,0.80238
394.53299, 50.64750,    -0.49080,74.25801,50.00000,0.0000e+000,20.00000,-4.9948e-002,0.80072
396.30200, 50.82750,    -0.49514,74.24977,50.00000,0.0000e+000,20.00000,-4.8708e-002,0.79909
398.09500, 51.00750,    -0.49880,74.24006,50.00000,0.0000e+000,20.00000,-4.7965e-002,0.79745
399.87399, 51.18750,    -0.50233,74.23265,50.00000,0.0000e+000,20.00000,-4.7708e-002,0.79582
401.66000, 51.36750,    -0.50565,74.22246,50.00000,0.0000e+000,20.00000,-4.7100e-002,0.79420
403.43399, 51.54750,    -0.50932,74.21453,50.00000,0.0000e+000,20.00000,-4.6413e-002,0.79259
405.21201, 51.72750,    -0.51374,74.20746,50.00000,0.0000e+000,20.00000,-4.6608e-002,0.79098
407.00900, 51.90750,    -0.51825,74.20155,50.00000,0.0000e+000,20.00000,-4.6459e-002,0.78936
408.80099, 52.08750,    -0.52242,74.19539,50.00000,0.0000e+000,20.00000,-4.6280e-002,0.78776
410.58600, 52.26750,    -0.52588,74.18772,50.00000,0.0000e+000,20.00000,-4.6478e-002,0.78616
412.39401, 52.44750,    -0.52955,74.17960,50.00000,0.0000e+000,20.00000,-4.6670e-002,0.78455
414.16501, 52.62750,    -0.53298,74.17230,50.00000,0.0000e+000,20.00000,-4.6527e-002,0.78298
415.94901, 52.80750,    -0.53635,74.16413,50.00000,0.0000e+000,20.00000,-4.5903e-002,0.78140
417.73099, 52.98750,    -0.53970,74.15455,50.00000,0.0000e+000,20.00000,-4.5813e-002,0.77983
419.52701, 53.16750,    -0.54295,74.14653,50.00000,0.0000e+000,20.00000,-4.5199e-002,0.77826
421.29901, 53.34750,    -0.54573,74.13844,50.00000,0.0000e+000,20.00000,-4.4574e-002,0.77671
423.08600, 53.52750,    -0.54899,74.12796,50.00000,0.0000e+000,20.00000,-4.4259e-002,0.77516
424.88000, 53.70750,    -0.55241,74.11903,50.00000,0.0000e+000,20.00000,-4.4049e-002,0.77360
426.65900, 53.88750,    -0.55604,74.11068,50.00000,0.0000e+000,20.00000,-4.4118e-002,0.77206
428.44299, 54.06750,    -0.55949,74.10100,50.00000,0.0000e+000,20.00000,-4.3615e-002,0.77053
430.23001, 54.24750,    -0.56331,74.09006,50.00000,0.0000e+000,20.00000,-4.2755e-002,0.76900
432.01599, 54.42750,    -0.56635,74.08225,50.00000,0.0000e+000,20.00000,-4.2160e-002,0.76747
433.79999, 54.60750,    -0.56955,74.07475,50.00000,0.0000e+000,20.00000,-4.1651e-002,0.76595
435.58899, 54.78750,    -0.57308,74.06755,50.00000,0.0000e+000,20.00000,-4.0843e-002,0.76444
437.37299, 54.96750,    -0.57686,74.05997,50.00000,0.0000e+000,20.00000,-4.0273e-002,0.76293
439.17300, 55.14750,    -0.58125,74.05348,50.00000,0.0000e+000,20.00000,-3.9802e-002,0.76142
440.95200, 55.32750,    -0.58473,74.04772,50.00000,0.0000e+000,20.00000,-3.8265e-002,0.75993
442.75101, 55.50750,    -0.58870,74.04215,50.00000,0.0000e+000,20.00000,-3.7311e-002,0.75843
444.55399, 55.68750,    -0.59300,74.03621,50.00000,0.0000e+000,20.00000,-3.6784e-002,0.75693
446.36301, 55.86750,    -0.59711,74.03030,50.00000,0.0000e+000,20.00000,-3.5816e-002,0.75543
448.14700, 56.04750,    -0.60061,74.02530,50.00000,0.0000e+000,20.00000,-3.4158e-002,0.75396
449.94901, 56.22750,    -0.60343,74.02017,50.00000,0.0000e+000,20.00000,-3.3602e-002,0.75248
451.74799, 56.40750,    -0.60521,74.01418,50.00000,0.0000e+000,20.00000,-3.3253e-002,0.75101
453.53400, 56.58750,    -0.60760,74.00777,50.00000,0.0000e+000,20.00000,-3.2753e-002,0.74956
455.31799, 56.76750,    -0.61041,74.00136,50.00000,0.0000e+000,20.00000,-3.2037e-002,0.74811
457.09399, 56.94750,    -0.61396,73.99519,50.00000,0.0000e+000,20.00000,-3.1742e-002,0.74667
458.88501, 57.12750,    -0.61725,73.99051,50.00000,0.0000e+000,20.00000,-3.2085e-002,0.74523
460.65900, 57.30750,    -0.62019,73.98477,50.00000,0.0000e+000,20.00000,-3.2401e-002,0.74381
462.45499, 57.48750,    -0.62346,73.97854,50.00000,0.0000e+000,20.00000,-3.2369e-002,0.74238
464.24301, 57.66750,    -0.62611,73.97260,50.00000,0.0000e+000,20.00000,-3.2272e-002,0.74096
466.02301, 57.84750,    -0.62954,73.96744,50.00000,0.0000e+000,20.00000,-3.2449e-002,0.73955
467.81201, 58.02750,    -0.63232,73.96161,50.00000,0.0000e+000,20.00000,-3.3258e-002,0.73814
469.58899, 58.20750,    -0.63518,73.95518,50.00000,0.0000e+000,20.00000,-3.4208e-002,0.73674
471.37900, 58.38750,    -0.63759,73.94976,50.00000,0.0000e+000,20.00000,-3.4810e-002,0.73534
473.17200, 58.56750,    -0.64051,73.94476,50.00000,0.0000e+000,20.00000,-3.5082e-002,0.73394
474.97601, 58.74750,    -0.64400,73.93931,50.00000,0.0000e+000,20.00000,-3.4993e-002,0.73254
476.79800, 58.92750,    -0.65016,73.93249,50.00000,0.0000e+000,20.00000,-3.5370e-002,0.73114
478.62799, 59.10750,    -0.65459,73.92543,50.00000,0.0000e+000,20.00000,-3.5663e-002,0.72973
480.40799, 59.28750,    -0.65642,73.91979,50.00000,0.0000e+000,20.00000,-3.6028e-002,0.72836
482.18399, 59.46750,    -0.65570,73.91400,50.00000,0.0000e+000,20.00000,-3.6541e-002,0.72701
483.96301, 59.64750,    -0.65698,73.90840,50.00000,0.0000e+000,20.00000,-3.7557e-002,0.72566
485.79199, 59.82750,    -0.66086,73.90088,50.00000,0.0000e+000,20.00000,-3.7982e-002,0.72427
487.58801, 60.00750,    -0.66512,73.89145,50.00000,0.0000e+000,20.00000,-3.7741e-002,0.72292
489.39301, 60.18750,    -0.66824,73.88283,50.00000,0.0000e+000,20.00000,-3.7971e-002,0.72157
491.18600, 60.36750,    -0.67010,73.87510,50.00000,0.0000e+000,20.00000,-3.8354e-002,0.72023
492.97800, 60.54750,    -0.67178,73.86905,50.00000,0.0000e+000,20.00000,-3.8765e-002,0.71889
494.76199, 60.72750,    -0.67368,73.86294,50.00000,0.0000e+000,20.00000,-3.8852e-002,0.71757
496.54401, 60.90750,    -0.67592,73.85640,50.00000,0.0000e+000,20.00000,-3.9030e-002,0.71626
498.31201, 61.08750,    -0.67746,73.84903,50.00000,0.0000e+000,20.00000,-3.9264e-002,0.71496
500.10300, 61.26750,    -0.68026,73.84119,50.00000,0.0000e+000,20.00000,-3.9530e-002,0.71365
501.90201, 61.44750,    -0.68424,73.83221,50.00000,0.0000e+000,20.00000,-4.0062e-002,0.71234
503.68799, 61.62750,    -0.68823,73.82479,50.00000,0.0000e+000,20.00000,-4.0259e-002,0.71104
505.51999, 61.80750,    -0.69251,73.81897,50.00000,0.0000e+000,20.00000,-3.9981e-002,0.70972
507.33401, 61.98750,    -0.69676,73.81282,50.00000,0.0000e+000,20.00000,-3.9542e-002,0.70841
509.14200, 62.16750,    -0.69909,73.80633,50.00000,0.0000e+000,20.00000,-3.9674e-002,0.70712
510.91800, 62.34750,    -0.69941,73.79952,50.00000,0.0000e+000,20.00000,-4.0651e-002,0.70585
512.69098, 62.52750,    -0.69825,73.79282,50.00000,0.0000e+000,20.00000,-4.1706e-002,0.70459
514.44202, 62.70750,    -0.69871,73.78482,50.00000,0.0000e+000,20.00000,-4.2203e-002,0.70336
516.21002, 62.88750,    -0.70106,73.77816,50.00000,0.0000e+000,20.00000,-4.2284e-002,0.70211
518.02802, 63.06750,    -0.70611,73.77146,50.00000,0.0000e+000,20.00000,-4.2501e-002,0.70084
519.85498, 63.24750,    -0.71160,73.76403,50.00000,0.0000e+000,20.00000,-4.2320e-002,0.69956
521.64697, 63.42750,    -0.71460,73.75636,50.00000,0.0000e+000,20.00000,-4.2905e-002,0.69832
523.45300, 63.60750,    -0.71696,73.74793,50.00000,0.0000e+000,20.00000,-4.4457e-002,0.69707
525.27100, 63.78750,    -0.72088,73.74066,50.00000,0.0000e+000,20.00000,-4.5528e-002,0.69581
527.10303, 63.96750,    -0.72442,73.73261,50.00000,0.0000e+000,20.00000,-4.6383e-002,0.69456
528.91699, 64.14750,    -0.72688,73.72286,50.00000,0.0000e+000,20.00000,-4.7346e-002,0.69332
530.71002, 64.32750,    -0.72711,73.71292,50.00000,0.0000e+000,20.00000,-4.8614e-002,0.69210
532.50299, 64.50750,    -0.72859,73.70431,50.00000,0.0000e+000,20.00000,-4.8880e-002,0.69089
534.29700, 64.68750,    -0.72951,73.69691,50.00000,0.0000e+000,20.00000,-4.9506e-002,0.68968
536.09100, 64.86750,    -0.73209,73.68837,50.00000,0.0000e+000,20.00000,-5.0620e-002,0.68847
537.89099, 65.04750,    -0.73489,73.68020,50.00000,0.0000e+000,20.00000,-5.1662e-002,0.68727
539.70001, 65.22750,    -0.73796,73.67068,50.00000,0.0000e+000,20.00000,-5.2649e-002,0.68607
541.48602, 65.40750,    -0.74069,73.65904,50.00000,0.0000e+000,20.00000,-5.3522e-002,0.68488
543.28699, 65.58750,    -0.74256,73.64883,50.00000,0.0000e+000,20.00000,-5.4602e-002,0.68370
545.08398, 65.76750,    -0.74509,73.63932,50.00000,0.0000e+000,20.00000,-5.5464e-002,0.68252
546.87701, 65.94750,    -0.74735,73.62915,50.00000,0.0000e+000,20.00000,-5.5597e-002,0.68134
548.67297, 66.12750,    -0.74930,73.61789,50.00000,0.0000e+000,20.00000,-5.5726e-002,0.68017
550.45898, 66.30750,    -0.75146,73.60857,50.00000,0.0000e+000,20.00000,-5.6190e-002,0.67902
552.23297, 66.48750,    -0.75285,73.59976,50.00000,0.0000e+000,20.00000,-5.7123e-002,0.67787
554.04401, 66.66750,    -0.75617,73.58915,50.00000,0.0000e+000,20.00000,-5.7509e-002,0.67671
555.86298, 66.84750,    -0.75990,73.57809,50.00000,0.0000e+000,20.00000,-5.8127e-002,0.67555
557.69098, 67.02750,    -0.76335,73.56686,50.00000,0.0000e+000,20.00000,-5.8571e-002,0.67438
559.47498, 67.20750,    -0.76626,73.55539,50.00000,0.0000e+000,20.00000,-5.8247e-002,0.67325
561.28699, 67.38750,    -0.76777,73.54380,50.00000,0.0000e+000,20.00000,-5.8231e-002,0.67211
563.08099, 67.56750,    -0.76865,73.53292,50.00000,0.0000e+000,20.00000,-5.8827e-002,0.67098
564.86102, 67.74750,    -0.76937,73.52271,50.00000,0.0000e+000,20.00000,-5.9008e-002,0.66987
566.66199, 67.92750,    -0.77128,73.51233,50.00000,0.0000e+000,20.00000,-5.8868e-002,0.66875
568.45697, 68.10750,    -0.77331,73.50179,50.00000,0.0000e+000,20.00000,-5.9404e-002,0.66763
570.24103, 68.28750,    -0.77526,73.49090,50.00000,0.0000e+000,20.00000,-6.0139e-002,0.66653
572.03900, 68.46750,    -0.77681,73.48098,50.00000,0.0000e+000,20.00000,-5.9863e-002,0.66543
573.82001, 68.64750,    -0.77920,73.47066,50.00000,0.0000e+000,20.00000,-5.9767e-002,0.66434
575.62500, 68.82750,    -0.78260,73.45988,50.00000,0.0000e+000,20.00000,-6.0726e-002,0.66324
577.41998, 69.00750,    -0.78519,73.44943,50.00000,0.0000e+000,20.00000,-6.1319e-002,0.66215
579.20898, 69.18750,    -0.78821,73.43915,50.00000,0.0000e+000,20.00000,-6.1131e-002,0.66107
581.00800, 69.36750,    -0.79072,73.42756,50.00000,0.0000e+000,20.00000,-6.1235e-002,0.65999
582.80200, 69.54750,    -0.79285,73.41666,50.00000,0.0000e+000,20.00000,-6.1389e-002,0.65891
584.59302, 69.72750,    -0.79528,73.40615,50.00000,0.0000e+000,20.00000,-6.1657e-002,0.65784
586.40802, 69.90750,    -0.79937,73.39451,50.00000,0.0000e+000,20.00000,-6.2057e-002,0.65677
588.23102, 70.08750,    -0.80303,73.38306,50.00000,0.0000e+000,20.00000,-6.2875e-002,0.65569
590.01801, 70.26750,    -0.80491,73.37339,50.00000,0.0000e+000,20.00000,-6.4447e-002,0.65464
591.82501, 70.44750,    -0.80619,73.36325,50.00000,0.0000e+000,20.00000,-6.5568e-002,0.65358
593.61798, 70.62750,    -0.80800,73.34902,50.00000,0.0000e+000,20.00000,-6.5822e-002,0.65254
595.43201, 70.80750,    -0.81194,73.33482,50.00000,0.0000e+000,20.00000,-6.5839e-002,0.65148
597.25098, 70.98750,    -0.81562,73.32382,50.00000,0.0000e+000,20.00000,-6.6332e-002,0.65043
599.07898, 71.16750,    -0.81874,73.31238,50.00000,0.0000e+000,20.00000,-6.6972e-002,0.64938
600.87799, 71.34750,    -0.81997,73.30160,50.00000,0.0000e+000,20.00000,-6.7519e-002,0.64835
602.68799, 71.52750,    -0.82096,73.29029,50.00000,0.0000e+000,20.00000,-6.8040e-002,0.64732
604.48798, 71.70750,    -0.82211,73.27853,50.00000,0.0000e+000,20.00000,-6.8395e-002,0.64630
606.28497, 71.88750,    -0.82377,73.26504,50.00000,0.0000e+000,20.00000,-6.9193e-002,0.64528
608.08801, 72.06750,    -0.82564,73.24926,50.00000,0.0000e+000,20.00000,-7.0432e-002,0.64427
609.88300, 72.24750,    -0.82728,73.23469,50.00000,0.0000e+000,20.00000,-7.1441e-002,0.64326
611.67798, 72.42750,    -0.82887,73.22255,50.00000,0.0000e+000,20.00000,-7.1481e-002,0.64226
613.47498, 72.60750,    -0.82995,73.21204,50.00000,0.0000e+000,20.00000,-7.1027e-002,0.64126
615.27698, 72.78750,    -0.83119,73.20032,50.00000,0.0000e+000,20.00000,-7.1743e-002,0.64027
617.06500, 72.96750,    -0.83148,73.18671,50.00000,0.0000e+000,20.00000,-7.2437e-002,0.63928
618.86499, 73.14750,    -0.83480,73.17335,50.00000,0.0000e+000,20.00000,-7.3136e-002,0.63829
620.68799, 73.32750,    -0.83857,73.16105,50.00000,0.0000e+000,20.00000,-7.3985e-002,0.63730
622.51202, 73.50750,    -0.84223,73.14837,50.00000,0.0000e+000,20.00000,-7.4526e-002,0.63631
624.33002, 73.68750,    -0.84499,73.13414,50.00000,0.0000e+000,20.00000,-7.4091e-002,0.63532
626.12903, 73.86750,    -0.84535,73.11945,50.00000,0.0000e+000,20.00000,-7.3420e-002,0.63436
627.92999, 74.04750,    -0.84453,73.10597,50.00000,0.0000e+000,20.00000,-7.3569e-002,0.63339
629.71600, 74.22750,    -0.84398,73.09220,50.00000,0.0000e+000,20.00000,-7.4562e-002,0.63244
631.51501, 74.40750,    -0.84509,73.07911,50.00000,0.0000e+000,20.00000,-7.6328e-002,0.63148
633.29901, 74.58750,    -0.84653,73.06544,50.00000,0.0000e+000,20.00000,-7.7533e-002,0.63053
635.10999, 74.76750,    -0.84847,73.05144,50.00000,0.0000e+000,20.00000,-7.7972e-002,0.62958
636.91803, 74.94750,    -0.84971,73.03800,50.00000,0.0000e+000,20.00000,-7.8393e-002,0.62863
638.70898, 75.12750,    -0.85133,73.02390,50.00000,0.0000e+000,20.00000,-7.9417e-002,0.62770
640.51599, 75.30750,    -0.85378,73.00985,50.00000,0.0000e+000,20.00000,-8.0689e-002,0.62675
642.30798, 75.48750,    -0.85485,72.99830,50.00000,0.0000e+000,20.00000,-8.1318e-002,0.62583
644.10901, 75.66750,    -0.85579,72.98551,50.00000,0.0000e+000,20.00000,-8.1371e-002,0.62490
645.89801, 75.84750,    -0.85654,72.97030,50.00000,0.0000e+000,20.00000,-8.2073e-002,0.62398
647.71997, 76.02750,    -0.85735,72.95425,50.00000,0.0000e+000,20.00000,-8.2950e-002,0.62305
649.52301, 76.20750,    -0.85897,72.93726,50.00000,0.0000e+000,20.00000,-8.3592e-002,0.62213
651.33099, 76.38750,    -0.85968,72.92117,50.00000,0.0000e+000,20.00000,-8.3990e-002,0.62121
653.13300, 76.56750,    -0.86159,72.90614,50.00000,0.0000e+000,20.00000,-8.4634e-002,0.62030
654.97101, 76.74750,    -0.86494,72.89113,50.00000,0.0000e+000,20.00000,-8.5598e-002,0.61938
656.79102, 76.92750,    -0.86556,72.87519,50.00000,0.0000e+000,20.00000,-8.6637e-002,0.61846
658.59399, 77.10750,    -0.86510,72.85809,50.00000,0.0000e+000,20.00000,-8.7757e-002,0.61756
660.38702, 77.28750,    -0.86522,72.84154,50.00000,0.0000e+000,20.00000,-8.9909e-002,0.61667
662.18103, 77.46750,    -0.86408,72.82652,50.00000,0.0000e+000,20.00000,-9.0994e-002,0.61579
663.95398, 77.64750,    -0.86278,72.81062,50.00000,0.0000e+000,20.00000,-9.1162e-002,0.61491
665.75000, 77.82750,    -0.86232,72.79365,50.00000,0.0000e+000,20.00000,-9.1335e-002,0.61403
667.53003, 78.00750,    -0.86167,72.77783,50.00000,0.0000e+000,20.00000,-9.1345e-002,0.61316
669.31500, 78.18750,    -0.86124,72.76297,50.00000,0.0000e+000,20.00000,-9.1863e-002,0.61229
671.09698, 78.36750,    -0.86175,72.74679,50.00000,0.0000e+000,20.00000,-9.2848e-002,0.61143
672.89801, 78.54750,    -0.86230,72.72981,50.00000,0.0000e+000,20.00000,-9.3629e-002,0.61056
674.70898, 78.72750,    -0.86334,72.71223,50.00000,0.0000e+000,20.00000,-9.4604e-002,0.60969
676.51099, 78.90750,    -0.86420,72.69400,50.00000,0.0000e+000,20.00000,-9.5094e-002,0.60883
678.29797, 79.08750,    -0.86363,72.67430,50.00000,0.0000e+000,20.00000,-9.5149e-002,0.60798
680.09302, 79.26750,    -0.86281,72.65737,50.00000,0.0000e+000,20.00000,-9.5829e-002,0.60712
681.90100, 79.44750,    -0.86220,72.64197,50.00000,0.0000e+000,20.00000,-9.6556e-002,0.60627
683.70898, 79.62750,    -0.86213,72.62550,50.00000,0.0000e+000,20.00000,-9.6682e-002,0.60542
685.54102, 79.80750,    -0.86386,72.60863,50.00000,0.0000e+000,20.00000,-9.6654e-002,0.60456
687.36499, 79.98750,    -0.86393,72.59066,50.00000,0.0000e+000,20.00000,-9.6794e-002,0.60370
689.17102, 80.16750,    -0.86378,72.57183,50.00000,0.0000e+000,20.00000,-9.6796e-002,0.60286
690.99902, 80.34750,    -0.86336,72.55401,50.00000,0.0000e+000,20.00000,-9.6613e-002,0.60202
692.82898, 80.52750,    -0.86296,72.53498,50.00000,0.0000e+000,20.00000,-9.5903e-002,0.60117
694.64502, 80.70750,    -0.86309,72.51585,50.00000,0.0000e+000,20.00000,-9.4785e-002,0.60034
696.44299, 80.88750,    -0.86146,72.49879,50.00000,0.0000e+000,20.00000,-9.3479e-002,0.59951
698.23700, 81.06750,    -0.85976,72.48130,50.00000,0.0000e+000,20.00000,-9.2549e-002,0.59869
700.01898, 81.24750,    -0.85793,72.46304,50.00000,0.0000e+000,20.00000,-9.1690e-002,0.59788
701.82703, 81.42750,    -0.85769,72.44539,50.00000,0.0000e+000,20.00000,-9.0540e-002,0.59707
703.62598, 81.60750,    -0.85865,72.42922,50.00000,0.0000e+000,20.00000,-8.9141e-002,0.59625
705.42902, 81.78750,    -0.85947,72.41390,50.00000,0.0000e+000,20.00000,-8.7557e-002,0.59544
707.21600, 81.96750,    -0.85960,72.39802,50.00000,0.0000e+000,20.00000,-8.5716e-002,0.59464
709.01300, 82.14750,    -0.85922,72.38178,50.00000,0.0000e+000,20.00000,-8.4173e-002,0.59384
710.80200, 82.32750,    -0.85887,72.36655,50.00000,0.0000e+000,20.00000,-8.2452e-002,0.59305
712.59601, 82.50750,    -0.85871,72.35264,50.00000,0.0000e+000,20.00000,-8.0521e-002,0.59225
714.43298, 82.68750,    -0.86202,72.33790,50.00000,0.0000e+000,20.00000,-7.8954e-002,0.59144
716.30902, 82.86750,    -0.86743,72.32343,50.00000,0.0000e+000,20.00000,-7.7154e-002,0.59062
718.15100, 83.04750,    -0.86876,72.31113,50.00000,0.0000e+000,20.00000,-7.5558e-002,0.58981
719.97498, 83.22750,    -0.86692,72.29895,50.00000,0.0000e+000,20.00000,-7.4057e-002,0.58902
721.75897, 83.40750,    -0.86363,72.28723,50.00000,0.0000e+000,20.00000,-7.2702e-002,0.58824
723.52802, 83.58750,    -0.86090,72.27532,50.00000,0.0000e+000,20.00000,-7.1508e-002,0.58748
725.31299, 83.76750,    -0.85915,72.26323,50.00000,0.0000e+000,20.00000,-6.9970e-002,0.58671
727.11401, 83.94750,    -0.85851,72.25095,50.00000,0.0000e+000,20.00000,-6.7905e-002,0.58593
728.89697, 84.12750,    -0.85795,72.23857,50.00000,0.0000e+000,20.00000,-6.6392e-002,0.58517
730.69897, 84.30750,    -0.85777,72.22616,50.00000,0.0000e+000,20.00000,-6.5379e-002,0.58440
732.48297, 84.48750,    -0.85615,72.21444,50.00000,0.0000e+000,20.00000,-6.3870e-002,0.58364
734.27899, 84.66750,    -0.85377,72.20377,50.00000,0.0000e+000,20.00000,-6.2151e-002,0.58288
736.04700, 84.84750,    -0.85177,72.19164,50.00000,0.0000e+000,20.00000,-6.0762e-002,0.58213
737.81702, 85.02750,    -0.84954,72.17912,50.00000,0.0000e+000,20.00000,-6.0037e-002,0.58139
739.58502, 85.20750,    -0.84731,72.16761,50.00000,0.0000e+000,20.00000,-5.9684e-002,0.58064
741.37299, 85.38750,    -0.84618,72.15655,50.00000,0.0000e+000,20.00000,-5.9028e-002,0.57990
743.23199, 85.56750,    -0.85081,72.14615,50.00000,0.0000e+000,20.00000,-5.8335e-002,0.57912
745.09497, 85.74750,    -0.85540,72.13743,50.00000,0.0000e+000,20.00000,-5.7120e-002,0.57835
746.94897, 85.92750,    -0.85653,72.12769,50.00000,0.0000e+000,20.00000,-5.5436e-002,0.57758
748.76300, 86.10750,    -0.85293,72.11730,50.00000,0.0000e+000,20.00000,-5.4245e-002,0.57683
750.55603, 86.28750,    -0.84856,72.10813,50.00000,0.0000e+000,20.00000,-5.3369e-002,0.57610
752.35699, 86.46750,    -0.84458,72.09950,50.00000,0.0000e+000,20.00000,-5.2281e-002,0.57536
754.13800, 86.64750,    -0.84056,72.09210,50.00000,0.0000e+000,20.00000,-5.0679e-002,0.57463
755.93903, 86.82750,    -0.83902,72.08298,50.00000,0.0000e+000,20.00000,-4.9443e-002,0.57390
757.75897, 87.00750,    -0.83984,72.07238,50.00000,0.0000e+000,20.00000,-4.8520e-002,0.57316
759.55701, 87.18750,    -0.83889,72.06286,50.00000,0.0000e+000,20.00000,-4.7433e-002,0.57243
761.34601, 87.36750,    -0.83709,72.05329,50.00000,0.0000e+000,20.00000,-4.6361e-002,0.57171
763.11102, 87.54750,    -0.83429,72.04505,50.00000,0.0000e+000,20.00000,-4.6080e-002,0.57100
764.91302, 87.72750,    -0.83404,72.03891,50.00000,0.0000e+000,20.00000,-4.5672e-002,0.57028
766.72101, 87.90750,    -0.83492,72.03109,50.00000,0.0000e+000,20.00000,-4.4991e-002,0.56955
768.52197, 88.08750,    -0.83610,72.02233,50.00000,0.0000e+000,20.00000,-4.4544e-002,0.56884
770.32300, 88.26750,    -0.83803,72.01523,50.00000,0.0000e+000,20.00000,-4.4286e-002,0.56812
772.12000, 88.44750,    -0.83962,72.00940,50.00000,0.0000e+000,20.00000,-4.4842e-002,0.56741
773.90601, 88.62750,    -0.84164,72.00156,50.00000,0.0000e+000,20.00000,-4.5034e-002,0.56670
775.70502, 88.80750,    -0.84517,71.99319,50.00000,0.0000e+000,20.00000,-4.4376e-002,0.56599
777.51001, 88.98750,    -0.84933,71.98586,50.00000,0.0000e+000,20.00000,-4.4205e-002,0.56529
779.30298, 89.16750,    -0.85276,71.97926,50.00000,0.0000e+000,20.00000,-4.4250e-002,0.56458
781.12097, 89.34750,    -0.85674,71.97157,50.00000,0.0000e+000,20.00000,-4.4480e-002,0.56387
782.92902, 89.52750,    -0.86212,71.96356,50.00000,0.0000e+000,20.00000,-4.5410e-002,0.56317
784.73602, 89.70750,    -0.86687,71.95559,50.00000,0.0000e+000,20.00000,-4.5878e-002,0.56247
786.54102, 89.88750,    -0.87084,71.94785,50.00000,0.0000e+000,20.00000,-4.5983e-002,0.56177
788.35199, 90.06750,    -0.87573,71.94014,50.00000,0.0000e+000,20.00000,-4.6817e-002,0.56107
790.16602, 90.24750,    -0.88180,71.93089,50.00000,0.0000e+000,20.00000,-4.8121e-002,0.56037
791.99799, 90.42750,    -0.88940,71.92129,50.00000,0.0000e+000,20.00000,-4.9118e-002,0.55967
793.83099, 90.60750,    -0.89608,71.91299,50.00000,0.0000e+000,20.00000,-5.0202e-002,0.55896
795.64301, 90.78750,    -0.90248,71.90420,50.00000,0.0000e+000,20.00000,-5.1286e-002,0.55827
797.45203, 90.96750,    -0.90778,71.89448,50.00000,0.0000e+000,20.00000,-5.2792e-002,0.55758
799.25098, 91.14750,    -0.91198,71.88498,50.00000,0.0000e+000,20.00000,-5.4146e-002,0.55690
801.06702, 91.32750,    -0.91698,71.87541,50.00000,0.0000e+000,20.00000,-5.4905e-002,0.55621
802.85901, 91.50750,    -0.92144,71.86605,50.00000,0.0000e+000,20.00000,-5.6120e-002,0.55553
804.64301, 91.68750,    -0.92479,71.85708,50.00000,0.0000e+000,20.00000,-5.7700e-002,0.55486
806.44702, 91.86750,    -0.92715,71.84666,50.00000,0.0000e+000,20.00000,-5.9229e-002,0.55418
808.25299, 92.04750,    -0.93064,71.83610,50.00000,0.0000e+000,20.00000,-6.0369e-002,0.55350
810.06299, 92.22750,    -0.93419,71.82516,50.00000,0.0000e+000,20.00000,-6.1804e-002,0.55282
811.86401, 92.40750,    -0.93590,71.81280,50.00000,0.0000e+000,20.00000,-6.3802e-002,0.55215
813.66998, 92.58750,    -0.93783,71.80115,50.00000,0.0000e+000,20.00000,-6.5868e-002,0.55148
815.47601, 92.76750,    -0.93953,71.78931,50.00000,0.0000e+000,20.00000,-6.7936e-002,0.55080
817.27802, 92.94750,    -0.93999,71.77667,50.00000,0.0000e+000,20.00000,-6.9685e-002,0.55014
819.07501, 93.12750,    -0.93991,71.76578,50.00000,0.0000e+000,20.00000,-7.1328e-002,0.54947
820.85101, 93.30750,    -0.93950,71.75372,50.00000,0.0000e+000,20.00000,-7.2768e-002,0.54881
822.63702, 93.48750,    -0.94139,71.74017,50.00000,0.0000e+000,20.00000,-7.4548e-002,0.54815
824.47803, 93.66750,    -0.94379,71.72689,50.00000,0.0000e+000,20.00000,-7.6383e-002,0.54748
826.30798, 93.84750,    -0.94609,71.71382,50.00000,0.0000e+000,20.00000,-7.8489e-002,0.54680
828.12402, 94.02750,    -0.94755,71.69920,50.00000,0.0000e+000,20.00000,-8.0538e-002,0.54614
829.94501, 94.20750,    -0.94813,71.68340,50.00000,0.0000e+000,20.00000,-8.1664e-002,0.54547
831.74902, 94.38750,    -0.94698,71.66748,50.00000,0.0000e+000,20.00000,-8.2894e-002,0.54481
833.52502, 94.56750,    -0.94533,71.65023,50.00000,0.0000e+000,20.00000,-8.4727e-002,0.54417
835.34900, 94.74750,    -0.94536,71.63408,50.00000,0.0000e+000,20.00000,-8.6412e-002,0.54350
837.17200, 94.92750,    -0.94684,71.61855,50.00000,0.0000e+000,20.00000,-8.8563e-002,0.54284
839.00500, 95.10750,    -0.94841,71.60366,50.00000,0.0000e+000,20.00000,-9.0410e-002,0.54218
840.80499, 95.28750,    -0.94832,71.58851,50.00000,0.0000e+000,20.00000,-9.2031e-002,0.54153
842.61499, 95.46750,    -0.94593,71.57182,50.00000,0.0000e+000,20.00000,-9.3922e-002,0.54087
844.41302, 95.64750,    -0.94491,71.55364,50.00000,0.0000e+000,20.00000,-9.5665e-002,0.54022
846.21100, 95.82750,    -0.94522,71.53528,50.00000,0.0000e+000,20.00000,-9.6940e-002,0.53958
847.99799, 96.00750,    -0.94421,71.51861,50.00000,0.0000e+000,20.00000,-9.7157e-002,0.53893
849.78601, 96.18750,    -0.94242,71.50252,50.00000,0.0000e+000,20.00000,-9.7477e-002,0.53829
851.57800, 96.36750,    -0.94192,71.48445,50.00000,0.0000e+000,20.00000,-9.7968e-002,0.53765
853.38098, 96.54750,    -0.94256,71.46555,50.00000,0.0000e+000,20.00000,-9.8788e-002,0.53701
855.18597, 96.72750,    -0.94354,71.44661,50.00000,0.0000e+000,20.00000,-9.9084e-002,0.53636
856.99597, 96.90750,    -0.94467,71.42807,50.00000,0.0000e+000,20.00000,-9.9886e-002,0.53572
858.87903, 97.08750,    -0.95042,71.40896,50.00000,0.0000e+000,20.00000,    -0.10098,0.53505
860.69702, 97.26750,    -0.95097,71.38867,50.00000,0.0000e+000,20.00000,    -0.10152,0.53440
862.51001, 97.44750,    -0.94955,71.36911,50.00000,0.0000e+000,20.00000,    -0.10205,0.53376
864.29401, 97.62750,    -0.94846,71.35007,50.00000,0.0000e+000,20.00000,    -0.10271,0.53313
866.08398, 97.80750,    -0.94740,71.33311,50.00000,0.0000e+000,20.00000,    -0.10348,0.53249
867.85797, 97.98750,    -0.94708,71.31646,50.00000,0.0000e+000,20.00000,    -0.10416,0.53187
869.65601, 98.16750,    -0.94704,71.29779,50.00000,0.0000e+000,20.00000,    -0.10467,0.53123
871.43701, 98.34750,    -0.94793,71.27819,50.00000,0.0000e+000,20.00000,    -0.10490,0.53060
873.22498, 98.52750,    -0.94910,71.26125,50.00000,0.0000e+000,20.00000,    -0.10491,0.52997
875.01202, 98.70750,    -0.95023,71.24371,50.00000,0.0000e+000,20.00000,    -0.10494,0.52934
876.77802, 98.88750,    -0.95080,71.22468,50.00000,0.0000e+000,20.00000,    -0.10512,0.52872
878.56000, 99.06750,    -0.95268,71.20632,50.00000,0.0000e+000,20.00000,    -0.10523,0.52810
880.36298, 99.24750,    -0.95772,71.18660,50.00000,0.0000e+000,20.00000,    -0.10549,0.52747
882.25897, 99.42750,    -0.96814,71.16583,50.00000,0.0000e+000,20.00000,    -0.10525,0.52680
884.14099, 99.60750,    -0.97705,71.14563,50.00000,0.0000e+000,20.00000,    -0.10530,0.52614
885.96600, 99.78750,    -0.98011,71.12725,50.00000,0.0000e+000,20.00000,    -0.10590,0.52551
887.78601, 99.96750,    -0.98172,71.10781,50.00000,0.0000e+000,20.00000,    -0.10618,0.52487
889.59399,100.14750,    -0.98327,71.08794,50.00000,0.0000e+000,20.00000,    -0.10608,0.52424
891.37903,100.32750,    -0.98335,71.06896,50.00000,0.0000e+000,20.00000,    -0.10632,0.52362
893.19000,100.50750,    -0.98438,71.05017,50.00000,0.0000e+000,20.00000,    -0.10674,0.52299
894.96503,100.68750,    -0.98615,71.03085,50.00000,0.0000e+000,20.00000,    -0.10692,0.52237
896.76001,100.86750,    -0.98723,71.01034,50.00000,0.0000e+000,20.00000,    -0.10738,0.52175
898.55603,101.04750,    -0.98790,70.98947,50.00000,0.0000e+000,20.00000,    -0.10729,0.52112
900.31598,101.22750,    -0.98709,70.97093,50.00000,0.0000e+000,20.00000,    -0.10680,0.52051
902.11798,101.40750,    -0.98689,70.95338,50.00000,0.0000e+000,20.00000,    -0.10662,0.51989
903.90997,101.58750,    -0.98724,70.93503,50.00000,0.0000e+000,20.00000,    -0.10681,0.51926
905.71503,101.76750,    -0.98795,70.91562,50.00000,0.0000e+000,20.00000,    -0.10687,0.51864
907.52002,101.94750,    -0.98746,70.89631,50.00000,0.0000e+000,20.00000,    -0.10629,0.51801
909.33801,102.12750,    -0.98935,70.87781,50.00000,0.0000e+000,20.00000,    -0.10555,0.51739
911.14301,102.30750,    -0.99058,70.85941,50.00000,0.0000e+000,20.00000,    -0.10533,0.51676
912.97998,102.48750,    -0.99244,70.83978,50.00000,0.0000e+000,20.00000,    -0.10522,0.51613
914.78601,102.66750,    -0.99262,70.81972,50.00000,0.0000e+000,20.00000,    -0.10495,0.51550
916.57703,102.84750,    -0.99139,70.80043,50.00000,0.0000e+000,20.00000,    -0.10453,0.51488
918.37201,103.02750,    -0.99050,70.78160,50.00000,0.0000e+000,20.00000,    -0.10447,0.51426
920.15302,103.20750,    -0.98961,70.76191,50.00000,0.0000e+000,20.00000,    -0.10496,0.51365
921.96503,103.38750,    -0.99255,70.74257,50.00000,0.0000e+000,20.00000,    -0.10506,0.51302
923.75299,103.56750,    -0.99336,70.72323,50.00000,0.0000e+000,20.00000,    -0.10459,0.51241
925.57397,103.74750,    -0.99566,70.70495,50.00000,0.0000e+000,20.00000,    -0.10418,0.51178
927.36902,103.92750,    -0.99703,70.68863,50.00000,0.0000e+000,20.00000,    -0.10394,0.51116
929.17401,104.10750,    -0.99700,70.67088,50.00000,0.0000e+000,20.00000,    -0.10396,0.51054
930.98297,104.28750,    -0.99710,70.65219,50.00000,0.0000e+000,20.00000,    -0.10415,0.50992
932.79102,104.46750,    -0.99723,70.63298,50.00000,0.0000e+000,20.00000,    -0.10373,0.50929
934.60901,104.64750,    -0.99638,70.61340,50.00000,0.0000e+000,20.00000,    -0.10232,0.50867
936.42603,104.82750,    -0.99469,70.59471,50.00000,0.0000e+000,20.00000,    -0.10182,0.50804
938.23199,105.00750,    -0.99121,70.57538,50.00000,0.0000e+000,20.00000,    -0.10120,0.50742
940.04700,105.18750,    -0.98662,70.55669,50.00000,0.0000e+000,20.00000,-9.9351e-002,0.50680
941.85498,105.36750,    -0.98170,70.53898,50.00000,0.0000e+000,20.00000,-9.6957e-002,0.50617
943.65802,105.54750,    -0.97758,70.52123,50.00000,0.0000e+000,20.00000,-9.4819e-002,0.50555
945.46301,105.72750,    -0.97227,70.50335,50.00000,0.0000e+000,20.00000,-9.3358e-002,0.50493
947.26703,105.90750,    -0.96830,70.48528,50.00000,0.0000e+000,20.00000,-9.1521e-002,0.50431
949.06299,106.08750,    -0.96538,70.46526,50.00000,0.0000e+000,20.00000,-8.9904e-002,0.50369
950.85602,106.26750,    -0.96343,70.44611,50.00000,0.0000e+000,20.00000,-8.7406e-002,0.50307
952.66998,106.44750,    -0.96371,70.43153,50.00000,0.0000e+000,20.00000,-8.3885e-002,0.50245
954.50897,106.62750,    -0.96725,70.41520,50.00000,0.0000e+000,20.00000,-8.0529e-002,0.50182
956.31201,106.80750,    -0.96776,70.39741,50.00000,0.0000e+000,20.00000,-7.7732e-002,0.50120
958.11401,106.98750,    -0.96948,70.38408,50.00000,0.0000e+000,20.00000,-7.5179e-002,0.50057
959.95300,107.16750,    -0.97357,70.37338,50.00000,0.0000e+000,20.00000,-7.2241e-002,0.49994
961.79102,107.34750,    -0.97795,70.36277,50.00000,0.0000e+000,20.00000,-6.9307e-002,0.49931
963.60498,107.52750,    -0.97990,70.35148,50.00000,0.0000e+000,20.00000,-6.6658e-002,0.49868
965.39899,107.70750,    -0.97900,70.34105,50.00000,0.0000e+000,20.00000,-6.3639e-002,0.49806
967.18597,107.88750,    -0.97985,70.32830,50.00000,0.0000e+000,20.00000,-5.9645e-002,0.49745
968.98102,108.06750,    -0.98062,70.31780,50.00000,0.0000e+000,20.00000,-5.5749e-002,0.49683
970.76202,108.24750,    -0.98242,70.31061,50.00000,0.0000e+000,20.00000,-5.3185e-002,0.49621
972.53900,108.42750,    -0.98339,70.30443,50.00000,0.0000e+000,20.00000,-5.0047e-002,0.49560
974.30402,108.60750,    -0.98460,70.29570,50.00000,0.0000e+000,20.00000,-4.5937e-002,0.49499
976.11401,108.78750,    -0.98756,70.28606,50.00000,0.0000e+000,20.00000,-4.3349e-002,0.49436
977.93597,108.96750,    -0.99107,70.27853,50.00000,0.0000e+000,20.00000,-4.1321e-002,0.49373
979.78302,109.14750,    -0.99741,70.27187,50.00000,0.0000e+000,20.00000,-3.9892e-002,0.49309
981.60303,109.32750,    -1.00122,70.26366,50.00000,0.0000e+000,20.00000,-3.7709e-002,0.49246
983.40698,109.50750,    -1.00326,70.25643,50.00000,0.0000e+000,20.00000,-3.4275e-002,0.49184
985.20300,109.68750,    -1.00247,70.25117,50.00000,0.0000e+000,20.00000,-3.3562e-002,0.49122
987.01599,109.86750,    -1.00404,70.24585,50.00000,0.0000e+000,20.00000,-3.1230e-002,0.49059
988.83002,110.04750,    -1.00615,70.24010,50.00000,0.0000e+000,20.00000,-2.9309e-002,0.48996
990.59100,110.22750,    -1.00613,70.23551,50.00000,0.0000e+000,20.00000,-2.5976e-002,0.48935
992.38501,110.40750,    -1.00715,70.23261,50.00000,0.0000e+000,20.00000,-2.4699e-002,0.48872
994.28101,110.58750,    -1.01590,70.22806,50.00000,0.0000e+000,20.00000,-2.2141e-002,0.48807
996.10797,110.76750,    -1.01996,70.22449,50.00000,0.0000e+000,20.00000,-2.3890e-002,0.48743
997.90198,110.94750,    -1.01822,70.21957,50.00000,0.0000e+000,20.00000,-2.8383e-002,0.48681
998.46997,111.00250,    -1.01858,70.21818,50.00000,0.0000e+000,20.00000,-4.4702e-003,0.48661