File: book/some_content/TG_ExpDat_B50S50DC28.csv
#FILE:                       ,B50S50DC28; 13-2-2025.ngb-ds3
#FORMAT:                     ,NETZSCH5
#IDENTITY:                   ,geopolymer paste
#DECIMAL:                    ,POINT
#SEPARATOR:                  ,COMMA
#MTYPE:                      ,DSC
#INSTRUMENT:                 ,Microlab TU Delft
#PROJECT:                    ,
#DATE/TIME:                  ,13/02/2025 10:54:11 AM
#CORR. FILE:                 ,Blank with cover; 13-1-2025.ngb-bs3
#LABORATORY:                 ,TU Delft Micro Lab
#OPERATOR:                   ,Ahmed
#REMARK:                     ,under Argon atmosphere, 10K/min
#SAMPLE:                     ,B50S50DC28
#SAMPLE MASS /mg:            ,31.8
#MATERIAL:                   ,Geopolymer paste
#REFERENCE:                  ,blank
#REFERENCE MASS /mg:         ,0
#TYPE OF CRUCIBLE:           ,DSC/TG pan Al2O3
#SAMPLE CRUCIBLE MASS /mg:   ,0
#REFERENCE CRUCIBLE MASS /mg:,0
#CORR. CODE:                 ,020
#EXO:                        ,-1
#RANGE:                      ,40/10.0(K/min)/1000
#SEGMENT:                    ,S2/2

##Temp./øC,Time/min,DSC/(mW/mg),Mass/%,Gas Flow(purge1)/(ml/min),Gas Flow(purge2)/(ml/min),Gas Flow(protective)/(ml/min),DTG/(%/min),Sensit./(uV/mW)
 39.68400, 15.09500, 1.9625e-002,98.90529,50.00000,0.0000e+000,20.00000,-4.5522e-002,1.22738
 39.74100, 15.27500, 1.9314e-002,98.89717,50.00000,0.0000e+000,20.00000,-4.8649e-002,1.22730
 39.79700, 15.45500, 1.9315e-002,98.88875,50.00000,0.0000e+000,20.00000,-5.4744e-002,1.22722
 39.89300, 15.63500, 1.8907e-002,98.87635,50.00000,0.0000e+000,20.00000,-4.8530e-002,1.22709
 40.02500, 15.81500, 1.8851e-002,98.86436,50.00000,0.0000e+000,20.00000,-4.7735e-002,1.22691
 40.23600, 15.99500, 1.8816e-002,98.85611,50.00000,0.0000e+000,20.00000,-4.5449e-002,1.22662
 40.52200, 16.17500, 1.8783e-002,98.85055,50.00000,0.0000e+000,20.00000,-4.3995e-002,1.22622
 40.83500, 16.35500, 1.9220e-002,98.84475,50.00000,0.0000e+000,20.00000,-4.4540e-002,1.22579
 41.24500, 16.53500, 1.9895e-002,98.83652,50.00000,0.0000e+000,20.00000,-4.5442e-002,1.22523
 41.76500, 16.71500, 2.1062e-002,98.82728,50.00000,0.0000e+000,20.00000,-4.6462e-002,1.22451
 42.34500, 16.89500, 2.1625e-002,98.82129,50.00000,0.0000e+000,20.00000,-4.8366e-002,1.22371
 43.01300, 17.07500, 2.3054e-002,98.81621,50.00000,0.0000e+000,20.00000,-4.9691e-002,1.22279
 43.76300, 17.25500, 2.4213e-002,98.80930,50.00000,0.0000e+000,20.00000,-5.1158e-002,1.22175
 44.59200, 17.43500, 2.6397e-002,98.80279,50.00000,0.0000e+000,20.00000,-5.2265e-002,1.22061
 45.52000, 17.61500, 2.7940e-002,98.79388,50.00000,0.0000e+000,20.00000,-5.4659e-002,1.21933
 46.52100, 17.79500, 2.9410e-002,98.78380,50.00000,0.0000e+000,20.00000,-5.8177e-002,1.21795
 47.60700, 17.97500, 3.0827e-002,98.77427,50.00000,0.0000e+000,20.00000,-6.2099e-002,1.21646
 48.79000, 18.15500, 3.2863e-002,98.76570,50.00000,0.0000e+000,20.00000,-6.6757e-002,1.21483
 50.04800, 18.33500, 3.4729e-002,98.75571,50.00000,0.0000e+000,20.00000,-7.1873e-002,1.21309
 51.39300, 18.51500, 3.6327e-002,98.74446,50.00000,0.0000e+000,20.00000,-7.7169e-002,1.21124
 52.81700, 18.69500, 3.7616e-002,98.73206,50.00000,0.0000e+000,20.00000,-8.3923e-002,1.20928
 54.31200, 18.87500, 3.9687e-002,98.71869,50.00000,0.0000e+000,20.00000,-9.1757e-002,1.20722
 55.88200, 19.05500, 4.1331e-002,98.70542,50.00000,0.0000e+000,20.00000,-9.9764e-002,1.20506
 57.53500, 19.23500, 4.2566e-002,98.69017,50.00000,0.0000e+000,20.00000,    -0.10985,1.20279
 59.24700, 19.41500, 4.4089e-002,98.66958,50.00000,0.0000e+000,20.00000,    -0.12131,1.20044
 61.04300, 19.59500, 4.5922e-002,98.64768,50.00000,0.0000e+000,20.00000,    -0.13196,1.19797
 62.91000, 19.77500, 4.7807e-002,98.62750,50.00000,0.0000e+000,20.00000,    -0.14358,1.19540
 64.82000, 19.95500, 4.9742e-002,98.60550,50.00000,0.0000e+000,20.00000,    -0.15741,1.19278
 66.82300, 20.13500, 5.1611e-002,98.57945,50.00000,0.0000e+000,20.00000,    -0.17188,1.19003
 68.83700, 20.31500, 5.3752e-002,98.55110,50.00000,0.0000e+000,20.00000,    -0.18749,1.18727
 70.93800, 20.49500, 5.6273e-002,98.52013,50.00000,0.0000e+000,20.00000,    -0.20417,1.18439
 73.07000, 20.67500, 5.8504e-002,98.48708,50.00000,0.0000e+000,20.00000,    -0.22073,1.18147
 75.24700, 20.85500, 6.1156e-002,98.45149,50.00000,0.0000e+000,20.00000,    -0.23890,1.17849
 77.46900, 21.03500, 6.4457e-002,98.40967,50.00000,0.0000e+000,20.00000,    -0.25904,1.17545
 79.71900, 21.21500, 6.8044e-002,98.35973,50.00000,0.0000e+000,20.00000,    -0.27875,1.17237
 82.03400, 21.39500, 7.1921e-002,98.31049,50.00000,0.0000e+000,20.00000,    -0.29873,1.16921
 84.35300, 21.57500, 7.5656e-002,98.25934,50.00000,0.0000e+000,20.00000,    -0.31890,1.16605
 86.73300, 21.75500, 7.9704e-002,98.20105,50.00000,0.0000e+000,20.00000,    -0.33588,1.16280
 89.12800, 21.93500, 8.4253e-002,98.13893,50.00000,0.0000e+000,20.00000,    -0.35182,1.15954
 91.55300, 22.11500, 8.8415e-002,98.07188,50.00000,0.0000e+000,20.00000,    -0.36955,1.15624
 93.99300, 22.29500, 9.3123e-002,97.99900,50.00000,0.0000e+000,20.00000,    -0.38632,1.15292
 96.45100, 22.47500, 9.7108e-002,97.92551,50.00000,0.0000e+000,20.00000,    -0.40226,1.14959
 98.92200, 22.65500,     0.10116,97.84705,50.00000,0.0000e+000,20.00000,    -0.41666,1.14623
101.40300, 22.83500,     0.10450,97.75995,50.00000,0.0000e+000,20.00000,    -0.42876,1.14287
103.90000, 23.01500,     0.10755,97.66823,50.00000,0.0000e+000,20.00000,    -0.43892,1.13949
106.39500, 23.19500,     0.11017,97.57385,50.00000,0.0000e+000,20.00000,    -0.45004,1.13612
108.88900, 23.37500,     0.11206,97.47874,50.00000,0.0000e+000,20.00000,    -0.46029,1.13276
111.38300, 23.55500,     0.11306,97.39375,50.00000,0.0000e+000,20.00000,    -0.46633,1.12940
113.87200, 23.73500,     0.11350,97.31123,50.00000,0.0000e+000,20.00000,    -0.47098,1.12605
116.37200, 23.91500,     0.11271,97.21924,50.00000,0.0000e+000,20.00000,    -0.47491,1.12269
118.85600, 24.09500,     0.11130,97.12681,50.00000,0.0000e+000,20.00000,    -0.47870,1.11936
121.31100, 24.27500,     0.10910,97.03596,50.00000,0.0000e+000,20.00000,    -0.48046,1.11607
123.78500, 24.45500,     0.10606,96.94721,50.00000,0.0000e+000,20.00000,    -0.47930,1.11276
126.24800, 24.63500,     0.10187,96.86262,50.00000,0.0000e+000,20.00000,    -0.47593,1.10947
128.68401, 24.81500, 9.6773e-002,96.77662,50.00000,0.0000e+000,20.00000,    -0.47028,1.10622
131.15199, 24.99500, 9.1427e-002,96.68702,50.00000,0.0000e+000,20.00000,    -0.46267,1.10293
133.54800, 25.17500, 8.5278e-002,96.59795,50.00000,0.0000e+000,20.00000,    -0.45428,1.09975
135.98100, 25.35500, 7.8374e-002,96.51784,50.00000,0.0000e+000,20.00000,    -0.44865,1.09652
138.38000, 25.53500, 7.0417e-002,96.43920,50.00000,0.0000e+000,20.00000,    -0.44180,1.09334
140.77901, 25.71500, 6.3514e-002,96.35951,50.00000,0.0000e+000,20.00000,    -0.43202,1.09017
143.13200, 25.89500, 5.5926e-002,96.27373,50.00000,0.0000e+000,20.00000,    -0.42259,1.08706
145.47800, 26.07500, 4.8184e-002,96.19224,50.00000,0.0000e+000,20.00000,    -0.41209,1.08397
147.79401, 26.25500, 4.0307e-002,96.11887,50.00000,0.0000e+000,20.00000,    -0.40078,1.08092
150.09900, 26.43500, 3.2252e-002,96.04541,50.00000,0.0000e+000,20.00000,    -0.39021,1.07790
152.37100, 26.61500, 2.3346e-002,95.97391,50.00000,0.0000e+000,20.00000,    -0.37947,1.07492
154.63800, 26.79500, 1.3317e-002,95.90733,50.00000,0.0000e+000,20.00000,    -0.36812,1.07195
156.86501, 26.97500, 3.3439e-003,95.84260,50.00000,0.0000e+000,20.00000,    -0.35558,1.06904
159.07001, 27.15500,-7.8985e-003,95.77597,50.00000,0.0000e+000,20.00000,    -0.34477,1.06617
161.25101, 27.33500,-1.9404e-002,95.71771,50.00000,0.0000e+000,20.00000,    -0.33459,1.06333
163.41901, 27.51500,-3.1038e-002,95.66344,50.00000,0.0000e+000,20.00000,    -0.32354,1.06052
165.57100, 27.69500,-4.2688e-002,95.60477,50.00000,0.0000e+000,20.00000,    -0.31033,1.05773
167.71600, 27.87500,-5.4672e-002,95.55131,50.00000,0.0000e+000,20.00000,    -0.29756,1.05495
169.82600, 28.05500,-6.6260e-002,95.50271,50.00000,0.0000e+000,20.00000,    -0.28665,1.05223
171.91299, 28.23500,-7.7174e-002,95.45635,50.00000,0.0000e+000,20.00000,    -0.27522,1.04954
174.00000, 28.41500,-8.7845e-002,95.41010,50.00000,0.0000e+000,20.00000,    -0.26360,1.04685
176.04700, 28.59500,-9.8313e-002,95.36269,50.00000,0.0000e+000,20.00000,    -0.25340,1.04422
178.10001, 28.77500,    -0.10856,95.31779,50.00000,0.0000e+000,20.00000,    -0.24358,1.04159
180.11700, 28.95500,    -0.11781,95.27602,50.00000,0.0000e+000,20.00000,    -0.23358,1.03901
182.10800, 29.13500,    -0.12720,95.23450,50.00000,0.0000e+000,20.00000,    -0.22513,1.03647
184.10899, 29.31500,    -0.13665,95.19517,50.00000,0.0000e+000,20.00000,    -0.21728,1.03392
186.04800, 29.49500,    -0.14517,95.15833,50.00000,0.0000e+000,20.00000,    -0.20776,1.03145
188.00999, 29.67500,    -0.15375,95.12184,50.00000,0.0000e+000,20.00000,    -0.19917,1.02896
189.94099, 29.85500,    -0.16267,95.08732,50.00000,0.0000e+000,20.00000,    -0.19206,1.02652
191.85500, 30.03500,    -0.17207,95.05538,50.00000,0.0000e+000,20.00000,    -0.18566,1.02410
193.75900, 30.21500,    -0.18098,95.02558,50.00000,0.0000e+000,20.00000,    -0.17937,1.02169
195.65700, 30.39500,    -0.18966,94.99562,50.00000,0.0000e+000,20.00000,    -0.17255,1.01930
197.53101, 30.57500,    -0.19895,94.96667,50.00000,0.0000e+000,20.00000,    -0.16604,1.01695
199.41000, 30.75500,    -0.20722,94.93703,50.00000,0.0000e+000,20.00000,    -0.16046,1.01459
201.25400, 30.93500,    -0.21575,94.90710,50.00000,0.0000e+000,20.00000,    -0.15494,1.01228
203.12000, 31.11500,    -0.22389,94.88174,50.00000,0.0000e+000,20.00000,    -0.14966,1.00995
204.94000, 31.29500,    -0.23180,94.85779,50.00000,0.0000e+000,20.00000,    -0.14492,1.00768
206.77901, 31.47500,    -0.23877,94.83462,50.00000,0.0000e+000,20.00000,    -0.14023,1.00540
208.59300, 31.65500,    -0.24596,94.81151,50.00000,0.0000e+000,20.00000,    -0.13600,1.00314
210.41100, 31.83500,    -0.25356,94.78834,50.00000,0.0000e+000,20.00000,    -0.13265,1.00089
212.20399, 32.01500,    -0.26109,94.76511,50.00000,0.0000e+000,20.00000,    -0.13021,0.99867
213.98100, 32.19500,    -0.26792,94.74264,50.00000,0.0000e+000,20.00000,    -0.12718,0.99648
215.78101, 32.37500,    -0.27443,94.72075,50.00000,0.0000e+000,20.00000,    -0.12407,0.99426
217.56000, 32.55500,    -0.28082,94.69922,50.00000,0.0000e+000,20.00000,    -0.12128,0.99208
219.32100, 32.73500,    -0.28749,94.67769,50.00000,0.0000e+000,20.00000,    -0.11800,0.98992
221.06400, 32.91500,    -0.29396,94.65707,50.00000,0.0000e+000,20.00000,    -0.11623,0.98778
222.82201, 33.09500,    -0.30059,94.63716,50.00000,0.0000e+000,20.00000,    -0.11480,0.98564
224.56200, 33.27500,    -0.30773,94.61783,50.00000,0.0000e+000,20.00000,    -0.11364,0.98351
226.30400, 33.45500,    -0.31480,94.59828,50.00000,0.0000e+000,20.00000,    -0.11199,0.98140
228.04700, 33.63500,    -0.32126,94.57850,50.00000,0.0000e+000,20.00000,    -0.11100,0.97928
229.78200, 33.81500,    -0.32821,94.55724,50.00000,0.0000e+000,20.00000,    -0.10991,0.97718
231.51401, 33.99500,    -0.33561,94.53816,50.00000,0.0000e+000,20.00000,    -0.10848,0.97508
233.23700, 34.17500,    -0.34279,94.52027,50.00000,0.0000e+000,20.00000,    -0.10754,0.97301
234.97800, 34.35500,    -0.35104,94.50143,50.00000,0.0000e+000,20.00000,    -0.10671,0.97091
236.71899, 34.53500,    -0.35866,94.48291,50.00000,0.0000e+000,20.00000,    -0.10557,0.96882
238.43500, 34.71500,    -0.36595,94.46359,50.00000,0.0000e+000,20.00000,    -0.10439,0.96677
240.17101, 34.89500,    -0.37352,94.44472,50.00000,0.0000e+000,20.00000,    -0.10286,0.96469
241.90500, 35.07500,    -0.38080,94.42555,50.00000,0.0000e+000,20.00000,    -0.10101,0.96262
243.65100, 35.25500,    -0.38852,94.40836,50.00000,0.0000e+000,20.00000,-9.9447e-002,0.96054
245.38000, 35.43500,    -0.39586,94.38938,50.00000,0.0000e+000,20.00000,-9.8308e-002,0.95849
247.09500, 35.61500,    -0.40325,94.36960,50.00000,0.0000e+000,20.00000,-9.6837e-002,0.95646
248.83400, 35.79500,    -0.40977,94.35229,50.00000,0.0000e+000,20.00000,-9.5314e-002,0.95440
250.56500, 35.97500,    -0.41670,94.33384,50.00000,0.0000e+000,20.00000,-9.4112e-002,0.95236
252.27499, 36.15500,    -0.42430,94.31530,50.00000,0.0000e+000,20.00000,-9.2816e-002,0.95035
254.01100, 36.33500,    -0.43204,94.29766,50.00000,0.0000e+000,20.00000,-9.1468e-002,0.94831
255.74001, 36.51500,    -0.44072,94.28105,50.00000,0.0000e+000,20.00000,-9.0062e-002,0.94629
257.48401, 36.69500,    -0.44942,94.26619,50.00000,0.0000e+000,20.00000,-8.8934e-002,0.94425
259.22900, 36.87500,    -0.45778,94.25357,50.00000,0.0000e+000,20.00000,-8.7777e-002,0.94222
260.96301, 37.05500,    -0.46600,94.23998,50.00000,0.0000e+000,20.00000,-8.6663e-002,0.94020
262.72000, 37.23500,    -0.47433,94.22479,50.00000,0.0000e+000,20.00000,-8.5426e-002,0.93816
264.47400, 37.41500,    -0.48228,94.20881,50.00000,0.0000e+000,20.00000,-8.4279e-002,0.93614
266.21500, 37.59500,    -0.48976,94.19457,50.00000,0.0000e+000,20.00000,-8.3598e-002,0.93413
267.97800, 37.77500,    -0.49796,94.18119,50.00000,0.0000e+000,20.00000,-8.2881e-002,0.93210
269.73499, 37.95500,    -0.50577,94.16718,50.00000,0.0000e+000,20.00000,-8.2093e-002,0.93008
271.49301, 38.13500,    -0.51359,94.15354,50.00000,0.0000e+000,20.00000,-8.0795e-002,0.92807
273.27100, 38.31500,    -0.52039,94.13956,50.00000,0.0000e+000,20.00000,-7.9712e-002,0.92604
275.01300, 38.49500,    -0.52709,94.12488,50.00000,0.0000e+000,20.00000,-7.9744e-002,0.92405
276.77802, 38.67500,    -0.53263,94.10978,50.00000,0.0000e+000,20.00000,-8.0703e-002,0.92205
278.51599, 38.85500,    -0.53745,94.09616,50.00000,0.0000e+000,20.00000,-8.1685e-002,0.92008
280.26300, 39.03500,    -0.54386,94.08260,50.00000,0.0000e+000,20.00000,-8.2355e-002,0.91810
281.99399, 39.21500,    -0.55031,94.06678,50.00000,0.0000e+000,20.00000,-8.3654e-002,0.91615
283.75101, 39.39500,    -0.55706,94.05167,50.00000,0.0000e+000,20.00000,-8.5155e-002,0.91417
285.49200, 39.57500,    -0.56420,94.03624,50.00000,0.0000e+000,20.00000,-8.6092e-002,0.91222
287.23801, 39.75500,    -0.57123,94.02030,50.00000,0.0000e+000,20.00000,-8.6739e-002,0.91027
288.98599, 39.93500,    -0.57737,94.00686,50.00000,0.0000e+000,20.00000,-8.7910e-002,0.90832
290.71201, 40.11500,    -0.58352,93.99424,50.00000,0.0000e+000,20.00000,-8.9027e-002,0.90640
292.46399, 40.29500,    -0.58889,93.97933,50.00000,0.0000e+000,20.00000,-9.0491e-002,0.90445
294.20999, 40.47500,    -0.59477,93.96300,50.00000,0.0000e+000,20.00000,-9.2139e-002,0.90252
295.95901, 40.65500,    -0.60124,93.94621,50.00000,0.0000e+000,20.00000,-9.3626e-002,0.90059
297.69199, 40.83500,    -0.60826,93.92905,50.00000,0.0000e+000,20.00000,-9.4605e-002,0.89868
299.44299, 41.01500,    -0.61464,93.90871,50.00000,0.0000e+000,20.00000,-9.5081e-002,0.89676
301.20499, 41.19500,    -0.62109,93.88821,50.00000,0.0000e+000,20.00000,-9.6089e-002,0.89483
302.95700, 41.37500,    -0.62763,93.87106,50.00000,0.0000e+000,20.00000,-9.7750e-002,0.89292
304.71201, 41.55500,    -0.63390,93.85490,50.00000,0.0000e+000,20.00000,-9.9516e-002,0.89101
306.47299, 41.73500,    -0.63975,93.83707,50.00000,0.0000e+000,20.00000,    -0.10135,0.88910
308.24799, 41.91500,    -0.64462,93.81914,50.00000,0.0000e+000,20.00000,    -0.10383,0.88718
310.02301, 42.09500,    -0.64965,93.79968,50.00000,0.0000e+000,20.00000,    -0.10588,0.88526
311.78101, 42.27500,    -0.65413,93.77839,50.00000,0.0000e+000,20.00000,    -0.10727,0.88337
313.55801, 42.45500,    -0.65933,93.75872,50.00000,0.0000e+000,20.00000,    -0.10922,0.88147
315.32199, 42.63500,    -0.66402,93.74155,50.00000,0.0000e+000,20.00000,    -0.11171,0.87958
317.09601, 42.81500,    -0.66985,93.72448,50.00000,0.0000e+000,20.00000,    -0.11439,0.87769
318.86700, 42.99500,    -0.67540,93.70574,50.00000,0.0000e+000,20.00000,    -0.11657,0.87580
320.64001, 43.17500,    -0.68070,93.68482,50.00000,0.0000e+000,20.00000,    -0.11913,0.87392
322.42099, 43.35500,    -0.68571,93.66227,50.00000,0.0000e+000,20.00000,    -0.12204,0.87204
324.20801, 43.53500,    -0.69125,93.64138,50.00000,0.0000e+000,20.00000,    -0.12543,0.87016
325.98499, 43.71500,    -0.69522,93.62024,50.00000,0.0000e+000,20.00000,    -0.12949,0.86829
327.76001, 43.89500,    -0.69982,93.59799,50.00000,0.0000e+000,20.00000,    -0.13308,0.86643
329.54099, 44.07500,    -0.70357,93.57686,50.00000,0.0000e+000,20.00000,    -0.13630,0.86458
331.31799, 44.25500,    -0.70791,93.55334,50.00000,0.0000e+000,20.00000,    -0.13984,0.86273
333.10199, 44.43500,    -0.71200,93.52778,50.00000,0.0000e+000,20.00000,    -0.14511,0.86087
334.87601, 44.61500,    -0.71696,93.49849,50.00000,0.0000e+000,20.00000,    -0.15095,0.85904
336.65100, 44.79500,    -0.72123,93.46933,50.00000,0.0000e+000,20.00000,    -0.15660,0.85721
338.43900, 44.97500,    -0.72457,93.44216,50.00000,0.0000e+000,20.00000,    -0.16205,0.85537
340.23099, 45.15500,    -0.72714,93.41553,50.00000,0.0000e+000,20.00000,    -0.16773,0.85354
341.99301, 45.33500,    -0.73031,93.38634,50.00000,0.0000e+000,20.00000,    -0.17407,0.85174
343.78299, 45.51500,    -0.73335,93.35352,50.00000,0.0000e+000,20.00000,    -0.18022,0.84992
345.56400, 45.69500,    -0.73616,93.32148,50.00000,0.0000e+000,20.00000,    -0.18547,0.84811
347.35199, 45.87500,    -0.73889,93.28835,50.00000,0.0000e+000,20.00000,    -0.19129,0.84630
349.13300, 46.05500,    -0.74137,93.25571,50.00000,0.0000e+000,20.00000,    -0.19718,0.84450
350.91299, 46.23500,    -0.74397,93.21949,50.00000,0.0000e+000,20.00000,    -0.20353,0.84272
352.69901, 46.41500,    -0.74729,93.18137,50.00000,0.0000e+000,20.00000,    -0.20788,0.84093
354.47601, 46.59500,    -0.75053,93.14235,50.00000,0.0000e+000,20.00000,    -0.21205,0.83915
356.26700, 46.77500,    -0.75442,93.10229,50.00000,0.0000e+000,20.00000,    -0.21658,0.83737
358.04501, 46.95500,    -0.75768,93.05931,50.00000,0.0000e+000,20.00000,    -0.22108,0.83561
359.82001, 47.13500,    -0.76229,93.01508,50.00000,0.0000e+000,20.00000,    -0.22564,0.83385
361.60300, 47.31500,    -0.76742,92.97130,50.00000,0.0000e+000,20.00000,    -0.22864,0.83210
363.39700, 47.49500,    -0.77312,92.92978,50.00000,0.0000e+000,20.00000,    -0.23074,0.83034
365.19299, 47.67500,    -0.77913,92.88756,50.00000,0.0000e+000,20.00000,    -0.23260,0.82858
366.98801, 47.85500,    -0.78331,92.84354,50.00000,0.0000e+000,20.00000,    -0.23560,0.82683
368.77802, 48.03500,    -0.78740,92.79526,50.00000,0.0000e+000,20.00000,    -0.23801,0.82509
370.54800, 48.21500,    -0.79119,92.75000,50.00000,0.0000e+000,20.00000,    -0.23929,0.82337
372.32999, 48.39500,    -0.79598,92.70546,50.00000,0.0000e+000,20.00000,    -0.23938,0.82165
374.09299, 48.57500,    -0.80277,92.66120,50.00000,0.0000e+000,20.00000,    -0.23887,0.81996
375.89600, 48.75500,    -0.81007,92.61830,50.00000,0.0000e+000,20.00000,    -0.23712,0.81823
377.66901, 48.93500,    -0.81689,92.57337,50.00000,0.0000e+000,20.00000,    -0.23491,0.81654
379.43799, 49.11500,    -0.82523,92.52923,50.00000,0.0000e+000,20.00000,    -0.23347,0.81485
381.22800, 49.29500,    -0.83283,92.48896,50.00000,0.0000e+000,20.00000,    -0.23339,0.81316
383.00500, 49.47500,    -0.84076,92.44960,50.00000,0.0000e+000,20.00000,    -0.23305,0.81148
384.79001, 49.65500,    -0.84754,92.40643,50.00000,0.0000e+000,20.00000,    -0.23165,0.80979
386.57001, 49.83500,    -0.85493,92.36211,50.00000,0.0000e+000,20.00000,    -0.22910,0.80812
388.33099, 50.01500,    -0.86316,92.31883,50.00000,0.0000e+000,20.00000,    -0.22605,0.80648
390.10300, 50.19500,    -0.87212,92.27933,50.00000,0.0000e+000,20.00000,    -0.22310,0.80483
391.90500, 50.37500,    -0.88245,92.24117,50.00000,0.0000e+000,20.00000,    -0.22055,0.80315
393.69400, 50.55500,    -0.89221,92.20475,50.00000,0.0000e+000,20.00000,    -0.21907,0.80150
395.48199, 50.73500,    -0.90154,92.16895,50.00000,0.0000e+000,20.00000,    -0.21656,0.79985
397.28000, 50.91500,    -0.91023,92.13058,50.00000,0.0000e+000,20.00000,    -0.21447,0.79820
399.05399, 51.09500,    -0.91718,92.08952,50.00000,0.0000e+000,20.00000,    -0.21431,0.79657
400.82901, 51.27500,    -0.92339,92.04822,50.00000,0.0000e+000,20.00000,    -0.21491,0.79495
402.60599, 51.45500,    -0.92790,92.00982,50.00000,0.0000e+000,20.00000,    -0.21400,0.79334
404.38901, 51.63500,    -0.93407,91.97093,50.00000,0.0000e+000,20.00000,    -0.21283,0.79173
406.14999, 51.81500,    -0.94217,91.93563,50.00000,0.0000e+000,20.00000,    -0.21220,0.79014
407.92001, 51.99500,    -0.94967,91.90207,50.00000,0.0000e+000,20.00000,    -0.21192,0.78855
409.68799, 52.17500,    -0.95685,91.86736,50.00000,0.0000e+000,20.00000,    -0.21211,0.78696
411.46399, 52.35500,    -0.96443,91.82989,50.00000,0.0000e+000,20.00000,    -0.21421,0.78538
413.23801, 52.53500,    -0.97216,91.79413,50.00000,0.0000e+000,20.00000,    -0.21645,0.78380
415.02200, 52.71500,    -0.98007,91.75778,50.00000,0.0000e+000,20.00000,    -0.21754,0.78222
416.80899, 52.89500,    -0.98758,91.71789,50.00000,0.0000e+000,20.00000,    -0.21785,0.78065
418.60999, 53.07500,    -0.99516,91.67653,50.00000,0.0000e+000,20.00000,    -0.21819,0.77906
420.39499, 53.25500,    -1.00158,91.63697,50.00000,0.0000e+000,20.00000,    -0.21917,0.77750
422.18500, 53.43500,    -1.00808,91.59727,50.00000,0.0000e+000,20.00000,    -0.22012,0.77594
423.97101, 53.61500,    -1.01428,91.55582,50.00000,0.0000e+000,20.00000,    -0.22244,0.77439
425.78400, 53.79500,    -1.02121,91.51647,50.00000,0.0000e+000,20.00000,    -0.22415,0.77282
427.57800, 53.97500,    -1.02749,91.47790,50.00000,0.0000e+000,20.00000,    -0.22560,0.77127
429.37000, 54.15500,    -1.03484,91.43424,50.00000,0.0000e+000,20.00000,    -0.22747,0.76973
431.17801, 54.33500,    -1.04189,91.38985,50.00000,0.0000e+000,20.00000,    -0.22975,0.76819
432.97699, 54.51500,    -1.04711,91.34791,50.00000,0.0000e+000,20.00000,    -0.23207,0.76665
434.76501, 54.69500,    -1.05251,91.30611,50.00000,0.0000e+000,20.00000,    -0.23432,0.76513
436.59601, 54.87500,    -1.06070,91.26346,50.00000,0.0000e+000,20.00000,    -0.23525,0.76359
438.41800, 55.05500,    -1.06958,91.22088,50.00000,0.0000e+000,20.00000,    -0.23614,0.76205
440.23401, 55.23500,    -1.07730,91.17902,50.00000,0.0000e+000,20.00000,    -0.23814,0.76053
442.05099, 55.41500,    -1.08294,91.13433,50.00000,0.0000e+000,20.00000,    -0.23992,0.75901
443.87201, 55.59500,    -1.08656,91.09381,50.00000,0.0000e+000,20.00000,    -0.24148,0.75750
445.65900, 55.77500,    -1.08901,91.05468,50.00000,0.0000e+000,20.00000,    -0.24401,0.75601
447.44000, 55.95500,    -1.09110,91.01110,50.00000,0.0000e+000,20.00000,    -0.24489,0.75454
449.20801, 56.13500,    -1.09464,90.96637,50.00000,0.0000e+000,20.00000,    -0.24513,0.75309
451.00299, 56.31500,    -1.09917,90.92243,50.00000,0.0000e+000,20.00000,    -0.24598,0.75162
452.77399, 56.49500,    -1.10349,90.87496,50.00000,0.0000e+000,20.00000,    -0.24726,0.75017
454.54901, 56.67500,    -1.10812,90.82951,50.00000,0.0000e+000,20.00000,    -0.24834,0.74873
456.33401, 56.85500,    -1.11376,90.78658,50.00000,0.0000e+000,20.00000,    -0.24956,0.74729
458.10101, 57.03500,    -1.12004,90.74049,50.00000,0.0000e+000,20.00000,    -0.25178,0.74586
459.86099, 57.21500,    -1.12577,90.69228,50.00000,0.0000e+000,20.00000,    -0.25345,0.74445
461.63199, 57.39500,    -1.13199,90.64676,50.00000,0.0000e+000,20.00000,    -0.25537,0.74303
463.41000, 57.57500,    -1.13923,90.59945,50.00000,0.0000e+000,20.00000,    -0.25781,0.74162
465.20300, 57.75500,    -1.14829,90.55303,50.00000,0.0000e+000,20.00000,    -0.25949,0.74020
467.00000, 57.93500,    -1.15508,90.50744,50.00000,0.0000e+000,20.00000,    -0.26124,0.73878
468.78299, 58.11500,    -1.16023,90.46217,50.00000,0.0000e+000,20.00000,    -0.26384,0.73737
470.57401, 58.29500,    -1.16509,90.41594,50.00000,0.0000e+000,20.00000,    -0.26467,0.73597
472.35300, 58.47500,    -1.17098,90.36946,50.00000,0.0000e+000,20.00000,    -0.26566,0.73458
474.14600, 58.65500,    -1.17658,90.32245,50.00000,0.0000e+000,20.00000,    -0.26772,0.73319
475.93600, 58.83500,    -1.18234,90.27315,50.00000,0.0000e+000,20.00000,    -0.26876,0.73180
477.72900, 59.01500,    -1.18846,90.22237,50.00000,0.0000e+000,20.00000,    -0.26982,0.73042
479.53500, 59.19500,    -1.19713,90.17350,50.00000,0.0000e+000,20.00000,    -0.27223,0.72903
481.35001, 59.37500,    -1.20417,90.12601,50.00000,0.0000e+000,20.00000,    -0.27402,0.72764
483.14499, 59.55500,    -1.21033,90.07714,50.00000,0.0000e+000,20.00000,    -0.27600,0.72628
484.93100, 59.73500,    -1.21458,90.02629,50.00000,0.0000e+000,20.00000,    -0.27770,0.72492
486.72400, 59.91500,    -1.21920,89.97300,50.00000,0.0000e+000,20.00000,    -0.27905,0.72357
488.52100, 60.09500,    -1.22457,89.92241,50.00000,0.0000e+000,20.00000,    -0.28082,0.72222
490.31100, 60.27500,    -1.22911,89.87289,50.00000,0.0000e+000,20.00000,    -0.28318,0.72088
492.08200, 60.45500,    -1.23373,89.82234,50.00000,0.0000e+000,20.00000,    -0.28437,0.71956
493.87701, 60.63500,    -1.23803,89.77308,50.00000,0.0000e+000,20.00000,    -0.28431,0.71823
495.65201, 60.81500,    -1.24207,89.72156,50.00000,0.0000e+000,20.00000,    -0.28386,0.71691
497.43100, 60.99500,    -1.24736,89.66699,50.00000,0.0000e+000,20.00000,    -0.28471,0.71560
499.21899, 61.17500,    -1.25586,89.61343,50.00000,0.0000e+000,20.00000,    -0.28637,0.71429
501.03799, 61.35500,    -1.26597,89.55939,50.00000,0.0000e+000,20.00000,    -0.28825,0.71297
502.85001, 61.53500,    -1.27610,89.50715,50.00000,0.0000e+000,20.00000,    -0.28990,0.71165
504.66901, 61.71500,    -1.28259,89.45688,50.00000,0.0000e+000,20.00000,    -0.29097,0.71033
506.46799, 61.89500,    -1.28727,89.40501,50.00000,0.0000e+000,20.00000,    -0.29178,0.70904
508.26599, 62.07500,    -1.29080,89.34974,50.00000,0.0000e+000,20.00000,    -0.29177,0.70775
510.06400, 62.25500,    -1.29468,89.29807,50.00000,0.0000e+000,20.00000,    -0.29139,0.70646
511.86099, 62.43500,    -1.29941,89.24892,50.00000,0.0000e+000,20.00000,    -0.29190,0.70518
513.65002, 62.61500,    -1.30444,89.20042,50.00000,0.0000e+000,20.00000,    -0.29329,0.70392
515.44598, 62.79500,    -1.30829,89.14817,50.00000,0.0000e+000,20.00000,    -0.29452,0.70265
517.23199, 62.97500,    -1.31245,89.09502,50.00000,0.0000e+000,20.00000,    -0.29481,0.70139
519.03497, 63.15500,    -1.31786,89.03966,50.00000,0.0000e+000,20.00000,    -0.29411,0.70013
520.82599, 63.33500,    -1.32385,88.98341,50.00000,0.0000e+000,20.00000,    -0.29520,0.69889
522.62201, 63.51500,    -1.32934,88.92625,50.00000,0.0000e+000,20.00000,    -0.29919,0.69764
524.40698, 63.69500,    -1.33504,88.87134,50.00000,0.0000e+000,20.00000,    -0.30166,0.69641
526.19897, 63.87500,    -1.33985,88.82158,50.00000,0.0000e+000,20.00000,    -0.30118,0.69518
527.97900, 64.05500,    -1.34473,88.77257,50.00000,0.0000e+000,20.00000,    -0.30171,0.69396
529.77399, 64.23500,    -1.34970,88.72179,50.00000,0.0000e+000,20.00000,    -0.30306,0.69274
531.56897, 64.41500,    -1.35544,88.66667,50.00000,0.0000e+000,20.00000,    -0.30578,0.69152
533.35602, 64.59500,    -1.36021,88.60766,50.00000,0.0000e+000,20.00000,    -0.30900,0.69031
535.13300, 64.77500,    -1.36536,88.55209,50.00000,0.0000e+000,20.00000,    -0.31154,0.68911
536.94202, 64.95500,    -1.37338,88.50062,50.00000,0.0000e+000,20.00000,    -0.31097,0.68790
538.76001, 65.13500,    -1.38184,88.44534,50.00000,0.0000e+000,20.00000,    -0.30940,0.68669
540.56299, 65.31500,    -1.38874,88.38095,50.00000,0.0000e+000,20.00000,    -0.30959,0.68549
542.37500, 65.49500,    -1.39453,88.31925,50.00000,0.0000e+000,20.00000,    -0.31175,0.68430
544.19202, 65.67500,    -1.40014,88.26533,50.00000,0.0000e+000,20.00000,    -0.31401,0.68310
545.96997, 65.85500,    -1.40457,88.21144,50.00000,0.0000e+000,20.00000,    -0.31508,0.68194
547.77002, 66.03500,    -1.40840,88.15685,50.00000,0.0000e+000,20.00000,    -0.31588,0.68076
549.58197, 66.21500,    -1.41373,88.09983,50.00000,0.0000e+000,20.00000,    -0.31728,0.67959
551.36603, 66.39500,    -1.41794,88.03675,50.00000,0.0000e+000,20.00000,    -0.31757,0.67843
553.17102, 66.57500,    -1.42328,87.97350,50.00000,0.0000e+000,20.00000,    -0.31798,0.67727
554.97101, 66.75500,    -1.42855,87.91927,50.00000,0.0000e+000,20.00000,    -0.31919,0.67612
556.77100, 66.93500,    -1.43410,87.86922,50.00000,0.0000e+000,20.00000,    -0.32114,0.67497
558.55298, 67.11500,    -1.43915,87.81287,50.00000,0.0000e+000,20.00000,    -0.32157,0.67384
560.35199, 67.29500,    -1.44419,87.74952,50.00000,0.0000e+000,20.00000,    -0.32136,0.67270
562.14301, 67.47500,    -1.44976,87.68976,50.00000,0.0000e+000,20.00000,    -0.32223,0.67157
563.93597, 67.65500,    -1.45473,87.63643,50.00000,0.0000e+000,20.00000,    -0.32370,0.67045
565.74103, 67.83500,    -1.46076,87.58373,50.00000,0.0000e+000,20.00000,    -0.32499,0.66932
567.52100, 68.01500,    -1.46627,87.52511,50.00000,0.0000e+000,20.00000,    -0.32683,0.66821
569.31500, 68.19500,    -1.46971,87.46493,50.00000,0.0000e+000,20.00000,    -0.32637,0.66710
571.12299, 68.37500,    -1.47394,87.40668,50.00000,0.0000e+000,20.00000,    -0.32425,0.66599
572.93500, 68.55500,    -1.48279,87.35052,50.00000,0.0000e+000,20.00000,    -0.32447,0.66488
574.74902, 68.73500,    -1.49029,87.29043,50.00000,0.0000e+000,20.00000,    -0.32845,0.66377
576.55402, 68.91500,    -1.49956,87.22555,50.00000,0.0000e+000,20.00000,    -0.33120,0.66267
578.34601, 69.09500,    -1.50427,87.16260,50.00000,0.0000e+000,20.00000,    -0.33077,0.66159
580.15900, 69.27500,    -1.51057,87.10450,50.00000,0.0000e+000,20.00000,    -0.33068,0.66050
581.98401, 69.45500,    -1.52057,87.04571,50.00000,0.0000e+000,20.00000,    -0.33389,0.65940
583.80798, 69.63500,    -1.53012,86.98665,50.00000,0.0000e+000,20.00000,    -0.33802,0.65831
585.63800, 69.81500,    -1.53583,86.92400,50.00000,0.0000e+000,20.00000,    -0.34035,0.65722
587.45801, 69.99500,    -1.54036,86.86275,50.00000,0.0000e+000,20.00000,    -0.34172,0.65615
589.25897, 70.17500,    -1.54418,86.80588,50.00000,0.0000e+000,20.00000,    -0.34406,0.65509
591.06598, 70.35500,    -1.54906,86.75030,50.00000,0.0000e+000,20.00000,    -0.34659,0.65403
592.87299, 70.53500,    -1.55237,86.68665,50.00000,0.0000e+000,20.00000,    -0.34892,0.65297
594.63397, 70.71500,    -1.55422,86.62129,50.00000,0.0000e+000,20.00000,    -0.35015,0.65195
596.43103, 70.89500,    -1.55800,86.55940,50.00000,0.0000e+000,20.00000,    -0.35119,0.65091
598.20599, 71.07500,    -1.56278,86.49922,50.00000,0.0000e+000,20.00000,    -0.35370,0.64988
600.00897, 71.25500,    -1.56915,86.43441,50.00000,0.0000e+000,20.00000,    -0.35637,0.64885
601.79199, 71.43500,    -1.57569,86.36674,50.00000,0.0000e+000,20.00000,    -0.35955,0.64783
603.59003, 71.61500,    -1.58082,86.30038,50.00000,0.0000e+000,20.00000,    -0.36223,0.64681
605.37903, 71.79500,    -1.58668,86.23520,50.00000,0.0000e+000,20.00000,    -0.36452,0.64579
607.17499, 71.97500,    -1.59196,86.16799,50.00000,0.0000e+000,20.00000,    -0.36757,0.64478
608.96899, 72.15500,    -1.59695,86.10243,50.00000,0.0000e+000,20.00000,    -0.37165,0.64377
610.74701, 72.33500,    -1.60140,86.03522,50.00000,0.0000e+000,20.00000,    -0.37317,0.64278
612.54199, 72.51500,    -1.60576,85.96622,50.00000,0.0000e+000,20.00000,    -0.37442,0.64178
614.33301, 72.69500,    -1.61132,85.89844,50.00000,0.0000e+000,20.00000,    -0.37677,0.64079
616.13300, 72.87500,    -1.61982,85.83099,50.00000,0.0000e+000,20.00000,    -0.37931,0.63979
617.95001, 73.05500,    -1.62780,85.76268,50.00000,0.0000e+000,20.00000,    -0.38249,0.63880
619.78699, 73.23500,    -1.63646,85.69268,50.00000,0.0000e+000,20.00000,    -0.38491,0.63779
621.57800, 73.41500,    -1.64216,85.62063,50.00000,0.0000e+000,20.00000,    -0.38561,0.63682
623.39697, 73.59500,    -1.64664,85.55009,50.00000,0.0000e+000,20.00000,    -0.38610,0.63583
625.18500, 73.77500,    -1.65069,85.48137,50.00000,0.0000e+000,20.00000,    -0.38622,0.63486
626.99298, 73.95500,    -1.65485,85.41147,50.00000,0.0000e+000,20.00000,    -0.38852,0.63389
628.79199, 74.13500,    -1.66093,85.34314,50.00000,0.0000e+000,20.00000,    -0.39070,0.63293
630.60797, 74.31500,    -1.66681,85.27359,50.00000,0.0000e+000,20.00000,    -0.39039,0.63196
632.42297, 74.49500,    -1.67145,85.20215,50.00000,0.0000e+000,20.00000,    -0.39158,0.63100
634.21600, 74.67500,    -1.67659,85.13298,50.00000,0.0000e+000,20.00000,    -0.39255,0.63005
636.02698, 74.85500,    -1.68252,85.05878,50.00000,0.0000e+000,20.00000,    -0.39247,0.62910
637.85498, 75.03500,    -1.68829,84.98123,50.00000,0.0000e+000,20.00000,    -0.39226,0.62814
639.74799, 75.21500,    -1.71050,84.91136,50.00000,0.0000e+000,20.00000,    -0.39138,0.62715
641.65002, 75.39500,    -1.72730,84.84419,50.00000,0.0000e+000,20.00000,    -0.39145,0.62617
643.48297, 75.57500,    -1.72857,84.77726,50.00000,0.0000e+000,20.00000,    -0.39070,0.62522
645.31097, 75.75500,    -1.72253,84.70410,50.00000,0.0000e+000,20.00000,    -0.38759,0.62428
647.08698, 75.93500,    -1.71600,84.62849,50.00000,0.0000e+000,20.00000,    -0.38680,0.62337
648.85101, 76.11500,    -1.71023,84.56035,50.00000,0.0000e+000,20.00000,    -0.38777,0.62247
650.62598, 76.29500,    -1.70970,84.48875,50.00000,0.0000e+000,20.00000,    -0.38671,0.62157
652.41901, 76.47500,    -1.71402,84.41701,50.00000,0.0000e+000,20.00000,    -0.38503,0.62066
654.22900, 76.65500,    -1.72362,84.34918,50.00000,0.0000e+000,20.00000,    -0.38366,0.61975
656.04303, 76.83500,    -1.73112,84.28030,50.00000,0.0000e+000,20.00000,    -0.38101,0.61884
657.80603, 77.01500,    -1.73285,84.21183,50.00000,0.0000e+000,20.00000,    -0.37930,0.61796
659.55499, 77.19500,    -1.73043,84.14073,50.00000,0.0000e+000,20.00000,    -0.37741,0.61709
661.32202, 77.37500,    -1.73075,84.07331,50.00000,0.0000e+000,20.00000,    -0.37575,0.61621
663.09100, 77.55500,    -1.73383,84.01452,50.00000,0.0000e+000,20.00000,    -0.37276,0.61534
664.85498, 77.73500,    -1.73889,83.95056,50.00000,0.0000e+000,20.00000,    -0.36825,0.61447
666.63098, 77.91500,    -1.74288,83.87816,50.00000,0.0000e+000,20.00000,    -0.36667,0.61360
668.41901, 78.09500,    -1.75014,83.80927,50.00000,0.0000e+000,20.00000,    -0.36525,0.61273
670.25403, 78.27500,    -1.76245,83.74621,50.00000,0.0000e+000,20.00000,    -0.36212,0.61184
672.11798, 78.45500,    -1.77648,83.67898,50.00000,0.0000e+000,20.00000,    -0.35897,0.61094
673.91998, 78.63500,    -1.78038,83.61026,50.00000,0.0000e+000,20.00000,    -0.35509,0.61007
675.71002, 78.81500,    -1.77785,83.54502,50.00000,0.0000e+000,20.00000,    -0.35161,0.60921
677.48297, 78.99500,    -1.77524,83.48398,50.00000,0.0000e+000,20.00000,    -0.34772,0.60836
679.23602, 79.17500,    -1.77483,83.42376,50.00000,0.0000e+000,20.00000,    -0.34435,0.60753
681.03101, 79.35500,    -1.77803,83.36251,50.00000,0.0000e+000,20.00000,    -0.34258,0.60668
682.83398, 79.53500,    -1.78611,83.30282,50.00000,0.0000e+000,20.00000,    -0.33806,0.60583
684.64502, 79.71500,    -1.79327,83.24046,50.00000,0.0000e+000,20.00000,    -0.33055,0.60498
686.43903, 79.89500,    -1.79667,83.17482,50.00000,0.0000e+000,20.00000,    -0.32429,0.60414
688.24200, 80.07500,    -1.80065,83.11305,50.00000,0.0000e+000,20.00000,    -0.32024,0.60330
690.05200, 80.25500,    -1.80619,83.05595,50.00000,0.0000e+000,20.00000,    -0.31606,0.60246
691.86700, 80.43500,    -1.81090,83.00136,50.00000,0.0000e+000,20.00000,    -0.31060,0.60162
693.66400, 80.61500,    -1.81384,82.94585,50.00000,0.0000e+000,20.00000,    -0.30482,0.60079
695.48102, 80.79500,    -1.81944,82.88934,50.00000,0.0000e+000,20.00000,    -0.30027,0.59995
697.29498, 80.97500,    -1.82492,82.83303,50.00000,0.0000e+000,20.00000,    -0.29662,0.59912
699.10498, 81.15500,    -1.82479,82.77878,50.00000,0.0000e+000,20.00000,    -0.29184,0.59830
700.87402, 81.33500,    -1.82560,82.73228,50.00000,0.0000e+000,20.00000,    -0.28788,0.59750
702.66498, 81.51500,    -1.82928,82.68800,50.00000,0.0000e+000,20.00000,    -0.28320,0.59669
704.47601, 81.69500,    -1.83484,82.64134,50.00000,0.0000e+000,20.00000,    -0.27662,0.59587
706.28900, 81.87500,    -1.83953,82.59302,50.00000,0.0000e+000,20.00000,    -0.27136,0.59506
708.08301, 82.05500,    -1.84015,82.54220,50.00000,0.0000e+000,20.00000,    -0.26725,0.59426
709.85999, 82.23500,    -1.83872,82.49246,50.00000,0.0000e+000,20.00000,    -0.26265,0.59347
711.65900, 82.41500,    -1.83962,82.44733,50.00000,0.0000e+000,20.00000,    -0.25633,0.59267
713.47302, 82.59500,    -1.83976,82.40276,50.00000,0.0000e+000,20.00000,    -0.24839,0.59187
715.28302, 82.77500,    -1.84537,82.35586,50.00000,0.0000e+000,20.00000,    -0.23838,0.59107
717.13800, 82.95500,    -1.85454,82.31187,50.00000,0.0000e+000,20.00000,    -0.22858,0.59026
718.99597, 83.13500,    -1.86287,82.26673,50.00000,0.0000e+000,20.00000,    -0.22197,0.58944
720.83502, 83.31500,    -1.86532,82.22174,50.00000,0.0000e+000,20.00000,    -0.21715,0.58864
722.65302, 83.49500,    -1.86644,82.18011,50.00000,0.0000e+000,20.00000,    -0.21244,0.58785
724.41101, 83.67500,    -1.86411,82.13706,50.00000,0.0000e+000,20.00000,    -0.20618,0.58709
726.15802, 83.85500,    -1.86024,82.09386,50.00000,0.0000e+000,20.00000,    -0.19737,0.58634
727.92902, 84.03500,    -1.86516,82.05514,50.00000,0.0000e+000,20.00000,    -0.18822,0.58558
729.71301, 84.21500,    -1.87752,82.02214,50.00000,0.0000e+000,20.00000,    -0.18103,0.58482
731.52698, 84.39500,    -1.88929,81.99387,50.00000,0.0000e+000,20.00000,    -0.17463,0.58405
733.31702, 84.57500,    -1.89533,81.97299,50.00000,0.0000e+000,20.00000,    -0.16698,0.58329
735.10901, 84.75500,    -1.89994,81.95446,50.00000,0.0000e+000,20.00000,    -0.15925,0.58253
736.90302, 84.93500,    -1.90332,81.93150,50.00000,0.0000e+000,20.00000,    -0.15196,0.58177
738.73102, 85.11500,    -1.90996,81.90552,50.00000,0.0000e+000,20.00000,    -0.14506,0.58100
740.55798, 85.29500,    -1.91897,81.87647,50.00000,0.0000e+000,20.00000,    -0.13935,0.58024
742.38702, 85.47500,    -1.92407,81.85037,50.00000,0.0000e+000,20.00000,    -0.13299,0.57947
744.20398, 85.65500,    -1.92584,81.83114,50.00000,0.0000e+000,20.00000,    -0.12629,0.57872
746.00702, 85.83500,    -1.92579,81.81458,50.00000,0.0000e+000,20.00000,    -0.11992,0.57797
747.79700, 86.01500,    -1.92219,81.79546,50.00000,0.0000e+000,20.00000,    -0.11436,0.57723
749.60999, 86.19500,    -1.92493,81.77466,50.00000,0.0000e+000,20.00000,    -0.11034,0.57648
751.42902, 86.37500,    -1.92639,81.75525,50.00000,0.0000e+000,20.00000,    -0.10882,0.57574
753.24200, 86.55500,    -1.92800,81.73899,50.00000,0.0000e+000,20.00000,    -0.10792,0.57500
755.05701, 86.73500,    -1.92998,81.72130,50.00000,0.0000e+000,20.00000,    -0.10494,0.57426
756.87402, 86.91500,    -1.93234,81.70137,50.00000,0.0000e+000,20.00000,    -0.10198,0.57352
758.69000, 87.09500,    -1.93575,81.68031,50.00000,0.0000e+000,20.00000,-9.7920e-002,0.57278
760.48700, 87.27500,    -1.93606,81.66053,50.00000,0.0000e+000,20.00000,-9.4139e-002,0.57205
762.26599, 87.45500,    -1.93144,81.64162,50.00000,0.0000e+000,20.00000,-9.2742e-002,0.57134
764.05902, 87.63500,    -1.92933,81.62448,50.00000,0.0000e+000,20.00000,-9.2280e-002,0.57062
765.85400, 87.81500,    -1.92979,81.61101,50.00000,0.0000e+000,20.00000,-9.1573e-002,0.56990
767.63397, 87.99500,    -1.93156,81.59682,50.00000,0.0000e+000,20.00000,-8.9964e-002,0.56919
769.45697, 88.17500,    -1.93411,81.58063,50.00000,0.0000e+000,20.00000,-8.7813e-002,0.56846
771.25897, 88.35500,    -1.93672,81.56503,50.00000,0.0000e+000,20.00000,-8.5994e-002,0.56775
773.08002, 88.53500,    -1.94007,81.55349,50.00000,0.0000e+000,20.00000,-8.4896e-002,0.56703
774.86603, 88.71500,    -1.93972,81.53941,50.00000,0.0000e+000,20.00000,-8.4211e-002,0.56632
776.70697, 88.89500,    -1.94619,81.52489,50.00000,0.0000e+000,20.00000,-8.2757e-002,0.56560
778.53497, 89.07500,    -1.95117,81.51210,50.00000,0.0000e+000,20.00000,-8.1153e-002,0.56488
780.34399, 89.25500,    -1.95196,81.49698,50.00000,0.0000e+000,20.00000,-8.0264e-002,0.56418
782.15503, 89.43500,    -1.95044,81.48230,50.00000,0.0000e+000,20.00000,-7.9084e-002,0.56347
783.94501, 89.61500,    -1.95294,81.46631,50.00000,0.0000e+000,20.00000,-7.9335e-002,0.56277
785.75897, 89.79500,    -1.95675,81.45107,50.00000,0.0000e+000,20.00000,-7.9618e-002,0.56207
787.55103, 89.97500,    -1.95716,81.43872,50.00000,0.0000e+000,20.00000,-7.9122e-002,0.56138
789.34399, 90.15500,    -1.95906,81.42865,50.00000,0.0000e+000,20.00000,-7.8557e-002,0.56069
791.13800, 90.33500,    -1.96314,81.41630,50.00000,0.0000e+000,20.00000,-7.9720e-002,0.56000
792.95502, 90.51500,    -1.97082,81.39939,50.00000,0.0000e+000,20.00000,-8.1248e-002,0.55930
794.76099, 90.69500,    -1.97936,81.38317,50.00000,0.0000e+000,20.00000,-8.2696e-002,0.55861
796.57898, 90.87500,    -1.98659,81.36915,50.00000,0.0000e+000,20.00000,-8.4955e-002,0.55791
798.38000, 91.05500,    -1.99231,81.35347,50.00000,0.0000e+000,20.00000,-8.6654e-002,0.55723
800.15399, 91.23500,    -1.99644,81.33972,50.00000,0.0000e+000,20.00000,-8.7704e-002,0.55656
801.92798, 91.41500,    -1.99674,81.32545,50.00000,0.0000e+000,20.00000,-8.9511e-002,0.55588
803.75897, 91.59500,    -2.00502,81.31028,50.00000,0.0000e+000,20.00000,-9.1683e-002,0.55519
805.57397, 91.77500,    -2.01784,81.29619,50.00000,0.0000e+000,20.00000,-9.3978e-002,0.55451
807.40900, 91.95500,    -2.02650,81.28215,50.00000,0.0000e+000,20.00000,-9.6652e-002,0.55382
809.19702, 92.13500,    -2.02913,81.26658,50.00000,0.0000e+000,20.00000,-9.9505e-002,0.55315
810.98798, 92.31500,    -2.03120,81.24787,50.00000,0.0000e+000,20.00000,    -0.10239,0.55248
812.80103, 92.49500,    -2.03609,81.22773,50.00000,0.0000e+000,20.00000,    -0.10567,0.55180
814.62500, 92.67500,    -2.04404,81.20699,50.00000,0.0000e+000,20.00000,    -0.10964,0.55112
816.48798, 92.85500,    -2.05463,81.18563,50.00000,0.0000e+000,20.00000,    -0.11315,0.55043
818.31201, 93.03500,    -2.05899,81.16690,50.00000,0.0000e+000,20.00000,    -0.11639,0.54975
820.11902, 93.21500,    -2.05673,81.14541,50.00000,0.0000e+000,20.00000,    -0.11923,0.54908
821.88599, 93.39500,    -2.05293,81.12145,50.00000,0.0000e+000,20.00000,    -0.12239,0.54843
823.67999, 93.57500,    -2.05194,81.10018,50.00000,0.0000e+000,20.00000,    -0.12660,0.54777
825.46698, 93.75500,    -2.04985,81.07984,50.00000,0.0000e+000,20.00000,    -0.13195,0.54711
827.25403, 93.93500,    -2.05033,81.05866,50.00000,0.0000e+000,20.00000,    -0.13751,0.54646
829.04901, 94.11500,    -2.05122,81.03217,50.00000,0.0000e+000,20.00000,    -0.14136,0.54580
830.84601, 94.29500,    -2.05210,81.00354,50.00000,0.0000e+000,20.00000,    -0.14543,0.54514
832.62701, 94.47500,    -2.05182,80.97508,50.00000,0.0000e+000,20.00000,    -0.14981,0.54449
834.40997, 94.65500,    -2.05158,80.94642,50.00000,0.0000e+000,20.00000,    -0.15351,0.54384
836.18799, 94.83500,    -2.05327,80.92013,50.00000,0.0000e+000,20.00000,    -0.15784,0.54320
837.98700, 95.01500,    -2.05499,80.89572,50.00000,0.0000e+000,20.00000,    -0.16187,0.54255
839.78400, 95.19500,    -2.05803,80.86954,50.00000,0.0000e+000,20.00000,    -0.16545,0.54189
841.59900, 95.37500,    -2.06083,80.84028,50.00000,0.0000e+000,20.00000,    -0.17023,0.54124
843.41498, 95.55500,    -2.06551,80.80746,50.00000,0.0000e+000,20.00000,    -0.17547,0.54058
845.21301, 95.73500,    -2.06745,80.77182,50.00000,0.0000e+000,20.00000,    -0.18045,0.53994
847.03003, 95.91500,    -2.07347,80.73906,50.00000,0.0000e+000,20.00000,    -0.18288,0.53928
848.85602, 96.09500,    -2.07640,80.70499,50.00000,0.0000e+000,20.00000,    -0.18455,0.53863
850.66302, 96.27500,    -2.07586,80.66810,50.00000,0.0000e+000,20.00000,    -0.18709,0.53798
852.46997, 96.45500,    -2.07608,80.63303,50.00000,0.0000e+000,20.00000,    -0.18963,0.53733
854.27100, 96.63500,    -2.07804,80.59812,50.00000,0.0000e+000,20.00000,    -0.19318,0.53669
856.06201, 96.81500,    -2.07720,80.56295,50.00000,0.0000e+000,20.00000,    -0.19749,0.53605
857.86200, 96.99500,    -2.08117,80.52602,50.00000,0.0000e+000,20.00000,    -0.20168,0.53541
859.67603, 97.17500,    -2.08431,80.48725,50.00000,0.0000e+000,20.00000,    -0.20420,0.53476
861.48297, 97.35500,    -2.08483,80.44752,50.00000,0.0000e+000,20.00000,    -0.20606,0.53412
863.30798, 97.53500,    -2.08826,80.40843,50.00000,0.0000e+000,20.00000,    -0.20776,0.53347
865.12598, 97.71500,    -2.09245,80.37305,50.00000,0.0000e+000,20.00000,    -0.20979,0.53283
866.93298, 97.89500,    -2.09587,80.33900,50.00000,0.0000e+000,20.00000,    -0.21129,0.53219
868.74799, 98.07500,    -2.09803,80.30146,50.00000,0.0000e+000,20.00000,    -0.21247,0.53155
870.56702, 98.25500,    -2.09840,80.26348,50.00000,0.0000e+000,20.00000,    -0.21374,0.53091
872.36200, 98.43500,    -2.09882,80.22406,50.00000,0.0000e+000,20.00000,    -0.21500,0.53028
874.15802, 98.61500,    -2.09548,80.18384,50.00000,0.0000e+000,20.00000,    -0.21679,0.52964
875.96002, 98.79500,    -2.09459,80.14278,50.00000,0.0000e+000,20.00000,    -0.21844,0.52901
877.73901, 98.97500,    -2.09439,80.10425,50.00000,0.0000e+000,20.00000,    -0.22024,0.52839
879.52899, 99.15500,    -2.09583,80.06581,50.00000,0.0000e+000,20.00000,    -0.22183,0.52776
881.33698, 99.33500,    -2.09908,80.02427,50.00000,0.0000e+000,20.00000,    -0.22316,0.52713
883.15399, 99.51500,    -2.10531,79.98309,50.00000,0.0000e+000,20.00000,    -0.22415,0.52649
884.97803, 99.69500,    -2.11233,79.94439,50.00000,0.0000e+000,20.00000,    -0.22482,0.52585
886.76703, 99.87500,    -2.11014,79.90331,50.00000,0.0000e+000,20.00000,    -0.22465,0.52523
888.54102,100.05500,    -2.10600,79.86311,50.00000,0.0000e+000,20.00000,    -0.22580,0.52461
890.39001,100.23500,    -2.11651,79.82380,50.00000,0.0000e+000,20.00000,    -0.22713,0.52396
892.22302,100.41500,    -2.12313,79.78248,50.00000,0.0000e+000,20.00000,    -0.22889,0.52332
894.06000,100.59500,    -2.12688,79.74009,50.00000,0.0000e+000,20.00000,    -0.23013,0.52268
895.87598,100.77500,    -2.12600,79.69522,50.00000,0.0000e+000,20.00000,    -0.23093,0.52205
897.66101,100.95500,    -2.12356,79.64978,50.00000,0.0000e+000,20.00000,    -0.23271,0.52143
899.45001,101.13500,    -2.11965,79.60507,50.00000,0.0000e+000,20.00000,    -0.23359,0.52081
901.26202,101.31500,    -2.11843,79.56474,50.00000,0.0000e+000,20.00000,    -0.23455,0.52018
903.05701,101.49500,    -2.11704,79.52810,50.00000,0.0000e+000,20.00000,    -0.23634,0.51956
904.84998,101.67500,    -2.11851,79.49209,50.00000,0.0000e+000,20.00000,    -0.23708,0.51894
906.65698,101.85500,    -2.11750,79.45074,50.00000,0.0000e+000,20.00000,    -0.23719,0.51831
908.47998,102.03500,    -2.11628,79.40678,50.00000,0.0000e+000,20.00000,    -0.23744,0.51768
910.27399,102.21500,    -2.11836,79.36077,50.00000,0.0000e+000,20.00000,    -0.23825,0.51706
912.09100,102.39500,    -2.11852,79.31444,50.00000,0.0000e+000,20.00000,    -0.23964,0.51643
913.89398,102.57500,    -2.11703,79.27246,50.00000,0.0000e+000,20.00000,    -0.23996,0.51581
915.69098,102.75500,    -2.11581,79.22817,50.00000,0.0000e+000,20.00000,    -0.24006,0.51519
917.55298,102.93500,    -2.12293,79.18375,50.00000,0.0000e+000,20.00000,    -0.24060,0.51455
919.38800,103.11500,    -2.12462,79.13885,50.00000,0.0000e+000,20.00000,    -0.24316,0.51391
921.19702,103.29500,    -2.11958,79.09337,50.00000,0.0000e+000,20.00000,    -0.24644,0.51329
922.96503,103.47500,    -2.11358,79.04959,50.00000,0.0000e+000,20.00000,    -0.24994,0.51268
924.75098,103.65500,    -2.10699,79.00831,50.00000,0.0000e+000,20.00000,    -0.25257,0.51206
926.53400,103.83500,    -2.10291,78.96833,50.00000,0.0000e+000,20.00000,    -0.25393,0.51145
928.33600,104.01500,    -2.10142,78.92516,50.00000,0.0000e+000,20.00000,    -0.25496,0.51083
930.12000,104.19500,    -2.09916,78.87798,50.00000,0.0000e+000,20.00000,    -0.25574,0.51021
931.90302,104.37500,    -2.09764,78.83202,50.00000,0.0000e+000,20.00000,    -0.25727,0.50960
933.71802,104.55500,    -2.09654,78.78640,50.00000,0.0000e+000,20.00000,    -0.25905,0.50897
935.51099,104.73500,    -2.09602,78.73960,50.00000,0.0000e+000,20.00000,    -0.26054,0.50836
937.30402,104.91500,    -2.09129,78.68975,50.00000,0.0000e+000,20.00000,    -0.26129,0.50774
939.10498,105.09500,    -2.08751,78.63998,50.00000,0.0000e+000,20.00000,    -0.26165,0.50712
940.91498,105.27500,    -2.08349,78.59195,50.00000,0.0000e+000,20.00000,    -0.26367,0.50650
942.72699,105.45500,    -2.07909,78.54183,50.00000,0.0000e+000,20.00000,    -0.26746,0.50587
944.54602,105.63500,    -2.07601,78.49276,50.00000,0.0000e+000,20.00000,    -0.27200,0.50525
946.34003,105.81500,    -2.06923,78.44385,50.00000,0.0000e+000,20.00000,    -0.27384,0.50463
948.13702,105.99500,    -2.06106,78.39382,50.00000,0.0000e+000,20.00000,    -0.27273,0.50401
949.94800,106.17500,    -2.05871,78.34602,50.00000,0.0000e+000,20.00000,    -0.27021,0.50339
951.74500,106.35500,    -2.05623,78.29598,50.00000,0.0000e+000,20.00000,    -0.26708,0.50277
953.59302,106.53500,    -2.05936,78.24574,50.00000,0.0000e+000,20.00000,    -0.26253,0.50213
955.41901,106.71500,    -2.06376,78.19786,50.00000,0.0000e+000,20.00000,    -0.25685,0.50150
957.22803,106.89500,    -2.06221,78.15130,50.00000,0.0000e+000,20.00000,    -0.24990,0.50088
959.03101,107.07500,    -2.05906,78.10062,50.00000,0.0000e+000,20.00000,    -0.24323,0.50026
960.82300,107.25500,    -2.05546,78.04558,50.00000,0.0000e+000,20.00000,    -0.23533,0.49964
962.62097,107.43500,    -2.05465,77.98868,50.00000,0.0000e+000,20.00000,    -0.22631,0.49902
964.40997,107.61500,    -2.05508,77.93823,50.00000,0.0000e+000,20.00000,    -0.21509,0.49840
966.20099,107.79500,    -2.05334,77.89449,50.00000,0.0000e+000,20.00000,    -0.20368,0.49779
967.99298,107.97500,    -2.05661,77.85676,50.00000,0.0000e+000,20.00000,    -0.19359,0.49717
969.79199,108.15500,    -2.06682,77.82215,50.00000,0.0000e+000,20.00000,    -0.18310,0.49655
971.60602,108.33500,    -2.07761,77.79182,50.00000,0.0000e+000,20.00000,    -0.17320,0.49592
973.43402,108.51500,    -2.09169,77.76292,50.00000,0.0000e+000,20.00000,    -0.16361,0.49529
975.24402,108.69500,    -2.09748,77.73756,50.00000,0.0000e+000,20.00000,    -0.15439,0.49466
977.04401,108.87500,    -2.09974,77.71398,50.00000,0.0000e+000,20.00000,    -0.14268,0.49404
978.87598,109.05500,    -2.10652,77.69232,50.00000,0.0000e+000,20.00000,    -0.12945,0.49341
980.71399,109.23500,    -2.11620,77.67491,50.00000,0.0000e+000,20.00000,    -0.11446,0.49277
982.49701,109.41500,    -2.11422,77.66618,50.00000,0.0000e+000,20.00000,-9.8497e-002,0.49215
984.26099,109.59500,    -2.10265,77.65851,50.00000,0.0000e+000,20.00000,-8.5848e-002,0.49154
986.04401,109.77500,    -2.10456,77.64743,50.00000,0.0000e+000,20.00000,-7.4646e-002,0.49093
987.84302,109.95500,    -2.10871,77.63649,50.00000,0.0000e+000,20.00000,-6.4427e-002,0.49030
989.65100,110.13500,    -2.11327,77.62236,50.00000,0.0000e+000,20.00000,-5.6211e-002,0.48967
991.45697,110.31500,    -2.11819,77.60912,50.00000,0.0000e+000,20.00000,-5.9216e-002,0.48905
993.27197,110.49500,    -2.12122,77.59584,50.00000,0.0000e+000,20.00000,-5.8194e-002,0.48842
995.15900,110.67500,    -2.13470,77.58805,50.00000,0.0000e+000,20.00000,-4.8260e-002,0.48776
997.01801,110.85500,    -2.14596,77.58209,50.00000,0.0000e+000,20.00000,-4.0259e-002,0.48711
998.49200,111.00000,    -2.14378,77.57547,50.00000,0.0000e+000,20.00000,    -0.13761,0.48660