File: book/some_content/TG_ExpDat_B30S70DC28.csv
#FILE:                       ,B30S70DC28; 13-2-2025.ngb-ds3
#FORMAT:                     ,NETZSCH5
#IDENTITY:                   ,geopolymer paste
#DECIMAL:                    ,POINT
#SEPARATOR:                  ,COMMA
#MTYPE:                      ,DSC
#INSTRUMENT:                 ,Microlab TU Delft
#PROJECT:                    ,
#DATE/TIME:                  ,13/02/2025 7:56:58 AM
#CORR. FILE:                 ,Blank with cover; 13-1-2025.ngb-bs3
#LABORATORY:                 ,TU Delft Micro Lab
#OPERATOR:                   ,Ahmed
#REMARK:                     ,under Argon atmosphere, 10K/min
#SAMPLE:                     ,B30S70DC28
#SAMPLE MASS /mg:            ,27
#MATERIAL:                   ,Geopolymer paste
#REFERENCE:                  ,blank
#REFERENCE MASS /mg:         ,0
#TYPE OF CRUCIBLE:           ,DSC/TG pan Al2O3
#SAMPLE CRUCIBLE MASS /mg:   ,0
#REFERENCE CRUCIBLE MASS /mg:,0
#CORR. CODE:                 ,020
#EXO:                        ,-1
#RANGE:                      ,40/10.0(K/min)/1000
#SEGMENT:                    ,S2/2

##Temp./øC,Time/min,DSC/(mW/mg),Mass/%,Gas Flow(purge1)/(ml/min),Gas Flow(purge2)/(ml/min),Gas Flow(protective)/(ml/min),DTG/(%/min),Sensit./(uV/mW)
 40.75100, 15.00000, 2.0399e-002,98.06296,50.00000,0.0000e+000,20.00000,     0.17538,1.22591
 40.77900, 15.17667, 2.0192e-002,98.06113,50.00000,0.0000e+000,20.00000,-2.2818e-002,1.22587
 40.81800, 15.35667, 1.9986e-002,98.05535,50.00000,0.0000e+000,20.00000,-4.4494e-002,1.22581
 40.88000, 15.53667, 1.9296e-002,98.04407,50.00000,0.0000e+000,20.00000,-4.7763e-002,1.22573
 40.98500, 15.71667, 1.8837e-002,98.03157,50.00000,0.0000e+000,20.00000,-4.7469e-002,1.22558
 41.16700, 15.89667, 1.8748e-002,98.02023,50.00000,0.0000e+000,20.00000,-4.9207e-002,1.22533
 41.38000, 16.07667, 1.8707e-002,98.01212,50.00000,0.0000e+000,20.00000,-4.6244e-002,1.22504
 41.67400, 16.25667, 1.9313e-002,98.00512,50.00000,0.0000e+000,20.00000,-4.5020e-002,1.22463
 42.04500, 16.43667, 1.9967e-002,97.99529,50.00000,0.0000e+000,20.00000,-4.5283e-002,1.22412
 42.47400, 16.61667, 2.0993e-002,97.98436,50.00000,0.0000e+000,20.00000,-4.4547e-002,1.22353
 43.01400, 16.79667, 2.1699e-002,97.97513,50.00000,0.0000e+000,20.00000,-4.4795e-002,1.22279
 43.62800, 16.97667, 2.3240e-002,97.96929,50.00000,0.0000e+000,20.00000,-4.7646e-002,1.22194
 44.35500, 17.15667, 2.5018e-002,97.96383,50.00000,0.0000e+000,20.00000,-5.0193e-002,1.22094
 45.12800, 17.33667, 2.6824e-002,97.95744,50.00000,0.0000e+000,20.00000,-5.1527e-002,1.21987
 45.98500, 17.51667, 2.8937e-002,97.95024,50.00000,0.0000e+000,20.00000,-5.2543e-002,1.21869
 46.93200, 17.69667, 3.0824e-002,97.94247,50.00000,0.0000e+000,20.00000,-5.4692e-002,1.21739
 47.97900, 17.87667, 3.2813e-002,97.93324,50.00000,0.0000e+000,20.00000,-5.7988e-002,1.21594
 49.10000, 18.05667, 3.4786e-002,97.92551,50.00000,0.0000e+000,20.00000,-6.1051e-002,1.21440
 50.31000, 18.23667, 3.6884e-002,97.91937,50.00000,0.0000e+000,20.00000,-6.3815e-002,1.21273
 51.57700, 18.41667, 3.8758e-002,97.91224,50.00000,0.0000e+000,20.00000,-6.7298e-002,1.21099
 52.94000, 18.59667, 4.0968e-002,97.90237,50.00000,0.0000e+000,20.00000,-7.1651e-002,1.20911
 54.38700, 18.77667, 4.2931e-002,97.88973,50.00000,0.0000e+000,20.00000,-7.7331e-002,1.20712
 55.91100, 18.95667, 4.5117e-002,97.87539,50.00000,0.0000e+000,20.00000,-8.3534e-002,1.20502
 57.51600, 19.13667, 4.6891e-002,97.86011,50.00000,0.0000e+000,20.00000,-9.1296e-002,1.20282
 59.16900, 19.31667, 4.9310e-002,97.84399,50.00000,0.0000e+000,20.00000,    -0.10146,1.20054
 60.91900, 19.49667, 5.0965e-002,97.82516,50.00000,0.0000e+000,20.00000,    -0.11216,1.19814
 62.72100, 19.67667, 5.3009e-002,97.80417,50.00000,0.0000e+000,20.00000,    -0.12240,1.19566
 64.61000, 19.85667, 5.5232e-002,97.78591,50.00000,0.0000e+000,20.00000,    -0.13451,1.19307
 66.50900, 20.03667, 5.7465e-002,97.76700,50.00000,0.0000e+000,20.00000,    -0.14747,1.19046
 68.50800, 20.21667, 5.9692e-002,97.74382,50.00000,0.0000e+000,20.00000,    -0.16014,1.18772
 70.54300, 20.39667, 6.2193e-002,97.71843,50.00000,0.0000e+000,20.00000,    -0.17372,1.18493
 72.64200, 20.57667, 6.4687e-002,97.69162,50.00000,0.0000e+000,20.00000,    -0.18831,1.18205
 74.76800, 20.75667, 6.7267e-002,97.66391,50.00000,0.0000e+000,20.00000,    -0.20332,1.17914
 76.95100, 20.93667, 7.0297e-002,97.63085,50.00000,0.0000e+000,20.00000,    -0.21901,1.17616
 79.16400, 21.11667, 7.3031e-002,97.58763,50.00000,0.0000e+000,20.00000,    -0.23570,1.17313
 81.42000, 21.29667, 7.6170e-002,97.54085,50.00000,0.0000e+000,20.00000,    -0.25246,1.17005
 83.73000, 21.47667, 7.9790e-002,97.49472,50.00000,0.0000e+000,20.00000,    -0.26917,1.16690
 86.08000, 21.65667, 8.3944e-002,97.44322,50.00000,0.0000e+000,20.00000,    -0.28670,1.16369
 88.43100, 21.83667, 8.7170e-002,97.38937,50.00000,0.0000e+000,20.00000,    -0.30306,1.16049
 90.84000, 22.01667, 9.1422e-002,97.33653,50.00000,0.0000e+000,20.00000,    -0.31761,1.15721
 93.26400, 22.19667, 9.5381e-002,97.27872,50.00000,0.0000e+000,20.00000,    -0.33189,1.15391
 95.71100, 22.37667, 9.9365e-002,97.21380,50.00000,0.0000e+000,20.00000,    -0.34644,1.15059
 98.17100, 22.55667,     0.10283,97.14534,50.00000,0.0000e+000,20.00000,    -0.36121,1.14725
100.60900, 22.73667,     0.10617,97.07339,50.00000,0.0000e+000,20.00000,    -0.37426,1.14395
103.09400, 22.91667,     0.10881,96.99709,50.00000,0.0000e+000,20.00000,    -0.38348,1.14058
105.55200, 23.09667,     0.11049,96.91787,50.00000,0.0000e+000,20.00000,    -0.39213,1.13726
108.02100, 23.27667,     0.11191,96.83620,50.00000,0.0000e+000,20.00000,    -0.40208,1.13393
110.50100, 23.45667,     0.11234,96.75315,50.00000,0.0000e+000,20.00000,    -0.40912,1.13059
112.95600, 23.63667,     0.11210,96.67419,50.00000,0.0000e+000,20.00000,    -0.41368,1.12728
115.39700, 23.81667,     0.11094,96.59833,50.00000,0.0000e+000,20.00000,    -0.41897,1.12400
117.85600, 23.99667,     0.10885,96.52141,50.00000,0.0000e+000,20.00000,    -0.42618,1.12070
120.32400, 24.17667,     0.10619,96.44190,50.00000,0.0000e+000,20.00000,    -0.43217,1.11739
122.77500, 24.35667,     0.10234,96.36057,50.00000,0.0000e+000,20.00000,    -0.43747,1.11411
125.21400, 24.53667, 9.8061e-002,96.28052,50.00000,0.0000e+000,20.00000,    -0.44181,1.11085
127.63100, 24.71667, 9.2709e-002,96.20455,50.00000,0.0000e+000,20.00000,    -0.44401,1.10762
130.06400, 24.89667, 8.7224e-002,96.12724,50.00000,0.0000e+000,20.00000,    -0.44343,1.10438
132.49001, 25.07667, 8.0705e-002,96.04473,50.00000,0.0000e+000,20.00000,    -0.44034,1.10115
134.88400, 25.25667, 7.4041e-002,95.96737,50.00000,0.0000e+000,20.00000,    -0.43551,1.09797
137.29201, 25.43667, 6.8037e-002,95.89609,50.00000,0.0000e+000,20.00000,    -0.43139,1.09478
139.66100, 25.61667, 6.2874e-002,95.82516,50.00000,0.0000e+000,20.00000,    -0.42705,1.09165
142.04100, 25.79667, 5.9655e-002,95.74357,50.00000,0.0000e+000,20.00000,    -0.42123,1.08850
144.35400, 25.97667, 5.8443e-002,95.65762,50.00000,0.0000e+000,20.00000,    -0.41398,1.08545
146.68500, 26.15667, 5.6834e-002,95.57060,50.00000,0.0000e+000,20.00000,    -0.40606,1.08238
149.00999, 26.33667, 5.4298e-002,95.48300,50.00000,0.0000e+000,20.00000,    -0.39744,1.07933
151.28300, 26.51667, 4.9565e-002,95.39866,50.00000,0.0000e+000,20.00000,    -0.38855,1.07634
153.54201, 26.69667, 4.0725e-002,95.32062,50.00000,0.0000e+000,20.00000,    -0.38019,1.07339
155.79201, 26.87667, 2.9143e-002,95.24980,50.00000,0.0000e+000,20.00000,    -0.37146,1.07044
157.99800, 27.05667, 1.5749e-002,95.18391,50.00000,0.0000e+000,20.00000,    -0.36211,1.06757
160.20100, 27.23667, 1.7251e-003,95.11889,50.00000,0.0000e+000,20.00000,    -0.35273,1.06470
162.37500, 27.41667,-1.2480e-002,95.05794,50.00000,0.0000e+000,20.00000,    -0.34327,1.06187
164.52600, 27.59667,-2.6894e-002,95.00196,50.00000,0.0000e+000,20.00000,    -0.33111,1.05908
166.67700, 27.77667,-4.0662e-002,94.94920,50.00000,0.0000e+000,20.00000,    -0.31688,1.05629
168.78500, 27.95667,-5.4204e-002,94.89677,50.00000,0.0000e+000,20.00000,    -0.30219,1.05357
170.88400, 28.13667,-6.7439e-002,94.84709,50.00000,0.0000e+000,20.00000,    -0.28718,1.05086
172.93401, 28.31667,-7.9901e-002,94.80236,50.00000,0.0000e+000,20.00000,    -0.27251,1.04822
174.99500, 28.49667,-9.3021e-002,94.75754,50.00000,0.0000e+000,20.00000,    -0.25883,1.04557
177.02400, 28.67667,    -0.10480,94.70705,50.00000,0.0000e+000,20.00000,    -0.24688,1.04297
179.06700, 28.85667,    -0.11644,94.66154,50.00000,0.0000e+000,20.00000,    -0.23685,1.04035
181.06599, 29.03667,    -0.12789,94.62302,50.00000,0.0000e+000,20.00000,    -0.22717,1.03780
183.07500, 29.21667,    -0.13858,94.58736,50.00000,0.0000e+000,20.00000,    -0.21691,1.03524
185.05200, 29.39667,    -0.14896,94.55180,50.00000,0.0000e+000,20.00000,    -0.20801,1.03272
187.01199, 29.57667,    -0.15933,94.51768,50.00000,0.0000e+000,20.00000,    -0.19969,1.03023
188.94800, 29.75667,    -0.16892,94.48462,50.00000,0.0000e+000,20.00000,    -0.19115,1.02777
190.86301, 29.93667,    -0.17841,94.45163,50.00000,0.0000e+000,20.00000,    -0.18168,1.02535
192.79601, 30.11667,    -0.18757,94.41983,50.00000,0.0000e+000,20.00000,    -0.17339,1.02291
194.68700, 30.29667,    -0.19626,94.39047,50.00000,0.0000e+000,20.00000,    -0.16685,1.02053
196.58400, 30.47667,    -0.20507,94.36214,50.00000,0.0000e+000,20.00000,    -0.15891,1.01814
198.44200, 30.65667,    -0.21341,94.33305,50.00000,0.0000e+000,20.00000,    -0.15170,1.01581
200.30701, 30.83667,    -0.22235,94.30246,50.00000,0.0000e+000,20.00000,    -0.14563,1.01347
202.14101, 31.01667,    -0.23102,94.27780,50.00000,0.0000e+000,20.00000,    -0.14037,1.01118
203.98801, 31.19667,    -0.23847,94.25357,50.00000,0.0000e+000,20.00000,    -0.13461,1.00887
205.81400, 31.37667,    -0.24667,94.23080,50.00000,0.0000e+000,20.00000,    -0.12928,1.00660
207.63699, 31.55667,    -0.25434,94.20901,50.00000,0.0000e+000,20.00000,    -0.12452,1.00433
209.44600, 31.73667,    -0.26247,94.19249,50.00000,0.0000e+000,20.00000,    -0.11933,1.00209
211.22200, 31.91667,    -0.27022,94.17785,50.00000,0.0000e+000,20.00000,    -0.11525,0.99989
213.02200, 32.09667,    -0.27805,94.15831,50.00000,0.0000e+000,20.00000,    -0.11203,0.99766
214.80800, 32.27667,    -0.28536,94.13716,50.00000,0.0000e+000,20.00000,    -0.10846,0.99546
216.57700, 32.45667,    -0.29256,94.11641,50.00000,0.0000e+000,20.00000,    -0.10519,0.99328
218.34700, 32.63667,    -0.30016,94.09892,50.00000,0.0000e+000,20.00000,    -0.10201,0.99111
220.12399, 32.81667,    -0.30748,94.08218,50.00000,0.0000e+000,20.00000,-9.9762e-002,0.98893
221.86800, 32.99667,    -0.31519,94.06734,50.00000,0.0000e+000,20.00000,-9.7296e-002,0.98680
223.62900, 33.17667,    -0.32247,94.05268,50.00000,0.0000e+000,20.00000,-9.6024e-002,0.98465
225.37900, 33.35667,    -0.32996,94.03688,50.00000,0.0000e+000,20.00000,-9.4461e-002,0.98252
227.13000, 33.53667,    -0.33788,94.02269,50.00000,0.0000e+000,20.00000,-9.3356e-002,0.98039
228.87100, 33.71667,    -0.34546,94.00617,50.00000,0.0000e+000,20.00000,-9.3537e-002,0.97828
230.61400, 33.89667,    -0.35283,93.98798,50.00000,0.0000e+000,20.00000,-9.2105e-002,0.97617
232.34900, 34.07667,    -0.35997,93.97228,50.00000,0.0000e+000,20.00000,-8.9604e-002,0.97408
234.09000, 34.25667,    -0.36729,93.95610,50.00000,0.0000e+000,20.00000,-8.7683e-002,0.97198
235.83800, 34.43667,    -0.37505,93.93692,50.00000,0.0000e+000,20.00000,-8.7060e-002,0.96988
237.56599, 34.61666,    -0.38295,93.91913,50.00000,0.0000e+000,20.00000,-8.5682e-002,0.96781
239.30299, 34.79667,    -0.39033,93.90416,50.00000,0.0000e+000,20.00000,-8.4564e-002,0.96573
241.02100, 34.97667,    -0.39825,93.88608,50.00000,0.0000e+000,20.00000,-8.3472e-002,0.96368
242.74800, 35.15667,    -0.40628,93.86912,50.00000,0.0000e+000,20.00000,-8.2843e-002,0.96162
244.47301, 35.33667,    -0.41368,93.85552,50.00000,0.0000e+000,20.00000,-8.3220e-002,0.95957
246.21100, 35.51667,    -0.42157,93.84083,50.00000,0.0000e+000,20.00000,-8.2620e-002,0.95751
247.94901, 35.69667,    -0.42910,93.82673,50.00000,0.0000e+000,20.00000,-8.1153e-002,0.95545
249.68500, 35.87667,    -0.43610,93.81485,50.00000,0.0000e+000,20.00000,-8.0486e-002,0.95340
251.40800, 36.05667,    -0.44312,93.80124,50.00000,0.0000e+000,20.00000,-8.0664e-002,0.95137
253.13200, 36.23667,    -0.45094,93.78555,50.00000,0.0000e+000,20.00000,-7.9505e-002,0.94934
254.85100, 36.41667,    -0.45899,93.77307,50.00000,0.0000e+000,20.00000,-7.7820e-002,0.94733
256.59900, 36.59667,    -0.46692,93.76220,50.00000,0.0000e+000,20.00000,-7.6596e-002,0.94528
258.33301, 36.77667,    -0.47463,93.75151,50.00000,0.0000e+000,20.00000,-7.4885e-002,0.94326
260.05499, 36.95667,    -0.48318,93.73891,50.00000,0.0000e+000,20.00000,-7.3700e-002,0.94126
261.81601, 37.13667,    -0.49031,93.72291,50.00000,0.0000e+000,20.00000,-7.2947e-002,0.93921
263.55899, 37.31667,    -0.49851,93.70902,50.00000,0.0000e+000,20.00000,-7.2183e-002,0.93719
265.29599, 37.49667,    -0.50656,93.69597,50.00000,0.0000e+000,20.00000,-7.1979e-002,0.93519
267.04599, 37.67667,    -0.51514,93.68271,50.00000,0.0000e+000,20.00000,-7.2939e-002,0.93317
268.78799, 37.85667,    -0.52316,93.66645,50.00000,0.0000e+000,20.00000,-7.3362e-002,0.93117
270.53601, 38.03667,    -0.53034,93.65141,50.00000,0.0000e+000,20.00000,-7.2558e-002,0.92916
272.27600, 38.21667,    -0.53779,93.63885,50.00000,0.0000e+000,20.00000,-7.2047e-002,0.92717
274.03601, 38.39667,    -0.54360,93.62819,50.00000,0.0000e+000,20.00000,-7.2410e-002,0.92516
275.77301, 38.57667,    -0.55159,93.61718,50.00000,0.0000e+000,20.00000,-7.3443e-002,0.92319
277.52701, 38.75667,    -0.55793,93.60404,50.00000,0.0000e+000,20.00000,-7.4330e-002,0.92120
279.26801, 38.93667,    -0.56494,93.59250,50.00000,0.0000e+000,20.00000,-7.4097e-002,0.91922
281.01700, 39.11666,    -0.57330,93.58135,50.00000,0.0000e+000,20.00000,-7.4119e-002,0.91725
282.75101, 39.29667,    -0.58055,93.56777,50.00000,0.0000e+000,20.00000,-7.4422e-002,0.91530
284.50101, 39.47667,    -0.58826,93.55257,50.00000,0.0000e+000,20.00000,-7.5465e-002,0.91333
286.26199, 39.65667,    -0.59524,93.53743,50.00000,0.0000e+000,20.00000,-7.5366e-002,0.91136
288.01199, 39.83667,    -0.60208,93.52457,50.00000,0.0000e+000,20.00000,-7.5379e-002,0.90940
289.76099, 40.01667,    -0.60967,93.51303,50.00000,0.0000e+000,20.00000,-7.6670e-002,0.90745
291.52100, 40.19667,    -0.61579,93.50138,50.00000,0.0000e+000,20.00000,-7.8227e-002,0.90550
293.26801, 40.37667,    -0.62305,93.48689,50.00000,0.0000e+000,20.00000,-7.9185e-002,0.90356
295.01901, 40.55667,    -0.62959,93.47190,50.00000,0.0000e+000,20.00000,-8.0227e-002,0.90163
296.77100, 40.73667,    -0.63550,93.45671,50.00000,0.0000e+000,20.00000,-8.1674e-002,0.89969
298.53000, 40.91667,    -0.64325,93.44224,50.00000,0.0000e+000,20.00000,-8.2889e-002,0.89776
300.28799, 41.09667,    -0.64839,93.42833,50.00000,0.0000e+000,20.00000,-8.3558e-002,0.89583
302.04001, 41.27667,    -0.65443,93.41163,50.00000,0.0000e+000,20.00000,-8.3923e-002,0.89392
303.79300, 41.45667,    -0.66023,93.39584,50.00000,0.0000e+000,20.00000,-8.4352e-002,0.89201
305.54700, 41.63667,    -0.66685,93.38053,50.00000,0.0000e+000,20.00000,-8.5737e-002,0.89010
307.31500, 41.81667,    -0.67322,93.36316,50.00000,0.0000e+000,20.00000,-8.7280e-002,0.88819
309.07101, 41.99667,    -0.67833,93.34614,50.00000,0.0000e+000,20.00000,-8.8990e-002,0.88629
310.84900, 42.17667,    -0.68459,93.33184,50.00000,0.0000e+000,20.00000,-9.0261e-002,0.88437
312.59799, 42.35667,    -0.69072,93.31561,50.00000,0.0000e+000,20.00000,-9.1517e-002,0.88249
314.37500, 42.53667,    -0.69684,93.29803,50.00000,0.0000e+000,20.00000,-9.2984e-002,0.88059
316.14401, 42.71667,    -0.70265,93.28262,50.00000,0.0000e+000,20.00000,-9.4295e-002,0.87870
317.89899, 42.89667,    -0.70862,93.26700,50.00000,0.0000e+000,20.00000,-9.5543e-002,0.87683
319.68500, 43.07667,    -0.71513,93.25074,50.00000,0.0000e+000,20.00000,-9.6503e-002,0.87494
321.44601, 43.25667,    -0.72132,93.23404,50.00000,0.0000e+000,20.00000,-9.8691e-002,0.87307
323.21899, 43.43667,    -0.72731,93.21581,50.00000,0.0000e+000,20.00000,    -0.10153,0.87120
324.99799, 43.61666,    -0.73301,93.19836,50.00000,0.0000e+000,20.00000,    -0.10366,0.86933
326.78400, 43.79667,    -0.73827,93.18087,50.00000,0.0000e+000,20.00000,    -0.10481,0.86746
328.56201, 43.97667,    -0.74341,93.16221,50.00000,0.0000e+000,20.00000,    -0.10659,0.86560
330.33499, 44.15667,    -0.74844,93.14279,50.00000,0.0000e+000,20.00000,    -0.10884,0.86375
332.08801, 44.33667,    -0.75373,93.12229,50.00000,0.0000e+000,20.00000,    -0.11132,0.86193
333.88199, 44.51667,    -0.75900,93.10259,50.00000,0.0000e+000,20.00000,    -0.11491,0.86007
335.64600, 44.69667,    -0.76433,93.08419,50.00000,0.0000e+000,20.00000,    -0.11879,0.85825
337.42200, 44.87667,    -0.76996,93.06486,50.00000,0.0000e+000,20.00000,    -0.12239,0.85642
339.19199, 45.05667,    -0.77536,93.04130,50.00000,0.0000e+000,20.00000,    -0.12599,0.85460
340.97601, 45.23667,    -0.78021,93.01581,50.00000,0.0000e+000,20.00000,    -0.12976,0.85278
342.75800, 45.41667,    -0.78503,92.99068,50.00000,0.0000e+000,20.00000,    -0.13461,0.85096
344.53400, 45.59667,    -0.78876,92.96861,50.00000,0.0000e+000,20.00000,    -0.13905,0.84915
346.29999, 45.77667,    -0.79386,92.94780,50.00000,0.0000e+000,20.00000,    -0.14275,0.84736
348.08899, 45.95667,    -0.79800,92.92439,50.00000,0.0000e+000,20.00000,    -0.14670,0.84556
349.85199, 46.13667,    -0.80239,92.89794,50.00000,0.0000e+000,20.00000,    -0.15102,0.84378
351.64700, 46.31667,    -0.80743,92.86945,50.00000,0.0000e+000,20.00000,    -0.15476,0.84198
353.42401, 46.49667,    -0.81115,92.83986,50.00000,0.0000e+000,20.00000,    -0.15898,0.84020
355.20499, 46.67667,    -0.81624,92.81032,50.00000,0.0000e+000,20.00000,    -0.16354,0.83843
356.98700, 46.85667,    -0.82094,92.78091,50.00000,0.0000e+000,20.00000,    -0.16693,0.83666
358.76901, 47.03667,    -0.82521,92.74943,50.00000,0.0000e+000,20.00000,    -0.16972,0.83489
360.55399, 47.21667,    -0.82967,92.71444,50.00000,0.0000e+000,20.00000,    -0.17216,0.83313
362.33099, 47.39667,    -0.83447,92.68029,50.00000,0.0000e+000,20.00000,    -0.17451,0.83138
364.12201, 47.57667,    -0.83910,92.64835,50.00000,0.0000e+000,20.00000,    -0.17764,0.82963
365.90100, 47.75667,    -0.84428,92.61502,50.00000,0.0000e+000,20.00000,    -0.18105,0.82789
367.68301, 47.93667,    -0.84865,92.57898,50.00000,0.0000e+000,20.00000,    -0.18393,0.82615
369.45499, 48.11666,    -0.85333,92.54484,50.00000,0.0000e+000,20.00000,    -0.18649,0.82443
371.23401, 48.29667,    -0.85787,92.51129,50.00000,0.0000e+000,20.00000,    -0.18857,0.82271
373.02701, 48.47667,    -0.86322,92.47575,50.00000,0.0000e+000,20.00000,    -0.19017,0.82098
374.80301, 48.65667,    -0.86881,92.44040,50.00000,0.0000e+000,20.00000,    -0.19132,0.81928
376.57700, 48.83667,    -0.87476,92.40486,50.00000,0.0000e+000,20.00000,    -0.19213,0.81758
378.37299, 49.01667,    -0.88151,92.37016,50.00000,0.0000e+000,20.00000,    -0.19195,0.81587
380.14999, 49.19667,    -0.88803,92.33865,50.00000,0.0000e+000,20.00000,    -0.19192,0.81418
381.92999, 49.37667,    -0.89432,92.30700,50.00000,0.0000e+000,20.00000,    -0.19263,0.81249
383.70200, 49.55667,    -0.90160,92.27197,50.00000,0.0000e+000,20.00000,    -0.19290,0.81082
385.49600, 49.73667,    -0.90830,92.23553,50.00000,0.0000e+000,20.00000,    -0.19216,0.80913
387.29700, 49.91667,    -0.91493,92.19806,50.00000,0.0000e+000,20.00000,    -0.19142,0.80744
389.06500, 50.09667,    -0.92283,92.16081,50.00000,0.0000e+000,20.00000,    -0.19030,0.80579
390.85001, 50.27667,    -0.93089,92.12498,50.00000,0.0000e+000,20.00000,    -0.18766,0.80413
392.63000, 50.45667,    -0.94006,92.09134,50.00000,0.0000e+000,20.00000,    -0.18544,0.80248
394.41699, 50.63667,    -0.94803,92.05743,50.00000,0.0000e+000,20.00000,    -0.18430,0.80083
396.20999, 50.81667,    -0.95724,92.02355,50.00000,0.0000e+000,20.00000,    -0.18302,0.79918
397.98099, 50.99667,    -0.96599,91.98916,50.00000,0.0000e+000,20.00000,    -0.18233,0.79755
399.78699, 51.17667,    -0.97516,91.95446,50.00000,0.0000e+000,20.00000,    -0.18194,0.79590
401.55600, 51.35667,    -0.98358,91.92041,50.00000,0.0000e+000,20.00000,    -0.18073,0.79429
403.36700, 51.53667,    -0.99261,91.88720,50.00000,0.0000e+000,20.00000,    -0.17871,0.79265
405.14499, 51.71667,    -1.00152,91.85498,50.00000,0.0000e+000,20.00000,    -0.17714,0.79104
406.93701, 51.89667,    -1.00965,91.82528,50.00000,0.0000e+000,20.00000,    -0.17596,0.78943
408.71899, 52.07667,    -1.01887,91.79912,50.00000,0.0000e+000,20.00000,    -0.17454,0.78783
410.53201, 52.25667,    -1.02712,91.77259,50.00000,0.0000e+000,20.00000,    -0.17408,0.78621
412.30701, 52.43667,    -1.03610,91.74149,50.00000,0.0000e+000,20.00000,    -0.17404,0.78463
414.09500, 52.61666,    -1.04365,91.71094,50.00000,0.0000e+000,20.00000,    -0.17346,0.78304
415.89200, 52.79667,    -1.05127,91.68135,50.00000,0.0000e+000,20.00000,    -0.17232,0.78145
417.69501, 52.97667,    -1.05960,91.65175,50.00000,0.0000e+000,20.00000,    -0.17077,0.77987
419.46201, 53.15667,    -1.06647,91.62142,50.00000,0.0000e+000,20.00000,    -0.16983,0.77832
421.25699, 53.33667,    -1.07321,91.59242,50.00000,0.0000e+000,20.00000,    -0.16951,0.77675
423.04001, 53.51667,    -1.08049,91.56153,50.00000,0.0000e+000,20.00000,    -0.16988,0.77520
424.82101, 53.69667,    -1.08747,91.52818,50.00000,0.0000e+000,20.00000,    -0.17041,0.77365
426.57401, 53.87667,    -1.09297,91.49705,50.00000,0.0000e+000,20.00000,    -0.17183,0.77214
428.37299, 54.05667,    -1.09884,91.46535,50.00000,0.0000e+000,20.00000,    -0.17245,0.77059
430.13599, 54.23667,    -1.10588,91.43158,50.00000,0.0000e+000,20.00000,    -0.17145,0.76908
431.89001, 54.41667,    -1.11268,91.39952,50.00000,0.0000e+000,20.00000,    -0.17196,0.76758
433.67401, 54.59667,    -1.12108,91.36911,50.00000,0.0000e+000,20.00000,    -0.17338,0.76606
435.46799, 54.77667,    -1.12945,91.34012,50.00000,0.0000e+000,20.00000,    -0.17497,0.76454
437.25400, 54.95667,    -1.13786,91.30962,50.00000,0.0000e+000,20.00000,    -0.17631,0.76303
439.03500, 55.13667,    -1.14622,91.27781,50.00000,0.0000e+000,20.00000,    -0.17732,0.76153
440.83801, 55.31667,    -1.15452,91.24394,50.00000,0.0000e+000,20.00000,    -0.17782,0.76002
442.63901, 55.49667,    -1.16128,91.21170,50.00000,0.0000e+000,20.00000,    -0.17834,0.75852
444.42401, 55.67667,    -1.16770,91.17963,50.00000,0.0000e+000,20.00000,    -0.17960,0.75704
446.22900, 55.85667,    -1.17356,91.15075,50.00000,0.0000e+000,20.00000,    -0.18052,0.75554
448.00900, 56.03667,    -1.17948,91.12408,50.00000,0.0000e+000,20.00000,    -0.18049,0.75408
449.80399, 56.21667,    -1.18581,91.09240,50.00000,0.0000e+000,20.00000,    -0.18091,0.75260
451.59601, 56.39667,    -1.19162,91.05739,50.00000,0.0000e+000,20.00000,    -0.18200,0.75114
453.38199, 56.57667,    -1.19872,91.02241,50.00000,0.0000e+000,20.00000,    -0.18450,0.74968
455.18900, 56.75667,    -1.20526,90.98683,50.00000,0.0000e+000,20.00000,    -0.18657,0.74821
456.97101, 56.93667,    -1.21311,90.95362,50.00000,0.0000e+000,20.00000,    -0.18794,0.74677
458.78299, 57.11666,    -1.22007,90.92169,50.00000,0.0000e+000,20.00000,    -0.18928,0.74531
460.56100, 57.29667,    -1.22598,90.88695,50.00000,0.0000e+000,20.00000,    -0.19071,0.74389
462.34399, 57.47667,    -1.23111,90.85067,50.00000,0.0000e+000,20.00000,    -0.19200,0.74247
464.13901, 57.65667,    -1.23615,90.81588,50.00000,0.0000e+000,20.00000,    -0.19525,0.74104
465.93201, 57.83667,    -1.24158,90.78216,50.00000,0.0000e+000,20.00000,    -0.19895,0.73962
467.70499, 58.01667,    -1.24719,90.74824,50.00000,0.0000e+000,20.00000,    -0.20137,0.73822
469.48700, 58.19667,    -1.25320,90.71399,50.00000,0.0000e+000,20.00000,    -0.20279,0.73682
471.28500, 58.37667,    -1.25944,90.67621,50.00000,0.0000e+000,20.00000,    -0.20452,0.73541
473.09698, 58.55667,    -1.26487,90.63804,50.00000,0.0000e+000,20.00000,    -0.20608,0.73400
474.87799, 58.73667,    -1.27234,90.60164,50.00000,0.0000e+000,20.00000,    -0.20884,0.73262
476.69800, 58.91667,    -1.27912,90.56323,50.00000,0.0000e+000,20.00000,    -0.21284,0.73121
478.50500, 59.09667,    -1.28492,90.52507,50.00000,0.0000e+000,20.00000,    -0.21533,0.72982
480.29999, 59.27667,    -1.28944,90.48867,50.00000,0.0000e+000,20.00000,    -0.21687,0.72845
482.09698, 59.45667,    -1.29421,90.44763,50.00000,0.0000e+000,20.00000,    -0.21897,0.72708
483.88101, 59.63667,    -1.29791,90.40719,50.00000,0.0000e+000,20.00000,    -0.22259,0.72572
485.66699, 59.81667,    -1.30127,90.36776,50.00000,0.0000e+000,20.00000,    -0.22605,0.72437
487.45300, 59.99667,    -1.30432,90.32768,50.00000,0.0000e+000,20.00000,    -0.22876,0.72302
489.23599, 60.17667,    -1.30877,90.28670,50.00000,0.0000e+000,20.00000,    -0.23081,0.72168
491.03000, 60.35667,    -1.31297,90.24532,50.00000,0.0000e+000,20.00000,    -0.23233,0.72034
492.79999, 60.53667,    -1.31880,90.20224,50.00000,0.0000e+000,20.00000,    -0.23358,0.71903
494.60199, 60.71667,    -1.32444,90.15572,50.00000,0.0000e+000,20.00000,    -0.23458,0.71769
496.39499, 60.89667,    -1.33020,90.11192,50.00000,0.0000e+000,20.00000,    -0.23621,0.71637
498.18399, 61.07667,    -1.33454,90.06992,50.00000,0.0000e+000,20.00000,    -0.23835,0.71505
499.97198, 61.25667,    -1.34067,90.02758,50.00000,0.0000e+000,20.00000,    -0.23960,0.71374
501.78101, 61.43667,    -1.34752,89.98108,50.00000,0.0000e+000,20.00000,    -0.24185,0.71243
503.58401, 61.61666,    -1.35369,89.93413,50.00000,0.0000e+000,20.00000,    -0.24416,0.71112
505.38199, 61.79667,    -1.35887,89.88998,50.00000,0.0000e+000,20.00000,    -0.24561,0.70982
507.18301, 61.97667,    -1.36303,89.84547,50.00000,0.0000e+000,20.00000,    -0.24640,0.70852
508.98599, 62.15667,    -1.36740,89.80111,50.00000,0.0000e+000,20.00000,    -0.24700,0.70723
510.77701, 62.33667,    -1.37184,89.75965,50.00000,0.0000e+000,20.00000,    -0.24806,0.70595
512.56598, 62.51667,    -1.37559,89.71854,50.00000,0.0000e+000,20.00000,    -0.24859,0.70468
514.35400, 62.69667,    -1.37983,89.67415,50.00000,0.0000e+000,20.00000,    -0.24934,0.70342
516.15302, 62.87667,    -1.38430,89.63002,50.00000,0.0000e+000,20.00000,    -0.25101,0.70215
517.92798, 63.05667,    -1.38974,89.58545,50.00000,0.0000e+000,20.00000,    -0.25324,0.70091
519.73102, 63.23667,    -1.39442,89.53693,50.00000,0.0000e+000,20.00000,    -0.25401,0.69965
521.52301, 63.41667,    -1.39958,89.48849,50.00000,0.0000e+000,20.00000,    -0.25370,0.69840
523.31201, 63.59667,    -1.40295,89.44303,50.00000,0.0000e+000,20.00000,    -0.25453,0.69716
525.10199, 63.77667,    -1.40727,89.39901,50.00000,0.0000e+000,20.00000,    -0.25586,0.69593
526.88898, 63.95667,    -1.41219,89.35571,50.00000,0.0000e+000,20.00000,    -0.25764,0.69470
528.67999, 64.13667,    -1.41746,89.30975,50.00000,0.0000e+000,20.00000,    -0.25951,0.69348
530.47699, 64.31667,    -1.42286,89.26157,50.00000,0.0000e+000,20.00000,    -0.26147,0.69226
532.27802, 64.49667,    -1.42729,89.21423,50.00000,0.0000e+000,20.00000,    -0.26283,0.69104
534.06702, 64.67667,    -1.43130,89.16651,50.00000,0.0000e+000,20.00000,    -0.26395,0.68983
535.87000, 64.85667,    -1.43595,89.11629,50.00000,0.0000e+000,20.00000,    -0.26533,0.68862
537.66199, 65.03667,    -1.44059,89.06720,50.00000,0.0000e+000,20.00000,    -0.26621,0.68742
539.44202, 65.21667,    -1.44555,89.02102,50.00000,0.0000e+000,20.00000,    -0.26723,0.68624
541.24500, 65.39667,    -1.45051,88.97367,50.00000,0.0000e+000,20.00000,    -0.26923,0.68504
543.05603, 65.57667,    -1.45478,88.92488,50.00000,0.0000e+000,20.00000,    -0.27114,0.68385
544.84198, 65.75667,    -1.45877,88.87388,50.00000,0.0000e+000,20.00000,    -0.27351,0.68267
546.64203, 65.93667,    -1.46444,88.82456,50.00000,0.0000e+000,20.00000,    -0.27544,0.68150
548.44702, 66.11667,    -1.46958,88.77690,50.00000,0.0000e+000,20.00000,    -0.27554,0.68032
550.24902, 66.29667,    -1.47611,88.72784,50.00000,0.0000e+000,20.00000,    -0.27560,0.67915
552.06201, 66.47667,    -1.47961,88.67935,50.00000,0.0000e+000,20.00000,    -0.27646,0.67798
553.85699, 66.65667,    -1.48226,88.63040,50.00000,0.0000e+000,20.00000,    -0.27753,0.67683
555.65399, 66.83667,    -1.48533,88.57946,50.00000,0.0000e+000,20.00000,    -0.27823,0.67568
557.44098, 67.01667,    -1.48888,88.52709,50.00000,0.0000e+000,20.00000,    -0.27903,0.67454
559.26501, 67.19666,    -1.49286,88.47387,50.00000,0.0000e+000,20.00000,    -0.27988,0.67338
561.07202, 67.37666,    -1.49725,88.42242,50.00000,0.0000e+000,20.00000,    -0.28168,0.67224
562.85901, 67.55666,    -1.50173,88.37088,50.00000,0.0000e+000,20.00000,    -0.28302,0.67112
564.68298, 67.73666,    -1.50564,88.31802,50.00000,0.0000e+000,20.00000,    -0.28288,0.66998
566.48700, 67.91666,    -1.50805,88.26914,50.00000,0.0000e+000,20.00000,    -0.28320,0.66885
568.28302, 68.09666,    -1.51094,88.22150,50.00000,0.0000e+000,20.00000,    -0.28427,0.66774
570.06702, 68.27666,    -1.51242,88.17154,50.00000,0.0000e+000,20.00000,    -0.28479,0.66664
571.86902, 68.45667,    -1.51350,88.11795,50.00000,0.0000e+000,20.00000,    -0.28402,0.66553
573.65698, 68.63667,    -1.51539,88.06525,50.00000,0.0000e+000,20.00000,    -0.28475,0.66444
575.45001, 68.81667,    -1.51955,88.01572,50.00000,0.0000e+000,20.00000,    -0.28630,0.66334
577.26501, 68.99667,    -1.52460,87.96602,50.00000,0.0000e+000,20.00000,    -0.28787,0.66224
579.03998, 69.17667,    -1.52972,87.91162,50.00000,0.0000e+000,20.00000,    -0.28899,0.66117
580.82800, 69.35667,    -1.53384,87.85552,50.00000,0.0000e+000,20.00000,    -0.29039,0.66009
582.64398, 69.53667,    -1.53886,87.80513,50.00000,0.0000e+000,20.00000,    -0.29095,0.65901
584.45398, 69.71667,    -1.54207,87.75703,50.00000,0.0000e+000,20.00000,    -0.29127,0.65793
586.25098, 69.89667,    -1.54522,87.70449,50.00000,0.0000e+000,20.00000,    -0.29239,0.65686
588.04999, 70.07667,    -1.54949,87.65306,50.00000,0.0000e+000,20.00000,    -0.29410,0.65580
589.85699, 70.25667,    -1.55339,87.60725,50.00000,0.0000e+000,20.00000,    -0.29532,0.65473
591.66998, 70.43667,    -1.55799,87.55528,50.00000,0.0000e+000,20.00000,    -0.29668,0.65367
593.46997, 70.61667,    -1.56248,87.49776,50.00000,0.0000e+000,20.00000,    -0.30012,0.65262
595.28003, 70.79667,    -1.56552,87.43869,50.00000,0.0000e+000,20.00000,    -0.30261,0.65157
597.08398, 70.97667,    -1.56660,87.38237,50.00000,0.0000e+000,20.00000,    -0.30308,0.65053
598.87500, 71.15667,    -1.56717,87.32631,50.00000,0.0000e+000,20.00000,    -0.30380,0.64950
600.65601, 71.33667,    -1.56994,87.27058,50.00000,0.0000e+000,20.00000,    -0.30519,0.64848
602.45300, 71.51667,    -1.57334,87.21951,50.00000,0.0000e+000,20.00000,    -0.30713,0.64745
604.25098, 71.69666,    -1.58025,87.16835,50.00000,0.0000e+000,20.00000,    -0.30933,0.64643
606.09302, 71.87666,    -1.58739,87.11325,50.00000,0.0000e+000,20.00000,    -0.31088,0.64539
607.89398, 72.05666,    -1.58976,87.05563,50.00000,0.0000e+000,20.00000,    -0.31470,0.64438
609.66901, 72.23666,    -1.58958,86.99794,50.00000,0.0000e+000,20.00000,    -0.31813,0.64338
611.46002, 72.41666,    -1.59078,86.93577,50.00000,0.0000e+000,20.00000,    -0.31894,0.64238
613.26599, 72.59666,    -1.59402,86.87638,50.00000,0.0000e+000,20.00000,    -0.31825,0.64138
615.05402, 72.77666,    -1.59820,86.82117,50.00000,0.0000e+000,20.00000,    -0.31795,0.64039
616.86700, 72.95667,    -1.60308,86.76261,50.00000,0.0000e+000,20.00000,    -0.31869,0.63939
618.67700, 73.13667,    -1.60810,86.70519,50.00000,0.0000e+000,20.00000,    -0.31975,0.63840
620.46698, 73.31667,    -1.61300,86.65095,50.00000,0.0000e+000,20.00000,    -0.32223,0.63742
622.29102, 73.49667,    -1.61596,86.59123,50.00000,0.0000e+000,20.00000,    -0.32356,0.63643
624.08600, 73.67667,    -1.61919,86.53308,50.00000,0.0000e+000,20.00000,    -0.32367,0.63546
625.88397, 73.85667,    -1.62349,86.47361,50.00000,0.0000e+000,20.00000,    -0.32341,0.63449
627.68201, 74.03667,    -1.62578,86.41064,50.00000,0.0000e+000,20.00000,    -0.32333,0.63352
629.48102, 74.21667,    -1.62977,86.34982,50.00000,0.0000e+000,20.00000,    -0.32174,0.63256
631.29602, 74.39667,    -1.63360,86.29303,50.00000,0.0000e+000,20.00000,    -0.32089,0.63160
633.09900, 74.57667,    -1.63787,86.23734,50.00000,0.0000e+000,20.00000,    -0.32310,0.63064
634.90302, 74.75667,    -1.64070,86.17933,50.00000,0.0000e+000,20.00000,    -0.32558,0.62969
636.68799, 74.93667,    -1.64364,86.11947,50.00000,0.0000e+000,20.00000,    -0.32557,0.62875
638.47998, 75.11667,    -1.64605,86.05846,50.00000,0.0000e+000,20.00000,    -0.32462,0.62781
640.29102, 75.29667,    -1.65272,86.00209,50.00000,0.0000e+000,20.00000,    -0.32219,0.62687
642.09802, 75.47667,    -1.65759,85.94746,50.00000,0.0000e+000,20.00000,    -0.32084,0.62593
643.90802, 75.65667,    -1.66436,85.89109,50.00000,0.0000e+000,20.00000,    -0.31959,0.62500
645.72803, 75.83667,    -1.66984,85.83391,50.00000,0.0000e+000,20.00000,    -0.31743,0.62407
647.53101, 76.01667,    -1.67227,85.77793,50.00000,0.0000e+000,20.00000,    -0.31585,0.62314
649.34998, 76.19666,    -1.67476,85.72123,50.00000,0.0000e+000,20.00000,    -0.31399,0.62222
651.17297, 76.37666,    -1.68149,85.65905,50.00000,0.0000e+000,20.00000,    -0.31148,0.62129
652.99402, 76.55666,    -1.68963,85.59162,50.00000,0.0000e+000,20.00000,    -0.30923,0.62037
654.82098, 76.73666,    -1.69547,85.53187,50.00000,0.0000e+000,20.00000,    -0.30642,0.61945
656.62500, 76.91666,    -1.69744,85.48059,50.00000,0.0000e+000,20.00000,    -0.30316,0.61855
658.41199, 77.09666,    -1.69843,85.43080,50.00000,0.0000e+000,20.00000,    -0.30147,0.61765
660.22400, 77.27666,    -1.70288,85.37755,50.00000,0.0000e+000,20.00000,    -0.29982,0.61675
662.04498, 77.45667,    -1.70964,85.32318,50.00000,0.0000e+000,20.00000,    -0.29626,0.61585
663.87000, 77.63667,    -1.71567,85.26864,50.00000,0.0000e+000,20.00000,    -0.29195,0.61495
665.67700, 77.81667,    -1.72068,85.21277,50.00000,0.0000e+000,20.00000,    -0.28877,0.61407
667.48700, 77.99667,    -1.72026,85.16115,50.00000,0.0000e+000,20.00000,    -0.28597,0.61318
669.21100, 78.17667,    -1.71200,85.11480,50.00000,0.0000e+000,20.00000,    -0.28149,0.61234
670.96301, 78.35667,    -1.71373,85.06580,50.00000,0.0000e+000,20.00000,    -0.27545,0.61150
672.80402, 78.53667,    -1.72673,85.01623,50.00000,0.0000e+000,20.00000,    -0.26998,0.61061
674.62201, 78.71667,    -1.73635,84.96730,50.00000,0.0000e+000,20.00000,    -0.26681,0.60973
676.42700, 78.89667,    -1.74289,84.91629,50.00000,0.0000e+000,20.00000,    -0.26424,0.60887
678.23999, 79.07667,    -1.74793,84.86721,50.00000,0.0000e+000,20.00000,    -0.26102,0.60800
680.04602, 79.25667,    -1.75375,84.82330,50.00000,0.0000e+000,20.00000,    -0.25745,0.60715
681.87201, 79.43667,    -1.75998,84.78200,50.00000,0.0000e+000,20.00000,    -0.25409,0.60628
683.69202, 79.61667,    -1.76396,84.73809,50.00000,0.0000e+000,20.00000,    -0.25042,0.60542
685.49597, 79.79667,    -1.76592,84.69177,50.00000,0.0000e+000,20.00000,    -0.24779,0.60458
687.27399, 79.97667,    -1.76690,84.64720,50.00000,0.0000e+000,20.00000,    -0.24672,0.60375
689.07001, 80.15667,    -1.76953,84.60170,50.00000,0.0000e+000,20.00000,    -0.24465,0.60291
690.84100, 80.33667,    -1.76993,84.55977,50.00000,0.0000e+000,20.00000,    -0.24310,0.60209
692.61102, 80.51667,    -1.77003,84.51918,50.00000,0.0000e+000,20.00000,    -0.24388,0.60127
694.40002, 80.69666,    -1.77467,84.47896,50.00000,0.0000e+000,20.00000,    -0.24394,0.60045
696.18701, 80.87666,    -1.78016,84.43822,50.00000,0.0000e+000,20.00000,    -0.24359,0.59963
698.00098, 81.05666,    -1.78640,84.39679,50.00000,0.0000e+000,20.00000,    -0.24493,0.59880
699.80902, 81.23666,    -1.79377,84.35491,50.00000,0.0000e+000,20.00000,    -0.24711,0.59798
701.64801, 81.41666,    -1.80015,84.31248,50.00000,0.0000e+000,20.00000,    -0.24839,0.59715
703.47400, 81.59666,    -1.80216,84.26947,50.00000,0.0000e+000,20.00000,    -0.24812,0.59632
705.26300, 81.77666,    -1.80061,84.22663,50.00000,0.0000e+000,20.00000,    -0.24858,0.59552
707.06799, 81.95667,    -1.79959,84.18548,50.00000,0.0000e+000,20.00000,    -0.24913,0.59471
708.88098, 82.13667,    -1.79904,84.14253,50.00000,0.0000e+000,20.00000,    -0.25047,0.59390
710.67200, 82.31667,    -1.79870,84.09162,50.00000,0.0000e+000,20.00000,    -0.25213,0.59311
712.48602, 82.49667,    -1.79990,84.04006,50.00000,0.0000e+000,20.00000,    -0.25200,0.59230
714.28802, 82.67667,    -1.80136,83.99156,50.00000,0.0000e+000,20.00000,    -0.24868,0.59151
716.07202, 82.85667,    -1.80294,83.94208,50.00000,0.0000e+000,20.00000,    -0.24137,0.59072
717.87598, 83.03667,    -1.80396,83.89273,50.00000,0.0000e+000,20.00000,    -0.23242,0.58993
719.67700, 83.21667,    -1.80589,83.84440,50.00000,0.0000e+000,20.00000,    -0.22423,0.58915
721.47699, 83.39667,    -1.81060,83.79878,50.00000,0.0000e+000,20.00000,    -0.21613,0.58836
723.27100, 83.57667,    -1.81636,83.75277,50.00000,0.0000e+000,20.00000,    -0.20839,0.58759
725.06299, 83.75667,    -1.82506,83.70522,50.00000,0.0000e+000,20.00000,    -0.19859,0.58681
726.85498, 83.93667,    -1.83156,83.65784,50.00000,0.0000e+000,20.00000,    -0.18857,0.58604
728.65601, 84.11667,    -1.84517,83.61075,50.00000,0.0000e+000,20.00000,    -0.17694,0.58527
730.43701, 84.29667,    -1.87619,83.56944,50.00000,0.0000e+000,20.00000,    -0.16466,0.58451
732.26099, 84.47667,    -1.91451,83.53912,50.00000,0.0000e+000,20.00000,    -0.15406,0.58373
734.05798, 84.65667,    -1.93441,83.52236,50.00000,0.0000e+000,20.00000,    -0.14235,0.58297
735.88898, 84.83667,    -1.95121,83.51360,50.00000,0.0000e+000,20.00000,    -0.13031,0.58220
737.71600, 85.01667,    -1.96108,83.50130,50.00000,0.0000e+000,20.00000,    -0.11906,0.58143
739.54498, 85.19666,    -1.97433,83.48853,50.00000,0.0000e+000,20.00000,    -0.10846,0.58066
741.39502, 85.37666,    -1.98671,83.47318,50.00000,0.0000e+000,20.00000,-9.8036e-002,0.57989
743.24597, 85.55666,    -1.99604,83.46633,50.00000,0.0000e+000,20.00000,-8.7145e-002,0.57912
745.06799, 85.73666,    -2.00119,83.46157,50.00000,0.0000e+000,20.00000,-7.6961e-002,0.57836
746.88599, 85.91666,    -2.00639,83.45390,50.00000,0.0000e+000,20.00000,-6.5737e-002,0.57761
748.75598, 86.09666,    -2.01833,83.44728,50.00000,0.0000e+000,20.00000,-5.6612e-002,0.57684
750.59802, 86.27666,    -2.02403,83.43729,50.00000,0.0000e+000,20.00000,-4.9385e-002,0.57608
752.39001, 86.45667,    -2.02293,83.43013,50.00000,0.0000e+000,20.00000,-4.3794e-002,0.57534
754.19501, 86.63667,    -2.02115,83.42502,50.00000,0.0000e+000,20.00000,-4.0883e-002,0.57461
755.95898, 86.81667,    -2.02195,83.41763,50.00000,0.0000e+000,20.00000,-4.0486e-002,0.57389
757.73102, 86.99667,    -2.02350,83.41033,50.00000,0.0000e+000,20.00000,-4.0630e-002,0.57317
759.52301, 87.17667,    -2.02952,83.40279,50.00000,0.0000e+000,20.00000,-3.8086e-002,0.57244
761.34802, 87.35667,    -2.04039,83.39533,50.00000,0.0000e+000,20.00000,-3.6800e-002,0.57171
763.15698, 87.53667,    -2.04873,83.38520,50.00000,0.0000e+000,20.00000,-3.7129e-002,0.57098
764.97900, 87.71667,    -2.05477,83.37853,50.00000,0.0000e+000,20.00000,-3.6692e-002,0.57025
766.76300, 87.89667,    -2.05730,83.36965,50.00000,0.0000e+000,20.00000,-3.6216e-002,0.56954
768.55402, 88.07667,    -2.05739,83.36282,50.00000,0.0000e+000,20.00000,-3.5439e-002,0.56882
770.32800, 88.25667,    -2.06039,83.36345,50.00000,0.0000e+000,20.00000,-3.4824e-002,0.56812
772.11401, 88.43667,    -2.06331,83.36606,50.00000,0.0000e+000,20.00000,-3.5005e-002,0.56741
773.86798, 88.61667,    -2.06708,83.35745,50.00000,0.0000e+000,20.00000,-3.4886e-002,0.56672
775.66101, 88.79667,    -2.07630,83.34380,50.00000,0.0000e+000,20.00000,-3.4398e-002,0.56601
777.46600, 88.97667,    -2.08610,83.33665,50.00000,0.0000e+000,20.00000,-3.4648e-002,0.56530
779.26599, 89.15667,    -2.09291,83.33296,50.00000,0.0000e+000,20.00000,-3.5666e-002,0.56460
781.07098, 89.33667,    -2.10349,83.32790,50.00000,0.0000e+000,20.00000,-3.5203e-002,0.56389
782.86499, 89.51667,    -2.11368,83.32163,50.00000,0.0000e+000,20.00000,-3.5019e-002,0.56319
784.67297, 89.69666,    -2.11742,83.31697,50.00000,0.0000e+000,20.00000,-3.5128e-002,0.56249
786.45300, 89.87666,    -2.12128,83.31034,50.00000,0.0000e+000,20.00000,-3.5632e-002,0.56180
788.26501, 90.05666,    -2.12876,83.30443,50.00000,0.0000e+000,20.00000,-3.7548e-002,0.56110
790.05298, 90.23666,    -2.13319,83.29896,50.00000,0.0000e+000,20.00000,-3.9739e-002,0.56041
791.85797, 90.41666,    -2.13801,83.29230,50.00000,0.0000e+000,20.00000,-3.9361e-002,0.55972
793.65100, 90.59666,    -2.14210,83.28657,50.00000,0.0000e+000,20.00000,-3.7374e-002,0.55903
795.45099, 90.77666,    -2.14939,83.27892,50.00000,0.0000e+000,20.00000,-3.6950e-002,0.55835
797.27899, 90.95667,    -2.16135,83.26783,50.00000,0.0000e+000,20.00000,-3.7537e-002,0.55765
799.14301, 91.13667,    -2.17577,83.25903,50.00000,0.0000e+000,20.00000,-3.8642e-002,0.55694
801.02301, 91.31667,    -2.18974,83.25261,50.00000,0.0000e+000,20.00000,-4.0217e-002,0.55623
802.85602, 91.49667,    -2.19542,83.24417,50.00000,0.0000e+000,20.00000,-4.2068e-002,0.55553
804.66498, 91.67667,    -2.19787,83.23464,50.00000,0.0000e+000,20.00000,-4.2300e-002,0.55485
806.46399, 91.85667,    -2.19841,83.22661,50.00000,0.0000e+000,20.00000,-4.2210e-002,0.55417
808.24298, 92.03667,    -2.20071,83.22157,50.00000,0.0000e+000,20.00000,-4.1850e-002,0.55351
810.03003, 92.21667,    -2.20736,83.21654,50.00000,0.0000e+000,20.00000,-4.2396e-002,0.55284
811.81299, 92.39667,    -2.21366,83.21010,50.00000,0.0000e+000,20.00000,-4.4219e-002,0.55217
813.58398, 92.57667,    -2.22246,83.20322,50.00000,0.0000e+000,20.00000,-4.5587e-002,0.55151
815.35797, 92.75667,    -2.23107,83.19732,50.00000,0.0000e+000,20.00000,-4.4577e-002,0.55085
817.15002, 92.93667,    -2.24235,83.18920,50.00000,0.0000e+000,20.00000,-4.4018e-002,0.55018
818.95697, 93.11667,    -2.25639,83.17751,50.00000,0.0000e+000,20.00000,-4.4787e-002,0.54951
820.77802, 93.29667,    -2.27162,83.16539,50.00000,0.0000e+000,20.00000,-4.5793e-002,0.54884
822.62201, 93.47667,    -2.28661,83.15777,50.00000,0.0000e+000,20.00000,-4.6288e-002,0.54816
824.43402, 93.65667,    -2.29620,83.15174,50.00000,0.0000e+000,20.00000,-4.5754e-002,0.54749
826.22601, 93.83667,    -2.30145,83.14764,50.00000,0.0000e+000,20.00000,-4.6270e-002,0.54683
828.03003, 94.01667,    -2.31013,83.14006,50.00000,0.0000e+000,20.00000,-4.7443e-002,0.54617
829.84198, 94.19666,    -2.32025,83.12782,50.00000,0.0000e+000,20.00000,-4.7694e-002,0.54551
831.65503, 94.37666,    -2.32898,83.11533,50.00000,0.0000e+000,20.00000,-4.7531e-002,0.54485
833.48199, 94.55666,    -2.33795,83.10750,50.00000,0.0000e+000,20.00000,-4.7695e-002,0.54418
835.31403, 94.73666,    -2.34690,83.10051,50.00000,0.0000e+000,20.00000,-4.7912e-002,0.54352
837.12000, 94.91666,    -2.35364,83.09158,50.00000,0.0000e+000,20.00000,-4.7257e-002,0.54286
838.91699, 95.09666,    -2.35694,83.08008,50.00000,0.0000e+000,20.00000,-4.7635e-002,0.54221
840.71198, 95.27666,    -2.35731,83.06837,50.00000,0.0000e+000,20.00000,-4.9278e-002,0.54156
842.49701, 95.45667,    -2.35756,83.06122,50.00000,0.0000e+000,20.00000,-5.0344e-002,0.54091
844.30402, 95.63667,    -2.36276,83.05451,50.00000,0.0000e+000,20.00000,-5.0652e-002,0.54026
846.09497, 95.81667,    -2.36757,83.04526,50.00000,0.0000e+000,20.00000,-5.0559e-002,0.53962
847.90399, 95.99667,    -2.37279,83.03794,50.00000,0.0000e+000,20.00000,-4.9539e-002,0.53897
849.68799, 96.17667,    -2.37534,83.03129,50.00000,0.0000e+000,20.00000,-4.8028e-002,0.53833
851.51300, 96.35667,    -2.37997,83.02517,50.00000,0.0000e+000,20.00000,-4.7941e-002,0.53767
853.31702, 96.53667,    -2.38361,83.01682,50.00000,0.0000e+000,20.00000,-4.8306e-002,0.53703
855.12402, 96.71667,    -2.38506,83.00834,50.00000,0.0000e+000,20.00000,-4.7816e-002,0.53638
856.91602, 96.89667,    -2.38669,82.99526,50.00000,0.0000e+000,20.00000,-4.7566e-002,0.53575
858.72699, 97.07667,    -2.38798,82.98062,50.00000,0.0000e+000,20.00000,-4.6310e-002,0.53510
860.50897, 97.25667,    -2.38584,82.96967,50.00000,0.0000e+000,20.00000,-4.5688e-002,0.53447
862.31897, 97.43667,    -2.38749,82.96398,50.00000,0.0000e+000,20.00000,-4.6513e-002,0.53383
864.11102, 97.61667,    -2.39002,82.95789,50.00000,0.0000e+000,20.00000,-4.6810e-002,0.53319
865.92902, 97.79667,    -2.39774,82.95003,50.00000,0.0000e+000,20.00000,-4.7053e-002,0.53255
867.75299, 97.97667,    -2.40877,82.94254,50.00000,0.0000e+000,20.00000,-4.7638e-002,0.53190
869.59399, 98.15667,    -2.41384,82.93464,50.00000,0.0000e+000,20.00000,-4.8795e-002,0.53125
871.40198, 98.33667,    -2.41483,82.92618,50.00000,0.0000e+000,20.00000,-4.8738e-002,0.53061
873.19501, 98.51667,    -2.41477,82.91963,50.00000,0.0000e+000,20.00000,-4.8383e-002,0.52998
874.99402, 98.69666,    -2.41403,82.90960,50.00000,0.0000e+000,20.00000,-4.7984e-002,0.52935
876.80499, 98.87666,    -2.41843,82.90157,50.00000,0.0000e+000,20.00000,-4.7492e-002,0.52871
878.60400, 99.05666,    -2.42319,82.89611,50.00000,0.0000e+000,20.00000,-4.7488e-002,0.52808
880.40997, 99.23666,    -2.42910,82.88742,50.00000,0.0000e+000,20.00000,-4.9060e-002,0.52745
882.23102, 99.41666,    -2.43499,82.87699,50.00000,0.0000e+000,20.00000,-5.1266e-002,0.52681
884.03900, 99.59666,    -2.44351,82.86820,50.00000,0.0000e+000,20.00000,-5.3805e-002,0.52618
885.84399, 99.77666,    -2.44735,82.85966,50.00000,0.0000e+000,20.00000,-5.5441e-002,0.52555
887.64001, 99.95667,    -2.44990,82.84935,50.00000,0.0000e+000,20.00000,-5.6751e-002,0.52492
889.45398,100.13667,    -2.45631,82.84106,50.00000,0.0000e+000,20.00000,-5.7700e-002,0.52429
891.25702,100.31667,    -2.45888,82.83411,50.00000,0.0000e+000,20.00000,-6.0189e-002,0.52366
893.04498,100.49667,    -2.46283,82.82422,50.00000,0.0000e+000,20.00000,-6.2481e-002,0.52304
894.84100,100.67667,    -2.46670,82.81100,50.00000,0.0000e+000,20.00000,-6.5253e-002,0.52241
896.63599,100.85667,    -2.47170,82.79915,50.00000,0.0000e+000,20.00000,-6.8277e-002,0.52179
898.45502,101.03667,    -2.48316,82.78736,50.00000,0.0000e+000,20.00000,-7.0611e-002,0.52116
900.26398,101.21667,    -2.48784,82.77396,50.00000,0.0000e+000,20.00000,-7.2763e-002,0.52053
902.07202,101.39667,    -2.48899,82.75709,50.00000,0.0000e+000,20.00000,-7.7225e-002,0.51990
903.88800,101.57667,    -2.49282,82.74296,50.00000,0.0000e+000,20.00000,-8.0596e-002,0.51927
905.69702,101.75667,    -2.49900,82.73034,50.00000,0.0000e+000,20.00000,-8.1708e-002,0.51865
907.51398,101.93667,    -2.49816,82.71848,50.00000,0.0000e+000,20.00000,-8.3738e-002,0.51802
909.29901,102.11667,    -2.49814,82.70335,50.00000,0.0000e+000,20.00000,-8.6296e-002,0.51740
911.08801,102.29667,    -2.49692,82.68573,50.00000,0.0000e+000,20.00000,-8.9152e-002,0.51678
912.89001,102.47667,    -2.49533,82.66677,50.00000,0.0000e+000,20.00000,-9.1809e-002,0.51616
914.68298,102.65667,    -2.49477,82.64994,50.00000,0.0000e+000,20.00000,-9.4688e-002,0.51554
916.45300,102.83667,    -2.49202,82.63352,50.00000,0.0000e+000,20.00000,-9.7832e-002,0.51493
918.25000,103.01667,    -2.48822,82.61573,50.00000,0.0000e+000,20.00000,    -0.10138,0.51431
920.04102,103.19666,    -2.48681,82.59124,50.00000,0.0000e+000,20.00000,    -0.10292,0.51369
921.82898,103.37666,    -2.48561,82.56896,50.00000,0.0000e+000,20.00000,    -0.10402,0.51307
923.62500,103.55666,    -2.48399,82.55454,50.00000,0.0000e+000,20.00000,    -0.10433,0.51245
925.42603,103.73666,    -2.48639,82.53858,50.00000,0.0000e+000,20.00000,    -0.10540,0.51183
927.26898,103.91666,    -2.49130,82.52247,50.00000,0.0000e+000,20.00000,    -0.10817,0.51120
929.07501,104.09666,    -2.48980,82.50343,50.00000,0.0000e+000,20.00000,    -0.11236,0.51057
930.84802,104.27666,    -2.47793,82.48110,50.00000,0.0000e+000,20.00000,    -0.11521,0.50996
932.64600,104.45667,    -2.47840,82.45808,50.00000,0.0000e+000,20.00000,    -0.11576,0.50934
934.49500,104.63667,    -2.48205,82.43554,50.00000,0.0000e+000,20.00000,    -0.11647,0.50871
936.28601,104.81667,    -2.47750,82.40950,50.00000,0.0000e+000,20.00000,    -0.11816,0.50809
938.12701,104.99667,    -2.47648,82.38665,50.00000,0.0000e+000,20.00000,    -0.11825,0.50746
939.98602,105.17667,    -2.47866,82.36732,50.00000,0.0000e+000,20.00000,    -0.11903,0.50682
941.82098,105.35667,    -2.47198,82.35275,50.00000,0.0000e+000,20.00000,    -0.12205,0.50618
943.63599,105.53667,    -2.46017,82.33821,50.00000,0.0000e+000,20.00000,    -0.12533,0.50556
945.43903,105.71667,    -2.44663,82.31484,50.00000,0.0000e+000,20.00000,    -0.12654,0.50494
947.26001,105.89667,    -2.43644,82.28311,50.00000,0.0000e+000,20.00000,    -0.12665,0.50431
949.16498,106.07667,    -2.44814,82.25225,50.00000,0.0000e+000,20.00000,    -0.12713,0.50366
951.05402,106.25667,    -2.45760,82.23190,50.00000,0.0000e+000,20.00000,    -0.12698,0.50301
952.87598,106.43667,    -2.44768,82.21370,50.00000,0.0000e+000,20.00000,    -0.12739,0.50238
954.68298,106.61667,    -2.43579,82.19045,50.00000,0.0000e+000,20.00000,    -0.12687,0.50176
956.44598,106.79667,    -2.42075,82.16698,50.00000,0.0000e+000,20.00000,    -0.12699,0.50115
958.19202,106.97667,    -2.40673,82.14069,50.00000,0.0000e+000,20.00000,    -0.12714,0.50055
959.93799,107.15667,    -2.40064,82.11464,50.00000,0.0000e+000,20.00000,    -0.12918,0.49995
961.69702,107.33667,    -2.40185,82.08708,50.00000,0.0000e+000,20.00000,    -0.13311,0.49934
963.43701,107.51667,    -2.39766,82.06507,50.00000,0.0000e+000,20.00000,    -0.13329,0.49874
965.21002,107.69666,    -2.40066,82.04702,50.00000,0.0000e+000,20.00000,    -0.12898,0.49813
966.95801,107.87666,    -2.40215,82.02366,50.00000,0.0000e+000,20.00000,    -0.12361,0.49753
968.75098,108.05666,    -2.40787,82.00078,50.00000,0.0000e+000,20.00000,    -0.12237,0.49691
970.55200,108.23666,    -2.41692,81.97733,50.00000,0.0000e+000,20.00000,    -0.12400,0.49628
972.34497,108.41666,    -2.42234,81.95347,50.00000,0.0000e+000,20.00000,    -0.12233,0.49567
974.14001,108.59666,    -2.42737,81.92913,50.00000,0.0000e+000,20.00000,    -0.12088,0.49505
975.94800,108.77666,    -2.43415,81.90843,50.00000,0.0000e+000,20.00000,    -0.11898,0.49442
977.83600,108.95667,    -2.45397,81.88643,50.00000,0.0000e+000,20.00000,    -0.11685,0.49377
979.67297,109.13667,    -2.46292,81.85873,50.00000,0.0000e+000,20.00000,    -0.11472,0.49313
981.47400,109.31667,    -2.45903,81.83451,50.00000,0.0000e+000,20.00000,    -0.11522,0.49251
983.24799,109.49667,    -2.45406,81.81906,50.00000,0.0000e+000,20.00000,    -0.11398,0.49189
985.04700,109.67667,    -2.45597,81.80631,50.00000,0.0000e+000,20.00000,    -0.11180,0.49127
986.84601,109.85667,    -2.46042,81.79073,50.00000,0.0000e+000,20.00000,    -0.10904,0.49065
988.63898,110.03667,    -2.46129,81.76690,50.00000,0.0000e+000,20.00000,    -0.10537,0.49003
990.44000,110.21667,    -2.46617,81.74930,50.00000,0.0000e+000,20.00000,    -0.10080,0.48940
992.24799,110.39667,    -2.46905,81.73192,50.00000,0.0000e+000,20.00000,    -0.10885,0.48877
994.06403,110.57667,    -2.47716,81.71276,50.00000,0.0000e+000,20.00000,    -0.10447,0.48814
995.87201,110.75667,    -2.48244,81.69431,50.00000,0.0000e+000,20.00000,    -0.10920,0.48751
997.68597,110.93667,    -2.48729,81.67537,50.00000,0.0000e+000,20.00000,    -0.12607,0.48688
998.28998,110.99667,    -2.48941,81.66667,50.00000,0.0000e+000,20.00000,    -0.21470,0.48667