File: book/some_content/TG_ExpDat_OPC9%DC7; 23-1-2025-2.csv
#FILE:                       ,OPC9%DC7; 23-1-2025.ngb-ds3
#FORMAT:                     ,NETZSCH5
#IDENTITY:                   ,GEOPOLYMER PASTE
#DECIMAL:                    ,POINT
#SEPARATOR:                  ,COMMA
#MTYPE:                      ,DSC
#INSTRUMENT:                 ,Microlab TU Delft
#PROJECT:                    ,
#DATE/TIME:                  ,24/01/2025 6:51:37 AM
#CORR. FILE:                 ,Blank with cover; 13-1-2025.ngb-bs3
#LABORATORY:                 ,TU Delft Micro Lab
#OPERATOR:                   ,Ahmed
#REMARK:                     ,under Argon atmosphere, 10K/min
#SAMPLE:                     ,OPC9%DC7
#SAMPLE MASS /mg:            ,25.2
#MATERIAL:                   ,Geopolymer paste
#REFERENCE:                  ,blank
#REFERENCE MASS /mg:         ,0
#TYPE OF CRUCIBLE:           ,DSC/TG pan Al2O3
#SAMPLE CRUCIBLE MASS /mg:   ,0
#REFERENCE CRUCIBLE MASS /mg:,0
#CORR. CODE:                 ,020
#EXO:                        ,-1
#RANGE:                      ,40/10.0(K/min)/1000
#SEGMENT:                    ,S2/2

##Temp./øC,Time/min,DSC/(mW/mg),Mass/%,Gas Flow(purge1)/(ml/min),Gas Flow(purge2)/(ml/min),Gas Flow(protective)/(ml/min),DTG/(%/min),Sensit./(uV/mW)
 40.56000, 15.00583, 5.5505e-002,97.13889,50.00000,0.0000e+000,20.00000,     0.18255,1.22617
 40.58100, 15.18583, 5.5284e-002,97.12894,50.00000,0.0000e+000,20.00000,-8.6319e-002,1.22614
 40.61500, 15.36583, 5.5089e-002,97.10854,50.00000,0.0000e+000,20.00000,    -0.12854,1.22609
 40.65800, 15.54583, 5.3981e-002,97.07912,50.00000,0.0000e+000,20.00000,    -0.14126,1.22603
 40.77000, 15.72583, 5.3172e-002,97.04717,50.00000,0.0000e+000,20.00000,    -0.13773,1.22588
 40.92400, 15.90583, 5.3182e-002,97.01627,50.00000,0.0000e+000,20.00000,    -0.14242,1.22567
 41.12300, 16.08583, 5.2872e-002,96.98730,50.00000,0.0000e+000,20.00000,    -0.14425,1.22539
 41.41700, 16.26583, 5.2692e-002,96.96690,50.00000,0.0000e+000,20.00000,    -0.14399,1.22499
 41.77200, 16.44583, 5.3208e-002,96.94148,50.00000,0.0000e+000,20.00000,    -0.14452,1.22450
 42.21100, 16.62583, 5.3927e-002,96.91286,50.00000,0.0000e+000,20.00000,    -0.14866,1.22389
 42.71200, 16.80583, 5.4947e-002,96.88346,50.00000,0.0000e+000,20.00000,    -0.15325,1.22320
 43.32800, 16.98583, 5.6199e-002,96.85418,50.00000,0.0000e+000,20.00000,    -0.15989,1.22235
 44.00300, 17.16583, 5.7828e-002,96.82831,50.00000,0.0000e+000,20.00000,    -0.16508,1.22142
 44.76100, 17.34583, 5.9862e-002,96.80475,50.00000,0.0000e+000,20.00000,    -0.16832,1.22038
 45.63400, 17.52583, 6.1734e-002,96.77696,50.00000,0.0000e+000,20.00000,    -0.17221,1.21918
 46.54000, 17.70583, 6.4507e-002,96.74962,50.00000,0.0000e+000,20.00000,    -0.17804,1.21793
 47.57900, 17.88583, 6.6748e-002,96.72365,50.00000,0.0000e+000,20.00000,    -0.18363,1.21650
 48.66900, 18.06583, 6.9397e-002,96.69418,50.00000,0.0000e+000,20.00000,    -0.19180,1.21499
 49.86400, 18.24583, 7.2136e-002,96.65810,50.00000,0.0000e+000,20.00000,    -0.20228,1.21335
 51.12200, 18.42583, 7.5138e-002,96.62354,50.00000,0.0000e+000,20.00000,    -0.21355,1.21162
 52.45000, 18.60583, 7.8179e-002,96.58807,50.00000,0.0000e+000,20.00000,    -0.22414,1.20979
 53.90600, 18.78583, 8.2019e-002,96.55270,50.00000,0.0000e+000,20.00000,    -0.23538,1.20778
 55.41300, 18.96583, 8.5399e-002,96.51479,50.00000,0.0000e+000,20.00000,    -0.24955,1.20571
 56.98100, 19.14583, 8.9124e-002,96.47513,50.00000,0.0000e+000,20.00000,    -0.26536,1.20355
 58.63300, 19.32583, 9.2796e-002,96.43024,50.00000,0.0000e+000,20.00000,    -0.28179,1.20128
 60.33200, 19.50583, 9.6714e-002,96.37824,50.00000,0.0000e+000,20.00000,    -0.30110,1.19895
 62.14300, 19.68583,     0.10061,96.32747,50.00000,0.0000e+000,20.00000,    -0.32307,1.19646
 64.00700, 19.86583,     0.10524,96.27732,50.00000,0.0000e+000,20.00000,    -0.34774,1.19390
 65.92500, 20.04583,     0.10938,96.21683,50.00000,0.0000e+000,20.00000,    -0.36992,1.19126
 67.90700, 20.22583,     0.11427,96.14728,50.00000,0.0000e+000,20.00000,    -0.39203,1.18854
 69.92400, 20.40583,     0.11959,96.07917,50.00000,0.0000e+000,20.00000,    -0.41744,1.18578
 72.03100, 20.58583,     0.12488,96.00948,50.00000,0.0000e+000,20.00000,    -0.44517,1.18289
 74.13800, 20.76583,     0.13021,95.93218,50.00000,0.0000e+000,20.00000,    -0.47035,1.18001
 76.32500, 20.94583,     0.13584,95.85120,50.00000,0.0000e+000,20.00000,    -0.49753,1.17701
 78.55600, 21.12583,     0.14181,95.76556,50.00000,0.0000e+000,20.00000,    -0.52258,1.17396
 80.79600, 21.30583,     0.14712,95.66860,50.00000,0.0000e+000,20.00000,    -0.54566,1.17090
 83.10500, 21.48583,     0.15338,95.56392,50.00000,0.0000e+000,20.00000,    -0.57076,1.16775
 85.46700, 21.66583,     0.15934,95.44671,50.00000,0.0000e+000,20.00000,    -0.59569,1.16453
 87.82900, 21.84583,     0.16531,95.32885,50.00000,0.0000e+000,20.00000,    -0.61362,1.16131
 90.22700, 22.02583,     0.17221,95.21426,50.00000,0.0000e+000,20.00000,    -0.62627,1.15804
 92.67600, 22.20583,     0.17884,95.08836,50.00000,0.0000e+000,20.00000,    -0.65033,1.15471
 95.12500, 22.38583,     0.18506,94.95153,50.00000,0.0000e+000,20.00000,    -0.66532,1.15139
 97.59700, 22.56583,     0.19159,94.82162,50.00000,0.0000e+000,20.00000,    -0.67080,1.14803
100.07600, 22.74583,     0.19662,94.68443,50.00000,0.0000e+000,20.00000,    -0.67757,1.14467
102.56000, 22.92583,     0.20020,94.54785,50.00000,0.0000e+000,20.00000,    -0.68154,1.14131
105.06000, 23.10583,     0.20162,94.41315,50.00000,0.0000e+000,20.00000,    -0.68814,1.13793
107.54000, 23.28583,     0.20043,94.27102,50.00000,0.0000e+000,20.00000,    -0.69560,1.13458
110.03500, 23.46583,     0.19703,94.12882,50.00000,0.0000e+000,20.00000,    -0.69217,1.13121
112.52000, 23.64583,     0.19166,94.00150,50.00000,0.0000e+000,20.00000,    -0.68529,1.12787
115.01100, 23.82583,     0.18480,93.88868,50.00000,0.0000e+000,20.00000,    -0.67967,1.12452
117.49200, 24.00583,     0.17555,93.73722,50.00000,0.0000e+000,20.00000,    -0.67140,1.12118
119.97700, 24.18583,     0.16632,93.60346,50.00000,0.0000e+000,20.00000,    -0.66032,1.11785
122.44800, 24.36583,     0.15557,93.50866,50.00000,0.0000e+000,20.00000,    -0.65167,1.11454
124.92200, 24.54583,     0.14478,93.40238,50.00000,0.0000e+000,20.00000,    -0.64151,1.11124
127.39100, 24.72583,     0.13289,93.30426,50.00000,0.0000e+000,20.00000,    -0.62795,1.10794
129.86000, 24.90583,     0.12070,93.18870,50.00000,0.0000e+000,20.00000,    -0.61251,1.10465
132.30099, 25.08583,     0.10869,93.05689,50.00000,0.0000e+000,20.00000,    -0.59520,1.10140
134.72200, 25.26583, 9.6407e-002,92.94944,50.00000,0.0000e+000,20.00000,    -0.58044,1.09819
137.14600, 25.44583, 8.4275e-002,92.85615,50.00000,0.0000e+000,20.00000,    -0.56695,1.09497
139.52699, 25.62583, 7.2290e-002,92.76217,50.00000,0.0000e+000,20.00000,    -0.55684,1.09182
141.92799, 25.80583, 6.0709e-002,92.66902,50.00000,0.0000e+000,20.00000,    -0.53683,1.08865
144.28900, 25.98583, 4.9142e-002,92.57368,50.00000,0.0000e+000,20.00000,    -0.51474,1.08554
146.62500, 26.16583, 3.7786e-002,92.47473,50.00000,0.0000e+000,20.00000,    -0.50516,1.08246
148.90500, 26.34583, 2.5831e-002,92.37595,50.00000,0.0000e+000,20.00000,    -0.49250,1.07946
151.21400, 26.52583, 1.3500e-002,92.28545,50.00000,0.0000e+000,20.00000,    -0.48214,1.07643
153.48900, 26.70583, 9.3072e-004,92.20699,50.00000,0.0000e+000,20.00000,    -0.46926,1.07345
155.72301, 26.88583,-1.2330e-002,92.13037,50.00000,0.0000e+000,20.00000,    -0.45100,1.07053
157.96600, 27.06583,-2.5692e-002,92.04206,50.00000,0.0000e+000,20.00000,    -0.43645,1.06761
160.16600, 27.24583,-3.9581e-002,91.95883,50.00000,0.0000e+000,20.00000,    -0.42585,1.06474
162.35001, 27.42583,-5.3799e-002,91.88336,50.00000,0.0000e+000,20.00000,    -0.41306,1.06190
164.50101, 27.60583,-6.7634e-002,91.81059,50.00000,0.0000e+000,20.00000,    -0.40132,1.05911
166.65500, 27.78583,-8.1398e-002,91.74728,50.00000,0.0000e+000,20.00000,    -0.39012,1.05632
168.76100, 27.96583,-9.4912e-002,91.68686,50.00000,0.0000e+000,20.00000,    -0.37666,1.05360
170.86800, 28.14583,    -0.10873,91.62712,50.00000,0.0000e+000,20.00000,    -0.36047,1.05088
172.94299, 28.32583,    -0.12217,91.56682,50.00000,0.0000e+000,20.00000,    -0.34737,1.04821
174.99600, 28.50583,    -0.13482,91.50306,50.00000,0.0000e+000,20.00000,    -0.33682,1.04557
177.03600, 28.68583,    -0.14755,91.43747,50.00000,0.0000e+000,20.00000,    -0.32685,1.04295
179.07201, 28.86583,    -0.15947,91.37764,50.00000,0.0000e+000,20.00000,    -0.31341,1.04035
181.07401, 29.04583,    -0.17142,91.32182,50.00000,0.0000e+000,20.00000,    -0.30129,1.03779
183.07201, 29.22583,    -0.18360,91.27393,50.00000,0.0000e+000,20.00000,    -0.29115,1.03524
185.06400, 29.40583,    -0.19481,91.22441,50.00000,0.0000e+000,20.00000,    -0.28190,1.03270
187.02299, 29.58583,    -0.20612,91.17100,50.00000,0.0000e+000,20.00000,    -0.27325,1.03022
188.97800, 29.76583,    -0.21684,91.11988,50.00000,0.0000e+000,20.00000,    -0.26404,1.02774
190.90199, 29.94583,    -0.22734,91.07964,50.00000,0.0000e+000,20.00000,    -0.25612,1.02530
192.82001, 30.12583,    -0.23859,91.03544,50.00000,0.0000e+000,20.00000,    -0.24997,1.02288
194.73100, 30.30583,    -0.24909,90.99370,50.00000,0.0000e+000,20.00000,    -0.24223,1.02047
196.60100, 30.48583,    -0.25999,90.95371,50.00000,0.0000e+000,20.00000,    -0.23054,1.01812
198.49400, 30.66583,    -0.26984,90.91652,50.00000,0.0000e+000,20.00000,    -0.21805,1.01574
200.34700, 30.84583,    -0.28070,90.87550,50.00000,0.0000e+000,20.00000,    -0.20868,1.01342
202.20799, 31.02583,    -0.29144,90.83673,50.00000,0.0000e+000,20.00000,    -0.20284,1.01109
204.02800, 31.20583,    -0.30176,90.79678,50.00000,0.0000e+000,20.00000,    -0.19660,1.00882
205.87399, 31.38583,    -0.31228,90.76210,50.00000,0.0000e+000,20.00000,    -0.18839,1.00652
207.67799, 31.56583,    -0.32323,90.73522,50.00000,0.0000e+000,20.00000,    -0.17754,1.00428
209.49200, 31.74583,    -0.33429,90.70534,50.00000,0.0000e+000,20.00000,    -0.17058,1.00203
211.28900, 31.92583,    -0.34481,90.66839,50.00000,0.0000e+000,20.00000,    -0.16918,0.99980
213.08400, 32.10583,    -0.35520,90.63246,50.00000,0.0000e+000,20.00000,    -0.16668,0.99759
214.86200, 32.28583,    -0.36575,90.60722,50.00000,0.0000e+000,20.00000,    -0.16241,0.99539
216.63100, 32.46583,    -0.37572,90.59210,50.00000,0.0000e+000,20.00000,    -0.15761,0.99322
218.40800, 32.64583,    -0.38688,90.57111,50.00000,0.0000e+000,20.00000,    -0.15050,0.99104
220.16100, 32.82583,    -0.39751,90.54385,50.00000,0.0000e+000,20.00000,    -0.14493,0.98889
221.91200, 33.00583,    -0.40850,90.51761,50.00000,0.0000e+000,20.00000,    -0.14014,0.98675
223.65300, 33.18583,    -0.41931,90.49367,50.00000,0.0000e+000,20.00000,    -0.13672,0.98462
225.41400, 33.36583,    -0.43031,90.47942,50.00000,0.0000e+000,20.00000,    -0.13540,0.98248
227.14101, 33.54583,    -0.44148,90.46621,50.00000,0.0000e+000,20.00000,    -0.13385,0.98038
228.89000, 33.72583,    -0.45287,90.43026,50.00000,0.0000e+000,20.00000,    -0.12968,0.97826
230.62700, 33.90583,    -0.46373,90.39494,50.00000,0.0000e+000,20.00000,    -0.12516,0.97616
232.36200, 34.08583,    -0.47434,90.36937,50.00000,0.0000e+000,20.00000,    -0.12337,0.97406
234.09700, 34.26583,    -0.48504,90.34901,50.00000,0.0000e+000,20.00000,    -0.12330,0.97197
235.83200, 34.44584,    -0.49604,90.33389,50.00000,0.0000e+000,20.00000,    -0.12253,0.96989
237.55400, 34.62583,    -0.50667,90.31616,50.00000,0.0000e+000,20.00000,    -0.12034,0.96782
239.27200, 34.80583,    -0.51794,90.29421,50.00000,0.0000e+000,20.00000,    -0.11777,0.96576
241.01700, 34.98583,    -0.52908,90.27045,50.00000,0.0000e+000,20.00000,    -0.11558,0.96368
242.73900, 35.16583,    -0.54004,90.24801,50.00000,0.0000e+000,20.00000,    -0.11894,0.96163
244.47000, 35.34583,    -0.55060,90.22450,50.00000,0.0000e+000,20.00000,    -0.12034,0.95957
246.19400, 35.52583,    -0.56164,90.20344,50.00000,0.0000e+000,20.00000,    -0.11212,0.95753
247.91800, 35.70583,    -0.57136,90.18308,50.00000,0.0000e+000,20.00000,    -0.10414,0.95549
249.64700, 35.88583,    -0.58138,90.16237,50.00000,0.0000e+000,20.00000,    -0.10237,0.95344
251.38400, 36.06583,    -0.59186,90.14575,50.00000,0.0000e+000,20.00000,    -0.10372,0.95140
253.11700, 36.24583,    -0.60202,90.13007,50.00000,0.0000e+000,20.00000,    -0.10531,0.94936
254.84399, 36.42583,    -0.61194,90.11092,50.00000,0.0000e+000,20.00000,    -0.10424,0.94734
256.59000, 36.60583,    -0.62200,90.09352,50.00000,0.0000e+000,20.00000,    -0.10097,0.94530
258.31400, 36.78583,    -0.63161,90.07762,50.00000,0.0000e+000,20.00000,-9.9278e-002,0.94328
260.06400, 36.96583,    -0.64144,90.05068,50.00000,0.0000e+000,20.00000,-9.8638e-002,0.94125
261.78101, 37.14583,    -0.65021,90.03057,50.00000,0.0000e+000,20.00000,-9.7690e-002,0.93925
263.53101, 37.32583,    -0.65950,90.02729,50.00000,0.0000e+000,20.00000,-9.5230e-002,0.93723
265.26300, 37.50583,    -0.66884,90.02085,50.00000,0.0000e+000,20.00000,-9.1156e-002,0.93522
266.99899, 37.68583,    -0.67774,90.00245,50.00000,0.0000e+000,20.00000,-9.0215e-002,0.93322
268.73499, 37.86583,    -0.68622,89.97665,50.00000,0.0000e+000,20.00000,-9.2956e-002,0.93123
270.46201, 38.04583,    -0.69543,89.95386,50.00000,0.0000e+000,20.00000,-9.5105e-002,0.92925
272.20300, 38.22583,    -0.70466,89.93980,50.00000,0.0000e+000,20.00000,-9.3511e-002,0.92725
273.93301, 38.40583,    -0.71477,89.93045,50.00000,0.0000e+000,20.00000,-8.9861e-002,0.92528
275.68100, 38.58583,    -0.72576,89.91433,50.00000,0.0000e+000,20.00000,-8.9243e-002,0.92329
277.42499, 38.76583,    -0.73658,89.89397,50.00000,0.0000e+000,20.00000,-8.8169e-002,0.92131
279.19400, 38.94584,    -0.74678,89.87387,50.00000,0.0000e+000,20.00000,-8.8465e-002,0.91931
280.95700, 39.12583,    -0.75702,89.85953,50.00000,0.0000e+000,20.00000,-9.3940e-002,0.91732
282.71100, 39.30583,    -0.76553,89.85418,50.00000,0.0000e+000,20.00000,-9.7796e-002,0.91534
284.48099, 39.48583,    -0.77280,89.83960,50.00000,0.0000e+000,20.00000,-9.8405e-002,0.91335
286.24399, 39.66583,    -0.78066,89.81213,50.00000,0.0000e+000,20.00000,-9.6960e-002,0.91138
287.98199, 39.84583,    -0.78825,89.78832,50.00000,0.0000e+000,20.00000,-9.6256e-002,0.90944
289.75299, 40.02583,    -0.79540,89.77311,50.00000,0.0000e+000,20.00000,-9.7720e-002,0.90746
291.49799, 40.20583,    -0.80372,89.76841,50.00000,0.0000e+000,20.00000,-9.9024e-002,0.90552
293.25900, 40.38583,    -0.81243,89.75711,50.00000,0.0000e+000,20.00000,    -0.10026,0.90357
295.01300, 40.56583,    -0.82160,89.73645,50.00000,0.0000e+000,20.00000,    -0.10165,0.90163
296.77600, 40.74583,    -0.83013,89.71279,50.00000,0.0000e+000,20.00000,    -0.10285,0.89969
298.53699, 40.92583,    -0.83823,89.68756,50.00000,0.0000e+000,20.00000,    -0.10512,0.89775
300.28699, 41.10583,    -0.84550,89.66788,50.00000,0.0000e+000,20.00000,    -0.10779,0.89584
302.03299, 41.28583,    -0.85316,89.64927,50.00000,0.0000e+000,20.00000,    -0.10886,0.89393
303.78699, 41.46583,    -0.86025,89.62932,50.00000,0.0000e+000,20.00000,    -0.10899,0.89202
305.56201, 41.64583,    -0.86810,89.60847,50.00000,0.0000e+000,20.00000,    -0.10963,0.89009
307.31799, 41.82583,    -0.87654,89.58693,50.00000,0.0000e+000,20.00000,    -0.11352,0.88818
309.08401, 42.00583,    -0.88359,89.57220,50.00000,0.0000e+000,20.00000,    -0.12108,0.88627
310.83600, 42.18583,    -0.89133,89.55462,50.00000,0.0000e+000,20.00000,    -0.12440,0.88439
312.60699, 42.36583,    -0.89898,89.52915,50.00000,0.0000e+000,20.00000,    -0.12502,0.88248
314.37900, 42.54583,    -0.90762,89.50497,50.00000,0.0000e+000,20.00000,    -0.12811,0.88059
316.15500, 42.72583,    -0.91558,89.47988,50.00000,0.0000e+000,20.00000,    -0.12952,0.87869
317.91501, 42.90583,    -0.92423,89.46302,50.00000,0.0000e+000,20.00000,    -0.13100,0.87682
319.69901, 43.08583,    -0.93305,89.44840,50.00000,0.0000e+000,20.00000,    -0.13476,0.87492
321.47699, 43.26583,    -0.94099,89.42231,50.00000,0.0000e+000,20.00000,    -0.14053,0.87304
323.25601, 43.44584,    -0.94844,89.39505,50.00000,0.0000e+000,20.00000,    -0.14511,0.87116
325.02600, 43.62583,    -0.95573,89.36490,50.00000,0.0000e+000,20.00000,    -0.14825,0.86930
326.82300, 43.80583,    -0.96200,89.33096,50.00000,0.0000e+000,20.00000,    -0.15388,0.86741
328.60101, 43.98583,    -0.96816,89.30771,50.00000,0.0000e+000,20.00000,    -0.16032,0.86556
330.36401, 44.16583,    -0.97362,89.28720,50.00000,0.0000e+000,20.00000,    -0.16610,0.86372
332.15601, 44.34583,    -0.98008,89.25385,50.00000,0.0000e+000,20.00000,    -0.17151,0.86186
333.93900, 44.52583,    -0.98574,89.22182,50.00000,0.0000e+000,20.00000,    -0.17444,0.86001
335.71301, 44.70583,    -0.99214,89.19596,50.00000,0.0000e+000,20.00000,    -0.18198,0.85818
337.48401, 44.88583,    -0.99896,89.16528,50.00000,0.0000e+000,20.00000,    -0.19091,0.85635
339.27499, 45.06583,    -1.00486,89.12510,50.00000,0.0000e+000,20.00000,    -0.19504,0.85452
341.05499, 45.24583,    -1.01049,89.08667,50.00000,0.0000e+000,20.00000,    -0.19951,0.85269
342.83301, 45.42583,    -1.01613,89.05321,50.00000,0.0000e+000,20.00000,    -0.20762,0.85088
344.62201, 45.60583,    -1.02109,89.01753,50.00000,0.0000e+000,20.00000,    -0.21510,0.84906
346.40201, 45.78583,    -1.02705,88.97842,50.00000,0.0000e+000,20.00000,    -0.21954,0.84726
348.17599, 45.96583,    -1.03219,88.93334,50.00000,0.0000e+000,20.00000,    -0.22518,0.84547
349.94400, 46.14583,    -1.03925,88.88781,50.00000,0.0000e+000,20.00000,    -0.22961,0.84369
351.73099, 46.32583,    -1.04625,88.85169,50.00000,0.0000e+000,20.00000,    -0.23330,0.84190
353.51099, 46.50583,    -1.05250,88.80745,50.00000,0.0000e+000,20.00000,    -0.23936,0.84012
355.28201, 46.68583,    -1.06006,88.76006,50.00000,0.0000e+000,20.00000,    -0.24587,0.83835
357.06299, 46.86583,    -1.06701,88.71976,50.00000,0.0000e+000,20.00000,    -0.24589,0.83658
358.82101, 47.04583,    -1.07453,88.67748,50.00000,0.0000e+000,20.00000,    -0.24510,0.83484
360.61401, 47.22583,    -1.08353,88.62110,50.00000,0.0000e+000,20.00000,    -0.24597,0.83307
362.41101, 47.40583,    -1.09269,88.55771,50.00000,0.0000e+000,20.00000,    -0.24658,0.83130
364.20200, 47.58583,    -1.10266,88.51374,50.00000,0.0000e+000,20.00000,    -0.24592,0.82955
365.98099, 47.76583,    -1.11189,88.47476,50.00000,0.0000e+000,20.00000,    -0.24642,0.82781
367.75299, 47.94584,    -1.11795,88.42765,50.00000,0.0000e+000,20.00000,    -0.24537,0.82608
369.53799, 48.12583,    -1.12463,88.38033,50.00000,0.0000e+000,20.00000,    -0.24262,0.82435
371.33801, 48.30583,    -1.13213,88.33314,50.00000,0.0000e+000,20.00000,    -0.23877,0.82261
373.10699, 48.48583,    -1.13979,88.27938,50.00000,0.0000e+000,20.00000,    -0.23507,0.82091
374.88800, 48.66583,    -1.14697,88.23819,50.00000,0.0000e+000,20.00000,    -0.23332,0.81920
376.67401, 48.84583,    -1.15459,88.20189,50.00000,0.0000e+000,20.00000,    -0.23013,0.81749
378.45499, 49.02583,    -1.16167,88.16497,50.00000,0.0000e+000,20.00000,    -0.22546,0.81579
380.22900, 49.20583,    -1.16910,88.12757,50.00000,0.0000e+000,20.00000,    -0.21754,0.81410
382.00400, 49.38583,    -1.17916,88.09163,50.00000,0.0000e+000,20.00000,    -0.21288,0.81242
383.78799, 49.56583,    -1.19147,88.04761,50.00000,0.0000e+000,20.00000,    -0.21063,0.81074
385.57700, 49.74583,    -1.20210,88.00248,50.00000,0.0000e+000,20.00000,    -0.20644,0.80906
387.35999, 49.92583,    -1.21374,87.97427,50.00000,0.0000e+000,20.00000,    -0.20065,0.80738
389.14099, 50.10583,    -1.22353,87.94697,50.00000,0.0000e+000,20.00000,    -0.19351,0.80572
390.93701, 50.28583,    -1.23413,87.91329,50.00000,0.0000e+000,20.00000,    -0.18555,0.80405
392.73300, 50.46583,    -1.24564,87.87768,50.00000,0.0000e+000,20.00000,    -0.18162,0.80239
394.51801, 50.64583,    -1.25550,87.84824,50.00000,0.0000e+000,20.00000,    -0.17985,0.80074
396.31100, 50.82583,    -1.26749,87.81274,50.00000,0.0000e+000,20.00000,    -0.17962,0.79909
398.10001, 51.00583,    -1.27784,87.77618,50.00000,0.0000e+000,20.00000,    -0.17883,0.79745
399.87900, 51.18583,    -1.28776,87.74599,50.00000,0.0000e+000,20.00000,    -0.17713,0.79582
401.67700, 51.36583,    -1.29723,87.71591,50.00000,0.0000e+000,20.00000,    -0.17486,0.79418
403.44699, 51.54583,    -1.30704,87.68534,50.00000,0.0000e+000,20.00000,    -0.17223,0.79258
405.23801, 51.72583,    -1.31607,87.65738,50.00000,0.0000e+000,20.00000,    -0.17465,0.79096
407.00299, 51.90583,    -1.32474,87.63668,50.00000,0.0000e+000,20.00000,    -0.17866,0.78937
408.80600, 52.08583,    -1.33377,87.61343,50.00000,0.0000e+000,20.00000,    -0.17853,0.78775
410.58200, 52.26583,    -1.34250,87.58417,50.00000,0.0000e+000,20.00000,    -0.17909,0.78616
412.36801, 52.44584,    -1.35132,87.55515,50.00000,0.0000e+000,20.00000,    -0.18231,0.78457
414.15399, 52.62583,    -1.36001,87.51983,50.00000,0.0000e+000,20.00000,    -0.18297,0.78299
415.93799, 52.80583,    -1.36876,87.48443,50.00000,0.0000e+000,20.00000,    -0.18265,0.78141
417.72501, 52.98583,    -1.37797,87.45439,50.00000,0.0000e+000,20.00000,    -0.18358,0.77984
419.49500, 53.16583,    -1.38667,87.42169,50.00000,0.0000e+000,20.00000,    -0.18693,0.77829
421.29199, 53.34583,    -1.39583,87.38429,50.00000,0.0000e+000,20.00000,    -0.18965,0.77672
423.08401, 53.52583,    -1.40512,87.34622,50.00000,0.0000e+000,20.00000,    -0.19216,0.77516
424.86301, 53.70583,    -1.41367,87.30413,50.00000,0.0000e+000,20.00000,    -0.19863,0.77361
426.66299, 53.88583,    -1.42209,87.27122,50.00000,0.0000e+000,20.00000,    -0.20414,0.77206
428.44800, 54.06583,    -1.43066,87.23463,50.00000,0.0000e+000,20.00000,    -0.20637,0.77052
430.22699, 54.24583,    -1.43901,87.19231,50.00000,0.0000e+000,20.00000,    -0.21029,0.76900
432.02100, 54.42583,    -1.44622,87.15555,50.00000,0.0000e+000,20.00000,    -0.21241,0.76747
433.80099, 54.60583,    -1.45335,87.11891,50.00000,0.0000e+000,20.00000,    -0.21591,0.76595
435.59399, 54.78583,    -1.46059,87.08514,50.00000,0.0000e+000,20.00000,    -0.22093,0.76443
437.35699, 54.96583,    -1.46793,87.04411,50.00000,0.0000e+000,20.00000,    -0.22431,0.76294
439.14700, 55.14583,    -1.47604,87.00245,50.00000,0.0000e+000,20.00000,    -0.22562,0.76144
440.94400, 55.32583,    -1.48342,86.96515,50.00000,0.0000e+000,20.00000,    -0.22550,0.75993
442.70801, 55.50583,    -1.48941,86.92068,50.00000,0.0000e+000,20.00000,    -0.22572,0.75846
444.47601, 55.68583,    -1.49434,86.87723,50.00000,0.0000e+000,20.00000,    -0.23103,0.75699
446.25500, 55.86583,    -1.50030,86.84038,50.00000,0.0000e+000,20.00000,    -0.23386,0.75552
448.03400, 56.04583,    -1.50796,86.79791,50.00000,0.0000e+000,20.00000,    -0.23551,0.75405
449.79999, 56.22583,    -1.51754,86.75571,50.00000,0.0000e+000,20.00000,    -0.23883,0.75260
451.58600, 56.40583,    -1.52803,86.70835,50.00000,0.0000e+000,20.00000,    -0.24159,0.75114
453.38800, 56.58583,    -1.53736,86.65820,50.00000,0.0000e+000,20.00000,    -0.24674,0.74968
455.19699, 56.76583,    -1.54778,86.61417,50.00000,0.0000e+000,20.00000,    -0.25177,0.74821
456.99799, 56.94584,    -1.56078,86.57122,50.00000,0.0000e+000,20.00000,    -0.25222,0.74675
458.79501, 57.12583,    -1.56734,86.53392,50.00000,0.0000e+000,20.00000,    -0.25517,0.74531
460.58801, 57.30583,    -1.57163,86.49281,50.00000,0.0000e+000,20.00000,    -0.25665,0.74387
462.41501, 57.48583,    -1.58344,86.43935,50.00000,0.0000e+000,20.00000,    -0.25785,0.74241
464.24200, 57.66583,    -1.59864,86.39292,50.00000,0.0000e+000,20.00000,    -0.26195,0.74096
466.07800, 57.84583,    -1.60997,86.34548,50.00000,0.0000e+000,20.00000,    -0.26243,0.73950
467.91101, 58.02583,    -1.61604,86.29542,50.00000,0.0000e+000,20.00000,    -0.26590,0.73806
469.72101, 58.20583,    -1.61751,86.24858,50.00000,0.0000e+000,20.00000,    -0.27171,0.73664
471.50400, 58.38583,    -1.61815,86.19742,50.00000,0.0000e+000,20.00000,    -0.27252,0.73524
473.30801, 58.56583,    -1.62046,86.13877,50.00000,0.0000e+000,20.00000,    -0.27387,0.73384
475.06000, 58.74583,    -1.62235,86.09283,50.00000,0.0000e+000,20.00000,    -0.27826,0.73248
476.83499, 58.92583,    -1.62453,86.04641,50.00000,0.0000e+000,20.00000,    -0.28460,0.73111
478.62100, 59.10583,    -1.63157,85.99674,50.00000,0.0000e+000,20.00000,    -0.29054,0.72973
480.38101, 59.28583,    -1.64016,85.94900,50.00000,0.0000e+000,20.00000,    -0.29185,0.72839
482.16699, 59.46583,    -1.64960,85.89596,50.00000,0.0000e+000,20.00000,    -0.29416,0.72702
483.93500, 59.64583,    -1.65512,85.85225,50.00000,0.0000e+000,20.00000,    -0.29687,0.72568
485.70300, 59.82583,    -1.66185,85.80004,50.00000,0.0000e+000,20.00000,    -0.29735,0.72434
487.48300, 60.00583,    -1.66908,85.73295,50.00000,0.0000e+000,20.00000,    -0.30206,0.72300
489.26001, 60.18583,    -1.67359,85.67656,50.00000,0.0000e+000,20.00000,    -0.30589,0.72167
491.01901, 60.36583,    -1.68043,85.62803,50.00000,0.0000e+000,20.00000,    -0.30567,0.72035
492.79700, 60.54583,    -1.68992,85.56994,50.00000,0.0000e+000,20.00000,    -0.30498,0.71903
494.57901, 60.72583,    -1.69987,85.50849,50.00000,0.0000e+000,20.00000,    -0.30765,0.71771
496.35599, 60.90583,    -1.71118,85.44733,50.00000,0.0000e+000,20.00000,    -0.31806,0.71640
498.16299, 61.08583,    -1.72265,85.38930,50.00000,0.0000e+000,20.00000,    -0.32311,0.71507
499.99301, 61.26583,    -1.73484,85.33324,50.00000,0.0000e+000,20.00000,    -0.31998,0.71373
501.79901, 61.44584,    -1.74399,85.27615,50.00000,0.0000e+000,20.00000,    -0.32425,0.71241
503.59601, 61.62583,    -1.75170,85.22466,50.00000,0.0000e+000,20.00000,    -0.32703,0.71111
505.42801, 61.80583,    -1.76265,85.16188,50.00000,0.0000e+000,20.00000,    -0.32411,0.70978
507.25299, 61.98583,    -1.77066,85.09729,50.00000,0.0000e+000,20.00000,    -0.32480,0.70847
509.07001, 62.16583,    -1.77494,85.03827,50.00000,0.0000e+000,20.00000,    -0.32982,0.70717
510.85901, 62.34583,    -1.77875,84.99097,50.00000,0.0000e+000,20.00000,    -0.33053,0.70589
512.67401, 62.52583,    -1.78248,84.94048,50.00000,0.0000e+000,20.00000,    -0.33141,0.70461
514.47302, 62.70583,    -1.78738,84.85535,50.00000,0.0000e+000,20.00000,    -0.33398,0.70333
516.27399, 62.88583,    -1.79220,84.78266,50.00000,0.0000e+000,20.00000,    -0.33234,0.70207
518.06403, 63.06583,    -1.79757,84.74160,50.00000,0.0000e+000,20.00000,    -0.33058,0.70081
519.85303, 63.24583,    -1.80216,84.68338,50.00000,0.0000e+000,20.00000,    -0.33402,0.69956
521.63702, 63.42583,    -1.80762,84.62276,50.00000,0.0000e+000,20.00000,    -0.33738,0.69832
523.42902, 63.60583,    -1.81205,84.56693,50.00000,0.0000e+000,20.00000,    -0.33825,0.69708
525.21100, 63.78583,    -1.81681,84.50724,50.00000,0.0000e+000,20.00000,    -0.33939,0.69586
526.99701, 63.96583,    -1.82259,84.44000,50.00000,0.0000e+000,20.00000,    -0.34283,0.69463
528.77197, 64.14584,    -1.83106,84.38023,50.00000,0.0000e+000,20.00000,    -0.34739,0.69342
530.56500, 64.32584,    -1.83844,84.31716,50.00000,0.0000e+000,20.00000,    -0.34970,0.69220
532.37201, 64.50584,    -1.84507,84.24607,50.00000,0.0000e+000,20.00000,    -0.34489,0.69097
534.15503, 64.68584,    -1.84973,84.18998,50.00000,0.0000e+000,20.00000,    -0.34264,0.68977
535.94299, 64.86584,    -1.85595,84.14277,50.00000,0.0000e+000,20.00000,    -0.34954,0.68857
537.73999, 65.04583,    -1.86285,84.07462,50.00000,0.0000e+000,20.00000,    -0.35636,0.68737
539.53198, 65.22583,    -1.86829,84.00885,50.00000,0.0000e+000,20.00000,    -0.36050,0.68618
541.33600, 65.40583,    -1.87840,83.94621,50.00000,0.0000e+000,20.00000,    -0.36660,0.68498
543.14801, 65.58583,    -1.88727,83.87698,50.00000,0.0000e+000,20.00000,    -0.36912,0.68379
544.98102, 65.76583,    -1.89512,83.80495,50.00000,0.0000e+000,20.00000,    -0.36818,0.68258
546.76300, 65.94583,    -1.89938,83.73676,50.00000,0.0000e+000,20.00000,    -0.37039,0.68142
548.57202, 66.12583,    -1.90200,83.68058,50.00000,0.0000e+000,20.00000,    -0.37038,0.68024
550.36798, 66.30583,    -1.90598,83.61956,50.00000,0.0000e+000,20.00000,    -0.37208,0.67908
552.16302, 66.48583,    -1.91173,83.54874,50.00000,0.0000e+000,20.00000,    -0.37886,0.67792
554.00098, 66.66583,    -1.92326,83.48163,50.00000,0.0000e+000,20.00000,    -0.38366,0.67674
555.82098, 66.84583,    -1.93159,83.40335,50.00000,0.0000e+000,20.00000,    -0.38277,0.67557
557.63000, 67.02583,    -1.93399,83.32530,50.00000,0.0000e+000,20.00000,    -0.38463,0.67442
559.43298, 67.20583,    -1.93583,83.24734,50.00000,0.0000e+000,20.00000,    -0.38507,0.67328
561.23499, 67.38583,    -1.93726,83.17728,50.00000,0.0000e+000,20.00000,    -0.38685,0.67214
563.02502, 67.56583,    -1.93803,83.11482,50.00000,0.0000e+000,20.00000,    -0.38683,0.67102
564.80902, 67.74583,    -1.93913,83.04520,50.00000,0.0000e+000,20.00000,    -0.38284,0.66990
566.61700, 67.92583,    -1.94960,82.98355,50.00000,0.0000e+000,20.00000,    -0.38454,0.66877
568.42297, 68.10583,    -1.95885,82.90997,50.00000,0.0000e+000,20.00000,    -0.39086,0.66765
570.23499, 68.28584,    -1.96205,82.82406,50.00000,0.0000e+000,20.00000,    -0.39654,0.66653
572.03101, 68.46584,    -1.96235,82.75744,50.00000,0.0000e+000,20.00000,    -0.39764,0.66543
573.82098, 68.64584,    -1.96258,82.69760,50.00000,0.0000e+000,20.00000,    -0.39127,0.66434
575.58301, 68.82584,    -1.95913,82.62286,50.00000,0.0000e+000,20.00000,    -0.38690,0.66326
577.34497, 69.00584,    -1.95727,82.55892,50.00000,0.0000e+000,20.00000,    -0.38435,0.66219
579.09698, 69.18584,    -1.96379,82.48585,50.00000,0.0000e+000,20.00000,    -0.38442,0.66113
580.86798, 69.36584,    -1.97205,82.41186,50.00000,0.0000e+000,20.00000,    -0.39002,0.66007
582.65997, 69.54583,    -1.98165,82.35525,50.00000,0.0000e+000,20.00000,    -0.39068,0.65900
584.45099, 69.72583,    -1.99094,82.29456,50.00000,0.0000e+000,20.00000,    -0.39110,0.65793
586.24799, 69.90583,    -2.00002,82.21458,50.00000,0.0000e+000,20.00000,    -0.39327,0.65686
588.06403, 70.08583,    -2.00704,82.12378,50.00000,0.0000e+000,20.00000,    -0.39039,0.65579
589.85101, 70.26583,    -2.01058,82.04739,50.00000,0.0000e+000,20.00000,    -0.38928,0.65474
591.65399, 70.44583,    -2.01587,81.99444,50.00000,0.0000e+000,20.00000,    -0.39459,0.65368
593.48401, 70.62583,    -2.02705,81.93283,50.00000,0.0000e+000,20.00000,    -0.39745,0.65261
595.31702, 70.80583,    -2.03733,81.86515,50.00000,0.0000e+000,20.00000,    -0.40194,0.65155
597.13599, 70.98583,    -2.04128,81.79362,50.00000,0.0000e+000,20.00000,    -0.40295,0.65050
598.93799, 71.16583,    -2.04118,81.71206,50.00000,0.0000e+000,20.00000,    -0.40057,0.64946
600.71600, 71.34583,    -2.04046,81.63723,50.00000,0.0000e+000,20.00000,    -0.40705,0.64844
602.50702, 71.52583,    -2.04275,81.57411,50.00000,0.0000e+000,20.00000,    -0.41527,0.64742
604.32001, 71.70583,    -2.04830,81.49771,50.00000,0.0000e+000,20.00000,    -0.42065,0.64639
606.14301, 71.88583,    -2.05607,81.42020,50.00000,0.0000e+000,20.00000,    -0.41690,0.64536
607.94299, 72.06583,    -2.06184,81.35396,50.00000,0.0000e+000,20.00000,    -0.41157,0.64435
609.75403, 72.24583,    -2.06557,81.27833,50.00000,0.0000e+000,20.00000,    -0.41746,0.64333
611.55701, 72.42583,    -2.06762,81.19410,50.00000,0.0000e+000,20.00000,    -0.42193,0.64233
613.35797, 72.60583,    -2.06943,81.11179,50.00000,0.0000e+000,20.00000,    -0.42757,0.64133
615.15698, 72.78584,    -2.07340,81.03540,50.00000,0.0000e+000,20.00000,    -0.43446,0.64033
616.96198, 72.96584,    -2.07677,80.96902,50.00000,0.0000e+000,20.00000,    -0.43437,0.63934
618.75098, 73.14584,    -2.08119,80.88893,50.00000,0.0000e+000,20.00000,    -0.44093,0.63836
620.56000, 73.32584,    -2.08542,80.80112,50.00000,0.0000e+000,20.00000,    -0.44783,0.63737
622.35199, 73.50584,    -2.09080,80.70507,50.00000,0.0000e+000,20.00000,    -0.44381,0.63639
624.15997, 73.68584,    -2.09726,80.62316,50.00000,0.0000e+000,20.00000,    -0.44544,0.63542
625.96002, 73.86584,    -2.10099,80.56317,50.00000,0.0000e+000,20.00000,    -0.45288,0.63445
627.76001, 74.04583,    -2.10400,80.48851,50.00000,0.0000e+000,20.00000,    -0.45767,0.63348
629.56000, 74.22583,    -2.10801,80.41255,50.00000,0.0000e+000,20.00000,    -0.46039,0.63252
631.36200, 74.40583,    -2.11322,80.32781,50.00000,0.0000e+000,20.00000,    -0.46282,0.63156
633.18500, 74.58583,    -2.11785,80.23020,50.00000,0.0000e+000,20.00000,    -0.46304,0.63060
634.97198, 74.76583,    -2.12044,80.15042,50.00000,0.0000e+000,20.00000,    -0.47063,0.62965
636.78802, 74.94583,    -2.12482,80.05206,50.00000,0.0000e+000,20.00000,    -0.47424,0.62870
638.61499, 75.12583,    -2.13186,79.95794,50.00000,0.0000e+000,20.00000,    -0.47162,0.62774
640.43500, 75.30583,    -2.14064,79.89780,50.00000,0.0000e+000,20.00000,    -0.47130,0.62680
642.25598, 75.48583,    -2.14241,79.81799,50.00000,0.0000e+000,20.00000,    -0.47064,0.62585
644.05200, 75.66583,    -2.14123,79.72248,50.00000,0.0000e+000,20.00000,    -0.47798,0.62493
645.83600, 75.84583,    -2.13977,79.63218,50.00000,0.0000e+000,20.00000,    -0.47810,0.62401
647.65698, 76.02583,    -2.15094,79.53888,50.00000,0.0000e+000,20.00000,    -0.47182,0.62308
649.50201, 76.20583,    -2.15881,79.44546,50.00000,0.0000e+000,20.00000,    -0.46978,0.62214
651.31201, 76.38583,    -2.16219,79.36618,50.00000,0.0000e+000,20.00000,    -0.47124,0.62122
653.16199, 76.56583,    -2.16970,79.27479,50.00000,0.0000e+000,20.00000,    -0.47146,0.62029
654.97101, 76.74583,    -2.17381,79.18101,50.00000,0.0000e+000,20.00000,    -0.46448,0.61938
656.78497, 76.92583,    -2.17471,79.10367,50.00000,0.0000e+000,20.00000,    -0.45866,0.61847
658.57397, 77.10583,    -2.17760,79.01205,50.00000,0.0000e+000,20.00000,    -0.45867,0.61757
660.37500, 77.28584,    -2.17895,78.92526,50.00000,0.0000e+000,20.00000,    -0.45642,0.61668
662.16199, 77.46584,    -2.17726,78.83977,50.00000,0.0000e+000,20.00000,    -0.45052,0.61580
663.91998, 77.64584,    -2.17377,78.76171,50.00000,0.0000e+000,20.00000,    -0.44445,0.61493
665.68103, 77.82584,    -2.17392,78.70847,50.00000,0.0000e+000,20.00000,    -0.43855,0.61407
667.45203, 78.00584,    -2.17951,78.63880,50.00000,0.0000e+000,20.00000,    -0.43473,0.61320
669.23102, 78.18584,    -2.18902,78.53776,50.00000,0.0000e+000,20.00000,    -0.42806,0.61233
671.02600, 78.36584,    -2.19817,78.44965,50.00000,0.0000e+000,20.00000,    -0.42042,0.61146
672.82501, 78.54583,    -2.20616,78.38245,50.00000,0.0000e+000,20.00000,    -0.40975,0.61060
674.62903, 78.72583,    -2.21392,78.30427,50.00000,0.0000e+000,20.00000,    -0.40530,0.60973
676.45001, 78.90583,    -2.22082,78.23962,50.00000,0.0000e+000,20.00000,    -0.40227,0.60886
678.24200, 79.08583,    -2.22598,78.17513,50.00000,0.0000e+000,20.00000,    -0.39785,0.60800
680.03198, 79.26583,    -2.22775,78.10110,50.00000,0.0000e+000,20.00000,    -0.39256,0.60715
681.82202, 79.44583,    -2.22951,78.03148,50.00000,0.0000e+000,20.00000,    -0.38422,0.60631
683.61200, 79.62583,    -2.23377,77.96303,50.00000,0.0000e+000,20.00000,    -0.38388,0.60546
685.41803, 79.80583,    -2.24040,77.88052,50.00000,0.0000e+000,20.00000,    -0.38268,0.60461
687.23700, 79.98583,    -2.24907,77.82199,50.00000,0.0000e+000,20.00000,    -0.37154,0.60376
689.06299, 80.16583,    -2.26299,77.76278,50.00000,0.0000e+000,20.00000,    -0.35950,0.60291
690.89398, 80.34583,    -2.26850,77.70469,50.00000,0.0000e+000,20.00000,    -0.35891,0.60207
692.69702, 80.52583,    -2.26816,77.64517,50.00000,0.0000e+000,20.00000,    -0.35781,0.60123
694.48401, 80.70583,    -2.26718,77.56853,50.00000,0.0000e+000,20.00000,    -0.35616,0.60041
696.29303, 80.88583,    -2.26547,77.49398,50.00000,0.0000e+000,20.00000,    -0.35344,0.59958
698.08197, 81.06583,    -2.26826,77.42785,50.00000,0.0000e+000,20.00000,    -0.34811,0.59877
699.88000, 81.24583,    -2.27450,77.37449,50.00000,0.0000e+000,20.00000,    -0.34500,0.59795
701.71997, 81.42583,    -2.29030,77.32255,50.00000,0.0000e+000,20.00000,    -0.34902,0.59711
703.58002, 81.60583,    -2.30134,77.26213,50.00000,0.0000e+000,20.00000,    -0.34710,0.59627
705.40302, 81.78584,    -2.30110,77.20412,50.00000,0.0000e+000,20.00000,    -0.34485,0.59546
707.21399, 81.96584,    -2.29691,77.15456,50.00000,0.0000e+000,20.00000,    -0.34018,0.59464
709.00403, 82.14584,    -2.29133,77.09287,50.00000,0.0000e+000,20.00000,    -0.34033,0.59385
710.79797, 82.32584,    -2.28741,77.01889,50.00000,0.0000e+000,20.00000,    -0.33717,0.59305
712.60901, 82.50584,    -2.28627,76.95517,50.00000,0.0000e+000,20.00000,    -0.32660,0.59225
714.39600, 82.68584,    -2.28599,76.90236,50.00000,0.0000e+000,20.00000,    -0.31610,0.59146
716.19098, 82.86584,    -2.28591,76.84803,50.00000,0.0000e+000,20.00000,    -0.30474,0.59067
717.99103, 83.04583,    -2.28856,76.79134,50.00000,0.0000e+000,20.00000,    -0.29494,0.58988
719.82300, 83.22583,    -2.29845,76.71167,50.00000,0.0000e+000,20.00000,    -0.28633,0.58908
721.62598, 83.40583,    -2.30758,76.63419,50.00000,0.0000e+000,20.00000,    -0.27867,0.58830
723.44202, 83.58583,    -2.31422,76.57580,50.00000,0.0000e+000,20.00000,    -0.26956,0.58751
725.22900, 83.76583,    -2.32031,76.53650,50.00000,0.0000e+000,20.00000,    -0.25936,0.58674
727.02100, 83.94583,    -2.33070,76.47831,50.00000,0.0000e+000,20.00000,    -0.24778,0.58597
728.80902, 84.12583,    -2.34570,76.42859,50.00000,0.0000e+000,20.00000,    -0.23262,0.58521
730.59900, 84.30583,    -2.36482,76.39293,50.00000,0.0000e+000,20.00000,    -0.21919,0.58444
732.38501, 84.48583,    -2.38154,76.35435,50.00000,0.0000e+000,20.00000,    -0.20926,0.58368
734.19202, 84.66583,    -2.39283,76.32708,50.00000,0.0000e+000,20.00000,    -0.19924,0.58292
735.98901, 84.84583,    -2.40235,76.30641,50.00000,0.0000e+000,20.00000,    -0.18925,0.58216
737.78699, 85.02583,    -2.41011,76.28840,50.00000,0.0000e+000,20.00000,    -0.17318,0.58140
739.59998, 85.20583,    -2.41759,76.25827,50.00000,0.0000e+000,20.00000,    -0.15611,0.58064
741.41400, 85.38583,    -2.42311,76.22966,50.00000,0.0000e+000,20.00000,    -0.14195,0.57988
743.20001, 85.56583,    -2.42810,76.21635,50.00000,0.0000e+000,20.00000,    -0.13326,0.57914
745.02802, 85.74583,    -2.43276,76.20070,50.00000,0.0000e+000,20.00000,    -0.12241,0.57838
746.82397, 85.92583,    -2.43552,76.18253,50.00000,0.0000e+000,20.00000,    -0.11202,0.57763
748.63800, 86.10583,    -2.43789,76.16519,50.00000,0.0000e+000,20.00000,    -0.10779,0.57688
750.45697, 86.28584,    -2.44101,76.14840,50.00000,0.0000e+000,20.00000,    -0.10228,0.57614
752.24103, 86.46584,    -2.44006,76.13053,50.00000,0.0000e+000,20.00000,-9.6588e-002,0.57540
754.04999, 86.64584,    -2.43867,76.11256,50.00000,0.0000e+000,20.00000,-9.6483e-002,0.57467
755.87903, 86.82584,    -2.44420,76.09415,50.00000,0.0000e+000,20.00000,-9.5297e-002,0.57392
757.68402, 87.00584,    -2.44717,76.07696,50.00000,0.0000e+000,20.00000,-8.7259e-002,0.57319
759.48999, 87.18584,    -2.44564,76.06513,50.00000,0.0000e+000,20.00000,-7.9465e-002,0.57246
761.28400, 87.36584,    -2.44662,76.05766,50.00000,0.0000e+000,20.00000,-7.7301e-002,0.57173
763.08099, 87.54583,    -2.44526,76.04319,50.00000,0.0000e+000,20.00000,-7.7323e-002,0.57101
764.87097, 87.72583,    -2.44494,76.02740,50.00000,0.0000e+000,20.00000,-8.0170e-002,0.57029
766.68903, 87.90583,    -2.45045,76.00849,50.00000,0.0000e+000,20.00000,-8.1654e-002,0.56957
768.53101, 88.08583,    -2.45697,75.98750,50.00000,0.0000e+000,20.00000,-8.0822e-002,0.56883
770.34100, 88.26583,    -2.45859,75.97968,50.00000,0.0000e+000,20.00000,-7.9815e-002,0.56811
772.14899, 88.44583,    -2.45529,75.95996,50.00000,0.0000e+000,20.00000,-7.7744e-002,0.56740
773.93103, 88.62583,    -2.45187,75.94406,50.00000,0.0000e+000,20.00000,-7.4513e-002,0.56669
775.72803, 88.80583,    -2.45333,75.94426,50.00000,0.0000e+000,20.00000,-7.2480e-002,0.56598
777.53900, 88.98583,    -2.45610,75.94325,50.00000,0.0000e+000,20.00000,-7.1423e-002,0.56527
779.34003, 89.16583,    -2.45831,75.93683,50.00000,0.0000e+000,20.00000,-7.2619e-002,0.56457
781.14502, 89.34583,    -2.46020,75.92420,50.00000,0.0000e+000,20.00000,-7.3161e-002,0.56386
782.94397, 89.52583,    -2.46401,75.89677,50.00000,0.0000e+000,20.00000,-7.2965e-002,0.56316
784.77301, 89.70583,    -2.46863,75.87195,50.00000,0.0000e+000,20.00000,-7.1357e-002,0.56245
786.59497, 89.88583,    -2.47022,75.85763,50.00000,0.0000e+000,20.00000,-6.9141e-002,0.56175
788.37000, 90.06583,    -2.46369,75.84366,50.00000,0.0000e+000,20.00000,-7.2361e-002,0.56106
790.17102, 90.24583,    -2.46361,75.83229,50.00000,0.0000e+000,20.00000,-7.1203e-002,0.56037
791.96399, 90.42583,    -2.46561,75.82589,50.00000,0.0000e+000,20.00000,-6.9049e-002,0.55968
793.76599, 90.60583,    -2.46746,75.81592,50.00000,0.0000e+000,20.00000,-7.1488e-002,0.55899
795.57001, 90.78584,    -2.47463,75.80690,50.00000,0.0000e+000,20.00000,-7.7584e-002,0.55830
797.37402, 90.96584,    -2.48100,75.79567,50.00000,0.0000e+000,20.00000,-8.1638e-002,0.55761
799.18298, 91.14584,    -2.48526,75.78079,50.00000,0.0000e+000,20.00000,-8.1182e-002,0.55692
801.00598, 91.32584,    -2.49150,75.76530,50.00000,0.0000e+000,20.00000,-7.6143e-002,0.55623
802.80902, 91.50584,    -2.49020,75.75266,50.00000,0.0000e+000,20.00000,-7.1936e-002,0.55555
804.59900, 91.68584,    -2.49012,75.74002,50.00000,0.0000e+000,20.00000,-7.2580e-002,0.55488
806.40997, 91.86584,    -2.49543,75.71924,50.00000,0.0000e+000,20.00000,-7.5337e-002,0.55419
808.23700, 92.04583,    -2.50711,75.70527,50.00000,0.0000e+000,20.00000,-7.7909e-002,0.55351
810.05603, 92.22583,    -2.51250,75.69406,50.00000,0.0000e+000,20.00000,-8.1286e-002,0.55283
811.84698, 92.40583,    -2.50951,75.68491,50.00000,0.0000e+000,20.00000,-8.1978e-002,0.55216
813.65302, 92.58583,    -2.51115,75.66419,50.00000,0.0000e+000,20.00000,-8.2885e-002,0.55148
815.43298, 92.76583,    -2.50966,75.64189,50.00000,0.0000e+000,20.00000,-8.4217e-002,0.55082
817.21002, 92.94583,    -2.50888,75.63130,50.00000,0.0000e+000,20.00000,-8.4127e-002,0.55016
819.02301, 93.12583,    -2.51161,75.62452,50.00000,0.0000e+000,20.00000,-8.3791e-002,0.54949
820.82202, 93.30583,    -2.51510,75.61390,50.00000,0.0000e+000,20.00000,-8.7337e-002,0.54882
822.66101, 93.48583,    -2.52362,75.59775,50.00000,0.0000e+000,20.00000,-9.3997e-002,0.54815
824.50598, 93.66583,    -2.53549,75.57392,50.00000,0.0000e+000,20.00000,-9.4394e-002,0.54747
826.34698, 93.84583,    -2.53625,75.55214,50.00000,0.0000e+000,20.00000,-9.3970e-002,0.54679
828.14600, 94.02583,    -2.53066,75.53222,50.00000,0.0000e+000,20.00000,-9.5833e-002,0.54613
829.91699, 94.20583,    -2.52196,75.51965,50.00000,0.0000e+000,20.00000,    -0.10016,0.54548
831.66901, 94.38583,    -2.51014,75.50734,50.00000,0.0000e+000,20.00000,    -0.10167,0.54484
833.42499, 94.56583,    -2.50602,75.49240,50.00000,0.0000e+000,20.00000,    -0.10207,0.54420
835.22803, 94.74583,    -2.50994,75.47752,50.00000,0.0000e+000,20.00000,    -0.10690,0.54355
837.00000, 94.92583,    -2.51665,75.46417,50.00000,0.0000e+000,20.00000,    -0.11347,0.54290
838.80103, 95.10583,    -2.52085,75.44009,50.00000,0.0000e+000,20.00000,    -0.11753,0.54225
840.62299, 95.28584,    -2.52364,75.40402,50.00000,0.0000e+000,20.00000,    -0.12119,0.54159
842.46198, 95.46584,    -2.52892,75.37969,50.00000,0.0000e+000,20.00000,    -0.12493,0.54093
844.29303, 95.64584,    -2.53509,75.36556,50.00000,0.0000e+000,20.00000,    -0.12697,0.54027
846.11401, 95.82584,    -2.54059,75.34890,50.00000,0.0000e+000,20.00000,    -0.12872,0.53961
847.92798, 96.00584,    -2.53973,75.32426,50.00000,0.0000e+000,20.00000,    -0.13397,0.53896
849.72998, 96.18584,    -2.53226,75.30023,50.00000,0.0000e+000,20.00000,    -0.13892,0.53831
851.52301, 96.36584,    -2.52633,75.27556,50.00000,0.0000e+000,20.00000,    -0.14282,0.53767
853.32397, 96.54583,    -2.52947,75.24647,50.00000,0.0000e+000,20.00000,    -0.14612,0.53703
855.14001, 96.72583,    -2.53360,75.21545,50.00000,0.0000e+000,20.00000,    -0.14997,0.53638
856.96002, 96.90583,    -2.53599,75.18962,50.00000,0.0000e+000,20.00000,    -0.15234,0.53573
858.87402, 97.08583,    -2.55925,75.16314,50.00000,0.0000e+000,20.00000,    -0.15370,0.53505
860.84497, 97.26583,    -2.58850,75.12632,50.00000,0.0000e+000,20.00000,    -0.15711,0.53435
862.71802, 97.44583,    -2.58355,75.09533,50.00000,0.0000e+000,20.00000,    -0.16139,0.53368
864.54199, 97.62583,    -2.56539,75.06895,50.00000,0.0000e+000,20.00000,    -0.16601,0.53304
866.31097, 97.80583,    -2.54355,75.03663,50.00000,0.0000e+000,20.00000,    -0.16861,0.53241
868.07599, 97.98583,    -2.53037,75.00609,50.00000,0.0000e+000,20.00000,    -0.17046,0.53179
869.87500, 98.16583,    -2.52940,74.97704,50.00000,0.0000e+000,20.00000,    -0.17351,0.53115
871.62701, 98.34583,    -2.52111,74.94975,50.00000,0.0000e+000,20.00000,    -0.17737,0.53054
873.37598, 98.52583,    -2.51170,74.92240,50.00000,0.0000e+000,20.00000,    -0.18175,0.52992
875.11700, 98.70583,    -2.50608,74.89349,50.00000,0.0000e+000,20.00000,    -0.18101,0.52931
876.85602, 98.88583,    -2.50296,74.85391,50.00000,0.0000e+000,20.00000,    -0.18097,0.52870
878.61102, 99.06583,    -2.50617,74.81377,50.00000,0.0000e+000,20.00000,    -0.18184,0.52808
880.37299, 99.24583,    -2.51295,74.78187,50.00000,0.0000e+000,20.00000,    -0.18543,0.52746
882.13397, 99.42583,    -2.51618,74.75085,50.00000,0.0000e+000,20.00000,    -0.18834,0.52685
883.91699, 99.60583,    -2.51968,74.71648,50.00000,0.0000e+000,20.00000,    -0.18892,0.52622
885.70300, 99.78584,    -2.52457,74.68583,50.00000,0.0000e+000,20.00000,    -0.19030,0.52560
887.49103, 99.96584,    -2.53201,74.65104,50.00000,0.0000e+000,20.00000,    -0.18928,0.52497
889.32599,100.14584,    -2.54192,74.61022,50.00000,0.0000e+000,20.00000,    -0.19087,0.52433
891.14697,100.32584,    -2.55095,74.56186,50.00000,0.0000e+000,20.00000,    -0.19869,0.52370
892.99200,100.50584,    -2.55663,74.53411,50.00000,0.0000e+000,20.00000,    -0.20865,0.52306
894.79797,100.68584,    -2.55554,74.51165,50.00000,0.0000e+000,20.00000,    -0.20720,0.52243
896.59399,100.86584,    -2.54949,74.47393,50.00000,0.0000e+000,20.00000,    -0.20431,0.52180
898.39398,101.04583,    -2.55272,74.42843,50.00000,0.0000e+000,20.00000,    -0.20723,0.52118
900.21399,101.22583,    -2.55547,74.38999,50.00000,0.0000e+000,20.00000,    -0.21054,0.52055
902.00098,101.40583,    -2.55456,74.35655,50.00000,0.0000e+000,20.00000,    -0.21124,0.51993
903.83099,101.58583,    -2.55902,74.32023,50.00000,0.0000e+000,20.00000,    -0.21249,0.51929
905.66400,101.76583,    -2.56811,74.29287,50.00000,0.0000e+000,20.00000,    -0.21410,0.51866
907.47302,101.94583,    -2.56391,74.26320,50.00000,0.0000e+000,20.00000,    -0.21596,0.51803
909.29602,102.12583,    -2.57072,74.21000,50.00000,0.0000e+000,20.00000,    -0.21419,0.51740
911.10602,102.30583,    -2.56704,74.14435,50.00000,0.0000e+000,20.00000,    -0.21724,0.51677
912.77100,102.48583,    -2.53301,74.10649,50.00000,0.0000e+000,20.00000,    -0.22479,0.51620
914.61499,102.66583,    -2.55017,74.07854,50.00000,0.0000e+000,20.00000,    -0.22641,0.51556
916.52502,102.84583,    -2.58654,74.03593,50.00000,0.0000e+000,20.00000,    -0.22641,0.51490
918.43597,103.02583,    -2.60405,73.99234,50.00000,0.0000e+000,20.00000,    -0.22701,0.51424
920.26801,103.20583,    -2.59340,73.95503,50.00000,0.0000e+000,20.00000,    -0.22925,0.51361
921.96100,103.38583,    -2.55971,73.91928,50.00000,0.0000e+000,20.00000,    -0.23013,0.51303
923.71198,103.56583,    -2.54648,73.88101,50.00000,0.0000e+000,20.00000,    -0.22854,0.51242
925.48901,103.74583,    -2.55289,73.83463,50.00000,0.0000e+000,20.00000,    -0.22780,0.51181
927.31097,103.92583,    -2.56237,73.79212,50.00000,0.0000e+000,20.00000,    -0.22610,0.51118
929.13501,104.10583,    -2.57293,73.74976,50.00000,0.0000e+000,20.00000,    -0.22071,0.51055
930.97498,104.28584,    -2.58070,73.70188,50.00000,0.0000e+000,20.00000,    -0.21524,0.50992
932.82800,104.46584,    -2.58685,73.65886,50.00000,0.0000e+000,20.00000,    -0.21661,0.50928
934.65198,104.64584,    -2.58784,73.61513,50.00000,0.0000e+000,20.00000,    -0.21382,0.50865
936.43597,104.82584,    -2.57810,73.57145,50.00000,0.0000e+000,20.00000,    -0.20708,0.50804
938.24597,105.00584,    -2.57136,73.53056,50.00000,0.0000e+000,20.00000,    -0.20285,0.50742
940.07001,105.18584,    -2.57258,73.48956,50.00000,0.0000e+000,20.00000,    -0.20104,0.50679
941.88000,105.36584,    -2.56713,73.46394,50.00000,0.0000e+000,20.00000,    -0.20103,0.50616
943.66400,105.54583,    -2.56138,73.44140,50.00000,0.0000e+000,20.00000,    -0.19361,0.50555
945.46399,105.72583,    -2.55481,73.40085,50.00000,0.0000e+000,20.00000,    -0.18476,0.50493
947.30701,105.90583,    -2.56013,73.35242,50.00000,0.0000e+000,20.00000,    -0.18132,0.50430
949.13202,106.08583,    -2.55581,73.32674,50.00000,0.0000e+000,20.00000,    -0.17200,0.50367
950.94098,106.26583,    -2.54820,73.29782,50.00000,0.0000e+000,20.00000,    -0.15971,0.50305
952.74799,106.44583,    -2.54515,73.26508,50.00000,0.0000e+000,20.00000,    -0.14899,0.50242
954.57202,106.62583,    -2.54369,73.24457,50.00000,0.0000e+000,20.00000,    -0.14185,0.50179
956.33698,106.80583,    -2.53240,73.22290,50.00000,0.0000e+000,20.00000,    -0.13868,0.50119
958.12500,106.98583,    -2.52856,73.19527,50.00000,0.0000e+000,20.00000,    -0.13221,0.50057
959.92200,107.16583,    -2.52376,73.15775,50.00000,0.0000e+000,20.00000,    -0.12535,0.49995
961.71100,107.34583,    -2.52257,73.13538,50.00000,0.0000e+000,20.00000,    -0.12270,0.49933
963.49402,107.52583,    -2.51937,73.12610,50.00000,0.0000e+000,20.00000,    -0.11692,0.49872
965.26801,107.70583,    -2.51687,73.09806,50.00000,0.0000e+000,20.00000,    -0.10292,0.49811
967.07098,107.88583,    -2.51776,73.08120,50.00000,0.0000e+000,20.00000,-9.7838e-002,0.49749
968.88098,108.06583,    -2.51983,73.08094,50.00000,0.0000e+000,20.00000,-9.6787e-002,0.49686
970.67798,108.24583,    -2.52146,73.07928,50.00000,0.0000e+000,20.00000,-8.9764e-002,0.49624
972.49902,108.42583,    -2.52527,73.06285,50.00000,0.0000e+000,20.00000,-8.5312e-002,0.49561
974.29901,108.60583,    -2.52557,73.03466,50.00000,0.0000e+000,20.00000,-8.2641e-002,0.49499
976.10797,108.78584,    -2.52496,73.01319,50.00000,0.0000e+000,20.00000,-7.8935e-002,0.49437
977.90503,108.96584,    -2.52048,73.00936,50.00000,0.0000e+000,20.00000,-7.0061e-002,0.49374
979.70203,109.14584,    -2.52279,72.99986,50.00000,0.0000e+000,20.00000,-6.3263e-002,0.49312
981.51300,109.32584,    -2.52484,72.98266,50.00000,0.0000e+000,20.00000,-6.0883e-002,0.49250
983.31702,109.50584,    -2.52601,72.98158,50.00000,0.0000e+000,20.00000,-5.8332e-002,0.49187
985.11603,109.68584,    -2.52515,72.97592,50.00000,0.0000e+000,20.00000,-6.2656e-002,0.49125
986.93500,109.86584,    -2.52408,72.95192,50.00000,0.0000e+000,20.00000,-4.9836e-002,0.49062
988.74200,110.04583,    -2.52607,72.94194,50.00000,0.0000e+000,20.00000,-5.2140e-002,0.48999
990.54700,110.22583,    -2.52572,72.93670,50.00000,0.0000e+000,20.00000,-4.7798e-002,0.48936
992.33301,110.40583,    -2.52316,72.92652,50.00000,0.0000e+000,20.00000,-4.5703e-002,0.48874
994.13000,110.58583,    -2.52366,72.91330,50.00000,0.0000e+000,20.00000,-3.9974e-002,0.48812
995.94202,110.76583,    -2.52798,72.90736,50.00000,0.0000e+000,20.00000,-2.6667e-002,0.48749
997.77301,110.94583,    -2.53048,72.90686,50.00000,0.0000e+000,20.00000,-1.8311e-002,0.48685
998.36401,111.00584,    -2.53068,72.90476,50.00000,0.0000e+000,20.00000,-1.5848e-002,0.48664