File: book/some_content/voorbeeld_ExpDat_R30B70D28.csv
#FILE:                       ,R30B70D28; 13-1-2025.ngb-ds3       ,,,,,,
#FORMAT:                     ,NETZSCH5                           ,,,,,,
#IDENTITY:                   ,Geopolymere paste                  ,,,,,,
#DECIMAL:                    ,POINT                              ,,,,,,
#SEPARATOR:                  ,COMMA                              ,,,,,,
#MTYPE:                      ,DSC                                ,,,,,,
#INSTRUMENT:                 ,Microlab TU Delft                  ,,,,,,
#PROJECT:                    ,                                   ,,,,,,
#DATE/TIME:                  ,13/01/2025 12:57:40 PM             ,,,,,,
#CORR. FILE:                 ,Blank with cover; 13-1-2025.ngb-bs3,,,,,,
#LABORATORY:                 ,TU Delft Micro Lab                 ,,,,,,
#OPERATOR:                   ,Ahmed                              ,,,,,,
#REMARK:                     ,under Argon atmosphere, 10K/min    ,,,,,
#SAMPLE:                     ,R30B70D28;13-1-2025                ,,,,,,
#SAMPLE MASS /mg:            ,55,,,,,,
#MATERIAL:                   ,Geopolymer paste                   ,,,,,,
#REFERENCE:                  ,blank                              ,,,,,,
#REFERENCE MASS /mg:         ,0,,,,,,
#TYPE OF CRUCIBLE:           ,DSC/TG pan Al2O3                   ,,,,,,
#SAMPLE CRUCIBLE MASS /mg:   ,0,,,,,,
#REFERENCE CRUCIBLE MASS /mg:,0,,,,,,
#CORR. CODE:                 ,20,,,,,,
#EXO:                        ,-1,,,,,,
#RANGE:                      ,40/10.0(K/min)/1000                ,,,,,,
#SEGMENT:                    ,S2/2                               ,,,,,,
,,,,,,,
##Temp./øC,Time/min,DSC/(mW/mg),Mass/%,Gas Flow(purge1)/(ml/min),Gas Flow(purge2)/(ml/min),Gas Flow(protective)/(ml/min),Sensit./(uV/mW)
40.552,15.0075,7.17E-02,97.92364,50,0.00E+00,20,1.22618
40.597,15.1225,7.15E-02,97.90182,50,0.00E+00,20,1.22612
40.613,15.2375,7.14E-02,97.88182,50,0.00E+00,20,1.2261
40.671,15.3525,7.10E-02,97.86,50,0.00E+00,20,1.22602
40.713,15.4675,7.12E-02,97.84,50,0.00E+00,20,1.22596
40.799,15.5825,7.12E-02,97.81818,50,0.00E+00,20,1.22584
40.883,15.6975,7.15E-02,97.8,50,0.00E+00,20,1.22572
40.999,15.8125,7.21E-02,97.77636,50,0.00E+00,20,1.22556
41.079,15.9275,7.27E-02,97.75636,50,0.00E+00,20,1.22545
41.28,16.0425,7.38E-02,97.73091,50,0.00E+00,20,1.22518
41.466,16.1575,7.51E-02,97.71091,50,0.00E+00,20,1.22492
41.682,16.2725,7.68E-02,97.68909,50,0.00E+00,20,1.22462
41.929,16.3875,7.85E-02,97.66909,50,0.00E+00,20,1.22428
42.213,16.5025,8.09E-02,97.64182,50,0.00E+00,20,1.22389
42.514,16.6175,8.33E-02,97.62,50,0.00E+00,20,1.22348
42.863,16.7325,8.63E-02,97.59455,50,0.00E+00,20,1.22299
43.242,16.8475,8.90E-02,97.57273,50,0.00E+00,20,1.22247
43.65,16.9625,9.25E-02,97.54909,50,0.00E+00,20,1.22191
44.095,17.0775,9.59E-02,97.52727,50,0.00E+00,20,1.2213
44.554,17.1925,9.98E-02,97.50364,50,0.00E+00,20,1.22066
45.076,17.3075,0.10356,97.47818,50,0.00E+00,20,1.21994
45.6,17.4225,0.10796,97.45636,50,0.00E+00,20,1.21922
46.189,17.5375,0.1123,97.42909,50,0.00E+00,20,1.21841
46.784,17.6525,0.11712,97.40182,50,0.00E+00,20,1.21759
47.439,17.7675,0.1219,97.37818,50,0.00E+00,20,1.21669
48.103,17.8825,0.12685,97.35091,50,0.00E+00,20,1.21577
48.801,17.9975,0.13206,97.32,50,0.00E+00,20,1.21481
49.536,18.1125,0.13752,97.29091,50,0.00E+00,20,1.2138
50.285,18.2275,0.14311,97.26182,50,0.00E+00,20,1.21277
51.1,18.3425,0.14905,97.22545,50,0.00E+00,20,1.21165
51.927,18.4575,0.15506,97.19818,50,0.00E+00,20,1.21051
52.803,18.5725,0.16124,97.16,50,0.00E+00,20,1.2093
53.673,18.6875,0.16765,97.12364,50,0.00E+00,20,1.2081
54.61,18.8025,0.17432,97.08182,50,0.00E+00,20,1.20681
55.552,18.9175,0.18132,97.04,50,0.00E+00,20,1.20552
56.534,19.0325,0.18847,97.00182,50,0.00E+00,20,1.20417
57.546,19.1475,0.19582,96.95273,50,0.00E+00,20,1.20278
58.599,19.2625,0.20341,96.90909,50,0.00E+00,20,1.20133
59.67,19.3775,0.21153,96.86182,50,0.00E+00,20,1.19986
60.758,19.4925,0.21965,96.80727,50,0.00E+00,20,1.19836
61.912,19.6075,0.22821,96.75636,50,0.00E+00,20,1.19677
63.062,19.7225,0.2371,96.70182,50,0.00E+00,20,1.19519
64.242,19.8375,0.2463,96.64364,50,0.00E+00,20,1.19357
65.422,19.9525,0.25602,96.58364,50,0.00E+00,20,1.19195
66.642,20.0675,0.26621,96.50727,50,0.00E+00,20,1.19028
67.903,20.1825,0.27673,96.42545,50,0.00E+00,20,1.18855
69.154,20.2975,0.28774,96.36,50,0.00E+00,20,1.18683
70.471,20.4125,0.2995,96.28364,50,0.00E+00,20,1.18503
71.773,20.5275,0.31156,96.18909,50,0.00E+00,20,1.18324
73.086,20.6425,0.32387,96.10909,50,0.00E+00,20,1.18145
74.448,20.7575,0.33726,96.01455,50,0.00E+00,20,1.17958
75.815,20.8725,0.35116,95.92,50,0.00E+00,20,1.17771
77.184,20.9875,0.36591,95.81818,50,0.00E+00,20,1.17584
78.587,21.1025,0.38109,95.70727,50,0.00E+00,20,1.17392
79.997,21.2175,0.39752,95.58727,50,0.00E+00,20,1.17199
81.419,21.3325,0.41441,95.46364,50,0.00E+00,20,1.17005
82.857,21.4475,0.43266,95.33091,50,0.00E+00,20,1.16809
84.316,21.5625,0.45133,95.19091,50,0.00E+00,20,1.1661
85.774,21.6775,0.47142,95.04364,50,0.00E+00,20,1.16411
87.266,21.7925,0.49272,94.88727,50,0.00E+00,20,1.16207
88.774,21.9075,0.51506,94.71636,50,0.00E+00,20,1.16002
90.28,22.0225,0.53867,94.54,50,0.00E+00,20,1.15797
91.762,22.1375,0.56315,94.35273,50,0.00E+00,20,1.15595
93.288,22.2525,0.58917,94.15455,50,0.00E+00,20,1.15388
94.82,22.3675,0.61668,93.94,50,0.00E+00,20,1.1518
96.349,22.4825,0.6455,93.71818,50,0.00E+00,20,1.14972
97.882,22.5975,0.67558,93.47091,50,0.00E+00,20,1.14764
99.42,22.7125,0.70695,93.21818,50,0.00E+00,20,1.14556
100.952,22.8275,0.73992,92.95091,50,0.00E+00,20,1.14348
102.492,22.9425,0.77408,92.67091,50,0.00E+00,20,1.1414
104.042,23.0575,0.80949,92.37455,50,0.00E+00,20,1.1393
105.593,23.1725,0.84615,92.06545,50,0.00E+00,20,1.13721
107.131,23.2875,0.88358,91.73091,50,0.00E+00,20,1.13513
108.671,23.4025,0.92186,91.39455,50,0.00E+00,20,1.13305
110.197,23.5175,0.96019,91.03818,50,0.00E+00,20,1.13099
111.728,23.6325,0.99868,90.67091,50,0.00E+00,20,1.12893
113.266,23.7475,1.03763,90.28727,50,0.00E+00,20,1.12686
114.79,23.8625,1.07595,89.89636,50,0.00E+00,20,1.12481
116.337,23.9775,1.11365,89.47818,50,0.00E+00,20,1.12274
117.853,24.0925,1.15035,89.05455,50,0.00E+00,20,1.1207
119.35,24.2075,1.18608,88.62545,50,0.00E+00,20,1.11869
120.878,24.3225,1.22023,88.18364,50,0.00E+00,20,1.11665
122.386,24.4375,1.25259,87.72909,50,0.00E+00,20,1.11463
123.89,24.5525,1.28298,87.26909,50,0.00E+00,20,1.11262
125.41,24.6675,1.31125,86.79455,50,0.00E+00,20,1.11059
126.893,24.7825,1.3366,86.31818,50,0.00E+00,20,1.10861
128.366,24.8975,1.36005,85.84545,50,0.00E+00,20,1.10664
129.909,25.0125,1.38079,85.36909,50,0.00E+00,20,1.10459
131.416,25.1275,1.39832,84.89455,50,0.00E+00,20,1.10258
132.923,25.2425,1.41285,84.42364,50,0.00E+00,20,1.10058
134.42599,25.3575,1.42413,83.94364,50,0.00E+00,20,1.09858
135.916,25.4725,1.43243,83.47636,50,0.00E+00,20,1.0966
137.41499,25.5875,1.43858,83.01273,50,0.00E+00,20,1.09462
138.92101,25.7025,1.44109,82.55818,50,0.00E+00,20,1.09262
140.42599,25.8175,1.43962,82.10727,50,0.00E+00,20,1.09063
141.925,25.9325,1.43339,81.66909,50,0.00E+00,20,1.08865
143.423,26.0475,1.42209,81.23818,50,0.00E+00,20,1.08668
144.91701,26.1625,1.40545,80.81636,50,0.00E+00,20,1.08471
146.418,26.2775,1.38365,80.41273,50,0.00E+00,20,1.08273
147.914,26.3925,1.35723,80.02909,50,0.00E+00,20,1.08077
149.392,26.5075,1.3262,79.66727,50,0.00E+00,20,1.07882
150.897,26.6225,1.29086,79.32545,50,0.00E+00,20,1.07685
152.399,26.7375,1.25198,79,50,0.00E+00,20,1.07488
153.91,26.8525,1.20889,78.69455,50,0.00E+00,20,1.0729
155.41,26.9675,1.16141,78.42182,50,0.00E+00,20,1.07094
156.90401,27.0825,1.10927,78.17454,50,0.00E+00,20,1.06899
158.395,27.1975,1.0527,77.94727,50,0.00E+00,20,1.06705
159.89101,27.3125,0.99293,77.75454,50,0.00E+00,20,1.0651
161.383,27.4275,0.93012,77.58909,50,0.00E+00,20,1.06316
162.86501,27.5425,0.86572,77.43636,50,0.00E+00,20,1.06123
164.36301,27.6575,0.80165,77.30909,50,0.00E+00,20,1.05929
165.841,27.7725,0.7377,77.20182,50,0.00E+00,20,1.05738
167.30499,27.8875,0.67437,77.11273,50,0.00E+00,20,1.05548
168.774,28.0025,0.61273,77.02909,50,0.00E+00,20,1.05358
170.22701,28.1175,0.55478,76.95636,50,0.00E+00,20,1.05171
171.668,28.2325,0.50115,76.89455,50,0.00E+00,20,1.04985
173.129,28.3475,0.45209,76.84,50,0.00E+00,20,1.04797
174.552,28.4625,0.40755,76.78727,50,0.00E+00,20,1.04614
175.97701,28.5775,0.3669,76.72909,50,0.00E+00,20,1.04431
177.40601,28.6925,0.33017,76.68182,50,0.00E+00,20,1.04248
178.802,28.8075,0.29656,76.63455,50,0.00E+00,20,1.04069
180.215,28.9225,0.26625,76.59273,50,0.00E+00,20,1.03889
181.60201,29.0375,0.2384,76.54546,50,0.00E+00,20,1.03711
182.968,29.1525,0.21344,76.50545,50,0.00E+00,20,1.03537
184.347,29.2675,0.19025,76.46909,50,0.00E+00,20,1.03362
185.718,29.3825,0.16914,76.44182,50,0.00E+00,20,1.03187
187.04201,29.4975,0.14979,76.40727,50,0.00E+00,20,1.03019
188.37801,29.6125,0.13243,76.36909,50,0.00E+00,20,1.0285
189.702,29.7275,0.11611,76.34182,50,0.00E+00,20,1.02682
190.98599,29.8425,0.10149,76.31454,50,0.00E+00,20,1.0252
192.283,29.9575,8.77E-02,76.28545,50,0.00E+00,20,1.02356
193.584,30.0725,7.49E-02,76.26,50,0.00E+00,20,1.02192
194.838,30.1875,6.31E-02,76.23455,50,0.00E+00,20,1.02034
196.11301,30.3025,5.22E-02,76.21091,50,0.00E+00,20,1.01873
197.35201,30.4175,4.20E-02,76.18727,50,0.00E+00,20,1.01717
198.578,30.5325,3.26E-02,76.16364,50,0.00E+00,20,1.01564
199.834,30.6475,2.39E-02,76.14,50,0.00E+00,20,1.01406
201.047,30.7625,1.53E-02,76.11818,50,0.00E+00,20,1.01254
202.24001,30.8775,7.29E-03,76.09818,50,0.00E+00,20,1.01105
203.438,30.9925,-2.89E-04,76.07818,50,0.00E+00,20,1.00956
204.63,31.1075,-7.33E-03,76.06182,50,0.00E+00,20,1.00807
205.8,31.2225,-1.42E-02,76.04182,50,0.00E+00,20,1.00661
206.976,31.3375,-2.08E-02,76.02727,50,0.00E+00,20,1.00515
208.15401,31.4525,-2.71E-02,76.01454,50,0.00E+00,20,1.00369
209.308,31.5675,-3.30E-02,75.99818,50,0.00E+00,20,1.00226
210.45399,31.6825,-3.87E-02,75.98364,50,0.00E+00,20,1.00084
211.61,31.7975,-4.43E-02,75.96727,50,0.00E+00,20,0.99941
212.744,31.9125,-4.97E-02,75.94909,50,0.00E+00,20,0.99801
213.867,32.0275,-5.50E-02,75.93455,50,0.00E+00,20,0.99662
215.007,32.1425,-6.01E-02,75.92,50,0.00E+00,20,0.99522
216.129,32.2575,-6.48E-02,75.90909,50,0.00E+00,20,0.99383
217.235,32.3725,-6.96E-02,75.89273,50,0.00E+00,20,0.99247
218.35699,32.4875,-7.45E-02,75.88,50,0.00E+00,20,0.9911
219.45799,32.6025,-7.89E-02,75.86727,50,0.00E+00,20,0.98975
220.565,32.7175,-8.34E-02,75.85636,50,0.00E+00,20,0.98839
221.66701,32.8325,-8.77E-02,75.84182,50,0.00E+00,20,0.98705
222.761,32.9475,-9.19E-02,75.83091,50,0.00E+00,20,0.98571
223.85899,33.0625,-9.59E-02,75.82364,50,0.00E+00,20,0.98437
224.944,33.1775,-1.00E-01,75.81091,50,0.00E+00,20,0.98305
226.049,33.2925,-0.10377,75.79818,50,0.00E+00,20,0.98171
227.14,33.4075,-0.10802,75.78545,50,0.00E+00,20,0.98038
228.22301,33.5225,-0.1117,75.77636,50,0.00E+00,20,0.97907
229.30701,33.6375,-0.1155,75.76909,50,0.00E+00,20,0.97775
230.381,33.7525,-0.11929,75.75455,50,0.00E+00,20,0.97645
231.463,33.8675,-0.12289,75.74727,50,0.00E+00,20,0.97515
232.532,33.9825,-0.12659,75.73636,50,0.00E+00,20,0.97386
233.62601,34.0975,-0.13012,75.72727,50,0.00E+00,20,0.97254
234.688,34.2125,-0.13377,75.72,50,0.00E+00,20,0.97126
235.756,34.3275,-0.13703,75.71091,50,0.00E+00,20,0.96998
236.851,34.4425,-0.14058,75.70182,50,0.00E+00,20,0.96866
237.929,34.5575,-0.14413,75.69273,50,0.00E+00,20,0.96737
239.00101,34.6725,-0.14745,75.68182,50,0.00E+00,20,0.96609
240.08099,34.7875,-0.15092,75.67091,50,0.00E+00,20,0.9648
241.16,34.9025,-0.15412,75.66364,50,0.00E+00,20,0.96351
242.23199,35.0175,-0.15745,75.65091,50,0.00E+00,20,0.96223
243.3,35.1325,-0.16074,75.64364,50,0.00E+00,20,0.96096
244.371,35.2475,-0.16397,75.63636,50,0.00E+00,20,0.95969
245.44,35.3625,-0.16676,75.62545,50,0.00E+00,20,0.95842
246.513,35.4775,-0.16985,75.61455,50,0.00E+00,20,0.95715
247.60001,35.5925,-0.17296,75.60727,50,0.00E+00,20,0.95586
248.677,35.7075,-0.17574,75.6,50,0.00E+00,20,0.95459
249.76199,35.8225,-0.17879,75.58909,50,0.00E+00,20,0.95331
250.851,35.9375,-0.18139,75.58,50,0.00E+00,20,0.95203
251.92999,36.0525,-0.18426,75.57273,50,0.00E+00,20,0.95076
253.00101,36.1675,-0.18721,75.56182,50,0.00E+00,20,0.9495
254.077,36.2825,-0.19006,75.55454,50,0.00E+00,20,0.94824
255.162,36.3975,-0.19285,75.54727,50,0.00E+00,20,0.94697
256.24399,36.5125,-0.1952,75.53818,50,0.00E+00,20,0.9457
257.33099,36.6275,-0.19827,75.53273,50,0.00E+00,20,0.94443
258.41599,36.7425,-0.20067,75.52364,50,0.00E+00,20,0.94317
259.508,36.8575,-0.20356,75.51636,50,0.00E+00,20,0.94189
260.59698,36.9725,-0.20627,75.50727,50,0.00E+00,20,0.94063
261.68799,37.0875,-0.20869,75.5,50,0.00E+00,20,0.93936
262.76599,37.2025,-0.2109,75.49273,50,0.00E+00,20,0.93811
263.86401,37.3175,-0.21344,75.48545,50,0.00E+00,20,0.93684
264.94901,37.4325,-0.21598,75.47818,50,0.00E+00,20,0.93559
266.03799,37.5475,-0.21851,75.46909,50,0.00E+00,20,0.93433
267.13699,37.6625,-0.22074,75.46,50,0.00E+00,20,0.93306
268.23199,37.7775,-0.22321,75.45273,50,0.00E+00,20,0.93181
269.32101,37.8925,-0.22538,75.44364,50,0.00E+00,20,0.93055
270.414,38.0075,-0.22795,75.43636,50,0.00E+00,20,0.9293
271.513,38.1225,-0.23016,75.42909,50,0.00E+00,20,0.92804
272.612,38.2375,-0.23271,75.41818,50,0.00E+00,20,0.92679
273.71399,38.3525,-0.23498,75.41091,50,0.00E+00,20,0.92553
274.82199,38.4675,-0.23737,75.40545,50,0.00E+00,20,0.92427
275.91199,38.5825,-0.23979,75.39818,50,0.00E+00,20,0.92303
277.01501,38.6975,-0.24206,75.39091,50,0.00E+00,20,0.92178
278.12799,38.8125,-0.24441,75.38182,50,0.00E+00,20,0.92051
279.22299,38.9275,-0.24658,75.37455,50,0.00E+00,20,0.91928
280.345,39.0425,-0.24869,75.36364,50,0.00E+00,20,0.91801
281.44299,39.1575,-0.25063,75.35273,50,0.00E+00,20,0.91677
282.53799,39.2725,-0.25248,75.34545,50,0.00E+00,20,0.91554
283.647,39.3875,-0.25475,75.33454,50,0.00E+00,20,0.91429
284.77399,39.5025,-0.2567,75.32727,50,0.00E+00,20,0.91302
285.86499,39.6175,-0.25858,75.32,50,0.00E+00,20,0.9118
286.97101,39.7325,-0.2609,75.31091,50,0.00E+00,20,0.91056
288.08899,39.8475,-0.2629,75.3,50,0.00E+00,20,0.90932
289.21201,39.9625,-0.26481,75.28909,50,0.00E+00,20,0.90806
290.34399,40.0775,-0.2668,75.28182,50,0.00E+00,20,0.9068
291.44,40.1925,-0.26887,75.26909,50,0.00E+00,20,0.90559
292.55499,40.3075,-0.27087,75.26,50,0.00E+00,20,0.90435
293.65799,40.4225,-0.27306,75.25091,50,0.00E+00,20,0.90313
294.78699,40.5375,-0.27504,75.24,50,0.00E+00,20,0.90188
295.90302,40.6525,-0.27706,75.23091,50,0.00E+00,20,0.90065
297.02399,40.7675,-0.27885,75.22,50,0.00E+00,20,0.89942
298.13,40.8825,-0.28108,75.20909,50,0.00E+00,20,0.8982
299.25101,40.9975,-0.28306,75.2,50,0.00E+00,20,0.89697
300.38,41.1125,-0.28506,75.18909,50,0.00E+00,20,0.89573
301.487,41.2275,-0.28696,75.17818,50,0.00E+00,20,0.89452
302.608,41.3425,-0.28917,75.16727,50,0.00E+00,20,0.8933
303.73599,41.4575,-0.29131,75.15818,50,0.00E+00,20,0.89207
304.87299,41.5725,-0.29307,75.14546,50,0.00E+00,20,0.89083
305.991,41.6875,-0.29526,75.13091,50,0.00E+00,20,0.88962
307.116,41.8025,-0.29707,75.12364,50,0.00E+00,20,0.8884
308.255,41.9175,-0.29897,75.11273,50,0.00E+00,20,0.88717
309.383,42.0325,-0.3009,75.10182,50,0.00E+00,20,0.88595
310.51199,42.1475,-0.30287,75.09273,50,0.00E+00,20,0.88474
311.62601,42.2625,-0.3046,75.08182,50,0.00E+00,20,0.88354
312.763,42.3775,-0.30647,75.06909,50,0.00E+00,20,0.88232
313.89001,42.4925,-0.30873,75.05818,50,0.00E+00,20,0.88111
315.01501,42.6075,-0.31054,75.04727,50,0.00E+00,20,0.87991
316.13599,42.7225,-0.31199,75.03455,50,0.00E+00,20,0.87871
317.259,42.8375,-0.31355,75.02182,50,0.00E+00,20,0.87751
318.38699,42.9525,-0.31488,75.01091,50,0.00E+00,20,0.87631
319.526,43.0675,-0.31622,75,50,0.00E+00,20,0.8751
320.64099,43.1825,-0.31728,74.98364,50,0.00E+00,20,0.87392
321.771,43.2975,-0.31864,74.97455,50,0.00E+00,20,0.87273
322.90201,43.4125,-0.32006,74.96182,50,0.00E+00,20,0.87153
324.026,43.5275,-0.32129,74.94909,50,0.00E+00,20,0.87035
325.15601,43.6425,-0.32256,74.93636,50,0.00E+00,20,0.86916
326.30701,43.7575,-0.32349,74.92364,50,0.00E+00,20,0.86796
327.431,43.8725,-0.32486,74.91091,50,0.00E+00,20,0.86678
328.55801,43.9875,-0.32594,74.89636,50,0.00E+00,20,0.8656
329.69601,44.1025,-0.32742,74.88,50,0.00E+00,20,0.86441
330.82101,44.2175,-0.32847,74.86727,50,0.00E+00,20,0.86324
331.95901,44.3325,-0.33037,74.85273,50,0.00E+00,20,0.86206
333.10599,44.4475,-0.33157,74.83818,50,0.00E+00,20,0.86087
334.22198,44.5625,-0.33298,74.82364,50,0.00E+00,20,0.85972
335.37,44.6775,-0.33452,74.81091,50,0.00E+00,20,0.85853
336.508,44.7925,-0.33606,74.79818,50,0.00E+00,20,0.85736
337.64899,44.9075,-0.33772,74.78182,50,0.00E+00,20,0.85618
338.78299,45.0225,-0.33974,74.76545,50,0.00E+00,20,0.85502
339.914,45.1375,-0.34131,74.75091,50,0.00E+00,20,0.85386
341.043,45.2525,-0.34366,74.73455,50,0.00E+00,20,0.85271
342.172,45.3675,-0.34555,74.71818,50,0.00E+00,20,0.85155
343.30399,45.4825,-0.34809,74.70364,50,0.00E+00,20,0.8504
344.46201,45.5975,-0.35072,74.68909,50,0.00E+00,20,0.84923
345.586,45.7125,-0.35377,74.67636,50,0.00E+00,20,0.84809
346.728,45.8275,-0.35699,74.65818,50,0.00E+00,20,0.84693
347.88599,45.9425,-0.36017,74.64,50,0.00E+00,20,0.84576
349.01199,46.0575,-0.36363,74.62727,50,0.00E+00,20,0.84463
350.155,46.1725,-0.36725,74.62,50,0.00E+00,20,0.84348
351.32401,46.2875,-0.37122,74.60545,50,0.00E+00,20,0.8423
352.466,46.4025,-0.37519,74.58909,50,0.00E+00,20,0.84116
353.617,46.5175,-0.37849,74.57818,50,0.00E+00,20,0.84001
354.746,46.6325,-0.38156,74.56727,50,0.00E+00,20,0.83888
355.897,46.7475,-0.38442,74.55273,50,0.00E+00,20,0.83774
357.034,46.8625,-0.38736,74.54,50,0.00E+00,20,0.83661
358.186,46.9775,-0.39045,74.52727,50,0.00E+00,20,0.83547
359.31201,47.0925,-0.39371,74.51273,50,0.00E+00,20,0.83435
360.45499,47.2075,-0.39687,74.50182,50,0.00E+00,20,0.83323
361.58701,47.3225,-0.40026,74.48909,50,0.00E+00,20,0.83211
362.73499,47.4375,-0.40359,74.47636,50,0.00E+00,20,0.83098
363.867,47.5525,-0.40665,74.46727,50,0.00E+00,20,0.82988
365.00699,47.6675,-0.41001,74.45818,50,0.00E+00,20,0.82876
366.13901,47.7825,-0.41364,74.44909,50,0.00E+00,20,0.82766
367.27701,47.8975,-0.4175,74.43636,50,0.00E+00,20,0.82655
368.41699,48.0125,-0.421,74.42364,50,0.00E+00,20,0.82544
369.54901,48.1275,-0.42422,74.41636,50,0.00E+00,20,0.82434
370.68201,48.2425,-0.42698,74.40727,50,0.00E+00,20,0.82324
371.81699,48.3575,-0.43026,74.39636,50,0.00E+00,20,0.82215
372.95599,48.4725,-0.43385,74.38545,50,0.00E+00,20,0.82105
374.08401,48.5875,-0.43731,74.37818,50,0.00E+00,20,0.81997
375.23901,48.7025,-0.44046,74.37091,50,0.00E+00,20,0.81886
376.37,48.8175,-0.44406,74.36,50,0.00E+00,20,0.81778
377.51901,48.9325,-0.4474,74.35273,50,0.00E+00,20,0.81668
378.65201,49.0475,-0.45066,74.34727,50,0.00E+00,20,0.8156
379.793,49.1625,-0.45361,74.34,50,0.00E+00,20,0.81452
380.931,49.2775,-0.45658,74.33091,50,0.00E+00,20,0.81344
382.06201,49.3925,-0.45933,74.32545,50,0.00E+00,20,0.81237
383.20801,49.5075,-0.46237,74.32,50,0.00E+00,20,0.81128
384.349,49.6225,-0.46509,74.31273,50,0.00E+00,20,0.81021
385.49399,49.7375,-0.46789,74.30545,50,0.00E+00,20,0.80913
386.62799,49.8525,-0.47072,74.29636,50,0.00E+00,20,0.80807
387.76999,49.9675,-0.47378,74.29455,50,0.00E+00,20,0.807
388.91299,50.0825,-0.47694,74.28546,50,0.00E+00,20,0.80593
390.05499,50.1975,-0.47967,74.28182,50,0.00E+00,20,0.80487
391.18399,50.3125,-0.48265,74.27455,50,0.00E+00,20,0.80382
392.34201,50.4275,-0.48542,74.27091,50,0.00E+00,20,0.80275
393.48199,50.5425,-0.48855,74.26364,50,0.00E+00,20,0.80169
394.625,50.6575,-0.49113,74.25636,50,0.00E+00,20,0.80064
395.76199,50.7725,-0.49375,74.25636,50,0.00E+00,20,0.79959
396.91,50.8875,-0.49614,74.24727,50,0.00E+00,20,0.79854
398.04599,51.0025,-0.49884,74.23636,50,0.00E+00,20,0.79749
399.18701,51.1175,-0.50089,74.23636,50,0.00E+00,20,0.79645
400.30301,51.2325,-0.50303,74.23273,50,0.00E+00,20,0.79543
401.457,51.3475,-0.50553,74.22182,50,0.00E+00,20,0.79438
402.59601,51.4625,-0.50755,74.21818,50,0.00E+00,20,0.79335
403.73401,51.5775,-0.51024,74.21455,50,0.00E+00,20,0.79232
404.86499,51.6925,-0.5128,74.20727,50,0.00E+00,20,0.7913
406.01099,51.8075,-0.51596,74.20182,50,0.00E+00,20,0.79026
407.16,51.9225,-0.51859,74.20182,50,0.00E+00,20,0.78923
408.311,52.0375,-0.52117,74.19636,50,0.00E+00,20,0.7882
409.45901,52.1525,-0.52375,74.19273,50,0.00E+00,20,0.78717
410.586,52.2675,-0.52588,74.18909,50,0.00E+00,20,0.78616
411.746,52.3825,-0.52795,74.18182,50,0.00E+00,20,0.78513
412.88199,52.4975,-0.53033,74.17636,50,0.00E+00,20,0.78412
414.008,52.6125,-0.53276,74.17455,50,0.00E+00,20,0.78312
415.15302,52.7275,-0.53503,74.16727,50,0.00E+00,20,0.78211
416.28201,52.8425,-0.53703,74.16364,50,0.00E+00,20,0.78111
417.444,52.9575,-0.53908,74.15636,50,0.00E+00,20,0.78009
418.582,53.0725,-0.54127,74.14727,50,0.00E+00,20,0.77909
419.71399,53.1875,-0.54324,74.14727,50,0.00E+00,20,0.7781
420.849,53.3025,-0.54522,74.14182,50,0.00E+00,20,0.7771
421.983,53.4175,-0.54701,74.13636,50,0.00E+00,20,0.77612
423.13699,53.5325,-0.54927,74.12727,50,0.00E+00,20,0.77511
424.284,53.6475,-0.55148,74.12,50,0.00E+00,20,0.77412
425.41599,53.7625,-0.55331,74.11818,50,0.00E+00,20,0.77314
426.552,53.8775,-0.5559,74.10909,50,0.00E+00,20,0.77216
427.70001,53.9925,-0.55811,74.10545,50,0.00E+00,20,0.77117
428.83499,54.1075,-0.56044,74.09818,50,0.00E+00,20,0.77019
429.983,54.2225,-0.56317,74.08909,50,0.00E+00,20,0.76921
431.12299,54.3375,-0.56515,74.08545,50,0.00E+00,20,0.76823
432.272,54.4525,-0.56696,74.08,50,0.00E+00,20,0.76725
433.40201,54.5675,-0.56903,74.07636,50,0.00E+00,20,0.76629
434.54099,54.6825,-0.57091,74.07091,50,0.00E+00,20,0.76532
435.69101,54.7975,-0.57332,74.06727,50,0.00E+00,20,0.76435
436.823,54.9125,-0.57535,74.06182,50,0.00E+00,20,0.76339
437.979,55.0275,-0.57843,74.05636,50,0.00E+00,20,0.76242
439.11499,55.1425,-0.58116,74.05273,50,0.00E+00,20,0.76147
440.26501,55.2575,-0.58335,74.04909,50,0.00E+00,20,0.7605
441.40799,55.3725,-0.58588,74.04545,50,0.00E+00,20,0.75955
442.556,55.4875,-0.58845,74.04182,50,0.00E+00,20,0.75859
443.703,55.6025,-0.59113,74.04182,50,0.00E+00,20,0.75764
444.86301,55.7175,-0.59388,74.03455,50,0.00E+00,20,0.75667
446.009,55.8325,-0.59631,74.03091,50,0.00E+00,20,0.75572
447.14801,55.9475,-0.59834,74.02909,50,0.00E+00,20,0.75478
448.30099,56.0625,-0.60057,74.02364,50,0.00E+00,20,0.75383
449.45401,56.1775,-0.60276,74.02,50,0.00E+00,20,0.75289
450.59399,56.2925,-0.60395,74.02,50,0.00E+00,20,0.75195
451.74799,56.4075,-0.60521,74.01273,50,0.00E+00,20,0.75101
452.88501,56.5225,-0.60671,74.00909,50,0.00E+00,20,0.75008
454.03699,56.6375,-0.60827,74.00546,50,0.00E+00,20,0.74915
455.168,56.7525,-0.6102,74.00182,50,0.00E+00,20,0.74823
456.30301,56.8675,-0.61238,73.99818,50,0.00E+00,20,0.74731
457.45099,56.9825,-0.61451,73.99273,50,0.00E+00,20,0.74639
458.591,57.0975,-0.61657,73.99091,50,0.00E+00,20,0.74547
459.728,57.2125,-0.61873,73.98727,50,0.00E+00,20,0.74456
460.86899,57.3275,-0.62077,73.98364,50,0.00E+00,20,0.74364
462.004,57.4425,-0.62252,73.98,50,0.00E+00,20,0.74274
463.159,57.5575,-0.6246,73.97455,50,0.00E+00,20,0.74182
464.297,57.6725,-0.62628,73.97455,50,0.00E+00,20,0.74091
465.43701,57.7875,-0.62856,73.96727,50,0.00E+00,20,0.74001
466.564,57.9025,-0.6302,73.96727,50,0.00E+00,20,0.73912
467.71799,58.0175,-0.63216,73.96182,50,0.00E+00,20,0.73821
468.85901,58.1325,-0.63376,73.95818,50,0.00E+00,20,0.73731
469.98999,58.2475,-0.63579,73.95455,50,0.00E+00,20,0.73643
471.133,58.3625,-0.63733,73.95091,50,0.00E+00,20,0.73553
472.27899,58.4775,-0.63901,73.94545,50,0.00E+00,20,0.73464
473.41199,58.5925,-0.64078,73.94545,50,0.00E+00,20,0.73376
474.565,58.7075,-0.64329,73.94,50,0.00E+00,20,0.73286
475.72198,58.8225,-0.64654,73.93636,50,0.00E+00,20,0.73197
476.901,58.9375,-0.65038,73.93273,50,0.00E+00,20,0.73106
478.06201,59.0525,-0.65346,73.92727,50,0.00E+00,20,0.73016
479.23999,59.1675,-0.65544,73.92364,50,0.00E+00,20,0.72926
480.36801,59.2825,-0.6562,73.92,50,0.00E+00,20,0.72839
481.48499,59.3975,-0.65568,73.91636,50,0.00E+00,20,0.72754
482.62399,59.5125,-0.65556,73.91273,50,0.00E+00,20,0.72667
483.76901,59.6275,-0.65663,73.90909,50,0.00E+00,20,0.7258
484.923,59.7425,-0.65901,73.90545,50,0.00E+00,20,0.72493
486.09399,59.8575,-0.66168,73.90182,50,0.00E+00,20,0.72405
487.228,59.9725,-0.66436,73.89273,50,0.00E+00,20,0.72319
488.39099,60.0875,-0.66647,73.88909,50,0.00E+00,20,0.72232
489.54001,60.2025,-0.66803,73.88182,50,0.00E+00,20,0.72146
490.685,60.3175,-0.66973,73.87636,50,0.00E+00,20,0.7206
491.83899,60.4325,-0.67088,73.87273,50,0.00E+00,20,0.71974
492.978,60.5475,-0.67178,73.86909,50,0.00E+00,20,0.71889
494.108,60.6625,-0.67278,73.86545,50,0.00E+00,20,0.71806
495.246,60.7775,-0.67442,73.86,50,0.00E+00,20,0.71721
496.39301,60.8925,-0.67562,73.85636,50,0.00E+00,20,0.71637
497.52802,61.0075,-0.67672,73.85273,50,0.00E+00,20,0.71553
498.664,61.1225,-0.67811,73.84727,50,0.00E+00,20,0.7147
499.797,61.2375,-0.67958,73.84182,50,0.00E+00,20,0.71387
500.95099,61.3525,-0.68186,73.83636,50,0.00E+00,20,0.71303
502.11301,61.4675,-0.68491,73.83091,50,0.00E+00,20,0.71218
503.25,61.5825,-0.68732,73.82727,50,0.00E+00,20,0.71136
504.401,61.6975,-0.68975,73.82,50,0.00E+00,20,0.71053
505.56,61.8125,-0.6925,73.82,50,0.00E+00,20,0.70969
506.72501,61.9275,-0.69531,73.81455,50,0.00E+00,20,0.70885
507.89099,62.0425,-0.69784,73.81091,50,0.00E+00,20,0.70801
509.047,62.1575,-0.69928,73.80727,50,0.00E+00,20,0.70719
510.20001,62.2725,-0.69943,73.80182,50,0.00E+00,20,0.70636
511.30499,62.3875,-0.69911,73.79636,50,0.00E+00,20,0.70558
512.43402,62.5025,-0.69843,73.79636,50,0.00E+00,20,0.70478
513.56299,62.6175,-0.69824,73.78727,50,0.00E+00,20,0.70398
514.68903,62.7325,-0.69883,73.78364,50,0.00E+00,20,0.70318
515.82098,62.8475,-0.70027,73.78,50,0.00E+00,20,0.70238
516.98199,62.9625,-0.70308,73.77636,50,0.00E+00,20,0.70157
518.12903,63.0775,-0.70666,73.77273,50,0.00E+00,20,0.70077
519.29401,63.1925,-0.71004,73.76545,50,0.00E+00,20,0.69995
520.448,63.3075,-0.71292,73.76,50,0.00E+00,20,0.69915
521.59399,63.4225,-0.71456,73.75818,50,0.00E+00,20,0.69835
522.75,63.5375,-0.7157,73.75091,50,0.00E+00,20,0.69755
523.91602,63.6525,-0.71788,73.74364,50,0.00E+00,20,0.69675
525.07202,63.7675,-0.72048,73.74,50,0.00E+00,20,0.69595
526.24701,63.8825,-0.72289,73.74,50,0.00E+00,20,0.69514
527.41302,63.9975,-0.72472,73.73091,50,0.00E+00,20,0.69435
528.58197,64.1125,-0.72634,73.72364,50,0.00E+00,20,0.69355
529.70697,64.2275,-0.72696,73.72,50,0.00E+00,20,0.69278
530.86499,64.3425,-0.72722,73.70909,50,0.00E+00,20,0.69199
532.00598,64.4575,-0.72822,73.70545,50,0.00E+00,20,0.69122
533.15601,64.5725,-0.7289,73.70182,50,0.00E+00,20,0.69045
534.297,64.6875,-0.72951,73.69818,50,0.00E+00,20,0.68968
535.44702,64.8025,-0.73141,73.68909,50,0.00E+00,20,0.6889
536.59003,64.9175,-0.73291,73.68545,50,0.00E+00,20,0.68814
537.74298,65.0325,-0.73492,73.68182,50,0.00E+00,20,0.68737
538.89001,65.1475,-0.73679,73.67636,50,0.00E+00,20,0.6866
540.04303,65.2625,-0.73854,73.66909,50,0.00E+00,20,0.68584
541.19,65.3775,-0.73995,73.66182,50,0.00E+00,20,0.68508
542.35101,65.4925,-0.74163,73.65455,50,0.00E+00,20,0.68431
543.48999,65.6075,-0.74283,73.64727,50,0.00E+00,20,0.68356
544.63898,65.7225,-0.74473,73.64182,50,0.00E+00,20,0.68281
545.78699,65.8375,-0.74612,73.63455,50,0.00E+00,20,0.68206
546.92603,65.9525,-0.74732,73.63091,50,0.00E+00,20,0.68131
548.08398,66.0675,-0.74882,73.62182,50,0.00E+00,20,0.68056
549.20697,66.1825,-0.75011,73.61454,50,0.00E+00,20,0.67983
550.35901,66.2975,-0.75139,73.60727,50,0.00E+00,20,0.67908
551.48999,66.4125,-0.75234,73.60364,50,0.00E+00,20,0.67835
552.65698,66.5275,-0.75334,73.59818,50,0.00E+00,20,0.6776
553.79498,66.6425,-0.75557,73.59091,50,0.00E+00,20,0.67687
554.94598,66.7575,-0.75781,73.58364,50,0.00E+00,20,0.67613
556.10498,66.8725,-0.76055,73.57636,50,0.00E+00,20,0.67539
557.27399,66.9875,-0.76295,73.57091,50,0.00E+00,20,0.67465
558.42902,67.1025,-0.76456,73.56364,50,0.00E+00,20,0.67391
559.57703,67.2175,-0.76611,73.55454,50,0.00E+00,20,0.67319
560.73102,67.3325,-0.76725,73.54727,50,0.00E+00,20,0.67246
561.88397,67.4475,-0.76795,73.54,50,0.00E+00,20,0.67173
563.03699,67.5625,-0.76893,73.53273,50,0.00E+00,20,0.67101
564.177,67.6775,-0.76931,73.52727,50,0.00E+00,20,0.67029
565.32397,67.7925,-0.77034,73.52,50,0.00E+00,20,0.66958
566.45398,67.9075,-0.77127,73.51273,50,0.00E+00,20,0.66887
567.60999,68.0225,-0.77231,73.50727,50,0.00E+00,20,0.66816
568.75098,68.1375,-0.77354,73.49818,50,0.00E+00,20,0.66745
569.89502,68.2525,-0.77519,73.49091,50,0.00E+00,20,0.66674
571.03497,68.3675,-0.77578,73.48545,50,0.00E+00,20,0.66604
572.18298,68.4825,-0.77719,73.48,50,0.00E+00,20,0.66534
573.34003,68.5975,-0.77833,73.47455,50,0.00E+00,20,0.66463
574.48199,68.7125,-0.78038,73.46727,50,0.00E+00,20,0.66393
575.625,68.8275,-0.7826,73.46,50,0.00E+00,20,0.66324
576.76801,68.9425,-0.78424,73.45273,50,0.00E+00,20,0.66254
577.914,69.0575,-0.786,73.44545,50,0.00E+00,20,0.66185
579.05902,69.1725,-0.78806,73.44182,50,0.00E+00,20,0.66116
580.216,69.2875,-0.78956,73.43273,50,0.00E+00,20,0.66046
581.367,69.4025,-0.79098,73.42545,50,0.00E+00,20,0.65977
582.51001,69.5175,-0.79249,73.41636,50,0.00E+00,20,0.65909
583.64697,69.6325,-0.79384,73.41273,50,0.00E+00,20,0.65841
584.797,69.7475,-0.79572,73.40545,50,0.00E+00,20,0.65772
585.95502,69.8625,-0.79841,73.39636,50,0.00E+00,20,0.65704
587.117,69.9775,-0.80111,73.39273,50,0.00E+00,20,0.65635
588.28003,70.0925,-0.80319,73.38182,50,0.00E+00,20,0.65566
589.42798,70.2075,-0.80425,73.37636,50,0.00E+00,20,0.65499
590.57202,70.3225,-0.80533,73.37273,50,0.00E+00,20,0.65431
591.72699,70.4375,-0.80572,73.36364,50,0.00E+00,20,0.65364
592.87,70.5525,-0.80682,73.35818,50,0.00E+00,20,0.65297
594.013,70.6675,-0.80856,73.34364,50,0.00E+00,20,0.65231
595.17499,70.7825,-0.81129,73.33636,50,0.00E+00,20,0.65163
596.34601,70.8975,-0.81382,73.33091,50,0.00E+00,20,0.65095
597.51398,71.0125,-0.81637,73.32364,50,0.00E+00,20,0.65028
598.67603,71.1275,-0.81774,73.31273,50,0.00E+00,20,0.64961
599.82098,71.2425,-0.81944,73.30727,50,0.00E+00,20,0.64896
600.97498,71.3575,-0.81998,73.30182,50,0.00E+00,20,0.6483
602.13599,71.4725,-0.82045,73.29273,50,0.00E+00,20,0.64763
603.27802,71.5875,-0.82134,73.28727,50,0.00E+00,20,0.64698
604.44598,71.7025,-0.82229,73.27818,50,0.00E+00,20,0.64632
605.59198,71.8175,-0.82312,73.27091,50,0.00E+00,20,0.64567
606.74103,71.9325,-0.82476,73.26,50,0.00E+00,20,0.64502
607.888,72.0475,-0.82569,73.25091,50,0.00E+00,20,0.64438
609.04401,72.1625,-0.8264,73.24182,50,0.00E+00,20,0.64373
610.19,72.2775,-0.8275,73.23273,50,0.00E+00,20,0.64309
611.34998,72.3925,-0.8287,73.22364,50,0.00E+00,20,0.64244
612.47601,72.5075,-0.82996,73.22,50,0.00E+00,20,0.64182
613.63098,72.6225,-0.83008,73.21273,50,0.00E+00,20,0.64118
614.77399,72.7375,-0.83068,73.20364,50,0.00E+00,20,0.64054
615.92297,72.8525,-0.83094,73.19455,50,0.00E+00,20,0.63991
617.065,72.9675,-0.83148,73.18545,50,0.00E+00,20,0.63928
618.21301,73.0825,-0.83349,73.17818,50,0.00E+00,20,0.63865
619.36798,73.1975,-0.83584,73.17091,50,0.00E+00,20,0.63802
620.54199,73.3125,-0.83842,73.16182,50,0.00E+00,20,0.63738
621.70203,73.4275,-0.8411,73.15455,50,0.00E+00,20,0.63675
622.87402,73.5425,-0.84303,73.14545,50,0.00E+00,20,0.63611
624.03998,73.6575,-0.84459,73.13818,50,0.00E+00,20,0.63548
625.18903,73.7725,-0.84531,73.12727,50,0.00E+00,20,0.63486
626.328,73.8875,-0.84536,73.11636,50,0.00E+00,20,0.63425
627.492,74.0025,-0.8447,73.11091,50,0.00E+00,20,0.63362
628.617,74.1175,-0.84467,73.1,50,0.00E+00,20,0.63302
629.75299,74.2325,-0.84421,73.08909,50,0.00E+00,20,0.63242
630.91101,74.3475,-0.84418,73.08545,50,0.00E+00,20,0.6318
632.05499,74.4625,-0.84554,73.07455,50,0.00E+00,20,0.63119
633.203,74.5775,-0.84651,73.06727,50,0.00E+00,20,0.63059
634.34802,74.6925,-0.84749,73.05636,50,0.00E+00,20,0.62998
635.513,74.8075,-0.84891,73.04727,50,0.00E+00,20,0.62937
636.65698,74.9225,-0.84944,73.04,50,0.00E+00,20,0.62877
637.80798,75.0375,-0.85027,73.03273,50,0.00E+00,20,0.62817
638.95599,75.1525,-0.85159,73.02364,50,0.00E+00,20,0.62757
640.112,75.2675,-0.85345,73.01091,50,0.00E+00,20,0.62696
641.26898,75.3825,-0.85482,73.00545,50,0.00E+00,20,0.62636
642.41901,75.4975,-0.85475,72.99818,50,0.00E+00,20,0.62577
643.573,75.6125,-0.85541,72.98909,50,0.00E+00,20,0.62517
644.70801,75.7275,-0.85572,72.98182,50,0.00E+00,20,0.62459
645.85602,75.8425,-0.85613,72.96909,50,0.00E+00,20,0.624
647.01898,75.9575,-0.85735,72.96182,50,0.00E+00,20,0.6234
648.15503,76.0725,-0.8577,72.94909,50,0.00E+00,20,0.62282
649.323,76.1875,-0.85857,72.93818,50,0.00E+00,20,0.62223
650.466,76.3025,-0.85903,72.92909,50,0.00E+00,20,0.62165
651.62799,76.4175,-0.85998,72.92,50,0.00E+00,20,0.62106
652.79102,76.5325,-0.86104,72.90909,50,0.00E+00,20,0.62047
653.96301,76.6475,-0.86349,72.90182,50,0.00E+00,20,0.61988
655.12097,76.7625,-0.86529,72.88909,50,0.00E+00,20,0.6193
656.27698,76.8775,-0.86568,72.88,50,0.00E+00,20,0.61872
657.43402,76.9925,-0.86574,72.87091,50,0.00E+00,20,0.61814
658.59399,77.1075,-0.8651,72.85636,50,0.00E+00,20,0.61756
659.72699,77.2225,-0.86505,72.84727,50,0.00E+00,20,0.617
660.89301,77.3375,-0.86483,72.83636,50,0.00E+00,20,0.61642
662.03003,77.4525,-0.86397,72.82727,50,0.00E+00,20,0.61586
663.164,77.5675,-0.86332,72.81818,50,0.00E+00,20,0.6153
664.315,77.6825,-0.86251,72.80727,50,0.00E+00,20,0.61474
665.44702,77.7975,-0.86232,72.79636,50,0.00E+00,20,0.61418
666.59198,77.9125,-0.86191,72.78364,50,0.00E+00,20,0.61362
667.74103,78.0275,-0.86184,72.77636,50,0.00E+00,20,0.61306
668.875,78.1425,-0.86137,72.76727,50,0.00E+00,20,0.61251
670.01398,78.2575,-0.86162,72.75818,50,0.00E+00,20,0.61195
671.146,78.3725,-0.86167,72.74727,50,0.00E+00,20,0.61141
672.29999,78.4875,-0.86182,72.73636,50,0.00E+00,20,0.61085
673.45599,78.6025,-0.86256,72.72545,50,0.00E+00,20,0.61029
674.60303,78.7175,-0.86343,72.71273,50,0.00E+00,20,0.60974
675.76398,78.8325,-0.86372,72.70364,50,0.00E+00,20,0.60919
676.91302,78.9475,-0.86416,72.68909,50,0.00E+00,20,0.60864
678.04999,79.0625,-0.86385,72.67455,50,0.00E+00,20,0.60809
679.21002,79.1775,-0.86357,72.66545,50,0.00E+00,20,0.60754
680.34198,79.2925,-0.86303,72.65455,50,0.00E+00,20,0.60701
681.50299,79.4075,-0.86216,72.64545,50,0.00E+00,20,0.60646
682.646,79.5225,-0.86167,72.63455,50,0.00E+00,20,0.60592
683.80499,79.6375,-0.86226,72.62364,50,0.00E+00,20,0.60537
684.98297,79.7525,-0.86321,72.61455,50,0.00E+00,20,0.60482
686.14398,79.8675,-0.86394,72.60364,50,0.00E+00,20,0.60427
687.31799,79.9825,-0.86431,72.59091,50,0.00E+00,20,0.60373
688.474,80.0975,-0.86412,72.57818,50,0.00E+00,20,0.60319
689.63898,80.2125,-0.86354,72.56727,50,0.00E+00,20,0.60265
690.80701,80.3275,-0.86318,72.55636,50,0.00E+00,20,0.60211
691.96802,80.4425,-0.86317,72.54364,50,0.00E+00,20,0.60157
693.12701,80.5575,-0.86318,72.53091,50,0.00E+00,20,0.60103
694.28998,80.6725,-0.86274,72.52,50,0.00E+00,20,0.6005
695.44299,80.7875,-0.86235,72.50727,50,0.00E+00,20,0.59997
696.58801,80.9025,-0.86181,72.49818,50,0.00E+00,20,0.59945
697.73999,81.0175,-0.86036,72.48545,50,0.00E+00,20,0.59892
698.883,81.1325,-0.85861,72.47455,50,0.00E+00,20,0.5984
700.01898,81.2475,-0.85793,72.46182,50,0.00E+00,20,0.59788
701.172,81.3625,-0.85762,72.45091,50,0.00E+00,20,0.59736
702.323,81.4775,-0.85808,72.44,50,0.00E+00,20,0.59684
703.474,81.5925,-0.85874,72.42909,50,0.00E+00,20,0.59632
704.63098,81.7075,-0.85958,72.42,50,0.00E+00,20,0.5958
705.77399,81.8225,-0.8599,72.41273,50,0.00E+00,20,0.59529
706.92499,81.9375,-0.86011,72.4,50,0.00E+00,20,0.59477
708.06403,82.0525,-0.85973,72.38909,50,0.00E+00,20,0.59427
709.20801,82.1675,-0.85962,72.38,50,0.00E+00,20,0.59376
710.35303,82.2825,-0.85915,72.36727,50,0.00E+00,20,0.59325
711.48999,82.3975,-0.85838,72.36182,50,0.00E+00,20,0.59274
712.64099,82.5125,-0.8587,72.35091,50,0.00E+00,20,0.59223
713.80298,82.6275,-0.86024,72.34364,50,0.00E+00,20,0.59172
715.01001,82.7425,-0.86408,72.33454,50,0.00E+00,20,0.59119
716.20001,82.8575,-0.86677,72.32182,50,0.00E+00,20,0.59067
717.388,82.9725,-0.86843,72.31636,50,0.00E+00,20,0.59015
718.55902,83.0875,-0.86841,72.30909,50,0.00E+00,20,0.58963
719.71997,83.2025,-0.8672,72.3,50,0.00E+00,20,0.58913
720.87402,83.3175,-0.86523,72.29273,50,0.00E+00,20,0.58863
722.01599,83.4325,-0.86339,72.28545,50,0.00E+00,20,0.58813
723.14899,83.5475,-0.86137,72.27636,50,0.00E+00,20,0.58764
724.276,83.6625,-0.86064,72.26909,50,0.00E+00,20,0.58715
725.41602,83.7775,-0.85888,72.26364,50,0.00E+00,20,0.58666
726.56598,83.8925,-0.85875,72.25273,50,0.00E+00,20,0.58617
727.71002,84.0075,-0.85848,72.24727,50,0.00E+00,20,0.58568
728.85303,84.1225,-0.85815,72.24,50,0.00E+00,20,0.58519
730.008,84.2375,-0.85783,72.22909,50,0.00E+00,20,0.58469
731.15198,84.3525,-0.85786,72.22364,50,0.00E+00,20,0.58421
732.29602,84.4675,-0.85687,72.21273,50,0.00E+00,20,0.58372
733.42902,84.5825,-0.85469,72.20909,50,0.00E+00,20,0.58324
734.56,84.6975,-0.85333,72.20182,50,0.00E+00,20,0.58276
735.70502,84.8125,-0.85137,72.19455,50,0.00E+00,20,0.58228
736.83502,84.9275,-0.85028,72.18727,50,0.00E+00,20,0.5818
737.953,85.0425,-0.84891,72.17818,50,0.00E+00,20,0.58133
739.08899,85.1575,-0.84741,72.17091,50,0.00E+00,20,0.58085
740.224,85.2725,-0.84681,72.16364,50,0.00E+00,20,0.58038
741.37299,85.3875,-0.84618,72.15636,50,0.00E+00,20,0.5799
742.55298,85.5025,-0.84855,72.15091,50,0.00E+00,20,0.5794
743.75098,85.6175,-0.85225,72.14364,50,0.00E+00,20,0.57891
744.95502,85.7325,-0.8557,72.13818,50,0.00E+00,20,0.57841
746.13599,85.8475,-0.8568,72.13273,50,0.00E+00,20,0.57792
747.30402,85.9625,-0.85589,72.12545,50,0.00E+00,20,0.57743
748.46198,86.0775,-0.85371,72.11818,50,0.00E+00,20,0.57696
749.61603,86.1925,-0.85078,72.11273,50,0.00E+00,20,0.57648
750.75201,86.3075,-0.84839,72.10727,50,0.00E+00,20,0.57602
751.91199,86.4225,-0.84526,72.10182,50,0.00E+00,20,0.57554
753.04602,86.5375,-0.84261,72.09636,50,0.00E+00,20,0.57508
754.17902,86.6525,-0.84058,72.09273,50,0.00E+00,20,0.57461
755.33197,86.7675,-0.83912,72.08727,50,0.00E+00,20,0.57414
756.49298,86.8825,-0.83921,72.08182,50,0.00E+00,20,0.57367
757.64502,86.9975,-0.8396,72.07273,50,0.00E+00,20,0.5732
758.80603,87.1125,-0.83937,72.06727,50,0.00E+00,20,0.57273
759.95398,87.2275,-0.83852,72.06182,50,0.00E+00,20,0.57227
761.091,87.3425,-0.83774,72.05273,50,0.00E+00,20,0.57181
762.22699,87.4575,-0.83593,72.04909,50,0.00E+00,20,0.57135
763.383,87.5725,-0.83394,72.04182,50,0.00E+00,20,0.57089
764.52698,87.6875,-0.83376,72.04182,50,0.00E+00,20,0.57043
765.67499,87.8025,-0.83458,72.03636,50,0.00E+00,20,0.56997
766.81897,87.9175,-0.83505,72.03091,50,0.00E+00,20,0.56951
767.97302,88.0325,-0.83549,72.02364,50,0.00E+00,20,0.56905
769.12598,88.1475,-0.8367,72.02,50,0.00E+00,20,0.5686
770.27698,88.2625,-0.83805,72.01454,50,0.00E+00,20,0.56814
771.427,88.3775,-0.83877,72.01091,50,0.00E+00,20,0.56768
772.57001,88.4925,-0.8401,72.00727,50,0.00E+00,20,0.56723
773.70398,88.6075,-0.84111,72.00364,50,0.00E+00,20,0.56678
774.85602,88.7225,-0.84387,71.99636,50,0.00E+00,20,0.56633
776.013,88.8375,-0.84592,71.99273,50,0.00E+00,20,0.56587
777.15997,88.9525,-0.84831,71.98727,50,0.00E+00,20,0.56542
778.30103,89.0675,-0.85095,71.98364,50,0.00E+00,20,0.56498
779.46899,89.1825,-0.85308,71.98,50,0.00E+00,20,0.56452
780.60602,89.2975,-0.85521,71.97273,50,0.00E+00,20,0.56407
781.76898,89.4125,-0.8585,71.96909,50,0.00E+00,20,0.56362
782.92902,89.5275,-0.86212,71.96364,50,0.00E+00,20,0.56317
784.073,89.6425,-0.86512,71.95818,50,0.00E+00,20,0.56272
785.23401,89.7575,-0.86794,71.95455,50,0.00E+00,20,0.56227
786.39801,89.8725,-0.87053,71.94727,50,0.00E+00,20,0.56182
787.54999,89.9875,-0.87364,71.94364,50,0.00E+00,20,0.56138
788.69501,90.1025,-0.87693,71.94,50,0.00E+00,20,0.56094
789.85999,90.2175,-0.87998,71.93273,50,0.00E+00,20,0.56049
791.02899,90.3325,-0.8853,71.92545,50,0.00E+00,20,0.56004
792.20001,90.4475,-0.89012,71.92182,50,0.00E+00,20,0.55959
793.37,90.5625,-0.89476,71.91455,50,0.00E+00,20,0.55914
794.53998,90.6775,-0.8985,71.91091,50,0.00E+00,20,0.55869
795.69299,90.7925,-0.90284,71.90545,50,0.00E+00,20,0.55825
796.849,90.9075,-0.90644,71.89818,50,0.00E+00,20,0.55781
797.995,91.0225,-0.90921,71.89091,50,0.00E+00,20,0.55738
799.151,91.1375,-0.9117,71.88546,50,0.00E+00,20,0.55694
800.29401,91.2525,-0.915,71.88,50,0.00E+00,20,0.5565
801.46503,91.3675,-0.91825,71.87273,50,0.00E+00,20,0.55606
802.60901,91.4825,-0.92096,71.86546,50,0.00E+00,20,0.55563
803.74298,91.5975,-0.92335,71.86182,50,0.00E+00,20,0.5552
804.89697,91.7125,-0.92507,71.85636,50,0.00E+00,20,0.55476
806.03998,91.8275,-0.92679,71.84727,50,0.00E+00,20,0.55433
807.19202,91.9425,-0.92832,71.84364,50,0.00E+00,20,0.5539
808.35999,92.0575,-0.93086,71.83454,50,0.00E+00,20,0.55346
809.51099,92.1725,-0.93354,71.82909,50,0.00E+00,20,0.55303
810.66602,92.2875,-0.93515,71.82,50,0.00E+00,20,0.5526
811.815,92.4025,-0.9361,71.81273,50,0.00E+00,20,0.55217
812.96802,92.5175,-0.93675,71.80545,50,0.00E+00,20,0.55174
814.112,92.6325,-0.93816,71.8,50,0.00E+00,20,0.55131
815.28101,92.7475,-0.93938,71.79091,50,0.00E+00,20,0.55088
816.42798,92.8625,-0.94031,71.78364,50,0.00E+00,20,0.55045
817.57202,92.9775,-0.93972,71.77273,50,0.00E+00,20,0.55003
818.72803,93.0925,-0.9398,71.76909,50,0.00E+00,20,0.5496
819.85498,93.2075,-0.9395,71.76,50,0.00E+00,20,0.54918
821.00098,93.3225,-0.93949,71.75273,50,0.00E+00,20,0.54876
822.13702,93.4375,-0.94059,71.74545,50,0.00E+00,20,0.54834
823.30298,93.5525,-0.94193,71.73636,50,0.00E+00,20,0.54791
824.47803,93.6675,-0.94379,71.72727,50,0.00E+00,20,0.54748
825.65503,93.7825,-0.94527,71.71818,50,0.00E+00,20,0.54704
826.81702,93.8975,-0.94629,71.71273,50,0.00E+00,20,0.54662
827.97198,94.0125,-0.94743,71.7,50,0.00E+00,20,0.54619
829.14301,94.1275,-0.94782,71.68909,50,0.00E+00,20,0.54577
830.30298,94.2425,-0.94797,71.68,50,0.00E+00,20,0.54534
831.44897,94.3575,-0.94738,71.67091,50,0.00E+00,20,0.54492
832.604,94.4725,-0.94658,71.65818,50,0.00E+00,20,0.5445
833.73901,94.5875,-0.9448,71.64727,50,0.00E+00,20,0.54409
834.89502,94.7025,-0.94489,71.63818,50,0.00E+00,20,0.54367
836.06403,94.8175,-0.94612,71.62727,50,0.00E+00,20,0.54324
837.22302,94.9325,-0.947,71.62,50,0.00E+00,20,0.54282
838.38501,95.0475,-0.9481,71.60727,50,0.00E+00,20,0.5424
839.55298,95.1625,-0.9485,71.6,50,0.00E+00,20,0.54198
840.70898,95.2775,-0.94824,71.59091,50,0.00E+00,20,0.54156
841.86499,95.3925,-0.94661,71.58,50,0.00E+00,20,0.54114
843.01703,95.5075,-0.94544,71.56909,50,0.00E+00,20,0.54073
844.15698,95.6225,-0.94521,71.55818,50,0.00E+00,20,0.54032
845.31702,95.7375,-0.94496,71.54364,50,0.00E+00,20,0.5399
846.46399,95.8525,-0.94525,71.53091,50,0.00E+00,20,0.53949
847.59399,95.9675,-0.94416,71.52182,50,0.00E+00,20,0.53908
848.75,96.0825,-0.94332,71.51091,50,0.00E+00,20,0.53866
849.88,96.1975,-0.94256,71.50182,50,0.00E+00,20,0.53826
851.03101,96.3125,-0.94189,71.49091,50,0.00E+00,20,0.53785
852.172,96.4275,-0.94206,71.47636,50,0.00E+00,20,0.53744
853.32098,96.5425,-0.94265,71.46727,50,0.00E+00,20,0.53703
854.48401,96.6575,-0.94312,71.45455,50,0.00E+00,20,0.53661
855.63098,96.7725,-0.94382,71.44182,50,0.00E+00,20,0.5362
856.79199,96.8875,-0.94449,71.42909,50,0.00E+00,20,0.53579
857.987,97.0025,-0.9476,71.41818,50,0.00E+00,20,0.53536
859.19098,97.1175,-0.95077,71.40364,50,0.00E+00,20,0.53494
860.34302,97.2325,-0.95137,71.39273,50,0.00E+00,20,0.53453
861.50897,97.3475,-0.95086,71.38,50,0.00E+00,20,0.53411
862.66101,97.4625,-0.94975,71.36909,50,0.00E+00,20,0.5337
863.79303,97.5775,-0.94864,71.35636,50,0.00E+00,20,0.5333
864.93903,97.6925,-0.9477,71.34182,50,0.00E+00,20,0.5329
866.08398,97.8075,-0.9474,71.33454,50,0.00E+00,20,0.53249
867.22101,97.9225,-0.94767,71.32182,50,0.00E+00,20,0.53209
868.349,98.0375,-0.94734,71.31091,50,0.00E+00,20,0.53169
869.49701,98.1525,-0.94728,71.3,50,0.00E+00,20,0.53129
870.63898,98.2675,-0.9474,71.28727,50,0.00E+00,20,0.53088
871.784,98.3825,-0.9489,71.27273,50,0.00E+00,20,0.53048
872.92401,98.4975,-0.94925,71.26364,50,0.00E+00,20,0.53008
874.065,98.6125,-0.9499,71.25455,50,0.00E+00,20,0.52968
875.20599,98.7275,-0.95022,71.24182,50,0.00E+00,20,0.52928
876.33899,98.8425,-0.9506,71.22909,50,0.00E+00,20,0.52888
877.47101,98.9575,-0.95178,71.21636,50,0.00E+00,20,0.52848
878.60797,99.0725,-0.95284,71.20909,50,0.00E+00,20,0.52808
879.74597,99.1875,-0.95593,71.19273,50,0.00E+00,20,0.52768
880.93597,99.3025,-0.96016,71.18,50,0.00E+00,20,0.52727
882.15198,99.4175,-0.96762,71.16727,50,0.00E+00,20,0.52684
883.36603,99.5325,-0.97404,71.15273,50,0.00E+00,20,0.52641
884.54999,99.6475,-0.97795,71.14,50,0.00E+00,20,0.526
885.71002,99.7625,-0.9796,71.13091,50,0.00E+00,20,0.5256
886.88202,99.8775,-0.98094,71.11818,50,0.00E+00,20,0.52519
888.04602,99.9925,-0.98207,71.10545,50,0.00E+00,20,0.52478
889.19098,100.1075,-0.98282,71.09091,50,0.00E+00,20,0.52438
890.34998,100.2225,-0.98313,71.08182,50,0.00E+00,20,0.52398
891.47998,100.3375,-0.98294,71.06727,50,0.00E+00,20,0.52358
892.61401,100.4525,-0.98355,71.05455,50,0.00E+00,20,0.52319
893.76898,100.5675,-0.98513,71.04546,50,0.00E+00,20,0.52279
894.91803,100.6825,-0.98583,71.03091,50,0.00E+00,20,0.52239
896.06201,100.7975,-0.98648,71.01818,50,0.00E+00,20,0.52199
897.21002,100.9125,-0.98752,71.00727,50,0.00E+00,20,0.52159
898.367,101.0275,-0.98767,70.99091,50,0.00E+00,20,0.52119
899.492,101.1425,-0.98796,70.98,50,0.00E+00,20,0.5208
900.62097,101.2575,-0.98681,70.96909,50,0.00E+00,20,0.5204
901.77301,101.3725,-0.98712,70.95636,50,0.00E+00,20,0.52001
902.91498,101.4875,-0.98725,70.94545,50,0.00E+00,20,0.51961
904.06097,101.6025,-0.9874,70.93273,50,0.00E+00,20,0.51921
905.21899,101.7175,-0.98816,70.91818,50,0.00E+00,20,0.51881
906.36603,101.8325,-0.98811,70.91091,50,0.00E+00,20,0.51841
907.52002,101.9475,-0.98746,70.89636,50,0.00E+00,20,0.51801
908.68298,102.0625,-0.98919,70.88364,50,0.00E+00,20,0.51761
909.82501,102.1775,-0.98933,70.87273,50,0.00E+00,20,0.51722
910.98499,102.2925,-0.99007,70.86182,50,0.00E+00,20,0.51682
912.16803,102.4075,-0.99195,70.84909,50,0.00E+00,20,0.51641
913.32599,102.5225,-0.9931,70.83636,50,0.00E+00,20,0.51601
914.47699,102.6375,-0.99301,70.82182,50,0.00E+00,20,0.51561
915.62701,102.7525,-0.99226,70.81273,50,0.00E+00,20,0.51521
916.77502,102.8675,-0.99138,70.79636,50,0.00E+00,20,0.51481
917.92499,102.9825,-0.99085,70.78545,50,0.00E+00,20,0.51442
919.06598,103.0975,-0.99032,70.77636,50,0.00E+00,20,0.51402
920.20398,103.2125,-0.98948,70.76,50,0.00E+00,20,0.51363
921.35699,103.3275,-0.99171,70.74909,50,0.00E+00,20,0.51323
922.49799,103.4425,-0.99282,70.73818,50,0.00E+00,20,0.51284
923.651,103.5575,-0.99337,70.72364,50,0.00E+00,20,0.51244
924.81702,103.6725,-0.99453,70.71273,50,0.00E+00,20,0.51204
925.96301,103.7875,-0.99611,70.70182,50,0.00E+00,20,0.51165
927.112,103.9025,-0.99727,70.69273,50,0.00E+00,20,0.51125
928.25897,104.0175,-0.99635,70.68182,50,0.00E+00,20,0.51085
929.422,104.1325,-0.99689,70.66909,50,0.00E+00,20,0.51045
930.573,104.2475,-0.99737,70.65636,50,0.00E+00,20,0.51006
931.73401,104.3625,-0.99695,70.64545,50,0.00E+00,20,0.50966
932.888,104.4775,-0.99729,70.63273,50,0.00E+00,20,0.50926
934.05103,104.5925,-0.99633,70.61818,50,0.00E+00,20,0.50886
935.21198,104.7075,-0.99614,70.60727,50,0.00E+00,20,0.50846
936.36798,104.8225,-0.99449,70.59636,50,0.00E+00,20,0.50806
937.52698,104.9375,-0.99226,70.58364,50,0.00E+00,20,0.50766
938.70203,105.0525,-0.99029,70.57091,50,0.00E+00,20,0.50726
939.86798,105.1675,-0.98705,70.55818,50,0.00E+00,20,0.50686
941.013,105.2825,-0.98379,70.54727,50,0.00E+00,20,0.50646
942.16803,105.3975,-0.98133,70.53636,50,0.00E+00,20,0.50607
943.31702,105.5125,-0.97837,70.52545,50,0.00E+00,20,0.50567
944.461,105.6275,-0.97507,70.51273,50,0.00E+00,20,0.50528
945.61298,105.7425,-0.97163,70.50182,50,0.00E+00,20,0.50488
946.758,105.8575,-0.96895,70.49091,50,0.00E+00,20,0.50449
947.92297,105.9725,-0.96772,70.47818,50,0.00E+00,20,0.50408
949.06299,106.0875,-0.96538,70.46727,50,0.00E+00,20,0.50369
950.20398,106.2025,-0.96432,70.45091,50,0.00E+00,20,0.5033
951.35699,106.3175,-0.96337,70.44,50,0.00E+00,20,0.5029
952.51898,106.4325,-0.96364,70.43636,50,0.00E+00,20,0.5025
953.70099,106.5475,-0.96589,70.42545,50,0.00E+00,20,0.50209
954.85101,106.6625,-0.96737,70.41091,50,0.00E+00,20,0.5017
956.00598,106.7775,-0.96775,70.39818,50,0.00E+00,20,0.5013
957.15802,106.8925,-0.9684,70.38909,50,0.00E+00,20,0.5009
958.32397,107.0075,-0.96954,70.38182,50,0.00E+00,20,0.5005
959.49298,107.1225,-0.97221,70.37455,50,0.00E+00,20,0.5001
960.66901,107.2375,-0.97555,70.37091,50,0.00E+00,20,0.49969
961.84003,107.3525,-0.97817,70.36182,50,0.00E+00,20,0.49929
962.995,107.4675,-0.97954,70.35454,50,0.00E+00,20,0.49889
964.15002,107.5825,-0.98004,70.34909,50,0.00E+00,20,0.49849
965.30103,107.6975,-0.97985,70.34364,50,0.00E+00,20,0.4981
966.44501,107.8125,-0.9792,70.33455,50,0.00E+00,20,0.4977
967.57599,107.9275,-0.9802,70.32545,50,0.00E+00,20,0.49731
968.73401,108.0425,-0.9809,70.31818,50,0.00E+00,20,0.49691
969.86298,108.1575,-0.98159,70.31454,50,0.00E+00,20,0.49652
971.01703,108.2725,-0.9826,70.30909,50,0.00E+00,20,0.49612
972.14502,108.3875,-0.98326,70.30909,50,0.00E+00,20,0.49573
973.271,108.5025,-0.98336,70.3,50,0.00E+00,20,0.49535
974.41101,108.6175,-0.98428,70.29455,50,0.00E+00,20,0.49495
975.57703,108.7325,-0.98646,70.28909,50,0.00E+00,20,0.49455
976.71399,108.8475,-0.98873,70.28182,50,0.00E+00,20,0.49416
977.883,108.9625,-0.99049,70.27818,50,0.00E+00,20,0.49375
979.05298,109.0775,-0.99516,70.27454,50,0.00E+00,20,0.49335
980.24298,109.1925,-0.99875,70.26909,50,0.00E+00,20,0.49293
981.396,109.3075,-1.00125,70.26545,50,0.00E+00,20,0.49254
982.56299,109.4225,-1.00246,70.25818,50,0.00E+00,20,0.49213
983.70898,109.5375,-1.00274,70.25455,50,0.00E+00,20,0.49173
984.85797,109.6525,-1.00268,70.25091,50,0.00E+00,20,0.49134
986.01099,109.7675,-1.00318,70.24909,50,0.00E+00,20,0.49094
987.15002,109.8825,-1.00385,70.24364,50,0.00E+00,20,0.49054
988.31299,109.9975,-1.00538,70.24182,50,0.00E+00,20,0.49014
989.46698,110.1125,-1.00626,70.23636,50,0.00E+00,20,0.48974
990.591,110.2275,-1.00613,70.23455,50,0.00E+00,20,0.48935
991.73102,110.3425,-1.00646,70.23455,50,0.00E+00,20,0.48895
992.909,110.4575,-1.00912,70.23091,50,0.00E+00,20,0.48854
994.13501,110.5725,-1.0152,70.22727,50,0.00E+00,20,0.48812
995.29901,110.6875,-1.01912,70.22545,50,0.00E+00,20,0.48771
996.46198,110.8025,-1.01976,70.22546,50,0.00E+00,20,0.48731
997.59802,110.9175,-1.01865,70.22,50,0.00E+00,20,0.48691
998.46997,111.0025,-1.01858,70.21818,50,0.00E+00,20,0.48661